File: Data Files/25-65/MSS d (25-65, 15w)_1.xrdml
<?xml version="1.0"?>
<xrdMeasurements xmlns="http://www.xrdml.com/XRDMeasurement/2.2" xmlns:xsi="http://www.w3.org/2001/XMLSchema-instance" xsi:schemaLocation="http://www.xrdml.com/XRDMeasurement/2.2 http://www.xrdml.com/XRDMeasurement/2.2/XRDMeasurement.xsd" status="Completed" recordIdentifier="{8F05225A-43E5-4876-AD07-4DD4B344C5B9}">
	<comment>
		<entry/>
	</comment>
	<sample type="To be analyzed">
		<id>doped wafer</id>
		<name></name>
		<preparedBy></preparedBy>
	</sample>
	<xrdMeasurement measurementType="Scan" status="Completed" sampleMode="Reflection">
		<usedWavelength intended="K-Alpha 1">
			<kAlpha1 unit="Angstrom">1.5405980</kAlpha1>
			<kAlpha2 unit="Angstrom">1.5444260</kAlpha2>
			<kBeta unit="Angstrom">1.3922500</kBeta>
			<ratioKAlpha2KAlpha1>0.5000</ratioKAlpha2KAlpha1>
		</usedWavelength>
		<incidentBeamPath>
			<radius unit="mm">145.00</radius>
			<xRayTube id="1010048" name="Empyrean Cu LFF HR (9430 033 7310x) DK437964">
				<tension unit="kV">40.0</tension>
				<current unit="mA">15.0</current>
				<anodeMaterial>Cu</anodeMaterial>
				<focus type="Line">
					<length unit="mm">12.0</length>
					<width unit="mm">0.4</width>
					<takeOffAngle unit="deg">6.0</takeOffAngle>
				</focus>
			</xRayTube>
			<filter id="20010004" name="Beta-filter Nickel">
				<material>Ni</material>
				<thickness unit="mm">0.020</thickness>
			</filter>
			<sollerSlit id="21010001" name="Soller slits 0.02 rad.">
				<opening unit="rad">0.0200</opening>
			</sollerSlit>
			<mask id="22210002" name="2D Mask">
				<width unit="mm">1.60</width>
			</mask>
			<divergenceSlit id="22120006" name="Divergence slit 1/32°" xsi:type="fixedDivergenceSlitType">
				<distanceToSample unit="mm">50.00</distanceToSample>
				<height unit="mm">0.05</height>
			</divergenceSlit>
		</incidentBeamPath>
		<beamKnife id="29030101" name="Beam knife high"/>
		<sampleMovement xsi:type="spinningSampleMovementType">
			<spinnerRevolutionTime unit="seconds">1.0</spinnerRevolutionTime>
		</sampleMovement>
		<diffractedBeamPath>
			<radius unit="mm">145.00</radius>
			<parallelPlateCollimator id="25020001" name="Parallel plate collimator 0.28°">
				<opening unit="deg">0.28</opening>
			</parallelPlateCollimator>
			<detector id="7010020" name="PIXcel3D-Medipix3 1x1 detector" xsi:type="areaDetectorType">
				<phd unit="keV">
					<lowerLevel>4.0</lowerLevel>
					<upperLevel>11.3</upperLevel>
				</phd>
				<mode>Scanning</mode>
				<activeChannelsEquatorial>255</activeChannelsEquatorial>
				<activeChannelsAxial>255</activeChannelsAxial>
				<pitchEquatorial unit="mm">0.05500</pitchEquatorial>
				<pitchAxial unit="mm">0.05500</pitchAxial>
				<readOutPeriod unit="seconds">0.235</readOutPeriod>
			</detector>
		</diffractedBeamPath>
		<scan appendNumber="0" mode="Continuous" scanAxis="2Theta" status="Completed">
			<header>
				<startTimeStamp>2025-04-25T13:37:23-08:00</startTimeStamp>
				<endTimeStamp>2025-04-25T13:45:38-08:00</endTimeStamp>
				<author>
					<name>Instrument</name>
				</author>
				<source>
					<applicationSoftware version="1.6 (94)">PANalytical Aeris Instrument Suite</applicationSoftware>
					<instrumentControlSoftware version="3.0.0 20211014">AERIS</instrumentControlSoftware>
					<instrumentID>2855484</instrumentID>
				</source>
			</header>
			<dataPoints>
				<positions axis="2Theta" unit="deg">
					<startPosition>25.00086644</startPosition>
					<endPosition>64.98936564</endPosition>
				</positions>
				<positions axis="Omega" unit="deg">
					<commonPosition>15.000</commonPosition>
				</positions>
				<commonCountingTime unit="seconds">58.395</commonCountingTime>
				<counts unit="counts">4 0 0 1 1 0 1 0 0 2 2 0 1 1 0 0 0 0 0 0 1 1 0 1 0 2 0 2 1 0 4 5 0 0 2 1 2 0 1 1 0 0 3 2 1 0 0 2 4 2 0 1 2 0 2 1 0 0 2 0 1 0 1 5 2 0 0 0 1 0 1 3 0 1 1 0 1 0 2 2 1 1 2 2 2 2 0 2 0 0 0 0 2 2 0 0 2 0 2 0 0 2 1 0 1 2 2 1 0 0 0 0 0 0 2 0 1 1 2 0 1 1 3 1 3 2 2 0 2 0 0 1 2 0 0 1 7 0 0 0 1 0 0 0 1 2 4 2 0 3 1 1 0 2 0 3 0 3 2 2 2 2 1 0 0 1 2 3 1 0 3 1 4 2 3 10 2 3 7 2 3 2 2 0 4 4 3 2 5 4 0 2 1 3 1 1 1 2 8 4 0 0 1 1 3 3 4 5 6 1 1 3 0 3 1 3 6 4 3 0 2 8 4 3 1 5 3 1 3 0 2 4 5 3 1 4 1 3 1 0 2 3 0 5 0 2 0 0 1 1 5 4 2 1 2 1 1 4 0 1 3 3 2 1 3 4 5 1 3 5 1 3 3 5 3 0 0 1 1 3 2 2 5 6 2 2 2 2 0 2 0 0 3 5 1 0 0 2 0 1 2 0 1 1 0 2 1 2 4 0 1 1 3 1 2 2 3 0 1 2 0 0 1 3 3 1 0 0 1 5 1 0 0 0 1 1 0 1 0 3 0 1 0 3 2 2 0 2 0 0 2 1 1 0 2 1 0 0 1 0 0 1 1 0 1 1 3 2 2 3 0 0 2 1 1 0 1 1 0 2 0 0 1 0 2 3 0 0 0 2 0 0 0 3 0 1 0 0 2 2 2 2 0 0 2 0 0 0 0 0 0 2 0 0 0 1 2 1 0 1 0 2 0 0 0 2 2 1 2 3 1 1 0 0 0 0 2 3 0 2 0 2 2 3 0 0 1 1 0 0 1 1 2 0 0 0 1 0 0 0 2 3 0 2 1 1 1 0 2 0 0 2 0 0 2 6 0 1 0 0 2 1 1 0 1 1 1 0 0 1 1 0 0 0 2 0 4 4 0 1 2 0 2 2 1 2 1 0 1 2 0 0 0 2 1 0 0 0 1 0 0 0 0 2 1 0 0 1 1 0 1 1 1 4 1 2 0 1 0 1 0 4 0 0 0 2 3 0 2 1 5 0 3 2 1 1 6 1 3 0 2 1 4 0 1 0 0 0 1 1 0 2 0 0 3 1 0 0 0 1 0 1 1 0 0 1 0 1 0 3 3 4 0 0 0 5 4 0 1 2 2 0 0 1 2 1 0 2 2 2 2 0 0 1 0 2 1 0 2 2 2 0 2 4 1 3 0 0 0 1 0 0 5 0 2 1 4 4 0 1 1 0 0 0 1 0 1 0 0 3 2 1 1 0 2 2 0 0 1 0 1 0 2 0 6 4 0 1 2 0 0 0 4 1 2 0 0 1 4 8 6 1 1 1 0 2 0 4 0 0 3 3 3 1 0 0 0 1 2 1 0 0 0 1 1 3 2 0 1 0 0 1 0 2 1 0 2 1 4 0 0 0 2 1 0 3 0 0 4 2 1 1 1 2 1 2 0 2 1 0 2 1 1 2 1 1 0 0 3 1 0 0 3 0 1 6 0 3 2 1 3 0 0 3 0 0 0 2 3 0 2 0 1 0 0 1 1 1 1 3 0 0 1 0 2 1 1 1 3 1 5 2 2 0 0 4 0 0 0 0 1 3 0 1 5 2 0 1 1 1 0 1 0 1 0 2 2 0 1 2 4 2 1 2 0 0 0 0 0 2 0 0 1 1 4 0 0 1 0 0 1 2 2 1 0 1 0 0 2 0 1 2 1 3 0 3 0 4 0 4 0 1 0 0 0 2 1 0 0 1 0 1 3 0 0 0 0 1 4 0 3 1 0 0 3 0 3 3 0 0 2 0 1 0 2 0 0 1 0 2 0 0 1 0 0 0 0 1 2 0 0 1 1 0 0 0 2 4 2 0 1 1 1 0 3 2 0 0 1 2 3 1 1 5 0 3 1 1 2 1 1 2 2 0 1 2 3 2 2 1 1 1 0 1 2 3 0 1 0 1 0 0 1 2 3 0 2 1 2 3 2 2 1 1 2 1 0 3 3 0 0 2 2 1 1 3 1 2 2 1 1 3 0 0 1 1 0 2 2 1 3 1 0 1 4 3 1 1 2 2 0 0 0 1 0 1 0 2 3 3 1 4 0 0 0 2 1 1 4 0 2 0 0 1 0 0 0 2 4 0 1 0 4 3 2 3 0 4 1 1 3 5 2 0 1 1 4 3 0 2 0 3 2 1 0 0 1 3 3 2 3 1 2 1 0 0 3 3 2 3 1 3 0 2 1 3 0 2 0 1 2 0 0 0 0 3 3 2 1 0 0 3 2 1 3 3 1 1 0 0 0 0 0 1 1 2 2 2 0 2 4 1 2 0 4 0 0 0 1 1 3 2 1 0 0 3 0 1 1 1 2 2 2 2 0 1 1 1 0 0 3 0 0 0 1 1 0 2 4 2 5 0 1 2 2 4 0 2 1 0 1 0 0 0 3 3 0 0 4 4 0 0 1 0 1 0 3 3 0 0 1 1 3 0 1 3 0 1 2 0 1 4 1 1 5 2 4 2 2 0 0 0 6 1 1 3 2 1 0 0 3 0 1 4 0 0 2 2 2 1 2 1 0 0 1 1 3 2 2 1 4 1 0 5 2 0 2 5 1 1 0 1 1 0 2 0 0 0 3 3 1 0 1 1 3 2 2 4 4 0 1 1 1 0 3 0 2 1 2 0 1 3 1 2 3 1 0 3 1 1 4 3 4 2 0 0 0 0 4 1 1 0 2 4 5 0 1 0 3 0 1 0 0 4 2 0 2 0 3 0 2 1 2 0 1 2 0 0 2 0 3 1 1 0 3 1 0 1 2 0 1 5 0 1 0 2 1 0 1 2 1 4 0 2 2 2 3 3 0 1 0 3 0 0 0 1 1 1 0 3 0 2 0 1 0 5 3 1 0 2 2 1 2 0 1 0 0 0 4 4 0 4 2 1 3 1 2 0 1 0 1 0 2 1 0 1 2 3 1 3 1 2 1 5 2 0 0 1 2 1 4 1 2 2 2 2 2 1 5 0 0 0 0 0 0 1 2 0 0 3 3 4 3 3 1 0 2 1 0 2 1 2 0 1 0 2 1 2 3 2 1 0 2 3 0 0 0 3 2 4 2 1 1 4 0 1 1 0 1 1 2 0 1 0 3 2 0 2 3 2 2 1 1 3 1 2 3 4 4 3 0 1 0 4 2 1 1 1 2 0 2 0 1 0 6 0 0 0 1 2 0 2 1 0 1 0 1 3 2 1 2 0 3 6 2 2 1 3 1 2 0 4 4 0 2 0 1 2 0 1 2 3 3 0 2 0 0 0 2 1 0 1 2 1 0 1 1 1 4 0 0 2 1 5 1 4 1 1 2 0 4 2 0 2 3 1 1 1 3 4 3 1 2 4 2 1 1 2 0 0 1 0 2 0 3 1 0 1 3 5 1 0 1 0 1 0 1 1 0 0 4 3 1 3 1 1 0 1 2 1 1 0 0 2 3 0 1 2 0 7 2 1 0 1 1 2 1 3 0 1 4 0 0 0 3 1 0 4 2 3 0 1 1 4 2 3 4 2 3 2 3 0 0 2 1 2 1 0 0 0 1 2 3 0 0 3 2 3 2 2 0 1 0 0 1 0 2 2 0 4 2 1 5 0 0 1 1 2 1 4 0 2 0 1 1 2 1 3 3 1 1 4 2 2 2 4 2 2 3 0 2 3 3 0 3 3 0 2 0 7 4 0 1 2 1 1 1 0 3 2 0 0 0 1 3 2 2 3 3 2 0 0 0 0 3 4 0 0 1 0 2 1 3 2 0 0 3 6 0 0 1 1 0 3 1 0 2 4 1 4 1 0 3 2 2 0 1 1 1 2 5 0 0 1 0 2 2 0 3 0 1 2 3 2 5 0 1 0 2 1 1 0 1 2 1 0 3 1 1 0 2 0 1 3 2 1 3 1 4 2 2</counts>
			</dataPoints>
		</scan>
	</xrdMeasurement>
</xrdMeasurements>