File: Data Files/Full/MSS d (0-125, 002).xrdml
<?xml version="1.0"?>
<xrdMeasurements xmlns="http://www.xrdml.com/XRDMeasurement/2.2" xmlns:xsi="http://www.w3.org/2001/XMLSchema-instance" xsi:schemaLocation="http://www.xrdml.com/XRDMeasurement/2.2 http://www.xrdml.com/XRDMeasurement/2.2/XRDMeasurement.xsd" status="Completed" recordIdentifier="{323776D4-7FFC-48E2-BBB9-8045FAA74410}">
	<comment>
		<entry/>
	</comment>
	<sample type="To be analyzed">
		<id>doped wafer</id>
		<name></name>
		<preparedBy></preparedBy>
	</sample>
	<xrdMeasurement measurementType="Scan" status="Completed" sampleMode="Reflection">
		<usedWavelength intended="K-Alpha 1">
			<kAlpha1 unit="Angstrom">1.5405980</kAlpha1>
			<kAlpha2 unit="Angstrom">1.5444260</kAlpha2>
			<kBeta unit="Angstrom">1.3922500</kBeta>
			<ratioKAlpha2KAlpha1>0.5000</ratioKAlpha2KAlpha1>
		</usedWavelength>
		<incidentBeamPath>
			<radius unit="mm">145.00</radius>
			<xRayTube id="1010048" name="Empyrean Cu LFF HR (9430 033 7310x) DK437964">
				<tension unit="kV">40.0</tension>
				<current unit="mA">15.0</current>
				<anodeMaterial>Cu</anodeMaterial>
				<focus type="Line">
					<length unit="mm">12.0</length>
					<width unit="mm">0.4</width>
					<takeOffAngle unit="deg">6.0</takeOffAngle>
				</focus>
			</xRayTube>
			<filter id="20010004" name="Beta-filter Nickel">
				<material>Ni</material>
				<thickness unit="mm">0.020</thickness>
			</filter>
			<sollerSlit id="21010001" name="Soller slits 0.02 rad.">
				<opening unit="rad">0.0200</opening>
			</sollerSlit>
			<mask id="22210002" name="2D Mask">
				<width unit="mm">1.60</width>
			</mask>
			<divergenceSlit id="22120006" name="Divergence slit 1/32°" xsi:type="fixedDivergenceSlitType">
				<distanceToSample unit="mm">50.00</distanceToSample>
				<height unit="mm">0.05</height>
			</divergenceSlit>
		</incidentBeamPath>
		<beamKnife id="29030101" name="Beam knife high"/>
		<sampleMovement xsi:type="spinningSampleMovementType">
			<spinnerRevolutionTime unit="seconds">1.0</spinnerRevolutionTime>
		</sampleMovement>
		<diffractedBeamPath>
			<radius unit="mm">145.00</radius>
			<parallelPlateCollimator id="25020001" name="Parallel plate collimator 0.28°">
				<opening unit="deg">0.28</opening>
			</parallelPlateCollimator>
			<detector id="7010020" name="PIXcel3D-Medipix3 1x1 detector" xsi:type="areaDetectorType">
				<phd unit="keV">
					<lowerLevel>4.0</lowerLevel>
					<upperLevel>11.3</upperLevel>
				</phd>
				<mode>Scanning</mode>
				<activeChannelsEquatorial>255</activeChannelsEquatorial>
				<activeChannelsAxial>255</activeChannelsAxial>
				<pitchEquatorial unit="mm">0.05500</pitchEquatorial>
				<pitchAxial unit="mm">0.05500</pitchAxial>
				<readOutPeriod unit="seconds">1.355</readOutPeriod>
			</detector>
		</diffractedBeamPath>
		<scan appendNumber="0" mode="Continuous" scanAxis="Gonio" status="Completed">
			<header>
				<startTimeStamp>2025-05-01T08:44:58-08:00</startTimeStamp>
				<endTimeStamp>2025-05-02T02:50:04-08:00</endTimeStamp>
				<author>
					<name>Instrument</name>
				</author>
				<source>
					<applicationSoftware version="1.6 (94)">PANalytical Aeris Instrument Suite</applicationSoftware>
					<instrumentControlSoftware version="3.0.0 20211014">AERIS</instrumentControlSoftware>
					<instrumentID>2855484</instrumentID>
				</source>
			</header>
			<dataPoints>
				<positions axis="2Theta" unit="deg">
					<startPosition>0.00135831</startPosition>
					<endPosition>124.99801762</endPosition>
				</positions>
				<positions axis="Omega" unit="deg">
					<startPosition>0.00067915</startPosition>
					<endPosition>62.49900881</endPosition>
				</positions>
				<commonCountingTime unit="seconds">343.995</commonCountingTime>
				<counts 7 12 14 10 6 11 11 16 4 3 8 5 11 1 8 6 11 12 5 9 10 3 8 5 9 9 6 9 8 11 6 11 6 9 5 10 10 15 7 10 7 7 4 7 8 11 10 7 11 7 2 8 2 6 12 15 11 8 7 10 4 6 13 11 6 11 9 11 8 5 11 8 5 7 3 13 7 11 17 11 7 5 10 5 8 14 11 16 10 15 18 13 17 25 339 781 1470 2067 2292 2480 2264 2088 2562 4237 7941 13301 19793 27889 36322 44961 52890 58702 60562 58386 53488 47254 39826 31498 22835 15704 11999 11516 10951 11174 10912 10410 10202 10090 9718 9607 9456 9270 8721 8625 8425 8041 7804 7555 7319 6968 6653 6514 6087 5834 5515 5277 4894 4544 4358 3904 3670 3483 3203 2998 2749 2703 2442 2271 2061 1912 1807 1715 1550 1570 1513 1413 1428 1274 1285 1271 1238 1212 1266 1257 1224 1213 1304 1272 1298 1312 1304 1368 1397 1382 1440 1447 1510 1460 1497 1508 1565 1505 1561 1673 1587 1741 1685 1703 1691 1709 1697 1670 1716 1739 1684 1633 1595 1661 1652 1612 1569 1586 1534 1516 1470 1568 1477 1366 1367 1362 1354 1344 1252 1357 1232 1204 1201 1148 1137 1106 1001 1038 959 954 1011 994 925 938 900 866 909 868 854 912 975 964 992 993 1001 1110 1051 1054 1125 1206 1073 1169 1246 1187 1087 986 798 542 331 145 80 52 31 25 13 18 19 15 11 13 10 18 16 10 4 13 7 9 12 8 5 9 11 18 12 18 13 8 13 9 9 14 9 15 10 8 7 13 7 5 10 10 7 6 9 14 9 9 7 9 9 5 10 9 9 11 11 6 3 5 10 5 16 12 10 10 13 6 8 5 5 8 6 11 7 2 4 5 7 7 10 9 9 5 7 15 10 7 10 6 10 15 8 9 8 14 12 6 8 5 8 11 8 8 4 7 7 12 6 9 12 9 7 11 24 6 11 17 8 19 17 10 13 8 14 26 12 11 9 14 22 16 16 11 23 14 12 15 18 24 19 15 15 14 19 21 18 22 17 25 24 32 23 26 26 17 21 28 17 18 24 22 15 21 17 18 25 24 27 19 21 25 23 22 29 20 14 24 20 24 15 18 19 16 20 16 30 23 27 22 22 17 28 20 26 26 22 23 18 20 23 16 32 23 27 23 19 17 28 28 20 14 20 22 17 21 14 20 18 21 22 19 17 22 22 16 21 17 16 17 19 17 19 17 18 18 13 14 15 19 22 15 19 12 16 13 12 10 19 7 8 10 21 11 14 14 14 17 16 15 17 9 16 17 15 16 14 13 11 8 13 6 15 13 10 17 13 7 12 8 13 18 11 13 13 15 9 13 10 9 13 11 7 11 13 10 7 11 10 9 7 11 4 10 3 12 8 17 10 4 10 10 5 9 10 11 9 10 9 5 8 9 13 8 9 10 6 5 5 7 7 7 5 4 7 9 17 10 6 6 7 7 10 13 7 12 6 8 8 10 3 4 3 19 7 11 6 6 2 8 7 10 8 11 7 3 9 5 10 9 12 6 15 8 7 7 10 10 10 8 6 3 8 2 11 6 9 8 7 8 10 11 9 7 10 8 9 10 7 4 6 13 10 4 5 10 6 9 7 13 11 7 9 9 9 7 4 6 7 6 9 8 7 6 3 11 7 3 10 5 8 9 5 10 8 5 5 6 7 12 2 8 15 8 13 10 6 6 9 10 8 8 8 7 8 7 3 4 10 10 9 6 4 4 8 5 15 10 6 9 9 8 10 5 8 6 10 3 13 12 6 9 8 12 13 3 4 4 8 13 4 8 6 9 8 10 6 12 18 6 7 3 12 11 4 12 12 10 8 4 7 5 8 7 10 7 17 11 3 3 10 4 8 8 11 14 3 5 8 8 9 9 14 8 9 5 6 13 4 18 10 5 6 6 4 4 4 7 6 13 15 2 4 5 6 11 4 11 10 8 13 9 12 4 2 6 4 9 7 6 6 4 6 6 6 7 3 5 6 7 9 7 8 11 4 4 4 5 12 5 4 7 5 4 8 7 9 2 7 8 12 15 2 9 8 5 6 4 10 3 11 8 2 11 6 7 6 10 8 6 8 8 13 7 9 8 9 9 10 10 13 10 8 4 10 7 5 11 9 9 13 3 9 6 11 7 4 9 0 7 10 3 10 7 12 10 3 11 4 7 7 9 7 7 8 11 11 5 6 5 2 7 7 5 6 9 11 8 5 7 3 4 13 3 3 13 8 11 7 9 9 1 10 8 7 5 7 7 9 9 6 3 3 4 9 12 10 8 7 8 5 7 10 5 4 6 5 6 7 9 8 8 11 7 11 9 2 6 5 11 9 14 12 7 3 7 6 6 8 2 4 11 7 6 4 7 6 4 9 9 12 7 4 4 7 9 3 6 7 7 7 8 9 11 7 5 2 8 5 0 7 12 7 13 3 13 4 5 3 9 6 8 7 8 8 6 9 5 7 7 7 6 7 9 5 8 6 7 9 9 4 2 8 14 9 8 5 8 8 7 9 4 8 1 9 5 8 3 8 9 9 11 4 9 9 6 8 5 5 2 6 8 5 6 5 6 12 13 9 8 8 3 7 7 7 10 9 9 8 1 5 4 12 9 7 7 2 7 8 6 10 6 4 5 6 5 5 6 4 15 6 4 4 9 5 6 8 9 10 5 7 15 8 16 11 6 15 7 7 5 9 11 3 10 6 6 5 5 13 8 2 9 6 2 4 10 7 10 9 5 7 5 12 4 5 4 6 8 8 8 11 7 10 5 7 6 6 6 7 11 5 10 3 6 11 9 4 11 7 6 3 9 9 4 16 5 5 9 8 6 8 6 7 12 5 10 8 7 7 8 6 7 10 6 8 10 8 3 19 2 13 3 11 7 8 9 2 5 12 7 5 8 4 3 12 7 7 6 5 7 7 4 5 8 10 5 6 5 14 5 6 7 2 10 7 6 4 5 6 3 6 5 5 5 10 5 8 7 10 8 5 8 7 6 5 2 5 5 7 4 5 7 3 11 3 9 5 12 11 13 5 13 5 7 7 9 4 8 7 12 5 7 7 2 8 7 16 8 6 11 10 8 8 4 6 7 8 9 10 8 4 7 7 6 10 6 6 4 9 10 7 11 4 6 9 7 11 8 12 9 8 7 7 7 4 8 12 14 12 11 9 7 4 10 9 11 4 4 5 15 11 5 7 5 6 9 2 4 7 4 7 6 7 4 9 12 11 6 3 14 5 5 7 10 6 14 9 11 6 8 5 9 6 13 5 9 15 6 12 6 10 5 10 3 9 10 2 5 6 5 7 11 6 7 12 3 7 7 5 7 5 9 5 6 4 5 8 7 11 9 6 10 11 10 8 12 7 8 4 13 7 6 9 7 9 4 10 10 8 10 5 9 3 7 9 7 9 11 1 5 6 10 9 4 5 8 7 6 14 5 11 11 7 4 13 12 10 6 4 3 10 10 9 12 5 9 10 7 10 9 3 8 11 7 6 10 3 7 13 10 3 11 5 11 5 6 11 8 9 6 9 10 11 9 3 7 4 12 14 8 1 12 8 7 8 10 6 4 12 7 10 8 4 7 7 7 6 9 3 5 7 9 5 13 12 8 9 9 10 10 1 6 11 4 7 9 8 10 7 6 6 6 6 9 8 10 14 3 6 9 10 7 9 7 13 4 11 7 14 8 5 3 8 8 6 10 5 8 9 5 4 6 7 7 10 14 7 7 7 4 7 6 10 14 13 6 10 6 13 5 14 10 13 7 9 8 3 8 12 7 6 5 9 10 7 12 4 10 14 8 8 11 7 10 6 10 12 12 13 6 9 4 15 5 10 8 10 11 18 11 13 9 12 14 5 14 13 7 12 8 11 11 13 15 8 6 7 8 10 11 6 9 7 10 7 18 10 16 9 10 2 8 7 9 9 11 13 9 9 5 9 13 6 15 11 10 9 12 6 13 7 5 7 15 9 5 5 6 13 16 7 9 16 7 6 9 13 11 11 13 10 9 8 10 7 8 10 10 5 19 13 8 10 13 8 15 8 7 11 11 10 8 20 14 12 9 15 9 12 6 13 6 17 16 12 6 12 9 10 19 8 7 13 15 8 9 13 3 9 11 13 14 11 9 10 15 15 9 13 8 14 11 10 13 9 15 12 17 9 7 12 18 6 9 12 17 8 11 7 6 15 10 13 21 8 9 14 9 15 8 7 14 11 12 10 8 14 16 22 12 17 17 7 6 14 15 9 15 9 10 20 15 14 23 16 8 13 11 12 6 8 23 13 22 14 17 16 9 17 12 16 14 9 11 9 11 5 17 17 19 9 14 18 9 19 13 15 7 16 23 13 16 12 14 9 18 18 11 18 16 18 12 14 10 7 12 13 7 12 19 12 9 15 9 18 12 15 11 15 12 18 10 19 9 15 10 15 6 9 13 16 12 14 18 12 12 15 11 10 18 12 12 18 17 17 9 13 15 12 14 10 12 12 13 13 20 11 14 6 16 14 10 12 17 9 13 17 18 18 19 11 15 13 10 23 10 16 10 12 18 14 10 6 10 7 14 15 18 19 16 9 9 11 17 11 23 13 17 9 17 16 16 13 16 10 15 12 12 7 14 16 10 13 9 15 16 13 13 13 8 12 11 18 14 10 17 14 20 16 16 19 12 10 13 15 16 17 9 14 15 15 19 20 12 15 10 9 13 17 13 16 19 8 13 23 16 10 12 14 16 15 13 18 11 11 13 16 20 22 22 13 15 20 19 17 12 15 15 14 15 13 15 18 18 12 12 15 16 20 14 14 13 16 8 18 15 14 10 15 11 18 10 8 7 11 19 18 12 12 13 12 17 15 17 14 9 18 12 25 15 20 24 20 9 20 18 11 13 19 14 16 18 17 14 17 20 15 21 14 16 13 10 17 19 10 18 9 31 17 18 22 14 14 9 34 19 16 15 13 17 21 8 19 12 19 24 17 21 22 11 19 21 12 18 11 12 20 13 15 15 17 19 19 28 12 26 18 17 19 18 25 18 12 12 14 22 18 18 18 14 17 19 14 18 10 17 11 20 25 15 12 12 9 13 13 19 19 14 11 17 14 15 8 21 8 15 19 20 20 22 18 19 18 21 19 18 19 11 12 20 12 19 12 19 22 11 15 10 24 18 15 15 21 11 13 18 11 20 21 18 12 21 15 13 13 29 24 12 10 20 22 10 11 17 19 16 20 14 18 16 16 16 16 24 25 19 20 21 22 13 16 19 19 11 15 20 28 16 14 12 12 17 20 27 14 17 19 16 18 14 9 13 27 28 17 14 19 14 19 13 17 15 13 25 20 20 18 23 18 22 17 13 24 18 10 29 22 23 14 14 25 20 14 21 17 18 25 12 21 22 17 22 18 18 17 24 22 24 17 25 15 22 17 14 14 17 16 12 18 8 11 18 15 17 17 20 16 25 16 18 21 17 21 16 13 21 20 16 24 16 16 14 15 17 17 25 23 14 24 19 15 12 18 15 22 15 19 25 14 17 20 13 15 17 21 17 19 13 12 17 13 24 14 15 19 13 17 21 23 17 19 16 17 20 22 14 26 22 16 22 17 12 20 20 12 17 18 16 17 19 20 21 20 6 17 16 25 17 18 21 18 16 17 17 12 18 23 25 13 18 11 24 18 21 21 24 19 23 24 14 17 18 14 14 24 21 17 15 14 19 22 19 19 19 13 19 17 15 16 23 18 15 18 22 26 15 12 14 19 10 17 16 14 14 22 13 19 13 12 14 23 13 16 15 19 16 14 17 15 27 23 21 13 16 16 20 28 20 22 21 14 13 19 22 16 13 26 16 23 18 18 13 17 21 12 25 21 15 14 23 17 19 20 17 18 13 18 20 16 18 15 19 30 18 20 19 16 18 17 19 20 25 17 14 16 24 24 19 18 17 22 13 28 17 14 23 26 22 13 15 19 14 16 21 23 23 17 14 17 16 24 27 20 11 21 15 18 22 20 18 18 30 22 20 22 8 19 18 14 9 21 21 20 21 16 16 20 20 18 12 25 27 21 19 27 20 21 15 16 14 17 22 24 9 18 11 21 13 21 16 20 25 15 20 24 16 12 24 21 21 24 21 12 18 19 20 23 15 20 18 22 16 24 10 14 21 21 14 16 22 17 17 14 29 18 15 18 17 18 22 20 21 16 24 23 14 14 26 23 17 15 23 26 17 17 14 15 23 26 13 23 21 21 13 18 16 14 17 21 27 24 16 19 22 23 21 21 22 23 12 18 12 17 18 14 19 24 16 22 18 17 19 19 15 11 29 20 14 18 29 17 16 21 22 27 13 22 19 23 25 26 27 16 19 14 17 25 25 15 13 17 16 20 23 29 11 18 13 13 19 15 13 20 21 31 19 19 17 29 13 21 24 20 22 21 18 15 21 21 12 13 19 25 26 13 24 17 16 12 22 17 20 18 13 25 19 22 19 18 19 20 17 22 22 17 26 16 16 27 11 19 23 23 21 22 13 15 16 19 18 20 18 27 23 18 21 21 15 16 12 20 14 19 16 30 16 26 16 19 18 21 9 14 16 20 9 9 16 26 18 20 20 15 21 17 15 23 13 14 16 20 21 28 10 19 24 19 19 18 19 21 22 19 12 15 9 18 21 14 24 15 18 21 17 16 17 11 17 23 11 15 15 22 24 20 16 12 22 13 19 15 11 21 10 23 28 19 29 28 16 22 22 20 27 13 22 21 21 25 24 16 16 18 27 22 23 13 9 23 19 21 13 22 21 20 15 19 14 12 19 23 17 18 19 15 21 10 22 15 18 9 16 13 13 12 16 21 23 19 19 22 10 25 20 19 21 18 20 22 20 16 15 23 23 21 14 15 13 19 21 21 14 9 20 28 19 14 16 16 24 16 15 12 21 12 19 18 14 20 17 15 19 17 20 15 15 9 20 23 17 21 22 24 18 19 25 20 20 11 20 20 23 26 19 17 26 22 26 14 13 20 24 20 19 17 14 23 11 19 15 15 13 12 21 10 14 16 17 17 21 13 24 17 15 13 14 16 21 12 10 16 23 25 12 27 19 20 18 18 11 17 24 22 23 22 24 21 21 16 13 23 15 25 16 10 24 26 18 15 18 22 21 20 13 19 15 19 23 19 19 22 12 20 20 18 20 18 20 11 22 20 21 27 19 16 22 14 18 12 20 18 29 17 16 12 22 15 22 20 24 10 13 19 13 23 16 27 14 17 16 10 17 15 24 16 21 26 21 18 17 18 18 21 19 19 18 21 13 19 20 12 19 23 25 19 13 23 15 23 23 12 11 9 20 29 34 16 12 18 19 17 16 16 26 14 15 15 18 13 26 16 22 16 25 21 21 27 26 7 19 25 14 9 6 26 20 11 28 18 19 20 7 10 14 14 19 23 25 19 26 17 22 22 19 15 19 12 18 22 18 17 19 20 15 19 13 22 18 22 19 19 15 16 17 20 29 12 21 23 22 20 15 19 16 19 19 11 21 17 11 20 24 14 16 19 9 19 16 15 13 16 24 14 18 19 16 13 21 19 17 20 15 18 23 13 17 15 20 16 20 15 8 8 18 23 18 19 23 16 19 20 16 15 13 19 15 14 11 23 25 8 20 8 19 17 23 14 15 14 13 15 25 15 19 23 11 22 24 18 21 23 19 17 15 24 12 15 16 14 23 22 14 25 21 12 15 18 25 11 24 15 21 16 18 14 14 16 15 7 27 7 11 19 8 14 18 14 20 15 10 17 22 14 19 18 21 12 10 19 18 18 20 16 19 20 11 19 18 20 22 24 22 18 18 19 15 24 14 24 30 16 22 10 17 21 24 13 22 13 23 15 19 10 22 17 21 15 21 19 18 25 14 16 22 22 19 14 17 16 18 19 17 16 27 20 28 19 8 26 13 19 19 12 11 17 19 15 16 16 18 23 14 21 29 42 29 37 22 17 11 19 16 29 31 22 30 27 17 20 20 13 20 19 25 19 10 17 13 23 16 26 12 10 16 8 9 16 23 22 25 18 13 12 18 19 14 15 10 17 18 19 20 11 17 16 13 10 10 16 15 10 26 15 15 19 18 27 28 12 10 17 21 16 24 18 15 15 13 22 30 15 20 18 14 18 15 14 19 17 19 9 24 14 10 19 12 20 16 13 18 19 17 18 9 25 15 19 22 20 22 20 18 14 16 21 21 16 15 25 16 11 12 16 20 18 17 11 23 10 15 20 23 12 11 9 17 20 12 16 15 19 28 13 20 18 13 15 18 18 15 16 21 11 12 12 17 21 9 19 14 20 28 14 21 16 15 19 15 16 11 18 9 23 15 19 21 15 13 15 16 20 18 16 15 7 11 11 11 18 17 18 21 15 16 15 11 15 7 21 10 20 10 14 14 16 9 14 11 17 12 10 9 18 6 17 11 15 12 14 19 21 21 19 27 16 10 17 19 17 12 25 26 12 19 21 16 20 13 15 16 15 11 21 17 17 17 11 23 17 13 14 23 15 13 11 13 15 20 20 21 13 10 16 16 14 16 18 21 11 19 10 19 17 19 13 15 19 17 12 15 21 6 15 12 15 6 14 22 17 11 16 18 12 21 15 24 14 21 15 18 18 17 18 19 13 10 10 25 14 7 19 15 24 13 15 18 19 21 17 19 21 10 16 14 16 18 12 14 11 16 19 23 16 13 15 15 16 15 17 28 18 25 12 15 17 16 11 16 15 19 11 20 14 13 14 11 11 10 19 17 11 16 12 12 14 18 16 11 7 23 14 18 14 16 11 19 13 21 25 22 10 17 21 20 16 19 8 13 17 9 10 16 16 21 10 23 19 14 17 19 15 14 22 9 14 16 12 15 19 15 19 15 13 17 13 16 15 18 21 17 24 5 11 17 19 21 18 20 19 20 19 22 12 10 16 12 14 17 14 15 15 18 15 12 13 10 14 19 23 25 15 21 15 12 12 10 17 15 17 19 13 18 18 11 19 14 22 14 10 23 13 19 11 21 13 16 9 12 9 14 20 18 20 13 16 17 13 9 20 11 17 15 12 11 13 12 19 10 20 13 8 21 10 9 15 14 15 9 13 17 23 19 20 21 23 12 15 15 20 7 13 17 26 26 18 10 20 13 15 9 17 15 8 19 17 16 15 7 20 12 11 17 21 12 13 12 18 12 16 17 19 20 15 19 13 6 18 18 10 16 18 16 15 13 34 16 21 12 8 22 26 34 23 17 16 15 19 18 18 25 17 15 18 16 18 19 17 18 12 16 12 19 21 23 21 15 10 14 9 16 16 13 12 9 15 13 16 10 15 21 9 23 19 12 15 12 11 12 16 11 17 15 8 15 8 9 14 10 12 9 6 17 23 19 20 10 11 12 9 14 15 19 14 11 16 18 18 6 17 12 18 12 16 19 16 18 12 12 14 7 15 24 20 19 10 14 14 17 16 23 19 14 5 15 13 19 17 14 17 20 14 14 17 26 18 12 16 17 10 18 19 14 16 14 23 12 14 18 7 13 14 18 17 10 16 16 10 13 18 14 12 16 16 11 12 11 14 14 13 18 21 12 18 20 9 18 19 17 21 22 10 17 11 17 15 20 16 11 13 18 12 9 16 15 17 12 17 12 16 15 17 18 12 14 15 16 10 20 11 11 17 13 18 16 24 11 14 14 19 14 10 17 19 8 18 20 11 16 17 12 16 13 17 19 9 14 17 15 19 13 14 22 13 10 13 13 10 22 13 14 12 14 18 17 10 20 12 11 16 13 9 14 14 17 15 16 19 11 10 14 7 9 13 9 22 14 19 17 12 10 12 13 16 9 11 13 13 9 10 22 22 16 13 12 15 15 13 11 12 10 15 14 14 5 15 8 7 13 17 17 17 11 19 12 8 11 15 13 16 16 17 21 19 20 15 17 23 12 12 11 14 17 14 16 20 22 17 14 12 16 16 10 14 7 8 17 13 13 18 12 15 6 18 14 12 12 17 10 16 14 23 14 9 17 12 12 16 13 10 15 17 11 14 18 15 13 8 12 17 17 11 19 9 13 9 17 20 14 12 19 10 11 14 15 14 20 16 16 21 10 18 12 16 12 14 9 7 13 16 10 14 8 20 10 9 16 12 16 13 19 13 14 16 9 15 21 15 16 16 14 9 16 10 14 13 10 23 12 16 16 10 12 20 11 18 16 16 14 14 15 15 10 12 8 14 13 19 14 11 10 14 20 21 20 13 13 8 12 16 20 24 17 12 7 15 24 15 16 16 16 6 10 11 20 10 9 16 14 13 17 11 20 11 11 17 11 14 9 17 12 10 19 12 18 15 16 18 16 16 10 15 17 17 12 6 11 15 16 12 17 17 17 16 17 17 16 15 12 12 20 12 14 13 13 15 16 19 19 11 8 13 13 12 18 20 12 10 17 18 16 12 16 13 8 15 12 9 23 20 11 16 13 10 14 14 19 12 10 12 13 10 17 19 9 10 22 10 10 9 10 11 15 10 16 16 16 13 12 15 13 13 17 8 6 11 16 15 12 12 13 15 9 16 9 7 15 13 17 9 16 22 10 12 7 11 12 20 9 17 17 15 25 13 17 9 11 16 16 17 21 18 16 15 21 15 18 21 14 9 12 11 10 18 11 14 10 10 8 12 13 7 13 8 13 14 14 12 6 20 8 6 16 10 14 16 13 4 16 18 12 19 13 19 7 17 12 16 10 15 13 10 10 13 16 8 3 20 12 11 15 19 14 11 10 12 17 9 15 21 16 10 8 16 13 4 15 12 18 13 16 12 10 21 7 26 18 10 11 19 5 10 16 10 18 12 14 15 15 6 18 10 17 13 18 12 12 12 7 12 13 12 16 10 12 11 13 11 12 11 8 14 16 13 21 19 16 6 8 13 15 26 9 11 9 9 12 12 16 14 12 16 8 12 10 10 14 15 19 7 13 14 16 15 18 12 13 9 16 6 8 13 12 15 12 18 9 11 14 12 15 9 10 17 12 14 11 7 14 15 16 9 8 13 12 17 16 9 16 10 23 16 13 13 11 14 8 16 8 14 17 17 9 18 11 14 17 14 14 18 15 17 15 14 20 16 17 13 14 11 12 13 16 19 12 8 13 8 10 13 11 10 14 14 19 16 16 14 8 17 15 9 12 15 12 12 14 14 23 17 13 12 17 11 19 17 12 7 16 10 12 13 17 19 21 5 14 19 9 10 9 20 9 11 15 19 16 12 16 15 11 13 12 10 13 10 15 15 14 10 8 5 13 10 6 16 3 16 21 14 3 14 12 15 12 14 12 9 13 9 12 10 11 16 8 14 14 22 21 11 14 8 21 17 8 15 7 16 20 12 16 14 14 16 9 11 13 15 13 19 9 14 10 10 4 14 11 10 13 16 11 7 19 18 12 14 15 9 15 16 10 15 19 16 11 12 12 17 11 9 6 23 14 12 5 13 8 8 12 15 11 19 14 12 19 13 15 11 14 19 14 9 13 15 16 14 13 7 18 11 8 14 23 15 20 12 15 9 10 9 13 7 18 11 11 14 14 19 13 6 11 6 15 14 15 10 11 11 14 10 16 11 8 11 12 12 13 17 12 8 18 14 9 13 12 18 11 11 8 13 22 13 8 10 18 19 17 13 13 11 8 17 13 13 16 15 14 12 19 13 13 17 9 13 13 8 21 16 12 11 11 16 15 12 15 10 12 12 16 11 12 18 11 14 17 15 19 12 16 16 20 16 11 11 9 16 10 11 13 12 18 12 17 7 17 10 6 13 14 9 18 15 17 16 16 21 10 17 11 10 13 7 11 10 17 13 18 12 14 10 10 16 8 15 7 13 16 18 8 17 14 13 12 14 12 9 21 20 11 15 15 14 12 9 6 15 10 10 7 14 18 16 13 11 13 7 12 18 7 10 13 11 15 6 10 18 10 11 13 15 16 14 20 10 9 10 13 17 8 19 12 17 13 14 10 11 9 9 11 11 19 17 11 8 15 14 12 10 11 14 15 11 13 17 21 13 11 15 10 15 14 14 12 14 12 9 16 11 14 14 15 12 11 13 7 10 16 15 12 11 9 18 12 19 8 9 14 15 14 12 8 18 11 15 10 13 8 16 12 16 15 15 12 14 19 9 9 13 9 18 13 13 12 13 9 18 16 12 7 16 10 20 13 9 9 18 10 11 32 14 13 9 10 7 15 11 8 9 7 13 12 13 17 8 11 10 11 12 15 22 10 15 14 11 14 20 12 7 11 17 10 8 17 14 13 13 15 16 8 18 9 19 13 9 20 15 8 7 12 6 10 11 14 15 13 14 13 12 15 17 16 15 20 14 15 15 8 11 21 13 8 11 13 13 12 11 10 15 12 16 16 8 15 7 9 9 13 22 16 21 12 14 15 14 13 8 19 14 10 21 13 10 17 12 11 16 16 8 10 15 9 15 3 13 14 15 7 20 13 19 9 9 11 12 8 15 15 16 14 11 20 10 14 12 19 10 10 14 14 9 18 16 16 14 14 16 17 19 12 18 12 10 5 10 17 12 11 14 11 15 13 13 21 13 18 18 13 8 16 9 16 13 11 21 12 9 14 11 12 15 13 14 13 5 12 9 16 18 11 22 14 10 12 15 9 15 17 12 9 10 6 12 14 17 21 9 19 9 13 14 20 9 15 4 15 14 9 10 16 16 19 13 12 15 12 17 14 9 21 9 12 14 17 12 14 18 14 12 15 11 17 9 19 19 8 12 13 10 11 7 9 10 15 9 14 21 22 11 9 9 13 14 16 11 13 11 14 14 10 11 8 15 15 13 11 16 12 12 14 16 14 18 14 21 13 9 19 14 16 18 19 13 12 12 11 14 16 13 15 8 20 8 14 7 12 20 15 11 10 11 6 14 12 10 12 10 13 14 12 17 11 9 9 10 11 19 19 9 10 10 6 9 21 14 14 16 16 11 13 14 12 7 17 12 13 14 11 10 11 5 15 12 16 11 12 23 14 6 11 17 14 20 16 7 12 16 12 9 13 13 13 17 11 15 10 11 10 15 16 12 16 11 8 11 9 14 11 13 15 17 7 13 11 13 13 10 10 9 10 16 9 5 13 13 8 8 12 8 16 11 7 12 14 11 14 14 12 13 14 10 9 14 18 12 9 10 9 14 13 9 10 13 23 13 9 16 9 10 8 18 14 13 19 15 13 14 7 12 16 7 8 12 14 8 10 17 12 12 16 10 15 18 17 12 13 21 8 12 6 15 6 11 15 9 22 13 13 14 8 14 9 18 13 13 15 15 8 14 14 17 17 6 16 14 10 13 19 13 16 12 8 11 16 7 15 9 12 19 10 7 14 10 11 18 14 13 11 18 9 12 10 16 15 9 14 13 12 12 11 4 18 13 12 10 12 17 18 11 10 14 20 9 12 12 7 20 11 15 15 20 19 14 12 13 13 17 11 15 10 15 8 14 10 13 16 16 5 7 10 14 14 14 10 17 11 11 9 11 14 13 18 8 19 12 14 13 6 15 18 14 18 14 15 11 11 19 13 9 9 8 21 13 14 12 11 10 10 23 17 17 7 22 17 10 14 12 14 15 12 13 18 14 15 16 11 10 12 8 12 21 21 12 11 13 17 18 7 19 13 13 7 13 13 15 14 15 15 16 13 14 15 11 10 19 7 9 12 11 10 14 10 15 9 24 9 15 5 10 12 7 10 15 17 15 11 13 13 9 8 14 14 12 10 12 14 9 14 16 16 11 14 14 11 11 7 16 12 11 12 19 10 12 13 14 11 20 18 9 16 15 14 14 16 11 7 14 10 12 12 10 20 10 12 12 12 6 17 12 24 16 13 13 16 15 8 16 5 14 14 12 17 14 14 13 17 18 12 18 16 14 10 9 14 10 4 16 14 9 13 15 11 14 14 19 12 7 10 7 16 12 8 16 7 14 17 11 16 8 7 18 16 8 17 11 14 10 8 12 15 10 10 13 14 20 11 20 10 18 12 18 11 12 12 15 15 9 14 16 8 12 16 7 16 6 19 8 17 14 11 8 10 13 16 19 9 17 14 17 13 10 4 12 10 12 19 10 14 16 10 16 7 11 23 10 10 17 10 10 14 10 14 10 13 13 11 9 12 15 17 15 13 13 11 12 15 16 15 14 14 11 9 11 13 15 17 12 9 13 11 13 18 10 5 20 12 17 8 11 10 17 16 11 13 10 8 14 15 16 15 11 13 14 13 8 17 8 16 11 6 25 11 9 19 15 13 6 12 17 9 13 18 21 12 22 11 16 14 15 13 6 14 13 11 16 18 11 18 10 14 9 8 11 12 14 6 16 10 11 10 13 12 20 8 16 9 14 19 15 14 10 6 17 8 10 17 17 15 15 14 13 10 13 15 15 9 9 19 11 9 18 11 13 8 15 17 8 12 16 9 14 14 17 18 8 10 12 12 13 11 10 7 11 11 11 12 15 8 17 19 11 11 14 12 19 10 13 7 12 11 21 13 13 11 15 13 13 10 19 12 14 19 12 14 17 17 14 7 10 14 13 10 20 7 11 13 9 13 16 12 9 10 12 14 13 13 13 10 13 18 10 16 16 8 10 11 16 12 9 15 13 19 14 16 12 13 12 17 10 12 8 10 13 11 15 7 11 14 5 20 11 12 17 11 8 14 16 19 20 21 8 11 20 14 14 11 9 17 18 21 15 10 13 14 17 12 13 17 17 9 15 12 16 8 9 17 14 15 11 14 14 11 13 8 15 14 13 13 12 9 12 13 14 11 14 9 12 11 9 8 19 13 9 10 11 14 19 14 11 12 17 15 10 20 11 14 19 13 15 14 9 5 13 10 15 20 13 7 9 14 9 19 18 16 9 18 7 11 10 17 10 7 9 9 17 12 12 14 13 19 15 7 20 11 14 10 15 8 17 7 13 12 16 11 17 6 11 11 8 17 7 18 18 14 7 14 18 20 18 11 12 7 8 17 16 11 17 13 9 13 8 7 9 16 18 11 19 9 14 17 20 12 11 11 18 11 23 10 6 12 18 15 13 20 13 15 15 14 15 19 13 14 12 10 14 13 10 7 12 9 12 14 12 14 14 11 14 13 14 16 20 10 9 19 13 10 17 13 8 11 6 13 11 17 12 14 16 15 11 14 13 8 14 16 13 17 18 9 11 10 8 20 14 8 12 17 14 14 14 15 8 12 20 12 10 8 10 16 15 8 8 7 12 13 17 24 10 10 10 17 7 15 9 15 15 13 10 12 19 14 12 13 10 11 14 18 19 13 16 16 9 20 13 13 13 19 17 13 8 9 18 11 17 14 12 13 8 5 20 18 15 16 13 16 4 12 9 15 10 10 19 15 7 12 14 8 7 10 11 13 15 21 11 15 7 16 12 15 9 14 8 18 10 14 17 20 11 12 10 13 15 14 12 22 11 13 17 13 13 10 19 19 16 15 14 12 16 14 9 12 11 18 10 11 11 19 7 16 10 17 10 15 12 7 10 10 12 15 10 14 14 8 10 15 13 14 13 10 11 18 16 11 16 16 9 12 9 15 11 13 14 11 11 17 20 18 15 14 18 16 10 16 21 12 11 12 12 7 12 10 13 13 14 17 9 12 8 12 13 14 16 16 15 13 14 17 12 5 13 13 12 21 7 13 21 15 13 12 15 21 7 12 14 20 12 17 10 12 16 14 10 12 6 14 12 8 12 9 14 20 9 17 8 17 11 9 10 12 18 11 9 9 13 17 14 14 25 10 12 10 12 12 11 13 11 11 17 16 18 11 17 9 12 10 13 15 9 15 14 13 10 13 15 15 15 13 14 12 11 18 18 14 9 15 13 12 11 17 11 7 11 10 14 16 12 18 14 13 17 16 8 13 14 17 16 9 13 11 16 9 21 16 13 10 9 11 7 14 16 13 15 11 16 14 15 15 14 12 16 11 17 11 12 21 16 9 13 16 17 22 11 11 8 18 8 13 13 18 11 9 9 12 12 16 22 13 13 14 9 17 19 20 9 12 10 17 14 10 14 16 13 14 17 8 11 10 12 15 12 10 10 13 9 10 19 12 7 15 17 10 17 11 11 12 16 22 15 14 13 12 19 18 10 11 12 16 17 10 8 9 9 9 10 20 16 8 10 13 9 9 15 15 20 12 14 11 12 17 20 8 21 14 12 13 15 11 6 15 17 13 11 8 15 21 16 8 16 20 6 18 11 14 5 16 13 12 15 12 8 15 9 13 8 12 7 8 14 11 22 13 13 16 18 12 11 17 7 12 14 16 12 13 17 8 11 16 6 12 7 6 12 10 15 11 16 11 17 11 20 12 18 12 14 20 20 9 15 17 16 17 12 13 12 8 12 18 14 21 11 12 17 11 10 12 10 14 12 12 14 18 7 9 9 17 6 11 15 16 16 14 14 14 9 9 10 16 20 13 9 11 10 16 18 23 15 13 9 10 11 10 7 17 11 11 17 7 12 13 10 12 14 16 15 11 23 12 18 11 9 18 16 18 11 12 19 14 13 12 18 11 17 15 8 14 12 13 8 11 14 11 13 11 11 11 13 12 11 13 16 8 18 16 19 10 13 10 11 7 19 14 21 14 21 11 11 7 18 10 11 10 10 14 15 13 17 7 14 8 12 11 11 6 16 17 13 17 13 13 11 8 11 10 13 19 12 6 10 16 16 16 14 19 10 11 10 8 13 10 12 18 7 10 13 13 17 11 10 17 15 10 15 18 15 22 10 17 17 13 21 12 14 25 20 7 18 12 20 17 14 14 21 20 19 11 16 15 12 12 14 11 10 9 14 12 20 12 13 13 14 10 18 19 12 12 17 16 16 10 12 12 15 14 19 10 21 14 7 15 15 10 9 8 11 14 12 16 13 14 15 4 13 19 20 18 15 23 12 15 17 17 13 13 18 13 12 10 15 18 12 14 17 6 12 17 16 16 19 15 9 15 12 12 14 12 17 18 15 15 15 18 12 17 18 13 7 12 17 16 7 10 18 10 5 20 19 4 14 19 11 11 15 19 14 21 11 7 12 15 11 23 11 10 10 12 16 15 8 12 17 18 15 10 14 16 14 10 2 16 19 11 25 12 11 16 25 10 12 12 10 12 14 15 18 18 14 15 11 18 15 8 16 11 26 14 8 8 12 10 12 18 10 18 12 12 8 14 13 17 15 15 16 20 24 22 18 25 33 27 23 30 16 20 10 12 17 11 14 16 13 21 12 22 13 19 20 11 19 10 13 14 12 12 13 13 18 8 17 10 10 12 17 15 12 16 12 12 14 12 8 16 14 20 17 11 22 16 21 15 22 13 19 16 17 14 23 12 16 15 13 14 11 14 12 11 12 15 9 15 15 10 13 12 13 18 10 10 17 16 11 10 12 15 19 10 14 8 27 16 13 9 9 10 18 16 20 15 12 9 20 18 12 15 12 16 10 18 11 14 18 17 17 15 11 20 16 15 13 8 8 7 12 13 12 3 10 12 16 12 14 15 16 10 16 15 13 15 9 14 18 11 14 11 12 14 11 10 11 19 16 16 17 10 13 16 8 19 16 15 22 10 20 16 13 15 13 16 14 12 17 9 16 11 13 15 13 10 12 16 8 15 13 13 15 9 21 13 11 10 11 16 16 12 15 16 10 12 16 18 20 16 20 12 11 17 19 9 15 17 15 8 9 11 11 16 14 13 11 13 10 12 9 16 15 16 16 11 15 19 14 15 11 13 8 15 7 11 11 15 18 12 13 11 16 12 17 15 16 17 15 12 11 11 12 17 5 13 15 15 5 9 11 17 20 16 16 17 14 13 10 15 10 15 14 16 8 12 9 7 20 16 17 11 11 19 14 14 13 15 11 12 14 16 10 17 15 15 8 15 17 13 14 16 18 20 16 16 16 14 14 17 11 9 14 11 13 17 12 15 10 14 19 20 6 14 14 20 15 11 15 11 7 10 19 13 15 14 17 15 17 15 19 22 7 15 18 10 12 16 13 16 16 10 14 15 18 10 20 9 14 16 11 5 15 11 17 15 12 13 9 12 11 14 7 13 8 11 19 6 11 15 15 11 11 7 12 20 13 12 15 9 11 14 13 16 14 14 13 14 9 12 16 18 13 20 16 12 9 14 11 12 14 9 17 13 15 13 11 21 12 8 17 18 14 13 12 19 9 9 11 22 13 11 12 14 10 7 16 8 17 10 14 15 18 14 13 19 17 12 16 11 18 17 15 6 13 20 15 8 10 11 17 19 14 12 20 20 14 18 12 15 12 24 13 13 8 10 14 16 10 14 10 14 16 15 18 12 19 8 8 17 16 12 22 13 12 13 15 25 20 16 15 19 12 15 11 12 13 10 18 16 11 18 15 14 18 20 17 22 14 21 10 15 20 20 13 15 9 21 17 19 9 11 18 18 16 8 9 11 10 10 11 15 10 13 13 24 14 11 17 18 14 21 8 16 16 13 13 17 17 24 12 12 5 20 18 14 23 15 15 28 15 20 13 18 17 15 18 17 18 17 18 25 22 22 19 15 19 23 19 17 23 28 27 21 19 16 21 16 19 16 20 26 24 16 24 19 28 30 21 21 23 23 20 15 18 20 14 26 19 19 24 21 22 22 24 26 20 23 31 29 15 25 27 28 24 19 22 14 21 33 21 23 21 22 27 26 24 21 28 29 16 24 26 17 23 20 18 28 20 17 18 23 28 19 22 20 17 25 22 20 17 18 24 25 21 26 16 28 18 31 20 22 30 17 25 21 20 29 24 21 23 24 25 15 25 29 26 14 23 22 16 26 28 27 27 28 22 35 36 23 20 21 22 24 28 23 19 25 30 21 20 26 19 24 29 27 23 24 29 30 32 28 21 32 15 27 17 25 26 29 24 31 27 25 30 32 17 22 23 22 24 33 24 35 23 26 23 24 26 24 30 29 29 30 28 34 32 36 18 19 30 28 39 34 28 20 39 27 24 32 15 38 30 39 39 41 37 26 34 19 33 24 30 30 29 24 15 20 33 23 41 32 27 43 31 31 38 35 33 28 39 31 30 31 29 35 33 38 34 34 34 27 40 36 34 30 35 34 26 37 26 42 35 32 33 27 51 36 47 41 36 43 59 56 48 47 67 65 66 81 61 77 58 68 88 65 74 77 74 78 81 79 90 116 98 96 90 91 108 107 110 135 115 133 110 124 118 99 131 124 122 121 127 126 133 137 152 157 126 153 150 160 185 192 224 260 312 298 352 446 516 622 728 972 1440 2127 3473 5750 8464 9947 9470 7476 5343 4042 2875 2104 1727 1354 1157 973 947 819 706 624 639 598 702 745 967 1318 1993 3041 3888 4452 4311 3758 2988 2292 1761 1250 1030 868 695 559 476 427 370 341 280 285 209 205 194 177 181 141 149 134 126 101 115 118 93 90 85 96 82 73 79 74 78 60 64 83 81 45 62 67 68 65 63 65 51 50 39 42 53 45 60 54 43 36 39 44 59 32 46 52 39 41 37 27 30 37 46 40 33 42 31 33 40 32 40 38 37 38 32 28 31 29 38 25 29 33 29 31 44 38 29 32 33 42 24 29 42 29 31 33 27 25 34 33 20 39 38 35 32 30 31 22 32 30 35 28 29 23 27 28 37 28 22 30 21 29 33 27 19 31 27 24 33 26 26 27 18 21 38 20 34 32 27 23 28 24 30 25 38 25 29 28 20 20 31 32 27 23 27 19 20 22 28 19 30 18 20 23 23 20 28 24 16 26 24 21 27 26 17 27 21 21 11 36 23 27 23 23 24 17 20 29 24 26 23 25 25 19 27 20 32 23 23 30 30 32 26 19 20 34 18 27 26 16 22 15 24 18 21 17 19 25 23 26 19 26 22 29 19 29 20 19 13 18 28 28 20 13 18 19 18 22 31 28 16 19 13 16 26 27 26 25 21 20 18 18 20 22 22 20 20 15 22 29 21 17 17 26 23 23 21 25 20 20 29 21 18 26 22 19 22 15 23 22 18 13 22 22 24 28 20 14 16 21 19 19 24 15 15 21 26 20 28 18 19 19 24 15 18 28 17 17 20 21 24 19 26 16 23 22 15 26 22 14 18 20 18 15 15 18 27 12 22 11 18 21 21 20 9 19 16 7 22 17 21 26 17 18 29 20 18 20 19 18 17 17 18 24 24 20 17 16 21 18 11 12 17 14 16 9 21 16 20 12 18 14 20 20 26 21 17 14 9 26 9 18 22 24 21 22 18 17 22 18 20 13 17 12 27 19 28 21 13 20 25 23 8 20 15 24 22 23 17 16 19 13 20 18 18 23 11 11 25 17 20 19 18 14 18 25 26 23 16 17 27 26 17 19 16 19 20 22 23 18 14 11 20 13 27 16 21 14 21 22 24 22 9 15 20 17 17 15 15 20 22 17 22 15 24 16 19 13 18 19 22 21 15 8 17 18 24 19 9 14 11 15 22 24 17 11 18 15 24 21 12 15 16 19 16 21 22 26 18 13 20 12 20 19 26 12 20 16 19 20 12 17 10 23 11 16 7 19 14 21 26 7 21 17 14 16 20 16 19 16 14 16 13 12 13 22 17 14 11 14 20 17 17 21 17 12 15 10 17 18 17 8 19 14 17 19 21 21 15 20 17 20 16 17 9 18 18 18 15 15 13 22 17 11 8 12 17 18 9 15 20 20 18 21 9 22 20 19 15 23 15 22 10 18 15 14 22 13 10 17 13 19 13 18 16 11 19 15 12 13 12 20 17 9 15 19 12 16 8 15 23 9 23 12 13 19 20 16 14 19 13 13 14 21 20 15 18 15 13 22 12 18 16 19 10 17 16 14 16 17 20 19 19 18 15 25 14 17 13 17 12 17 9 23 14 13 14 9 21 22 15 19 21 10 24 15 15 16 20 13 21 14 22 12 11 18 20 19 14 7 16 19 16 22 25 21 14 21 22 21 19 17 13 12 13 10 16 26 11 24 22 10 17 17 26 21 18 17 29 15 15 21 16 16 15 22 25 12 17 16 13 20 16 20 18 13 16 16 16 11 15 19 15 28 14 16 26 15 14 15 15 18 20 13 14 14 13 12 8 21 20 15 12 25 19 19 20 15 8 14 14 16 20 21 20 16 28 13 23 21 15 14 18 19 11 21 21 12 25 17 11 19 20 18 19 21 29 24 16 19 8 19 13 25 12 21 16 11 23 13 16 17 18 16 10 18 20 16 11 18 17 8 12 20 24 16 19 9 12 20 16 21 19 12 14 15 13 17 20 13 11 21 22 17 23 17 10 23 21 19 14 15 15 14 14 14 14 11 20 17 20 20 16 10 16 17 12 14 14 12 15 20 9 15 12 11 14 14 11 8 13 11 18 16 18 16 8 15 16 14 17 16 9 11 14 15 14 17 15 18 14 16 15 11 17 20 18 13 20 13 12 16 9 14 17 16 18 16 12 15 20 24 13 7 19 13 10 19 20 17 10 16 18 12 19 12 15 13 15 17 19 12 11 12 10 18 21 14 15 17 15 12 15 19 15 10 19 12 10 10 15 10 13 12 12 14 13 14 17 19 11 19 19 12 20 16 18 11 17 19 10 10 23 11 15 17 18 13 11 23 11 15 15 14 17 15 12 15 14 21 15 9 16 13 19 12 9 10 10 16 12 14 13 17 11 11 17 16 13 13 14 24 14 9 12 11 11 17 16 23 20 18 14 15 18 13 17 17 19 8 14 13 25 14 14 12 23 10 15 8 22 17 10 13 17 12 14 12 15 25 13 19 19 13 10 17 9 18 11 12 21 19 11 14 11 22 14 14 10 12 8 11 22 20 13 17 25 11 19 12 18 6 16 19 13 14 9 11 20 16 13 15 10 17 22 13 12 22 12 15 11 8 10 20 10 16 18 17 15 15 15 13 7 12 13 20 9 13 8 13 13 15 19 13 20 18 18 14 9 13 12 18 14 13 7 15 16 9 29 16 12 18 17 23 20 10 15 17 13 14 13 9 15 19 7 20 19 15 16 20 16 11 12 17 8 13 16 14 12 17 22 13 11 10 27 14 9 18 14 13 17 10 11 20 9 16 10 17 11 13 15 13 11 14 17 17 17 11 17 15 12 14 7 16 21 21 19 11 12 14 14 24 14 15 18 19 13 18 13 21 15 16 18 17 11 16 21 12 16 18 12 11 13 8 10 14 12 13 19 20 14 11 22 10 15 11 15 19 5 12 15 15 11 18 13 18 14 16 13 9 15 19 14 25 20 16 15 16 9 11 13 11 14 7 10 17 12 11 10 15 8 13 11 16 12 12 12 17 15 12 17 14 10 11 10 16 10 14 16 19 20 13 13 18 15 15 13 10 13 15 17 13 19 19 12 18 11 7 17 21 31 9 9 13 16 13 20 14 15 13 10 13 16 10 21 16 17 13 9 20 14 13 27 17 9 18 16 17 18 20 15 13 18 10 14 17 13 11 20 12 11 11 19 14 10 15 12 11 9 11 14 20 10 14 9 16 9 15 17 15 12 9 22 9 10 16 10 24 11 14 21 18 15 16 15 12 12 16 14 18 15 21 13 11 15 15 18 11 16 19 15 7 17 12 12 19 14 13 14 12 11 11 18 18 25 17 19 20 26 19 9 12 10 15 15 10 11 21 19 17 21 14 15 12 11 15 17 12 15 8 17 15 20 15 8 13 11 13 12 13 14 12 13 11 19 20 8 15 17 15 10 16 10 15 15 7 14 13 18 11 12 13 16 18 14 19 14 5 19 19 18 20 24 14 10 20 14 7 17 9 16 13 20 9 12 14 19 16 19 15 13 8 15 12 11 11 11 14 12 18 14 12 16 11 12 8 12 14 14 19 11 16 14 17 10 15 13 9 10 19 13 19 16 12 16 11 10 13 13 4 11 20 10 12 13 10 14 17 13 16 14 11 8 13 11 12 11 17 16 13 20 20 8 13 12 17 9 12 11 11 9 23 12 13 8 14 12 12 15 14 8 14 9 15 12 14 18 18 10 14 10 14 19 15 22 15 14 10 14 18 17 14 15 11 11 14 14 8 15 21 18 8 13 13 13 19 12 12 15 13 19 11 11 16 16 10 11 15 15 14 15 15 11 9 13 7 11 14 17 13 12 17 15 7 8 11 18 14 14 17 14 11 14 13 18 15 10 17 11 11 16 17 12 26 19 13 9 8 14 17 11 11 13 6 9 14 19 16 13 17 7 10 17 12 10 16 17 8 16 13 10 11 12 13 17 14 13 8 14 14 8 19 18 13 13 10 14 15 12 12 15 16 15 9 20 9 9 10 10 8 14 10 18 11 12 10 17 18 12 13 9 17 19 16 18 11 16 14 18 11 8 14 12 10 8 19 15 17 14 8 19 16 17 17 22 18 9 10 14 13 9 14 14 12 8 7 12 23 16 14 10 12 11 16 12 12 10 15 17 15 15 19 15 16 19 17 13 17 10 17 10 11 16 16 11 13 8 18 14 21 11 15 4 13 12 16 11 18 18 10 13 11 15 21 8 13 9 22 15 16 10 12 15 11 15 21 11 10 13 12 14 13 11 14 10 7 12 13 14 9 23 11 10 9 19 10 16 10 10 13 9 13 19 11 11 16 17 19 22 13 12 10 8 11 16 18 17 22 19 16 10 10 15 10 11 15 13 12 14 12 11 17 13 11 15 12 21 14 15 17 11 15 17 10 7 13 21 7 18 7 6 11 13 7 7 14 22 17 17 13 13 17 19 10 18 23 9 16 12 11 14 8 12 17 13 12 17 18 11 20 11 16 13 12 6 12 14 11 12 13 14 9 12 10 13 10 22 20 13 9 18 20 8 10 9 10 13 12 12 12 10 19 8 19 16 19 9 15 16 12 15 14 16 13 12 13 15 21 20 10 8 10 23 11 10 10 10 12 10 15 16 7 15 10 18 10 18 14 12 14 9 12 14 12 10 12 15 14 8 12 13 8 12 10 19 12 14 15 14 10 7 12 13 16 12 19 10 16 4 17 7 16 16 10 9 13 10 9 14 13 9 10 10 11 11 17 19 22 15 15 13 17 10 19 14 12 13 14 13 13 14 19 15 16 15 9 16 12 12 9 9 17 12 10 13 10 14 13 12 14 10 19 13 12 15 17 12 13 14 14 13 12 23 13 11 19 10 11 15 15 20 7 19 17 16 10 14 12 15 14 9 12 10 11 19 12 13 5 12 17 16 14 14 22 12 23 17 20 14 11 16 8 14 24 11 8 14 11 12 11 17 13 13 7 12 12 11 14 15 11 16 12 12 13 10 16 16 7 7 10 17 9 11 16 12 13 15 16 14 15 16 13 16 9 9 17 13 11 20 11 18 15 13 17 10 6 15 9 18 9 17 11 20 19 15 19 9 9 7 12 14 16 13 17 11 15 7 14 16 11 14 9 14 7 18 14 12 17 14 11 12 17 9 9 14 15 13 17 11 10 9 10 14 16 10 12 15 13 16 11 12 12 12 18 14 5 12 11 13 14 10 11 18 11 13 14 9 10 10 7 10 11 3 12 13 17 10 14 15 13 9 17 7 13 9 17 17 10 13 13 14 15 16 13 17 11 8 12 10 12 15 18 13 19 17 16 11 15 15 9 14 13 16 9 11 8 12 19 17 14 5 13 15 15 16 16 13 13 8 17 7 13 17 20 16 15 16 12 13 13 16 16 16 6 16 10 14 19 12 6 13 10 19 16 20 16 8 11 7 14 12 6 13 13 8 10 14 14 13 16 20 14 10 12 8 10 16 18 17 11 10 13 18 13 12 13 10 7 8 16 9 14 11 11 12 16 12 15 13 10 12 11 6 8 15 11 13 11 9 12 18 18 13 13 11 12 11 16 13 15 8 11 10 16 8 15 6 11 14 11 5 10 16 10 13 10 15 11 11 13 16 17 17 13 11 13 6 18 18 12 10 11 15 16 13 10 9 6 11 11 18 11 10 12 16 11 9 12 11 13 11 12 11 15 13 12 16 8 11 18 12 5 13 14 7 13 16 16 12 5 13 16 14 11 15 18 16 18 18 17 9 14 16 14 18 19 6 14 7 13 14 15 13 11 15 12 18 12 11 14 17 12 10 15 10 13 10 9 13 10 17 11 9 11 15 15 16 14 15 13 12 14 13 14 15 8 16 11 15 10 11 14 12 9 16 12 15 19 18 11 23 12 15 9 12 18 9 8 21 5 12 8 15 11 9 16 15 16 13 17 8 17 12 10 8 12 13 11 11 10 14 8 20 16 11 11 13 10 8 15 11 10 16 13 21 14 16 6 17 10 17 22 10 12 10 12 12 15 13 14 14 10 18 10 8 9 8 16 13 10 14 6 9 15 12 13 9 17 17 11 17 12 8 13 12 13 16 11 6 14 16 13 13 13 9 13 5 14 15 14 16 9 19 8 15 17 8 15 15 16 11 13 19 8 11 9 14 13 12 9 23 15 12 15 16 8 16 16 12 20 18 13 16 9 11 8 10 13 18 17 14 12 14 7 10 20 7 11 15 15 11 17 22 18 8 12 10 7 14 17 12 10 25 17 16 10 11 9 14 9 8 22 15 6 9 13 12 18 9 8 16 10 10 17 12 8 7 10 17 11 10 18 9 13 17 15 14 16 10 11 13 14 17 5 11 14 11 16 18 11 19 15 20 16 10 16 18 14 13 12 21 12 18 17 8 17 9 11 8 10 11 9 13 11 7 8 10 13 7 16 7 5 8 9 9 10 9 11 10 12 11 15 14 24 8 8 12 9 6 10 8 16 17 13 11 15 17 16 18 15 9 10 13 19 15 17 12 11 13 7 12 17 13 15 12 13 14 11 16 9 8 7 12 19 15 17 14 12 13 7 14 13 13 10 19 18 12 15 15 9 7 15 16 15 12 7 11 17 7 7 9 11 9 11 17 16 13 7 9 12 9 13 8 14 12 23 8 6 11 9 15 11 14 15 10 13 16 10 16 15 7 19 16 14 11 12 15 11 8 8 10 13 13 6 13 8 16 6 14 11 6 16 12 17 11 15 8 9 7 17 17 15 10 14 10 7 14 15 15 8 12 7 15 14 14 15 14 18 14 10 15 16 11 7 8 6 10 7 16 15 16 9 15 8 7 6 11 13 18 8 7 10 11 9 13 15 14 8 12 13 13 14 11 14 12 19 3 10 10 10 13 14 13 4 15 15 13 8 16 8 10 21 10 13 20 15 15 14 10 14 11 17 10 13 12 15 11 7 12 9 11 12 12 9 13 7 7 17 12 14 11 7 11 19 10 12 15 14 17 8 13 16 13 16 14 12 17 15 13 11 11 8 15 9 11 11 9 11 11 11 15 9 14 14 8 9 10 16 16 11 13 12 12 16 11 7 11 12 13 18 10 10 10 11 13 12 12 11 7 13 15 7 10 9 15 14 14 16 13 9 15 12 14 11 14 10 10 15 15 12 15 12 6 11 12 15 13 14 18 18 15 9 15 14 7 15 10 12 12 11 5 14 13 18 12 11 13 11 7 11 16 9 12 15 15 12 17 13 14 6 16 18 10 10 6 11 14 11 11 16 4 14 12 8 10 13 4 13 13 6 6 12 10 16 17 11 16 20 9 15 9 11 20 11 14 11 17 9 7 12 16 17 14 8 13 18 18 13 8 14 12 8 11 7 15 14 8 7 13 10 10 7 17 11 10 10 13 9 11 15 13 11 9 14 9 11 7 9 14 15 18 18 14 13 18 12 13 15 13 9 11 10 13 10 11 7 13 7 14 12 9 13 10 17 21 9 9 16 11 15 10 14 9 18 9 14 11 15 15 14 7 9 14 11 12 5 16 9 7 7 12 16 10 7 13 13 11 13 9 13 14 8 7 13 18 10 15 12 6 10 8 16 9 9 7 9 12 15 8 14 11 10 12 9 10 8 10 10 13 11 14 15 14 10 9 10 7 12 9 10 12 10 14 9 15 7 8 11 7 12 11 12 12 10 11 10 8 6 16 13 12 14 6 19 11 11 5 23 15 12 11 13 12 14 21 9 10 16 14 14 15 15 19 11 15 10 9 10 10 11 10 10 12 7 11 8 13 9 12 13 6 11 14 7 13 15 16 11 18 14 15 13 7 20 6 13 12 11 10 11 12 13 12 13 12 10 17 8 13 11 15 17 10 9 22 12 14 8 15 12 10 12 11 16 11 14 13 12 14 11 17 13 13 8 17 10 10 9 11 17 13 9 17 11 7 13 20 11 16 14 14 17 8 10 17 16 15 13 13 8 13 10 11 16 10 8 10 19 9 19 13 9 10 11 13 10 8 9 11 16 13 13 13 9 8 7 7 9 18 13 17 14 14 10 6 14 16 16 17 15 10 11 8 10 5 12 16 11 12 16 15 9 9 13 15 12 15 13 9 7 11 13 9 10 12 14 10 12 15 13 18 14 12 10 17 15 11 11 9 11 14 9 11 13 12 11 12 10 7 9 8 7 8 8 11 10 13 15 8 10 5 11 8 14 15 5 12 9 9 14 8 7 7 11 12 18 24 16 9 12 13 8 7 9 11 11 14 8 6 7 10 7 12 13 13 12 8 16 8 6 14 15 15 4 13 8 13 14 13 14 6 19 17 14 16 10 14 20 17 10 9 7 17 11 12 10 11 13 8 9 19 11 9 12 8 7 11 14 12 12 12 7 15 10 8 13 15 14 13 12 20 9 11 9 7 7 8 14 5 12 5 15 11 8 10 9 10 7 20 9 13 7 11 11 12 12 19 14 9 14 11 10 7 16 12 8 13 7 10 9 12 8 8 14 14 6 8 9 14 13 10 13 16 12 12 11 9 11 10 12 12 9 9 13 11 9 11 19 11 11 13 7 14 15 14 12 7 17 12 11 10 12 7 11 8 14 14 10 14 8 10 12 18 9 11 13 10 9 9 8 12 9 12 10 14 7 9 11 11 8 10 13 11 13 14 7 13 16 8 4 11 8 9 16 11 11 9 12 8 12 13 10 5 11 10 9 14 18 17 9 11 3 9 9 13 8 15 13 16 14 14 8 8 6 13 5 7 12 11 18 10 7 11 11 6 14 11 11 9 9 8 14 15 7 12 13 7 14 11 13 13 16 10 8 7 11 13 8 15 11 6 9 13 7 8 10 12 8 5 12 12 9 13 12 12 11 10 11 11 11 10 12 9 12 12 13 11 13 10 9 9 11 9 11 9 8 9 9 9 10 8 11 12 15 7 6 6 8 9 12 5 13 9 12 12 24 11 12 13 18 17 13 12 17 17 16 14 8 15 22 9 11 11 12 13 15 16 18 10 11 8 8 8 13 7 12 18 11 11 14 14 14 17 16 12 16 17 16 5 11 10 9 11 9 15 10 15 8 7 10 11 6 9 7 12 10 7 12 16 14 12 13 12 12 11 11 8 12 16 15 9 9 13 10 15 12 8 11 8 7 10 8 22 11 11 10 11 9 10 16 16 9 12 13 13 8 5 18 10 8 10 11 14 10 12 7 12 14 8 11 12 14 14 11 12 3 14 12 13 10 13 13 5 4 11 15 12 12 13 17 16 14 12 10 15 14 12 5 7 14 15 19 10 11 18 6 14 10 6 8 8 13 10 18 11 9 19 15 9 16 16 10 9 7 13 14 12 9 13 7 16 8 8 8 10 7 6 10 5 17 11 9 8 10 9 11 20 9 11 11 14 7 16 9 12 8 17 9 10 7 12 11 19 15 12 10 8 12 18 8 12 21 14 10 5 9 8 13 9 10 12 11 15 9 6 13 8 14 19 6 14 10 8 16 13 7 11 7 9 8 11 7 11 15 13 13 11 17 7 14 9 10 12 8 14 11 11 7 9 13 4 7 11 5 6 16 15 7 7 9 13 10 8 10 7 14 9 9 8 6 9 11 12 10 11 9 17 8 9 10 8 10 3 10 12 14 13 14 7 14 7 9 7 6 10 9 11 11 18 10 9 11 13 13 6 8 11 13 9 14 14 13 8 10 16 7 8 10 14 6 7 12 12 7 6 10 7 14 10 10 11 9 6 9 4 13 13 11 6 6 14 10 11 11 6 17 6 17 19 8 12 12 13 13 12 8 11 21 13 8 11 9 12 8 8 13 9 12 11 10 13 7 18 9 13 9 8 14 10 20 10 8 10 12 15 9 18 9 12 12 11 13 11 10 17 11 13 12 12 11 15 14 15 12 19 14 8 6 9 12 6 13 17 4 8 7 12 21 8 8 13 9 4 16 10 8 14 10 10 3 8 13 9 9 13 9 11 6 15 8 12 8 11 8 15 5 4 7 8 18 17 19 9 9 8 14 11 13 8 8 5 11 7 9 10 13 18 8 9 9 11 13 9 11 11 12 7 8 8 10 10 15 9 12 13 15 10 11 11 20 6 7 10 9 15 9 6 17 18 14 8 11 13 16 9 3 11 8 11 11 22 14 3 7 10 4 11 9 11 9 10 13 12 12 18 10 9 16 8 16 10 13 13 9 8 6 7 6 12 8 12 8 17 6 8 12 13 13 16 11 12 8 14 23 12 8 14 10 16 13 10 10 12 6 13 11 12 8 12 6 11 14 14 7 7 14 9 14 9 12 9 4 15 11 10 10 10 8 15 9 6 9 12 12 12 7 9 11 13 10 12 11 9 18 11 13 9 9 11 7 4 12 14 13 9 14 9 7 13 13 8 5 16 6 8 11 6 10 6 8 14 18 9 3 17 7 11 12 8 9 11 10 6 5 6 11 6 7 9 10 9 4 6 13 10 13 15 10 14 12 7 12 13 15 16 7 7 7 14 14 4 19 10 7 9 8 8 14 11 8 11 10 8 7 11 10 11 13 10 11 11 12 8 14 10 10 9 12 11 9 10 9 9 10 8 11 12 11 11 15 16 6 7 9 8 7 11 11 10 11 7 11 17 10 12 9 17 9 15 6 11 16 5 12 13 11 12 11 11 9 7 12 9 9 5 4 13 12 7 8 4 9 10 17 7 7 16 11 4 8 7 5 7 14 6 9 7 6 12 9 8 9 9 19 12 15 13 15 6 5 6 8 11 8 9 9 10 9 3 8 10 8 10 15 12 9 11 9 8 9 11 14 9 10 9 16 10 13 8 12 14 14 10 9 10 12 5 11 7 4 9 6 6 6 15 7 8 6 11 15 5 6 7 13 10 15 4 14 16 7 3 15 10 7 7 14 14 10 10 5 8 14 8 5 10 15 11 10 7 6 5 11 14 10 7 8 16 8 5 10 12 7 11 6 10 13 8 8 10 16 9 12 13 14 10 13 8 7 14 14 15 14 8 10 13 9 11 5 11 12 13 14 9 8 10 10 12 7 4 9 13 12 7 9 10 11 7 13 13 14 7 8 10 8 2 8 5 19 6 7 9 13 5 9 8 8 10 9 11 9 3 16 13 16 4 12 18 8 15 11 14 8 9 7 12 12 16 7 11 8 15 10 18 2 9 13 8 15 9 10 13 15 13 14 4 10 7 7 13 16 9 11 8 10 10 10 12 13 6 11 11 11 4 5 11 13 11 7 10 13 16 13 13 11 10 11 10 14 9 8 13 15 13 9 13 11 10 10 6 12 18 5 4 10 4 10 7 14 12 13 12 10 6 8 4 9 8 9 8 9 7 9 7 9 15 11 8 14 10 14 16 12 13 15 13 12 6 9 16 10 14 11 6 10 16 12 7 10 9 8 11 12 9 9 12 9 7 12 5 16 14 10 14 8 14 7 8 12 9 14 8 12 15 9 9 9 6 12 7 7 11 7 9 9 7 9 11 14 9 10 10 6 6 11 14 9 14 4 9 6 9 7 17 7 5 9 12 10 9 14 14 4 8 14 6 11 18 11 10 12 4 11 12 8 13 10 11 10 6 12 14 7 9 18 8 10 6 8 6 14 9 7 7 14 13 15 10 9 12 15 8 8 4 6 10 10 8 10 9 9 7 16 11 13 9 12 6 8 9 11 8 11 9 11 11 8 8 4 10 7 12 9 11 8 12 12 10 13 10 7 9 14 16 10 13 7 8 10 13 7 13 7 11 4 13 10 6 13 11 10 12 10 11 9 13 8 12 8 8 13 13 14 11 8 14 12 10 20 18 8 14 9 14 14 14 9 13 6 7 10 5 8 7 13 14 5 3 8 10 8 12 12 12 5 10 10 8 8 7 10 8 4 9 8 8 11 7 11 10 10 15 7 5 4 13 13 6 9 12 11 10 5 7 5 5 8 8 9 9 10 15 3 7 10 10 10 12 6 5 13 6 15 7 8 6 9 9 4 5 7 7 10 10 7 9 11 11 5 14 6 4 9 10 14 10 14 7 11 5 7 9 9 13 11 18 6 7 6 13 13 5 10 12 8 8 11 6 9 8 12 8 15 8 12 11 12 6 9 14 8 7 4 3 6 8 11 8 14 7 11 10 7 10 6 10 6 7 4 7 7 15 11 9 7 13 5 9 8 15 6 12 8 13 13 8 8 15 4 5 5 10 13 5 8 10 10 7 9 4 8 7 8 8 9 11 11 10 13 3 4 12 11 6 7 5 9 5 9 11 2 12 10 8 11 8 4 12 6 7 6 6 10 16 4 8 7 5 6 9 7 10 11 6 7 13 9 8 12 4 9 8 13 4 10 8 9 11 3 7 8 5 10 8 5 9 6 5 7 11 7 12 6 7 7 10 7 8 4 10 7 12 10 7 10 11 9 5 9 10 4 7 4 9 8 10 4 10 5 2 7 5 20 10 15 11 8 7 6 5 9 6 2 4 13 10 14 10 6 4 2 6 9 9 12 7 9 10 8 10 8 9 7 3 13 5 6 8 9 7 11 8 13 10 9 7 7 12 11 10 6 10 7 12 8 6 9 10 15 6 7 9 17 7 10 7 11 8 7 13 5 6 6 10 11 11 12 10 10 7 5 9 8 7 11 9 12 6 6 8 9 3 3 7 10 5 7 10 7 11 7 6 9 5 8 7 5 6 5 8 9 10 8 4 9 8 1 4 9 12 10 14 15 9 9 14 7 6 9 7 15 11 12 9 8 10 4 8 10 6 4 7 9 8 9 7 6 10 10 11 2 8 2 9 6 8 7 6 8 5 9 10 10 6 8 10 10 11 8 9 7 4 8 6 8 9 14 15 2 14 15 10 5 9 12 10 7 9 9 11 7 9 8 10 4 7 7 8 6 11 9 7 5 8 4 6 11 4 9 6 7 10 8 8 3 9 9 9 4 7 6 6 8 8 12 7 6 6 8 10 9 8 7 9 12 11 9 5 14 4 5 8 7 10 10 10 12 5 7 4 8 9 9 11 12 9 8 8 6 4 9 8 11 11 9 3 10 8 8 9 6 12 7 11 10 6 9 6 9 9 12 4 5 8 10 5 7 10 10 4 5 8 12 2 10 6 9 6 3 6 10 5 6 7 4 8 8 4 6 4 14 6 11 4 11 8 6 11 7 7 15 12 12 6 8 5 10 7 7 10 4 4 9 8 8 5 10 11 12 13 6 5 13 5 11 8 8 8 11 11 7 9 10 14 8 4 6 2 12 3 5 12 8 9 8 3 6 11 8 10 8 8 6 7 6 8 12 9 8 5 9 9 7 5 9 7 8 8 14 7 8 10 7 8 5 7 3 9 11 8 6 9 8 7 2 6 10 11 13 13 11 6 6 8 7 5 7 13 7 6 11 7 7 11 11 4 10 9 8 4 5 7 13 19 10 7 7 14 8 4 9 10 6 5 17 12 6 13 2 3 4 10 3 4 13 7 7 7 11 6 9 6 7 10 2 10 13 14 13 3 6 6 13 5 4 8 9 7 9 9 14 7 11 6 11 7 6 5 16 7 10 7 11 6 4 6 3 9 4 11 10 4 11 10 9 9 10 8 3 7 3 9 3 9 2 5 6 6 6 8 10 7 8 6 6 7 10 5 8 6 5 3 9 9 12 12 12 9 6 5 12 4 9 12 9 8 6 9 7 6 4 5 9 7 15 5 12 6 9 4 5 4 6 6 8 6 4 5 6 8 7 6 13 5 6 11 10 4 16 7 10 9 7 5 11 5 9 7 5 8 2 6 6 9 6 13 10 9 5 9 8 5 14 5 5 9 10 9 5 7 10 10 7 7 10 9 5 8 5 6 4 1 5 5 7 6 8 9 5 4 2 11 5 16 8 10 9 9 7 5 9 11 5 11 12 7 7 11 12 10 10 4 5 7 9 5 5 6 13 8 7 5 11 8 11 5 10 10 6 5 3 9 4 8 7 5 0 8 4 8 7 7 8 3 3 6 11 3 10 6 16 7 6 10 19 8 6 9 10 4 9 4 8 14 6 6 6 13 7 9 9 3 8 6 5 9 6 9 9 10 2 6 9 6 5 10 3 13 4 10 6 6 11 3 7 2 8 9 7 8 6 11 6 8 2 7 7 9 10 11 4 5 9 9 8 8 5 7 10 3 7 4 8 10 9 8 8 16 6 8 6 5 7 4 5 8 4 7 1 7 7 8 8 4 12 9 11 8 8 6 6 15 6 9 3 6 10 9 13 5 9 6 6 6 9 10 11 9 8 7 7 8 6 6 9 12 8 5 7 6 6 9 8 4 13 6 12 6 6 9 5 9 8 8 17 8 10 7 3 4 8 8 5 9 12 7 7 9 7 9 13 5 6 6 10 8 9 8 6 3 9 9 5 7 3 11 5 10 7 6 6 11 12 7 7 12 1 8 8 9 8 9 5 3 10 8 9 3 9 9 9 7 10 12 7 8 5 10 3 8 9 5 5 3 10 6 5 4 7 2 4 7 6 1 8 7 9 6 7 4 9 6 16 2 7 10 6 3 6 6 6 6 12 8 11 10 6 4 6 3 3 6 8 6 5 5 1 8 6 11 6 5 13 6 8 10 4 6 9 10 8 7 6 9 7 5 2 9 8 9 3 6 10 7 6 9 3 6 10 6 7 7 4 13 3 8 11 9 6 7 2 7 9 7 11 6 7 3 2 7 12 14 7 8 6 6 3 3 6 8 5 7 4 18 5 10 6 2 6 8 16 5 5 10 4 7 11 7 12 9 5 11 4 4 7 12 4 7 7 8 4 8 7 13 11 7 11 5 7 6 8 6 5 7 14 6 7 10 11 6 11 5 8 5 11 9 5 6 2 7 5 5 8 4 6 11 3 8 7 8 5 10 3 5 5 3 6 11 4 4 0 5 8 4 10 10 7 15 9 3 2 8 5 4 11 6 6 5 6 9 7 7 9 8 12 6 5 7 9 4 8 9 3 7 8 10 10 6 11 10 7 7 7 2 6 6 8 10 10 5 8 3 11 7 8 3 6 11 10 13 9 10 6 7 5 4 11 11 13 1 6 9 4 4 9 9 9 9 7 9 3 7 6 9 5 11 3 10 6 9 7 12 8 5 12 7 9 6 6 8 6 6 6 5 8 9 9 3 5 5 6 4 9 9 4 6 8 7 10 8 10 9 9 10 8 6 11 6 7 3 2 13 8 4 3 8 3 5 3 3 10 9 12 8 5 13 6 6 11 7 8 7 7 10 9 11 3 5 6 7 9 6 7 4 7 7 8 9 12 9 6 6 8 7 9 10 2 8 3 9 8 10 11 5 5 8 6 12 8 7 7 3 6 3 10 10 6 4 6 3 11 11 7 6 8 6 9 7 9 4 4 8 7 6 5 11 7 6 6 6 6 6 5 7 8 13 10 4 7 6 5 5 5 2 8 5 6 2 10 5 8 5 5 8 6 5 3 4 3 3 6 10 12 6 3 6 8 5 11 9 6 4 3 10 7</counts>
			</dataPoints>
		</scan>
	</xrdMeasurement>
</xrdMeasurements>