File: Data Files/Full/MSS p (6-129, 8w)_01.xrdml
<?xml version="1.0"?>
<xrdMeasurements xmlns="http://www.xrdml.com/XRDMeasurement/2.2" xmlns:xsi="http://www.w3.org/2001/XMLSchema-instance" xsi:schemaLocation="http://www.xrdml.com/XRDMeasurement/2.2 http://www.xrdml.com/XRDMeasurement/2.2/XRDMeasurement.xsd" status="Completed" recordIdentifier="{432100A0-DD3E-44ED-AC8D-029C98A0BAD5}">
	<comment>
		<entry/>
	</comment>
	<sample type="To be analyzed">
		<id>p</id>
		<name></name>
		<preparedBy></preparedBy>
	</sample>
	<xrdMeasurement measurementType="Scan" status="Completed" sampleMode="Reflection">
		<usedWavelength intended="K-Alpha 1">
			<kAlpha1 unit="Angstrom">1.5405980</kAlpha1>
			<kAlpha2 unit="Angstrom">1.5444260</kAlpha2>
			<kBeta unit="Angstrom">1.3922500</kBeta>
			<ratioKAlpha2KAlpha1>0.5000</ratioKAlpha2KAlpha1>
		</usedWavelength>
		<incidentBeamPath>
			<radius unit="mm">145.00</radius>
			<xRayTube id="1010048" name="Empyrean Cu LFF HR (9430 033 7310x) DK437964">
				<tension unit="kV">40.0</tension>
				<current unit="mA">15.0</current>
				<anodeMaterial>Cu</anodeMaterial>
				<focus type="Line">
					<length unit="mm">12.0</length>
					<width unit="mm">0.4</width>
					<takeOffAngle unit="deg">6.0</takeOffAngle>
				</focus>
			</xRayTube>
			<filter id="20010004" name="Beta-filter Nickel">
				<material>Ni</material>
				<thickness unit="mm">0.020</thickness>
			</filter>
			<sollerSlit id="21010002" name="Soller slits 0.04 rad.">
				<opening unit="rad">0.0400</opening>
			</sollerSlit>
			<mask id="22031000" name="Fixed mask 13 mm">
				<width unit="mm">9.00</width>
			</mask>
			<divergenceSlit id="22120002" name="Divergence slit 1/2°" xsi:type="fixedDivergenceSlitType">
				<distanceToSample unit="mm">50.00</distanceToSample>
				<height unit="mm">0.76</height>
			</divergenceSlit>
		</incidentBeamPath>
		<diffractedBeamPath>
			<radius unit="mm">145.00</radius>
			<parallelPlateCollimator id="25020001" name="Parallel plate collimator 0.28°">
				<opening unit="deg">0.28</opening>
			</parallelPlateCollimator>
			<detector id="7010020" name="PIXcel3D-Medipix3 1x1 detector" xsi:type="areaDetectorType">
				<phd unit="keV">
					<lowerLevel>4.0</lowerLevel>
					<upperLevel>11.3</upperLevel>
				</phd>
				<mode>Receiving slit</mode>
				<activeChannelsEquatorial>255</activeChannelsEquatorial>
				<activeChannelsAxial>255</activeChannelsAxial>
				<pitchEquatorial unit="mm">0.05500</pitchEquatorial>
				<pitchAxial unit="mm">0.05500</pitchAxial>
				<readOutPeriod unit="seconds">0.050</readOutPeriod>
			</detector>
		</diffractedBeamPath>
		<scan appendNumber="0" mode="Continuous" scanAxis="2Theta" status="Completed">
			<header>
				<startTimeStamp>2025-06-25T13:23:13-08:00</startTimeStamp>
				<endTimeStamp>2025-06-26T03:03:17-08:00</endTimeStamp>
				<author>
					<name>Instrument</name>
				</author>
				<source>
					<applicationSoftware version="1.6 (94)">PANalytical Aeris Instrument Suite</applicationSoftware>
					<instrumentControlSoftware version="3.0.0 20211014">AERIS</instrumentControlSoftware>
					<instrumentID>2855484</instrumentID>
				</source>
			</header>
			<dataPoints>
				<positions axis="2Theta" unit="deg">
					<startPosition>6.005</startPosition>
					<endPosition>128.995</endPosition>
				</positions>
				<positions axis="Omega" unit="deg">
					<commonPosition>8.000</commonPosition>
				</positions>
				<commonCountingTime unit="seconds">3.520</commonCountingTime>
				<counts 3423 3387 3350 3461 3441 3416 3409 3462 3375 3390 3241 3418 3316 3358 3264 3231 3219 3377 3432 3303 3251 3373 3345 3315 3297 3290 3348 3346 3199 3262 3294 3105 3265 3184 3209 3191 3164 3203 3237 3270 3295 3117 3259 3074 3186 3188 3199 3200 3189 3327 3104 3344 3179 3207 3200 3074 3080 3270 3134 3172 3133 3190 3186 3183 3180 3116 3289 3187 3142 3142 3147 3157 3187 3211 3244 3246 3200 3191 3293 3397 3242 3350 3340 3234 3335 3269 3287 3286 3243 3263 3298 3235 3276 3228 3340 3246 3357 3284 3202 3284 3211 3279 3388 3226 3316 3191 3347 3195 3254 3231 3293 3242 3427 3322 3175 3279 3282 3376 3274 3305 3134 3269 3278 3260 3234 3262 3221 3183 3229 3307 3206 3179 3153 3121 3179 3193 3109 3166 3216 3146 3197 3184 3238 3229 3306 3115 3234 3224 3162 3129 3158 3072 3064 3230 3173 3208 3187 3227 3118 3133 3147 3098 3136 3170 3059 3107 3111 3096 3099 2964 3027 3001 3113 3023 3146 2965 3062 3134 3039 2988 2989 3049 2987 3115 3121 3006 3039 3033 2966 3004 2950 2938 3070 3116 2970 2963 2981 2976 3044 3081 2922 2901 2904 2930 2969 3050 2932 2888 2876 2953 2993 2943 2906 2908 2908 2879 2917 2855 2924 2922 2846 2988 2860 2847 2847 2806 2792 2866 2964 2848 2880 2874 2843 2944 2917 2896 2771 2798 2779 2811 2764 2799 2836 2843 2677 2848 2787 2695 2747 2865 2833 2800 2806 2832 2802 2749 2777 2783 2723 2831 2780 2828 2764 2709 2761 2673 2732 2714 2837 2731 2786 2722 2819 2766 2849 2657 2679 2788 2842 2691 2758 2724 2689 2796 2712 2722 2892 2706 2760 2840 2727 2699 2738 2654 2913 2721 2765 2809 2667 2865 2796 2837 2748 2794 2778 2726 2862 2772 2743 2843 2831 2752 2795 2806 2931 2756 2877 2845 2799 2791 2849 2891 2855 2889 2819 2924 2783 2790 2856 2930 2807 2970 2820 2844 2972 2810 2837 2923 2860 2880 2965 2812 2925 2860 2917 2955 3041 2875 2874 2907 2909 3006 3042 2844 2933 2856 2949 2987 2800 2929 2922 2891 2824 2842 2940 2897 2836 2875 2758 2873 2713 2835 2784 2785 2797 2705 2776 2658 2742 2758 2781 2810 2751 2779 2730 2761 2767 2760 2750 2685 2823 2741 2820 2765 2643 2780 2823 2723 2798 2801 2763 2723 2853 2913 2782 2741 2868 2904 2834 2719 2842 2752 2856 2855 2944 2913 2851 2805 2883 2762 2889 2875 2962 2844 2812 2862 2919 2862 2979 2922 2827 2847 2911 2850 2823 2904 2908 2926 2903 2911 2962 2914 2921 2965 2929 3003 2986 3226 3399 3585 3966 4252 4617 5104 5560 6187 6540 7140 7590 8190 8703 9112 9263 9364 9711 10282 10661 11061 11237 11986 12812 13115 13293 13714 14103 14596 14620 14602 14753 14957 14589 14209 13729 13080 12232 11324 10457 9483 8707 8117 7259 6469 5596 5162 4615 4119 3740 3417 3270 3243 3198 3192 3213 3109 3285 3234 3250 3129 3224 3190 3152 3177 3308 3149 3106 3105 3098 3208 3223 3186 3103 3130 3138 3094 3179 3186 3148 3188 3249 3123 3104 3149 3200 3240 3150 3223 3178 3127 3167 3092 3200 3137 3196 3092 3112 3236 3265 3166 3205 3170 3292 3324 3393 3195 3307 3371 3277 3380 3308 3326 3294 3314 3270 3384 3343 3350 3404 3476 3461 3348 3322 3331 3484 3317 3290 3417 3350 3319 3462 3401 3480 3446 3573 3317 3440 3543 3527 3456 3478 3443 3530 3482 3471 3506 3446 3456 3452 3564 3361 3503 3435 3569 3531 3454 3483 3455 3417 3562 3523 3538 3564 3608 3620 3530 3592 3521 3591 3582 3608 3575 3580 3600 3585 3668 3638 3601 3686 3598 3705 3609 3600 3648 3692 3741 3676 3743 3769 3652 3791 3788 3650 3683 3734 3739 3757 3782 3789 3857 3753 3881 3874 3769 3842 3778 3956 3902 3910 3907 3851 3936 3983 3889 3979 3871 3875 3976 3887 3929 3891 3913 3818 3926 4048 3984 3884 4068 3985 3948 4035 3835 4016 4035 4050 4025 4122 4019 4071 4133 4014 4078 3921 4056 3985 4095 4094 4053 4084 4014 4085 4125 4115 4013 3921 4040 4057 4105 4217 4224 4010 4164 4157 3995 4169 4263 4182 4361 4174 4227 4149 4297 4279 4177 4284 4136 4274 4224 4158 4170 4272 4180 4200 4095 4318 4226 4280 4349 4272 4232 4221 4220 4277 4271 4421 4319 4251 4307 4324 4419 4322 4267 4323 4285 4233 4345 4267 4325 4359 4319 4275 4269 4317 4348 4350 4271 4450 4416 4360 4350 4398 4404 4286 4288 4283 4293 4337 4245 4295 4211 4296 4440 4406 4310 4419 4450 4288 4452 4331 4448 4331 4441 4482 4249 4367 4376 4326 4291 4298 4367 4386 4378 4304 4330 4368 4277 4202 4330 4473 4419 4341 4358 4395 4330 4321 4282 4388 4339 4491 4294 4407 4265 4269 4229 4169 4380 4311 4255 4243 4333 4331 4317 4406 4237 4352 4239 4316 4262 4289 4168 4162 4288 4304 4229 4252 4344 4147 4204 4281 4149 4349 4218 4160 4219 4178 4100 4089 4111 4063 4090 4048 4109 4223 4165 4083 4079 4093 4039 4111 4124 4141 4117 3980 4077 4082 4278 4096 4112 4007 4045 4012 4030 4003 4085 4017 4111 4057 4012 3954 4127 3884 3960 3985 4033 3947 3960 4022 3891 3915 3985 3976 3884 3823 3893 3865 3963 3913 3802 3730 3826 3828 3854 3872 3875 3825 3776 3747 3772 3670 3825 3838 3701 3773 3752 3695 3710 3698 3757 3733 3633 3704 3631 3652 3573 3645 3691 3662 3499 3403 3485 3730 3602 3415 3521 3528 3612 3543 3587 3470 3510 3623 3590 3475 3564 3533 3512 3490 3430 3460 3609 3443 3572 3400 3352 3522 3403 3455 3490 3395 3459 3354 3401 3354 3353 3283 3388 3275 3410 3310 3298 3237 3377 3463 3259 3279 3246 3288 3253 3195 3211 3224 3195 3303 3309 3293 3301 3297 3253 3180 3233 3150 3082 3053 3190 3080 3108 3079 3157 3149 3105 3114 3153 3200 3099 3092 3014 3012 3032 3084 3017 3065 3107 3001 3073 3039 3005 3073 3041 2995 2993 3074 3007 3065 3008 2835 2975 2907 2887 2904 3006 2973 2996 2882 2974 2966 2912 2888 2893 2916 2983 2926 2982 2777 2867 2920 2807 2909 2871 2894 2829 2843 2819 2830 2853 2863 2826 2822 2848 2761 2920 2817 2750 2794 2820 2787 2738 2796 2809 2761 2737 2777 2790 2746 2800 2770 2825 2795 2799 2717 2768 2763 2654 2657 2675 2543 2724 2775 2559 2784 2663 2653 2631 2694 2631 2716 2694 2612 2706 2670 2673 2662 2713 2543 2668 2582 2654 2590 2555 2629 2611 2703 2635 2589 2623 2545 2672 2595 2594 2559 2503 2592 2590 2614 2603 2536 2649 2536 2556 2619 2648 2422 2503 2541 2529 2468 2532 2489 2541 2468 2665 2481 2515 2439 2558 2459 2586 2464 2506 2403 2468 2465 2424 2526 2381 2462 2462 2434 2461 2493 2486 2478 2445 2485 2529 2410 2507 2508 2503 2444 2373 2413 2464 2437 2405 2393 2411 2396 2272 2390 2409 2357 2337 2358 2335 2344 2341 2385 2370 2267 2356 2305 2382 2415 2409 2334 2412 2282 2366 2391 2426 2234 2398 2372 2361 2418 2341 2272 2309 2340 2451 2288 2289 2252 2262 2302 2273 2340 2279 2293 2261 2329 2235 2273 2317 2301 2318 2349 2249 2289 2378 2253 2219 2272 2349 2222 2220 2198 2190 2314 2214 2215 2287 2291 2262 2159 2226 2300 2275 2273 2206 2313 2274 2172 2256 2263 2125 2219 2172 2280 2274 2155 2164 2194 2227 2157 2182 2248 2134 2100 2174 2275 2196 2089 2192 2139 2125 2156 2139 2184 2147 2172 2205 2249 2127 2039 2150 2108 2160 2089 2144 2052 2121 2179 2187 2215 2081 2092 2103 2191 2260 2137 2082 2127 2086 2118 2171 2049 2171 2155 2163 2102 2097 2142 2034 2157 2048 2129 2122 2015 2099 2126 2024 2102 2069 2078 2087 2146 2074 2099 2068 2017 2160 2087 2113 2159 2023 2035 2108 2108 2219 2124 2093 2094 2095 2134 2232 2242 2247 2201 2251 2363 2298 2341 2393 2318 2279 2368 2389 2265 2436 2333 2397 2279 2415 2323 2377 2288 2293 2186 2276 2182 2161 2196 2135 2155 2148 2104 2097 2095 2029 1953 1957 1973 2060 2002 2014 2062 1951 1991 2020 2073 1963 1961 1965 1977 2015 1942 1925 1956 1972 2036 2011 2038 1987 1969 2040 1936 2009 1927 1988 1976 1997 2063 1930 2030 2000 1997 1950 1972 1884 1979 1933 2018 1959 1909 1943 1916 1979 1992 1937 1967 1951 1933 1942 1876 1908 1944 1924 1994 1892 2004 1882 1951 1977 1967 1980 1951 1906 1965 1979 2033 1929 1965 1877 1956 1912 1985 1877 1897 1996 1915 1842 1987 1918 1902 1923 1848 1925 1877 1899 1878 1933 1926 1715 1886 1834 1942 1865 1816 1841 1894 1867 1807 1900 2035 1923 1776 1801 1908 1939 1856 1917 1904 1952 1888 1876 1923 1898 1861 1895 1875 1881 1948 1880 1801 1882 1784 1900 1821 1941 1907 1790 1857 1796 1770 1815 1846 1774 1930 1804 1869 1835 1817 1777 1892 1842 1815 1861 1933 1802 1839 1870 1949 1765 1923 1890 1845 1840 1849 1815 1813 1865 1790 1852 1891 1859 1863 1901 1799 1913 1816 1966 1785 1838 1819 1830 1768 1860 1919 1818 1997 1800 1868 1674 1900 1841 1874 1887 1857 1886 1854 1802 1814 1860 1788 1897 1887 1802 1850 1931 1883 1969 2060 2189 2233 2373 2501 2714 2940 3214 3255 3660 3716 4106 4390 4544 4732 4823 5166 5348 5613 5637 5746 5999 6047 6343 6391 6588 6516 6523 6426 6567 6440 6453 5934 5949 5589 5487 4926 4729 4390 4010 3687 3446 3112 2727 2515 2335 2251 2062 2030 1981 1943 1861 1830 1827 1918 1879 1818 1872 1780 1842 1871 1776 1861 1831 1830 1874 1829 1807 1868 1759 1743 1837 1858 1819 1844 1713 1817 1801 1803 1775 1774 1790 1743 1746 1753 1724 1723 1725 1783 1784 1879 1803 1742 1778 1664 1869 1730 1738 1817 1651 1751 1698 1860 1676 1705 1659 1783 1669 1792 1715 1739 1680 1813 1664 1758 1819 1727 1707 1740 1672 1794 1687 1806 1640 1715 1785 1640 1632 1727 1761 1714 1645 1832 1706 1686 1773 1731 1683 1697 1741 1718 1705 1697 1704 1810 1554 1652 1696 1732 1757 1676 1748 1779 1724 1595 1798 1721 1727 1674 1724 1704 1641 1728 1589 1693 1660 1658 1765 1682 1612 1735 1694 1686 1733 1669 1748 1608 1697 1726 1628 1657 1676 1672 1608 1650 1639 1411 1705 1552 1661 1683 1522 1709 1733 1798 1710 1789 1636 1716 1758 1681 1819 1757 1694 1659 1801 1524 1691 1668 1789 1719 1772 1630 1774 1557 1717 1742 1724 1743 1697 1708 1582 1702 1711 1701 1538 1654 1740 1695 1519 1745 1744 1693 1761 1482 1640 1612 1582 1677 1594 1665 1811 1571 1675 1635 1586 1573 1611 1573 1686 1659 1687 1660 1673 1633 1737 1582 1623 1593 1669 1496 1694 1579 1647 1496 1645 1672 1671 1570 1630 1615 1575 1658 1590 1572 1736 1539 1670 1699 1617 1718 1698 1567 1541 1662 1668 1596 1667 1669 1706 1630 1618 1783 1669 1706 1680 1495 1658 1688 1690 1608 1661 1655 1582 1783 1614 1615 1597 1544 1628 1442 1666 1545 1545 1658 1645 1632 1550 1687 1625 1682 1687 1585 1659 1676 1657 1681 1577 1752 1691 1551 1621 1570 1776 1552 1728 1638 1618 1621 1618 1669 1563 1603 1639 1517 1643 1690 1684 1608 1598 1638 1654 1565 1493 1589 1590 1709 1495 1645 1504 1652 1593 1715 1680 1479 1652 1711 1526 1567 1504 1714 1593 1635 1708 1582 1557 1608 1702 1655 1676 1666 1569 1625 1603 1620 1552 1670 1592 1658 1582 1717 1606 1680 1703 1581 1582 1565 1691 1565 1626 1637 1594 1588 1688 1691 1630 1652 1520 1718 1675 1566 1535 1760 1629 1725 1720 1748 1649 1750 1766 1663 1612 1773 1734 1620 1783 1686 1768 1713 1824 1843 1750 1898 1845 1696 1855 1859 1865 2168 2291 2458 2617 2698 2900 3198 3332 3702 3838 4182 4508 4748 4980 5329 5756 5867 6057 6380 6565 7032 7240 7441 7551 7992 7919 7967 7895 8092 7829 7553 7366 7174 6815 6427 5972 5306 5186 4552 4106 3763 3429 3104 2745 2350 2272 2154 2026 1881 1879 1818 1853 1850 1795 1818 1734 1888 1790 1793 1872 1741 1834 1702 1769 1714 1693 1727 1647 1574 1724 1754 1718 1651 1686 1688 1688 1633 1617 1721 1693 1739 1498 1541 1585 1710 1587 1583 1661 1505 1599 1617 1400 1479 1551 1417 1672 1605 1516 1613 1535 1709 1468 1539 1639 1644 1707 1480 1608 1673 1604 1625 1571 1589 1630 1641 1549 1622 1500 1512 1559 1654 1549 1560 1577 1594 1654 1717 1571 1673 1627 1631 1538 1534 1560 1529 1489 1670 1501 1409 1610 1519 1626 1707 1555 1564 1544 1525 1478 1584 1563 1428 1414 1532 1516 1545 1593 1493 1596 1626 1585 1656 1491 1670 1594 1566 1656 1379 1487 1657 1432 1542 1601 1500 1599 1563 1521 1505 1560 1619 1525 1598 1494 1578 1492 1569 1451 1537 1612 1608 1600 1476 1455 1632 1514 1668 1555 1585 1538 1545 1618 1710 1525 1645 1561 1399 1576 1553 1628 1489 1534 1522 1478 1528 1581 1560 1517 1687 1603 1709 1529 1574 1580 1481 1506 1511 1546 1593 1556 1744 1555 1484 1516 1656 1665 1531 1567 1565 1480 1666 1611 1558 1483 1537 1538 1573 1652 1773 1655 1563 1604 1559 1602 1678 1626 1520 1611 1509 1593 1704 1703 1475 1560 1704 1513 1562 1674 1621 1682 1580 1750 1561 1530 1411 1691 1501 1652 1524 1618 1584 1591 1694 1691 1679 1693 1583 1546 1682 1550 1646 1692 1640 1723 1707 1679 1664 1697 1575 1728 1665 1598 1660 1604 1525 1554 1633 1676 1756 1757 1647 1631 1709 1676 1694 1599 1708 1720 1746 1737 1606 1557 1750 1718 1679 1574 1644 1687 1638 1729 1751 1728 1732 1807 1678 1636 1718 1795 1758 1734 1792 1750 1711 1737 1758 1780 1762 1773 1778 1680 1772 1809 1739 1753 1714 1849 1694 1779 1840 1705 1770 1806 1766 1838 1821 1801 1925 1905 1894 2066 2050 2198 2414 2362 2661 2813 2942 3059 3309 3445 3719 3792 4176 4219 4339 4371 4657 4734 4940 5110 5262 5404 5531 5666 5782 5818 5836 5739 5778 5641 5646 5484 5121 4987 4698 4376 4173 3767 3680 3195 3076 2773 2816 2546 2367 2172 2098 1992 1992 2030 2055 1927 1973 1917 1943 1966 1985 2006 1969 1960 1947 2034 1942 2020 2029 1938 1932 1921 1974 1909 1948 1938 1914 1967 1996 1948 1942 2010 1874 1964 2039 1930 1969 1965 1886 1896 1919 2030 1999 1938 1947 1905 1991 1956 1885 2020 1956 1983 1885 1919 1969 1914 1943 1929 1962 1928 1982 1924 1929 2054 1953 2022 1963 1934 2041 1952 1951 2069 2046 2011 2056 2001 2025 1999 1972 1994 2087 2027 2059 2091 2098 2048 2012 2071 2034 2062 2103 2066 1927 2017 1925 1975 2004 1950 1998 1914 1987 1943 1915 1965 2016 2038 1968 1959 1960 2034 1940 2125 1978 2049 1953 2044 1906 2081 2026 2030 2067 2042 1977 2062 2077 2118 2031 2035 2029 2098 2197 2042 2034 2120 2191 2183 2137 2051 2116 2144 2095 2169 2103 2044 2108 2193 2089 1974 2069 2054 2002 2043 2051 1963 1990 1912 1945 1914 1952 1964 1870 1845 1815 1889 1859 1856 1814 1829 1862 1816 1907 1816 1767 1860 1894 1809 1788 1849 1823 1793 1850 1771 1738 1849 1729 1722 1841 1807 1784 1782 1846 1809 1781 1808 1789 1814 1855 1716 1636 1649 1782 1670 1702 1783 1730 1615 1720 1820 1796 1679 1721 1749 1809 1779 1640 1586 1665 1736 1620 1670 1722 1651 1662 1538 1702 1652 1516 1512 1643 1503 1549 1439 1690 1604 1665 1604 1624 1650 1726 1539 1492 1538 1602 1615 1630 1543 1414 1625 1526 1616 1488 1418 1550 1422 1593 1610 1474 1583 1497 1596 1585 1601 1545 1403 1585 1500 1641 1591 1539 1400 1310 1477 1407 1441 1359 1496 1564 1400 1353 1397 1448 1281 1506 1378 1329 1647 1431 1378 1504 1471 1460 1397 1389 1356 1391 1361 1436 1378 1359 1353 1334 1372 1326 1344 1353 1492 1247 1299 1369 1346 1263 1374 1325 1368 1327 1439 1261 1326 1355 1318 1435 1366 1338 1457 1223 1429 1332 1471 1347 1276 1365 1275 1282 1386 1290 1308 1266 1244 1353 1289 1318 1387 1296 1211 1230 1332 1314 1198 1191 1361 1310 1390 1290 1218 1251 1404 1209 1208 1339 1209 1308 1272 1241 1202 1246 1240 1292 1420 1247 1218 1229 1295 1304 1224 1203 1335 1200 1381 1295 1231 1300 1281 1265 1252 1216 1310 1268 1172 1222 1294 1220 1237 1267 1193 1183 1184 1154 1255 1316 1142 1251 1223 1219 1256 1150 1190 1247 1230 1262 1165 1143 1194 1281 1191 1225 1297 1188 1174 1237 1269 1140 1297 1246 1217 1288 1270 1172 1181 1234 1198 1264 1138 1204 1157 1167 1215 1302 1184 1173 1164 1195 1204 1250 1262 1198 1273 1289 1181 1211 1189 1121 1179 1160 1190 1137 1190 1208 1225 1081 1203 1266 1240 1155 1199 1224 1220 1147 1200 1195 1078 1161 1233 1170 1134 1156 1220 1203 1225 1155 1266 1212 1121 1176 1234 1134 1195 1224 1179 1185 1215 1193 1221 1168 1123 1293 1171 1177 1167 1207 1239 1161 1215 1222 1205 1302 1305 1259 1170 1278 1226 1351 1225 1421 1428 1315 1432 1514 1428 1470 1510 1582 1586 1504 1716 1733 1660 1805 1902 1945 2294 2477 2864 3325 3919 4548 4955 5880 6672 7612 8425 9528 10461 11468 12496 13095 14217 14841 15237 15911 17007 17242 17753 17957 18186 18233 17941 17397 17007 16624 16130 15363 14453 13457 12738 11631 10513 9319 8322 7383 6410 5418 4700 4158 3559 3139 2569 2315 1977 1837 1786 1736 1611 1653 1513 1536 1543 1486 1355 1389 1388 1521 1368 1322 1269 1273 1333 1188 1113 1256 1175 1179 1130 1150 1187 1165 1190 1140 1099 1097 1130 1108 1118 1149 1111 1157 1127 1149 1094 1033 1146 1176 1158 1156 1098 1100 1086 1171 1042 1093 1115 1129 1151 1121 1161 1086 1056 1059 1086 1055 1141 1112 1148 1115 1164 1098 1109 1081 1073 1118 1121 1144 1086 1126 1075 1125 1097 1081 1161 1001 1081 1176 1082 1120 1081 1069 1110 1045 1082 1111 1060 1022 1127 1166 1055 1128 1058 1139 1108 1058 1091 1039 1091 1033 1093 1114 1071 1059 1117 1086 1021 1039 1109 1117 1051 1128 1109 1112 1061 1092 1118 1095 1081 1054 1133 1057 1116 1083 1112 1127 1098 1105 1034 1076 1094 1095 1071 1088 1072 1124 1065 1074 1088 1102 1097 1101 1048 1098 1110 1083 1079 1097 1050 1018 1062 1067 1035 1034 1060 1089 1036 1065 1073 1091 1114 1117 1105 1068 1061 1061 1115 1098 1058 1143 1075 992 1146 1080 997 1102 1060 996 1054 1087 1101 1079 1060 1113 1036 1039 1085 1054 1106 1057 1061 1078 1073 1062 1066 1069 1068 1070 1062 1055 1056 1093 1081 1054 1004 1079 1068 1084 1031 1050 1025 1041 1066 1075 1036 1037 1060 1047 1058 1046 1012 1064 1056 1059 1061 1112 1065 1123 1071 1068 1079 1092 1058 1107 1119 989 1060 1090 1062 1116 1072 1001 1060 1105 1144 1020 1043 1045 1048 1135 1073 1061 1037 1054 1105 1027 1068 999 1050 1001 1103 1027 1093 993 1006 1042 1081 1090 1103 1034 1040 1070 1084 1041 1053 1058 1091 1053 1061 1075 1110 1057 1022 1021 1082 1041 997 1067 1079 1119 1118 1080 1070 1056 1098 1065 1013 1051 1067 1113 1057 1053 1056 1092 1090 1059 1124 1076 1114 1125 1055 995 1090 1060 1042 1076 1017 1086 987 1043 1074 1070 1109 1003 1024 991 1039 1039 1062 1045 1038 1045 1081 1113 1050 1092 1045 1043 959 1068 1014 1028 1036 1113 1121 1118 985 1002 1026 1063 1008 1056 1030 1116 1069 1062 1068 1034 1084 1077 1069 1064 1085 1067 1044 1060 1036 1103 1038 1076 1132 1041 1040 1021 1084 1035 1023 1055 1101 991 1082 1044 1132 1126 1020 1067 1100 1022 1136 1142 1040 1079 1077 1029 1037 1084 1077 1104 1165 1010 1094 1100 1045 1043 1071 1045 1026 1122 1094 1041 1055 1065 1188 1029 1046 1080 1069 1054 1075 1073 1075 1097 1061 1001 1085 1071 1027 1128 1037 1009 1061 1098 1102 1083 1111 1031 1070 1047 1069 1098 1023 1100 1125 1079 1069 1124 1056 1095 1016 1123 1084 1005 1147 1053 1065 1102 1075 1124 1092 1087 1177 1088 1071 1132 1074 1058 1076 1043 1132 1129 1092 1006 1106 1098 1094 1155 1061 1047 1152 1103 1159 1090 1098 1043 1101 1093 1069 1090 1101 1088 1095 1057 1045 1036 1053 1091 1159 1130 1090 1153 1100 1097 1072 1088 1116 1154 1086 1034 1062 1080 1116 1163 1092 1043 1069 1117 1141 1151 1097 1131 1092 1055 1111 1113 1122 1086 1122 1086 1090 1073 1137 1120 1150 1167 1168 1134 1108 1134 1135 1144 1105 1177 1135 1122 1258 1187 1166 1362 1244 1272 1416 1475 1604 1595 1708 1731 1780 1745 1938 1967 2018 2079 2085 2273 2199 2374 2308 2267 2425 2398 2421 2519 2506 2375 2455 2357 2295 2295 2290 2149 2191 2058 1981 1872 1502 1580 1468 1427 1421 1377 1269 1251 1166 1235 1158 1210 1149 1210 1195 1141 1127 1119 1154 1134 1212 1211 1156 1111 1123 1135 1175 1096 1139 1099 1209 1275 1153 1168 1144 1211 1161 1103 1197 1178 1112 1153 1164 1175 1121 1169 1177 1155 1069 1097 1085 1195 1182 1190 1179 1142 1128 1137 1196 1205 1122 1113 1163 1183 1233 1152 1132 1239 1230 1147 1204 1129 1219 1160 1235 1159 1179 1256 1265 1171 1203 1252 1148 1228 1143 1218 1193 1172 1168 1201 1229 1176 1204 1116 1205 1205 1191 1265 1189 1274 1221 1197 1180 1142 1184 1202 1222 1188 1203 1145 1229 1182 1213 1264 1252 1347 1299 1197 1285 1254 1419 1258 1211 1332 1325 1261 1412 1472 1390 1284 1297 1318 1355 1279 1374 1442 1525 1537 1400 1435 1511 1534 1373 1438 1538 1390 1370 1322 1407 1294 1398 1286 1329 1421 1487 1363 1426 1306 1437 1317 1347 1415 1299 1384 1277 1383 1305 1490 1448 1361 1356 1316 1300 1413 1382 1360 1509 1290 1388 1301 1298 1404 1326 1496 1480 1392 1331 1468 1519 1544 1391 1347 1577 1461 1376 1494 1497 1328 1314 1535 1474 1476 1472 1462 1579 1735 1706 1618 1545 1462 1549 1526 1570 1643 1601 1553 1572 1641 1617 1660 1532 1713 1662 1714 1638 1627 1735 1731 1628 1655 1746 1654 1723 1689 1741 1754 1739 1680 1718 1805 1869 1815 1851 1758 1880 1826 1775 1871 1793 1838 1830 1865 1827 1852 1864 1868 1835 1807 1942 1836 2004 1857 1882 1949 1899 1942 1898 1912 1989 1981 2033 1948 1985 1952 2015 2062 2015 2069 2147 2020 2052 2167 2061 2076 2130 2184 2204 2076 2174 2223 2209 2209 2202 2299 2340 2261 2156 2183 2249 2373 2355 2367 2270 2426 2370 2460 2350 2303 2506 2385 2517 2558 2572 2499 2512 2458 2565 2463 2646 2581 2601 2651 2754 2654 2641 2765 2793 2770 2780 2781 2787 2922 2925 3003 2920 3080 3093 2961 3135 3119 3193 3342 3492 3631 3756 3953 4086 4237 4388 4433 4564 4740 4771 4884 4958 4914 4891 4916 5018 4771 5015 4891 5045 5182 5587 5977 6631 7331 8180 9117 10227 11520 12877 14452 16199 18168 20126 21580 23509 25316 27047 28958 30410 32499 33484 34729 36471 37352 38099 38515 38850 39088 38426 37580 37406 36306 35274 33900 32410 30371 28091 26343 24085 21641 20328 18201 16568 15030 14258 13280 12654 12545 13425 14309 15397 16801 18228 20055 21861 23725 26367 28897 31507 33236 35550 37003 37762 37448 35971 34256 32560 30656 29289 26984 24779 22683 20384 18409 15997 13950 12562 12124 11946 11796 11608 11417 11403 11095 10846 10661 10830 10609 10485 10259 10227 9959 10026 9785 9505 9284 9423 8986 8874 8771 8597 8646 8305 8162 8170 8030 7862 7777 7426 7464 7280 6996 7048 6832 6747 6641 6543 6436 6313 6233 6069 6025 5889 5876 5627 5634 5531 5415 5455 5347 5239 5235 4996 4898 4990 4806 4706 4857 4527 4621 4652 4517 4312 4375 4323 4332 4248 4158 4124 4121 4037 3970 3981 3832 3884 3692 3749 3751 3693 3598 3602 3608 3564 3423 3475 3358 3399 3390 3344 3317 3377 3149 3152 3070 3034 3047 3144 3095 2995 3005 3058 2958 2857 2889 2919 2901 2808 2790 2858 2799 2823 2695 2716 2716 2766 2607 2612 2698 2534 2626 2453 2552 2474 2565 2526 2436 2440 2359 2510 2405 2306 2352 2378 2287 2494 2351 2355 2345 2246 2346 2257 2233 2271 2178 2275 2207 2137 2130 2101 2133 2256 2167 2140 2096 2112 2118 2093 2075 1996 2077 2023 2031 1970 2066 2002 1934 1961 1965 1947 1981 1909 2027 1883 1890 1869 1862 1939 1845 1928 1840 1835 1890 1852 1824 1827 1797 1752 1885 1763 1718 1835 1641 1799 1789 1756 1873 1709 1782 1701 1738 1612 1740 1652 1759 1635 1594 1710 1551 1696 1734 1701 1766 1826 1506 1606 1656 1769 1682 1716 1617 1858 1742 1785 1752 1741 1907 1807 1846 1809 1894 1888 1830 1842 1887 1851 1938 1796 1869 1734 1841 1905 1832 1740 1779 1619 1633 1612 1524 1455 1549 1463 1580 1319 1441 1321 1384 1315 1381 1301 1325 1297 1326 1261 1230 1217 1421 1300 1292 1265 1314 1299 1253 1287 1216 1360 1254 1179 1239 1245 1371 1177 1324 1221 1257 1197 1239 1206 1203 1313 1209 1204 1189 1185 1205 1267 1182 1161 1183 1144 1139 1124 1161 1182 1180 1204 1185 1195 1156 1183 1243 1151 1080 1140 1155 1170 1119 1121 1128 1117 1253 1185 1073 1112 1146 1209 1130 1049 1204 1178 1235 1181 1071 1158 1142 1113 1136 1121 1111 1077 1093 1122 1140 1122 1049 1107 1122 1131 1098 1036 1115 1066 1035 1114 1053 1067 1058 1062 1131 1069 1039 1060 1070 1069 1071 1104 1121 1108 1081 1078 1107 1111 1039 1096 1091 1108 1053 1046 1032 1067 1141 1157 1047 1064 1066 1034 1104 1045 1068 1031 952 1002 1000 1014 1078 1057 1046 1054 1021 1025 982 1057 1059 1028 1050 1021 1052 1053 1006 1046 1110 1018 1042 1064 1045 1099 1037 1057 1037 1052 1046 1028 990 1013 1044 1101 989 1008 1018 1044 1043 1007 1081 1150 1049 1054 1053 1171 1086 1054 1124 1159 1152 1050 1124 1178 1098 1126 1063 1165 1185 1159 1127 1198 1153 1066 1131 1138 1144 1136 1134 1147 1082 1044 1030 1068 979 1088 1038 991 1035 954 1021 944 993 982 1038 945 1002 998 977 1029 982 998 969 941 947 997 1005 976 958 1008 986 963 1015 949 965 978 977 992 1015 979 922 991 1014 956 1002 965 966 965 936 942 1011 1011 990 1071 965 941 960 939 961 904 944 973 916 990 927 992 867 1000 958 942 960 954 928 936 915 909 908 838 917 956 962 999 940 1031 959 941 931 939 935 903 912 976 931 947 902 900 981 886 931 987 931 917 899 902 938 859 945 941 968 906 945 950 961 942 925 922 945 953 869 893 915 896 862 965 946 927 909 953 934 933 977 936 957 943 908 898 916 896 948 889 1004 988 917 944 1001 973 971 934 1003 960 1012 973 897 916 994 944 929 935 958 961 1002 1001 963 924 1003 942 1017 961 947 941 996 961 883 945 885 933 920 978 922 938 932 896 889 932 831 901 917 923 846 869 870 892 898 939 964 860 972 927 886 901 937 950 905 896 903 934 877 907 916 886 922 924 936 890 954 901 859 962 929 937 1011 1005 886 863 943 931 870 927 883 880 892 878 882 922 873 919 898 856 920 897 938 988 871 879 860 964 886 905 919 853 869 905 883 945 911 951 907 868 883 913 916 917 873 916 903 844 958 908 937 884 831 889 896 862 897 923 935 933 931 935 939 895 927 871 930 901 928 929 1012 934 897 942 952 883 871 923 935 924 919 916 872 921 986 863 944 845 932 846 925 901 899 926 918 860 956 920 877 954 925 891 884 883 894 866 887 897 895 940 945 928 878 900 904 873 906 910 870 915 930 896 900 858 908 878 919 855 932 906 953 913 837 905 873 876 931 875 962 962 927 853 881 838 875 919 926 891 933 912 891 885 906 898 878 941 928 930 880 854 903 893 868 876 921 872 874 899 864 868 946 886 979 877 866 933 897 960 894 938 873 915 866 968 896 913 963 911 969 875 922 909 963 919 883 905 904 938 924 961 919 895 892 886 890 921 877 880 868 913 868 901 975 859 951 903 884 889 896 849 923 885 925 940 902 866 940 898 873 906 901 931 952 916 877 944 895 908 905 869 862 932 918 862 883 950 950 947 981 999 959 947 1031 994 1018 1075 1025 1082 1095 1184 1111 1172 1101 1157 1217 1240 1230 1158 1214 1266 1219 1162 1228 1166 1213 1140 1175 1183 1169 1288 1161 1072 1070 1014 1031 1002 955 960 897 975 960 952 878 960 904 883 949 895 982 918 941 939 893 909 924 903 913 911 887 908 885 1033 921 925 898 854 903 907 873 941 849 905 923 923 898 858 955 952 946 946 922 985 914 919 895 954 943 909 922 944 890 849 916 895 860 942 885 911 894 959 888 943 911 847 887 933 906 889 924 889 956 890 905 874 926 910 864 942 905 892 920 939 899 983 949 925 907 906 869 917 912 909 905 956 932 939 977 986 984 1004 1027 1000 1026 1104 1001 1106 1104 1073 1163 1130 1206 1202 1174 1331 1382 1468 1323 1417 1309 1290 1404 1390 1387 1348 1143 1368 1215 1229 1259 1182 1124 1018 1075 1034 1076 956 1024 1001 958 968 932 923 958 948 935 947 922 942 851 883 945 922 939 897 872 940 949 909 958 950 915 945 978 951 894 933 976 873 920 885 939 928 890 971 917 928 936 918 963 905 948 910 880 949 965 877 957 894 910 929 961 889 980 890 972 936 920 931 960 912 946 951 953 943 991 967 980 961 1011 1032 1000 1044 1021 1010 1000 989 998 1034 997 1123 1024 1006 970 961 1007 1042 998 1001 1022 1063 994 1053 992 943 1015 994 1003 965 935 953 968 900 960 968 917 904 934 866 919 934 901 975 880 895 948 851 947 938 914 975 996 968 948 926 937 937 943 937 890 959 1007 913 942 935 898 898 904 918 923 990 994 927 1004 947 965 933 965 1005 984 953 963 941 899 946 955 956 940 960 968 990 950 926 932 945 973 972 914 944 934 994 955 931 965 995 956 932 903 946 1005 966 959 1019 942 927 910 951 925 948 948 924 962 970 893 940 959 942 972 934 960 981 939 957 975 990 949 986 951 942 966 938 1025 972 991 1014 968 977 936 973 964 938 954 989 1036 996 1091 1035 954 995 961 969 989 1011 989 989 1046 1024 966 964 931 971 957 954 941 975 927 947 988 979 1009 951 933 927 1027 959 987 987 976 965 1014 997 1001 957 995 1004 946 978 992 996 1005 992 949 982 1030 1001 1026 984 936 1047 1030 949 1025 1017 984 1065 973 984 940 986 974 959 1005 950 927 988 955 1012 998 982 1008 945 959 1015 976 1021 947 1024 1062 927 956 983 952 962 1004 967 1043 1029 1028 1030 965 1077 999 1009 1025 958 992 1067 1047 939 1009 933 1008 976 1012 1010 1002 968 969 1038 994 1022 917 964 1011 1040 1044 1013 980 952 1021 1008 1016 1043 984 1020 953 995 998 992 1027 1026 1043 939 1008 1005 1019 967 1013 1008 1036 1070 1012 1026 1069 1048 1069 1000 1074 937 997 1001 1037 992 1055 1046 986 1058 993 1002 1018 1065 956 1060 984 1027 1021 1065 1039 1045 986 1030 1035 1011 1026 1039 1014 1004 1050 1014 1035 987 1006 1058 1028 1065 1106 1084 1047 984 1001 987 1017 1045 1005 954 978 1006 1010 1055 1057 998 1061 1010 1041 1031 1066 1012 1061 1094 1027 995 994 1049 1021 931 1018 1041 1011 1061 1049 1035 1018 1032 1070 1080 1062 1005 1007 1059 1086 1078 1074 993 1072 1023 1002 1002 986 1100 1025 1003 1077 994 1076 1032 1087 1063 999 999 1092 959 975 1011 1047 1031 1007 1119 1071 998 1038 995 1122 1054 1019 1053 1077 1043 1082 1025 1024 1045 1004 1101 1078 1103 1022 992 1012 1053 1071 1095 1043 1112 1068 1021 1111 1045 1102 1082 1015 1064 1065 1048 1087 1024 1090 1037 1041 1073 1065 1095 1037 1017 1011 1026 1081 1023 1038 1039 1035 1001 1079 1053 1044 1031 1006 1109 1085 1059 1075 1080 1036 1078 1106 1103 1043 1069 1071 1036 1020 1063 1045 1084 1071 1032 1081 1079 1069 1087 1072 1179 993 1144 1099 1093 1157 992 1117 1104 1076 1077 1077 1074 1121 1078 1116 1091 1024 1061 1053 1040 1101 1074 1048 1113 1085 1100 1152 1086 1041 1142 1092 1076 1122 1078 1102 1139 1075 1120 1127 1136 1048 1073 1078 1058 1031 1089 1100 1119 1096 1064 1080 1113 1128 1099 1116 1185 1104 1118 1142 1123 1112 1120 1104 1125 1056 1045 1071 1149 1106 1090 1086 1133 1057 1100 1138 1063 1081 1053 1084 1149 1066 1114 1162 1119 1113 1073 1150 1088 1140 1132 1083 1060 1150 1106 1073 1133 1125 1041 1135 1115 1131 1056 1093 1124 1094 1041 1084 1081 1171 1145 1160 1100 1135 1104 1111 1157 1178 1109 1168 1067 1108 1096 1155 1092 1155 1092 1190 1256 1110 1135 1124 1123 1123 1147 1151 1180 1068 1148 1193 1108 1136 1200 1160 1111 1103 1131 1130 1144 1164 1184 1124 1159 1168 1166 1144 1161 1219 1202 1300 1236 1144 1172 1175 1191 1197 1174 1162 1195 1208 1183 1268 1205 1218 1177 1261 1219 1190 1245 1212 1380 1305 1240 1291 1306 1382 1342 1359 1630 1708 1935 2142 2473 3077 3670 4370 5297 6278 7113 8262 9074 10347 11106 12069 12643 13487 13787 14394 14591 14440 14172 13669 13074 12674 11770 10827 10137 9256 8418 7536 6624 6165 5518 4925 4507 4160 3784 3501 3046 2835 2540 2429 2176 2006 1862 1598 1638 1683 1451 1290 1332 1379 1347 1499 1371 1318 1292 1273 1357 1407 1272 1311 1242 1224 1236 1254 1208 1214 1261 1216 1235 1229 1190 1188 1223 1184 1152 1197 1195 1297 1306 1243 1201 1141 1204 1233 1198 1121 1206 1225 1180 1177 1309 1189 1187 1193 1254 1236 1216 1228 1203 1161 1292 1297 1188 1259 1189 1247 1251 1197 1145 1177 1243 1192 1325 1206 1215 1255 1255 1301 1267 1185 1270 1174 1250 1285 1204 1225 1227 1248 1167 1228 1185 1155 1212 1292 1329 1220 1195 1244 1231 1339 1243 1182 1198 1315 1185 1219 1181 1155 1393 1258 1325 1204 1356 1209 1277 1179 1142 1165 1227 1191 1229 1256 1284 1150 1264 1293 1195 1225 1243 1262 1217 1257 1269 1424 1199 1203 1229 1221 1291 1423 1253 1261 1285 1215 1312 1288 1162 1412 1320 1261 1227 1292 1231 1288 1360 1227 1224 1346 1251 1361 1271 1273 1163 1375 1209 1236 1296 1260 1214 1375 1436 1314 1388 1322 1399 1275 1292 1319 1289 1336 1304 1251 1187 1440 1295 1287 1314</counts>
			</dataPoints>
		</scan>
	</xrdMeasurement>
</xrdMeasurements>