File: Data Files/Full/MSS p (14-129, 18w)_01.xrdml
<?xml version="1.0"?>
<xrdMeasurements xmlns="http://www.xrdml.com/XRDMeasurement/2.2" xmlns:xsi="http://www.w3.org/2001/XMLSchema-instance" xsi:schemaLocation="http://www.xrdml.com/XRDMeasurement/2.2 http://www.xrdml.com/XRDMeasurement/2.2/XRDMeasurement.xsd" status="Completed" recordIdentifier="{621E8AFA-69EC-4657-BCD3-978C84167504}">
	<comment>
		<entry/>
	</comment>
	<sample type="To be analyzed">
		<id>p</id>
		<name></name>
		<preparedBy></preparedBy>
	</sample>
	<xrdMeasurement measurementType="Scan" status="Completed" sampleMode="Reflection">
		<usedWavelength intended="K-Alpha 1">
			<kAlpha1 unit="Angstrom">1.5405980</kAlpha1>
			<kAlpha2 unit="Angstrom">1.5444260</kAlpha2>
			<kBeta unit="Angstrom">1.3922500</kBeta>
			<ratioKAlpha2KAlpha1>0.5000</ratioKAlpha2KAlpha1>
		</usedWavelength>
		<incidentBeamPath>
			<radius unit="mm">145.00</radius>
			<xRayTube id="1010048" name="Empyrean Cu LFF HR (9430 033 7310x) DK437964">
				<tension unit="kV">40.0</tension>
				<current unit="mA">15.0</current>
				<anodeMaterial>Cu</anodeMaterial>
				<focus type="Line">
					<length unit="mm">12.0</length>
					<width unit="mm">0.4</width>
					<takeOffAngle unit="deg">6.0</takeOffAngle>
				</focus>
			</xRayTube>
			<filter id="20010004" name="Beta-filter Nickel">
				<material>Ni</material>
				<thickness unit="mm">0.020</thickness>
			</filter>
			<sollerSlit id="21010002" name="Soller slits 0.04 rad.">
				<opening unit="rad">0.0400</opening>
			</sollerSlit>
			<mask id="22031000" name="Fixed mask 13 mm">
				<width unit="mm">9.00</width>
			</mask>
			<divergenceSlit id="22120001" name="Divergence slit 1°" xsi:type="fixedDivergenceSlitType">
				<distanceToSample unit="mm">50.00</distanceToSample>
				<height unit="mm">1.52</height>
			</divergenceSlit>
		</incidentBeamPath>
		<diffractedBeamPath>
			<radius unit="mm">145.00</radius>
			<parallelPlateCollimator id="25020001" name="Parallel plate collimator 0.28°">
				<opening unit="deg">0.28</opening>
			</parallelPlateCollimator>
			<detector id="7010020" name="PIXcel3D-Medipix3 1x1 detector" xsi:type="areaDetectorType">
				<phd unit="keV">
					<lowerLevel>4.0</lowerLevel>
					<upperLevel>11.3</upperLevel>
				</phd>
				<mode>Receiving slit</mode>
				<activeChannelsEquatorial>255</activeChannelsEquatorial>
				<activeChannelsAxial>255</activeChannelsAxial>
				<pitchEquatorial unit="mm">0.05500</pitchEquatorial>
				<pitchAxial unit="mm">0.05500</pitchAxial>
				<readOutPeriod unit="seconds">0.050</readOutPeriod>
			</detector>
		</diffractedBeamPath>
		<scan appendNumber="0" mode="Continuous" scanAxis="2Theta" status="Completed">
			<header>
				<startTimeStamp>2025-07-07T11:45:28-08:00</startTimeStamp>
				<endTimeStamp>2025-07-08T10:07:13-08:00</endTimeStamp>
				<author>
					<name>Instrument</name>
				</author>
				<source>
					<applicationSoftware version="1.6 (94)">PANalytical Aeris Instrument Suite</applicationSoftware>
					<instrumentControlSoftware version="3.0.0 20211014">AERIS</instrumentControlSoftware>
					<instrumentID>2855484</instrumentID>
				</source>
			</header>
			<dataPoints>
				<positions axis="2Theta" unit="deg">
					<startPosition>14.005</startPosition>
					<endPosition>128.995</endPosition>
				</positions>
				<positions axis="Omega" unit="deg">
					<commonPosition>18.000</commonPosition>
				</positions>
				<commonCountingTime unit="seconds">6.160</commonCountingTime>
				<counts 3750 3665 3710 3780 3680 3763 3526 3744 3667 3694 3692 3786 3754 3753 3696 3812 3719 3763 3707 3633 3741 3690 3679 3698 3747 3720 3819 3746 3770 3711 3674 3812 3793 3682 3817 3744 3683 3724 3733 3744 3659 3623 3863 3729 3666 3756 3691 3738 3629 3821 3744 3644 3764 3732 3782 3705 3753 3825 3729 3618 3679 3708 3729 3746 3822 3702 3721 3765 3653 3670 3735 3746 3646 3651 3690 3767 3767 3735 3686 3864 3743 3796 3722 3700 3770 3855 3772 3674 3613 3727 3764 3694 3736 3714 3816 3740 3750 3816 3698 3767 3580 3624 3733 3790 3588 3834 3751 3654 3785 3671 3678 3747 3655 3726 3663 3709 3703 3691 3764 3708 3799 3623 3771 3744 3687 3772 3689 3710 3683 3698 3753 3714 3709 3727 3739 3745 3863 3757 3658 3742 3670 3713 3584 3685 3679 3647 3651 3732 3734 3743 3700 3713 3736 3671 3600 3719 3842 3756 3755 3634 3765 3680 3754 3719 3774 3689 3840 3720 3891 3794 3927 3842 3880 3884 4023 4030 4091 4208 4214 4203 4171 4298 4354 4457 4375 4573 4408 4492 4584 4645 4709 4758 4729 4820 4784 4924 4860 4980 4929 4976 5073 5148 5158 5210 5229 5269 5279 5516 5381 5368 5426 5310 5354 5429 5558 5465 5531 5498 5553 5509 5649 5662 5655 5685 5708 5683 5590 5922 5714 5588 5814 5889 5870 5901 5913 5916 5978 5870 5875 5875 5788 6001 5964 5957 6075 6092 5952 6177 5974 5949 6030 6112 6125 6081 6092 6009 6222 6091 6148 6194 6118 6093 6166 6306 6356 6353 6303 6277 6163 6201 6243 6282 6362 6441 6314 6335 6432 6370 6280 6377 6308 6342 6388 6339 6341 6487 6351 6474 6411 6342 6514 6474 6492 6456 6451 6421 6459 6597 6400 6567 6536 6541 6534 6615 6586 6548 6480 6471 6636 6675 6616 6487 6579 6536 6660 6694 6577 6614 6729 6672 6693 6571 6711 6557 6689 6638 6466 6691 6690 6896 6708 6726 6659 6707 6674 6672 6706 6723 6721 6751 6846 6867 6782 6994 6778 6922 6812 6880 6812 6827 6739 7010 7001 6831 7000 7039 7128 6952 6777 6953 6941 6988 6958 6921 6908 6946 6900 7169 6989 6925 7164 7191 7013 7199 7297 7156 7159 7305 7069 7135 6931 7008 7086 7236 7209 7239 7154 7430 7226 7007 7249 7119 7233 7066 7292 7199 7077 7150 7196 7053 7088 6946 7282 7253 7065 7469 7357 7273 7155 7277 7127 7402 7389 7201 7352 7162 7215 7208 7189 7230 7276 7214 7167 7088 7299 7330 7102 7262 7388 7305 7133 7134 7221 7430 7286 7204 7139 7312 7211 7367 7359 7329 7323 7388 7206 7140 7477 7333 7338 7122 7325 7279 7408 7326 7162 7208 7174 7324 7276 7220 7179 7230 7313 7216 7354 7279 7188 7113 7364 7290 7237 7091 7282 7154 7505 7274 7110 7448 7248 7025 7200 7120 7135 7064 7165 7239 7062 7242 7148 7206 7098 7164 7142 6949 7259 7007 7142 6990 7162 6999 7032 7080 7073 7140 6843 7141 7156 7035 6909 7232 6929 6916 6965 7018 6843 6990 6888 6918 6834 6909 6904 7000 6962 6844 6711 6775 6853 6796 6712 6809 6669 6829 6811 6697 6777 6651 6763 6781 6746 6655 6578 6580 6899 6793 6700 6765 6616 6622 6690 6705 6569 6625 6484 6533 6514 6639 6578 6643 6571 6397 6476 6411 6575 6503 6562 6450 6367 6405 6304 6466 6274 6486 6425 6466 6372 6373 6367 6442 6338 6320 6383 6301 6362 6176 6417 6268 6197 6361 6367 6343 6404 6198 6190 6265 6172 6168 6093 6132 6177 6136 6146 6204 6178 6247 5974 6103 5948 5992 6099 6062 6061 6129 6200 6095 6067 6079 6018 5990 5999 5993 6108 5962 5995 5959 5965 5906 5835 5892 5811 5860 5989 5776 5982 5923 5830 5834 5644 5658 5793 5731 5754 5685 5843 5782 5837 5727 5756 5777 5675 5736 5956 5802 5892 5799 5705 5689 5734 5724 5757 5694 5597 5676 5556 5742 5641 5547 5682 5627 5823 5622 5667 5579 5555 5651 5584 5793 5722 5752 5645 5756 5839 6014 5771 6008 6030 5837 5582 5771 5892 5737 5804 5747 5731 5631 5535 5578 5506 5667 5633 5606 5575 5464 5533 5467 5563 5359 5423 5468 5445 5568 5555 5255 5475 5534 5641 5493 5358 5395 5356 5367 5224 5201 5352 5229 5322 5375 5430 5321 5333 5438 5370 5367 5434 5328 5311 5348 5359 5266 5315 5480 5374 5173 5292 5252 5340 5255 5281 5405 5207 5252 5241 5248 5231 5248 5250 5258 5162 5233 5325 5244 5362 5235 5239 5279 5132 5072 5090 5066 5323 5294 5106 5177 5062 5268 5035 5134 5270 5196 5158 5101 5209 5180 5190 5019 5183 5175 5093 5107 5099 5133 4968 5194 5284 5049 5134 5204 5080 5196 5243 5187 4996 5038 5192 5099 5091 5208 5229 5083 5006 4977 4864 5095 5087 5034 5046 4975 4971 5058 5064 5113 5075 5160 5055 4976 4968 5061 4951 4918 4983 4950 4871 4935 5066 5011 4981 4946 4926 4981 4923 4944 5135 4934 4905 4974 4855 4970 4832 5015 5023 5034 4997 4950 5032 4965 4819 4886 4906 5020 4922 4807 4927 4922 4862 4831 4904 4870 4935 4778 4790 4850 4868 4856 4848 4968 5024 4849 4815 4814 4872 4956 4952 4930 4841 4756 4810 4788 4859 4862 4765 4814 4747 4758 4810 4855 4806 4890 4723 4762 4845 4858 4651 4864 4860 4796 4824 4826 4745 4760 4726 4897 4829 4783 4779 4832 4878 4707 4787 4778 4752 4780 4787 4840 4800 4611 4834 4771 4873 4707 4843 4932 4669 4743 4694 4958 4871 4808 4768 4802 4631 4771 4904 4874 4773 4728 4797 4783 4746 4759 4773 4814 4789 4684 4760 4776 4823 4772 4805 4862 4788 4757 4836 4718 4797 4716 4758 4777 4687 4729 4847 4780 4890 4831 4702 4614 4719 4835 4741 4792 4748 4788 4935 4807 4819 4824 4859 4773 4859 4701 4894 4885 4811 4726 4777 4787 4775 4846 4681 4790 4807 4866 4756 4873 4917 4896 4954 4938 4892 4773 4853 4956 4809 4927 4930 4918 4821 4912 4840 4956 4982 5024 5046 5038 5036 4941 5041 5023 4983 5029 5101 4985 5126 5097 5207 5291 5219 5468 5865 6175 6526 6981 7422 7860 8394 9091 9123 10005 10679 11292 12321 12973 13688 14339 14598 15375 15472 15832 16100 15806 16046 16715 16770 16696 17061 17251 17704 18468 19006 19244 20027 20172 21182 21842 22847 23250 24069 24306 25025 25848 25755 26427 26374 27062 27813 27575 27680 27654 26793 26609 25907 25218 24776 23244 22086 20888 19704 18412 17214 16094 14757 13460 12129 10710 9434 8578 7386 6756 6062 5523 5261 5266 5099 4857 5037 4933 4849 4947 5026 4909 4959 4891 4852 4789 4798 4900 4807 4878 4559 4777 4756 4647 4682 4565 4579 4528 4749 4502 4404 4577 4455 4555 4484 4599 4493 4415 4650 4490 4578 4400 4325 4500 4638 4611 4430 4500 4579 4461 4477 4456 4490 4505 4395 4549 4683 4457 4519 4557 4606 4465 4539 4463 4503 4594 4497 4508 4414 4494 4603 4453 4419 4459 4581 4403 4459 4564 4451 4450 4485 4444 4409 4429 4483 4385 4497 4358 4329 4597 4297 4413 4300 4253 4203 4298 4439 4322 4356 4206 4246 4298 4290 4320 4350 4228 4146 4270 4249 4159 4164 4183 4033 4095 4337 4237 4165 4210 4272 4164 4197 4219 4317 4277 4020 4142 4139 4131 4281 4242 4118 4317 4068 4244 4116 4151 4121 4102 4080 4118 4056 4190 4033 3998 4105 4179 3996 4210 4278 4182 4070 4178 4148 4106 4095 4124 4089 3973 4045 4182 4060 3956 4147 3990 4105 4105 4103 4188 4077 4112 4061 3962 4111 4038 4016 4274 4086 4095 4034 4062 4092 4096 4203 4094 3959 4074 4049 3946 3983 3992 4022 4173 4071 4088 4011 3922 4137 4045 4002 3962 4005 4046 4039 4054 3903 4012 4051 3951 4126 3990 4024 4019 3976 3958 4030 3910 3969 4014 4059 4062 3984 3964 3936 3947 4138 3997 3985 3956 4063 4034 3780 3991 3912 3882 3904 4026 4047 3898 3921 3954 3958 3954 4053 3933 4002 4006 3901 3981 4117 4018 3867 4035 3922 3921 4056 3804 3855 4010 3931 3907 3918 3928 3944 3918 3929 4045 3978 4021 3842 3950 3935 3981 3949 4039 3872 3921 3932 4041 4014 3934 3890 3993 3992 3944 3986 3994 3962 3828 4036 3779 3800 4061 3955 4067 3881 4001 3973 3987 3771 3773 4033 3926 3995 3851 3983 3920 3758 3954 3840 3897 3930 3860 3878 3938 3813 3905 3903 3804 3900 3859 3969 3807 3896 3837 3930 3838 4002 3940 3900 3982 4081 3976 3903 3920 3849 3925 4012 3986 3840 3843 3991 3781 3982 3948 3948 3893 3878 3915 3934 3927 3847 3873 3895 3934 3856 3878 3855 3870 3716 3915 3937 3756 3947 3899 3962 3928 3800 3878 3807 3789 3848 3940 3935 3911 3856 3790 3886 3984 3845 3798 3973 3824 3910 3878 3825 3873 4003 3870 3886 3856 3913 3884 3878 3865 3788 3942 3949 3924 3844 3852 3930 3877 3798 3881 3906 3873 3821 3875 3874 3785 3891 3805 3815 3897 3794 3792 3897 3815 3939 3957 3751 3898 3881 3894 3874 3794 3971 3761 3858 3743 3828 3769 3907 3854 3905 3853 3908 3817 3831 3844 3955 3766 3874 3872 3881 3823 3850 3884 3910 3838 3792 3804 3796 3847 3806 3909 3897 3846 3760 3903 3899 3799 3820 3889 3801 3859 3869 3866 3776 3821 3920 3803 3935 3770 4007 3884 3764 3857 3823 3804 3868 3831 3856 3894 3874 3874 3902 3826 3773 4071 3825 3811 3789 3921 3860 3747 3851 3890 3841 3828 3902 3984 3868 3863 3854 3811 3809 3733 3791 3958 3848 3728 3723 3756 3852 3869 3850 3887 3871 3936 3840 3855 3794 3959 3849 3925 3921 3890 3863 3774 3757 3828 3686 3801 3784 3937 3731 3863 3794 3829 3766 3802 3783 3702 3814 3843 3879 3637 3677 3872 3829 3744 3831 3814 3827 3823 3855 3774 3964 3864 3793 3725 3753 3782 3872 3893 3711 3660 3740 3790 3714 3952 3793 3770 3847 3737 3943 3754 3744 3817 3893 3784 3807 3774 3720 3867 3786 3662 3870 3788 3807 3809 3850 3617 3892 3840 3926 3742 3857 3696 3881 3754 3865 3899 3916 3765 3784 3799 3833 3968 3708 3893 3732 3861 3684 3805 3736 3856 3759 3743 3775 3888 3742 3805 3860 3793 3839 3721 3723 3839 3875 3787 3735 3682 3870 3788 3868 3796 3812 3773 3644 3722 3905 3792 3828 3865 3784 3658 3796 3929 3870 3789 3664 3782 3851 3946 3777 3855 3817 3838 3815 3730 3743 3914 3897 3845 3764 3758 3886 3855 3941 3921 3814 3996 3854 3942 3871 3928 4029 3988 4100 3984 4020 3994 3971 4089 3998 4192 4046 4001 3946 3988 4082 4037 4044 3994 3879 4038 3986 4039 4005 4028 4027 4156 4153 3973 4015 4104 4029 4014 4119 4033 4112 4051 4071 4187 4070 4031 4098 3872 4002 3992 3879 4014 3865 3880 3757 3841 3870 3919 3891 3942 3783 3752 3757 3792 3826 3780 3828 3963 3862 3929 3826 3836 3801 3783 3881 3776 3800 3847 3746 3839 3760 3849 3760 3833 3912 3814 3857 3755 3909 3858 3734 3805 3783 3641 3791 3725 3774 3812 3825 3821 3747 3897 3789 3790 3689 3727 3709 3834 3788 3967 3945 3782 3817 3847 3789 3882 3876 3903 3893 3756 3956 3765 3747 3810 3804 3826 3905 3770 3744 3796 3749 3956 3901 3867 3906 3757 3909 3870 3786 3873 3893 3855 3815 3761 3783 3745 3817 3858 3857 4000 3926 3971 3903 3986 4141 4095 4111 4259 4351 4348 4315 4541 4547 4686 4758 4824 4761 4888 4925 4874 4888 4947 5117 5042 4990 5180 5280 5061 5228 5175 5406 5460 5337 5295 5468 5649 5602 5578 5632 5614 5636 5702 5694 5757 5747 6000 5758 5756 5704 5781 5758 5754 5693 5682 5577 5630 5396 5205 5324 5189 4972 4929 4775 4555 4633 4392 4398 4374 4090 4126 3916 4039 3995 3924 3903 3974 3831 3932 3893 3986 3812 3889 3933 3960 3860 3832 3975 3916 3872 3894 3904 3940 3888 3780 3966 3840 3913 3878 3740 3853 3926 4008 3906 3898 3859 3963 3878 3928 3971 3985 3978 3944 3907 3872 3987 4061 4014 3933 3972 4060 3937 3881 4065 3926 4020 4054 3887 3927 4030 3923 3913 4125 3968 4023 3897 3981 4024 3901 3903 3957 4031 3996 3962 4004 3905 3983 3987 4068 3929 3989 3985 4032 4008 4042 4138 3980 3934 3981 3904 4086 3993 3964 4044 4117 4033 4027 4105 4018 4109 4127 4125 4042 4152 4167 4083 4033 4011 4153 4042 4100 4069 4031 4050 4005 4049 4098 4119 4039 4125 4200 4042 4137 4047 4010 4227 4208 4180 4225 4107 4178 4168 4271 4104 4191 4316 4017 4134 4108 4266 4285 4242 4143 4267 4163 4151 4127 4239 4274 4183 4369 4289 4129 4141 4241 4183 4273 4129 4246 4379 4341 4355 4180 4234 4340 4296 4221 4402 4335 4285 4334 4311 4321 4244 4358 4312 4469 4398 4398 4395 4514 4559 4736 4754 4836 5186 5239 5225 5379 5580 5697 5927 6128 6217 6273 6604 6782 6897 7017 7091 7074 7089 7175 7376 7540 7599 7555 7915 8078 8091 8538 8588 8823 8928 9195 9286 9447 9684 9735 9791 9997 10076 10125 10611 10433 10454 10571 10761 10518 10600 10392 10554 10496 10545 10432 10024 9803 9447 9094 8620 8240 7949 7619 7160 6778 6417 6154 6011 5562 5394 5266 5079 5008 4748 4789 4705 4628 4663 4778 4676 4624 4745 4701 4689 4661 4531 4569 4795 4578 4605 4635 4608 4522 4582 4614 4576 4628 4648 4675 4529 4627 4620 4522 4737 4569 4635 4727 4553 4485 4651 4562 4635 4571 4641 4715 4585 4483 4528 4596 4517 4667 4580 4478 4590 4540 4533 4511 4685 4565 4618 4561 4641 4522 4547 4502 4529 4554 4650 4543 4534 4629 4565 4522 4314 4408 4499 4496 4474 4528 4538 4575 4493 4463 4462 4550 4589 4378 4369 4442 4497 4402 4413 4570 4468 4383 4481 4446 4401 4485 4297 4318 4406 4318 4377 4352 4369 4254 4468 4429 4417 4356 4336 4265 4268 4352 4375 4292 4428 4275 4373 4401 4432 4395 4332 4420 4397 4324 4438 4387 4454 4465 4578 4400 4422 4450 4494 4534 4540 4604 4428 4342 4666 4452 4444 4395 4283 4427 4415 4482 4459 4378 4493 4504 4358 4495 4434 4419 4342 4426 4537 4476 4312 4346 4381 4433 4427 4330 4429 4336 4384 4342 4235 4257 4339 4257 4200 4384 4273 4224 4226 4040 4259 4101 4004 4054 4019 4111 4006 4073 4011 4077 4009 3932 3901 4113 3957 3920 3951 3918 4107 4054 3957 3920 3956 3962 4062 4049 3895 3803 4006 4046 3919 4140 3971 4092 3943 4076 3848 3904 3928 3993 3926 3841 3754 3945 3851 3781 3826 3881 3872 3651 3989 3894 3843 3682 3821 3857 3787 3782 3870 3897 3798 3779 3834 3797 3759 3786 3824 3910 3644 3767 3757 3784 3801 3730 3756 3700 3801 3661 3665 3804 3687 3691 3714 3702 3728 3658 3648 3636 3639 3714 3644 3873 3608 3810 3675 3727 3608 3645 3697 3631 3745 3705 3662 3784 3591 3712 3647 3677 3833 3547 3730 3703 3666 3768 3657 3710 3586 3627 3730 3582 3702 3611 3523 3743 3633 3661 3577 3678 3575 3545 3642 3662 3526 3575 3645 3502 3521 3590 3659 3558 3707 3558 3498 3521 3594 3516 3557 3624 3675 3621 3494 3610 3493 3469 3451 3601 3521 3530 3549 3555 3573 3470 3602 3605 3457 3437 3455 3563 3514 3527 3543 3466 3460 3549 3469 3452 3388 3588 3518 3526 3638 3633 3484 3435 3450 3517 3632 3639 3543 3621 3632 3648 3899 3777 3883 3809 3907 4078 4059 4195 4253 4074 4192 4264 4445 4330 4300 4305 4341 4426 4352 4436 4500 4481 4629 4580 4443 4647 4555 4540 4718 4443 4641 4518 4623 4698 4698 4666 4667 4658 4615 4614 4748 4795 4807 4688 4752 4637 4597 4687 4543 4545 4478 4353 4445 4266 4174 4088 4042 3878 3784 3746 3679 3596 3601 3503 3593 3388 3486 3435 3338 3350 3256 3377 3336 3452 3404 3333 3323 3368 3274 3358 3341 3241 3299 3491 3346 3245 3465 3252 3319 3234 3330 3363 3375 3310 3248 3285 3285 3422 3320 3303 3302 3315 3367 3297 3230 3190 3449 3227 3326 3141 3283 3242 3190 3291 3346 3275 3292 3313 3289 3353 3262 3334 3249 3168 3289 3166 3231 3045 3217 3343 3177 3241 3252 3331 3339 3301 3145 3252 3235 3145 3303 3130 3228 3237 3092 3154 3268 3128 3410 3287 3224 3215 3266 3182 3219 3263 3235 3157 3272 3077 3254 3067 3234 3239 3092 3163 3110 3095 3101 3148 3158 3132 3283 3249 3258 3199 3149 3265 3115 2962 3126 3248 3146 3239 3093 3142 3170 3163 3218 3211 3163 3064 3141 3161 3277 3246 3112 3213 3332 3165 3087 3151 3069 3058 3166 3240 3213 3175 3271 2943 3127 3219 3055 3132 3099 3113 3148 3274 3110 3229 3167 3221 3019 3028 3239 3189 3177 3085 3176 3117 3055 3031 3198 3257 3159 3053 3079 3328 3257 3192 3056 3094 3090 3187 3162 3214 3212 3203 3267 3134 3136 3164 3115 3171 3218 3054 3255 3196 3164 3161 3066 3117 3172 3159 3117 3138 3156 3044 3137 3099 3151 3132 3142 3156 3108 3048 3188 3091 3100 3211 3145 3026 3103 2987 3027 3004 3185 3161 2975 3139 3071 3036 3190 3124 2980 2999 3120 3100 3153 3045 3097 3079 3098 3157 3284 3028 2936 3107 3058 3050 3126 3035 3121 3118 3166 2933 3098 3096 3112 3070 3068 3098 3112 3041 3177 3103 3201 3031 3031 3087 3068 3086 3060 2992 3093 3030 3021 3192 3031 2980 3159 3161 3127 3198 3163 2897 3273 3188 3102 3085 3214 3199 3230 3066 3040 3112 3013 3114 3116 3139 3305 3148 3258 3117 3361 3307 3309 3533 3588 3685 3779 3717 3818 3825 3970 4081 4202 4318 4368 4478 4650 4692 4671 4804 4816 4978 5050 5304 5316 5322 5447 5656 5780 5924 5853 6005 5996 6278 6339 6500 6356 6528 6464 6728 6685 6817 7063 6878 6769 6858 6984 7012 7045 6804 6587 6569 6506 6515 6237 6159 5889 5668 5385 5115 4874 4777 4474 4286 4092 3805 3724 3581 3468 3283 3344 3226 3258 3342 3254 3321 3048 3130 3044 3103 3156 3118 3071 3191 3068 3178 3080 3083 2989 3057 3084 2994 3134 3094 3167 3164 3021 3096 3052 3106 3048 2998 3043 3106 3020 2992 3156 2996 3054 2915 3040 3095 3091 2954 2980 3064 3122 2996 3224 3113 3015 3121 3015 3144 3086 3056 2946 2910 3001 3002 3170 3078 3019 3095 3026 3094 2996 2970 3040 3074 3060 3117 3001 3041 2944 3049 3099 2970 2973 3015 3107 3132 3025 2998 3197 3115 2804 2986 2952 3047 3162 2950 3025 3074 3150 3092 3013 3175 3101 3007 3073 3310 3216 3123 3187 3350 3171 3271 3327 3269 3367 3248 3284 3409 3396 3360 3410 3371 3321 3283 3360 3375 3446 3296 3496 3346 3492 3225 3393 3390 3360 3354 3371 3120 3395 3532 3399 3239 3485 3295 3437 3492 3375 3449 3293 3345 3297 3430 3240 3220 3152 3402 3329 3078 3284 3076 3085 3163 3094 3143 3014 3109 3219 3040 3128 3083 3025 3131 3202 2892 3124 2951 3019 3104 3152 3168 3025 2917 3052 2989 3085 2948 2996 2974 3071 2954 3032 2998 3026 3054 3036 2914 3060 3018 3099 2890 2932 3028 3153 3010 2973 3130 3004 3090 3192 2858 3127 3161 3138 3021 3007 3107 3089 3012 2948 3040 2927 3025 3051 3045 2895 3005 2918 3138 3054 3121 3100 3299 3049 2995 3046 3076 2897 3087 3122 3131 3165 3085 2925 3117 3243 2963 2974 2969 2928 3038 3176 3124 3029 3037 3048 3125 3056 3109 3121 3221 2894 2980 3129 2938 3121 2892 3067 3039 3012 3200 3091 3242 3091 2997 3050 3213 3174 3107 3138 3116 3185 3079 3157 3114 3201 3030 3150 2971 2900 3051 3071 3151 3093 3175 3094 3070 3108 3154 3099 3088 3130 3120 3028 3319 3144 3170 3231 3062 3266 3220 3018 3115 3200 3121 3117 2931 3206 3196 3143 3116 3259 3028 3101 2981 2950 3086 3086 3102 3175 3086 3154 3068 3054 3199 3253 3167 3265 3182 3202 3114 3278 3201 3221 3153 3032 3236 3168 3167 3151 3085 3081 3227 3307 3136 3182 3031 3142 3187 3353 3114 3286 3165 3334 3234 3179 3280 3194 3123 3083 3234 3194 3252 3168 3210 3220 3109 3231 3271 3322 3253 3188 3220 3124 3118 3220 3237 3018 3298 3298 3251 3100 3165 3254 3406 3325 3303 3251 3185 3272 3230 3206 3247 3259 3258 3285 3372 3291 3408 3276 3296 3345 3344 3383 3341 3332 3334 3337 3229 3262 3310 3359 3272 3427 3379 3309 3286 3375 3309 3387 3308 3372 3355 3346 3329 3308 3350 3463 3436 3396 3351 3450 3251 3343 3381 3371 3393 3359 3384 3428 3378 3369 3450 3441 3363 3524 3427 3552 3530 3426 3418 3462 3544 3406 3608 3405 3526 3568 3539 3572 3402 3462 3407 3605 3407 3676 3492 3533 3391 3533 3508 3516 3511 3596 3453 3546 3443 3568 3588 3523 3463 3592 3663 3663 3641 3612 3572 3633 3639 3687 3671 3616 3625 3593 3691 3730 3732 3762 3667 3935 3717 3926 3932 3900 4082 4199 4359 4599 4557 4695 4838 4965 5172 5208 5313 5318 5470 5586 5773 5923 5982 6125 5953 6088 6234 6507 6351 6349 6345 6439 6429 6603 6664 6534 6422 6501 6534 6591 6552 6577 6644 6541 6680 6671 6652 6735 6505 6684 6680 6613 6622 6621 6642 6433 6296 6273 6121 5893 5672 5606 5521 5258 5121 4984 4976 4802 4644 4573 4472 4354 4204 4133 4121 4101 4064 4191 4099 4065 4240 4138 4083 4113 4030 4065 4155 4134 4034 4041 4166 4097 4096 4145 4087 4077 4089 4040 4037 4172 4115 4057 4084 4061 4074 4154 4246 4062 4156 4116 4077 4126 4117 4155 4061 4096 4157 4105 4210 4260 4221 4231 4142 4304 4189 4307 4241 4148 4203 4195 4321 4305 4162 4221 4173 4206 4289 4204 4234 4291 4372 4252 4384 4227 4336 4297 4234 4306 4195 4225 4290 4298 4296 4244 4265 4213 4251 4293 4319 4464 4333 4352 4277 4287 4424 4210 4320 4084 4461 4243 4267 4287 4269 4249 4186 4256 4323 4321 4325 4322 4261 4234 4312 4291 4329 4317 4378 4308 4318 4319 4318 4322 4365 4378 4397 4265 4466 4363 4411 4377 4152 4388 4298 4330 4356 4336 4197 4336 4281 4256 4233 4329 4392 4357 4324 4267 4364 4410 4348 4318 4387 4193 4377 4298 4361 4279 4215 4167 4354 4409 4360 4282 4277 4254 4340 4288 4360 4264 4219 4187 4279 4387 4368 4243 4399 4095 4308 4098 4210 4239 4434 4298 4324 4186 4205 4206 4253 4258 4168 4274 4284 4252 4232 4326 4360 4210 4141 4176 4001 4200 4073 4222 4159 4256 4186 4149 4272 4130 4280 4068 4123 4205 4160 4265 4239 4112 4166 4359 4202 4171 4210 4175 4026 4257 4179 4196 4107 4062 4080 4177 4162 4071 4177 4036 4210 4063 4188 4218 4143 4136 4040 4030 4094 4182 4178 4092 4116 4122 4148 3994 4241 4120 4045 3949 4154 4085 4019 4091 4063 4125 3952 3992 4078 4126 3819 4009 3987 3953 4025 3990 3894 3971 4002 3936 3976 3991 4058 3927 3999 3995 3927 3955 3893 3962 3869 3935 4011 4078 4106 3969 4026 4009 3975 3935 3955 3923 3996 3988 3944 3886 3938 3881 4010 3959 3922 3949 3957 3885 3875 3895 3809 3910 3790 3847 3842 3925 3900 3777 3762 4015 3838 3925 3826 3798 3736 3693 3731 3828 3745 3794 3821 3792 3781 3754 3755 3895 3827 3702 3711 3756 3632 3819 3814 3782 3749 3758 3685 3730 3820 3740 3696 3698 3735 3760 3692 3781 3680 3661 3649 3625 3692 3725 3695 3818 3667 3660 3566 3688 3780 3604 3661 3620 3819 3580 3651 3713 3674 3586 3539 3657 3693 3641 3578 3531 3547 3679 3581 3659 3481 3707 3545 3563 3741 3634 3548 3604 3525 3731 3619 3584 3639 3630 3730 3661 3585 3623 3576 3580 3590 3570 3575 3698 3547 3553 3594 3587 3476 3563 3657 3618 3479 3607 3513 3463 3594 3557 3710 3568 3617 3540 3592 3579 3595 3532 3637 3450 3648 3587 3511 3501 3595 3501 3639 3595 3608 3590 3568 3565 3398 3487 3497 3623 3564 3660 3442 3458 3584 3566 3514 3437 3508 3550 3464 3629 3579 3578 3493 3554 3563 3681 3413 3512 3544 3638 3593 3471 3527 3553 3559 3575 3536 3456 3469 3560 3441 3543 3594 3485 3565 3479 3594 3502 3526 3639 3559 3660 3534 3570 3511 3489 3478 3404 3621 3536 3621 3444 3558 3451 3530 3471 3455 3578 3464 3427 3525 3488 3378 3458 3441 3478 3487 3432 3608 3483 3335 3405 3431 3536 3518 3446 3537 3499 3441 3582 3592 3603 3549 3571 3721 3695 3566 3689 3632 3666 3756 3781 3904 3836 3723 3804 3912 3917 4036 3864 3896 3882 3985 4095 4018 4163 4094 4192 4162 4172 4213 4053 4098 4199 4260 4218 4203 4163 4275 4245 4279 4304 4230 4199 4350 4294 4229 4321 4128 4137 4185 4046 4107 4177 3907 4037 3839 3855 3787 3705 3685 3557 3550 3512 3578 3569 3371 3531 3574 3476 3423 3332 3489 3400 3481 3415 3385 3320 3374 3432 3402 3519 3332 3398 3488 3351 3528 3315 3419 3421 3365 3390 3451 3466 3486 3394 3422 3310 3364 3283 3334 3383 3362 3331 3341 3423 3341 3422 3358 3244 3359 3260 3228 3484 3388 3282 3468 3343 3422 3285 3339 3349 3452 3208 3352 3349 3228 3331 3381 3388 3311 3341 3263 3375 3339 3432 3296 3449 3414 3314 3312 3294 3281 3316 3381 3393 3239 3284 3296 3366 3311 3229 3238 3313 3283 3291 3386 3288 3330 3198 3353 3369 3271 3496 3273 3431 3363 3535 3355 3435 3470 3426 3284 3390 3529 3482 3427 3529 3312 3414 3385 3637 3558 3466 3220 3420 3416 3512 3435 3542 3462 3393 3432 3551 3417 3372 3348 3453 3278 3298 3382 3487 3361 3405 3213 3272 3404 3434 3392 3315 3386 3316 3313 3242 3253 3307 3205 3297 3157 3170 3217 3135 3086 3195 3123 3202 3168 3186 3133 3061 3106 3244 3104 3202 3229 3099 3287 3154 3194 3331 3223 3213 3270 3185 3318 3264 3232 3305 3137 3313 3186 3353 3218 3215 3200 3192 3188 3123 3147 3206 3074 3118 3108 3219 3213 3206 3250 3132 3231 3163 3163 3249 3092 3229 3256 3017 3103 3210 3222 3081 3071 3208 3151 3111 3195 3154 3275 3141 3074 3155 3164 3008 3203 3206 3272 3153 3130 3108 3067 3214 3042 3179 3136 3182 3163 3167 3119 3183 3258 3149 3009 3154 3136 3168 3207 3207 3021 3067 2986 3055 3191 3184 3111 3159 3165 3145 3141 3120 3029 3111 3329 3145 3182 3176 3143 3140 3213 3043 3050 3208 3013 3211 3162 3288 3142 3131 3125 3302 3221 3130 3310 3258 3214 3227 3236 3178 3055 3294 3121 3213 3297 3137 3148 3279 3207 3062 3222 3167 3254 3195 3243 3244 3132 3202 3280 3296 3252 3246 3184 3346 3227 3189 3416 3424 3386 3369 3445 3332 3387 3409 3371 3428 3533 3444 3569 3481 3500 3604 3535 3846 4035 4190 4628 4912 5172 5808 6369 7175 7814 8446 9142 9965 10756 11522 12235 12460 13210 13764 14073 15067 15027 15196 15604 16103 16124 16072 16434 16607 16763 16688 16774 16523 16579 16771 16895 16808 17035 16772 17421 17478 17240 17281 17332 17042 17203 17375 17582 17192 17272 17198 17261 16704 16501 15541 15460 14739 14089 13679 13029 12326 11500 10719 9547 8973 7946 7298 6665 5874 5344 4800 4520 4319 4142 3867 3778 3723 3693 3651 3541 3711 3483 3672 3464 3537 3540 3474 3358 3352 3391 3551 3506 3356 3365 3455 3280 3354 3334 3332 3285 3324 3198 3359 3449 3325 3293 3218 3273 3291 3314 3236 3222 3347 3190 3263 3305 3186 3141 3120 3273 3195 3430 3176 3345 3257 3147 3184 3277 3253 3248 3279 3185 3228 3227 3313 3172 3153 3189 3270 3302 3088 3183 3210 3199 3194 3087 3146 3298 3265 3212 3119 3014 3285 3085 3163 3252 3110 3298 3312 3133 3165 3156 3234 3177 3067 3071 3281 3245 3178 3250 3095 3108 3212 3124 3170 3339 3298 3224 3127 3230 3303 3149 3290 3221 3121 3233 3206 3095 3144 3120 3125 3233 3061 3218 3215 3218 3244 3212 3242 3132 3180 3203 3143 3286 3096 3189 3150 3064 3223 3142 3204 3213 3147 3266 3265 3248 3152 3339 3298 3113 3209 3317 3222 3305 3062 3222 3272 3019 3213 3288 3063 3342 3138 3238 3224 3236 3302 3255 3189 3343 3096 3270 3131 3388 3229 3187 3206 3226 3083 3169 3197 3273 3320 3206 3251 3252 3217 3156 3249 3190 3266 3241 3032 3137 3254 3195 3188 3123 3315 3226 3168 3333 3242 3117 3319 3278 3272 3251 3075 3207 3255 3252 3226 3133 3246 3214 3248 3185 3346 3226 3242 3172 3251 3265 3291 3341 3262 3282 3324 3324 3363 3292 3370 3445 3610 3481 3471 3464 3524 3464 3479 3512 3608 3634 3557 3538 3566 3441 3660 3657 3617 3723 3648 3612 3632 3687 3681 3648 3799 3757 3697 3660 3596 3628 3618 3749 3678 3733 3765 3725 3747 3714 3613 3557 3565 3656 3643 3591 3518 3557 3505 3586 3491 3381 3492 3468 3460 3413 3312 3389 3287 3366 3208 3282 3267 3261 3279 3242 3333 3308 3314 3173 3253 3217 3334 3255 3301 3231 3270 3250 3305 3354 3386 3212 3270 3280 3306 3277 3153 3242 3376 3318 3213 3378 3349 3303 3314 3148 3263 3250 3236 3251 3447 3233 3192 3244 3408 3310 3244 3345 3374 3279 3250 3186 3276 3065 3328 3335 3213 3332 3281 3241 3233 3257 3313 3207 3306 3243 3324 3348 3235 3209 3329 3227 3273 3292 3272 3136 3275 3171 3184 3291 3350 3186 3374 3210 3311 3307 3249 3241 3328 3247 3291 3389 3284 3078 3272 3326 3252 3330 3300 3218 3295 3193 3417 3131 3258 3257 3243 3205 3304 3306 3220 3327 3447 3263 3251 3386 3303 3374 3276 3282 3289 3366 3193 3320 3432 3300 3128 3391 3345 3422 3275 3404 3258 3284 3275 3373 3334 3279 3316 3411 3346 3274 3337 3316 3277 3287 3308 3342 3337 3457 3393 3313 3507 3464 3416 3457 3549 3521 3467 3408 3428 3520 3510 3598 3561 3675 3394 3588 3601 3489 3511 3565 3583 3501 3746 3495 3440 3590 3557 3530 3354 3433 3550 3499 3541 3615 3411 3490 3595 3597 3362 3539 3442 3368 3362 3498 3378 3507 3444 3437 3555 3347 3394 3445 3464 3408 3436 3355 3336 3248 3330 3346 3307 3363 3372 3298 3342 3271 3255 3343 3401 3324 3237 3325 3441 3375 3534 3395 3259 3362 3466 3397 3306 3424 3356 3289 3375 3354 3349 3276 3342 3278 3501 3316 3380 3435 3262 3357 3347 3328 3387 3382 3450 3330 3305 3218 3404 3379 3337 3336 3506 3461 3442 3312 3368 3493 3394 3351 3373 3427 3408 3364 3491 3387 3376 3449 3451 3376 3335 3390 3445 3311 3391 3367 3439 3409 3286 3377 3436 3311 3503 3362 3351 3529 3332 3430 3400 3414 3400 3472 3454 3408 3308 3397 3382 3374 3482 3447 3313 3314 3491 3506 3373 3476 3403 3530 3481 3471 3457 3473 3414 3415 3412 3450 3495 3432 3613 3486 3581 3548 3592 3540 3449 3603 3537 3505 3579 3651 3575 3562 3549 3711 3563 3542 3549 3638 3613 3575 3652 3453 3585 3535 3503 3595 3591 3681 3608 3523 3623 3693 3731 3598 3563 3684 3549 3529 3605 3678 3727 3542 3545 3619 3534 3470 3495 3621 3479 3588 3614 3475 3566 3628 3472 3474 3525 3626 3566 3708 3562 3548 3538 3530 3514 3607 3486 3608 3430 3570 3543 3764 3703 3636 3649 3583 3571 3701 3562 3634 3735 3645 3572 3620 3637 3641 3600 3705 3718 3598 3618 3553 3570 3610 3629 3601 3651 3644 3776 3762 3643 3652 3718 3669 3569 3587 3683 3603 3680 3651 3686 3848 3629 3780 3664 3687 3582 3639 3759 3726 3755 3761 3636 3842 3795 3826 3669 3722 3611 3750 3802 3693 3745 3722 3666 3689 3837 3830 3866 3788 3889 3659 3810 3919 3908 3786 3958 3834 3906 3788 3825 3794 3904 3831 3711 3872 3807 3804 3933 3790 3884 3830 3860 3711 3897 3835 4002 3771 3800 3884 3971 3842 3887 3863 3782 3901 3852 3769 3804 3835 3886 3843 3913 3910 3700 3855 3790 3724 3891 3961 3800 3810 3839 3870 3835 3810 3820 3769 3807 3743 3758 3855 3908 3789 3876 3862 3806 3900 3939 3856 3843 3796 3865 3865 3780 4072 3884 3945 3924 3855 3752 3917 3993 3872 3889 3941 3953 3949 3857 3991 3799 3805 3908 3839 3938 3889 3877 4003 3966 3902 3976 4012 3838 3949 3874 3969 3973 4000 4082 3937 3957 3894 3970 4016 3935 4056 4047 4018 4031 3847 3988 3900 3928 3935 3979 4122 3994 3970 3940 3942 4018 3993 4044 4038 4028 3914 3910 3945 4126 3873 3925 3861 4119 4048 3854 4110 3929 4089 3956 4012 4078 4003 3958 3840 3994 4120 4087 4034 4076 4022 4048 4041 4046 4027 3934 4035 4015 4062 3935 4164 4188 3971 4146 4077 4030 3892 4073 4104 4187 4248 4070 4334 4055 4086 4241 4166 4397 4254 4272 4397 4313 4384 4408 4245 4410 4325 4471 4446 4392 4490 4460 4451 4531 4536 4684 4580 4604 4511 4471 4500 4663 4567 4586 4606 4553 4552 4588 4545 4684 4695 4695 4606 4566 4667 4632 4619 4663 4623 4555 4580 4500 4354 4531 4431 4354 4394 4404 4409 4193 4305 4340 4277 4240 4247 4223 4173 4057 4052 4249 4174 4313 4175 4236 4225 4227 4243 4176 4193 4213 4222 4112 4118 4157 4187 4183 4185 4209 4144 4279 4188 4201 4412 4334 4224 4143 4137 4228 4174 4307 4289 4317 4110 4152 4342 4307 4242 4207 4144 4271 4250 4241 4396 4306 4244 4329 4230 4174 4214 4202 4238 4353 4143 4351 4266 4346 4327 4367 4357 4368 4343 4412 4299 4256 4379 4407 4366 4503 4381 4431 4412 4434 4424 4531 4546 4555 4567 4574 4811 4748 4658 4768 4699 4693 4707 4821 4900 4808 4854 4875 4880 4887 4771 4964 5088 4932 5147 5083 4996 5324 5203 5092 4968 5148 5064 5170 5166 5139 5156 5171 5103</counts>
			</dataPoints>
		</scan>
	</xrdMeasurement>
</xrdMeasurements>