File: Data Files/Full/MSS p (7-129, 11w)_01_1.xrdml
<?xml version="1.0"?>
<xrdMeasurements xmlns="http://www.xrdml.com/XRDMeasurement/2.2" xmlns:xsi="http://www.w3.org/2001/XMLSchema-instance" xsi:schemaLocation="http://www.xrdml.com/XRDMeasurement/2.2 http://www.xrdml.com/XRDMeasurement/2.2/XRDMeasurement.xsd" status="Completed" recordIdentifier="{E86A4D24-D6B6-4EA5-83DA-DD0F83F9CD5E}">
	<comment>
		<entry/>
	</comment>
	<sample type="To be analyzed">
		<id>p</id>
		<name></name>
		<preparedBy></preparedBy>
	</sample>
	<xrdMeasurement measurementType="Scan" status="Completed" sampleMode="Reflection">
		<usedWavelength intended="K-Alpha 1">
			<kAlpha1 unit="Angstrom">1.5405980</kAlpha1>
			<kAlpha2 unit="Angstrom">1.5444260</kAlpha2>
			<kBeta unit="Angstrom">1.3922500</kBeta>
			<ratioKAlpha2KAlpha1>0.5000</ratioKAlpha2KAlpha1>
		</usedWavelength>
		<incidentBeamPath>
			<radius unit="mm">145.00</radius>
			<xRayTube id="1010048" name="Empyrean Cu LFF HR (9430 033 7310x) DK437964">
				<tension unit="kV">40.0</tension>
				<current unit="mA">15.0</current>
				<anodeMaterial>Cu</anodeMaterial>
				<focus type="Line">
					<length unit="mm">12.0</length>
					<width unit="mm">0.4</width>
					<takeOffAngle unit="deg">6.0</takeOffAngle>
				</focus>
			</xRayTube>
			<filter id="20010004" name="Beta-filter Nickel">
				<material>Ni</material>
				<thickness unit="mm">0.020</thickness>
			</filter>
			<sollerSlit id="21010002" name="Soller slits 0.04 rad.">
				<opening unit="rad">0.0400</opening>
			</sollerSlit>
			<mask id="22031000" name="Fixed mask 13 mm">
				<width unit="mm">9.00</width>
			</mask>
			<divergenceSlit id="22120001" name="Divergence slit 1°" xsi:type="fixedDivergenceSlitType">
				<distanceToSample unit="mm">50.00</distanceToSample>
				<height unit="mm">1.52</height>
			</divergenceSlit>
		</incidentBeamPath>
		<diffractedBeamPath>
			<radius unit="mm">145.00</radius>
			<parallelPlateCollimator id="25020001" name="Parallel plate collimator 0.28°">
				<opening unit="deg">0.28</opening>
			</parallelPlateCollimator>
			<detector id="7010020" name="PIXcel3D-Medipix3 1x1 detector" xsi:type="areaDetectorType">
				<phd unit="keV">
					<lowerLevel>4.0</lowerLevel>
					<upperLevel>11.3</upperLevel>
				</phd>
				<mode>Receiving slit</mode>
				<activeChannelsEquatorial>255</activeChannelsEquatorial>
				<activeChannelsAxial>255</activeChannelsAxial>
				<pitchEquatorial unit="mm">0.05500</pitchEquatorial>
				<pitchAxial unit="mm">0.05500</pitchAxial>
				<readOutPeriod unit="seconds">0.050</readOutPeriod>
			</detector>
		</diffractedBeamPath>
		<scan appendNumber="0" mode="Continuous" scanAxis="2Theta" status="Completed">
			<header>
				<startTimeStamp>2025-07-01T09:09:20-08:00</startTimeStamp>
				<endTimeStamp>2025-07-01T22:42:48-08:00</endTimeStamp>
				<author>
					<name>Instrument</name>
				</author>
				<source>
					<applicationSoftware version="1.6 (94)">PANalytical Aeris Instrument Suite</applicationSoftware>
					<instrumentControlSoftware version="3.0.0 20211014">AERIS</instrumentControlSoftware>
					<instrumentID>2855484</instrumentID>
				</source>
			</header>
			<dataPoints>
				<positions axis="2Theta" unit="deg">
					<startPosition>7.005</startPosition>
					<endPosition>128.995</endPosition>
				</positions>
				<positions axis="Omega" unit="deg">
					<commonPosition>11.000</commonPosition>
				</positions>
				<commonCountingTime unit="seconds">3.520</commonCountingTime>
				<counts 4726 4734 4690 4594 4608 4663 4741 4550 4650 4757 4614 4573 4744 4676 4665 4696 4617 4661 4563 4601 4729 4552 4598 4705 4630 4699 4652 4525 4696 4666 4589 4604 4658 4535 4641 4599 4569 4593 4676 4565 4605 4570 4599 4614 4615 4532 4640 4513 4509 4558 4561 4635 4648 4495 4499 4584 4472 4642 4558 4498 4545 4449 4471 4482 4600 4578 4570 4528 4479 4439 4575 4583 4464 4546 4414 4634 4564 4593 4594 4573 4528 4450 4616 4558 4615 4636 4528 4498 4528 4384 4426 4499 4547 4635 4491 4521 4407 4371 4525 4457 4428 4505 4381 4470 4351 4483 4446 4445 4437 4346 4502 4422 4468 4464 4442 4387 4484 4455 4301 4461 4443 4380 4405 4334 4401 4535 4542 4467 4421 4381 4378 4339 4276 4431 4425 4377 4290 4332 4372 4436 4395 4216 4498 4419 4304 4278 4295 4380 4366 4388 4476 4462 4387 4367 4415 4404 4356 4312 4425 4259 4358 4268 4336 4374 4477 4324 4445 4391 4305 4453 4452 4435 4453 4446 4489 4391 4369 4492 4457 4553 4574 4689 4669 4565 4695 4632 4705 4661 4574 4804 4688 4644 4728 4638 4627 4799 4607 4730 4675 4796 4727 4786 4771 4830 4769 4747 4761 4828 4860 4776 4808 4918 4919 4819 4646 4771 4698 4796 4717 4834 4844 4831 4874 4849 4756 4879 4837 4816 4776 4729 4767 4790 4824 4862 4823 4727 4843 4850 4705 4848 4851 4792 4546 4628 4743 4750 4730 4678 4793 4594 4660 4616 4691 4684 4805 4604 4552 4662 4605 4673 4714 4779 4551 4706 4652 4655 4657 4652 4695 4642 4670 4715 4600 4552 4675 4757 4642 4590 4558 4596 4551 4631 4690 4505 4473 4688 4700 4607 4627 4515 4676 4538 4579 4643 4803 4631 4632 4702 4657 4606 4513 4635 4476 4569 4664 4584 4521 4494 4600 4567 4644 4538 4599 4642 4755 4569 4582 4595 4576 4546 4563 4555 4547 4697 4561 4643 4745 4813 4564 4529 4609 4578 4505 4672 4545 4792 4525 4550 4703 4705 4590 4499 4616 4698 4673 4736 4668 4579 4588 4645 4755 4593 4735 4715 4641 4745 4713 4723 4644 4593 4700 4884 4749 4847 4628 4687 4626 4698 4719 4717 4726 4755 4613 4754 4661 4767 4832 4864 4756 4688 4754 4646 4815 4840 4794 4812 4672 4696 4868 4773 4743 4815 4794 4823 4884 4754 4775 4726 4725 4740 4816 4689 4956 4749 4927 4897 4852 4782 4822 4807 4880 4923 4749 4797 4720 5005 5054 4878 4849 4764 4864 4863 4901 4821 4933 4866 4995 4822 4867 4921 4846 4943 4860 4817 4866 4972 4849 4924 4915 4914 4794 4989 5004 4990 5010 4951 5088 5041 5034 4994 4948 4849 4897 5089 4935 4982 5010 5209 5141 5079 5005 5057 5012 5028 5051 5113 5206 5138 5050 5082 5045 5051 4996 5151 5052 5190 5287 5174 5124 5127 5109 5082 5210 5009 5137 5168 5210 5155 5204 5235 5267 5156 5324 5210 5316 5100 5150 5241 5097 5308 5243 5178 5228 5335 5300 5201 5362 5289 5321 5213 5335 5376 5467 5273 5333 5295 5304 5368 5387 5532 5378 5333 5347 5386 5267 5536 5362 5320 5605 5368 5452 5549 5431 5531 5381 5516 5558 5474 5492 5550 5646 5551 5534 5554 5727 5493 5696 5566 5412 5694 5796 5710 5848 5599 5700 5772 5607 5670 5778 5736 5553 5758 5745 5692 5790 5845 5806 5791 5757 5797 5846 5883 5804 5816 5878 5837 5936 5857 5822 5878 5908 5812 6116 5904 6089 6043 5798 6059 5998 5997 5748 6015 5984 6076 6077 6062 6065 6049 5985 6080 6154 6159 6164 6273 6058 6253 6088 6272 6235 6343 6166 6162 6410 6325 6540 6451 6252 6403 6434 6346 6471 6480 6538 6488 6546 6549 6400 6651 6789 6644 6541 6567 6573 6580 6508 6724 6658 6731 6588 6792 6799 6748 6695 6760 6836 6755 6774 6763 6951 6657 6955 6736 6906 6836 6780 6900 6988 6859 6704 6928 7044 6959 6943 6758 6933 7029 6952 7051 7185 6905 6974 7020 6833 6892 6880 6900 7059 7047 6976 7030 7017 7013 7035 7105 7230 7498 7609 8283 8599 9062 9417 10414 10847 11772 12501 13633 14320 15355 16562 17956 18424 19160 19543 20063 20273 20317 20272 20189 20420 19827 19529 18951 18810 18373 18185 18335 18143 18722 18830 19484 19920 20546 21511 22884 23869 25169 26557 27690 28420 29932 30323 32312 32442 33521 33454 33474 33243 32515 32020 31477 30568 29322 27977 26839 24963 23192 21644 19861 18211 16486 14682 13237 12069 10974 9869 9349 8496 8118 7751 7505 7288 7358 7507 7511 7297 7412 7418 7323 7373 7200 7253 7176 7304 7401 7358 7233 7095 7155 7119 7166 7011 7231 7066 7107 7090 7030 6861 7093 7065 6882 6980 6898 6923 6973 7115 7035 7018 6925 7056 7062 6987 6915 7000 6937 6915 7024 6939 7088 6898 7002 7092 6954 6881 7018 6961 6809 6884 7047 6895 6683 6794 6799 6860 6915 6882 6840 6897 6702 6827 6871 6832 6861 6911 6770 6603 6624 6585 6596 6548 6467 6597 6578 6680 6557 6535 6602 6681 6487 6434 6538 6617 6270 6490 6373 6548 6378 6565 6267 6434 6403 6409 6117 6361 6341 6299 6187 6244 6275 6328 6244 6185 6118 6153 6106 6043 6309 6185 6157 6269 6162 5991 5980 6214 6137 5996 6088 5965 6168 6102 6062 6133 6104 6005 5911 5925 5891 5962 6060 5809 5891 5877 5984 5830 5945 5948 5948 5997 5862 6060 6031 5882 5832 5744 5695 5776 5808 5774 5720 5595 5778 5587 5687 5708 5720 5735 5582 5762 5653 5543 5633 5551 5642 5615 5661 5580 5427 5631 5544 5406 5627 5694 5383 5586 5536 5474 5531 5347 5534 5388 5401 5388 5419 5303 5408 5352 5414 5287 5314 5312 5394 5445 5311 5360 5251 5328 5249 5347 5188 5388 5268 5235 5029 5291 5192 5302 5342 5257 5116 5258 5208 5264 5251 5094 5220 5153 5137 5017 5040 5067 5317 4988 5016 5202 5026 4872 5109 5017 4899 5131 5187 4934 4952 4985 4967 4995 4961 4988 5001 5024 4847 4959 5072 4864 4905 4818 4911 4938 4808 4824 4874 4972 4844 4856 4867 4743 4927 4898 4795 4662 4610 4888 4803 4727 4717 4793 4759 4838 4726 4817 4742 4734 4623 4733 4678 4630 4586 4749 4673 4651 4658 4622 4557 4602 4529 4654 4564 4640 4719 4565 4603 4584 4573 4556 4543 4463 4439 4502 4571 4556 4592 4574 4623 4556 4554 4585 4445 4582 4422 4346 4430 4364 4435 4454 4448 4568 4261 4324 4391 4423 4401 4383 4413 4349 4244 4520 4361 4425 4276 4396 4307 4353 4421 4404 4357 4193 4353 4242 4353 4388 4331 4296 4334 4354 4256 4255 4311 4161 4393 4254 4353 4294 4134 4285 4306 4178 4276 4197 4240 4228 4149 4214 4209 4284 4164 4185 4250 4188 4200 4149 4102 4333 3985 4306 4170 4201 4134 4149 4008 4138 4175 4135 4096 4109 4077 4047 4167 4041 3923 4015 4034 4207 4027 4114 3942 3965 4112 4001 3986 4115 3955 3962 4044 4050 3928 3950 4036 4020 4003 3946 4049 4086 4014 4022 3958 4004 3968 3893 3912 4035 3920 3930 3957 3901 3949 3930 3828 3915 3909 3896 3926 3900 3994 3772 3923 4016 3885 3853 3904 3929 3814 3934 3826 3748 3839 3841 3803 3831 3873 3854 3850 3794 3916 3797 3738 3865 3869 3876 3712 3746 3875 3802 3783 3650 3685 3826 3722 3814 3786 3952 3750 3802 3724 3798 3705 3864 3717 3669 3796 3769 3816 3836 3828 3749 3691 3688 3679 3746 3576 3728 3814 3841 3632 3792 3717 3623 3625 3634 3709 3635 3676 3756 3687 3726 3617 3689 3644 3654 3491 3639 3712 3639 3685 3554 3678 3576 3511 3566 3522 3648 3669 3661 3640 3609 3499 3797 3671 3577 3599 3565 3686 3565 3682 3690 3538 3574 3644 3563 3628 3593 3789 3596 3589 3531 3557 3482 3622 3547 3565 3536 3576 3531 3569 3624 3537 3464 3651 3543 3538 3440 3565 3460 3639 3464 3605 3606 3509 3498 3428 3551 3496 3501 3523 3544 3542 3487 3493 3355 3533 3443 3446 3465 3397 3463 3464 3429 3460 3392 3460 3452 3513 3426 3503 3528 3561 3518 3471 3494 3397 3523 3599 3408 3484 3477 3360 3374 3495 3498 3495 3483 3484 3451 3375 3323 3352 3416 3451 3349 3451 3372 3397 3516 3437 3365 3362 3303 3285 3417 3243 3471 3368 3236 3359 3351 3351 3447 3379 3484 3310 3400 3414 3374 3400 3331 3216 3401 3364 3360 3347 3406 3259 3283 3306 3332 3283 3266 3450 3356 3244 3417 3399 3199 3257 3284 3322 3235 3300 3268 3268 3193 3331 3261 3294 3347 3316 3182 3364 3291 3273 3318 3344 3235 3318 3281 3299 3284 3347 3247 3201 3250 3191 3270 3405 3253 3321 3285 3331 3247 3288 3419 3314 3198 3244 3199 3253 3293 3327 3284 3221 3289 3282 3204 3241 3254 3148 3209 3244 3354 3308 3136 3243 3239 3187 3353 3407 3370 3285 3334 3165 3191 3167 3372 3383 3382 3296 3237 3454 3203 3168 3125 3280 3289 3249 3110 3218 3224 3185 3287 3151 3130 3213 3183 3287 3221 3165 3168 3171 3131 3073 3323 3214 3253 3289 2994 3171 3219 3166 3221 3211 3088 3223 3168 3131 3186 3160 3171 3134 3125 3161 3301 2989 3086 3162 3122 3210 3127 3081 3230 3099 3264 3061 3100 3031 3076 3151 3163 3081 3143 3199 3102 3187 2992 3162 3010 3163 3096 3099 3134 3165 3111 3061 3122 3179 3228 3231 3318 3310 3378 3482 3404 3479 3496 3408 3521 3541 3660 3594 3578 3610 3579 3570 3655 3509 3711 3601 3635 3680 3547 3647 3508 3697 3651 3736 3744 3588 3795 3626 3718 3670 3770 3783 3864 3729 3892 3820 3789 3872 3847 3867 3897 3761 3703 3777 3637 3764 3602 3669 3559 3558 3480 3447 3464 3333 3238 3289 3223 3222 3197 3106 3080 3130 3011 3050 2999 3063 3065 3069 3045 3078 3009 3056 3122 3100 3038 3015 3017 3096 3061 2921 2952 3157 2980 3098 3064 2983 3053 3042 2920 2941 3057 3007 3096 3083 3066 2910 2970 2975 2957 3009 2963 3020 3039 3009 2989 2998 2989 3126 2923 2950 3080 3092 3018 2930 2995 3063 3039 2865 2884 3065 3046 2947 3030 2997 3019 3059 3047 3018 3052 2952 2918 2904 2948 3105 2958 2992 2991 2979 2970 3062 3018 3021 3087 3095 2965 3016 2980 2963 2955 3094 3131 3149 2985 2934 3016 3071 2889 2976 3036 3031 2966 3017 2949 2880 2943 2935 3074 2959 2933 2941 2961 2868 3036 2906 2968 2903 2995 2968 3008 2871 3060 2906 2925 2999 2962 3008 2904 3014 2989 3002 2950 3082 2958 2967 2974 3034 2846 2975 2879 2924 2995 2904 2912 3021 2973 3042 2844 2974 3064 3001 2964 2950 2901 3086 2931 2960 2972 3034 2983 2976 3006 2804 3057 2837 2974 2962 3009 2956 2984 2905 2942 2836 3017 3007 3034 3067 3207 3117 3268 3337 3240 3264 3482 3655 3869 4152 4341 4518 4936 5168 5352 5704 5945 6140 6421 6721 6696 7060 6970 7071 7167 6886 6819 7063 6972 6784 6857 6996 6778 6812 6903 6929 7013 6993 7154 7298 7552 7761 7855 8350 8446 8646 8584 8834 9061 8944 9153 9293 9214 9271 9195 8996 8847 8822 8614 7989 7686 7451 7237 6486 6101 5711 5385 5120 4742 4367 4167 3962 3696 3623 3496 3274 3072 3078 3039 2976 3070 3066 3025 3013 2894 3079 3005 2977 3109 2978 2969 2928 2910 2997 2991 2971 3035 2941 2938 2956 3006 2991 3016 2999 2856 2974 2977 2866 2878 3009 3084 3060 3022 2978 2939 2985 2983 3000 2942 2946 2867 2932 2944 3025 3010 2870 2905 2901 2940 2809 2916 2889 2937 3007 2918 2854 3026 2932 2884 2918 2966 2986 2929 2933 2920 3029 2986 2847 2941 2901 2864 2870 2871 2840 2844 2905 2845 2856 2932 3011 2869 2874 2903 2877 2812 2897 2854 2814 2782 2924 2903 2876 2900 2945 2831 2902 2833 2862 2960 2829 2868 2919 2826 2873 2923 2868 2801 2897 2820 2837 2893 2800 2889 2870 2850 2865 2845 2829 2899 2786 2768 2952 2909 2888 2913 2860 2841 3012 2884 2840 2875 2798 2911 2949 2999 2841 2929 3002 2923 2865 2823 2904 2935 2886 2977 2858 2792 2882 2931 2913 3004 2835 2905 2896 2960 2942 3042 2909 2892 2950 2934 2909 2912 2827 3044 2884 3007 2889 2875 2907 2866 2854 2812 2781 2768 2945 2836 2846 2919 2863 2810 2901 2913 2807 2868 2827 2962 2856 2994 2934 2811 2948 2896 2817 2773 2852 2880 2793 2855 2785 2871 2792 2893 2927 2776 2795 2830 2786 2797 2897 2871 2837 2903 2947 2825 2779 2835 2819 2900 2766 3008 2939 2863 2853 2778 2835 2890 2910 2919 2780 2853 2873 2925 2855 2914 2772 2866 2827 2782 2931 2802 2872 2773 2913 2940 2894 2812 2765 2875 2892 2827 2846 2817 2889 2866 2797 2904 2726 2857 2916 2975 2762 2905 2756 2880 2830 2808 2769 2846 2797 2812 2734 2887 2835 2919 2856 2793 2900 2878 2747 2810 2705 2863 2871 2807 2775 2890 2796 2837 2806 2802 2907 2832 2792 2926 2838 2751 2689 2948 2874 2848 2820 2844 2891 2909 2780 2808 2803 2835 2812 2793 2798 2897 2917 2888 2867 2938 2878 2902 2809 2812 2913 2851 2915 2836 2883 2744 2763 2972 2905 2861 2887 2919 2879 2868 2952 2887 2990 2927 2884 2906 2848 2912 2905 2890 2856 2896 2864 3030 2977 2895 2902 2940 2825 2879 2936 2949 3084 2954 2995 2998 3144 3147 3215 3265 3591 3670 3608 3923 4134 4218 4386 4484 4607 4827 4946 5045 5123 5100 5412 5563 5599 5503 5381 5269 5477 5549 5510 5667 5622 5665 5729 5768 5955 5887 6180 6133 6397 6298 6590 6662 6865 6847 6969 7064 7374 7276 7272 7337 7293 7349 7176 7117 6838 6980 6692 6610 6272 5961 5950 5474 5101 4820 4624 4584 4278 4006 3734 3695 3489 3482 3271 3238 3162 3028 3005 3125 3096 3187 3173 3057 3070 3031 2950 3081 3000 3021 2998 2999 3040 3041 2944 3061 3168 3004 3018 3040 3081 3008 2964 3077 2989 2939 3029 3200 2948 2921 3111 3059 3035 3066 3018 2965 2966 3023 3162 2959 3177 3053 3089 3003 3061 3043 3084 3069 3026 3107 3103 3113 3039 3003 3124 2998 3099 3042 3041 3055 3084 3167 3133 3060 2995 3138 3060 3144 2927 3132 3059 3162 3077 3147 3001 3202 3130 3063 3210 3112 3149 2975 3117 3064 3099 3069 3063 3141 3141 3120 3117 3083 3104 3041 3261 3293 3154 3104 3166 3215 3201 3134 3169 3195 3276 3253 3111 3176 3207 3050 3194 3233 3219 3206 3252 3265 3172 3099 3217 3154 3015 3296 3100 3121 3210 3227 3226 3118 3352 3146 3165 3091 3231 3233 3088 3123 3300 3252 3335 3280 3320 3184 3270 3077 3256 3209 3164 3217 3159 3222 3191 3286 3226 3329 3253 3237 3115 3291 3114 3205 3248 3268 3173 3322 3126 3178 3234 3309 3300 3329 3304 3241 3260 3181 3178 3303 3326 3277 3353 3336 3258 3257 3298 3247 3231 3178 3104 3221 3219 3359 3324 3232 3330 3322 3414 3241 3274 3274 3174 3116 3276 3209 3296 3109 3346 3272 3146 3163 3325 3203 3276 3085 3103 3223 3180 3241 3146 3145 3243 3216 3173 3104 3141 3219 3102 3156 3153 3077 3230 3190 3108 3283 3152 3122 3229 3093 3058 3035 3083 3175 3082 3144 3134 3029 3240 3140 3128 3065 3129 3100 3139 3080 3152 3149 3078 3178 3046 3140 3048 3143 2974 3150 3119 2975 3015 2986 3100 3161 3069 3150 2943 3151 3151 3040 3086 3013 3002 3053 3078 3055 3035 3059 3063 3051 2961 3063 3001 3168 3145 3069 3131 3278 3215 3345 3397 3497 3452 3776 3796 4054 4292 4476 4788 4773 4883 5055 5149 5267 5459 5340 5419 5475 5699 5463 5434 5468 5459 5476 5472 5461 5441 5457 5637 5558 5677 5854 5949 6021 6038 6313 6605 6619 6630 6828 6966 6919 6997 7240 7044 7120 7286 7138 7175 6943 6924 6729 6418 6178 6140 5899 5594 5354 5022 4549 4482 4186 4076 3803 3612 3446 3071 3104 3031 2934 2833 2846 2859 2658 2801 2797 2706 2894 2779 2774 2798 2877 2796 2797 2793 2676 2659 2741 2822 2695 2784 2840 2756 2741 2673 2646 2749 2762 2785 2708 2711 2636 2690 2681 2671 2717 2704 2673 2657 2658 2671 2621 2586 2670 2618 2611 2642 2561 2746 2666 2686 2542 2621 2624 2659 2597 2606 2612 2636 2571 2587 2700 2597 2499 2598 2616 2542 2560 2583 2689 2554 2536 2497 2551 2623 2589 2548 2505 2536 2593 2567 2616 2551 2637 2540 2630 2573 2605 2478 2613 2499 2570 2493 2538 2592 2486 2672 2618 2630 2547 2589 2587 2608 2717 2666 2668 2699 2616 2648 2586 2654 2745 2735 2687 2772 2601 2582 2664 2738 2650 2724 2727 2608 2651 2676 2724 2778 2630 2543 2705 2708 2642 2686 2609 2628 2672 2626 2730 2672 2614 2592 2673 2660 2595 2613 2586 2556 2546 2516 2483 2583 2459 2469 2480 2387 2521 2387 2534 2452 2415 2470 2394 2403 2350 2393 2527 2377 2361 2405 2477 2388 2452 2377 2422 2411 2385 2354 2333 2393 2417 2361 2393 2333 2277 2402 2399 2482 2411 2328 2452 2312 2411 2331 2296 2413 2334 2350 2464 2407 2375 2318 2325 2363 2467 2307 2191 2368 2285 2299 2327 2332 2318 2271 2456 2384 2352 2349 2514 2367 2388 2306 2254 2274 2365 2359 2353 2343 2265 2294 2321 2284 2269 2383 2356 2279 2330 2333 2272 2204 2357 2304 2267 2380 2290 2261 2339 2326 2332 2266 2321 2247 2286 2358 2320 2328 2321 2274 2286 2244 2175 2291 2404 2221 2363 2300 2229 2427 2203 2376 2331 2393 2253 2208 2191 2274 2272 2313 2260 2257 2265 2260 2299 2416 2177 2299 2352 2259 2227 2188 2278 2259 2197 2199 2207 2213 2235 2395 2223 2345 2230 2151 2362 2335 2125 2330 2211 2196 2106 2254 2227 2253 2366 2289 2183 2195 2250 2268 2181 2325 2246 2139 2165 2194 2231 2233 2212 2301 2256 2224 2177 2218 2253 2261 2206 2132 2274 2216 2218 2155 2240 2189 2209 2238 2224 2201 2269 2286 2289 2239 2170 2143 2168 2211 2230 2265 2233 2220 2233 2061 2286 2166 2177 2298 2202 2184 2211 2238 2216 2189 2283 2160 2265 2315 2169 2195 2135 2173 2163 2194 2168 2187 2263 2213 2297 2291 2209 2163 2200 2178 2164 2187 2192 2231 2165 2216 2183 2317 2203 2339 2273 2216 2231 2290 2132 2172 2206 2157 2244 2197 2138 2237 2219 2131 2169 2129 2255 2195 2223 2180 2163 2174 2183 2157 2253 2192 2131 2168 2193 2280 2087 2164 2180 2202 2194 2186 2190 2226 2159 2211 2163 2118 2121 2194 2073 2130 2172 2189 2105 2187 2201 2301 2159 2196 2149 2171 2194 2152 2123 2218 2159 2128 2130 2102 2192 2216 2117 2172 2289 2124 2116 2164 2198 2124 2169 2185 2090 2151 2110 2150 2185 2094 2172 2207 2224 2177 2124 2164 2240 2220 2324 2280 2279 2277 2321 2284 2373 2318 2353 2443 2481 2443 2525 2560 2853 2970 3167 3410 3802 4135 4486 4916 5432 5853 6318 6697 7412 7948 8299 8740 9014 9322 9421 9564 10012 9872 10146 9911 10192 10145 10129 10078 10114 10091 10192 10186 10177 10405 10599 10654 10672 10604 10631 10787 10889 10619 10609 10572 10726 10273 10534 10349 10116 10094 9695 9639 9447 8973 8692 8467 8157 7779 7569 7049 6867 6291 5902 5438 5007 4576 3991 3784 3475 3305 2971 2638 2660 2494 2450 2396 2344 2256 2256 2190 2200 2256 2203 2162 2328 2209 2244 2126 2171 2145 2080 2203 2120 2099 2132 2166 2209 2144 2144 2090 2178 2202 2208 2073 2061 2102 2089 2133 2076 2105 2125 2160 2217 2194 2165 2146 2184 2066 2114 2193 2059 2209 2128 2144 2190 2190 2124 2165 2129 2162 2159 2119 2117 2170 2166 2065 2140 2205 2047 2168 2125 2126 2155 2078 2077 1955 2162 2154 2080 2136 2155 2082 2114 2217 2073 2027 2204 2086 2076 2143 2145 2205 2126 2003 2115 2212 2069 2143 2047 2139 2103 2132 2150 2111 2239 2170 2149 2133 2109 2095 2060 2129 2101 2172 2108 1966 2146 2073 2040 2128 2147 2042 2135 2153 2154 2127 2090 2076 2169 2178 2165 2051 2094 2180 2123 2142 2034 2082 2065 2066 2150 2129 2153 2131 2054 2052 2076 2120 2172 2054 2101 2158 2188 2047 2092 2099 2145 2079 2122 2090 2059 2076 2129 2112 2148 2091 2103 2141 2117 2164 2084 2084 2039 2060 2052 2066 2118 2081 2105 2100 2215 2159 2180 2066 2133 2162 2183 2070 2031 2170 2172 2075 2006 2133 2058 2118 2127 2148 2119 2194 2160 2134 2120 2056 2111 2108 2053 2265 2177 2139 2042 2154 2221 2091 2144 2124 2180 2212 2140 2254 2103 2164 2178 2130 2198 2212 2118 2103 2179 2083 2201 2140 2049 2095 2134 2157 2231 2110 2097 2205 2219 2140 2151 2103 2159 2166 2129 2063 2144 2107 2144 2099 2229 2209 2184 2192 2131 2167 2133 2084 2159 2139 2123 2109 2169 2241 2220 2146 2110 2128 2175 2078 2132 2156 2125 2128 2229 2329 2200 2146 2155 2314 2183 2152 2274 2127 2124 2178 2148 2116 2266 2315 2208 2277 2150 2226 2164 2248 2203 2136 2215 2241 2071 2118 2203 2173 2166 2234 2261 2176 2163 2230 2177 2177 2221 2160 2229 2210 2258 2168 2167 2204 2180 2215 2226 2151 2294 2215 2173 2260 2241 2205 2159 2104 2243 2306 2236 2269 2188 2194 2213 2192 2259 2158 2210 2217 2229 2279 2301 2267 2262 2225 2285 2240 2231 2266 2192 2296 2260 2193 2243 2197 2285 2189 2281 2232 2135 2267 2322 2246 2200 2254 2242 2297 2261 2315 2316 2186 2158 2326 2289 2273 2223 2180 2260 2303 2340 2376 2313 2238 2266 2359 2260 2363 2264 2249 2385 2265 2314 2360 2232 2341 2403 2291 2295 2346 2247 2418 2316 2342 2310 2301 2318 2289 2363 2380 2309 2414 2190 2245 2347 2273 2387 2289 2378 2320 2333 2318 2312 2364 2329 2466 2363 2318 2444 2288 2394 2384 2344 2366 2423 2313 2381 2360 2334 2319 2453 2388 2314 2375 2426 2334 2349 2443 2420 2364 2290 2519 2421 2366 2266 2399 2387 2428 2434 2416 2358 2383 2486 2470 2343 2404 2438 2415 2549 2405 2394 2515 2433 2461 2509 2359 2531 2471 2440 2549 2420 2484 2433 2375 2411 2432 2469 2446 2532 2546 2493 2470 2507 2484 2435 2514 2518 2489 2525 2502 2507 2488 2484 2533 2540 2641 2575 2553 2579 2560 2558 2692 2593 2603 2599 2620 2610 2574 2623 2628 2541 2642 2668 2626 2602 2707 2642 2872 2878 2908 2974 2885 2840 3017 3099 3115 2984 3098 3112 3313 3152 3264 3320 3339 3269 3194 3455 3388 3309 3360 3408 3449 3340 3352 3491 3400 3509 3570 3686 3638 3619 3599 3759 3771 3758 3882 3789 3801 3973 3801 3754 3876 3814 3754 3782 3767 3728 3751 3490 3727 3641 3566 3449 3453 3445 3304 3316 3422 3194 3188 3102 3118 3104 3119 3042 2958 3012 3209 3093 3132 3126 3108 3141 3200 3107 3202 3180 3136 3125 3187 3214 3153 3070 3108 3200 3190 3371 3289 3201 3232 3421 3238 3218 3238 3358 3276 3237 3275 3409 3251 3374 3300 3358 3334 3395 3351 3465 3452 3465 3399 3469 3466 3475 3410 3419 3627 3486 3534 3658 3528 3586 3693 3534 3658 3780 3497 3688 3658 3711 3720 3769 3882 3637 3778 3791 3808 3709 3790 3818 3923 3906 3899 3898 3926 3957 3961 4029 3922 4065 4086 4110 4026 4079 4202 4081 4264 4177 4138 4284 4231 4349 4298 4252 4406 4347 4457 4381 4480 4401 4501 4563 4581 4538 4597 4655 4569 4636 4579 4637 4600 4838 4756 4800 4754 4785 4792 4821 4856 4904 4843 4960 4932 5025 5184 5033 5187 5003 5097 5141 5127 5043 5201 5162 5251 5256 5192 5252 5383 5319 5433 5410 5383 5480 5558 5542 5490 5552 5684 5541 5534 5652 5682 5619 5734 5897 5890 5698 5872 5895 5878 5877 5764 6040 6055 6077 6123 6044 6121 6140 6127 6274 6249 6294 6313 6441 6335 6456 6302 6402 6586 6528 6450 6574 6641 6672 6486 6501 6588 6733 6741 6660 6773 6841 6855 6792 6746 6842 6852 6914 6876 6886 7027 7016 6876 6902 7022 6934 7074 7011 6881 6962 7070 6986 7058 7022 7117 7054 7127 7054 6965 7061 6920 7010 7158 7156 7065 6970 7011 6942 6952 6764 7096 6956 6842 6835 6878 7001 6904 6803 6809 6717 6803 6790 6676 6716 6743 6492 6788 6736 6618 6525 6576 6507 6504 6407 6391 6311 6413 6321 6430 6242 6242 6266 6076 6064 6160 6183 5943 5942 5814 5987 5971 5734 5884 5615 5770 5602 5671 5730 5604 5714 5537 5332 5420 5354 5430 5242 5289 5266 5196 5137 5054 5022 5121 4957 4851 4984 4821 4881 5029 4766 4864 4781 4780 4741 4725 4567 4690 4778 4705 4659 4664 4686 4588 4701 4604 4554 4567 4511 4541 4496 4737 4662 4582 4643 4899 5218 5466 5903 6250 7008 7580 8383 9052 10083 11053 11848 12596 13900 15163 16046 17160 18024 18492 19147 19505 19956 20417 20747 21090 20934 21097 21151 21177 21439 21005 20999 21105 21197 21123 21409 21177 21381 21379 21548 21558 21650 21679 21508 21507 21373 21060 20934 20668 20108 19832 19495 19032 17932 17671 16771 16006 15304 14480 13616 12746 11864 10910 9986 9224 8356 7611 6935 6287 5875 5270 4671 4308 3844 3681 3596 3438 3348 3267 3167 3329 3236 3164 3185 3254 3119 3129 3140 3018 2978 3018 3032 2966 3003 3053 2868 3047 3002 2931 2894 2898 2896 2915 2970 2895 2913 2905 2906 2860 2907 2819 2810 2831 2727 2760 2835 2773 2833 2730 2770 2761 2831 2597 2782 2699 2802 2814 2707 2603 2656 2629 2674 2614 2657 2692 2592 2632 2621 2640 2622 2611 2657 2573 2592 2639 2669 2631 2681 2536 2632 2630 2496 2670 2527 2542 2606 2490 2551 2404 2507 2447 2613 2510 2493 2480 2492 2556 2446 2502 2503 2491 2485 2476 2604 2455 2483 2375 2400 2397 2387 2458 2404 2447 2414 2427 2300 2235 2325 2418 2383 2308 2315 2484 2440 2375 2321 2461 2325 2410 2415 2255 2397 2328 2349 2308 2361 2359 2345 2348 2338 2311 2334 2362 2379 2301 2206 2256 2320 2377 2278 2223 2289 2223 2285 2302 2325 2244 2237 2265 2277 2252 2261 2259 2138 2237 2287 2192 2293 2231 2279 2228 2255 2224 2275 2203 2159 2325 2141 2247 2229 2382 2142 2243 2217 2225 2229 2166 2176 2257 2196 2246 2161 2211 2111 2132 2208 2135 2165 2168 2206 2096 2037 2135 2171 2147 2183 2140 2177 2049 2034 2103 2245 2183 2129 2152 2143 2137 2104 2142 2184 2202 2166 2086 2112 2143 2322 2190 2164 2273 2267 2249 2221 2181 2311 2135 2307 2259 2185 2268 2258 2281 2314 2315 2295 2316 2365 2249 2205 2283 2409 2308 2340 2275 2286 2361 2352 2340 2383 2438 2327 2365 2261 2428 2336 2313 2364 2362 2368 2312 2346 2382 2282 2382 2258 2307 2271 2301 2224 2258 2167 2292 2157 2197 2234 2145 2094 2090 2095 2061 2080 2099 1981 2103 2004 2072 2020 1992 2029 1948 2015 1977 2062 2007 1966 2037 2040 2015 1939 1964 2056 2022 1991 1925 2020 1953 1975 1986 1982 1987 2014 2027 2032 2050 1984 1974 1984 1936 2018 1984 1898 1946 1981 2052 1951 1931 1940 1978 1986 2014 2052 2012 1960 2011 1895 1914 2018 1920 1822 2047 1983 1978 1994 1997 1920 1886 1939 1917 1946 2061 1999 1985 1960 1884 1884 2008 2038 1961 1927 1951 1965 1919 1968 1962 2004 1909 1920 1963 1943 1887 1912 2014 1903 1963 1884 1910 1997 1978 1890 2012 1815 1890 1878 1896 1891 1908 1964 1883 1917 1919 1897 1867 1797 1837 1945 1870 1988 1901 1952 1891 1830 2032 1869 1947 1913 1915 1876 1868 1958 1857 1933 1873 1840 1849 1866 1803 1907 1894 1963 1907 1882 1823 1929 1803 1884 1875 1842 1912 1863 1879 1864 1952 1875 1960 1960 1982 1928 1916 1958 1862 1942 1934 1958 1969 1948 1908 2023 1961 1946 1964 2047 1990 1937 2005 1956 2033 1967 2013 1915 1959 1900 2039 1946 1919 1977 1910 1981 1942 2028 1981 2078 1930 1951 2009 2019 1976 2021 1913 2024 1900 1921 2028 1971 1930 1811 1962 1892 1884 2013 1933 1955 1941 1903 1875 1793 1787 1861 1871 1793 1857 1945 1809 1918 1830 1879 1863 1928 1850 1836 1794 1775 1796 1879 1830 1864 1857 1788 1866 1767 1676 1841 1896 1882 1893 1860 1769 1865 1831 1812 1840 2007 1910 1835 1859 1767 1709 1842 1834 1876 1814 1871 1843 1812 1853 1942 1818 1864 1866 1918 1822 1891 1837 1832 1956 1901 1788 1885 1649 1839 1717 1757 1902 1879 1805 1930 1893 1858 1875 1873 1732 1823 1824 1926 1872 1947 1777 1859 1851 1828 1791 1932 1859 1862 1792 1847 1796 1881 1913 1818 1855 1904 1768 1860 1838 1898 1931 1903 1914 1814 1847 1757 1875 1845 1801 1907 1885 1819 1940 1874 1878 1888 1880 1876 1867 1869 1921 1844 1911 1913 1859 1780 1913 1917 1977 1801 1915 1903 1851 1870 1888 1875 1880 1904 1911 1894 1829 1964 1861 1840 1867 2060 1983 1947 1886 1948 1845 1868 1903 1945 1898 1802 1889 1797 1868 1966 1906 1891 1856 1935 1840 1893 1853 1929 1885 1749 1909 1791 1907 1896 1820 1783 1828 1738 1757 1907 1930 1860 1819 1835 1859 1904 1832 1818 1803 1837 1889 1836 1853 1878 1753 1790 1889 1904 1829 1891 1883 1867 1828 1921 1897 1952 1866 1928 1833 1823 1864 1948 1836 1867 1901 1733 1799 1876 1868 1736 1669 1838 1836 1794 1832 1845 1895 1749 1870 1834 1893 1857 1796 1940 1817 1812 1905 1747 1958 1691 1933 1947 1897 1936 1919 1929 1911 1846 1879 1889 1904 1849 1879 1904 1862 1876 1883 1880 1957 1968 1877 1897 1918 1889 1942 1894 1818 1893 1865 1973 1881 1920 1878 1912 1924 1832 1852 1851 1927 1867 1922 1946 1853 1895 1961 1830 1867 1899 1916 1948 1914 1917 1841 1976 1818 1866 1860 1976 1885 1869 1827 1884 1945 1791 1837 1890 1850 1976 1894 1919 1997 1809 1781 1877 1755 1862 1957 1908 1902 1938 1932 1839 1903 1942 1732 1968 1909 1922 1870 1837 1855 1956 1916 1946 1903 1925 1805 1886 1846 1826 1921 1893 1938 1934 1934 1919 1898 1939 1882 1901 1821 1904 1845 1914 1896 1942 1935 1873 1979 1930 1911 1927 1862 1931 1953 1900 1958 1950 1855 1994 1841 1955 1861 1912 1821 1898 1810 2023 1948 1944 1806 1953 1870 1942 1961 1955 1913 1852 1932 1840 1922 1902 1835 1968 1892 1941 1890 1894 1987 1896 1911 1822 1937 1978 1975 2020 1964 1882 1839 1952 1928 1940 1877 2008 1949 2018 1958 1992 1968 1842 1962 1909 1907 1951 1997 2006 1909 1911 1934 1980 1908 1941 1944 2009 2074 1946 2060 1979 2008 2064 2112 2030 2094 2088 2105 2111 2128 2139 2141 2156 2166 2164 2138 2174 2140 2099 2210 2176 2263 2130 2254 2165 2368 2161 2236 2246 2360 2351 2338 2434 2296 2414 2377 2371 2387 2393 2306 2295 2330 2337 2341 2379 2286 2285 2307 2200 2225 2144 2194 2104 2141 2237 2285 2154 2108 2075 2108 2119 2080 2069 2051 1981 1951 1989 1843 1920 1919 1944 2078 1944 1978 1965 1917 1948 1973 2038 1874 1977 2016 1840 1927 1949 1928 1922 1971 1960 2004 1976 1969 2020 1998 2017 2027 1994 1969 2048 1872 1989 1953 1993 1991 2011 1927 2041 1998 1900 2018 1979 1908 1951 2014 1969 1936 2022 1969 2024 2005 2017 1989 2005 2009 1939 1922 1964 2086 1939 2043 1963 2061 1994 2119 2072 2074 2153 2069 2084 2094 2118 2224 2239 2302 2191 2282 2221 2251 2362 2297 2327 2279 2229 2360 2368 2344 2387 2277 2502 2298 2420 2375 2392 2393 2464 2580 2464 2387 2481 2381 2469 2490 2428 2499 2520 2541 2451 2636 2573 2488 2525 2433 2441 2475 2385 2506 2465 2440 2447 2380 2387 2308 2412 2257 2317 2247 2195 2173 2169 2171 2137 2156 2125 2127 2076 2058 2053 2042 2003 1990 2052 2060 2006 2053 1994 1954 2042 2043 2048 2101 2128 2110 2122 1981 2084 2133 2129 2039 2019 2072 2055 2067 2018 2038 1992 2082 2070 2099 2102 1995 2139 2068 2083 2008 2046 2127 2187 2138 2127 2028 2082 2174 2106 2171 2181 2160 2078 2169 2155 2157 2146 2241 2228 2182 2217 2303 2138 2114 2153 2190 2215 2221 2170 2239 2184 2219 2141 2210 2185 2310 2154 2182 2325 2318 2349 2142 2258 2160 2228 2223 2155 2173 2218 2147 2231 2140 2195 2153 2240 2183 2128 2150 2100 2111 2135 2156 2171 2163 2062 2138 2010 2074 2097 2143 2072 2169 2202 2273 2186 2194 2121 2042 2097 2194 2140 2112 2101 2157 2089 2234 2070 2164 1998 2119 2162 2068 2118 2057 2093 2196 2151 2233 2144 2195 2136 2120 2101 2148 2153 2170 2157 2137 2151 2060 2088 2171 2175 2137 2149 2109 2176 2089 2097 2178 2152 2042 2097 2114 2092 2209 2166 2174 2226 2152 2242 2239 2190 2140 2259 2134 2172 2221 2112 2157 2178 2237 2246 2193 2161 2152 2266 2132 2212 2253 2232 2255 2248 2270 2137 2241 2093 2084 2195 2161 2163 2173 2242 2179 2234 2263 2220 2195 2156 2153 2219 2247 2173 2211 2230 2234 2304 2318 2132 2299 2197 2214 2288 2287 2155 2260 2358 2206 2206 2213 2278 2230 2295 2106 2217 2272 2146 2201 2246 2148 2092 2256 2255 2275 2217 2177 2224 2282 2161 2239 2258 2254 2185 2360 2256 2208 2190 2270 2232 2241 2219 2194 2256 2228 2229 2241 2210 2208 2200 2339 2276 2311 2283 2287 2267 2296 2142 2287 2214 2240 2267 2229 2291 2178 2302 2287 2255 2220 2179 2272 2244 2253 2290 2161 2378 2358 2236 2267 2326 2244 2271 2246 2327 2225 2376 2279 2285 2268 2185 2281 2233 2291 2250 2312 2385 2318 2300 2264 2300 2160 2301 2260 2249 2226 2259 2301 2341 2296 2329 2188 2366 2233 2336 2310 2387 2295 2219 2261 2313 2350 2193 2277 2354 2367 2302 2446 2281 2317 2335 2326 2200 2257 2351 2303 2293 2341 2328 2326 2316 2310 2416 2312 2435 2350 2392 2334 2320 2307 2317 2294 2226 2274 2337 2381 2336 2292 2320 2346 2393 2357 2338 2397 2248 2273 2403 2260 2320 2362 2325 2299 2352 2237 2410 2336 2376 2274 2344 2428 2261 2319 2331 2313 2370 2377 2393 2377 2312 2329 2306 2309 2355 2366 2233 2371 2338 2392 2342 2438 2430 2234 2399 2353 2351 2363 2279 2303 2374 2281 2455 2356 2396 2380 2359 2381 2465 2359 2307 2384 2400 2468 2464 2372 2494 2476 2459 2447 2353 2522 2375 2396 2445 2562 2428 2480 2546 2350 2460 2460 2436 2479 2371 2411 2464 2491 2417 2432 2312 2361 2459 2451 2439 2350 2397 2557 2527 2498 2382 2500 2363 2446 2427 2474 2397 2486 2507 2478 2443 2538 2455 2363 2417 2507 2401 2458 2386 2460 2504 2431 2561 2505 2494 2464 2573 2443 2418 2485 2444 2493 2418 2478 2486 2448 2467 2450 2481 2441 2501 2509 2517 2541 2458 2347 2407 2399 2546 2438 2506 2578 2406 2484 2518 2639 2497 2541 2486 2476 2485 2429 2520 2590 2581 2579 2553 2474 2508 2464 2519 2537 2617 2527 2613 2507 2538 2446 2523 2558 2577 2546 2512 2441 2651 2622 2548 2526 2456 2556 2449 2564 2547 2545 2552 2529 2576 2618 2537 2538 2534 2496 2499 2529 2535 2578 2652 2528 2565 2547 2540 2493 2559 2514 2541 2606 2598 2568 2454 2633 2569 2637 2611 2609 2586 2572 2566 2552 2594 2603 2587 2615 2486 2551 2558 2539 2593 2455 2766 2627 2667 2586 2655 2477 2499 2622 2700 2641 2554 2635 2619 2679 2659 2555 2649 2629 2733 2702 2506 2660 2651 2663 2674 2687 2725 2548 2658 2691 2616 2545 2588 2707 2686 2623 2766 2579 2620 2617 2486 2649 2599 2666 2552 2644 2517 2687 2582 2682 2640 2659 2684 2562 2661 2576 2721 2650 2572 2678 2620 2714</counts>
			</dataPoints>
		</scan>
	</xrdMeasurement>
</xrdMeasurements>