File: Data Files/Full/MSS p (6-129, 7w)_01.xrdml
<?xml version="1.0"?>
<xrdMeasurements xmlns="http://www.xrdml.com/XRDMeasurement/2.2" xmlns:xsi="http://www.w3.org/2001/XMLSchema-instance" xsi:schemaLocation="http://www.xrdml.com/XRDMeasurement/2.2 http://www.xrdml.com/XRDMeasurement/2.2/XRDMeasurement.xsd" status="Completed" recordIdentifier="{958A9CB0-B1F4-45B7-BC20-0535A48621A5}">
	<comment>
		<entry/>
	</comment>
	<sample type="To be analyzed">
		<id>p</id>
		<name></name>
		<preparedBy></preparedBy>
	</sample>
	<xrdMeasurement measurementType="Scan" status="Completed" sampleMode="Reflection">
		<usedWavelength intended="K-Alpha 1">
			<kAlpha1 unit="Angstrom">1.5405980</kAlpha1>
			<kAlpha2 unit="Angstrom">1.5444260</kAlpha2>
			<kBeta unit="Angstrom">1.3922500</kBeta>
			<ratioKAlpha2KAlpha1>0.5000</ratioKAlpha2KAlpha1>
		</usedWavelength>
		<incidentBeamPath>
			<radius unit="mm">145.00</radius>
			<xRayTube id="1010048" name="Empyrean Cu LFF HR (9430 033 7310x) DK437964">
				<tension unit="kV">40.0</tension>
				<current unit="mA">15.0</current>
				<anodeMaterial>Cu</anodeMaterial>
				<focus type="Line">
					<length unit="mm">12.0</length>
					<width unit="mm">0.4</width>
					<takeOffAngle unit="deg">6.0</takeOffAngle>
				</focus>
			</xRayTube>
			<filter id="20010004" name="Beta-filter Nickel">
				<material>Ni</material>
				<thickness unit="mm">0.020</thickness>
			</filter>
			<sollerSlit id="21010002" name="Soller slits 0.04 rad.">
				<opening unit="rad">0.0400</opening>
			</sollerSlit>
			<mask id="22031000" name="Fixed mask 13 mm">
				<width unit="mm">9.00</width>
			</mask>
			<divergenceSlit id="22120002" name="Divergence slit 1/2°" xsi:type="fixedDivergenceSlitType">
				<distanceToSample unit="mm">50.00</distanceToSample>
				<height unit="mm">0.76</height>
			</divergenceSlit>
		</incidentBeamPath>
		<diffractedBeamPath>
			<radius unit="mm">145.00</radius>
			<parallelPlateCollimator id="25020001" name="Parallel plate collimator 0.28°">
				<opening unit="deg">0.28</opening>
			</parallelPlateCollimator>
			<detector id="7010020" name="PIXcel3D-Medipix3 1x1 detector" xsi:type="areaDetectorType">
				<phd unit="keV">
					<lowerLevel>4.0</lowerLevel>
					<upperLevel>11.3</upperLevel>
				</phd>
				<mode>Receiving slit</mode>
				<activeChannelsEquatorial>255</activeChannelsEquatorial>
				<activeChannelsAxial>255</activeChannelsAxial>
				<pitchEquatorial unit="mm">0.05500</pitchEquatorial>
				<pitchAxial unit="mm">0.05500</pitchAxial>
				<readOutPeriod unit="seconds">0.050</readOutPeriod>
			</detector>
		</diffractedBeamPath>
		<scan appendNumber="0" mode="Continuous" scanAxis="2Theta" status="Completed">
			<header>
				<startTimeStamp>2025-06-24T15:23:54-08:00</startTimeStamp>
				<endTimeStamp>2025-06-25T05:03:58-08:00</endTimeStamp>
				<author>
					<name>Instrument</name>
				</author>
				<source>
					<applicationSoftware version="1.6 (94)">PANalytical Aeris Instrument Suite</applicationSoftware>
					<instrumentControlSoftware version="3.0.0 20211014">AERIS</instrumentControlSoftware>
					<instrumentID>2855484</instrumentID>
				</source>
			</header>
			<dataPoints>
				<positions axis="2Theta" unit="deg">
					<startPosition>6.005</startPosition>
					<endPosition>128.995</endPosition>
				</positions>
				<positions axis="Omega" unit="deg">
					<commonPosition>7.000</commonPosition>
				</positions>
				<commonCountingTime unit="seconds">3.520</commonCountingTime>
				<counts 3770 3745 3690 3829 3619 3755 3661 3699 3746 3729 3644 3805 3628 3664 3733 3759 3680 3624 3738 3706 3679 3789 3627 3550 3696 3716 3718 3654 3711 3738 3739 3784 3732 3702 3748 3817 3756 3743 3810 3890 3788 3665 3785 3711 3801 3851 3835 3771 3691 3826 3684 3722 3742 3813 3751 3764 3674 3778 3772 3834 3799 3810 3780 3723 3649 3684 3717 3738 3641 3639 3642 3701 3713 3798 3790 3658 3633 3732 3718 3642 3645 3610 3695 3620 3690 3608 3678 3532 3584 3650 3531 3588 3735 3542 3530 3612 3700 3574 3509 3455 3497 3622 3531 3499 3471 3523 3607 3537 3557 3569 3455 3488 3609 3567 3443 3424 3527 3406 3448 3436 3415 3417 3449 3505 3583 3409 3495 3471 3386 3476 3373 3464 3339 3374 3428 3325 3393 3233 3365 3402 3308 3428 3297 3383 3367 3408 3388 3346 3332 3302 3337 3305 3310 3368 3362 3246 3323 3296 3298 3363 3291 3350 3343 3328 3252 3248 3320 3215 3358 3233 3189 3291 3213 3175 3322 3239 3356 3232 3186 3183 3220 3182 3228 3165 3225 3133 3186 3204 3170 3198 3124 3136 3156 3161 3221 3151 3091 3258 3055 3201 3323 3340 3219 3307 3252 3208 3205 3255 3258 3219 3315 3231 3182 3309 3253 3287 3410 3289 3273 3279 3332 3145 3186 3228 3363 3237 3282 3296 3373 3264 3358 3388 3336 3311 3289 3340 3300 3385 3267 3379 3364 3352 3339 3441 3350 3422 3354 3344 3270 3373 3270 3340 3261 3301 3338 3310 3307 3342 3335 3222 3213 3236 3255 3295 3388 3240 3231 3170 3279 3296 3237 3175 3221 3216 3186 3177 3134 3137 3084 3174 3014 3088 3002 3179 3014 3018 2856 2931 2970 3039 2953 3023 2877 2927 2928 2907 2911 2948 2944 3013 2846 2842 2822 2808 3017 2842 2921 2906 2961 2964 2995 2953 2955 2894 2913 2824 2972 2937 2968 2909 2882 2868 2903 2974 2804 2914 2912 2999 2961 2958 2850 3014 2912 2981 3003 2888 2983 2952 2972 2934 2909 2922 2924 2916 2942 2965 2994 2985 3181 3226 3285 3397 3624 3894 3973 4105 4543 4643 4835 5018 4999 5488 5415 5696 5886 6089 6365 6606 6879 7172 7628 7968 8045 8507 8720 8692 8972 9030 9130 9130 8849 8785 8345 8041 7363 7182 6598 6189 5718 5379 4926 4531 4169 3883 3627 3318 3095 3139 3107 2947 2930 2987 2840 3087 2989 2991 2959 2941 3096 2998 3156 2980 2976 2877 2936 3033 3043 3048 3021 2919 2985 3013 3096 2990 2975 2930 3046 2986 3067 2966 3054 2943 3021 2955 2969 3037 3020 3069 3036 3078 3006 3104 3107 3041 2992 3083 3017 3065 3050 3122 3051 2999 3142 3165 3014 3079 3096 3215 3102 3170 3134 3076 3098 3067 3057 3278 3155 3082 3167 3100 3157 3156 3216 3174 3168 3305 3220 3172 3205 3201 3168 3242 3271 3169 3168 3197 3334 3254 3136 3243 3186 3218 3341 3255 3184 3285 3179 3285 3220 3264 3174 3259 3372 3308 3264 3157 3295 3301 3261 3341 3228 3202 3315 3344 3339 3282 3331 3280 3403 3285 3367 3357 3462 3278 3430 3368 3319 3392 3511 3368 3431 3328 3389 3410 3450 3461 3466 3459 3521 3463 3325 3492 3466 3381 3448 3404 3410 3493 3462 3527 3459 3489 3425 3612 3506 3616 3580 3395 3501 3607 3557 3587 3598 3534 3432 3579 3615 3436 3474 3609 3550 3582 3669 3578 3572 3511 3717 3532 3631 3508 3695 3612 3646 3616 3651 3608 3747 3773 3624 3651 3612 3610 3752 3672 3629 3687 3698 3658 3693 3786 3774 3869 3724 3764 3760 3795 3736 3733 3832 3723 3764 3859 3844 3896 3757 3943 3944 3763 3767 3848 3863 3793 3893 3853 4071 3874 3814 3862 3923 3873 3830 3910 3879 3976 3893 4030 3958 3890 4096 4016 3799 3967 4005 4059 4105 3972 4118 3987 4151 4135 4025 4097 3977 4057 4010 4092 4139 4131 4108 4205 4046 4053 4129 4168 4123 4288 4105 4150 4078 4174 4147 4143 4193 4236 4397 4298 4238 4177 4315 4283 4333 4198 4273 4266 4303 4352 4314 4202 4234 4264 4369 4408 4311 4284 4167 4256 4263 4261 4351 4361 4481 4377 4216 4472 4486 4459 4535 4575 4558 4412 4470 4469 4502 4587 4390 4543 4434 4533 4516 4507 4546 4502 4542 4570 4594 4619 4613 4403 4574 4503 4374 4464 4605 4529 4676 4558 4615 4569 4655 4692 4575 4521 4723 4557 4752 4542 4559 4703 4599 4745 4646 4803 4578 4685 4599 4618 4651 4792 4835 4645 4656 4674 4689 4759 4832 4588 4801 4692 4627 4720 4760 4762 4790 4649 4627 4598 4787 4847 4705 4713 4782 4811 4795 4672 4759 4713 4794 4845 4831 4718 4747 4801 4708 4660 4856 4589 4809 4909 4774 4622 4822 4817 4649 4812 4622 4720 4704 4791 4726 4724 4837 4760 4740 4646 4682 4560 4640 4819 4609 4758 4728 4686 4623 4513 4747 4706 4652 4675 4715 4676 4686 4557 4656 4567 4578 4468 4742 4725 4565 4558 4748 4649 4515 4598 4586 4486 4664 4543 4604 4579 4520 4343 4502 4475 4509 4489 4572 4475 4524 4538 4469 4544 4169 4571 4393 4454 4341 4419 4325 4254 4473 4277 4399 4195 4210 4300 4310 4418 4223 4298 4368 4313 4353 4341 4303 4250 4405 4233 4394 4355 4383 4258 4224 4308 4337 4220 4120 4139 4357 4220 4222 4201 4175 4123 4189 4072 4240 4080 4227 4176 4113 4106 4046 4180 4119 4034 4074 3953 4012 3916 3942 3970 4028 4206 4056 3897 4092 3976 3974 3974 3941 3993 3854 3975 3947 3914 3897 3914 3933 3949 3908 3770 3847 3841 3703 3733 3800 3869 3870 3772 3900 3833 3817 3743 3887 3716 3753 3608 3688 3673 3638 3771 3730 3750 3679 3708 3768 3742 3644 3636 3654 3680 3493 3453 3652 3683 3654 3766 3734 3456 3612 3608 3660 3563 3625 3520 3601 3507 3475 3453 3445 3457 3459 3496 3520 3517 3466 3364 3450 3240 3386 3374 3384 3357 3456 3374 3492 3407 3364 3324 3330 3345 3308 3376 3330 3319 3339 3178 3382 3327 3183 3274 3360 3224 3318 3266 3332 3280 3197 3200 3220 3248 3160 3241 3168 3254 3126 3138 3143 3193 3161 3226 3198 3122 3048 3106 3253 3079 3027 3102 3119 3143 3059 3076 3258 2991 3004 3059 3015 3161 3058 3057 3036 3016 3153 2988 3053 3010 3021 3022 2955 2935 3094 3007 3032 3012 3011 2954 3047 2929 2920 2978 2965 2912 2965 3047 2949 2897 2880 2926 2935 2927 3054 2903 2928 2896 2896 2914 2920 2944 2935 2930 2897 2908 2888 2850 2773 2908 2788 2825 2915 2837 2828 2911 2871 2861 2839 2760 2950 2866 2793 2820 2772 2837 2765 2847 2816 2636 2715 2767 2661 2788 2664 2759 2644 2735 2682 2760 2830 2735 2724 2765 2739 2719 2690 2621 2628 2738 2663 2622 2680 2682 2629 2672 2545 2674 2669 2610 2601 2756 2743 2514 2766 2672 2632 2643 2647 2722 2664 2519 2599 2661 2651 2662 2642 2635 2595 2618 2604 2537 2578 2504 2598 2571 2563 2586 2641 2591 2533 2491 2527 2596 2564 2386 2418 2624 2548 2593 2556 2474 2498 2500 2400 2470 2546 2492 2511 2504 2465 2588 2480 2471 2527 2367 2465 2519 2524 2408 2527 2462 2474 2399 2506 2477 2352 2417 2453 2383 2460 2455 2461 2426 2404 2471 2501 2369 2394 2424 2400 2428 2392 2447 2432 2536 2342 2452 2471 2420 2481 2543 2476 2477 2493 2439 2499 2488 2534 2454 2444 2409 2484 2533 2465 2541 2469 2552 2536 2492 2572 2498 2563 2482 2483 2493 2376 2495 2401 2509 2511 2479 2368 2341 2296 2414 2417 2335 2326 2368 2282 2331 2318 2364 2251 2341 2227 2258 2358 2319 2402 2254 2265 2377 2206 2262 2385 2383 2302 2275 2204 2256 2266 2302 2214 2197 2241 2346 2224 2278 2295 2273 2329 2217 2264 2229 2311 2290 2189 2260 2259 2267 2180 2312 2294 2250 2220 2289 2298 2219 2240 2249 2252 2243 2302 2112 2240 2278 2235 2170 2169 2183 2142 2226 2226 2191 2257 2237 2184 2151 2201 2196 2253 2196 2180 2252 2153 2206 2143 2141 2185 2114 2213 2163 2166 2085 2068 2217 2107 2164 2131 2125 2069 2105 2212 2095 2196 2139 2108 2058 2127 2232 2118 2150 2147 2187 2222 2183 2112 2219 2194 2139 2050 2209 2188 2163 2020 2073 2080 2112 2124 2128 2072 2123 2104 2179 2148 2150 2108 2077 2179 1991 2098 2083 2036 2060 2186 2132 2117 2117 2116 2093 2092 2159 2095 2184 2118 2074 2171 2057 2090 2101 2043 2022 2100 2145 2077 2082 2077 2150 2030 2034 2088 2146 2004 2052 2135 2123 2223 1999 2080 1995 2123 2071 2086 2087 2133 2140 2054 2123 2067 2157 2038 2085 2090 2063 2145 2136 2073 2161 2076 2034 2054 2048 2108 2084 2158 2100 2109 2089 2202 2151 2386 2385 2603 2780 3088 3181 3255 3559 3836 4033 4290 4548 4890 5006 5169 5446 5853 5951 6102 6225 6459 6646 6710 6821 7097 6888 6977 6996 6921 6853 6711 6597 6386 6048 5828 5538 5011 4684 4287 3904 3517 3233 3202 2918 2624 2379 2262 2129 2187 2037 2065 2004 2046 1999 1987 1977 2093 2045 2089 2117 2011 2002 2065 2045 1934 1974 1979 2078 2009 2043 1962 1962 1983 1951 2048 1940 2026 1880 1941 1889 1990 1975 1913 1988 2042 1903 1987 1927 1943 2003 1967 1966 1991 1810 1922 1997 1879 1866 1895 1934 1839 1892 1883 1926 1884 1968 2003 1945 1931 1897 1996 1922 1966 1943 1836 1952 1948 1900 1994 1881 1854 1917 1940 1921 1834 1827 1950 1958 1897 1912 1885 1949 1853 1960 1865 1927 1881 1865 1827 1857 1982 1889 1940 1916 1911 1915 1860 1933 1921 1899 1766 1997 1933 1837 1947 1875 1886 1789 1888 1911 1808 1895 1858 1798 1860 1914 1799 1900 1895 1862 1867 1849 1823 1834 1923 1858 1872 1923 1963 1812 1819 1863 1860 1823 1896 1864 1890 1813 1833 1879 1878 1930 1822 1773 1828 1832 1981 1884 1889 1791 1853 1760 1869 1814 1857 1857 1902 1890 1885 1839 1801 1829 1831 1833 1843 1810 1855 1772 1805 1835 1883 1863 1787 1818 1835 1836 1820 1757 1873 1843 1939 1753 1871 1823 1904 1789 1753 1748 1773 1832 1867 1902 1810 1795 1875 1865 1850 1810 1783 1805 1830 1868 1744 1726 1800 1804 1864 1834 1842 1814 1846 1825 1879 1883 1744 1794 1813 1742 1884 1856 1844 1764 1856 1804 1877 1821 1814 1790 1767 1826 1895 1883 1783 1768 1832 1848 1887 1639 1783 1822 1758 1828 1857 1729 1764 1780 1826 1788 1889 1797 1828 1842 1818 1731 1774 1789 1618 1904 1830 1791 1770 1803 1806 1764 1839 1709 1873 1848 1795 1788 1600 1672 1776 1709 1802 1750 1768 1791 1719 1800 1792 1821 1738 1790 1858 1836 1794 1861 1760 1819 1800 1859 1734 1870 1860 1779 1790 1885 1794 1830 1727 1813 1696 1842 1810 1832 1858 1713 1801 1844 1841 1876 1766 1842 1724 1883 1930 1864 1718 1819 1801 1822 1820 1706 1707 1814 1695 1866 1774 1691 1886 1799 1872 1789 1745 1774 1674 1777 1845 1894 1865 1828 1663 1753 1853 1768 1782 1892 1817 1829 1864 1825 1770 1754 1764 1849 1853 1675 1945 1866 1804 1804 1866 1811 1850 1915 1747 1876 1726 1882 1831 1893 1910 1922 1715 1918 1967 1786 1796 1879 1889 1920 1962 1878 1975 1989 2086 2377 2343 2608 2892 3069 3480 3525 3826 4177 4505 4829 5242 5705 5872 6297 6615 7086 7102 7560 8048 8318 8735 8953 9141 9514 9667 9675 9852 9626 9695 9440 8993 9049 8419 8089 7391 6941 6139 5514 5014 4441 4195 3651 3336 2706 2550 2362 2103 2089 2045 1988 2036 2007 1947 1991 1959 1929 1970 1936 1927 1903 1863 1890 1859 1869 1793 1838 1919 1815 1827 1779 1803 1829 1860 1776 1745 1821 1758 1708 1667 1973 1780 1752 1730 1745 1673 1840 1843 1826 1734 1774 1707 1787 1687 1624 1810 1813 1828 1799 1746 1790 1710 1659 1747 1654 1767 1706 1760 1645 1705 1819 1659 1662 1738 1793 1807 1746 1764 1623 1685 1601 1754 1763 1613 1781 1648 1748 1775 1645 1798 1655 1736 1773 1778 1719 1768 1763 1626 1648 1714 1750 1651 1500 1711 1734 1599 1682 1716 1722 1534 1796 1680 1773 1675 1699 1691 1669 1578 1764 1637 1750 1646 1672 1728 1673 1700 1618 1646 1624 1672 1739 1754 1734 1679 1610 1704 1662 1789 1657 1605 1720 1606 1623 1636 1709 1630 1671 1734 1734 1471 1715 1741 1764 1720 1674 1734 1657 1668 1626 1675 1791 1701 1821 1707 1609 1696 1762 1594 1785 1710 1812 1711 1670 1776 1654 1694 1583 1623 1697 1716 1700 1705 1816 1667 1635 1787 1610 1720 1769 1726 1754 1676 1713 1642 1784 1755 1635 1555 1614 1784 1686 1605 1702 1662 1802 1726 1785 1738 1593 1800 1752 1686 1753 1657 1798 1744 1684 1802 1671 1746 1743 1670 1737 1710 1645 1759 1630 1501 1737 1723 1818 1648 1781 1767 1709 1778 1676 1752 1778 1795 1745 1612 1634 1707 1713 1709 1739 1721 1724 1588 1663 1737 1675 1647 1769 1794 1761 1679 1759 1784 1672 1659 1720 1760 1668 1691 1736 1661 1696 1712 1679 1741 1731 1695 1746 1709 1738 1659 1770 1816 1579 1697 1764 1760 1671 1595 1595 1711 1818 1819 1624 1743 1701 1699 1761 1712 1895 1750 1690 1793 1739 1701 1809 1744 1786 1760 1807 1846 1605 1773 1804 1874 1813 1730 1836 1859 1829 1714 1716 1749 1779 1841 1864 1936 1848 1918 1927 1995 2096 2186 2326 2532 2696 2881 2923 3120 3386 3635 3765 3766 4113 4491 4596 4711 4748 5010 5339 5419 5780 5913 5946 6090 6065 6211 6183 6227 6094 5908 5932 5711 5638 5241 5025 4758 4468 4205 3840 3364 3233 2964 2815 2597 2360 2206 2114 1983 2014 1913 1922 1902 1920 1943 1945 1840 1858 1965 1937 1921 1909 1909 1881 1855 1974 1986 1896 1934 1957 1969 1823 1979 1908 1830 1888 1941 1916 1852 1805 1913 1933 1868 1981 1861 1931 1790 1871 1819 1896 1885 1822 2027 1890 1881 1898 1872 1890 1941 1888 1803 1808 1896 1924 1883 1957 1953 1913 1784 1967 1903 1948 2007 1947 1948 2061 1992 1952 1977 1934 1921 1986 1897 2053 1999 1910 1939 2009 2028 2069 2018 1935 2009 1928 1886 1967 2034 1973 1978 2028 1995 2016 2024 1932 1995 2012 2010 2056 2032 1947 2071 2039 2112 2068 2115 2053 2072 2019 2069 2004 2121 2038 2060 2098 2034 2111 2119 2124 2187 2188 2219 2183 2197 2177 2211 2171 2297 2298 2277 2298 2228 2357 2265 2314 2378 2354 2348 2427 2434 2328 2296 2259 2359 2299 2316 2316 2303 2290 2357 2316 2353 2185 2245 2239 2229 2236 2159 2135 2178 2150 2256 2278 2145 2235 2267 2140 2197 2159 2280 2209 2180 2277 2318 2193 2248 2196 2206 2281 2217 2207 2325 2263 2244 2249 2231 2142 2244 2280 2316 2229 2223 2158 2275 2257 2231 2245 2280 2201 2125 2197 2129 2278 2309 2280 2191 2253 2215 2279 2215 2252 2221 2275 2186 2193 2214 2315 2136 2112 2182 2145 2203 2165 2058 2188 2137 2160 2214 2172 2158 2176 2149 2190 2114 2077 2142 2175 2120 2169 2096 2184 2134 2115 2058 2054 2177 2163 1986 2048 2114 2105 2017 2004 2038 2073 2064 2030 2069 2026 2063 2085 2017 2104 2048 2074 2048 2031 2052 1987 1953 2059 1968 1925 1925 1960 1965 1980 2011 1936 1989 1965 1975 1909 1898 2018 1893 1956 1909 1919 1946 1829 1772 1907 1871 1875 1903 1901 1845 1971 1831 1920 1891 1905 1957 1899 1880 1862 1897 1854 1954 1827 1754 1855 1740 1713 1784 1806 1714 1754 1732 1727 1701 1794 1810 1646 1755 1716 1850 1769 1704 1722 1693 1725 1662 1800 1743 1678 1804 1675 1692 1705 1589 1478 1604 1657 1675 1630 1639 1741 1665 1646 1647 1783 1735 1713 1739 1557 1697 1571 1627 1699 1745 1641 1738 1541 1556 1598 1591 1584 1548 1560 1626 1519 1615 1574 1330 1464 1605 1512 1602 1536 1604 1579 1591 1651 1551 1521 1335 1368 1534 1445 1487 1443 1566 1453 1534 1435 1522 1504 1498 1482 1385 1356 1496 1535 1403 1502 1537 1434 1429 1476 1418 1452 1364 1483 1375 1471 1401 1505 1524 1333 1306 1345 1439 1459 1480 1516 1340 1300 1539 1379 1420 1452 1371 1359 1326 1393 1377 1318 1487 1380 1337 1339 1399 1288 1332 1387 1436 1360 1344 1402 1435 1342 1514 1469 1333 1196 1277 1268 1380 1342 1367 1232 1275 1469 1367 1291 1294 1421 1427 1390 1424 1366 1305 1381 1410 1328 1441 1294 1391 1422 1414 1369 1204 1381 1352 1393 1387 1404 1275 1300 1364 1427 1509 1358 1482 1331 1294 1312 1363 1358 1410 1544 1518 1490 1435 1484 1562 1563 1592 1504 1544 1661 1752 1755 1636 1766 1720 1738 1896 1821 1819 1998 1903 1994 2057 2254 2486 2852 3356 3909 4516 5120 5924 6800 7707 8812 9779 11172 12393 13745 14964 16293 17157 18253 19092 20146 20844 21542 22175 22520 22856 22827 22752 22304 21990 21309 20680 19583 19225 17824 16592 15109 13820 12071 10869 9666 8287 7210 6084 5181 4459 3787 3097 2754 2399 2187 1954 1855 1875 1901 1854 1757 1814 1783 1620 1686 1620 1530 1455 1382 1520 1460 1373 1468 1315 1329 1395 1325 1312 1292 1260 1317 1278 1231 1267 1252 1229 1252 1194 1288 1191 1187 1229 1200 1248 1277 1209 1270 1200 1157 1169 1258 1221 1213 1252 1260 1170 1138 1296 1176 1195 1267 1170 1259 1263 1197 1201 1269 1243 1176 1215 1338 1150 1169 1241 1170 1226 1229 1312 1127 1139 1185 1246 1252 1172 1200 1234 1150 1157 1194 1230 1242 1163 1211 1239 1134 1302 1231 1185 1229 1218 1115 1230 1133 1167 1229 1156 1205 1267 1231 1142 1258 1182 1245 1153 1239 1156 1132 1214 1177 1150 1112 1173 1180 1189 1159 1193 1156 1200 1110 1168 1195 1129 1159 1198 1237 1163 1263 1129 1103 1181 1112 1124 1193 1137 1187 1222 1209 1170 1165 1226 1134 1214 1235 1214 1163 1142 1260 1130 1151 1183 1133 1212 1155 1130 1179 1156 1253 1207 1169 1136 1148 1203 1130 1113 1125 1206 1148 1179 1151 1272 1140 1172 1156 1157 1267 1117 1130 1171 1134 1207 1180 1159 1139 1168 1089 1125 1111 1153 1157 1117 1165 1185 1150 1183 1130 1108 1092 1196 1134 1157 1116 1146 1159 1163 1107 1135 1151 1179 1243 1085 1157 1176 1146 1131 1173 1218 1060 1171 1086 1205 1088 1241 1157 1112 1123 1257 1143 1150 1220 1145 1085 1159 1145 1162 1110 1146 1170 1149 1115 1125 1168 1075 1076 1125 1150 1113 1110 1128 1123 1134 1137 1207 1127 1153 1144 1182 1192 1124 1193 1138 1089 1122 1201 1125 1069 1174 1120 1129 1121 1103 1144 1124 1110 1176 1113 1143 1179 1118 1181 1152 1082 1142 1157 1130 1121 1090 1132 1070 1146 1190 1115 1142 1197 1089 1142 1189 1198 1129 1188 1154 1127 1152 1169 1134 1225 1129 1095 1110 1152 1174 1068 1101 1139 1178 1168 1110 1085 1118 1042 1155 1185 1104 1097 1079 1111 1110 1146 1096 1083 1121 1076 1131 1147 1081 1165 1072 1100 1178 1067 1063 1113 1149 1087 1088 1159 1116 1093 1072 1139 1128 1114 1102 1181 1089 1047 1140 1133 1139 1116 1109 1076 1121 1105 1112 1167 1094 1082 1105 1121 1101 1124 1087 1166 1175 1130 1133 1069 1139 1047 1097 1142 1066 1212 1097 1094 1144 1064 1159 1121 1156 1101 1115 1099 1068 1135 1155 1085 1125 1106 1065 1099 1171 1147 1141 1127 1065 1132 1160 1126 1146 1089 1079 1104 1095 1191 1113 1127 1118 1153 1104 1111 1068 1066 1116 1037 1143 1155 1102 1088 1156 1101 1172 1084 1185 1122 1092 1175 1122 1089 1099 1197 1156 1112 1115 1128 1119 1086 1113 1171 1102 1189 1103 1102 1122 1125 1142 1101 1141 1116 1144 1126 1160 1148 1136 1106 1068 1075 1084 1122 1087 1151 1154 1073 1170 1109 1119 1172 1155 1181 1122 1120 1113 1112 1111 1115 1124 1141 1148 1123 1131 1111 1088 1095 1226 1155 1136 1111 1136 1074 1152 1175 1153 1079 1141 1205 1130 1076 1169 1170 1117 1153 1074 1103 1156 1126 1164 1129 1145 1134 1138 1159 1163 1130 1139 1129 1130 1141 1147 1174 1111 1161 1102 1185 1153 1229 1225 1146 1094 1133 1192 1215 1226 1118 1242 1275 1228 1265 1412 1392 1507 1645 1594 1769 1911 2066 2034 2151 2139 2199 2193 2367 2301 2337 2449 2427 2518 2554 2689 2577 2646 2707 2637 2687 2717 2513 2479 2513 2543 2320 2135 2098 2066 2083 1781 1789 1759 1456 1472 1330 1307 1266 1224 1241 1270 1207 1161 1189 1121 1186 1247 1185 1201 1125 1241 1160 1155 1192 1260 1250 1156 1143 1197 1121 1181 1176 1115 1211 1175 1214 1137 1187 1092 1105 1139 1189 1170 1102 1143 1219 1257 1124 1156 1196 1153 1190 1263 1152 1156 1190 1186 1236 1140 1126 1152 1157 1259 1140 1267 1185 1115 1172 1182 1131 1130 1124 1176 1121 1256 1181 1153 1131 1189 1175 1156 1244 1184 1188 1171 1207 1221 1180 1131 1172 1256 1150 1225 1298 1141 1144 1287 1215 1209 1191 1232 1186 1179 1152 1147 1250 1138 1201 1203 1216 1175 1285 1184 1204 1192 1203 1237 1247 1164 1215 1137 1218 1304 1237 1254 1289 1315 1333 1431 1410 1365 1337 1336 1408 1306 1475 1402 1239 1390 1407 1268 1422 1463 1380 1249 1372 1480 1428 1381 1244 1313 1330 1252 1196 1344 1327 1321 1234 1339 1216 1346 1254 1164 1319 1290 1245 1441 1214 1271 1182 1329 1279 1252 1254 1236 1313 1181 1305 1305 1349 1263 1256 1335 1368 1307 1385 1258 1291 1326 1376 1204 1207 1378 1320 1294 1414 1314 1287 1384 1263 1207 1370 1384 1415 1362 1333 1330 1336 1357 1351 1357 1542 1303 1354 1252 1362 1475 1331 1336 1321 1257 1357 1497 1390 1339 1432 1344 1363 1300 1485 1466 1300 1363 1364 1335 1420 1330 1542 1404 1296 1510 1506 1308 1510 1387 1478 1310 1408 1491 1479 1413 1437 1354 1449 1548 1408 1315 1373 1369 1363 1341 1494 1565 1528 1439 1544 1556 1441 1546 1531 1564 1480 1579 1664 1516 1552 1555 1565 1541 1590 1611 1605 1675 1516 1583 1648 1540 1590 1686 1689 1694 1639 1699 1506 1709 1614 1670 1682 1647 1622 1677 1540 1778 1663 1696 1833 1786 1751 1797 1690 1689 1806 1820 1719 1727 1792 1759 1790 1835 1863 1797 1816 1858 1847 1842 1852 1834 1780 1785 1884 1812 1901 1883 1906 1899 1898 1914 1908 1952 1871 1946 1870 1928 1882 2002 1971 1921 1926 2048 1973 2080 2022 1982 1994 2036 2048 2061 2044 2078 2059 2113 2096 2143 2078 2204 2239 2354 2375 2354 2656 3070 3389 4039 4885 5497 6574 7784 8850 10367 11771 13492 15499 17320 19091 20964 22739 24051 25394 26714 27583 27943 28597 28308 27904 27606 26703 25614 24153 22809 20933 19238 17517 15807 14047 12286 10705 9474 8222 7077 6190 5358 4500 4160 3665 3515 3411 3263 3347 3237 3220 3262 3247 3126 3175 3204 3133 3228 3116 3143 3164 3033 3044 3114 3078 3188 3172 3150 3166 3249 3286 3220 3337 3195 3397 3305 3358 3429 3512 3432 3414 3489 3454 3529 3676 3547 3745 3739 3817 3779 3724 3890 3826 4070 3992 4008 4021 4098 4098 4199 4154 4100 4170 4255 4224 4199 4216 4301 4401 4237 4360 4375 4393 4393 4306 4497 4332 4502 4545 4482 4591 4472 4619 4523 4521 4680 4634 4676 4738 4648 4703 4724 4679 4698 4747 4710 4877 4703 4820 4693 4662 4779 4762 4808 4756 4808 4665 4769 4590 4731 4660 4806 4673 4577 4637 4608 4541 4569 4565 4440 4593 4421 4535 4516 4476 4418 4483 4404 4434 4478 4480 4268 4243 4262 4112 4275 4166 4148 4108 4124 4087 3910 4104 4037 3980 3929 3901 3826 3999 3895 3926 3854 3788 3643 3700 3748 3649 3702 3605 3738 3643 3614 3466 3492 3426 3459 3445 3371 3392 3270 3321 3360 3211 3311 3237 3308 3202 3198 3235 3262 3082 3120 3207 3111 3082 3018 2992 2983 2983 2923 3007 2924 2950 2787 2897 2779 2823 2797 2772 2775 2718 2706 2657 2617 2732 2719 2577 2595 2695 2570 2637 2542 2576 2618 2469 2399 2538 2471 2406 2491 2455 2539 2360 2425 2473 2499 2335 2256 2337 2375 2373 2330 2287 2259 2219 2248 2262 2279 2232 2316 2346 2269 2176 2074 2196 2219 2176 2161 2216 2202 2320 2234 2239 2291 2217 2239 2245 2216 2338 2180 2237 2270 2182 2310 2283 2331 2321 2370 2215 2337 2227 2314 2291 2348 2150 2192 2105 2140 2263 2059 2052 2114 1941 1999 1939 1979 1974 1980 1960 1844 1873 1886 1836 1853 1824 1760 1860 1903 1765 1779 1798 1830 1799 1678 1844 1776 1562 1727 1810 1595 1709 1668 1730 1687 1666 1730 1731 1560 1780 1710 1784 1583 1663 1702 1618 1697 1619 1547 1663 1582 1647 1692 1658 1610 1628 1432 1594 1500 1727 1512 1503 1417 1560 1581 1520 1542 1513 1478 1402 1411 1487 1431 1446 1397 1500 1519 1361 1445 1358 1401 1337 1364 1409 1289 1389 1399 1329 1449 1280 1233 1383 1385 1268 1293 1313 1361 1223 1253 1310 1351 1366 1441 1282 1238 1204 1341 1410 1234 1206 1240 1300 1360 1232 1250 1433 1316 1243 1193 1329 1197 1233 1257 1152 1217 1257 1174 1265 1197 1149 1330 1254 1146 1188 1178 1231 1271 1228 1198 1246 1219 1201 1176 1159 1238 1170 1198 1187 1284 1207 1145 1149 1193 1214 1083 1167 1131 1188 1238 1149 1218 1234 1170 1101 1143 1166 1131 1166 1138 1153 1094 1145 1226 1126 1175 1104 1116 1118 1185 1159 1107 1133 1192 1125 1165 1169 1215 1205 1064 1231 1161 1153 1184 1201 1187 1288 1245 1306 1204 1236 1251 1202 1255 1316 1320 1359 1257 1267 1315 1220 1236 1282 1226 1250 1203 1190 1198 1223 1246 1201 1136 1241 1192 1078 1116 1178 1173 1160 1083 1071 1133 1104 1089 1024 1088 1015 1061 1091 1106 1117 1019 1111 1078 1123 1074 1070 1091 1083 1044 1129 1115 1056 997 1064 1089 1035 1036 1058 1012 1050 1088 1036 1011 1011 1063 1043 1029 1034 1049 1005 1039 1071 1057 1059 1022 1040 1037 1046 1010 1030 1019 1004 1019 1010 973 1037 993 1062 1036 1093 1062 1036 1003 1033 1052 1082 1008 1014 997 1049 1035 928 1026 1032 972 1055 1033 1004 1011 969 1101 1044 1044 1013 1036 979 991 1006 1035 998 1027 969 1025 977 1018 976 1013 989 948 1027 933 957 1038 1013 1037 1049 996 978 984 1030 1015 988 997 990 963 964 1018 1041 996 966 1038 1029 1031 1000 959 952 1027 1036 955 998 1023 1016 1048 993 1090 1004 976 942 1077 1032 1034 1019 1074 1075 1050 1062 1035 1068 1034 1014 1084 1031 996 965 981 953 922 973 995 1034 954 1001 1055 953 970 975 971 1011 978 985 967 913 1006 989 989 917 987 994 917 979 998 978 937 934 966 923 977 975 901 1036 923 967 979 926 1001 887 930 933 977 969 1017 968 995 996 954 1009 959 951 916 934 944 968 962 968 988 996 950 879 943 917 937 922 948 958 962 975 970 912 960 947 945 948 929 966 956 939 936 946 922 909 929 927 981 918 990 872 947 880 945 968 968 963 973 971 889 979 938 947 964 959 1002 953 946 1002 991 975 949 938 964 1004 968 972 976 953 972 972 999 928 929 969 1010 978 1004 1003 958 960 964 994 943 970 916 907 979 959 907 898 962 1002 953 884 954 929 927 969 930 886 980 947 951 957 1005 920 966 933 917 893 892 965 932 866 939 965 879 966 897 908 897 889 935 946 886 934 954 919 963 873 908 930 940 956 971 918 959 924 973 879 950 958 978 905 970 884 921 935 925 959 918 890 960 928 923 924 884 928 943 930 1005 879 857 955 945 930 961 949 976 916 907 961 892 963 955 929 997 922 952 942 943 911 910 1015 972 950 990 895 898 897 940 949 984 889 905 870 907 945 899 899 950 896 937 920 972 946 923 965 920 997 918 904 938 1006 976 914 957 881 884 872 904 957 962 926 877 888 950 903 946 980 914 942 930 881 959 977 923 942 911 940 900 912 965 979 931 967 954 997 949 1010 1067 1057 1019 1049 1077 1207 1038 1126 1202 1221 1164 1175 1211 1224 1232 1235 1380 1366 1266 1250 1329 1308 1224 1346 1266 1237 1132 1147 1175 1136 1131 1105 1075 1010 1049 1084 1037 987 988 940 967 982 969 967 848 956 950 949 962 936 900 916 922 952 940 907 933 1001 971 993 983 973 913 928 976 933 993 945 881 940 912 933 965 912 998 958 922 972 946 919 920 890 947 911 928 931 920 972 899 958 911 973 992 949 914 926 886 950 936 931 987 978 936 927 885 872 939 929 992 958 950 961 924 859 994 967 980 1055 986 977 950 986 941 930 950 974 920 923 890 917 984 960 924 942 935 955 1036 1034 975 1008 1076 1061 1117 1115 1136 1122 1200 1292 1158 1191 1226 1208 1227 1290 1314 1458 1308 1390 1211 1285 1454 1402 1465 1317 1466 1244 1426 1262 1197 1141 1144 1163 1076 1059 1083 1032 1019 930 965 950 969 922 958 970 903 955 936 950 1013 967 950 961 951 947 957 935 947 992 995 1037 915 942 937 941 969 915 1005 995 955 951 919 920 952 913 963 988 925 920 966 984 928 984 917 957 935 921 963 933 928 968 949 989 912 930 967 927 938 938 1012 1001 984 995 1074 1000 938 987 961 999 951 947 1022 1012 1031 1023 1041 1055 1080 1088 1054 1105 1070 1000 983 1019 1075 1107 1004 1075 1069 971 1003 895 1004 1028 998 1019 957 961 980 943 905 962 974 932 931 918 991 929 978 991 1013 914 905 943 933 915 933 973 928 987 936 912 934 982 938 940 930 941 924 909 972 890 936 996 935 980 994 999 960 936 928 954 945 887 951 948 943 949 995 972 986 895 941 995 964 962 932 919 1023 945 969 968 890 947 944 915 999 959 961 1057 992 989 1022 1032 910 976 955 1017 896 998 986 966 1000 902 1000 943 1000 953 959 949 949 931 984 959 977 995 950 1008 978 929 927 1010 924 973 969 1014 960 1012 966 954 966 1049 973 1004 985 1049 981 1021 959 957 982 1029 974 898 944 967 986 948 1004 1007 994 990 1010 1018 963 979 1025 981 960 980 985 947 925 974 956 1004 970 982 917 984 1020 1027 975 1013 1019 1010 1047 1046 1045 1025 1000 1002 977 984 961 935 935 976 1074 962 1056 1003 968 1042 987 992 1018 971 1019 991 1001 1006 1035 1010 958 945 1023 1018 935 990 1012 1008 1063 989 1020 963 1025 1050 1023 987 993 990 1017 1006 937 973 1040 1071 1004 956 931 1012 953 1023 972 1041 1054 1031 1029 979 1025 975 968 920 1004 1018 931 1026 1001 979 1031 998 945 1082 984 987 1013 1079 925 1046 959 980 1046 1027 995 1025 1040 995 1003 963 991 993 990 1015 1044 1005 1003 1031 1038 1043 968 1014 1020 1032 1007 1025 1071 1012 956 1000 962 1035 1012 1029 1068 1009 996 1078 1042 1028 992 1008 1034 1056 1006 1031 998 985 965 983 972 1075 978 978 1037 1037 1044 1013 1011 1012 1054 988 981 1032 1035 983 1097 1081 993 977 1008 1009 1051 985 1009 1040 1076 1020 1027 990 1021 994 1008 1054 1002 1000 981 966 1031 1009 1012 1002 1075 996 1025 1079 1026 1035 1017 1044 1070 1013 1010 1095 1010 1050 1023 1074 987 1004 985 1050 972 1081 996 1105 1060 1081 1092 1038 1046 1040 1026 992 1036 1080 990 1034 1056 998 1010 1041 1012 1073 997 1059 970 1061 1055 1021 997 1045 1012 1085 1047 1021 1017 971 1057 1052 1065 1068 978 1031 1016 1032 1048 1075 1043 1029 980 1024 1049 1015 1058 1039 1025 1001 1100 1059 1104 1055 1004 1143 1029 1011 1131 1139 968 1078 1069 1018 1080 1057 1090 959 988 1038 1040 1026 1098 1056 1058 1032 1089 1057 1051 1077 1050 1080 1100 1050 1063 1072 1027 1073 1094 1068 1052 1051 1110 1031 1073 1087 1118 1043 1074 1009 1117 1093 1112 1121 1100 1040 1017 1130 1008 1097 1064 1072 1044 1101 1030 1010 1045 1120 1150 1026 1055 1106 1008 1045 1112 1077 1021 1018 1027 1121 1085 1091 1067 1077 1106 1035 1097 1114 1056 1036 1085 1040 1090 1050 1074 1109 1081 1079 1097 1099 1080 1070 1080 1037 1057 1117 1058 1066 1108 1161 1093 1055 1100 1069 1064 1097 1124 1022 1065 1117 1067 1073 1092 1170 1049 1074 1120 1108 1094 1135 1138 1146 1189 1104 1125 1177 1098 1057 1101 1122 1116 1123 1130 1165 1095 1077 1121 1103 1065 1084 1078 1108 1023 1181 1129 1027 1092 1104 1140 1144 1043 1102 1074 1131 1074 1103 1082 1082 1062 1103 1132 1029 1137 1120 1179 1140 1131 1140 1071 1104 1151 1083 1142 1033 1103 1145 1100 1099 1097 1141 1146 1194 1156 1108 1170 1166 1077 1183 1153 1208 1098 1119 1166 1107 1152 1152 1124 1125 1265 1168 1086 1162 1155 1164 1211 1171 1105 1127 1257 1132 1161 1189 1146 1160 1104 1191 1117 1180 1127 1193 1171 1200 1159 1215 1214 1209 1187 1116 1250 1181 1323 1269 1218 1132 1285 1221 1319 1371 1417 1473 1552 1836 1811 1988 2098 2317 2428 2541 2864 2999 3223 3612 3766 3988 4209 4456 4517 4792 4929 5199 5218 5241 5555 5480 5504 5519 5514 5320 5211 5052 4778 4640 4480 4203 4037 3835 3477 3223 2925 2706 2403 2393 2164 2035 1849 1633 1670 1485 1424 1318 1318 1366 1355 1257 1238 1337 1334 1334 1218 1275 1278 1326 1216 1212 1269 1128 1285 1217 1257 1232 1213 1190 1144 1216 1206 1147 1181 1249 1227 1197 1317 1159 1243 1176 1217 1274 1162 1278 1265 1246 1197 1126 1152 1156 1136 1167 1162 1255 1221 1171 1161 1201 1206 1173 1316 1196 1138 1218 1141 1166 1194 1214 1223 1177 1177 1272 1145 1230 1295 1251 1240 1179 1233 1165 1212 1293 1293 1226 1244 1259 1147 1179 1211 1151 1292 1179 1203 1136 1273 1203 1217 1199 1211 1232 1205 1241 1211 1234 1156 1176 1228 1206 1193 1187 1163 1224 1190 1215 1251 1295 1122 1246 1175 1225 1210 1193 1150 1274 1252 1250 1220 1259 1267 1249 1222 1180 1244 1186 1220 1225 1259 1177 1212 1269 1166 1235 1192 1234 1271 1281 1325 1237 1196 1195 1241 1177 1293 1327 1283 1276 1263 1266 1280 1190 1176 1201 1352 1195 1242 1305 1131 1205 1387 1279 1280 1199 1339 1303 1256 1156 1229 1269 1263 1162 1214 1337 1334 1354 1227 1363 1278 1374 1251 1269 1237 1259 1292 1343 1314 1279 1252 1388 1273 1263 1243 1430 1202 1293 1346 1390 1315 1344 1234 1368 1291 1320 1214 1334 1349 1286 1277 1476 1340 1235 1291 1278 1328 1424 1296 1271 1272 1416 1268 1280 1404 1429 1338 1270 1251 1252 1265 1306 1219 1315 1434 1463 1350 1450 1366 1378 1475 1353 1530 1354 1360 1362 1295 1349 1310 1423 1294 1388 1304 1385 1287 1411 1270 1378 1280 1339 1294 1347 1402 1288 1372 1316 1461 1494 1405 1351 1411 1466 1446 1394 1447 1355 1416 1388 1458 1364</counts>
			</dataPoints>
		</scan>
	</xrdMeasurement>
</xrdMeasurements>