File: Data Files/Full/MSS p (6-129, 4w)_01.xrdml
<?xml version="1.0"?>
<xrdMeasurements xmlns="http://www.xrdml.com/XRDMeasurement/2.2" xmlns:xsi="http://www.w3.org/2001/XMLSchema-instance" xsi:schemaLocation="http://www.xrdml.com/XRDMeasurement/2.2 http://www.xrdml.com/XRDMeasurement/2.2/XRDMeasurement.xsd" status="Completed" recordIdentifier="{2A24D080-5628-4DFB-A38D-1200A9D8FBE5}">
	<comment>
		<entry/>
	</comment>
	<sample type="To be analyzed">
		<id>p</id>
		<name></name>
		<preparedBy></preparedBy>
	</sample>
	<xrdMeasurement measurementType="Scan" status="Completed" sampleMode="Reflection">
		<usedWavelength intended="K-Alpha 1">
			<kAlpha1 unit="Angstrom">1.5405980</kAlpha1>
			<kAlpha2 unit="Angstrom">1.5444260</kAlpha2>
			<kBeta unit="Angstrom">1.3922500</kBeta>
			<ratioKAlpha2KAlpha1>0.5000</ratioKAlpha2KAlpha1>
		</usedWavelength>
		<incidentBeamPath>
			<radius unit="mm">145.00</radius>
			<xRayTube id="1010048" name="Empyrean Cu LFF HR (9430 033 7310x) DK437964">
				<tension unit="kV">40.0</tension>
				<current unit="mA">15.0</current>
				<anodeMaterial>Cu</anodeMaterial>
				<focus type="Line">
					<length unit="mm">12.0</length>
					<width unit="mm">0.4</width>
					<takeOffAngle unit="deg">6.0</takeOffAngle>
				</focus>
			</xRayTube>
			<filter id="20010004" name="Beta-filter Nickel">
				<material>Ni</material>
				<thickness unit="mm">0.020</thickness>
			</filter>
			<sollerSlit id="21010002" name="Soller slits 0.04 rad.">
				<opening unit="rad">0.0400</opening>
			</sollerSlit>
			<mask id="22031000" name="Fixed mask 13 mm">
				<width unit="mm">9.00</width>
			</mask>
			<divergenceSlit id="22120003" name="Divergence slit 1/4°" xsi:type="fixedDivergenceSlitType">
				<distanceToSample unit="mm">50.00</distanceToSample>
				<height unit="mm">0.38</height>
			</divergenceSlit>
		</incidentBeamPath>
		<diffractedBeamPath>
			<radius unit="mm">145.00</radius>
			<parallelPlateCollimator id="25020001" name="Parallel plate collimator 0.28°">
				<opening unit="deg">0.28</opening>
			</parallelPlateCollimator>
			<detector id="7010020" name="PIXcel3D-Medipix3 1x1 detector" xsi:type="areaDetectorType">
				<phd unit="keV">
					<lowerLevel>4.0</lowerLevel>
					<upperLevel>11.3</upperLevel>
				</phd>
				<mode>Receiving slit</mode>
				<activeChannelsEquatorial>255</activeChannelsEquatorial>
				<activeChannelsAxial>255</activeChannelsAxial>
				<pitchEquatorial unit="mm">0.05500</pitchEquatorial>
				<pitchAxial unit="mm">0.05500</pitchAxial>
				<readOutPeriod unit="seconds">0.050</readOutPeriod>
			</detector>
		</diffractedBeamPath>
		<scan appendNumber="0" mode="Continuous" scanAxis="2Theta" status="Completed">
			<header>
				<startTimeStamp>2025-06-19T13:40:35-08:00</startTimeStamp>
				<endTimeStamp>2025-06-20T03:20:39-08:00</endTimeStamp>
				<author>
					<name>Instrument</name>
				</author>
				<source>
					<applicationSoftware version="1.6 (94)">PANalytical Aeris Instrument Suite</applicationSoftware>
					<instrumentControlSoftware version="3.0.0 20211014">AERIS</instrumentControlSoftware>
					<instrumentID>2855484</instrumentID>
				</source>
			</header>
			<dataPoints>
				<positions axis="2Theta" unit="deg">
					<startPosition>6.005</startPosition>
					<endPosition>128.995</endPosition>
				</positions>
				<positions axis="Omega" unit="deg">
					<commonPosition>4.000</commonPosition>
				</positions>
				<commonCountingTime unit="seconds">3.520</commonCountingTime>
				<counts 2547 2577 2463 2521 2602 2545 2495 2519 2448 2497 2558 2432 2442 2507 2401 2463 2505 2473 2460 2438 2455 2403 2387 2358 2399 2389 2439 2511 2601 2375 2442 2424 2389 2388 2502 2494 2431 2540 2410 2509 2402 2400 2400 2478 2425 2434 2412 2393 2499 2431 2421 2381 2359 2352 2388 2396 2329 2460 2369 2461 2489 2482 2467 2389 2415 2457 2455 2455 2421 2478 2449 2502 2443 2443 2503 2401 2407 2457 2432 2399 2376 2441 2427 2466 2483 2407 2327 2348 2356 2313 2340 2342 2395 2329 2338 2371 2306 2315 2316 2332 2294 2337 2296 2301 2300 2311 2234 2319 2304 2255 2269 2260 2241 2293 2241 2291 2403 2166 2332 2222 2308 2219 2171 2328 2187 2300 2286 2239 2241 2306 2281 2209 2271 2252 2217 2286 2184 2291 2182 2222 2210 2194 2215 2229 2212 2156 2223 2075 2191 2110 2226 2125 2162 2164 2134 2188 2168 2182 2096 2151 2125 2123 2142 2095 2194 2142 2100 2170 2139 2052 2043 2085 2129 2127 2132 2150 2071 2041 2176 2052 2069 2048 2090 2079 2086 2000 2011 1981 2024 2066 2077 2029 1954 1991 2073 2001 2021 2068 2009 1866 2013 1973 1950 2017 2059 2031 1897 1982 1999 1980 1905 1934 1986 1972 1942 1942 1995 1974 1936 1976 1948 1880 1948 1968 1967 1918 1952 1984 2003 1866 1904 1932 1925 1900 1868 1921 1928 1961 1899 1967 1910 1847 1909 1835 1933 1898 1820 1815 1902 1872 1850 1856 1859 1910 1832 1829 1876 1832 1898 1864 1859 1736 1850 1859 1837 1834 1898 1837 1803 1885 1838 1857 1908 1892 1869 1847 1873 1852 1796 1878 1770 1800 1878 1740 1886 1814 1898 1830 1731 1795 1760 1859 1788 1807 1885 1788 1862 1847 1808 1731 1778 1797 1847 1854 1803 1908 1795 1748 1808 1928 1747 1799 1813 1932 1881 1759 1827 1863 1742 1863 1798 1745 1761 1763 1726 1827 1871 1820 1844 1831 1844 1801 1778 1893 1784 1844 1866 1812 1758 1743 1809 1699 1818 1748 1883 1774 1815 1882 1830 1762 1820 1795 1852 1875 1871 1777 1882 1843 1844 1810 1761 1816 1820 1797 1907 1847 1850 1850 1908 1819 1893 1889 1847 1868 1774 1877 1824 1826 1813 1758 1877 1912 1848 1920 1824 1794 1836 1880 1742 1856 1896 1878 1880 1742 1886 1903 1869 1946 1944 1908 1806 1863 1953 1923 1947 1972 1991 2031 1931 1914 1919 1995 1894 1935 1919 1897 1990 1939 1922 1910 1978 1956 1990 1976 1920 1936 1944 1964 1868 1958 1936 1990 1953 2036 1994 2026 2028 2036 2060 2017 2009 2019 2078 2032 1996 1971 2046 1989 1996 2064 2018 2023 1947 1998 2065 2074 2083 1995 2051 2026 2104 2147 1938 2157 2039 2045 2110 2014 2073 2139 2129 2072 2078 2098 2103 2093 2145 2087 2112 2093 2083 2087 2051 2137 2120 2044 2142 2203 2089 2143 2144 2130 2052 2134 2082 2170 2180 2149 2117 2222 2193 2127 2146 2252 2073 2244 2203 2185 2196 2185 2217 2174 2145 2160 2269 2301 2182 2196 2269 2137 2301 2139 2174 2212 2256 2204 2275 2264 2184 2225 2197 2220 2351 2221 2297 2328 2266 2326 2306 2239 2312 2375 2311 2291 2308 2445 2299 2421 2429 2419 2280 2304 2409 2309 2376 2329 2425 2354 2330 2409 2327 2333 2425 2343 2309 2414 2435 2428 2416 2404 2429 2398 2452 2467 2422 2533 2486 2373 2513 2403 2425 2356 2370 2414 2468 2452 2449 2503 2488 2492 2551 2545 2477 2511 2466 2573 2491 2538 2588 2596 2587 2498 2584 2597 2506 2607 2506 2588 2643 2605 2533 2647 2660 2704 2618 2617 2607 2619 2639 2661 2621 2723 2631 2776 2707 2561 2791 2711 2747 2755 2753 2734 2813 2811 2811 2762 2717 2782 2744 2708 2693 2767 2758 2778 2860 2707 2858 2733 2796 2822 2815 2842 2793 2957 2806 2853 2852 2909 2856 2820 3055 2960 2937 2799 2939 2939 3042 2817 2915 2975 2965 2956 3066 2997 2901 2944 2993 2814 2985 2850 3054 2941 2995 3107 3099 3112 3035 3076 3010 3029 3098 3030 3034 3062 3124 3056 3105 3014 3016 3247 3033 3225 3203 3129 3080 3092 3178 3243 3182 3219 3165 3179 3248 3203 3244 3164 3252 3202 3163 3108 3158 3218 3121 3247 3213 3253 3196 3232 3213 3154 3336 3197 3315 3207 3208 3265 3259 3268 3238 3309 3283 3289 3366 3330 3218 3269 3254 3350 3363 3420 3278 3330 3333 3261 3332 3391 3377 3328 3309 3376 3384 3361 3430 3253 3362 3390 3414 3324 3391 3479 3301 3359 3406 3408 3381 3341 3457 3286 3390 3328 3306 3444 3398 3311 3393 3417 3392 3355 3427 3299 3345 3333 3431 3396 3439 3412 3369 3290 3417 3420 3296 3295 3441 3292 3296 3464 3377 3360 3337 3417 3412 3414 3363 3374 3329 3299 3408 3205 3262 3245 3364 3286 3378 3354 3243 3404 3297 3264 3396 3355 3269 3333 3256 3302 3318 3290 3296 3355 3323 3267 3230 3307 3297 3303 3222 3211 3296 3211 3295 3194 3287 3345 3239 3235 3233 3155 3276 3225 3214 3174 3264 3191 3206 3164 3182 3143 3160 3221 3168 3269 3139 3193 3169 3173 3108 3173 3219 3089 3078 2973 3141 3080 3171 3066 3089 3168 3119 2997 3041 3182 3126 3016 3035 3045 3068 3084 2880 3080 2910 3036 2954 3015 3041 2987 3018 2933 2956 2905 2957 2907 2894 2945 2918 2852 2915 2931 2895 2982 2908 2826 2718 2851 2854 2725 2952 2861 2716 2818 2821 2747 2798 2821 2769 2726 2708 2685 2682 2796 2771 2759 2650 2767 2670 2704 2640 2717 2721 2704 2654 2755 2625 2700 2686 2633 2686 2804 2628 2662 2640 2737 2520 2668 2536 2546 2585 2601 2596 2468 2495 2537 2559 2455 2483 2521 2512 2569 2456 2520 2500 2462 2649 2568 2462 2405 2493 2554 2451 2402 2380 2388 2506 2428 2461 2501 2413 2454 2482 2339 2369 2353 2368 2453 2337 2301 2399 2255 2367 2428 2304 2355 2301 2317 2305 2359 2356 2366 2342 2294 2349 2338 2373 2285 2241 2220 2324 2137 2326 2304 2346 2227 2243 2297 2225 2201 2325 2195 2203 2250 2162 2170 2171 2151 2240 2197 2184 2235 2261 2153 2150 2148 2178 2183 2149 2224 2121 2156 2135 2065 2132 2143 2141 2065 2126 2136 2146 2110 2054 2060 2092 2041 2133 2008 2091 2101 2139 2024 2054 2110 2060 2081 2094 2093 2133 2057 2035 1999 2039 1982 1933 2012 1956 2011 2011 1983 1866 1940 1987 1985 2019 1966 1934 2018 1890 1965 2001 1938 1928 1939 1996 1878 2055 1955 1979 1939 1968 2021 1949 1886 1923 1946 1886 1916 1876 1951 1868 1913 1914 1936 1939 1893 1846 1819 1847 1782 1810 1840 1882 1847 1863 1862 1784 1887 1781 1859 1893 1839 1869 1892 1726 1817 1801 1841 1790 1772 1712 1868 1722 1837 1834 1682 1743 1677 1833 1769 1751 1661 1773 1756 1686 1764 1796 1749 1780 1725 1741 1705 1745 1762 1818 1817 1787 1731 1735 1729 1704 1733 1721 1756 1759 1693 1674 1722 1555 1788 1878 1878 1932 2090 2146 2305 2345 2570 2737 2908 3099 3458 3701 3889 4189 4352 4525 4611 4735 4723 4627 4730 4713 4462 4363 4229 3941 3633 3409 3213 2858 2683 2476 2512 2191 2085 1960 1833 1757 1553 1613 1529 1581 1480 1589 1568 1625 1465 1659 1617 1517 1657 1571 1433 1640 1606 1525 1473 1670 1572 1491 1525 1629 1511 1430 1499 1391 1427 1612 1516 1435 1495 1442 1432 1484 1473 1384 1421 1445 1287 1500 1360 1439 1370 1421 1304 1464 1465 1539 1592 1431 1413 1371 1529 1356 1262 1472 1549 1370 1453 1392 1271 1432 1400 1383 1433 1407 1519 1324 1368 1501 1438 1460 1407 1393 1394 1405 1379 1558 1508 1281 1397 1410 1411 1294 1386 1423 1291 1330 1398 1367 1335 1316 1317 1242 1444 1348 1392 1284 1287 1346 1416 1318 1334 1265 1345 1265 1380 1277 1275 1278 1323 1313 1251 1282 1478 1409 1351 1225 1364 1249 1300 1408 1258 1252 1386 1300 1227 1404 1171 1202 1236 1165 1375 1303 1318 1251 1188 1202 1189 1318 1234 1303 1289 1326 1297 1239 1225 1187 1288 1235 1257 1213 1307 1211 1272 1259 1293 1210 1194 1204 1354 1259 1194 1287 1251 1335 1244 1282 1264 1226 1286 1262 1291 1223 1222 1176 1243 1140 1153 1232 1189 1262 1218 1125 1223 1232 1214 1219 1250 1175 1190 1250 1283 1226 1213 1281 1236 1234 1168 1214 1181 1268 1170 1225 1277 1160 1171 1228 1177 1147 1130 1154 1108 1164 1196 1195 1241 1208 1183 1140 1129 1156 1227 1144 1167 1193 1193 1206 1122 1145 1164 1140 1092 1211 1102 1232 1225 1192 1113 1116 1146 1140 1138 1135 1229 1089 1121 1116 1204 1148 1181 1136 1103 1144 1082 1199 1107 1132 1180 1167 1117 1177 1207 1154 1198 1208 1149 1098 1191 1198 1101 1080 1089 1092 1174 1037 1102 1191 1100 1059 1143 1156 1128 1141 1180 1110 1124 1098 1128 1099 1138 1127 1115 1085 1146 1128 1095 1163 1140 1126 1138 1101 1063 1106 1100 1175 1049 1093 1072 1128 1171 1142 1137 1150 1084 1125 1134 1104 1106 1104 1061 1071 1149 1134 1092 1079 1085 1102 1142 1136 1094 1119 1098 1088 1102 1125 1137 1076 1126 1132 1066 1110 1085 1103 1090 1105 1085 1094 1072 1081 1072 1026 1088 1147 1060 1080 1074 1079 1130 1095 1104 1115 1067 1187 1171 1121 1056 1010 1076 1081 1052 1097 1131 1126 1059 1088 1114 1071 1200 1087 1168 1106 1174 1170 1228 1155 1078 1159 1147 1231 1247 1208 1213 1133 1215 1291 1404 1748 1894 2250 2499 2787 3193 3604 4098 4730 5391 6059 6919 7737 8242 8699 9321 9566 9929 10413 10607 10451 10375 10107 9584 8831 8098 7311 6800 6097 5279 4817 3971 3521 2933 2492 2279 1784 1531 1239 1198 1216 1211 1181 1115 1103 1273 1212 1149 1161 1232 1210 1171 1135 1145 1153 1104 1068 1110 1056 1071 1072 1105 1150 1083 1170 1078 1092 998 1034 1089 1011 1042 1023 1055 1052 1042 1067 1032 1055 1002 1012 1029 1092 1062 1007 1001 1007 1064 1029 1022 1030 1031 1061 1018 1044 993 1032 977 1049 976 1038 1063 988 1040 972 999 952 1031 937 1019 1014 1014 1023 929 1040 1043 1079 976 1027 969 1036 1027 1016 1009 1052 1043 1016 1032 1047 972 1000 1008 1057 1042 1069 1022 1010 1045 996 1116 1034 1136 1038 1034 966 994 1057 1027 992 1034 1044 1021 979 973 987 1009 1024 983 964 975 1062 1064 1052 990 986 973 1007 1015 1036 1038 972 959 922 1044 1046 979 1013 1000 988 976 962 1003 995 944 986 1010 1055 1030 1086 1000 1023 964 1086 953 1021 973 1028 1018 1005 1001 1025 967 979 1032 967 1012 1074 1011 977 970 931 1026 918 926 972 1030 978 930 979 967 945 1046 994 991 1029 959 991 957 959 972 1003 1001 996 985 1016 919 1015 1020 1014 1020 949 1023 947 994 975 978 975 997 968 981 932 968 986 948 1009 887 968 1008 938 994 972 970 989 1000 954 918 967 940 1032 941 927 953 1047 956 980 1041 952 947 988 1013 1012 1018 940 1021 951 1011 998 1031 1000 1001 969 912 989 1007 950 1003 1013 998 987 1000 965 907 1011 1058 981 982 999 993 977 955 958 950 958 931 988 957 955 968 964 1028 972 1001 1004 974 1028 977 960 1027 982 1010 961 960 1010 982 992 987 1013 1040 930 982 951 1037 994 985 939 1012 968 985 988 1001 1064 936 983 980 1023 983 1021 957 987 951 1014 957 983 1029 987 1059 1028 1103 1182 1305 1447 1697 1893 1904 2226 2338 2630 2901 3255 3423 3667 3861 4227 4209 4324 4543 4391 4468 4502 4378 4175 3940 3831 3373 3219 2911 2701 2453 2223 2013 1853 1666 1325 1200 1192 1018 1014 959 1043 1037 1025 996 993 988 981 1003 1019 1006 1018 1022 969 965 975 990 966 959 939 996 929 988 954 984 941 971 971 972 1030 989 924 983 1026 949 1029 1017 972 965 957 931 992 975 956 960 945 932 1010 938 972 979 970 955 1018 991 988 944 957 965 973 1031 931 952 926 959 1010 977 972 924 963 984 976 1006 976 962 961 983 1005 959 927 866 990 990 989 921 1012 908 930 925 1006 1032 977 980 962 1005 955 936 1018 965 903 957 980 962 951 954 954 935 918 1000 941 1009 977 947 946 954 968 983 961 958 935 962 995 962 998 961 1014 923 980 977 980 955 992 971 989 1054 1051 1071 1014 999 1089 1083 997 1105 1084 1066 1026 1138 989 1020 1021 1014 984 877 1058 1014 963 992 927 1025 969 944 930 956 887 1015 940 1019 1004 976 1019 985 969 965 935 1009 1010 957 964 974 949 956 969 938 936 979 1011 1003 926 1022 998 921 932 942 985 983 988 987 966 969 956 935 979 989 974 967 937 959 966 1001 979 999 1006 954 957 989 950 1059 963 946 1000 929 949 980 954 994 920 1026 982 1008 928 975 1009 982 974 993 957 955 971 1004 972 975 1036 1045 1014 984 920 930 1044 977 958 1015 978 951 942 985 966 981 985 972 1011 1011 1001 944 986 957 1025 1044 1042 941 1033 1016 969 994 1043 1036 994 1059 999 1023 1023 1053 1052 1020 1001 1025 1019 1012 1053 1027 992 1031 1038 1000 1053 1069 1001 1102 1093 1056 1057 989 1036 1041 1059 1102 1036 1095 995 1064 1094 1054 1042 1102 1054 1122 1098 1045 1090 1130 1106 1085 1126 1130 1134 1156 1121 1067 1107 1078 1134 1071 1121 1170 1115 1072 1177 1175 1227 1261 1181 1133 1152 1133 1137 1169 1296 1224 1236 1119 1201 1160 1265 1207 1244 1221 1240 1187 1222 1212 1205 1246 1246 1276 1217 1251 1310 1223 1220 1333 1271 1322 1373 1377 1316 1310 1332 1328 1425 1330 1406 1326 1337 1452 1512 1434 1436 1527 1467 1413 1466 1658 1630 1674 1689 1669 1747 1629 1666 1715 1685 1650 1759 1776 1670 1793 1858 1848 1883 1854 1845 1886 1906 1908 1899 2003 2007 2001 2030 2063 2037 2026 2033 2076 2071 2074 2173 2170 2223 2193 2289 2278 2330 2293 2354 2321 2380 2356 2495 2456 2437 2541 2529 2537 2541 2490 2622 2641 2653 2582 2626 2675 2674 2785 2775 2742 2720 2822 2755 2844 2787 2775 2759 2827 2842 2860 2743 2743 2642 2807 2815 2618 2603 2641 2628 2605 2651 2591 2533 2515 2498 2487 2376 2371 2420 2363 2354 2318 2362 2329 2274 2196 2299 2258 2337 2230 2321 2328 2342 2346 2213 2349 2318 2288 2243 2074 2138 2205 2116 2074 1972 2007 1901 1912 1799 1850 1818 1754 1679 1817 1870 1968 1838 1847 1991 1851 2009 2040 1999 2082 2138 2120 2109 2215 2144 2333 2508 2917 3488 4256 5314 6781 8310 10177 12155 14486 17079 19893 22716 25625 28578 31181 33672 35600 36596 37595 38159 38691 37129 35755 34288 32163 29207 26234 23037 19923 17118 14414 12042 9878 7898 6241 4747 3676 2745 2242 1910 1735 1532 1596 1581 1367 1400 1416 1360 1266 1305 1137 1181 1133 1063 1091 1098 1098 998 1114 1046 1054 1001 997 1028 970 978 1016 978 1026 927 958 956 973 959 972 972 1023 927 925 937 973 987 979 978 986 895 1009 941 934 911 950 884 921 947 908 906 915 933 859 953 935 935 924 967 925 968 902 905 922 908 908 914 900 861 899 834 866 919 928 877 881 900 858 891 910 865 926 907 936 836 912 877 895 860 910 874 909 858 909 904 890 873 862 885 839 861 831 887 865 946 837 850 859 878 854 869 798 846 886 868 798 877 817 841 874 831 860 854 906 911 875 803 815 771 878 863 882 839 841 897 872 833 804 830 819 878 824 894 870 833 847 856 798 832 833 887 777 793 839 861 821 823 795 866 857 831 829 848 769 862 781 824 807 802 864 795 824 866 815 840 844 843 848 854 867 809 814 753 810 779 845 813 830 812 790 812 833 852 819 838 789 872 816 821 806 871 856 777 784 860 789 871 777 791 868 828 812 835 808 809 793 804 842 790 845 799 814 832 840 725 789 797 808 773 819 808 817 747 804 840 748 740 746 755 790 761 828 838 819 846 803 782 767 790 811 828 801 765 811 787 835 772 814 798 730 837 794 803 766 811 838 768 762 818 809 794 768 775 816 781 771 758 834 763 755 763 814 782 786 794 740 777 739 807 810 786 781 761 820 818 764 787 726 787 789 770 777 770 766 765 759 833 760 842 784 778 777 815 727 813 768 779 775 761 774 803 798 778 758 762 823 798 743 785 807 761 742 815 757 775 760 755 765 798 767 807 788 814 779 755 812 732 815 784 801 785 766 755 787 777 778 783 789 800 788 785 840 775 795 732 774 742 769 793 793 744 778 782 812 750 723 764 755 786 733 735 754 741 813 745 759 771 811 722 770 820 791 751 791 782 760 748 767 793 764 790 772 751 824 761 847 801 790 769 844 763 756 757 718 780 747 747 770 718 816 782 786 801 789 712 762 804 758 733 741 800 764 746 793 765 772 714 735 757 770 809 685 726 759 754 740 782 773 735 751 774 735 751 773 734 764 747 744 751 755 764 731 761 775 794 765 747 736 785 819 739 764 795 778 762 758 759 732 740 734 728 738 791 709 762 728 722 728 748 731 763 794 777 752 771 714 713 744 731 812 760 740 726 737 716 750 747 725 752 724 736 710 726 747 796 716 724 695 757 742 711 737 713 752 762 780 710 764 727 765 695 743 733 801 754 735 788 741 738 772 759 767 690 811 745 799 744 728 737 773 692 746 801 778 788 795 878 887 993 989 1050 1064 1397 1227 1614 1632 1821 1788 1932 1955 1920 2026 2013 2029 2107 2095 2030 1855 1786 1707 1518 1286 1307 1106 1069 1017 907 894 815 851 796 763 751 767 756 720 753 821 736 722 730 725 728 734 760 706 765 703 724 736 703 709 681 724 690 731 743 745 724 740 678 729 772 748 730 738 756 718 721 656 680 720 686 681 708 745 649 708 711 729 692 739 731 734 744 698 710 720 693 703 686 737 725 738 708 697 721 707 759 716 750 707 720 744 682 650 725 674 707 720 699 698 679 710 742 688 716 698 703 715 745 750 731 717 699 679 689 734 688 765 759 719 702 666 713 715 737 681 704 711 749 779 706 714 718 689 685 751 755 761 717 776 713 758 768 769 785 778 766 744 820 720 817 749 825 831 821 791 780 801 784 737 760 782 759 783 693 735 755 713 706 753 713 703 726 730 753 725 766 766 754 688 741 707 721 749 746 715 730 737 712 656 683 671 724 770 712 699 712 704 722 711 733 718 735 743 779 663 716 710 696 718 710 731 726 731 703 707 710 703 708 665 762 754 701 708 735 774 718 684 720 714 769 746 718 757 746 681 640 712 680 745 716 721 675 764 705 712 683 714 735 738 708 710 725 710 669 694 689 671 758 691 701 672 750 724 683 766 704 650 696 704 708 742 702 701 740 708 704 740 725 716 684 824 690 716 696 739 717 720 695 701 693 701 698 735 703 733 708 727 675 711 717 694 715 728 699 783 702 721 691 697 731 731 726 766 737 800 753 697 746 706 685 726 765 692 688 742 714 720 759 761 705 750 767 748 693 703 759 738 738 694 741 731 722 821 706 775 716 749 736 762 724 729 724 717 776 721 727 785 729 747 745 749 778 743 741 749 731 822 741 712 780 756 774 773 811 803 801 821 799 833 809 866 926 889 840 899 1009 959 1075 1063 1129 1200 1244 1477 1615 1586 1798 1999 2089 2182 2230 2196 2351 2408 2286 2285 2237 2308 2276 2154 1954 1861 1758 1482 1558 1308 1101 1016 1011 955 985 834 755 760 809 812 762 796 796 737 747 761 702 761 716 728 764 756 789 723 831 721 799 767 746 748 799 770 694 784 721 749 702 828 781 754 725 740 786 710 746 725 737 758 726 726 762 816 761 792 736 814 771 766 739 742 747 732 782 744 765 781 795 777 751 779 754 735 768 760 696 787 768 739 719 763 798 764 723 777 733 770 785 761 798 765 697 807 756 731 815 765 770 849 771 758 798 758 793 777 803 736 812 768 784 747 770 798 742 795 764 807 770 773 756 810 757 790 778 838 818 810 804 799 739 788 813 731 816 813 820 807 793 794 778 816 795 791 816 802 862 810 787 835 815 788 805 850 875 819 817 802 787 848 817 856 829 815 796 814 828 873 858 841 773 821 810 882 868 823 849 812 806 869 831 833 827 836 798 820 848 836 868 895 864 872 868 794 867 861 829 879 919 859 892 896 886 837 943 814 889 890 896 947 887 910 886 857 872 893 883 904 898 889 861 880 883 930 917 861 902 892 921 932 907 922 972 1001 929 904 946 971 948 918 899 905 955 959 911 941 1018 919 894 938 955 878 947 864 890 908 930 900 951 908 905 964 986 995 937 959 1009 1017 1023 1035 996 1041 1059 1071 1054 1100 1103 1115 1119 1066 1104 1101 1173 1150 1091 1142 1120 1126 1071 953 950 976 930 980 923 964 1006 1007 925 922 934 960 998 943 938 958 919 976 937 883 962 920 900 988 907 946 899 989 942 946 959 968 929 934 961 935 929 998 974 953 966 914 959 973 940 891 934 972 944 929 908 943 956 884 925 957 956 952 982 954 960 945 949 974 991 909 960 944 907 899 988 943 939 939 876 938 932 908 907 971 941 963 930 878 953 938 914 890 962 934 892 924 880 949 911 905 940 926 925 956 865 912 924 933 948 937 968 931 954 924 949 902 867 866 924 910 949 857 889 899 999 894 929 888 981 921 974 967 955 923 918 917 882 853 864 871 951 956 881 858 889 901 870 888 904 830 906 931 929 914 926 818 870 894 904 894 914 896 898 844 891 849 865 885 885 833 886 883 785 918 885 895 904 855 869 923 840 902 903 801 833 920 804 911 855 859 915 897 948 884 857 918 896 935 920 966 999 974 1045 978 1016 1043 1016 1081 1063 1057 1075 1003 1015 1018 1059 943 1042 1030 964 884 923 904 849 875 886 867 871 838 827 827 857 829 821 759 778 835 815 824 831 806 833 783 827 849 811 798 865 838 800 822 836 830 780 823 801 786 793 797 745 833 823 831 803 870 808 829 828 801 808 800 810 842 744 810 855 772 808 812 787 791 766 775 766 786 735 778 857 784 749 837 812 780 770 768 796 789 793 828 809 773 795 754 759 742 771 776 721 785 757 730 841 742 778 772 745 757 699 730 756 791 767 715 804 747 771 794 713 747 737 762 755 707 747 746 745 719 768 762 708 754 719 708 750 728 762 687 728 688 767 761 738 707 796 714 725 702 724 774 733 758 708 703 741 710 716 745 788 743 728 779 783 708 705 750 752 703 744 767 734 721 750 661 705 774 758 700 674 645 765 683 705 736 688 683 651 673 697 712 727 721 701 712 732 722 668 696 697 709 691 684 676 694 709 694 705 714 719 683 689 734 698 644 754 631 685 669 687 701 705 641 661 695 687 697 661 720 678 639 674 672 637 650 649 679 678 664 700 677 698 654 665 712 700 642 686 660 644 653 606 728 695 687 630 677 680 608 692 673 621 625 623 615 633 636 680 629 662 622 675 696 583 633 640 653 683 617 671 636 660 653 634 625 642 679 618 623 631 622 629 618 644 670 667 644 662 662 682 682 655 665 676 693 640 677 660 727 660 675 638 682 629 655 629 672 668 601 636 660 600 673 660 625 661 616 560 658 648 647 636 634 621 658 691 602 630 580 583 648 603 640 639 608 598 643 602 652 623 644 580 627 608 582 648 606 625 618 626 641 630 628 628 633 599 634 624 655 613 622 616 600 624 620 632 684 579 629 592 599 622 607 668 625 629 599 638 581 589 578 649 620 596 636 618 589 624 627 637 639 592 600 637 599 634 562 685 603 558 562 633 606 624 611 577 655 631 599 655 578 646 612 624 559 704 638 596 654 547 560 578 594 657 614 645 641 587 590 618 618 605 594 626 610 594 624 584 561 562 614 638 600 588 584 634 592 560 609 613 525 549 588 611 582 582 584 597 597 588 656 605 602 636 593 598 586 606 543 574 595 608 606 615 620 666 682 684 719 727 692 743 755 715 750 770 798 859 825 798 800 800 861 803 810 802 800 755 745 722 711 694 649 671 628 574 620 605 576 642 560 594 573 594 560 529 578 575 576 590 543 604 602 600 567 548 572 614 559 560 593 563 588 518 592 575 574 598 592 584 618 558 589 624 576 572 569 571 587 596 541 576 591 582 591 542 618 606 609 586 580 602 572 630 573 569 580 576 567 570 585 569 579 589 559 569 583 559 554 568 551 580 566 592 515 593 648 602 560 629 633 621 591 614 592 571 585 613 580 627 566 623 603 583 617 636 579 568 636 596 646 596 597 638 648 653 659 611 642 711 758 804 779 793 805 877 781 859 829 807 824 845 830 858 801 798 724 753 705 644 720 728 605 617 621 607 659 578 595 586 634 612 614 609 611 597 591 603 571 583 603 560 604 589 594 588 609 568 588 572 546 590 633 554 622 558 574 603 539 567 563 558 592 533 535 596 575 594 650 616 568 620 622 562 599 599 621 582 617 582 587 573 559 568 584 596 566 568 538 551 613 543 597 565 595 581 553 568 578 602 585 625 631 602 586 596 577 705 669 655 663 611 628 609 684 671 635 642 638 576 602 608 599 572 607 583 620 581 576 587 592 593 597 610 587 569 602 569 574 557 556 650 582 557 603 595 591 596 566 639 593 576 527 584 600 587 571 614 582 548 643 568 618 652 581 635 593 559 591 552 578 590 557 578 569 604 544 606 547 606 603 579 590 595 581 564 570 617 614 613 566 618 629 586 541 542 592 578 606 634 585 623 590 592 564 608 527 519 566 602 607 567 599 571 594 565 610 605 608 574 597 615 587 592 572 582 584 597 574 593 587 606 614 566 629 602 626 564 580 614 597 608 576 564 584 608 605 570 619 631 568 613 590 622 629 579 569 602 568 599 588 605 650 622 560 599 568 594 585 583 596 598 604 640 614 630 631 607 623 628 593 547 595 604 577 561 622 598 630 604 580 590 603 626 620 595 529 670 613 657 599 577 616 599 632 551 560 593 586 613 584 590 613 591 619 584 621 595 589 593 553 590 656 576 653 616 617 585 620 570 637 604 655 619 579 600 598 585 592 634 589 611 616 600 568 612 589 603 616 607 612 603 612 622 598 575 617 600 610 576 636 595 596 600 546 641 610 605 620 645 576 569 631 624 623 603 610 609 590 554 630 658 621 579 588 649 651 625 583 623 576 629 598 609 599 611 604 598 632 583 574 605 588 624 605 591 602 621 638 573 612 593 584 609 623 593 563 623 604 609 651 613 584 595 622 593 562 633 631 622 587 599 589 640 650 613 601 627 579 570 606 682 621 600 575 646 600 598 644 634 594 562 642 625 623 653 574 664 660 581 594 626 646 637 582 637 548 584 642 611 570 628 612 625 637 626 598 628 635 568 567 600 610 586 647 602 616 678 621 581 606 645 627 619 656 626 592 672 647 624 650 663 605 595 597 591 663 601 629 605 627 631 625 687 642 658 637 633 639 670 624 604 654 628 620 650 621 627 611 650 606 617 628 598 686 653 621 686 605 622 652 611 633 633 618 611 621 615 610 624 599 670 611 623 653 602 621 633 626 607 656 592 657 684 633 615 600 660 637 660 644 664 646 651 658 651 624 639 650 650 669 664 681 650 645 638 664 616 629 592 631 602 654 622 633 648 647 628 663 630 627 628 619 659 643 621 637 659 611 632 651 679 618 699 609 653 670 665 685 674 621 617 647 665 654 654 630 640 632 644 592 657 686 658 609 602 634 659 682 615 654 628 665 621 681 635 621 639 653 637 681 697 618 606 642 678 699 729 675 662 624 672 678 669 641 654 640 638 689 702 658 702 685 647 662 694 681 670 630 584 675 623 679 656 653 680 659 643 635 654 645 657 687 641 658 631 656 656 646 701 659 657 646 647 675 663 646 694 646 666 688 632 667 681 709 691 643 666 646 638 646 694 652 715 628 672 690 674 588 640 672 716 695 686 662 685 684 658 688 687 696 677 706 666 694 692 698 632 661 704 674 649 675 720 673 659 669 698 693 638 681 662 678 670 656 687 682 709 665 703 663 664 749 722 763 702 718 699 641 736 705 693 730 733 674 714 750 738 722 734 726 733 754 796 755 847 852 946 1014 1083 1299 1559 1835 2006 2268 2452 2716 2894 3096 3311 3344 3437 3545 3575 3506 3501 3465 3263 3175 2969 2716 2458 2199 2104 1832 1608 1344 1147 1048 962 914 824 833 718 730 758 688 733 736 722 731 738 720 699 749 717 719 737 733 699 738 712 704 699 708 761 668 689 711 690 727 732 680 732 673 746 715 722 708 726 725 706 731 695 705 698 675 711 682 657 740 688 713 710 701 734 700 658 710 734 731 725 692 741 734 729 714 738 789 695 740 758 706 706 712 737 752 718 711 708 738 690 697 709 672 703 696 696 702 717 721 690 693 729 743 733 679 734 683 688 669 748 688 710 686 658 667 710 752 688 690 755 741 723 717 751 713 765 702 707 745 768 729 753 736 767 717 693 711 727 814 792 722 760 712 716 764 702 730 683 737 751 752 688 732 773 735 773 810 729 742 742 735 686 750 765 734 764 719 693 724 707 771 745 767 734 729 731 740 771 746 707 755 768 737 734 746 740 779 737 763 748 724 788 734 722 719 801 737 789 725 792 686 749 782 739 717 757 745 712 784 760 737 694 755 726 788 747 782 746 770 739 742 706 750 739 764 821 769 740 719 758 718 758 705 731 732 741 778 740 763 731 736 743 790 781 770 717 729 748 784 718 746 771 814 731 732 772 782 817 737 776 755 765 762 706 780 784 785 778 796 750 786 839 726 798 783 780 788 795 753 786 849 757 724 760 791 755 739 759 767 772 770 734 786 796 736 759 755 782 743 764 812 770 797 813 742 716 805 805 813 757 748 806 743 696 795 778 817 760 840 796 729 767 757 756 777 788 840 820 791 732 722 777 831 756 823 777 747 775 796 748 782 835 845 745 772 772 739 766 796 787 831 797 804 796 822 789 810 804 732 823 803 819 774 806 783 813 773 837 786 771 795 794 807 789 801 811 782 814 766 792 820 861 808 752 852 779 780 809 828 763 813 816 814 752 838 857 809 846 813 825 800 779 794 788 808 780 775 805 770 809 814 799 804 818 800 821 815 758 804 823 830 842 835 835 764 829 854 779 854 860 837 829 863 867 845 808 780 861 816 824 816 863 837 812 832 850 875 823 832 864 812 855 848 843 812 847 853 813 814 855 837 844 791 831 859 864 809 838 830 859 783 847 884 869 833 869 804 877 803 868 791 865 855 858 846 818 915 823 841 841 858 906 861 893 807 840 860 819 827 853 848 806 874 883 863 877 860 863 866 915 872 849 876 906 848 927 836 852 830 833 848 849 898 892 883 850 830 843 829 890 855 843 892 883 899 854 886 895 799 902 902 869 905 867 883 894 914 871 939 880 855 837 844 858 843 868 901 940 864 847 947 930 981 943 938 933 890 878 965 902 912 890 938 936 913 970 911 907 856 910 848 873 870 929 974 878 945 891 909 944 906 912 905 880 907 952 865 914 874</counts>
			</dataPoints>
		</scan>
	</xrdMeasurement>
</xrdMeasurements>