File: Data Files/Full/MSS p (6-129, 10w)_01.xrdml
<?xml version="1.0"?>
<xrdMeasurements xmlns="http://www.xrdml.com/XRDMeasurement/2.2" xmlns:xsi="http://www.w3.org/2001/XMLSchema-instance" xsi:schemaLocation="http://www.xrdml.com/XRDMeasurement/2.2 http://www.xrdml.com/XRDMeasurement/2.2/XRDMeasurement.xsd" status="Completed" recordIdentifier="{C43F3929-55BB-4CC2-9167-E83BDD58A450}">
	<comment>
		<entry/>
	</comment>
	<sample type="To be analyzed">
		<id>p</id>
		<name></name>
		<preparedBy></preparedBy>
	</sample>
	<xrdMeasurement measurementType="Scan" status="Completed" sampleMode="Reflection">
		<usedWavelength intended="K-Alpha 1">
			<kAlpha1 unit="Angstrom">1.5405980</kAlpha1>
			<kAlpha2 unit="Angstrom">1.5444260</kAlpha2>
			<kBeta unit="Angstrom">1.3922500</kBeta>
			<ratioKAlpha2KAlpha1>0.5000</ratioKAlpha2KAlpha1>
		</usedWavelength>
		<incidentBeamPath>
			<radius unit="mm">145.00</radius>
			<xRayTube id="1010048" name="Empyrean Cu LFF HR (9430 033 7310x) DK437964">
				<tension unit="kV">40.0</tension>
				<current unit="mA">15.0</current>
				<anodeMaterial>Cu</anodeMaterial>
				<focus type="Line">
					<length unit="mm">12.0</length>
					<width unit="mm">0.4</width>
					<takeOffAngle unit="deg">6.0</takeOffAngle>
				</focus>
			</xRayTube>
			<filter id="20010004" name="Beta-filter Nickel">
				<material>Ni</material>
				<thickness unit="mm">0.020</thickness>
			</filter>
			<sollerSlit id="21010002" name="Soller slits 0.04 rad.">
				<opening unit="rad">0.0400</opening>
			</sollerSlit>
			<mask id="22031000" name="Fixed mask 13 mm">
				<width unit="mm">9.00</width>
			</mask>
			<divergenceSlit id="22120001" name="Divergence slit 1°" xsi:type="fixedDivergenceSlitType">
				<distanceToSample unit="mm">50.00</distanceToSample>
				<height unit="mm">1.52</height>
			</divergenceSlit>
		</incidentBeamPath>
		<diffractedBeamPath>
			<radius unit="mm">145.00</radius>
			<parallelPlateCollimator id="25020001" name="Parallel plate collimator 0.28°">
				<opening unit="deg">0.28</opening>
			</parallelPlateCollimator>
			<detector id="7010020" name="PIXcel3D-Medipix3 1x1 detector" xsi:type="areaDetectorType">
				<phd unit="keV">
					<lowerLevel>4.0</lowerLevel>
					<upperLevel>11.3</upperLevel>
				</phd>
				<mode>Receiving slit</mode>
				<activeChannelsEquatorial>255</activeChannelsEquatorial>
				<activeChannelsAxial>255</activeChannelsAxial>
				<pitchEquatorial unit="mm">0.05500</pitchEquatorial>
				<pitchAxial unit="mm">0.05500</pitchAxial>
				<readOutPeriod unit="seconds">0.050</readOutPeriod>
			</detector>
		</diffractedBeamPath>
		<scan appendNumber="0" mode="Continuous" scanAxis="2Theta" status="Completed">
			<header>
				<startTimeStamp>2025-06-27T13:57:19-08:00</startTimeStamp>
				<endTimeStamp>2025-06-28T03:37:23-08:00</endTimeStamp>
				<author>
					<name>Instrument</name>
				</author>
				<source>
					<applicationSoftware version="1.6 (94)">PANalytical Aeris Instrument Suite</applicationSoftware>
					<instrumentControlSoftware version="3.0.0 20211014">AERIS</instrumentControlSoftware>
					<instrumentID>2855484</instrumentID>
				</source>
			</header>
			<dataPoints>
				<positions axis="2Theta" unit="deg">
					<startPosition>6.005</startPosition>
					<endPosition>128.995</endPosition>
				</positions>
				<positions axis="Omega" unit="deg">
					<commonPosition>10.000</commonPosition>
				</positions>
				<commonCountingTime unit="seconds">3.520</commonCountingTime>
				<counts 5777 5597 5600 5493 5474 5502 5411 5399 5462 5397 5431 5570 5397 5622 5381 5482 5226 5229 5461 5390 5370 5438 5399 5392 5305 5448 5297 5270 5369 5382 5289 5343 5369 5370 5304 5178 5361 5284 5307 5351 5188 5430 5254 5198 5255 5316 5221 5117 5200 5138 5275 5243 5352 5187 5310 5363 5070 5239 5206 5099 5179 5092 5153 5150 5216 5190 5116 5163 5138 5111 5202 5058 5204 5200 5192 5071 5256 5182 5105 5213 5137 5171 5073 5143 5148 5110 5064 5107 5052 5067 5201 5097 5113 5029 5103 5254 5092 5158 4982 5068 5072 5132 5005 5107 4973 4997 4983 5020 5012 5052 4994 5038 4973 4943 5014 4880 5038 5077 4929 4975 5046 4862 4981 5021 4971 5026 5017 4986 4866 5013 4898 5008 4925 5019 4991 5032 4948 5066 4929 5066 5137 4820 4979 4750 4934 4907 4975 4871 4835 4787 4974 4980 4965 4794 4916 4774 4894 4867 4962 4805 4910 4872 4784 4825 4926 5010 4971 4867 4904 4985 5001 5016 5090 4974 4833 4969 5171 5008 5149 5159 5096 5085 5140 5080 5182 5145 5147 5070 5184 5222 5128 5147 5038 5135 5285 5179 5292 5255 5178 5138 5180 5205 5112 5257 5214 5296 5205 5232 5236 5240 5317 5234 5295 5103 5147 5276 5220 5310 5245 5112 5296 5285 5039 5210 5173 5046 5127 5191 5164 5087 5131 5130 5108 5076 5180 5235 5151 5159 5212 5028 5102 5159 5101 4952 5103 5134 4974 5218 5068 5043 5093 5017 5065 5135 5032 5101 5027 4933 4971 4861 5001 5084 5011 5078 4911 5030 4789 4993 5001 4932 4939 5017 4873 4998 4976 4965 5037 4889 4971 4957 4859 4907 4826 4901 4831 4851 4845 4888 4925 4970 4933 4937 4821 4897 4860 4905 4775 4894 4880 4777 4829 4848 4884 4960 4866 4868 4850 4743 5063 4822 4867 4704 4821 4854 4778 4836 4853 4839 5048 4798 4978 4886 4714 4756 4853 4911 4814 4822 4961 4830 4769 4815 4761 4882 4737 4840 4778 4869 5011 4959 4805 4833 4954 4830 4958 4795 4769 4810 4976 4825 4832 4782 4892 4796 4917 4977 4784 4822 4990 4878 4789 4884 4785 4844 4932 4899 4959 4872 4936 4871 4940 4832 4788 4766 4886 4761 4795 4752 4747 4835 4901 4972 4960 4854 4795 4776 4817 4914 4894 5007 4890 5017 5046 4926 4936 4913 4911 4978 4898 4834 4924 4898 4994 4832 4800 4901 4880 4762 4906 4945 4885 4990 4913 4942 4985 4890 4979 4840 4875 4878 4964 5062 4921 4969 4981 5025 4735 5035 5218 4935 4925 4983 4782 5031 5068 4962 5011 4889 4919 4962 4928 4983 4971 5139 5053 4962 5129 5056 5038 5020 5110 5001 5122 4990 5105 5084 5048 5186 5091 5015 5233 5085 4941 5231 5077 5147 5221 5157 5169 5202 5227 5140 5145 5055 5089 5282 5256 5221 5291 5366 5180 5153 5177 5236 5273 5069 5295 5179 5243 5260 5206 5141 5381 5445 5224 5430 5304 5229 5175 5402 5242 5196 5438 5308 5376 5279 5440 5312 5373 5523 5385 5510 5448 5536 5463 5351 5434 5513 5524 5459 5483 5572 5547 5523 5591 5518 5448 5444 5422 5528 5727 5575 5546 5464 5557 5541 5636 5519 5530 5611 5388 5585 5540 5454 5579 5618 5779 5615 5722 5567 5692 5789 5679 5669 5738 5800 5708 5713 5881 5823 5783 5782 5968 5837 5858 5863 5888 5798 5853 5892 5733 5935 6156 6153 5960 5960 6168 6097 6091 6058 6266 6141 6152 6196 6043 6116 6016 6441 6270 6165 6310 6105 6183 6237 6353 6349 6282 6445 6455 6439 6241 6403 6368 6526 6461 6378 6583 6604 6554 6662 6546 6505 6603 6414 6554 6609 6624 6761 6633 6630 6704 6639 6690 6732 6688 6751 6843 6677 6798 6698 6815 6804 6767 6942 7163 7496 7807 8179 8541 8800 9575 9988 11227 11670 12749 13770 14971 16025 16827 17966 18764 19420 19721 20297 20485 20905 21169 21170 20934 20874 20077 19732 19327 19416 19115 18651 19061 18793 19002 19595 20454 20774 21943 23099 24257 25627 26602 28122 28812 30799 31735 32630 33360 34011 33956 34149 33804 32960 32467 31534 30383 28656 27430 25919 24270 22666 21017 18734 17510 15554 14496 12852 11546 10546 9532 8961 8311 7936 7596 7417 7405 7500 7298 7328 7371 7345 7560 7528 7481 7458 7347 7331 7385 7460 7400 7379 7441 7483 7420 7383 7207 7306 7428 7357 7287 7184 7324 7510 7360 7445 7330 7423 7403 7531 7407 7581 7647 7538 7542 7548 7426 7582 7575 7457 7564 7682 7590 7661 7723 7715 7834 7668 7878 7775 7788 7669 7799 7887 7984 7663 7762 7561 7801 7695 7870 7583 7866 7652 7612 7550 7632 7632 7620 7510 7674 7573 7432 7500 7521 7552 7430 7704 7536 7599 7519 7465 7544 7564 7541 7367 7544 7527 7490 7497 7413 7348 7449 7597 7349 7643 7489 7427 7377 7311 7450 7378 7291 7372 7469 7325 7181 7605 7487 7371 7339 7470 7401 7328 7353 7175 7230 7461 7342 7272 7351 7266 7341 7320 7370 7317 7267 7374 7336 7211 7327 7034 7273 7260 7218 7127 7207 7212 7111 7142 7132 7400 7247 7110 7090 7060 7085 7000 7127 7172 6887 7072 7161 7200 6842 7132 7113 6832 7016 7069 6827 6876 6787 6888 7095 6924 6943 6920 7144 6820 6773 6854 6733 6813 6983 6769 6863 6801 6901 6740 6659 6779 6712 6675 6711 6705 6742 6669 6814 6768 6640 6595 6701 6690 6724 6604 6570 6482 6731 6588 6503 6534 6559 6684 6604 6470 6553 6735 6529 6359 6696 6567 6500 6373 6505 6520 6206 6547 6285 6372 6386 6435 6317 6221 6261 6393 6341 6280 6278 6259 6403 6137 6334 6371 6100 6332 6085 5983 6040 6176 6111 6012 6322 6153 6041 6120 5889 6018 6028 5934 6061 6123 5981 5886 6025 6027 6064 5970 6028 5862 5957 5899 5884 5826 5955 5837 5796 5781 5756 5636 5722 5901 5792 5872 5668 5728 5701 5583 5561 5558 5627 5595 5705 5679 5688 5568 5649 5620 5495 5536 5552 5583 5615 5567 5451 5447 5533 5489 5560 5502 5648 5442 5502 5379 5382 5448 5366 5273 5320 5296 5352 5455 5426 5481 5293 5371 5244 5299 5276 5364 5213 5252 5298 5245 5342 5263 5300 5140 5189 5181 5116 5133 5198 5305 5235 5125 5241 5085 5188 5132 5235 5163 5091 5126 5223 5075 4923 5034 5036 5008 4973 5105 4962 5008 4834 4912 5004 5042 4923 4928 4989 5064 5002 5001 5078 5080 4907 5090 5128 5055 5137 5036 4930 4888 4962 4847 4824 4971 4989 4894 4973 4992 5007 4853 4867 4832 4727 4877 4689 4846 4795 4837 4837 4857 4662 4779 4710 4675 4715 4706 4688 4798 4656 4912 4654 4665 4825 4678 4679 4681 4659 4628 4767 4597 4667 4627 4512 4420 4495 4688 4565 4478 4553 4456 4395 4606 4618 4518 4541 4618 4448 4485 4552 4504 4442 4527 4483 4510 4441 4528 4461 4313 4450 4429 4309 4438 4377 4400 4342 4446 4421 4476 4488 4428 4450 4475 4441 4305 4440 4294 4444 4523 4390 4349 4294 4347 4334 4266 4398 4301 4269 4322 4212 4206 4290 4289 4265 4310 4213 4324 4321 4343 4272 4236 4208 4230 4285 4185 4267 4350 4262 4273 4210 4156 4234 4214 4232 4150 4196 4144 4138 4273 4161 4235 4166 4024 4027 4227 4088 4139 4056 4032 4103 4055 4117 4108 4205 4198 4136 4168 3999 4076 4045 4105 4018 4169 4141 4121 4143 4065 4135 3999 4153 4001 4104 4037 3878 4020 4035 4035 4145 3990 4061 3914 3951 4035 4054 3995 3933 3909 3951 3927 4027 3998 4127 3914 4074 4030 3990 3924 3935 4050 3906 3873 3991 3990 3885 4111 4055 3897 3996 3851 3868 3973 3760 3852 3949 3823 3806 3900 3884 3967 3994 3841 3839 3901 4027 3800 3826 3757 3842 3872 3938 3708 3881 3738 3872 3904 3743 3843 3883 3800 3716 3801 3693 3782 3807 3824 3816 3750 3880 3780 3831 3771 3783 3847 3773 3713 3749 3840 3785 3647 3709 3840 3692 3765 3768 3686 3731 3581 3753 3671 3631 3677 3764 3688 3667 3665 3681 3715 3652 3746 3758 3619 3646 3840 3626 3743 3758 3743 3737 3587 3720 3667 3677 3598 3626 3669 3670 3721 3648 3617 3679 3758 3707 3551 3752 3574 3672 3570 3644 3631 3555 3621 3635 3660 3643 3636 3728 3648 3799 3704 3653 3638 3722 3575 3555 3643 3547 3642 3655 3673 3531 3559 3560 3755 3575 3583 3769 3558 3709 3611 3576 3606 3627 3623 3543 3534 3532 3703 3588 3615 3672 3486 3587 3618 3456 3598 3471 3503 3495 3535 3550 3524 3587 3533 3593 3554 3551 3549 3544 3575 3590 3576 3586 3512 3562 3470 3542 3565 3511 3499 3622 3441 3438 3640 3586 3533 3566 3521 3511 3504 3479 3321 3496 3560 3518 3520 3498 3432 3415 3519 3477 3443 3477 3411 3441 3571 3391 3380 3476 3592 3429 3534 3424 3497 3458 3462 3434 3402 3427 3411 3426 3458 3363 3398 3492 3406 3478 3232 3421 3359 3448 3454 3426 3341 3460 3341 3400 3373 3331 3415 3340 3393 3509 3375 3371 3333 3436 3311 3364 3398 3392 3402 3373 3301 3483 3406 3460 3408 3496 3518 3504 3514 3635 3544 3716 3649 3805 3801 3698 3767 3831 3875 3810 3868 3828 3864 3896 3783 3895 3748 3810 3665 3694 3859 3805 3816 3908 3877 3889 3809 3843 3974 3859 3901 3891 3937 4095 3883 4037 3936 3962 3947 4019 3939 3853 3996 3879 3904 3895 3634 3693 3693 3689 3651 3717 3513 3485 3417 3409 3307 3506 3256 3331 3346 3207 3281 3329 3301 3242 3219 3311 3256 3298 3339 3324 3235 3286 3167 3271 3151 3321 3252 3215 3232 3184 3232 3244 3229 3299 3259 3363 3265 3326 3189 3313 3249 3128 3237 3157 3260 3254 3178 3188 3252 3306 3210 3147 3100 3363 3189 3202 3208 3272 3333 3189 3208 3243 3238 3155 3208 3083 3199 3215 3220 3068 3208 3165 3295 3198 3189 3152 3210 3201 3116 3175 3239 3249 3149 3179 3305 3155 3224 3225 3117 3288 3093 3066 3120 3171 3147 3203 3164 3119 3136 3092 3117 3156 3114 3158 3075 3184 3115 3211 3062 3230 3258 3223 3156 3168 3106 3177 3091 3211 3182 3100 3182 3212 3052 3171 3234 3170 3131 3074 3113 3150 3191 3219 3221 3222 3197 3047 3113 3227 3143 3137 3259 3118 3094 3120 3208 3219 3208 3095 3135 3109 3164 3197 3054 3178 3150 3182 3160 3137 3281 3175 3150 3149 3137 3281 3302 3240 3208 3139 3140 3021 3243 3257 3098 3227 3219 3201 3075 3156 3163 3152 3210 3178 3040 3295 3386 3344 3500 3613 3631 3708 4078 4224 4244 4693 5005 5198 5628 5799 6128 6381 6665 6794 7174 7175 7500 7690 7364 7238 7603 7567 7262 7296 7322 7186 7152 7013 6973 7153 7271 7476 7368 7205 7894 7868 7972 8196 8168 8764 8756 9172 9236 9346 9416 9550 9671 9780 9598 9618 9298 8967 8962 8648 8328 8029 7611 7105 6711 6396 5993 5491 5058 4883 4585 4129 4018 3818 3589 3559 3394 3287 3243 3248 3300 3280 3205 3213 3043 3143 3174 3134 3280 3260 3254 3166 3224 3221 3330 3166 3056 3167 3209 3023 3242 3170 3142 3130 3115 3103 3010 3119 3195 3224 3167 3174 3044 3056 3099 3113 3101 3093 3071 3116 3127 3032 3111 3131 3088 3204 3127 3128 3146 3110 3232 3121 3214 3065 3079 3139 3020 3012 2949 3113 3127 3072 2950 3100 3061 3030 3022 3081 3094 2910 3034 3123 3044 2979 3049 3070 3128 3055 2995 3057 3025 3080 3059 2953 3127 3129 3005 2983 3085 3057 3065 3126 3005 3003 3092 3037 3111 2922 3098 3155 3092 3076 3041 3092 2962 3027 3066 2967 3024 3046 2946 3023 3029 3088 2950 3058 3017 3002 3012 3093 3076 2992 3081 3160 2990 3087 3134 3003 3088 3061 2978 3075 3075 3084 3072 3089 3106 3106 3045 2979 3054 3166 3186 3070 3093 3066 3094 3067 3011 3038 3052 3007 3064 2985 3032 3104 2953 3023 3098 2957 3004 2973 3077 3078 3004 3052 3122 3020 2951 3058 3093 3140 3004 2982 2978 3014 2982 2897 3026 3116 3139 3063 3011 2931 2990 2984 3067 2990 3065 2987 3072 3048 3020 2986 2962 3007 3001 3006 3113 3029 2981 2881 3036 3048 2960 3069 3031 2943 2981 2971 3018 2928 2997 3010 3083 2922 2879 2975 2991 3081 3084 3014 2941 3019 2982 3044 2956 2933 3035 2907 2934 3020 3063 3026 2931 3039 3014 3004 2952 3000 2992 2946 2924 2944 3064 3044 3015 3029 3036 3012 2964 3048 3050 2942 2878 2958 3047 3010 2945 2986 2997 3023 2997 2960 2939 2984 2926 3001 3015 3065 2985 2996 3004 2933 3026 3008 2993 2958 2996 2937 2991 3024 2872 2991 2944 2966 2886 2860 2999 3072 2935 2949 2944 3014 3004 3042 2905 3019 2952 2972 2990 2861 2956 3067 2997 2983 2997 3157 2897 2939 2975 2940 3027 2951 2979 3030 2943 2977 3045 2955 2984 2994 3023 2951 3020 2863 2841 2978 2979 2951 3056 3012 2915 2951 3002 2849 2858 2831 2942 2941 3020 3080 2902 3117 3025 2953 2989 2931 3034 3019 2973 3049 2920 2966 3080 3091 3008 2953 3078 3099 3194 3245 3243 3326 3499 3600 3643 3851 4163 4229 4535 4522 4796 4870 5248 5393 5564 5643 5932 5955 5839 6125 5960 6123 6166 6192 6194 6159 6317 6260 6055 6231 6362 6381 6630 6501 6719 7073 6999 7420 7254 7702 7697 7898 8053 8064 8288 8386 8336 8370 8557 8258 8179 8049 8012 7800 7688 7303 6992 6759 6469 6066 5561 5412 5013 4751 4520 4250 3980 3855 3725 3443 3397 3217 3140 3165 3165 3185 3111 3120 3122 3128 3044 2954 3070 3072 3097 3132 3125 3083 3106 2967 3047 2991 3004 2947 3154 2982 3021 3004 3008 3114 3115 3074 3153 3122 3029 3047 3093 2957 3024 3027 3014 2994 3033 3087 2999 3051 2965 2976 3108 3146 3009 3178 3008 3180 3104 3132 2979 2954 3040 3006 2983 3062 2989 3010 3017 3064 3023 3084 3079 3035 3096 3025 3040 3099 3048 3110 3026 2992 3068 2961 3052 3097 3059 3122 3081 3098 3058 3026 3060 3018 2992 3047 3088 2957 3079 3066 3106 3029 3152 3025 3004 2990 3050 3097 3139 3125 3207 3121 3151 3177 3180 3076 3104 3044 3191 3092 3169 3015 3156 3099 3155 3173 3122 3032 3081 3206 3166 3193 3099 3168 3089 3170 2955 3118 3170 3071 3144 3178 3191 3201 3141 3316 3179 3162 3141 3136 3253 3181 3204 3108 3235 3205 3209 3193 3216 3222 3263 3354 3153 3174 3211 3271 3269 3182 3179 3322 3243 3241 3222 3277 3234 3278 3283 3181 3198 3261 3361 3187 3326 3426 3270 3227 3359 3315 3268 3384 3294 3305 3336 3199 3392 3291 3329 3369 3284 3275 3397 3246 3321 3265 3236 3391 3363 3278 3308 3440 3248 3348 3446 3339 3204 3409 3358 3329 3441 3374 3268 3449 3376 3329 3492 3408 3380 3465 3317 3329 3457 3260 3393 3416 3377 3474 3392 3399 3292 3295 3406 3444 3421 3441 3433 3445 3296 3338 3415 3386 3518 3397 3477 3429 3548 3361 3430 3375 3381 3461 3503 3518 3438 3378 3466 3365 3482 3415 3437 3465 3384 3468 3530 3497 3500 3470 3419 3422 3408 3425 3446 3433 3388 3363 3542 3385 3456 3470 3315 3427 3372 3469 3476 3380 3412 3424 3446 3483 3603 3503 3551 3668 3815 3838 3903 4095 4261 4476 4549 4634 4797 5006 5170 5350 5727 5807 6058 6155 6203 6323 6382 6370 6358 6156 6264 6235 6189 6205 6185 6276 6092 6175 6220 6309 6365 6556 6484 6694 6706 6882 6974 7287 7340 7381 7518 7746 7822 7915 7848 7920 7813 7947 7806 7631 7637 7305 7075 7102 6746 6440 6262 5866 5577 5155 4958 4662 4265 4401 3891 3828 3657 3683 3530 3352 3338 3278 3243 3293 3297 3166 3179 3249 3174 3269 3266 3189 3194 3299 3051 3123 3131 3147 3238 3050 3030 3132 3100 3075 2994 3179 3040 3093 3085 3130 3059 3031 3073 3063 2939 3065 3113 2982 2999 2898 3122 2931 2994 2888 3086 2980 2991 2986 3005 2965 2945 3010 2921 2990 2944 2877 2983 2852 2963 3023 3037 2900 3062 2944 2908 2810 2819 2945 2873 2922 2858 2920 2941 2870 2823 2863 2876 2855 2853 2889 2875 2756 2855 2847 2872 2857 2879 2760 2811 2903 2795 2821 2867 3002 2888 2847 2844 2895 2916 2812 2898 2876 2818 2876 2909 2909 2774 2868 2910 2926 2895 2922 2810 2837 2972 2981 2959 2923 2954 2904 2962 2890 2846 2909 2936 2779 2951 2963 2805 2911 2884 2870 2887 2874 2782 2933 2904 2933 2869 2909 2923 3000 2868 2767 2756 2706 2660 2817 2796 2667 2716 2841 2671 2799 2708 2657 2690 2670 2678 2671 2697 2646 2602 2546 2606 2719 2593 2676 2589 2686 2522 2677 2675 2681 2558 2628 2711 2520 2615 2564 2569 2597 2500 2562 2558 2654 2575 2628 2401 2484 2585 2521 2631 2516 2600 2475 2519 2489 2565 2556 2550 2598 2536 2500 2508 2543 2437 2514 2554 2573 2496 2487 2499 2466 2536 2377 2537 2458 2528 2499 2447 2469 2430 2500 2419 2538 2488 2501 2387 2581 2394 2567 2424 2429 2440 2575 2528 2519 2443 2456 2406 2467 2436 2457 2487 2488 2529 2394 2529 2452 2403 2514 2372 2439 2440 2470 2468 2453 2494 2407 2451 2372 2424 2406 2402 2309 2390 2433 2453 2479 2439 2448 2405 2377 2506 2362 2447 2344 2425 2465 2368 2366 2365 2401 2501 2381 2293 2369 2388 2464 2340 2444 2396 2410 2398 2392 2295 2353 2453 2379 2428 2393 2449 2370 2446 2327 2365 2466 2330 2388 2374 2385 2422 2388 2356 2387 2372 2387 2373 2421 2403 2340 2371 2298 2387 2423 2323 2405 2332 2309 2356 2358 2261 2347 2332 2343 2262 2431 2440 2385 2411 2333 2398 2352 2437 2298 2349 2358 2347 2462 2373 2309 2295 2411 2287 2282 2334 2376 2322 2311 2309 2297 2388 2358 2337 2252 2290 2452 2342 2278 2400 2354 2342 2320 2312 2338 2300 2398 2261 2267 2304 2345 2243 2216 2288 2333 2298 2356 2330 2504 2303 2234 2265 2316 2305 2326 2207 2234 2341 2308 2331 2292 2437 2307 2341 2286 2354 2272 2307 2285 2283 2261 2347 2271 2284 2373 2292 2259 2307 2259 2325 2248 2253 2312 2237 2256 2247 2319 2290 2289 2261 2282 2247 2370 2210 2278 2316 2261 2239 2268 2253 2252 2178 2294 2237 2217 2263 2234 2291 2318 2221 2251 2320 2201 2282 2245 2268 2229 2237 2243 2247 2363 2280 2319 2219 2238 2219 2291 2208 2246 2309 2239 2351 2286 2269 2386 2208 2242 2388 2323 2344 2354 2290 2245 2200 2297 2259 2338 2382 2399 2263 2339 2344 2397 2356 2525 2472 2482 2461 2374 2543 2590 2871 2962 3115 3350 3651 4001 4519 5139 5585 5997 6750 7286 7865 8611 9100 9778 10239 10580 10912 11068 11386 11651 11556 11678 11969 12203 12243 12146 12183 12137 12316 12202 12149 12196 12269 12226 12505 12403 12481 12484 12809 12664 12655 12797 12674 12760 12706 12665 12542 12203 12143 11882 11582 11139 11046 10686 10505 10231 10050 9717 9302 8829 8198 7583 7213 6414 5944 5295 4749 4611 3952 3622 3186 2906 2605 2426 2385 2384 2286 2357 2384 2382 2256 2263 2401 2260 2222 2292 2232 2202 2133 2280 2262 2220 2153 2197 2192 2173 2148 2243 2183 2133 2212 2123 2145 2186 2137 2230 2211 2159 2224 2268 2202 2231 2176 2172 2133 2316 2235 2195 2290 2248 2157 2150 2097 2211 2186 2150 2190 2194 2174 2211 2245 2218 2116 2148 2102 2102 2075 2215 2142 2177 2185 2102 2186 2145 2163 2155 2237 2182 2297 2155 2165 2116 2145 2148 2140 2112 2210 2152 2144 2149 2238 2153 2146 2135 2122 2196 2209 2125 2136 2143 2114 2115 2139 2118 2194 2161 2116 2109 2114 2163 2183 2133 2062 2132 2211 2182 2185 2158 2263 2132 2083 2041 2144 2141 2143 2111 2128 2142 2150 2223 2042 2136 2079 2092 2117 2034 2116 2090 2221 2134 2112 2127 2174 2247 2084 2096 2169 2157 2140 2150 2248 2122 2143 2077 2092 2041 2095 2092 2150 2127 2050 2184 2086 2072 2086 2086 2165 2095 2119 2010 2221 2186 2148 2058 2121 2120 2216 2080 2050 2099 2091 2146 2113 2111 2091 2147 2194 2061 2060 2120 2085 2128 2067 2089 2075 2075 2103 2159 2152 2229 2085 2083 2178 2131 2072 2070 2150 2092 2092 2088 2173 2192 2173 2072 2084 2131 2128 2072 2075 2127 2129 2116 2107 2165 2138 2103 2067 2219 2142 2061 2140 2010 2149 2151 2225 2078 2135 2196 2163 2136 2066 2173 2048 2036 2143 2156 2187 2154 2103 2144 2110 2082 2071 2075 2076 2076 2130 2163 2058 2183 2212 2189 2183 2091 2087 2095 2092 2216 2164 2164 2079 2170 2157 2159 2149 2143 2142 2184 2220 2113 2126 2171 2081 2138 2100 2321 2099 2189 2164 2185 2203 2088 2093 2157 2113 2123 2149 2101 2189 2091 2212 2193 2153 2193 2214 2104 2159 2234 2076 2103 2185 2155 2107 2164 2284 2139 2128 2187 2230 2150 2218 2166 2109 2166 2066 2165 2132 2124 2159 2163 2124 2183 2129 2207 2139 2140 2200 2111 2157 2107 2102 2062 2225 2111 2178 2144 2227 2236 2188 2182 2034 2235 2045 2203 2148 2088 2146 2265 2196 2122 2219 2192 2097 2200 2171 2280 2135 2190 2190 2229 2244 2178 2167 2161 2238 2074 2217 2164 2169 2192 2150 2222 2232 2177 2187 2122 2179 2196 2104 2217 2184 2182 2068 2198 2254 2227 2168 2267 2291 2243 2183 2188 2215 2106 2242 2220 2177 2181 2249 2216 2271 2240 2156 2127 2179 2168 2256 2156 2181 2301 2246 2276 2184 2213 2281 2286 2207 2234 2233 2216 2170 2226 2181 2217 2253 2196 2237 2320 2244 2265 2241 2264 2243 2181 2198 2256 2209 2318 2346 2189 2277 2264 2274 2199 2116 2223 2198 2280 2250 2291 2285 2195 2252 2207 2254 2331 2295 2296 2356 2288 2326 2310 2313 2265 2284 2254 2309 2197 2349 2348 2276 2290 2311 2367 2325 2279 2328 2287 2189 2339 2422 2269 2296 2280 2271 2314 2244 2379 2295 2322 2317 2313 2356 2268 2294 2357 2268 2338 2317 2293 2346 2398 2330 2343 2306 2414 2381 2356 2370 2442 2337 2451 2376 2395 2381 2386 2482 2491 2532 2517 2476 2367 2510 2665 2548 2616 2632 2744 2792 2787 2885 2939 3038 3065 3012 2987 3084 3117 2982 3079 3216 3120 3080 3162 3101 3172 3126 3187 3201 3224 3297 3248 3348 3484 3452 3314 3488 3429 3442 3498 3650 3628 3619 3622 3646 3573 3529 3447 3456 3461 3348 3372 3240 3341 3262 3152 3266 3022 3030 2873 2817 2958 2714 2837 2700 2790 2764 2663 2659 2676 2512 2582 2641 2582 2560 2506 2656 2611 2531 2654 2698 2664 2627 2657 2656 2664 2717 2726 2802 2722 2654 2728 2639 2661 2689 2733 2710 2721 2690 2760 2637 2665 2725 2785 2660 2705 2743 2735 2827 2837 2810 2839 2793 2836 2877 2792 2832 2750 2782 2858 2848 2901 2835 2830 2807 2907 2893 2892 2983 2837 2968 2865 2914 2956 2957 2843 2959 2941 3061 2968 2955 3102 2963 3091 3072 3061 3068 3138 3047 3120 3147 3058 3150 3072 3232 3211 3155 3253 3218 3205 3389 3210 3139 3307 3272 3321 3416 3397 3344 3471 3400 3461 3504 3412 3471 3464 3382 3395 3402 3549 3542 3496 3521 3542 3644 3598 3652 3681 3627 3621 3652 3721 3724 3786 3717 3736 3742 3874 3651 3846 3968 3879 3890 3833 3800 4002 3953 3893 3872 3939 3928 3930 3894 4025 4049 4039 4018 4031 4061 4094 4271 4116 4194 4225 4136 4369 4230 4166 4353 4447 4294 4330 4441 4450 4496 4543 4428 4588 4614 4675 4548 4618 4788 4802 4870 4752 4849 4862 4896 4924 4908 5230 5234 5043 5213 5239 5137 5430 5236 5492 5471 5332 5483 5512 5495 5739 5830 5638 5859 5862 5858 5972 5963 6195 6146 6111 6132 6356 6351 6328 6474 6492 6684 6640 6666 6662 6886 6931 6929 6986 7194 7077 7298 7348 7255 7580 7540 7606 7697 7789 7922 7885 8142 8223 8357 8393 8353 8624 8543 8622 8830 8854 9057 9052 9197 9285 9497 9652 9835 9713 9770 10119 10112 10357 10384 10510 10629 10805 10945 10968 11202 11296 11679 11576 11652 11668 11917 11974 12003 12388 12492 12587 12731 12577 12884 12758 12879 12928 13335 13403 13275 13737 13450 13472 13857 13595 13812 13788 13961 13931 13987 14080 14139 13911 14000 14053 13754 13818 13789 13684 13573 13667 13704 13684 13524 13239 13179 13207 13271 12945 12987 12925 12803 12676 12494 12307 12294 12113 12002 11836 11504 11407 11400 11362 10952 10706 10835 10733 10688 10511 10838 11226 11780 12721 13433 14332 15743 16691 18580 19683 21335 23211 25146 26566 28421 29608 31171 32483 32937 34655 34477 35341 35320 35444 35100 35089 34833 34355 34099 33525 32856 33030 32238 32501 32073 31841 31615 31634 31787 31632 31326 31479 30771 30784 30149 30150 29270 28606 28039 26960 26114 24973 24364 23511 22354 21306 20312 18928 17616 16099 15064 14154 12752 11637 10489 9493 8609 7850 7201 6773 6003 5618 5276 5319 5003 4866 4924 4589 4763 4629 4607 4606 4418 4537 4364 4386 4285 4202 4158 4213 4193 4018 3976 4137 4049 4117 4008 4004 3841 3853 4000 3907 3796 3808 3993 3849 3715 3847 3770 3705 3805 3751 3644 3749 3717 3646 3713 3588 3610 3484 3466 3493 3467 3455 3420 3409 3457 3445 3383 3299 3400 3351 3330 3347 3269 3342 3245 3239 3220 3221 3309 3163 3098 3110 3233 3079 3126 3128 3057 3051 3011 3018 3010 3151 3035 3047 2946 2984 2951 2970 3048 2919 3013 2909 2849 2954 2839 2863 2774 2807 2963 2841 2857 2843 2784 2779 2847 2675 2753 2775 2793 2749 2805 2747 2713 2749 2703 2613 2709 2832 2834 2838 2763 2767 2764 2653 2719 2679 2634 2634 2692 2722 2594 2601 2663 2601 2645 2581 2534 2625 2615 2613 2557 2444 2580 2560 2576 2459 2516 2613 2599 2515 2575 2635 2505 2524 2480 2482 2476 2512 2441 2409 2498 2397 2455 2422 2508 2498 2420 2423 2479 2471 2378 2462 2386 2477 2371 2499 2386 2475 2380 2390 2512 2352 2396 2279 2353 2380 2389 2423 2321 2388 2394 2263 2310 2315 2313 2277 2398 2334 2263 2292 2376 2398 2335 2230 2256 2320 2315 2267 2235 2272 2283 2298 2267 2274 2286 2180 2250 2298 2183 2224 2243 2208 2286 2333 2345 2333 2264 2369 2270 2379 2343 2300 2391 2286 2373 2458 2383 2459 2489 2360 2337 2556 2460 2392 2426 2449 2432 2471 2449 2326 2466 2326 2426 2377 2491 2502 2513 2478 2483 2504 2435 2483 2402 2511 2405 2426 2378 2342 2393 2438 2387 2353 2381 2358 2360 2214 2283 2264 2296 2330 2220 2106 2201 2128 2163 2127 2163 2035 2180 2073 2101 2123 2122 2106 2067 2056 2118 2067 2076 2013 1987 2016 2022 2067 2056 2025 2001 2044 2068 2084 2004 2054 2052 2040 1974 1944 1994 1928 2034 2015 2076 1991 2065 1977 1994 2006 2040 1959 1968 2026 1953 1973 2094 2013 1986 1986 1988 2028 2002 2059 1994 1971 1877 2011 2034 2028 2013 1991 1934 2037 2048 1907 1950 2012 1978 1979 1987 2059 1955 1981 1941 1984 1850 1979 1912 1978 1937 1940 1997 1956 1914 1958 1880 1944 1956 2051 1863 1894 1919 1920 1952 1914 1945 2004 1924 2004 1948 1929 1945 1916 1882 1897 1983 1899 1994 1868 1915 1987 1762 1906 1905 1886 1918 1972 1899 1947 1960 1921 1902 1845 1879 1920 1935 1908 1913 1901 1941 1950 1880 1943 1850 1904 1954 1879 1971 1893 1905 1911 1853 1905 1922 1894 1789 1893 1858 1937 1949 1826 1922 1927 1886 1843 1953 2001 2014 1844 1878 1873 1881 1940 1930 1948 1956 1966 1927 2055 2035 2009 1969 2023 1878 1999 1947 2013 1958 1996 1954 1943 2001 2104 2020 1978 1946 1932 1898 1976 2000 2021 2071 1944 2124 2126 2139 2035 2194 2107 2185 2159 2139 2314 2247 2234 2218 2325 2157 2151 2120 1975 2092 1987 2075 1928 1819 1998 1915 1791 1914 1806 1921 1903 1758 1860 1806 1944 1937 1794 1811 1813 1826 1811 1891 1762 1909 1924 1880 1840 1802 1797 1806 1863 1847 1848 1757 1763 1842 1757 1776 1820 1811 1756 1827 1879 1726 1848 1877 1885 1819 1766 1846 1855 1898 1898 1806 1786 1830 1745 1790 1908 1809 1902 1745 1911 1897 1834 1910 1754 1824 1827 1817 1911 1937 1814 1808 1813 1765 1767 1855 1841 1838 1729 1874 1794 1790 1878 1800 1778 1720 1831 1868 1733 1901 1743 1780 1739 1815 1912 1863 1821 1816 1773 1823 1750 1872 1899 1854 1802 1748 1821 1782 1876 1785 1704 1862 1782 1806 1861 1862 1876 1827 1831 1876 1920 1852 1805 1839 1939 1862 1888 1900 1750 1860 1881 1775 1901 1849 1853 1914 1803 1863 1901 1834 1796 1827 1913 1870 1818 1827 1841 1821 1800 1814 1851 1806 1940 1927 1855 1907 1813 1793 1850 1904 1799 1756 1771 1919 1827 1851 1712 1773 1927 1724 1805 1797 1725 1745 1795 1691 1822 1811 1829 1830 1709 1815 1828 1731 1784 1753 1853 1703 1773 1814 1849 1746 1817 1863 1695 1870 1795 1837 1832 1792 1791 1766 1839 1834 1753 1878 1895 1645 1839 1796 1799 1851 1755 1889 1786 1817 1824 1795 1740 1752 1728 1861 1825 1860 1888 1730 1798 1836 1691 1738 1787 1890 1790 1793 1745 1834 1844 1746 1659 1802 1859 1840 1891 1820 1832 1812 1795 1747 1779 1810 1895 1893 1856 1821 1869 1927 1780 1914 1823 1940 1900 1833 1830 1882 1832 1866 1950 1881 1793 1824 1860 1793 1777 1848 1843 1838 1883 1896 1803 1909 1938 1859 1836 1767 1866 1882 1840 1925 1849 1873 1855 1820 1762 1859 1772 1771 1776 1781 1883 1865 1712 1868 1869 1790 1778 1816 1807 1847 1859 1880 1817 1758 1620 1772 1831 1809 1816 1786 1870 1896 1755 1857 1725 1883 1841 1781 1848 1810 1795 1783 1902 1800 1800 1812 1932 1792 1800 1931 1817 1869 1734 1850 1817 1675 1719 1822 1856 1855 1746 1881 1802 1921 1912 1841 1841 1745 1784 1861 1831 1886 1941 1862 1807 1938 1787 1772 1891 1800 1817 1813 1868 1855 1797 1928 1756 1896 1779 1858 1754 1842 1818 1873 1809 1747 1762 1928 1772 1848 1838 1826 1854 1810 1754 1752 1916 1786 1879 1851 1850 1845 1852 1826 1837 1863 1848 1828 1791 1926 1835 1855 1964 1894 1849 1793 1881 1846 1779 1893 1836 1853 1919 1920 1930 1798 1911 1804 1901 1897 1925 1856 1872 2025 1878 1834 1922 1905 1897 1974 1984 2039 1991 2076 2014 1985 2032 2098 2150 2141 2125 2094 2095 2222 2129 2154 2120 2159 2191 2128 2232 2107 2165 2154 2104 2259 2272 2116 2170 2222 2246 2354 2267 2337 2390 2359 2221 2335 2341 2235 2253 2249 2302 2252 2333 2200 2270 2268 2067 2083 2179 2134 2029 2085 2045 1953 1996 1996 1859 1999 1930 1863 1847 1898 1913 1937 1855 1800 1912 1846 1917 1848 1915 1900 1948 1989 1995 1871 1855 1949 1979 1950 1903 1893 1921 1810 1877 1911 1940 1928 1918 1750 1996 1888 1940 2020 1879 1879 2007 1844 1924 1761 1827 1787 1832 1884 1855 1839 1833 1913 1934 1941 1972 1934 1869 1899 1860 1905 1867 1895 1903 1860 1905 1937 1894 1939 1915 1827 1893 1896 1955 1928 1901 1951 1898 1968 1943 1982 2012 2011 2124 2059 2061 2165 2217 2112 2201 2297 2288 2264 2285 2240 2293 2345 2294 2280 2286 2279 2305 2206 2328 2313 2342 2320 2341 2384 2385 2398 2389 2314 2371 2354 2482 2383 2489 2615 2424 2449 2449 2529 2355 2336 2370 2446 2406 2314 2455 2304 2243 2305 2259 2345 2274 2174 2176 2095 2036 2066 2099 2090 2015 1987 1999 2009 2035 1976 1942 1998 1895 1934 2005 1856 1930 1940 1978 2039 2034 1818 1872 1893 1944 1957 1957 1958 1960 2097 2016 1922 1966 2027 2003 2038 1925 1931 2027 1809 2079 1936 1984 1973 2047 1918 2045 2037 2136 2031 2048 2070 2084 2012 2025 2055 2049 2141 2098 2058 2103 2118 2114 2049 2025 2050 2082 2079 2092 2104 2074 2054 2142 2100 2056 2093 2158 2140 2117 2185 2103 2133 2105 2193 2064 2091 2248 2075 2186 2140 2082 2084 2137 2047 2082 2066 2092 2131 2095 2084 2019 2004 2068 2106 2059 2022 1964 2001 2011 1870 2082 1951 2047 1925 1981 2011 1955 2028 2006 2044 1993 2066 2051 2051 2089 2037 2051 2031 2037 2041 2066 1980 2053 2097 2089 1994 2000 1997 1973 1995 2025 2012 2015 1994 2087 2114 2035 2085 2023 2013 2111 2025 2041 2010 2062 2137 2060 2102 1981 2042 2028 2162 2110 2017 2051 1988 1984 1948 2045 2042 2092 2027 1946 2026 2062 2165 2001 1965 2069 2103 2035 1975 2019 2062 2024 2126 2118 2115 2092 2073 1988 2163 2072 2027 2081 2042 2023 2045 2070 2181 2111 2168 1995 2037 1999 2124 2098 2054 2141 2067 2073 2042 2078 2015 2047 2133 2024 2186 2046 2142 2160 2128 2085 2143 2107 2067 2169 2122 2089 2192 2114 2156 2063 2144 2109 2105 2094 2090 2224 2034 2219 2191 2076 2094 2205 2138 2124 2083 2241 2074 2133 2189 2218 2165 2081 2139 2091 2115 2072 2149 2089 2113 2086 2097 2145 2127 2183 2044 2151 2189 2109 2207 2133 2104 2103 2090 2091 2231 2122 2150 2182 2145 2199 2174 2062 2132 2140 2135 2234 2120 2133 2170 2158 2064 2118 2105 2177 2161 2212 2090 2180 2177 2095 2181 2029 2149 2126 2192 2211 2119 2163 2144 2258 2120 2195 2116 2197 2175 2176 2203 2045 2120 2175 2156 2188 2109 2134 2141 2090 2191 2197 2096 2153 2276 2069 2080 2200 2183 2111 2188 2188 2051 2216 2184 2298 2125 2205 2167 2146 2186 2289 2125 2169 2188 2140 2255 2080 2219 2115 2243 2136 2159 2125 2237 2185 2144 2175 2141 2243 2137 2287 2168 2286 2258 2226 2174 2161 2212 2098 2127 2176 2178 2136 2248 2122 2174 2251 2295 2268 2203 2216 2181 2217 2205 2206 2256 2277 2207 2281 2241 2229 2200 2176 2179 2282 2099 2117 2084 2213 2191 2186 2289 2257 2249 2197 2243 2183 2290 2192 2225 2255 2254 2260 2208 2274 2252 2277 2263 2230 2292 2269 2232 2164 2238 2296 2219 2313 2208 2314 2319 2281 2281 2243 2216 2309 2243 2246 2327 2377 2345 2278 2213 2252 2360 2310 2228 2324 2278 2309 2350 2286 2271 2337 2365 2207 2277 2203 2366 2214 2421 2317 2264 2321 2303 2365 2353 2289 2217 2290 2257 2401 2316 2351 2273 2300 2366 2376 2345 2378 2301 2309 2295 2419 2297 2322 2308 2395 2304 2352 2361 2367 2298 2356 2311 2260 2312 2327 2344 2318 2238 2286 2308 2369 2402 2358 2368 2305 2365 2438 2301 2422 2381 2444 2380 2276 2228 2413 2251 2333 2425 2376 2281 2338 2271 2293 2413 2333 2417 2367 2365 2329 2387 2400 2262 2393 2412 2433 2456 2319 2311 2406 2310 2426 2282 2325 2492 2329 2288 2330 2407 2350 2469 2454 2382 2298 2438 2397 2439 2367 2479 2501 2336 2476 2384 2363 2429 2340 2456 2372 2310 2305 2343 2392 2317 2453 2452 2388 2463 2465 2444 2478 2428 2433 2394 2472 2351 2369 2466 2519 2489 2412 2433 2503 2458 2279 2451 2452 2476 2381 2480 2391 2512 2401 2517 2456 2483 2369 2509 2464 2411 2449 2516 2534 2487 2565 2496 2440 2517 2511 2359 2521 2364 2503 2454 2546 2506 2447 2482 2528 2508 2431 2562 2460 2447 2524 2544 2521 2412 2484 2433 2465 2447 2509 2417 2502 2482 2472 2531 2526 2524 2497 2488 2528 2446 2466 2436 2580 2374 2581 2491 2486 2571 2433 2498 2546 2559 2576 2546 2618 2678 2587 2525 2601 2531 2501 2462 2535 2562 2564 2607 2566 2419 2457 2605 2651 2514 2543 2570 2536 2622 2529 2618 2627 2551 2550 2567 2663 2557 2624 2667 2552 2521 2549 2516 2702 2585 2548 2553 2515 2518 2539 2550 2688 2635 2670 2739 2589 2609 2635 2542 2649 2664 2589 2803 2601 2658 2775 2612 2708 2744 2702 2832 2877 3003 3079 3353 3540 3423 3636 3847 4115 4359 4564 4854 4971 5102 5296 5468 5528 5661 5915 5830 5883 5989 5948 5980 6071 6132 6032 6116 6314 6246 6197 6015 6256 6246 6307 6326 6351 6461 6614 6459 6462 6401</counts>
			</dataPoints>
		</scan>
	</xrdMeasurement>
</xrdMeasurements>