File: Data Files/Full/MSS p (21-129, 25w)_01.xrdml
<?xml version="1.0"?>
<xrdMeasurements xmlns="http://www.xrdml.com/XRDMeasurement/2.2" xmlns:xsi="http://www.w3.org/2001/XMLSchema-instance" xsi:schemaLocation="http://www.xrdml.com/XRDMeasurement/2.2 http://www.xrdml.com/XRDMeasurement/2.2/XRDMeasurement.xsd" status="Completed" recordIdentifier="{1104763B-3FE7-4933-8D44-BF5CD11257E1}">
	<comment>
		<entry/>
	</comment>
	<sample type="To be analyzed">
		<id>p</id>
		<name></name>
		<preparedBy></preparedBy>
	</sample>
	<xrdMeasurement measurementType="Scan" status="Completed" sampleMode="Reflection">
		<usedWavelength intended="K-Alpha 1">
			<kAlpha1 unit="Angstrom">1.5405980</kAlpha1>
			<kAlpha2 unit="Angstrom">1.5444260</kAlpha2>
			<kBeta unit="Angstrom">1.3922500</kBeta>
			<ratioKAlpha2KAlpha1>0.5000</ratioKAlpha2KAlpha1>
		</usedWavelength>
		<incidentBeamPath>
			<radius unit="mm">145.00</radius>
			<xRayTube id="1010048" name="Empyrean Cu LFF HR (9430 033 7310x) DK437964">
				<tension unit="kV">40.0</tension>
				<current unit="mA">15.0</current>
				<anodeMaterial>Cu</anodeMaterial>
				<focus type="Line">
					<length unit="mm">12.0</length>
					<width unit="mm">0.4</width>
					<takeOffAngle unit="deg">6.0</takeOffAngle>
				</focus>
			</xRayTube>
			<filter id="20010004" name="Beta-filter Nickel">
				<material>Ni</material>
				<thickness unit="mm">0.020</thickness>
			</filter>
			<sollerSlit id="21010002" name="Soller slits 0.04 rad.">
				<opening unit="rad">0.0400</opening>
			</sollerSlit>
			<mask id="22031000" name="Fixed mask 13 mm">
				<width unit="mm">9.00</width>
			</mask>
			<divergenceSlit id="22120001" name="Divergence slit 1°" xsi:type="fixedDivergenceSlitType">
				<distanceToSample unit="mm">50.00</distanceToSample>
				<height unit="mm">1.52</height>
			</divergenceSlit>
		</incidentBeamPath>
		<diffractedBeamPath>
			<radius unit="mm">145.00</radius>
			<parallelPlateCollimator id="25020001" name="Parallel plate collimator 0.28°">
				<opening unit="deg">0.28</opening>
			</parallelPlateCollimator>
			<detector id="7010020" name="PIXcel3D-Medipix3 1x1 detector" xsi:type="areaDetectorType">
				<phd unit="keV">
					<lowerLevel>4.0</lowerLevel>
					<upperLevel>11.3</upperLevel>
				</phd>
				<mode>Receiving slit</mode>
				<activeChannelsEquatorial>255</activeChannelsEquatorial>
				<activeChannelsAxial>255</activeChannelsAxial>
				<pitchEquatorial unit="mm">0.05500</pitchEquatorial>
				<pitchAxial unit="mm">0.05500</pitchAxial>
				<readOutPeriod unit="seconds">0.050</readOutPeriod>
			</detector>
		</diffractedBeamPath>
		<scan appendNumber="0" mode="Continuous" scanAxis="2Theta" status="Completed">
			<header>
				<startTimeStamp>2025-06-30T14:06:26-08:00</startTimeStamp>
				<endTimeStamp>2025-07-01T02:06:31-08:00</endTimeStamp>
				<author>
					<name>Instrument</name>
				</author>
				<source>
					<applicationSoftware version="1.6 (94)">PANalytical Aeris Instrument Suite</applicationSoftware>
					<instrumentControlSoftware version="3.0.0 20211014">AERIS</instrumentControlSoftware>
					<instrumentID>2855484</instrumentID>
				</source>
			</header>
			<dataPoints>
				<positions axis="2Theta" unit="deg">
					<startPosition>21.005</startPosition>
					<endPosition>128.995</endPosition>
				</positions>
				<positions axis="Omega" unit="deg">
					<commonPosition>25.000</commonPosition>
				</positions>
				<commonCountingTime unit="seconds">3.520</commonCountingTime>
				<counts 1062 1047 1001 1015 984 1037 965 1007 1003 1025 1026 997 1031 1004 991 1012 1004 990 1004 1046 1030 979 996 1038 943 1014 1024 977 986 962 999 991 981 1011 1081 1028 1007 974 1011 986 997 977 938 1007 1001 1035 988 1026 1009 995 1061 965 1030 998 1053 1015 1023 1001 976 983 952 984 1024 987 979 970 1021 974 1035 908 1006 970 991 947 1003 990 952 942 1051 1027 998 961 960 988 1002 995 970 1050 898 1007 936 953 982 964 927 980 1004 981 1028 948 979 946 922 979 1013 931 979 958 972 1027 938 981 971 949 993 1043 1006 956 982 930 973 994 973 872 984 1042 993 914 968 959 974 971 949 1022 977 984 959 991 910 955 959 918 929 921 925 934 921 1000 974 994 959 993 926 943 1021 986 976 896 995 960 970 968 946 959 1003 1003 1017 1041 1031 1096 1022 1099 1107 1093 1135 1102 1133 1178 1245 1282 1224 1220 1379 1478 1374 1344 1500 1607 1589 1598 1762 1808 1738 1802 1801 1822 1766 1770 1906 1861 1966 1903 1890 1895 2032 1930 1958 1940 1947 1948 2131 1933 2050 1994 2031 2087 2007 2118 2084 2097 2073 2081 2107 2044 2176 2054 2077 2028 2040 2121 2132 2165 2114 2080 2177 2183 2211 2110 2133 2170 2226 2105 2082 2171 2212 2111 2176 2258 2178 2144 2182 2169 2289 2212 2205 2187 2282 2304 2283 2272 2217 2231 2306 2197 2223 2289 2197 2193 2226 2286 2207 2276 2252 2285 2320 2342 2391 2357 2283 2327 2378 2465 2399 2431 2465 2476 2392 2428 2373 2452 2514 2429 2485 2452 2493 2483 2444 2530 2402 2385 2382 2414 2507 2325 2227 2266 2309 2239 2202 2154 2101 2205 2062 2076 2034 1957 2025 2049 2070 2013 1975 1933 2042 1957 1991 2037 1945 1937 2036 2021 2010 1952 1944 1909 1964 2008 1939 2036 1964 1978 1909 1999 2045 1992 2178 2109 2140 2060 2118 2131 2034 1994 2012 1891 1992 1854 2009 1942 1962 1931 1917 1932 1888 1968 1917 1961 1945 2025 1954 1844 1881 1839 1914 1914 1856 1941 1920 1923 1893 1812 1980 1908 2016 1845 1967 1877 1761 1865 1873 1824 1889 1929 1914 1883 1826 1908 1855 1888 1843 1863 1834 1927 1864 1815 1786 1845 1843 1764 1815 1858 1937 1906 1867 1849 1835 1940 1732 1858 1724 1877 1800 1751 1841 1831 1820 1797 1802 1776 1766 1822 1778 1814 1792 1790 1780 1784 1859 1752 1809 1890 1795 1822 1776 1749 1874 1774 1868 1774 1832 1806 1838 1776 1839 1761 1801 1806 1799 1860 1769 1776 1719 1674 1786 1760 1741 1774 1864 1794 1887 1783 1735 1801 1799 1862 1797 1609 1794 1827 1808 1817 1794 1800 1828 1738 1668 1838 1781 1857 1791 1692 1765 1650 1741 1807 1845 1780 1868 1762 1892 1632 1766 1835 1858 1777 1902 1759 1738 1769 1758 1771 1786 1830 1848 1849 1840 1971 1897 1801 1834 1870 1811 1884 1831 1816 1792 1820 1848 1889 1757 1828 1933 1809 1881 1908 1883 1819 1892 1857 1847 1923 1913 1861 2016 1896 1872 1811 1991 1861 1828 1884 1865 1862 1815 1858 1836 1866 1824 1803 1813 1702 1739 1769 1828 1704 1774 1804 1799 1809 1837 1798 1759 1840 1771 1735 1798 1736 1765 1795 1827 1848 1738 1835 1795 1865 1717 1755 1803 1789 1891 1789 1699 1815 1834 1773 1737 1801 1799 1842 1784 1792 1826 1801 1918 1697 1786 1649 1852 1826 1744 1787 1823 1789 1743 1784 1629 1682 1798 1799 1827 1800 1906 1863 1740 1868 1783 1735 1704 1760 1778 1743 1771 1831 1659 1845 1859 1834 1659 1753 1731 1741 1847 1842 1807 1778 1666 1737 1882 1739 1772 1822 1735 1734 1761 1752 1790 1805 1728 1834 1673 1734 1838 1721 1752 1844 1758 1793 1730 1684 1777 1574 1817 1715 1793 1850 1717 1788 1807 1737 1801 1741 1811 1810 1675 1748 1711 1679 1705 1752 1742 1786 1814 1652 1736 1652 1794 1814 1806 1686 1741 1659 1705 1803 1824 1822 1738 1705 1957 1697 1852 1843 1800 1733 1728 1753 1706 1605 1671 1714 1670 1771 1670 1736 1669 1766 1741 1731 1709 1719 1752 1714 1687 1751 1678 1750 1739 1626 1834 1743 1730 1630 1736 1733 1708 1766 1696 1678 1795 1530 1757 1676 1608 1755 1741 1662 1646 1711 1631 1704 1755 1639 1713 1756 1708 1713 1810 1698 1807 1674 1663 1699 1612 1770 1584 1707 1719 1695 1651 1655 1644 1588 1775 1761 1801 1546 1693 1704 1637 1784 1799 1727 1703 1691 1672 1881 1758 1739 1764 1680 1664 1737 1734 1593 1697 1634 1616 1712 1664 1705 1560 1748 1630 1611 1705 1675 1692 1837 1680 1697 1741 1651 1635 1752 1681 1642 1786 1748 1575 1718 1726 1771 1701 1676 1779 1745 1583 1624 1617 1666 1617 1823 1677 1609 1668 1670 1503 1694 1581 1509 1689 1810 1736 1731 1700 1585 1612 1661 1736 1671 1739 1559 1762 1713 1547 1651 1587 1551 1676 1542 1614 1687 1628 1862 1789 1760 1661 1666 1656 1656 1717 1716 1740 1642 1581 1602 1653 1678 1658 1628 1542 1670 1599 1822 1690 1677 1660 1661 1753 1655 1773 1591 1592 1631 1693 1643 1600 1786 1602 1776 1719 1732 1671 1678 1619 1603 1695 1726 1758 1706 1649 1620 1716 1667 1687 1671 1626 1704 1689 1686 1682 1681 1585 1801 1647 1719 1680 1615 1609 1758 1562 1685 1762 1536 1656 1685 1656 1777 1525 1651 1611 1787 1719 1599 1627 1670 1622 1657 1680 1735 1686 1732 1544 1572 1671 1676 1646 1794 1608 1499 1569 1713 1822 1713 1668 1624 1626 1678 1736 1825 1639 1750 1669 1672 1585 1780 1693 1584 1618 1730 1668 1675 1693 1693 1689 1633 1587 1607 1706 1709 1826 1511 1705 1749 1591 1766 1739 1624 1703 1682 1722 1679 1619 1611 1548 1719 1676 1737 1666 1764 1725 1555 1650 1756 1688 1642 1645 1651 1739 1648 1596 1681 1631 1750 1616 1611 1628 1579 1705 1736 1743 1716 1678 1759 1560 1540 1759 1655 1646 1633 1659 1748 1759 1594 1653 1683 1551 1720 1731 1593 1526 1754 1684 1619 1688 1547 1749 1548 1652 1555 1710 1660 1635 1647 1640 1687 1617 1735 1678 1789 1713 1608 1662 1521 1713 1695 1740 1734 1576 1679 1715 1651 1541 1564 1632 1694 1726 1629 1687 1670 1749 1651 1716 1678 1626 1691 1739 1619 1663 1607 1738 1732 1692 1744 1701 1697 1605 1659 1631 1605 1713 1724 1720 1799 1714 1602 1746 1622 1799 1613 1635 1688 1784 1708 1635 1687 1661 1730 1780 1748 1749 1688 1703 1675 1513 1749 1793 1655 1694 1778 1772 1664 1609 1637 1772 1661 1809 1597 1638 1672 1740 1757 1754 1720 1733 1620 1763 1689 1607 1539 1647 1748 1560 1689 1644 1716 1545 1778 1716 1669 1743 1721 1837 1660 1648 1661 1530 1614 1571 1707 1779 1734 1726 1674 1704 1805 1669 1746 1758 1764 1634 1571 1725 1682 1667 1722 1643 1748 1581 1710 1686 1714 1708 1630 1610 1612 1642 1717 1753 1812 1864 1680 1730 1750 1731 1573 1620 1654 1658 1675 1833 1798 1809 1756 1814 1781 1645 1775 1622 1647 1731 1840 1676 1802 1673 1726 1570 1783 1639 1758 1720 1811 1657 1736 1664 1760 1645 1590 1648 1726 1618 1552 1595 1681 1808 1772 1737 1578 1642 1741 1743 1647 1683 1699 1621 1579 1666 1625 1805 1666 1768 1850 1721 1697 1715 1698 1776 1651 1606 1663 1810 1806 1749 1733 1801 1731 1701 1721 1677 1748 1666 1814 1757 1715 1733 1714 1769 1687 1655 1777 1744 1799 1682 1745 1804 1718 1898 1846 1763 1670 1710 1700 1684 1811 1812 1724 1690 1695 1732 1789 1793 1712 1631 1766 1758 1811 1668 1661 1849 1778 1765 1857 1792 1796 1726 1724 1629 1595 1808 1802 1800 1738 1788 1753 1702 1672 1744 1760 1786 1729 1856 1836 1689 1667 1852 1766 1694 1889 1707 1785 1764 1738 1730 1686 1807 1818 1850 1839 1853 1752 1883 1855 1823 1814 1828 1935 1856 2010 1961 2059 2063 2331 2469 2399 2542 2540 2732 2782 3008 3133 3403 3587 3826 3938 4216 4333 4450 4825 4766 5051 4945 5008 5074 5249 5411 5541 5670 5782 5841 5908 6072 6073 6179 6397 6370 6604 6472 6794 6734 6789 6730 6997 6946 7014 7000 7014 7007 7054 6702 6933 6677 6252 6168 5954 5812 5348 5229 4867 4560 4371 3868 3607 3382 3372 2869 2550 2411 2339 2226 1965 1924 1941 1924 1913 1877 1923 1876 1868 1848 1863 1872 1885 1761 1784 1788 1840 1865 1796 1917 1769 1837 1797 1733 1814 1765 1653 1667 1756 1860 1736 1790 1723 1648 1831 1670 1735 1813 1809 1771 1736 1876 1695 1819 1581 1830 1837 1820 1773 1659 1775 1806 1786 1791 1843 1808 1650 1863 1787 1737 1728 1753 1638 1787 1785 1739 1753 1768 1748 1690 1756 1587 1715 1629 1634 1745 1801 1667 1776 1799 1637 1851 1680 1828 1828 1722 1801 1699 1724 1759 1690 1667 1569 1726 1716 1637 1703 1661 1816 1715 1687 1698 1722 1694 1652 1652 1658 1784 1759 1736 1718 1705 1679 1705 1675 1653 1608 1778 1669 1786 1700 1674 1685 1747 1670 1611 1497 1674 1660 1797 1746 1644 1806 1469 1549 1729 1681 1740 1561 1687 1676 1708 1623 1670 1710 1615 1545 1774 1693 1728 1530 1711 1658 1677 1695 1543 1803 1733 1616 1731 1701 1656 1724 1724 1718 1493 1649 1552 1587 1563 1614 1696 1650 1684 1508 1611 1689 1636 1460 1744 1552 1561 1634 1737 1659 1705 1617 1690 1734 1700 1570 1682 1596 1679 1627 1576 1687 1730 1591 1639 1647 1630 1648 1650 1615 1620 1612 1594 1656 1749 1662 1616 1711 1575 1694 1769 1627 1689 1589 1542 1638 1675 1659 1764 1590 1608 1667 1718 1693 1540 1660 1718 1628 1483 1748 1668 1640 1642 1683 1631 1672 1751 1543 1683 1602 1728 1630 1690 1655 1761 1790 1647 1702 1704 1690 1628 1733 1663 1664 1677 1705 1727 1719 1829 1604 1648 1633 1716 1579 1748 1665 1618 1768 1576 1707 1673 1620 1627 1766 1658 1753 1671 1593 1719 1644 1833 1715 1693 1666 1759 1696 1773 1633 1657 1645 1742 1685 1757 1810 1717 1601 1670 1762 1705 1704 1573 1649 1637 1834 1734 1781 1763 1743 1657 1725 1740 1713 1701 1788 1706 1626 1765 1815 1742 1737 1791 1709 1662 1653 1706 1637 1679 1805 1827 1824 1726 1814 1782 1718 1803 1828 1710 1700 1739 1608 1765 1723 1767 1647 1844 1772 1747 1775 1648 1693 1697 1676 1716 1685 1806 1841 1621 1724 1752 1745 1779 1804 1708 1634 1846 1735 1935 1796 1787 1810 1787 1706 1818 1886 1877 1814 1651 1835 1707 1837 1798 1862 1727 1689 1812 1764 1800 1821 1868 1745 1749 1810 1885 1891 1828 1866 1744 1729 1802 1844 1869 1793 1928 1811 1812 1763 1705 1808 1845 1826 1817 1756 1840 1824 1836 1791 1796 1781 1888 1809 1874 1874 1792 1884 1831 1906 1911 1797 1915 1824 1872 1838 1874 1913 1854 1863 1818 1769 1843 1834 1752 1858 1893 1955 1774 1907 1808 1949 1850 1848 1944 1959 1924 1910 1898 1900 1884 1946 1884 1875 1883 1859 1888 1851 1888 1873 1927 1986 1898 1913 2005 1977 1956 1951 1966 1973 1983 2006 1859 1944 1965 1989 2003 1946 2036 1961 1965 1912 1944 1965 2041 1959 1996 1999 2025 1917 2025 1963 1935 2071 2057 2027 2048 2029 2044 2003 2008 2038 2081 1950 2039 2101 1991 1964 2057 1984 2052 2023 2074 2033 2104 2111 2085 2126 2032 2123 2026 2127 2090 2070 2090 2019 2144 2042 2083 2137 2043 2169 2083 2045 2028 2166 2037 2151 2127 2129 2113 2191 2104 2134 2144 2108 2168 2132 2120 2244 2115 2069 2194 2195 2087 2168 2140 2133 2229 2185 2255 2127 2280 2211 2161 2122 2163 2187 2218 2189 2172 2225 2272 2191 2134 2135 2265 2233 2256 2272 2278 2161 2346 2222 2227 2219 2223 2262 2290 2279 2337 2347 2287 2266 2279 2316 2199 2274 2278 2257 2255 2197 2302 2335 2267 2271 2290 2325 2319 2235 2207 2327 2320 2285 2253 2256 2258 2301 2327 2268 2445 2205 2208 2289 2231 2266 2353 2282 2338 2248 2305 2247 2317 2197 2257 2276 2254 2239 2249 2188 2275 2249 2248 2227 2278 2320 2300 2295 2217 2293 2244 2337 2304 2234 2353 2303 2293 2399 2381 2304 2283 2416 2349 2419 2358 2369 2322 2425 2466 2484 2434 2402 2491 2489 2510 2375 2403 2460 2494 2408 2391 2431 2384 2331 2430 2392 2469 2425 2446 2479 2427 2344 2419 2532 2359 2439 2434 2416 2399 2466 2474 2388 2457 2403 2376 2375 2341 2418 2267 2367 2331 2367 2238 2236 2263 2253 2194 2239 2225 2103 2215 2162 2153 2076 2174 2117 2145 2105 2180 2139 2165 2239 2137 2249 2209 2136 2162 2148 2141 2151 2140 2156 2135 2191 2086 2100 2068 2104 2215 2159 2050 2072 2117 2197 2103 2087 2114 2172 2086 2047 2180 2069 2108 2069 2103 2084 2013 1942 2077 2097 2104 2117 2078 1998 2072 2026 2137 2041 2025 2065 2072 1996 1980 2034 1983 2083 2054 2030 2015 2089 1982 1962 1996 2033 2026 1990 2030 2094 1975 2000 2018 2026 2003 2143 2048 2039 2038 2101 1981 2024 2097 2093 1925 2163 2009 2019 2081 2211 2096 2221 2193 2164 2262 2374 2390 2417 2482 2524 2469 2494 2507 2605 2561 2639 2728 2659 2761 2675 2830 2845 2778 2795 2832 2789 2821 2861 2889 2796 2765 2905 2953 2853 2872 2869 2919 2888 2834 2937 2860 2906 2845 2821 2801 2709 2705 2640 2683 2519 2648 2499 2449 2351 2326 2403 2125 2193 2057 1958 2066 1973 1829 1954 1940 1933 1805 1961 1881 1857 1876 1940 1871 1810 1809 1884 1773 1879 1817 1812 1769 1859 1784 1795 1752 1763 1777 1791 1884 1745 1800 1780 1729 1792 1772 1876 1821 1819 1904 1753 1730 1829 1758 1774 1792 1744 1712 1821 1851 1721 1713 1800 1826 1814 1735 1727 1725 1787 1735 1744 1808 1855 1816 1754 1669 1581 1646 1697 1760 1819 1672 1666 1760 1784 1792 1817 1765 1635 1681 1755 1692 1772 1726 1790 1780 1759 1751 1688 1781 1656 1654 1726 1822 1837 1731 1798 1711 1748 1710 1695 1634 1751 1768 1684 1703 1766 1733 1653 1782 1758 1735 1715 1744 1690 1596 1665 1729 1692 1639 1671 1707 1710 1670 1684 1661 1589 1648 1805 1715 1583 1670 1715 1623 1583 1706 1696 1592 1648 1568 1624 1642 1479 1680 1626 1737 1651 1656 1681 1629 1722 1534 1615 1654 1772 1578 1673 1617 1585 1783 1733 1577 1625 1657 1644 1761 1658 1542 1588 1732 1696 1635 1493 1584 1585 1707 1692 1607 1704 1760 1655 1754 1736 1716 1736 1771 1720 1676 1838 1804 1826 1906 1985 2093 2087 2131 2209 2202 2183 2406 2337 2295 2427 2488 2521 2582 2576 2600 2732 2659 2743 2717 2886 2845 2780 2864 2961 2873 2928 2801 2803 2955 2942 2883 2947 2990 2952 3051 2995 3001 2931 3021 2862 2934 2949 2814 2872 2688 2647 2620 2512 2491 2456 2402 2272 2211 2086 2103 1973 1881 1876 1821 1707 1784 1702 1616 1637 1631 1618 1658 1651 1533 1686 1621 1577 1549 1595 1611 1627 1675 1498 1501 1593 1563 1559 1681 1615 1672 1575 1458 1609 1511 1480 1455 1495 1673 1448 1489 1592 1386 1520 1612 1543 1407 1537 1490 1549 1489 1576 1604 1509 1460 1665 1418 1432 1417 1517 1560 1459 1590 1445 1449 1413 1422 1508 1554 1451 1480 1552 1674 1555 1549 1593 1522 1295 1607 1591 1371 1595 1490 1402 1480 1479 1614 1369 1558 1560 1622 1468 1677 1421 1472 1363 1400 1422 1516 1475 1396 1386 1357 1410 1461 1415 1464 1555 1497 1531 1434 1422 1491 1524 1502 1393 1351 1481 1522 1501 1468 1487 1500 1495 1466 1437 1490 1477 1568 1458 1657 1559 1660 1610 1560 1704 1579 1631 1613 1676 1776 1681 1727 1745 1758 1754 1659 1789 1607 1755 1839 1641 1773 1671 1662 1820 1686 1681 1719 1684 1685 1828 1736 1740 1805 1742 1654 1779 1755 1774 1617 1764 1597 1713 1735 1678 1709 1815 1610 1562 1558 1644 1568 1642 1496 1348 1412 1367 1502 1302 1394 1331 1481 1509 1517 1473 1455 1263 1345 1434 1268 1413 1332 1395 1408 1314 1263 1347 1483 1431 1447 1439 1380 1495 1381 1440 1353 1410 1283 1368 1352 1488 1358 1406 1503 1409 1329 1415 1457 1348 1380 1607 1406 1368 1375 1393 1285 1317 1308 1415 1249 1375 1429 1391 1281 1392 1349 1507 1542 1344 1373 1363 1490 1546 1427 1336 1351 1271 1374 1337 1359 1221 1348 1363 1350 1437 1439 1362 1218 1340 1321 1328 1536 1252 1334 1252 1370 1376 1255 1490 1183 1403 1354 1310 1481 1365 1295 1315 1431 1217 1261 1470 1235 1297 1319 1359 1270 1430 1347 1344 1484 1328 1389 1302 1407 1290 1221 1418 1405 1359 1320 1347 1421 1271 1231 1374 1396 1299 1296 1405 1235 1297 1358 1370 1482 1320 1215 1378 1261 1496 1337 1458 1372 1391 1325 1507 1395 1444 1293 1434 1521 1352 1235 1314 1290 1309 1357 1371 1487 1399 1300 1258 1315 1317 1326 1450 1273 1382 1268 1372 1294 1350 1266 1352 1311 1510 1330 1354 1316 1301 1409 1273 1422 1315 1569 1347 1290 1415 1283 1258 1304 1399 1400 1352 1325 1258 1393 1442 1398 1326 1423 1441 1380 1397 1565 1383 1454 1531 1555 1390 1417 1421 1446 1473 1408 1393 1323 1430 1398 1600 1401 1328 1408 1513 1378 1561 1346 1447 1476 1506 1364 1290 1488 1384 1333 1563 1472 1470 1456 1397 1302 1354 1299 1476 1439 1458 1430 1285 1364 1408 1420 1401 1284 1290 1389 1359 1382 1427 1315 1459 1408 1395 1397 1378 1484 1350 1490 1501 1382 1377 1395 1415 1322 1548 1509 1333 1428 1360 1254 1294 1359 1272 1258 1393 1265 1388 1296 1431 1423 1296 1360 1371 1366 1312 1373 1305 1281 1363 1369 1319 1229 1454 1401 1288 1394 1415 1269 1352 1327 1252 1402 1307 1310 1239 1226 1279 1309 1279 1460 1373 1462 1448 1339 1443 1348 1246 1360 1361 1264 1305 1291 1290 1366 1309 1380 1373 1359 1299 1197 1501 1349 1295 1257 1301 1348 1289 1303 1404 1407 1388 1310 1377 1475 1455 1433 1398 1291 1314 1408 1310 1331 1314 1403 1365 1388 1332 1266 1345 1377 1304 1263 1254 1405 1324 1318 1271 1280 1495 1433 1336 1370 1365 1295 1322 1441 1405 1271 1504 1479 1328 1434 1469 1431 1285 1377 1392 1358 1431 1334 1350 1324 1448 1325 1401 1357 1361 1532 1468 1293 1476 1434 1454 1454 1342 1471 1393 1587 1322 1468 1525 1477 1448 1444 1474 1467 1437 1521 1504 1719 1514 1608 1450 1598 1519 1526 1538 1439 1705 1533 1433 1495 1458 1645 1438 1419 1565 1463 1615 1532 1596 1495 1538 1537 1480 1664 1475 1568 1711 1518 1567 1535 1630 1534 1624 1711 1673 1620 1735 1556 1494 1400 1597 1507 1477 1621 1423 1505 1641 1620 1423 1576 1615 1600 1533 1559 1388 1621 1664 1611 1612 1592 1519 1624 1619 1607 1596 1588 1470 1618 1587 1678 1556 1696 1742 1673 1606 1493 1560 1777 1548 1694 1691 1555 1731 1480 1724 1702 1534 1624 1685 1725 1762 1727 1627 1599 1731 1772 1780 1729 1686 1794 1796 1718 1781 1727 1640 1735 1797 1769 1809 1721 1664 1841 1718 1726 1648 1727 1826 1845 1860 1825 1771 1808 1826 1955 1914 1933 1947 1940 2054 2027 2091 2129 2230 2196 2277 2267 2384 2434 2478 2432 2529 2614 2608 2640 2626 2605 2764 2634 2752 2792 2779 2824 2840 2795 2761 2914 2845 2895 2830 2924 2997 2910 2984 2837 2902 2985 2935 2926 2833 2924 2982 2951 2967 2929 2843 2677 2811 2572 2713 2597 2400 2444 2379 2312 2217 2130 2236 2136 2119 2072 2030 2048 2058 1909 2006 1999 1994 1952 1983 1986 2001 1978 1870 2023 1956 2018 1999 2015 2036 2069 2116 2008 1929 2000 2005 2068 1993 2023 2011 1988 1985 2028 2080 2119 2076 2019 2036 2017 2073 2055 2050 2047 2018 2057 2007 2105 2039 2072 2058 2052 2072 2078 2115 2064 2042 2120 2162 2172 2173 1997 2126 2056 2099 2020 2030 2139 2061 2104 2100 2149 2150 2082 2084 2169 2197 2116 2121 2053 2111 2154 2082 2076 2104 2142 2179 2157 2020 2166 2063 2071 2117 2138 2154 2178 2177 2116 2119 2213 2187 2178 2184 2251 2128 2120 2366 2229 2234 2222 2240 2232 2345 2236 2276 2266 2255 2295 2255 2264 2286 2280 2280 2288 2282 2315 2283 2334 2347 2430 2371 2278 2260 2321 2306 2279 2300 2314 2359 2273 2322 2156 2355 2319 2270 2192 2369 2413 2283 2191 2232 2300 2274 2254 2209 2188 2119 2177 2131 2106 2200 2177 2137 2048 2104 2129 2048 2132 2122 2052 2093 2161 2069 2102 2032 2129 2129 2017 2124 2086 2061 2023 2055 2063 2075 2154 2150 2060 2124 2046 2056 2197 2038 2137 2033 2081 2105 2045 2111 2091 2039 2039 2049 2012 2009 2003 2027 2039 2054 2028 1987 2030 2043 2102 2010 2012 2028 1977 2071 1986 2048 1965 2034 2000 1992 1979 2043 2038 1927 2020 2020 1947 1980 2004 1961 1997 1898 1921 1972 1933 1907 2005 1921 1953 1987 1872 2036 1963 1935 1992 1938 1974 1890 1975 1977 1865 1878 2000 1829 1945 1889 1892 1884 1955 1949 1900 1875 1976 1915 1786 1953 1913 1932 1979 1731 1974 1969 1905 1884 1923 1786 2001 1886 1857 1855 1910 1905 1868 1910 1810 1840 1970 1872 1898 1850 1880 1861 1849 1958 1837 1731 1842 1924 1853 1819 1844 1830 1909 1835 1853 1917 1928 1775 1842 1855 1799 1759 1831 1787 1780 1835 1816 1817 1764 1891 1849 1896 1786 1761 1898 1696 1798 1899 1710 1818 1742 1758 1813 1826 1695 1878 1770 1859 1837 1721 1746 1740 1660 1787 1799 1837 1650 1699 1734 1755 1827 1799 1745 1757 1849 1643 1728 1646 1725 1758 1780 1718 1724 1750 1743 1800 1738 1804 1702 1734 1634 1614 1681 1781 1831 1746 1719 1635 1819 1697 1728 1664 1706 1781 1677 1693 1713 1701 1797 1802 1776 1668 1827 1668 1711 1692 1605 1649 1739 1656 1599 1638 1624 1790 1833 1663 1499 1735 1737 1680 1677 1607 1564 1684 1734 1578 1538 1633 1634 1661 1667 1720 1539 1590 1679 1642 1694 1652 1712 1626 1611 1538 1619 1549 1663 1550 1552 1737 1595 1758 1629 1619 1573 1432 1651 1572 1579 1576 1659 1717 1777 1602 1585 1453 1698 1518 1723 1596 1706 1580 1617 1574 1569 1628 1655 1651 1592 1521 1532 1597 1775 1614 1609 1651 1567 1542 1594 1548 1442 1509 1486 1612 1640 1551 1716 1619 1429 1735 1503 1676 1636 1676 1605 1563 1485 1597 1718 1518 1621 1598 1656 1557 1804 1614 1683 1753 1609 1755 1861 1719 1816 1786 1979 1899 1915 2129 2170 2068 2131 2155 2208 2245 2292 2200 2329 2289 2368 2316 2286 2384 2341 2303 2323 2256 2270 2406 2376 2300 2344 2423 2369 2298 2264 2264 2315 2331 2279 2353 2334 2407 2332 2405 2414 2323 2267 2241 2244 2265 2220 2218 2079 2117 2087 1919 2004 1979 1798 1920 1828 1817 1799 1672 1681 1708 1636 1520 1479 1630 1648 1589 1534 1564 1592 1530 1512 1356 1452 1499 1614 1554 1534 1674 1639 1618 1457 1449 1553 1626 1468 1612 1675 1515 1593 1564 1748 1518 1461 1529 1493 1435 1468 1457 1438 1508 1632 1598 1574 1592 1515 1370 1512 1591 1548 1474 1624 1504 1592 1627 1590 1497 1421 1452 1463 1492 1568 1567 1461 1440 1433 1584 1497 1448 1460 1424 1382 1447 1570 1577 1660 1595 1570 1588 1527 1561 1404 1304 1484 1654 1479 1643 1477 1529 1506 1505 1491 1514 1468 1542 1380 1538 1513 1420 1460 1602 1565 1472 1391 1509 1437 1481 1506 1555 1462 1490 1540 1478 1429 1477 1533 1482 1442 1354 1440 1470 1479 1528 1455 1346 1496 1537 1320 1465 1422 1621 1581 1464 1321 1577 1655 1486 1478 1515 1511 1433 1490 1577 1497 1503 1364 1550 1490 1492 1484 1579 1425 1473 1415 1463 1350 1596 1531 1436 1561 1526 1556 1393 1455 1412 1611 1444 1444 1424 1465 1500 1511 1538 1449 1460 1460 1564 1436 1407 1541 1517 1464 1371 1414 1444 1334 1375 1577 1368 1641 1457 1358 1313 1446 1413 1609 1479 1437 1561 1633 1482 1423 1599 1438 1476 1659 1418 1355 1541 1540 1555 1419 1536 1462 1511 1557 1432 1460 1467 1519 1478 1587 1322 1571 1668 1556 1617 1451 1484 1508 1709 1513 1548 1587 1481 1553 1507 1713 1523 1604 1592 1464 1626 1404 1612 1498 1428 1651 1477 1515 1467 1430 1504 1451 1475 1460 1536 1557 1424 1503 1625 1584 1543 1625 1640 1496 1481 1395 1685 1481 1552 1464 1482 1493 1509 1489 1609 1543 1734 1523 1570 1469 1584 1582 1426 1587 1614 1654 1562 1540 1620 1508 1484 1553 1730 1592 1523 1608 1602 1642 1757 1552 1496 1531 1640 1481 1578 1550 1617 1432 1453 1710 1559 1527 1588 1529 1544 1598 1582 1685 1684 1575 1520 1654 1626 1469 1469 1460 1615 1441 1644 1539 1565 1368 1459 1458 1515 1439 1576 1596 1501 1314 1501 1724 1594 1589 1546 1426 1548 1519 1714 1445 1531 1452 1604 1604 1548 1442 1474 1645 1464 1522 1786 1473 1676 1564 1554 1510 1666 1594 1671 1541 1535 1520 1543 1490 1483 1525 1470 1484 1506 1543 1604 1449 1481 1649 1589 1528 1729 1544 1629 1479 1500 1472 1664 1758 1695 1571 1440 1761 1462 1423 1465 1620 1514 1490 1537 1576 1591 1498 1539 1443 1530 1508 1365 1535 1620 1580 1535 1581 1517 1489 1479 1501 1566 1541 1551 1589 1535 1411 1515 1585 1492 1494 1506 1566 1680 1545 1426 1485 1592 1591 1488 1536 1531 1601 1498 1467 1627 1508 1505 1482 1492 1629 1613 1672 1533 1376 1592 1650 1484 1585 1458 1666 1505 1416 1552 1698 1454 1486 1532 1621 1510 1549 1491 1454 1560 1587 1511 1609 1551 1490 1477 1552 1667 1393 1545 1519 1503 1711 1553 1554 1539 1445 1676 1491 1596 1449 1453 1516 1574 1524 1564 1604 1566 1653 1455 1383 1596 1583 1494 1505 1438 1575 1711 1556 1648 1556 1566 1713 1690 1508 1435 1629 1495 1641 1535 1563 1480 1569 1540 1632 1740 1634 1423 1737 1802 1726 1801 1880 1957 1832 1953 1894 1980 2003 2098 1910 2018 2039 1995 2068 1983 2085 1955 2124 2002 1966 2078 1850 1907 1996 1890 1973 2018 1982 1890 2043 1915 1942 1976 2050 2022 1949 1958 2021 1988 1948 1967 2014 2044 1972 1888 1945 1953 1789 1913 1890 1759 1814 1790 1678 1728 1715 1695 1700 1641 1545 1736 1748 1503 1533 1558 1520 1648 1590 1626 1723 1573 1520 1537 1501 1539 1622 1529 1501 1529 1636 1373 1640 1519 1491 1636 1620 1509 1560 1694 1700 1513 1542 1495 1604 1468 1633 1571 1592 1542 1578 1485 1551 1634 1583 1559 1491 1641 1516 1702 1453 1370 1652 1630 1696 1648 1629 1640 1525 1567 1511 1455 1441 1388 1646 1649 1640 1640 1663 1466 1524 1563 1533 1616 1404 1512 1647 1513 1503 1662 1683 1606 1635 1554 1552 1706 1576 1675 1654 1647 1600 1606 1707 1766 1628 1771 1605 1724 1749 1805 1774 1780 1748 1741 1681 1753 1694 1776 1686 1743 1702 1708 1884 1818 1759 1775 1766 1766 1748 1731 1840 1802 1661 1834 1774 1801 1689 1708 1876 1793 1704 1815 1733 1623 1827 1806 1704 1697 1722 1755 1704 1812 1770 1675 1673 1610 1729 1597 1767 1668 1682 1659 1723 1613 1714 1604 1550 1499 1720 1626 1666 1551 1627 1634 1802 1505 1481 1718 1702 1628 1736 1671 1668 1694 1627 1658 1626 1529 1751 1660 1636 1612 1757 1652 1691 1715 1642 1547 1729 1653 1630 1728 1697 1538 1654 1733 1713 1640 1669 1671 1597 1657 1603 1688 1620 1596 1614 1611 1668 1687 1748 1658 1612 1736 1673 1666 1670 1567 1651 1768 1711 1629 1733 1753 1647 1558 1652 1686 1688 1736 1634 1784 1637 1641 1639 1603 1693 1663 1787 1736 1760 1789 1779 1724 1787 1659 1731 1607 1630 1584 1753 1705 1726 1591 1717 1642 1613 1694 1648 1602 1748 1692 1663 1703 1806 1702 1713 1713 1584 1675 1788 1724 1640 1779 1559 1684 1754 1732 1771 1724 1748 1773 1706 1803 1585 1788 1733 1754 1748 1770 1753 1716 1653 1666 1680 1687 1699 1591 1725 1834 1881 1819 1661 1803 1659 1763 1781 1770 1781 1800 1765 1800 1785 1758 1855 1731 1754 1864 1787 1812 1820 1840 1857 1897 1901 1827 1934 1955 1951 1910 2015 1970 2027 2030 2094 2209 2355 2351 2478 2689 2902 3031 3144 3343 3783 3958 4175 4416 4718 4779 5027 5158 5223 5464 5567 5834 5888 5931 6111 6085 6082 6317 6119 6130 6223 6238 6028 6020 6138 6150 6300 6233 6086 6286 6124 6205 6219 6120 6293 6177 6198 6377 6333 6243 6321 6290 6259 6161 5867 5904 5668 5477 5120 4928 4574 4362 4040 3753 3516 3278 3328 2998 2831 2643 2428 2322 2162 2157 2093 2017 2023 1948 1972 1858 2023 1967 1964 1868 1878 1967 1872 1918 1853 1808 1967 1950 1967 1911 1953 1830 1954 1964 1882 1988 1888 1818 1877 1853 1916 1886 1819 1784 1968 1983 1825 1929 1876 1871 1838 1913 1841 1877 1915 1809 1849 1761 1910 1950 1944 1900 1913 1980 1931 1892 1936 1913 1893 1963 1893 1884 1879 1925 1946 1854 1907 1950 1845 1870 1928 1999 1916 1870 1941 1855 1888 1908 1896 1939 1873 1852 1757 2043 1932 1934 1897 1795 1923 1908 1820 1796 1884 1931 1957 1891 1960 1840 1921 1965 1872 1974 1880 1840 1928 2023 1958 1916 1814 1937 1923 2034 1859 1890 1971 1959 1924 1957 1951 1842 1843 1961 1985 1906 1964 1929 1962 1916 1919 1943 1946 1948 1985 1890 1965 1988 2009 1991 1938 1962 1934 2041 1925 1904 2029 2003 1916 1902 1991 1939 2016 2013 2045 1947 1963 1968 2009 2001 1956 2088 2019 1999 2020 1951 2035 1981 1979 1960 1975 1992 1987 2053 1962 1987 2041 1982 1993 1994 1990 1985 2025 2055 2057 2013 1934 2068 1967 2044 1904 2021 2057 2029 1948 1983 1933 2128 2019 2023 2054 2039 2045 2086 2067 2070 2038 2019 2037 2044 2069 2094 2021 2106 2099 2080 2091 1974 1985 2084 2154 2106 2013 2089 2196 2213 2156 2235 2177 2131 2178 2245 2246 2158 2236 2291 2148 2228 2352 2191 2274 2245 2400 2309 2331 2275 2290 2301 2373 2421 2373 2340 2337 2331 2410 2291 2422 2430 2454 2319 2345 2386 2422 2511 2379 2379 2295 2365 2391 2470 2356 2406 2418 2412 2340 2414 2330 2317 2347 2254 2374 2313 2359 2240 2161 2333 2306 2183 2258 2254 2179 2195 2257 2247 2293 2328 2206 2274 2180 2284 2207 2211 2255 2189 2334 2233 2275 2265 2235 2308 2242 2285 2269 2225 2367 2330 2307 2353 2315 2407 2321 2276 2289 2311 2345 2353 2287 2396 2243 2393 2384 2371 2346 2457 2344 2383 2346 2296 2439 2378 2470 2394 2398 2404 2417 2382 2292 2390 2419 2484 2471 2424 2414 2437 2508 2489 2466 2405 2531 2504 2432 2415 2516 2410 2451 2462 2519 2531 2555 2416 2503 2545 2593 2510 2424 2438 2522 2667 2546 2539 2576 2548 2550 2547 2676 2643 2562 2504 2616 2670 2623 2634 2700 2608 2666 2655 2680 2619 2597 2680 2668 2708 2694 2741 2697 2738 2588 2750 2831 2882 2792 2751 2867 2811 2843 2898 2861 2906</counts>
			</dataPoints>
		</scan>
	</xrdMeasurement>
</xrdMeasurements>