File: Data Files/Full/MSS p (6-129, 9w)_01.xrdml
<?xml version="1.0"?>
<xrdMeasurements xmlns="http://www.xrdml.com/XRDMeasurement/2.2" xmlns:xsi="http://www.w3.org/2001/XMLSchema-instance" xsi:schemaLocation="http://www.xrdml.com/XRDMeasurement/2.2 http://www.xrdml.com/XRDMeasurement/2.2/XRDMeasurement.xsd" status="Completed" recordIdentifier="{AB7A5820-9F27-4F5D-B0A1-793778E3BE59}">
	<comment>
		<entry/>
	</comment>
	<sample type="To be analyzed">
		<id>p</id>
		<name></name>
		<preparedBy></preparedBy>
	</sample>
	<xrdMeasurement measurementType="Scan" status="Completed" sampleMode="Reflection">
		<usedWavelength intended="K-Alpha 1">
			<kAlpha1 unit="Angstrom">1.5405980</kAlpha1>
			<kAlpha2 unit="Angstrom">1.5444260</kAlpha2>
			<kBeta unit="Angstrom">1.3922500</kBeta>
			<ratioKAlpha2KAlpha1>0.5000</ratioKAlpha2KAlpha1>
		</usedWavelength>
		<incidentBeamPath>
			<radius unit="mm">145.00</radius>
			<xRayTube id="1010048" name="Empyrean Cu LFF HR (9430 033 7310x) DK437964">
				<tension unit="kV">40.0</tension>
				<current unit="mA">15.0</current>
				<anodeMaterial>Cu</anodeMaterial>
				<focus type="Line">
					<length unit="mm">12.0</length>
					<width unit="mm">0.4</width>
					<takeOffAngle unit="deg">6.0</takeOffAngle>
				</focus>
			</xRayTube>
			<filter id="20010004" name="Beta-filter Nickel">
				<material>Ni</material>
				<thickness unit="mm">0.020</thickness>
			</filter>
			<sollerSlit id="21010002" name="Soller slits 0.04 rad.">
				<opening unit="rad">0.0400</opening>
			</sollerSlit>
			<mask id="22031000" name="Fixed mask 13 mm">
				<width unit="mm">9.00</width>
			</mask>
			<divergenceSlit id="22120001" name="Divergence slit 1°" xsi:type="fixedDivergenceSlitType">
				<distanceToSample unit="mm">50.00</distanceToSample>
				<height unit="mm">1.52</height>
			</divergenceSlit>
		</incidentBeamPath>
		<diffractedBeamPath>
			<radius unit="mm">145.00</radius>
			<parallelPlateCollimator id="25020001" name="Parallel plate collimator 0.28°">
				<opening unit="deg">0.28</opening>
			</parallelPlateCollimator>
			<detector id="7010020" name="PIXcel3D-Medipix3 1x1 detector" xsi:type="areaDetectorType">
				<phd unit="keV">
					<lowerLevel>4.0</lowerLevel>
					<upperLevel>11.3</upperLevel>
				</phd>
				<mode>Receiving slit</mode>
				<activeChannelsEquatorial>255</activeChannelsEquatorial>
				<activeChannelsAxial>255</activeChannelsAxial>
				<pitchEquatorial unit="mm">0.05500</pitchEquatorial>
				<pitchAxial unit="mm">0.05500</pitchAxial>
				<readOutPeriod unit="seconds">0.050</readOutPeriod>
			</detector>
		</diffractedBeamPath>
		<scan appendNumber="0" mode="Continuous" scanAxis="2Theta" status="Completed">
			<header>
				<startTimeStamp>2025-06-26T12:34:12-08:00</startTimeStamp>
				<endTimeStamp>2025-06-27T02:14:17-08:00</endTimeStamp>
				<author>
					<name>Instrument</name>
				</author>
				<source>
					<applicationSoftware version="1.6 (94)">PANalytical Aeris Instrument Suite</applicationSoftware>
					<instrumentControlSoftware version="3.0.0 20211014">AERIS</instrumentControlSoftware>
					<instrumentID>2855484</instrumentID>
				</source>
			</header>
			<dataPoints>
				<positions axis="2Theta" unit="deg">
					<startPosition>6.005</startPosition>
					<endPosition>128.995</endPosition>
				</positions>
				<positions axis="Omega" unit="deg">
					<commonPosition>9.000</commonPosition>
				</positions>
				<commonCountingTime unit="seconds">3.520</commonCountingTime>
				<counts 6434 6226 6239 6157 6192 5989 6056 6227 5962 6055 6122 6143 6103 5893 6074 5960 5919 5807 6016 5987 5839 6013 5960 5957 5986 6142 6010 5840 5942 5860 5898 5913 6022 5809 5888 5803 5903 5848 5893 5910 6021 5751 5869 5767 5843 5843 5770 5873 5838 5773 5808 5779 5749 5736 5775 5733 5716 5722 5647 5690 5786 5894 5909 5669 5677 5719 5741 5707 5616 5695 5695 5679 5771 5669 5720 5674 5757 5640 5748 5724 5657 5735 5568 5676 5664 5456 5701 5569 5508 5781 5703 5537 5539 5674 5464 5690 5515 5551 5544 5577 5484 5618 5624 5434 5489 5588 5561 5482 5355 5517 5612 5369 5623 5780 5494 5619 5645 5672 5721 5729 5570 5648 5591 5724 5679 5800 5754 5839 5595 5758 5803 5794 5792 5864 5813 5877 5943 5851 5903 5736 5814 5852 5791 5806 5926 5858 5789 5887 5817 5869 5886 5942 5778 5854 5706 5878 5949 5911 5828 5831 5760 5811 5728 5813 5780 5829 5833 5826 5859 5626 5852 5649 5552 5816 5735 5700 5687 5675 5725 5608 5757 5690 5629 5758 5590 5595 5718 5655 5726 5619 5657 5751 5561 5687 5555 5620 5766 5493 5585 5572 5547 5540 5665 5500 5613 5603 5630 5592 5413 5446 5513 5443 5604 5567 5470 5387 5453 5502 5434 5319 5356 5439 5394 5349 5364 5422 5300 5434 5315 5475 5430 5358 5389 5320 5259 5342 5261 5332 5409 5227 5341 5341 5419 5521 5289 5359 5313 5232 5360 5423 5452 5355 5230 5295 5203 5422 5244 5158 5269 5331 5133 5294 5310 5386 5228 5347 5175 5347 5274 5214 5275 5235 5240 5281 5082 5399 5110 5196 5203 5240 5258 5404 5170 5269 5171 5203 5214 5209 5319 5242 5092 5096 5193 5144 5209 5171 5172 5210 5176 5049 5096 5190 5063 5124 5101 5171 5081 5244 5157 5151 5125 5157 5166 5081 5137 5005 5154 5031 5069 5180 5245 5193 5057 5124 5259 5159 5164 5137 5167 5091 5108 5212 5241 5201 5029 5216 5164 5060 5086 5096 5186 5172 5163 5092 5222 5204 5105 5111 5283 5241 5055 5158 5077 5192 5093 5023 5049 5126 5082 5128 5019 5171 5110 5094 5144 5032 5274 5300 5065 4992 5044 5170 5010 5055 5233 5236 5150 5220 5056 5010 5282 5296 5156 5201 5063 5169 5338 5239 5294 5272 5278 5256 5272 5125 5194 5386 5200 5405 5229 5328 5419 5306 5247 5420 5203 5355 5492 5466 5420 5549 5380 5311 5456 5383 5523 5488 5443 5383 5345 5480 5395 5498 5493 5496 5525 5500 5539 5589 5454 5573 5627 5558 5570 5413 5462 5384 5479 5413 5427 5361 5604 5582 5414 5634 5711 5488 5529 5454 5481 5441 5480 5458 5540 5400 5452 5603 5422 5365 5495 5579 5637 5403 5516 5651 5432 5504 5457 5468 5471 5522 5374 5648 5445 5679 5533 5659 5584 5523 5628 5545 5603 5543 5555 5535 5618 5620 5741 5581 5652 5481 5619 5660 5766 5657 5783 5690 5944 5852 5808 5725 5751 5810 5675 5863 5870 5817 5889 5917 5892 6004 5901 6076 5878 5917 6046 6001 6130 5954 6031 5991 6117 6054 6000 5942 6208 6017 6050 6043 6345 6184 6172 6193 6377 6445 6541 6534 6968 7287 7481 8003 8499 9198 9911 10478 11549 12272 13081 14202 15127 16096 16998 17635 18536 18850 19229 19455 19659 19659 19940 19676 19167 19148 18648 18533 18052 17882 17716 17825 18029 18360 18279 19051 19933 20652 21789 22958 23735 24895 26597 27434 28238 29312 30048 30835 31451 30790 30915 30627 29776 28784 27745 26497 25110 23945 21998 20621 18377 17206 15592 14086 12699 11371 10320 9378 8871 8147 7507 7371 7040 6863 6887 6803 6932 7047 6852 6976 6825 6943 6712 6974 7061 6896 6958 7047 6728 6947 6732 6830 6949 6644 6772 6837 6818 7029 6705 6981 6789 7022 7106 6800 6919 7079 7072 7167 7108 7206 7143 7045 7123 7335 7034 7150 7130 7237 7269 7318 7043 7074 7103 7204 7176 7160 7292 6875 7173 7154 7075 7086 7228 7169 7295 7172 7378 7293 7394 7292 7320 7364 7219 7487 7199 7399 7460 7331 7261 7341 7268 7332 7449 7399 7389 7473 7366 7459 7326 7387 7391 7403 7482 7391 7374 7519 7252 7481 7587 7420 7608 7408 7418 7583 7436 7821 7571 7577 7595 7567 7581 7504 7503 7458 7550 7601 7624 7690 7700 7662 7680 7688 7562 7693 7583 7667 7607 7878 7605 7598 7627 7720 7805 7708 7504 7780 7839 7809 7572 7652 7716 7754 7874 7721 7786 7640 7897 7938 7733 7876 7755 7733 7811 7898 7933 7689 7964 7877 7674 7995 7794 7933 7876 7841 7976 7904 8068 7989 7883 7718 7884 7896 8060 8026 7977 8002 7937 7922 7928 7941 7851 8056 7939 7868 7804 7856 7940 7905 7860 7938 7988 8043 7751 7988 7981 7829 7719 7763 7903 7923 7751 7663 7783 7851 7640 7822 8009 7817 7850 8027 7836 7924 7907 7722 7981 7802 7721 7843 7853 7723 7780 7740 7830 7692 7761 7770 7863 7719 7773 7700 7690 7685 7612 7663 7769 7657 7560 7616 7767 7643 7420 7715 7498 7559 7619 7560 7597 7497 7502 7604 7328 7535 7619 7530 7508 7445 7362 7421 7524 7441 7443 7273 7401 7568 7547 7455 7216 7353 7249 7427 7441 7493 7362 7305 7300 7298 7261 7283 7220 7226 7327 7167 7343 7164 7209 7282 7272 7045 7213 7226 7130 7027 7198 7070 7065 7078 7050 7089 7086 6929 7206 6905 7136 6933 6824 6956 6938 6953 7051 6944 6878 6962 6814 6830 6787 6801 6806 6731 6657 6838 6786 6738 6733 6825 6816 6677 6787 6662 6542 6734 6599 6665 6613 6606 6608 6688 6525 6547 6523 6565 6606 6333 6609 6419 6478 6368 6413 6561 6588 6460 6356 6311 6395 6359 6409 6260 6293 6332 6310 6413 6349 6250 6241 6209 6206 6259 6130 6157 6264 6198 6124 6193 6152 6078 6117 6041 6045 5974 5972 6073 6108 6032 6118 5925 5929 5887 6059 5948 5907 6061 5931 6033 5848 5936 5861 5924 5968 5870 5875 5879 5808 5886 5722 5898 5915 5921 5616 5924 5690 5848 5769 5774 5787 5790 5862 5671 5727 5782 5565 5649 5573 5556 5711 5563 5572 5563 5555 5560 5422 5506 5428 5417 5493 5272 5438 5385 5417 5392 5393 5422 5378 5466 5491 5428 5364 5415 5365 5491 5298 5350 5262 5299 5375 5358 5248 5326 5088 5171 5346 5482 5163 5249 5145 5200 5315 5280 5101 5177 5148 5236 5225 5268 5131 5214 5120 5110 5211 5244 5300 5231 5070 5183 5146 5040 5056 5025 5103 5070 4975 5003 5007 5012 5005 5017 5023 4938 5030 5117 4935 5094 4938 4901 4996 4960 4940 4973 4898 4863 5089 4882 4985 5031 4920 4871 4963 4904 4918 4951 4908 4592 4744 4782 4926 4786 4727 4899 4899 4664 4763 4816 4731 4860 4815 4592 4784 4717 4752 4722 4654 4641 4682 4558 4715 4680 4695 4626 4669 4635 4750 4618 4627 4680 4615 4583 4580 4758 4568 4730 4755 4574 4499 4593 4551 4475 4623 4451 4607 4605 4610 4540 4522 4541 4488 4433 4666 4565 4509 4510 4373 4579 4443 4601 4582 4472 4405 4484 4482 4446 4528 4472 4480 4379 4469 4372 4394 4418 4311 4486 4555 4403 4254 4383 4395 4331 4349 4362 4355 4308 4391 4252 4304 4416 4327 4278 4481 4327 4516 4506 4302 4225 4296 4259 4309 4381 4337 4242 4357 4291 4288 4232 4151 4221 4286 4083 4218 4321 4325 4223 4256 4162 4258 4119 4266 4216 4179 4162 4130 4227 4231 4153 4095 4187 4132 4225 4193 4299 4189 4181 4211 4169 4105 4099 4200 4193 4199 4129 4053 4068 4166 4059 4146 4025 4208 4104 4005 4179 4045 4056 4109 4156 4143 4060 4114 4045 4080 4073 4027 4018 4062 4024 3981 4126 4103 3975 4068 3929 3999 3986 4139 4039 3937 4014 4014 3950 4006 3919 3873 3910 3977 4097 3855 4007 3831 3956 4138 4054 3958 3888 3901 3963 3831 3833 4058 4067 3994 3894 3954 3869 3977 3929 3955 3915 3852 3936 3857 3895 3850 3896 3941 3897 3926 3890 3882 3873 3937 4015 3844 3834 3786 4007 3812 3784 3883 3776 3932 3919 3867 3870 3819 3825 3850 3846 3862 3709 3709 3837 3782 3860 3884 3911 3782 3940 3739 3881 3779 3745 3858 3841 3697 3792 3791 3794 3803 3866 3611 3629 3785 3765 3914 3850 3734 3694 3735 3816 3697 3861 3737 3780 3750 3796 3717 3702 3779 3741 3750 3729 3701 3875 3753 3674 3623 3666 3681 3697 3705 3687 3826 3607 3667 3656 3804 3778 3777 3724 3704 3744 3764 3730 3663 3887 3840 3833 3923 3875 3812 3933 3957 3952 3955 4162 4044 4136 4088 4005 4052 4037 4134 4069 3984 4038 4187 3932 4167 4068 4082 4203 3958 4002 4119 4086 4138 4067 4258 4127 4286 3992 4101 4134 4020 4080 4200 4173 4114 4265 3997 4070 3981 4035 3994 3934 3896 3883 3856 3901 3701 3564 3780 3619 3677 3539 3710 3502 3615 3575 3471 3535 3472 3566 3662 3555 3479 3616 3553 3518 3632 3666 3488 3482 3529 3574 3512 3532 3648 3642 3494 3480 3488 3361 3603 3490 3495 3550 3390 3488 3533 3350 3540 3480 3512 3571 3506 3387 3469 3562 3526 3346 3554 3441 3467 3516 3443 3515 3504 3503 3538 3463 3577 3489 3529 3579 3488 3396 3439 3419 3530 3576 3428 3491 3433 3391 3259 3357 3467 3431 3387 3500 3493 3522 3488 3454 3451 3432 3346 3477 3444 3489 3501 3375 3474 3400 3504 3460 3476 3408 3414 3426 3355 3410 3400 3350 3439 3321 3434 3324 3294 3336 3400 3547 3393 3322 3533 3397 3365 3416 3371 3384 3398 3348 3343 3395 3357 3396 3293 3473 3302 3435 3384 3416 3295 3303 3314 3375 3540 3361 3293 3343 3461 3266 3299 3412 3288 3421 3300 3505 3357 3294 3347 3286 3493 3414 3480 3289 3402 3341 3245 3377 3486 3483 3378 3334 3328 3413 3300 3362 3417 3432 3290 3455 3377 3435 3416 3519 3504 3422 3395 3381 3362 3408 3372 3589 3627 3669 3742 3972 4149 4137 4562 4578 4816 5098 5402 5559 6080 6387 6622 6831 7380 7397 7441 7708 7852 7658 7931 7863 7789 7834 7811 7741 7798 7368 7631 7519 7636 7557 7571 7793 7874 7873 8202 8225 8634 8788 8814 9035 9290 9456 9753 9900 10058 10048 10006 9738 9601 9560 9408 9143 8767 8724 8160 7830 7309 7068 6357 5903 5556 5323 5022 4537 4274 4127 3751 3834 3683 3509 3491 3347 3288 3498 3365 3298 3435 3483 3374 3517 3301 3304 3274 3361 3375 3251 3394 3200 3255 3291 3343 3292 3359 3312 3289 3327 3265 3322 3285 3147 3310 3337 3262 3184 3272 3185 3326 3350 3302 3246 3333 3373 3380 3261 3312 3229 3295 3217 3228 3279 3228 3218 3305 3258 3203 3133 3191 3258 3276 3111 3245 3158 3286 3226 3220 3254 3186 3233 3263 3195 3268 3199 3184 3168 3166 3338 3203 3150 3246 3282 3168 3151 3240 3223 3146 3149 3167 3308 3286 3170 3032 3178 3325 3096 3136 3161 3291 3168 3201 3162 3235 3225 3166 3159 3228 3172 3332 3174 3183 3205 3188 3094 3165 3245 3036 3221 3174 3100 3258 3151 3144 3192 3281 3267 3267 3193 3070 3071 3208 3256 3119 3414 3194 3255 3182 3207 3281 3174 3158 3158 3188 3223 3199 3191 3114 3097 3043 3205 3222 3206 3233 3219 3239 3260 3134 3166 3269 3272 3279 3325 3075 3185 3227 3162 3118 3120 3238 3206 3146 3214 3170 3130 3104 3107 3139 3153 3193 3084 3132 3173 3034 3160 3143 3224 3156 3131 3051 3150 3183 3272 3194 3037 3134 3249 2994 3051 3041 3102 3218 3170 3194 3216 3148 3239 3159 3113 2993 3123 3140 3178 3078 3194 3242 3069 3060 3175 3089 3159 3149 3061 3143 3270 3193 3244 3068 3174 3041 3170 3151 3117 3206 3118 3236 3145 3151 3125 3134 3173 3217 3094 3186 3058 3059 3082 3027 3099 3102 3161 3189 3207 3145 3054 3137 3098 3126 3300 3161 3101 3094 3066 3137 3097 3212 3172 3079 3104 3202 3179 3200 3110 3068 3240 3064 3266 3117 3201 3183 3195 3035 3271 3130 3132 3103 3081 3111 3085 3080 3143 3192 3193 3097 3147 3122 3097 3170 3159 3163 3040 3110 3117 3028 3115 2987 3108 3072 3098 3100 3132 3087 3072 3067 3053 3061 3101 3080 3217 3156 3189 3194 3191 3168 3167 3131 3161 3105 3127 3140 3161 3164 3123 3126 3137 3107 3051 3215 3169 3057 3179 3110 3106 3212 3108 2958 3116 3059 3213 3076 3152 3129 3193 3168 3188 3167 3146 3168 3173 3194 3184 3142 3145 3120 3360 3286 3388 3456 3618 3487 3710 3886 4127 4330 4455 4690 4944 5353 5520 5699 5938 6158 6353 6740 6705 6610 6913 6955 7233 7233 7287 7068 7207 7249 7039 7106 7382 7322 7402 7417 7500 7714 7562 8229 8184 8362 8792 8893 9183 9209 9410 9712 9597 9633 10099 10145 9964 9906 9826 9775 9560 9199 8726 8526 7876 7753 7087 6726 6277 5813 5642 5132 4889 4621 4188 4071 3862 3452 3517 3231 3304 3217 3103 3286 3133 3244 3231 3168 3302 3294 3095 3129 3112 3121 3159 3047 3189 3186 3082 3149 3130 3117 3215 3033 3076 3024 3121 3159 3099 3014 2995 3122 3150 3134 3153 3173 3097 3081 3114 3014 3158 3193 3080 3059 3250 3057 3153 3248 3092 3182 3087 3082 3104 3129 3129 3112 3012 3066 3152 3081 3105 3063 3133 3110 3182 3065 3037 3123 3078 3011 3049 3140 3037 3056 3058 3048 3085 3043 2999 3051 3005 3034 3218 3132 3123 3077 3053 3040 3124 3035 3150 3049 3182 3051 3087 2953 3066 3019 3057 2978 3162 3024 3257 3111 3016 3189 3085 3104 3044 3172 3044 3194 3087 3006 3054 3091 3081 3148 3127 3138 3118 3173 3156 3046 2917 2996 3055 3067 3053 3166 2995 3067 3053 3037 3121 3048 3032 3182 3141 3178 3120 3110 3112 3216 3214 3223 3104 3097 3105 3146 3232 3170 3082 3208 3099 3194 3074 3134 3142 3172 3119 3037 3168 3210 3130 3138 3252 3314 3196 3120 3125 3314 3239 3146 3226 3234 3261 3132 3131 3252 3256 3126 3241 3173 3322 3159 3292 3243 3262 3198 3232 3327 3210 3278 3260 3319 3180 3196 3359 3129 3268 3289 3200 3272 3288 3302 3388 3402 3273 3169 3241 3212 3317 3288 3221 3337 3263 3377 3283 3303 3226 3242 3351 3316 3383 3255 3225 3274 3315 3223 3300 3238 3223 3331 3307 3236 3327 3389 3311 3439 3448 3346 3348 3303 3403 3300 3324 3339 3337 3335 3222 3354 3361 3298 3410 3459 3424 3402 3322 3480 3418 3362 3264 3388 3405 3397 3485 3439 3444 3328 3507 3366 3406 3408 3490 3368 3470 3505 3425 3568 3567 3406 3519 3498 3488 3527 3476 3524 3486 3581 3603 3542 3573 3705 3758 3726 3915 3945 3998 4304 4427 4592 4683 4863 5068 5323 5694 5865 5939 6404 6556 6510 6686 6872 6915 6870 6829 7019 7119 6933 6824 6764 6783 6631 6782 6807 6594 6923 6904 6785 7163 7311 7630 7557 7461 7824 7855 8144 8262 8259 8461 8551 8513 8557 8366 8440 8385 8066 7967 7995 7736 7404 7234 6961 6649 6266 5923 5726 5335 5241 4895 4632 4414 4219 4036 4019 3869 3815 3634 3626 3763 3764 3551 3725 3614 3644 3614 3670 3652 3639 3491 3472 3538 3639 3514 3598 3622 3515 3726 3606 3565 3522 3662 3521 3535 3395 3633 3513 3644 3446 3524 3492 3562 3492 3565 3546 3550 3525 3425 3524 3583 3617 3533 3394 3420 3336 3519 3516 3464 3606 3410 3291 3490 3582 3431 3418 3409 3356 3378 3429 3427 3413 3458 3383 3422 3213 3288 3331 3407 3433 3399 3309 3333 3281 3310 3312 3326 3313 3391 3305 3286 3223 3257 3252 3182 3182 3312 3218 3225 3340 3188 3228 3308 3099 3232 3277 3333 3304 3238 3322 3199 3413 3332 3264 3271 3308 3388 3416 3245 3459 3352 3343 3243 3244 3227 3286 3335 3342 3319 3274 3283 3300 3252 3235 3288 3235 3226 3161 3182 3248 3319 3296 3164 3185 3264 3132 3314 3276 3203 3082 3076 3084 3013 3153 3143 3044 3119 3047 3013 2948 2985 3091 2947 2934 2931 2907 2963 2949 2983 2898 2906 2961 2858 2915 2949 2823 2816 2886 2955 2807 2769 2921 2847 2760 2797 2798 2788 2782 2746 2906 2806 2849 2872 2736 2870 2895 2770 2807 2658 2806 2752 2776 2894 2644 2769 2824 2776 2651 2751 2721 2792 2725 2779 2763 2724 2661 2677 2850 2856 2625 2713 2762 2672 2683 2647 2751 2690 2703 2813 2621 2770 2675 2702 2665 2724 2809 2642 2771 2707 2588 2671 2706 2574 2790 2543 2631 2672 2740 2594 2722 2704 2655 2713 2569 2518 2625 2594 2638 2579 2551 2630 2669 2602 2707 2570 2542 2638 2648 2616 2689 2612 2560 2644 2575 2693 2607 2549 2604 2569 2632 2603 2565 2552 2528 2537 2555 2524 2555 2612 2646 2462 2476 2550 2630 2593 2530 2562 2572 2441 2561 2609 2472 2569 2660 2537 2514 2380 2445 2516 2540 2562 2553 2483 2490 2563 2399 2542 2475 2488 2524 2471 2601 2496 2553 2491 2417 2459 2410 2362 2449 2447 2500 2499 2514 2499 2502 2516 2412 2393 2489 2466 2494 2462 2442 2400 2492 2426 2452 2504 2361 2490 2509 2398 2432 2504 2477 2425 2361 2407 2411 2449 2446 2351 2579 2466 2413 2519 2410 2429 2336 2389 2416 2486 2476 2364 2468 2390 2485 2438 2442 2388 2293 2425 2553 2373 2418 2384 2357 2364 2388 2306 2443 2262 2397 2417 2419 2349 2437 2343 2396 2399 2358 2385 2409 2335 2491 2382 2389 2357 2380 2452 2396 2346 2420 2344 2448 2427 2406 2364 2346 2404 2280 2389 2246 2319 2370 2409 2429 2415 2425 2321 2387 2444 2366 2390 2375 2320 2352 2333 2370 2384 2395 2306 2367 2360 2312 2343 2369 2332 2372 2389 2482 2391 2355 2313 2323 2311 2276 2357 2269 2390 2506 2346 2377 2330 2302 2350 2328 2367 2391 2440 2302 2382 2398 2395 2362 2302 2451 2385 2371 2230 2409 2366 2427 2348 2399 2405 2354 2346 2336 2240 2313 2350 2401 2301 2393 2469 2418 2420 2339 2403 2409 2488 2551 2540 2505 2581 2599 2667 2808 2954 3270 3584 3866 4444 4901 5658 6151 6955 7719 8415 9428 10277 11101 11772 12759 13069 13633 14055 14573 14765 14697 15290 15418 15349 15363 15316 15250 15129 15024 15065 15181 15433 15451 15559 15330 15644 15637 15797 15726 15761 15866 16003 15784 15634 15255 15270 15027 14540 14377 13976 13335 13123 12316 11744 10998 10379 9735 9210 8582 7988 7211 6655 6013 5368 4829 4476 4019 3698 3382 3024 2816 2607 2572 2518 2442 2529 2395 2370 2360 2427 2356 2311 2319 2269 2356 2234 2276 2222 2249 2303 2267 2268 2245 2265 2277 2230 2182 2209 2198 2211 2189 2167 2235 2140 2161 2241 2294 2210 2253 2247 2189 2321 2238 2237 2272 2303 2220 2237 2172 2253 2174 2258 2253 2283 2191 2287 2367 2142 2249 2127 2197 2155 2138 2195 2116 2257 2223 2171 2196 2131 2207 2241 2300 2271 2215 2124 2209 2223 2226 2223 2158 2167 2148 2161 2207 2179 2226 2150 2113 2062 2087 2215 2111 2216 2151 2180 2131 2085 2121 2224 2238 2254 2091 2203 2143 2163 2214 2164 2085 2025 2053 2216 2228 2107 2197 2142 2208 2155 2056 2102 2124 2082 2103 2046 2188 2070 2111 2050 2131 2194 2126 2095 2160 2117 2032 2128 2131 2201 2145 2097 2128 2138 2043 2183 2131 2217 2123 2165 2114 2076 2080 2148 2085 2078 2097 2125 2148 2043 2139 2088 2028 2155 2191 2163 2108 2217 2163 2129 2095 2019 2168 2049 2226 2127 2130 2192 2085 2037 2095 2155 2167 2168 2084 2055 2101 2175 2159 2138 2111 2065 2013 2073 2185 2113 2140 2090 2073 2103 2129 2215 2105 2018 2030 2133 2067 2074 2057 2088 2185 2139 2101 2144 2087 2186 2059 2151 2060 2143 2017 2115 2031 2037 2065 2121 2038 2113 2165 2061 2067 2120 2143 2122 2133 2136 2101 2055 2182 2145 2087 2028 2033 2077 2165 2108 2075 2035 2081 2152 2065 2074 2050 2104 2098 2127 2059 2120 2082 2150 2079 2095 2070 2062 2146 2194 2075 2080 2222 2138 2107 2114 2037 2115 2179 2151 2222 2073 2150 2226 2100 2088 2070 2037 2137 2065 2124 2105 2064 2058 2152 2130 2144 2118 2200 2164 2062 2190 2159 2058 2169 2116 2135 2104 2091 2209 2149 2251 2116 2153 2140 2116 2092 2113 2107 2157 2199 2104 2056 2089 2143 2155 2040 2094 2117 2126 2093 2131 2110 2159 2133 2124 2181 2086 2130 2169 2170 2069 2076 2203 2139 2090 2147 2155 2140 2170 2105 2087 2123 2120 2185 2018 2153 2114 2098 2139 2225 2078 2177 2090 2181 2033 2113 2144 2124 2080 2220 2018 2139 2173 2197 2087 2109 2112 2076 2086 2126 2201 2162 2158 2100 2165 2058 2152 2118 2156 2134 2123 2057 2214 2143 2155 2188 2182 2137 2030 2151 2123 2108 2097 2114 2208 2172 2194 2160 2115 2144 2136 2102 2193 2077 2006 2144 2104 2157 2201 2115 2135 2150 2130 2123 2150 2197 2135 2103 2094 2056 2096 2076 2182 2159 2202 2198 2164 2138 2232 2104 2103 2218 2140 2163 2164 2132 2100 2078 2081 2126 2168 2182 2222 2150 2043 2101 2135 2195 2210 2191 2122 2239 2246 2175 2093 2190 2252 2304 2087 2086 2248 2167 2169 2231 2105 2143 2234 2166 2125 2273 2233 2107 2238 2136 2218 2134 2221 2222 2275 2256 2191 2173 2202 2194 2224 2240 2326 2187 2157 2266 2234 2157 2224 2246 2082 2279 2118 2185 2166 2204 2202 2198 2201 2257 2191 2232 2176 2122 2267 2195 2256 2227 2194 2269 2194 2289 2285 2143 2229 2138 2270 2338 2339 2422 2324 2347 2302 2366 2335 2510 2583 2547 2628 2694 2772 2828 2780 2883 2830 2904 2912 2827 3108 3108 2950 3174 3007 3027 3009 3084 3096 3019 3109 3016 3044 3082 3180 3219 3231 3228 3266 3322 3437 3308 3437 3413 3279 3368 3506 3454 3460 3412 3399 3446 3435 3214 3303 3086 3123 3051 2899 2851 2796 2783 2602 2707 2545 2441 2540 2580 2320 2349 2300 2399 2378 2351 2390 2429 2295 2414 2376 2292 2270 2309 2406 2429 2356 2416 2341 2350 2420 2354 2418 2441 2411 2410 2419 2439 2348 2378 2366 2469 2356 2310 2378 2276 2339 2445 2385 2459 2398 2477 2390 2453 2452 2490 2402 2380 2406 2395 2505 2375 2438 2467 2467 2417 2433 2421 2435 2506 2463 2458 2456 2576 2545 2458 2466 2431 2546 2459 2529 2468 2486 2639 2601 2550 2491 2548 2522 2548 2499 2641 2603 2521 2592 2457 2605 2631 2597 2558 2571 2616 2626 2582 2540 2697 2618 2668 2668 2660 2657 2667 2720 2776 2837 2686 2832 2830 2835 2739 2729 2866 2817 2818 2882 2753 2863 2733 2918 2831 3022 2825 2982 2938 2906 2893 2908 2839 2963 3013 3022 2926 2884 3010 3041 2931 2959 3052 2995 2921 2885 2865 2945 3011 3000 3018 3081 2917 3032 2907 3008 3029 3016 2934 2924 3183 3051 2990 2981 3103 3141 3035 3039 3132 3121 3173 3168 3164 3150 3065 3217 3166 3204 3321 3215 3212 3134 3269 3192 3266 3175 3341 3322 3312 3218 3295 3336 3358 3394 3405 3415 3522 3455 3510 3437 3489 3584 3574 3626 3526 3547 3696 3562 3655 3721 3625 3722 3743 3819 3681 3870 3799 3795 3823 3933 3937 3907 3783 4121 4042 4037 4092 4027 4047 4175 4051 4218 4262 4245 4207 4203 4290 4433 4391 4392 4340 4502 4578 4506 4535 4720 4664 4530 4710 4842 4850 4648 4817 4894 5070 4919 4955 5127 5110 5196 5144 5249 5321 5281 5339 5563 5656 5453 5510 5721 5740 5853 5970 5875 5880 5894 6283 6218 6287 6427 6380 6567 6597 6765 6794 6707 6906 7033 7174 7194 7229 7428 7568 7741 7726 7806 8007 8159 8192 8254 8434 8568 8697 9064 8880 9139 9380 9375 9657 9768 9889 10085 10357 10566 10711 10783 11199 11551 11791 11891 12168 12636 12659 13195 13565 13944 14109 14582 14840 15331 15614 16476 16799 17482 17872 18480 19412 19813 20799 22496 24867 28640 32855 38953 45843 53739 65010 76276 94213 116860 168607 317968 595333 920971 1266657 1624251 1971493 2355800 2724113 3198272 3667062 4173097 4656723 5140680 5585552 5948332 6166945 6159800 6059694 5925695 5739752 5542998 5316404 5003596 4586653 4088543 3605206 3065184 2568892 2046330 1644022 1354117 1129409 927821 729860 546930 360604 232082 157087 125317 106971 94762 85933 77445 70704 63742 57405 51912 46810 42083 37917 33895 30885 27429 24579 22232 20072 18498 17030 15127 14148 13403 12684 12271 12014 11677 11637 11186 10835 10770 10360 10288 10039 9753 9528 9287 9295 8983 8917 8700 8430 8374 8385 8114 7803 7807 7814 7513 7443 7399 7377 7408 7307 6967 6938 7096 6665 6770 6523 6585 6403 6309 6386 6198 6062 6033 5973 5823 5994 5860 5829 5723 5656 5467 5466 5341 5275 5363 5275 5260 5321 5215 5133 5046 5129 4909 4957 4831 4815 4849 4603 4671 4632 4701 4653 4566 4414 4429 4361 4394 4381 4344 4306 4202 4260 4242 4250 4274 4210 3937 3999 3964 4103 3986 3834 3837 3974 3901 3906 3923 3842 3771 3799 3773 3779 3690 3710 3564 3669 3667 3555 3464 3498 3564 3557 3527 3451 3468 3455 3352 3438 3424 3279 3378 3449 3328 3347 3354 3299 3417 3234 3236 3291 3290 3173 3151 3186 3141 3120 3143 3111 3201 3101 3055 3093 3126 3103 2994 3035 2952 3099 3006 2895 2896 2920 2880 2965 2863 2905 2903 2774 2875 2943 3016 2856 2812 2801 2802 2822 2911 2777 2775 2746 2713 2755 2747 2724 2862 2720 2706 2675 2741 2614 2775 2662 2625 2600 2724 2669 2647 2657 2628 2687 2563 2703 2639 2572 2577 2521 2575 2553 2536 2554 2536 2587 2482 2510 2531 2492 2468 2570 2534 2562 2524 2468 2532 2567 2450 2451 2395 2495 2469 2346 2548 2428 2522 2368 2416 2402 2519 2515 2408 2414 2443 2526 2402 2446 2587 2518 2537 2555 2590 2588 2640 2502 2544 2670 2575 2568 2544 2561 2483 2584 2639 2451 2578 2563 2565 2515 2620 2601 2577 2565 2602 2607 2511 2585 2607 2629 2548 2448 2530 2565 2562 2447 2495 2505 2400 2335 2466 2777 3890 4773 4972 4964 4718 4066 3241 2631 2258 2221 2423 2906 3769 4233 4817 4917 4829 4856 4445 3335 2450 2127 2074 2117 2215 2093 2119 2083 2093 2111 2134 2159 2084 2108 2050 2127 1974 2160 2046 2082 2101 2055 2222 2014 2002 2247 2023 2053 1988 2025 2074 2011 1996 2066 1978 2039 1956 2012 2027 2054 2013 2046 1999 2058 2018 1946 2009 2042 2009 2055 1940 2007 1997 2088 1958 2040 1901 2006 2055 1889 2005 2021 1996 1920 1948 1980 1994 2004 2039 2007 1859 1928 1911 2029 1969 1912 2034 1989 1937 1924 1880 1979 1966 1943 1953 1868 1940 1948 1998 1896 1942 1955 1946 1881 1880 1943 1866 1894 1936 1937 1891 1880 1994 2019 1891 1911 1935 1896 1920 1952 1943 1916 1968 1852 1869 1826 1945 1885 1929 1900 1941 1999 1817 1751 1932 1987 1952 1894 1864 2105 1852 1935 1719 1944 1964 1878 1992 1990 1951 1910 1925 1916 1915 1955 1919 1881 1950 1987 1940 1994 1960 2007 2008 1930 1899 1916 1913 1976 1885 1971 2064 2019 1915 1971 1971 1974 2009 1887 1961 2016 2018 1990 1957 2003 1994 2023 1982 2010 1953 1994 2064 2009 1892 1911 1952 1984 1995 1962 1953 1974 1984 1903 1786 1903 1929 1884 1786 1797 1804 1886 1875 1843 1766 1809 1752 1804 1904 1730 1740 1830 1804 1900 1778 1836 1836 1892 1781 1761 1792 1817 1695 1745 1777 1763 1741 1845 1688 1814 1815 1834 1840 1733 1823 1831 1749 1822 1773 1785 1786 1819 1757 1844 1787 1700 1773 1812 1793 1839 1830 1787 1685 1770 1815 1793 1837 1696 1822 1791 1838 1721 1769 1667 1795 1737 1832 1761 1848 1793 1846 1699 1745 1804 1641 1787 1751 1817 1713 1746 1798 1750 1712 1735 1879 1764 1614 1726 1787 1597 1832 1556 1782 1737 1756 1810 1634 1876 1723 1775 1745 1823 1760 1744 1779 1814 1801 1765 1732 1751 1744 1817 1690 1760 1805 1816 1863 1839 1829 1830 1859 1826 1787 1731 1806 1791 1877 1790 1822 1821 1846 1823 1838 1835 1862 1740 1841 1866 1778 1801 1793 1801 1796 1818 1854 1864 1706 1785 1700 1884 1696 1835 1832 1855 1782 1698 1831 1712 1747 1814 1740 1809 1767 1750 1772 1739 1659 1815 1740 1647 1811 1752 1606 1738 1675 1731 1768 1646 1884 1721 1729 1708 1708 1781 1710 1767 1650 1770 1646 1629 1705 1612 1762 1676 1742 1745 1710 1771 1670 1677 1699 1706 1847 1709 1812 1765 1654 1791 1795 1712 1635 1780 1725 1661 1800 1794 1544 1880 1690 1760 1825 1583 1741 1664 1809 1786 1767 1681 1791 1790 1681 1829 1737 1659 1710 1727 1653 1713 1666 1817 1781 1716 1690 1750 1757 1784 1749 1701 1663 1762 1755 1809 1703 1838 1784 1694 1727 1779 1826 1861 1781 1719 1686 1715 1776 1843 1797 1712 1723 1744 1846 1773 1811 1820 1782 1800 1840 1813 1788 1753 1707 1868 1785 1759 1697 1709 1756 1707 1736 1799 1659 1734 1804 1728 1794 1765 1775 1795 1739 1714 1663 1771 1758 1618 1735 1773 1800 1782 1754 1817 1730 1787 1689 1733 1725 1674 1650 1708 1791 1830 1669 1749 1728 1704 1777 1790 1703 1769 1782 1758 1723 1812 1612 1748 1739 1761 1634 1646 1681 1711 1809 1664 1669 1727 1807 1695 1823 1667 1775 1793 1753 1752 1732 1824 1727 1664 1599 1802 1758 1808 1756 1771 1668 1793 1663 1669 1682 1778 1700 1819 1823 1751 1704 1836 1812 1786 1742 1746 1680 1753 1735 1775 1854 1685 1844 1777 1737 1717 1592 1634 1745 1747 1785 1779 1735 1723 1705 1694 1745 1783 1668 1781 1806 1815 1749 1823 1769 1666 1586 1712 1756 1844 1751 1794 1757 1707 1744 1739 1837 1647 1683 1659 1806 1709 1742 1750 1680 1687 1733 1772 1794 1655 1761 1751 1696 1704 1755 1732 1788 1787 1798 1844 1891 1890 1902 1967 1903 1952 1958 1952 2070 2078 2118 1984 2036 2098 1981 2120 2093 2041 2139 2002 2091 2140 2150 1972 2068 2017 2073 2131 2036 2127 2077 2079 2133 2246 2152 2227 2277 2111 2174 2278 2267 2229 2228 2100 2203 2097 2097 2129 2053 2007 1935 1939 1913 1972 1827 1952 1906 1838 1812 1863 1913 1864 1859 1686 1802 1830 1770 1834 1832 1704 1865 1674 1692 1844 1713 1721 1729 1842 1758 1724 1729 1799 1790 1789 1911 1833 1913 1725 1806 1794 1795 1870 1803 1782 1775 1727 1806 1780 1769 1841 1776 1796 1834 1828 1695 1849 1758 1796 1821 1794 1751 1783 1887 1749 1860 1800 1796 1834 1892 1769 1832 1903 1789 1859 1722 1877 1698 1652 1869 1855 1832 1819 1816 1840 1935 1915 1833 1860 1881 1961 2010 1943 2021 1985 1983 2033 2005 2068 2172 2122 2150 2164 2236 2105 2155 2301 2195 2111 2149 2221 2226 2219 2241 2287 2239 2249 2223 2219 2281 2299 2385 2264 2266 2304 2271 2263 2210 2364 2271 2317 2308 2270 2221 2315 2294 2267 2120 2172 2187 2182 2037 2011 2048 2087 2010 2049 2008 1906 1889 1906 1833 1855 1889 1892 1949 1874 1929 1848 1928 1846 1922 1880 1810 1771 1911 1864 1880 1894 1895 2012 1815 1831 1806 1938 1814 1853 1869 1895 1727 1898 1836 1844 1901 1879 1856 1976 1871 1792 1864 1923 1866 1892 1943 1867 1977 1892 1862 1921 1951 1956 2018 1959 1969 1970 1921 1980 1958 1934 1993 1940 2012 1980 1962 1968 2002 1948 2017 2064 1968 1958 1950 1956 2034 1950 2030 2022 1999 2033 1982 2085 2011 2033 2061 2075 1854 2009 1994 2076 2067 1943 1921 2087 1890 1831 1968 1894 1946 1969 1938 1901 1923 1929 1861 1885 1929 1926 1879 1932 1837 1934 1879 1983 1843 1840 1941 1960 1877 1891 1955 1873 1843 1847 1925 1886 1966 1797 1929 1962 1899 1911 1836 1919 1922 1875 1969 1879 1924 1837 1869 1840 1896 1912 1910 1877 1935 1877 1985 1863 1970 1924 1921 1892 1944 1878 1830 1928 1974 1918 1882 1869 1925 1890 1937 1962 1917 1954 1940 1829 2056 1849 1862 1848 1935 1925 1850 1955 1835 1951 1908 1880 1917 1914 1943 1952 1970 1976 1986 1957 1989 1948 1988 1958 1942 1976 1991 1985 1919 1967 1962 1990 1923 1965 1881 1966 1977 1933 1978 2005 1995 1993 1909 1987 1948 1950 1971 1985 1974 2087 2011 2056 2011 1877 2042 2040 1938 2005 2026 1980 1986 1940 1950 2018 1992 2063 1910 2024 1962 1964 2089 1965 1909 2058 2003 1941 2122 1993 1986 2076 2034 2030 1961 1983 2014 1967 1962 1814 1941 1999 1968 2082 1971 1977 2037 2039 2049 2062 1988 1918 2084 2016 2040 2065 1980 2035 1960 1968 1991 2076 1996 1995 1984 2076 1985 2052 2033 2001 1997 2032 2077 2061 2012 2033 2016 2062 2115 2113 2047 1990 2014 2019 2053 2063 2002 2041 2030 1970 2056 2137 1956 2011 2018 2016 1986 2067 2052 2028 2102 2071 1976 2109 1955 1993 2048 1992 1938 2077 1982 2070 1990 2092 1996 2004 2078 2053 2001 1980 2040 2056 2076 2072 2150 2134 2007 2046 2127 2076 2107 1940 2028 2142 2060 1988 2076 2072 2051 1997 2069 2085 2071 2008 2147 1955 2151 2005 2091 2042 2078 2109 2109 2095 2056 2080 2141 2202 1959 2060 2135 2159 2187 2078 2265 2056 2000 2098 2110 2098 2083 2089 2114 2087 2066 2105 2085 2101 2202 2122 1981 2117 2111 2108 2009 2138 2171 2144 2056 2096 2068 2112 2103 2125 2041 2177 2191 2168 2223 2070 2187 2065 2124 2054 2099 2053 2107 2126 2019 2102 2144 2176 2068 2184 2127 2098 2137 2134 2185 2161 2077 2109 2076 2115 2116 2049 2191 2094 2162 2196 2144 2155 2145 2158 2098 2170 2043 2147 2074 2119 2094 2061 2252 2154 2192 2176 2054 2164 2116 2202 2205 2128 2155 2111 2185 2119 2142 2127 2256 2191 2180 2198 2123 2179 2093 2150 2150 2139 2167 2201 2191 2169 2252 2208 2222 2162 2177 2217 2167 2176 2214 2145 2182 2248 2212 2134 2197 2251 2255 2175 2229 2202 2253 2048 2146 2174 2204 2273 2203 2126 2238 2111 2203 2229 2239 2146 2215 2201 2253 2212 2186 2214 2121 2148 2173 2218 2131 2196 2152 2182 2139 2172 2325 2241 2185 2118 2294 2258 2206 2264 2158 2266 2227 2233 2255 2187 2111 2276 2230 2224 2178 2194 2213 2311 2236 2283 2256 2189 2205 2181 2306 2309 2357 2370 2231 2233 2285 2173 2317 2290 2196 2341 2223 2313 2193 2315 2209 2359 2265 2360 2276 2243 2291 2297 2270 2239 2213 2323 2353 2337 2286 2287 2324 2280 2299 2330 2296 2273 2248 2339 2179 2314 2286 2189 2404 2290 2300 2294 2229 2279 2340 2259 2310 2199 2287 2216 2296 2279 2304 2350 2318 2378 2303 2275 2279 2412 2338 2270 2350 2307 2217 2432 2451 2298 2301 2310 2267 2338 2277 2395 2411 2340 2382 2384 2406 2357 2225 2388 2302 2329 2332 2342 2378 2293 2322 2289 2316 2312 2452 2327 2318 2370 2324 2289 2261 2334 2350 2341 2398 2467 2342 2304 2341 2414 2466 2411 2347 2517 2411 2393 2308 2355 2389 2379 2356 2396 2335 2472 2315 2491 2335 2430 2423 2408 2320 2314 2432 2440 2483 2469 2382 2368 2436 2355 2496 2476 2483 2476 2492 2488 2415 2476 2509 2500 2541 2456 2522 2456 2466 2518 2439 2499 2446 2457 2456 2521 2566 2486 2495 2546 2620 2716 2767 2797 3082 3041 3193 3358 3447 3800 3909 4048 4454 4629 4696 5173 5185 5430 5475 5696 5867 5990 5808 5945 6062 6172 5997 6251 6455 5999 6279 6196 6181 6232 6241 6226 6342 6278 6250 6265 6451 6491 6528 6421 6529 6465 6307 6188 6328 6178 6062 5990 5925 5587 5623 5408 5222 4993 4829 4673 4540 4287 3970 3787 3759 3554 3206 3220 3173 3011 2857 2864 2689 2640 2575 2550 2547 2553 2610 2570 2611 2583 2641 2599 2674 2639 2522 2533 2582 2543 2656 2451 2587 2611 2565 2506 2518 2558 2569 2628 2484 2662 2576 2592 2657 2453 2516 2601 2605 2557 2615 2712 2587 2592 2635 2519 2549 2592 2576 2476 2628 2612 2541 2596 2555 2573 2550 2652 2533 2546 2586 2636 2592 2644 2681 2584 2625 2646 2664 2671 2547 2563 2631 2674 2565</counts>
			</dataPoints>
		</scan>
	</xrdMeasurement>
</xrdMeasurements>