File: Data Files/Full/MSS p (6-129, 5w)_01_1.xrdml
<?xml version="1.0"?>
<xrdMeasurements xmlns="http://www.xrdml.com/XRDMeasurement/2.2" xmlns:xsi="http://www.w3.org/2001/XMLSchema-instance" xsi:schemaLocation="http://www.xrdml.com/XRDMeasurement/2.2 http://www.xrdml.com/XRDMeasurement/2.2/XRDMeasurement.xsd" status="Completed" recordIdentifier="{C011C175-04DA-4CBD-916A-97D9960F148F}">
	<comment>
		<entry/>
	</comment>
	<sample type="To be analyzed">
		<id>p</id>
		<name></name>
		<preparedBy></preparedBy>
	</sample>
	<xrdMeasurement measurementType="Scan" status="Completed" sampleMode="Reflection">
		<usedWavelength intended="K-Alpha 1">
			<kAlpha1 unit="Angstrom">1.5405980</kAlpha1>
			<kAlpha2 unit="Angstrom">1.5444260</kAlpha2>
			<kBeta unit="Angstrom">1.3922500</kBeta>
			<ratioKAlpha2KAlpha1>0.5000</ratioKAlpha2KAlpha1>
		</usedWavelength>
		<incidentBeamPath>
			<radius unit="mm">145.00</radius>
			<xRayTube id="1010048" name="Empyrean Cu LFF HR (9430 033 7310x) DK437964">
				<tension unit="kV">40.0</tension>
				<current unit="mA">15.0</current>
				<anodeMaterial>Cu</anodeMaterial>
				<focus type="Line">
					<length unit="mm">12.0</length>
					<width unit="mm">0.4</width>
					<takeOffAngle unit="deg">6.0</takeOffAngle>
				</focus>
			</xRayTube>
			<filter id="20010004" name="Beta-filter Nickel">
				<material>Ni</material>
				<thickness unit="mm">0.020</thickness>
			</filter>
			<sollerSlit id="21010002" name="Soller slits 0.04 rad.">
				<opening unit="rad">0.0400</opening>
			</sollerSlit>
			<mask id="22031000" name="Fixed mask 13 mm">
				<width unit="mm">9.00</width>
			</mask>
			<divergenceSlit id="22120002" name="Divergence slit 1/2°" xsi:type="fixedDivergenceSlitType">
				<distanceToSample unit="mm">50.00</distanceToSample>
				<height unit="mm">0.76</height>
			</divergenceSlit>
		</incidentBeamPath>
		<diffractedBeamPath>
			<radius unit="mm">145.00</radius>
			<parallelPlateCollimator id="25020001" name="Parallel plate collimator 0.28°">
				<opening unit="deg">0.28</opening>
			</parallelPlateCollimator>
			<detector id="7010020" name="PIXcel3D-Medipix3 1x1 detector" xsi:type="areaDetectorType">
				<phd unit="keV">
					<lowerLevel>4.0</lowerLevel>
					<upperLevel>11.3</upperLevel>
				</phd>
				<mode>Receiving slit</mode>
				<activeChannelsEquatorial>255</activeChannelsEquatorial>
				<activeChannelsAxial>255</activeChannelsAxial>
				<pitchEquatorial unit="mm">0.05500</pitchEquatorial>
				<pitchAxial unit="mm">0.05500</pitchAxial>
				<readOutPeriod unit="seconds">0.050</readOutPeriod>
			</detector>
		</diffractedBeamPath>
		<scan appendNumber="0" mode="Continuous" scanAxis="2Theta" status="Completed">
			<header>
				<startTimeStamp>2025-06-23T13:16:41-08:00</startTimeStamp>
				<endTimeStamp>2025-06-24T02:56:46-08:00</endTimeStamp>
				<author>
					<name>Instrument</name>
				</author>
				<source>
					<applicationSoftware version="1.6 (94)">PANalytical Aeris Instrument Suite</applicationSoftware>
					<instrumentControlSoftware version="3.0.0 20211014">AERIS</instrumentControlSoftware>
					<instrumentID>2855484</instrumentID>
				</source>
			</header>
			<dataPoints>
				<positions axis="2Theta" unit="deg">
					<startPosition>6.005</startPosition>
					<endPosition>128.995</endPosition>
				</positions>
				<positions axis="Omega" unit="deg">
					<commonPosition>5.000</commonPosition>
				</positions>
				<commonCountingTime unit="seconds">3.520</commonCountingTime>
				<counts 4905 4678 4720 4776 4702 4680 4739 4711 4655 4710 4630 4551 4469 4673 4528 4659 4543 4653 4440 4464 4518 4534 4586 4433 4518 4447 4376 4553 4426 4337 4372 4386 4447 4499 4383 4422 4469 4332 4416 4281 4367 4420 4288 4273 4322 4391 4388 4301 4420 4375 4531 4323 4272 4232 4388 4345 4320 4223 4217 4258 4376 4282 4294 4333 4319 4238 4305 4284 4332 4217 4327 4292 4255 4372 4288 4468 4325 4175 4271 4199 4252 4209 4350 4266 4236 4349 4256 4179 4197 4180 4108 4163 4141 4177 4123 4232 4212 4194 4225 4173 4125 4207 4162 4227 4163 4292 4191 4057 4145 4191 4099 4156 4264 4120 4057 4132 3996 4176 4009 4192 3934 4155 4193 4174 4003 4031 4105 4053 3988 3983 4043 4051 3943 3920 3956 4132 3943 4191 3960 4031 4010 4061 3844 4046 3830 4111 3827 3979 3894 3908 3936 3903 3824 4036 3975 3759 3801 4038 3838 3895 3817 3958 3872 3981 3952 3994 3838 4071 3920 4035 4037 3793 4029 4039 4116 3969 4055 3999 4007 4134 3970 4120 4180 4045 4178 4036 4069 4082 4167 4144 4132 4000 4055 4181 4074 4053 4140 4127 4026 4154 4108 3993 4032 4076 4190 4140 4100 4150 4098 3980 4006 3974 3981 3908 4111 4004 3995 3933 3895 3922 3762 3743 3844 3823 3772 3753 3602 3693 3806 3674 3589 3602 3634 3672 3449 3570 3571 3521 3451 3487 3489 3434 3414 3412 3416 3468 3411 3323 3267 3322 3375 3353 3391 3315 3431 3342 3315 3189 3268 3306 3239 3390 3304 3419 3290 3288 3290 3320 3358 3307 3338 3284 3362 3338 3400 3334 3347 3244 3267 3218 3366 3218 3303 3244 3266 3265 3332 3189 3302 3237 3236 3279 3192 3293 3320 3213 3335 3334 3186 3304 3251 3221 3290 3204 3323 3280 3172 3168 3213 3353 3246 3325 3233 3308 3103 3238 3277 3256 3188 3246 3219 3284 3227 3359 3306 3340 3322 3217 3313 3262 3329 3161 3353 3223 3440 3180 3152 3334 3300 3313 3248 3215 3311 3374 3110 3224 3314 3257 3206 3185 3362 3249 3380 3274 3354 3278 3243 3177 3175 3302 3237 3242 3326 3307 3189 3270 3239 3314 3349 3369 3264 3254 3340 3274 3354 3264 3351 3393 3207 3324 3256 3273 3286 3158 3296 3373 3202 3360 3448 3388 3327 3252 3343 3312 3313 3329 3274 3353 3308 3362 3333 3307 3365 3478 3330 3402 3343 3409 3424 3382 3397 3505 3367 3422 3380 3412 3401 3397 3373 3407 3363 3355 3281 3360 3493 3427 3543 3418 3438 3424 3507 3466 3423 3515 3500 3499 3411 3583 3507 3373 3509 3467 3509 3448 3491 3489 3523 3564 3434 3552 3485 3550 3508 3463 3609 3707 3462 3565 3558 3646 3556 3581 3538 3602 3662 3642 3518 3511 3523 3607 3646 3586 3481 3598 3487 3609 3678 3555 3658 3679 3675 3638 3729 3662 3663 3727 3654 3839 3672 3707 3750 3634 3699 3731 3727 3743 3648 3797 3741 3770 3695 3753 3715 3860 3775 3762 3740 3884 3842 3719 3810 3669 3702 3822 3759 3787 3762 3842 3688 3752 3905 3854 3850 3912 4018 3716 3875 3912 3953 4042 3997 3854 3993 3928 4000 3816 3984 3784 4023 3988 3953 3942 3936 4030 3965 4042 4049 3871 4031 3967 4018 3948 3967 3988 4090 3980 4001 4182 4112 4028 4094 4156 4143 4164 4000 4024 4130 4171 4132 4106 4272 4180 4133 4136 4242 4211 4401 4361 4176 4223 4259 4208 4137 4263 4234 4234 4341 4223 4389 4252 4317 4296 4408 4397 4231 4144 4375 4385 4241 4511 4367 4388 4462 4453 4396 4266 4405 4374 4387 4444 4421 4375 4336 4344 4448 4520 4474 4615 4492 4614 4641 4567 4652 4550 4515 4709 4595 4559 4516 4553 4588 4602 4701 4677 4528 4685 4504 4755 4676 4659 4687 4755 4751 4721 4737 4639 4557 4892 4832 4693 4898 4993 4811 4740 4765 4672 4848 4893 4952 4807 4899 4811 4836 5010 4936 5036 4765 4815 4966 4831 5046 4889 5052 5029 5115 4955 4960 5093 4972 5004 5213 5091 5038 5019 5227 5086 5204 5255 5114 5204 5176 5187 5094 5253 5198 5206 5325 5269 5198 5189 5311 5252 5309 5456 5302 5171 5327 5252 5342 5326 5502 5326 5348 5315 5308 5336 5462 5385 5493 5437 5432 5300 5436 5516 5560 5342 5433 5420 5598 5358 5411 5415 5320 5487 5431 5436 5503 5396 5389 5561 5584 5500 5502 5603 5495 5506 5543 5641 5490 5552 5574 5701 5600 5479 5618 5560 5625 5515 5669 5725 5601 5590 5632 5589 5572 5656 5787 5684 5710 5630 5609 5686 5713 5696 5527 5836 5691 5610 5792 5752 5860 5771 5754 5672 5889 5763 5743 5668 5825 5501 5702 5753 5716 5631 5788 5730 5742 5906 5754 5818 5527 5728 5577 5729 5612 5576 5524 5619 5756 5568 5571 5754 5719 5734 5689 5614 5585 5699 5748 5606 5615 5711 5490 5615 5610 5741 5508 5721 5631 5468 5712 5664 5611 5460 5648 5636 5534 5622 5426 5665 5542 5475 5626 5455 5490 5525 5512 5351 5424 5279 5435 5418 5522 5448 5419 5419 5422 5444 5416 5332 5365 5258 5354 5431 5331 5346 5300 5378 5358 5190 5269 5229 5265 5322 5191 5135 5204 5377 5183 5094 5264 5067 5206 5111 5109 5122 5188 5122 5141 4971 5165 5005 4995 5153 4974 5062 5066 4934 4971 4888 4932 4930 4887 4883 5044 4811 4870 5031 4977 5048 4796 4829 4964 4879 4924 4764 4823 4849 4750 4741 4713 4882 4733 4634 4786 4828 4783 4802 4637 4889 4612 4721 4535 4558 4665 4593 4675 4679 4561 4575 4580 4544 4626 4510 4565 4632 4556 4560 4591 4473 4473 4439 4420 4355 4448 4320 4419 4399 4407 4427 4412 4419 4307 4281 4203 4403 4288 4365 4227 4278 4328 4182 4147 4169 4250 4153 4086 4209 4285 4152 4098 4192 4068 3983 4175 4013 4104 4069 4215 4049 4147 4109 3979 4067 4103 4055 4043 3914 3948 3992 3928 4006 4048 3910 3926 3961 3919 3953 3957 3970 3886 3881 3981 3931 3794 3782 3825 3789 3872 3837 3734 3950 3846 3715 3698 3864 3690 3724 3776 3905 3681 3796 3702 3747 3792 3619 3666 3689 3674 3693 3748 3732 3753 3542 3586 3660 3589 3647 3561 3703 3479 3515 3493 3636 3648 3681 3542 3512 3471 3583 3561 3576 3496 3497 3518 3593 3369 3587 3610 3412 3360 3435 3526 3414 3493 3318 3383 3531 3518 3332 3539 3313 3441 3407 3449 3417 3500 3400 3355 3323 3381 3416 3300 3304 3347 3288 3405 3426 3361 3313 3343 3304 3283 3428 3208 3377 3254 3324 3314 3327 3330 3192 3310 3222 3232 3234 3114 3261 3183 3237 3222 3210 3067 3223 3202 3174 3120 3138 3106 3175 3176 3191 3119 3144 3122 3150 3084 3120 3047 3127 3050 3158 3137 3040 2992 3169 3200 3100 3170 3000 3144 3124 3047 3132 3008 2943 2982 3040 3030 2995 3157 3030 3083 2921 3029 2990 3048 2833 2932 2934 3051 2929 2975 2953 2878 2995 2967 2984 2926 3013 2947 3008 2887 2970 2883 2975 2891 2895 2962 2931 2821 2940 2969 3076 2818 2737 2857 2996 2959 2851 2942 2847 2923 2883 2775 2946 2839 2863 2988 2829 2827 2794 2773 2826 2787 2851 2838 2843 2824 2788 2860 2735 2844 2865 2718 2773 2778 2800 2733 2798 2829 2802 2764 2825 2777 2765 2762 2725 2659 2754 2722 2733 2863 2697 2744 2711 2737 2695 2800 2794 2754 2814 2661 2685 2734 2707 2695 2817 2771 2759 2741 2675 2624 2679 2674 2725 2622 2727 2731 2708 2636 2798 2719 2787 2717 2704 2612 2630 2699 2651 2630 2709 2732 2768 2748 2720 2680 2755 2775 2835 3025 3076 3240 3466 3590 3864 3960 4176 4420 4894 5125 5214 5506 5762 5931 6188 6307 6612 6608 6942 6954 7087 7243 7503 7320 7377 7436 7212 7332 6971 6939 6829 6550 6324 5859 5661 5278 5053 4666 4229 4045 3781 3398 3235 3038 2837 2802 2638 2561 2533 2598 2642 2635 2601 2486 2533 2559 2547 2583 2525 2504 2575 2605 2588 2540 2536 2442 2587 2565 2612 2467 2538 2469 2543 2588 2458 2473 2487 2493 2455 2401 2512 2474 2461 2501 2424 2536 2484 2363 2459 2512 2439 2375 2514 2466 2429 2458 2437 2450 2470 2513 2413 2435 2453 2514 2411 2476 2492 2448 2382 2512 2379 2433 2480 2409 2500 2380 2374 2448 2519 2590 2336 2458 2423 2420 2476 2489 2320 2430 2246 2578 2376 2477 2392 2398 2407 2397 2433 2423 2413 2392 2389 2311 2334 2379 2408 2281 2391 2385 2301 2462 2380 2365 2420 2346 2343 2381 2368 2302 2325 2231 2478 2360 2302 2377 2371 2350 2394 2320 2309 2341 2292 2350 2322 2274 2311 2326 2246 2393 2314 2359 2336 2339 2341 2258 2300 2327 2346 2282 2300 2325 2310 2361 2260 2265 2218 2282 2242 2142 2171 2289 2257 2191 2298 2270 2223 2276 2297 2303 2337 2350 2227 2357 2290 2244 2238 2252 2309 2223 2246 2200 2314 2230 2187 2180 2220 2298 2344 2245 2226 2307 2147 2259 2269 2277 2342 2182 2261 2290 2208 2166 2224 2312 2271 2211 2141 2155 2136 2122 2151 2261 2180 2220 2218 2261 2200 2150 2218 2243 2226 2292 2282 2199 2164 2235 2154 2277 2222 2220 2184 2191 2262 2190 2118 2222 2096 2188 2123 2197 2195 2107 2141 2117 2148 2194 2127 2134 2105 2132 2178 2164 2191 2117 2210 2179 2129 2204 2258 2132 2156 2114 2153 2281 2146 2143 2148 2205 2194 2212 2194 2133 2186 2171 2076 2292 2147 2095 2075 2127 2174 2087 2087 2197 2172 2139 2206 2224 2104 2105 2116 2157 2061 2081 2260 2076 2196 2120 2188 2106 2063 2159 2031 2187 2155 2167 2140 2146 2152 2091 2073 2126 2235 2146 2152 2124 2125 2084 2123 2138 2093 2178 2150 2149 2181 2118 2010 2165 2065 2013 2092 2123 2096 2072 2202 2132 2083 2113 2090 2075 2158 2153 2087 2077 2123 2038 2075 2162 2222 2123 2147 2102 2017 2120 2013 2122 2154 2076 2125 2104 2021 2143 2083 2154 2108 2079 1972 2115 2085 2122 2134 2077 2171 2219 2165 2177 2084 2142 2173 2089 2113 2128 2256 2136 2211 2158 2219 2200 2240 2220 2200 2261 2215 2330 2239 2466 2588 2728 2908 3199 3579 4001 4372 4914 5538 5952 6587 6870 7675 8270 8708 9641 9536 10329 10846 11188 11816 12396 13041 13272 13487 14061 14245 14488 14439 14415 14609 14141 13816 13393 12808 11970 11151 10232 9140 8445 7453 6560 5669 5063 4336 3865 3522 3068 2809 2499 2537 2426 2302 2373 2285 2289 2277 2298 2346 2148 2113 2161 2183 2177 2151 2098 2097 2097 2133 2155 2186 2098 2094 1993 2030 2024 2190 1943 2018 2040 2003 2093 2057 2043 2053 1943 2118 2056 2080 2022 2024 2075 2043 2019 1952 2055 2059 1996 1949 2020 2128 2052 1973 1994 2091 2060 1922 2045 1966 2018 1985 2073 2093 1966 1979 2096 2052 1992 2061 1974 2014 2015 1919 1925 2032 1994 2027 2040 2063 1991 2094 1966 1910 2051 2058 1926 1995 2031 2021 2034 2036 2017 2033 2045 2015 2015 2041 2019 1979 2018 1909 2050 1867 1977 1983 2050 1951 1872 2049 2005 2035 1975 1916 1960 2094 2053 1977 1945 2067 1988 1931 1993 2025 2024 2038 1945 1885 1972 2018 1949 2028 2029 2072 1995 2013 2037 1914 2012 2064 1996 1910 2021 1931 1984 1987 1955 1902 2000 1919 1996 1905 2000 1925 1939 2068 1920 1999 1960 2046 2042 2010 1983 1966 1970 2059 1972 2020 1893 1998 1993 1915 1976 1928 1913 1976 1870 1838 2022 2006 1969 1882 1985 1988 1947 2051 2013 1929 1976 1903 1988 1907 1981 1925 1961 1880 1974 1928 1981 1944 1976 1929 1920 1936 1927 1951 1951 1948 1942 2009 1955 1938 1886 1931 2021 1987 1950 1855 1941 1896 1941 1996 2050 2039 1907 1902 1974 2052 2011 1957 2061 1942 1909 1841 1970 2042 1899 1926 1875 1964 1957 1984 1968 1940 1984 1939 1919 1959 1926 1957 1979 1950 1917 1937 1910 1971 1934 1903 1995 1996 1976 2035 2007 1969 2094 1942 1938 2001 2016 1893 2004 1979 1921 1964 1907 1933 1977 1852 2073 1964 2004 1957 1966 1960 1938 2013 1907 2039 1934 1951 1980 2045 1939 1955 1915 1961 2010 1939 1916 1910 1967 1986 2008 1978 1947 1919 1879 2001 2031 2014 1920 2068 2010 1990 2085 2018 2008 2065 2064 2151 2380 2337 2560 2658 2942 3044 3291 3560 3721 3993 4351 4535 4912 5157 5249 5422 5630 5876 6087 6221 6354 6493 7024 6979 6838 6993 7071 6983 6748 6805 6598 6607 6136 6038 5887 5583 5092 4654 4183 3916 3664 3359 3099 2820 2680 2457 2266 2261 2246 2030 2092 2056 2054 2024 1981 1890 1961 2018 2073 2053 2020 2025 1957 1980 1855 1993 2059 2062 1978 1913 1958 2102 1911 2053 1962 1957 1910 1908 1851 1949 2016 2040 1939 1992 1943 1920 1959 1886 1914 1971 1980 1947 2068 1968 1995 1934 2010 1937 1942 1937 2002 1960 1990 1968 1859 2040 1997 1925 1939 1960 1943 1975 1869 1945 2101 1914 1948 1988 1967 1935 1946 1989 1882 1927 1971 2003 1941 1955 1978 1945 1923 1935 1964 1977 1994 1884 1973 1987 2007 1950 1960 2000 1995 2008 2012 1859 1950 2038 1993 1882 1986 2005 1963 1940 2063 1904 1954 1879 1883 1963 2031 2067 1951 1963 1958 2037 2003 2006 2007 2081 2004 2047 2100 2075 2051 2032 2123 2087 2195 2107 2109 2190 2169 2264 2181 2236 2158 2173 2254 2135 2178 2179 2172 2140 2126 2219 2065 2139 2044 2028 2072 2088 2069 2074 2016 2085 2050 2049 1980 2056 2078 2015 2071 1921 1967 2008 2067 2044 2038 2076 2109 2069 2064 2075 2066 2100 2047 2039 2106 2089 2084 2154 2096 1979 2065 2042 1995 2019 2060 2075 2108 2155 1998 2069 1994 2144 2164 2088 2111 2083 2044 2052 2029 2012 2099 2066 2099 2153 2072 2102 2147 2192 2075 2091 2153 2225 2222 2136 2083 2140 2147 2165 2169 2083 2143 2136 2221 2220 2130 2263 2264 2193 2257 2199 2141 2184 2285 2307 2147 2246 2244 2216 2196 2313 2351 2282 2230 2198 2301 2332 2222 2290 2334 2299 2304 2291 2209 2313 2305 2344 2304 2444 2276 2378 2354 2399 2453 2478 2413 2403 2438 2427 2391 2441 2474 2569 2385 2420 2440 2527 2541 2467 2518 2532 2504 2483 2526 2618 2614 2511 2642 2611 2622 2557 2561 2692 2627 2686 2678 2607 2640 2721 2725 2596 2578 2721 2785 2770 2811 2791 2798 2803 2737 2856 2914 2859 2847 2953 2948 2855 2856 2898 2997 2902 2889 2993 2978 2926 2932 3041 3080 3100 3079 3053 3029 3108 3120 3061 3153 3141 3136 3166 3211 3186 3215 3212 3211 3256 3205 3294 3248 3170 3323 3262 3336 3263 3273 3282 3255 3303 3357 3392 3306 3327 3314 3355 3350 3330 3514 3383 3323 3312 3360 3312 3489 3258 3373 3288 3441 3274 3340 3378 3329 3378 3354 3361 3286 3379 3341 3232 3300 3251 3370 3164 3205 3233 3172 3150 3247 3134 3139 3185 3155 3043 3044 3057 3030 2922 3033 2964 2799 2952 2738 2991 2949 2866 2942 2809 2869 2820 2780 2798 2889 2703 2645 2765 2719 2751 2702 2654 2701 2705 2638 2612 2584 2594 2543 2569 2587 2537 2637 2502 2521 2608 2569 2488 2461 2542 2530 2550 2533 2484 2429 2474 2364 2537 2482 2381 2440 2363 2339 2351 2391 2174 2214 2206 2246 2095 2180 2178 2210 2151 2166 2200 2195 2070 2122 2069 2092 2165 2134 2025 2083 2013 2103 2102 2114 2003 2093 2090 2127 2060 1990 2038 1974 1964 1985 1981 2044 2013 2091 2034 2123 2034 2062 2124 2159 2058 2033 2055 2003 2162 2118 2256 2229 2227 2286 2323 2396 2467 2556 2565 2737 2850 3190 3528 4252 4918 5946 7019 8218 9485 11154 12879 14583 16674 18594 20771 23224 25095 27140 28872 30415 32229 33686 35608 36822 38090 38804 39494 39745 39394 39286 38228 37532 36848 35715 34366 32677 30497 28367 26357 23990 21219 19023 16680 14343 12612 10296 8584 7151 5763 4712 3845 3136 2721 2545 2238 2241 2177 2118 2155 2079 2119 2019 2052 2009 2006 1821 1852 1854 1791 1819 1850 1786 1774 1749 1757 1759 1720 1650 1702 1679 1687 1823 1661 1766 1516 1771 1612 1714 1595 1659 1633 1692 1696 1589 1538 1664 1691 1646 1565 1625 1691 1631 1636 1509 1574 1758 1605 1611 1630 1679 1465 1598 1644 1491 1483 1672 1497 1720 1651 1603 1548 1653 1535 1573 1744 1623 1642 1627 1665 1664 1534 1548 1703 1696 1548 1599 1521 1579 1432 1583 1643 1640 1639 1495 1555 1547 1494 1591 1471 1586 1530 1442 1588 1470 1491 1464 1598 1561 1547 1617 1439 1490 1463 1375 1420 1494 1537 1511 1585 1525 1515 1498 1461 1474 1570 1336 1669 1481 1580 1393 1477 1424 1455 1473 1577 1429 1603 1480 1527 1553 1539 1549 1556 1480 1512 1409 1458 1608 1469 1528 1413 1466 1411 1492 1473 1376 1499 1393 1465 1582 1414 1426 1548 1311 1578 1353 1393 1541 1436 1501 1393 1392 1377 1481 1427 1423 1481 1420 1290 1536 1411 1420 1415 1391 1481 1350 1453 1386 1407 1340 1513 1391 1467 1471 1428 1352 1362 1474 1400 1387 1495 1362 1531 1518 1449 1404 1252 1383 1421 1287 1425 1399 1468 1527 1350 1490 1282 1382 1505 1430 1357 1384 1405 1371 1341 1409 1266 1299 1530 1240 1494 1315 1211 1360 1386 1432 1469 1226 1366 1328 1402 1342 1266 1384 1381 1403 1377 1302 1411 1330 1425 1316 1351 1335 1357 1504 1345 1303 1255 1378 1344 1295 1246 1301 1279 1417 1267 1389 1358 1411 1379 1288 1365 1259 1319 1461 1355 1316 1205 1331 1359 1382 1339 1328 1458 1372 1295 1451 1261 1368 1450 1301 1301 1300 1443 1307 1376 1458 1344 1303 1335 1406 1263 1307 1358 1474 1474 1325 1379 1416 1370 1380 1363 1274 1357 1303 1187 1411 1431 1404 1323 1281 1247 1219 1205 1189 1301 1307 1294 1230 1250 1321 1244 1287 1246 1291 1335 1253 1211 1247 1264 1191 1375 1270 1320 1201 1232 1238 1279 1230 1216 1340 1301 1218 1194 1294 1278 1369 1327 1314 1283 1357 1221 1181 1263 1219 1202 1249 1219 1203 1271 1400 1311 1240 1311 1298 1275 1250 1264 1294 1246 1272 1184 1248 1237 1285 1188 1367 1235 1203 1226 1259 1228 1345 1255 1250 1202 1235 1283 1280 1327 1460 1263 1213 1323 1365 1255 1238 1341 1195 1171 1229 1269 1165 1193 1258 1353 1185 1286 1190 1270 1250 1220 1234 1330 1306 1284 1188 1272 1219 1144 1281 1281 1253 1255 1170 1262 1233 1192 1204 1243 1300 1234 1280 1217 1239 1182 1242 1205 1228 1249 1234 1238 1342 1227 1201 1268 1281 1230 1249 1260 1225 1278 1206 1231 1240 1228 1227 1294 1201 1165 1185 1202 1222 1172 1215 1194 1213 1299 1246 1224 1222 1153 1173 1192 1226 1338 1299 1247 1228 1212 1218 1171 1242 1227 1288 1305 1192 1224 1232 1196 1179 1200 1256 1230 1248 1253 1219 1287 1220 1182 1165 1228 1171 1241 1197 1243 1198 1285 1249 1223 1245 1227 1195 1195 1225 1202 1142 1201 1182 1171 1243 1163 1173 1228 1179 1208 1150 1143 1247 1170 1225 1272 1244 1195 1240 1216 1213 1174 1324 1206 1261 1322 1593 1566 1776 1689 1789 1910 1919 2018 2090 2186 2261 2368 2500 2674 2687 2644 2702 2825 2861 2863 3010 3001 2910 3154 3036 2903 3014 2923 2817 2801 2802 2570 2601 2442 2403 2181 2072 1954 1879 1826 1823 1712 1449 1494 1252 1305 1277 1192 1254 1318 1259 1264 1097 1173 1272 1170 1167 1145 1250 1134 1242 1116 1184 1105 1192 1196 1160 1188 1205 1196 1237 1157 1252 1195 1154 1164 1259 1194 1225 1218 1216 1212 1180 1172 1161 1274 1123 1140 1108 1237 1222 1162 1157 1171 1167 1223 1225 1238 1145 1167 1122 1217 1164 1190 1208 1192 1208 1158 1136 1201 1157 1181 1194 1246 1159 1278 1190 1162 1136 1153 1266 1329 1149 1161 1154 1257 1199 1163 1134 1146 1107 1279 1143 1101 1155 1149 1228 1215 1174 1140 1257 1232 1125 1168 1116 1206 1180 1225 1189 1200 1206 1169 1266 1240 1239 1134 1135 1160 1327 1221 1167 1283 1193 1311 1359 1215 1351 1226 1281 1499 1253 1286 1390 1345 1401 1341 1299 1339 1232 1336 1195 1342 1305 1381 1343 1263 1287 1201 1304 1236 1186 1202 1159 1145 1199 1205 1156 1215 1154 1154 1219 1189 1163 1277 1244 1226 1150 1144 1198 1122 1246 1209 1129 1245 1218 1166 1183 1144 1213 1184 1203 1198 1091 1136 1162 1159 1178 1182 1177 1186 1173 1114 1150 1172 1174 1132 1145 1180 1207 1190 1223 1163 1239 1208 1267 1266 1173 1206 1182 1159 1274 1165 1117 1255 1160 1159 1196 1156 1169 1159 1125 1156 1223 1204 1132 1181 1096 1126 1213 1177 1110 1217 1162 1194 1162 1180 1140 1154 1149 1332 1278 1201 1224 1150 1300 1162 1222 1304 1197 1201 1142 1224 1223 1188 1212 1180 1173 1195 1204 1231 1193 1173 1256 1197 1192 1263 1203 1128 1157 1240 1327 1190 1211 1214 1192 1119 1190 1187 1216 1187 1230 1182 1189 1267 1190 1180 1204 1300 1271 1283 1218 1219 1165 1195 1224 1238 1148 1262 1180 1182 1256 1224 1179 1206 1198 1220 1190 1205 1279 1247 1233 1178 1186 1183 1306 1269 1300 1218 1280 1227 1186 1243 1266 1210 1155 1275 1213 1154 1163 1264 1236 1286 1197 1339 1223 1330 1216 1253 1191 1442 1199 1306 1270 1387 1220 1171 1286 1160 1184 1223 1243 1274 1324 1191 1350 1232 1331 1280 1318 1305 1324 1293 1391 1398 1501 1714 1732 1765 1916 2000 2028 2056 2192 2223 2299 2409 2635 2684 2827 2735 2934 2912 2797 3003 2994 3025 2971 2990 3107 3021 3000 2976 2914 2789 2759 2790 2573 2500 2414 2386 2169 2122 2007 1920 1794 1716 1664 1474 1592 1391 1523 1438 1327 1352 1393 1447 1452 1391 1479 1368 1433 1418 1298 1385 1268 1401 1278 1351 1330 1533 1368 1343 1367 1272 1396 1313 1404 1360 1457 1316 1288 1513 1370 1523 1333 1492 1353 1450 1490 1545 1361 1529 1410 1498 1452 1503 1450 1410 1464 1315 1509 1448 1506 1371 1536 1648 1481 1453 1564 1430 1423 1513 1471 1450 1428 1592 1515 1546 1390 1500 1581 1471 1478 1616 1601 1717 1637 1623 1689 1516 1609 1546 1543 1586 1438 1613 1628 1701 1618 1651 1587 1719 1700 1548 1680 1687 1702 1769 1702 1724 1760 1682 1661 1746 1654 1730 1710 1679 1871 1794 1818 1792 1667 1733 1799 1767 1735 1697 1840 1874 1727 1840 1853 1805 1832 1748 1867 1862 1862 1929 1930 1821 1922 1918 1904 1860 1874 1888 1905 1790 1971 1962 1889 1957 1929 1893 1923 2024 1898 1941 1963 1919 1957 1974 2017 2002 1982 2027 1995 2055 2047 1972 1891 2083 2029 2009 2025 2028 2038 2123 2053 2096 2031 2135 2124 2109 2074 2083 2092 2057 2050 2011 2164 2039 2134 2163 2120 2086 2106 2084 2121 2090 2110 2158 2179 2126 2064 2057 2141 2152 2135 2214 2187 2217 2162 2099 2150 2136 2233 2129 2179 2166 2103 2117 2147 2216 2164 2263 2133 2104 2178 2214 2085 2110 2240 2092 2145 2141 2126 2176 2195 2205 2222 2122 2115 2193 2183 2136 2104 2144 2197 2213 2184 2299 2210 2300 2186 2307 2219 2317 2252 2335 2321 2210 2333 2342 2309 2386 2425 2442 2414 2527 2496 2479 2426 2533 2415 2423 2414 2543 2537 2390 2388 2364 2261 2288 2314 2252 2112 2288 2280 2226 2233 2276 2057 2121 2116 2085 2144 2114 2153 2146 2078 2077 2163 2030 1989 2109 2024 1949 2018 2053 2101 2003 2059 2046 2028 2054 1985 2081 1943 2003 2054 2013 2057 2066 2007 1963 1935 2077 2030 1945 1947 2006 1992 1949 1975 2035 2034 2094 1947 2079 1996 1949 1990 1979 2000 1985 1936 1973 1917 1942 1906 1896 1941 1946 1860 1848 1960 1980 1942 1857 1854 1872 1964 1859 1830 1932 1914 1798 1874 1934 1956 1889 1866 1813 1810 1889 1856 1915 1812 1876 1824 1882 1813 1952 1785 1840 1841 1800 1810 1809 1833 1788 1683 1843 1858 1809 1789 1804 1736 1868 1852 1753 1805 1789 1725 1721 1704 1754 1675 1786 1689 1681 1778 1710 1777 1672 1709 1756 1726 1642 1669 1622 1764 1670 1574 1631 1705 1628 1793 1679 1769 1674 1695 1545 1603 1602 1517 1477 1588 1700 1577 1518 1561 1590 1693 1628 1511 1558 1471 1566 1465 1516 1492 1462 1588 1488 1530 1517 1511 1386 1686 1581 1494 1518 1449 1593 1456 1617 1470 1524 1438 1498 1386 1487 1664 1536 1583 1673 1694 1687 1731 1854 1807 1633 1752 1840 1787 1750 1774 1821 1765 1668 1832 1539 1711 1717 1767 1637 1476 1619 1664 1530 1648 1443 1510 1500 1478 1338 1368 1350 1259 1317 1347 1268 1361 1229 1272 1321 1398 1313 1263 1305 1261 1303 1336 1303 1306 1316 1249 1252 1190 1262 1262 1313 1281 1311 1229 1265 1299 1237 1393 1358 1298 1179 1158 1328 1250 1230 1181 1214 1219 1242 1179 1198 1189 1258 1174 1201 1203 1189 1139 1120 1215 1200 1242 1228 1215 1280 1215 1229 1208 1144 1141 1170 1229 1132 1216 1204 1182 1110 1100 1150 1128 1184 1185 1106 1138 1103 1106 1133 1133 1154 1115 1157 1153 1105 1177 1129 1191 1197 1172 1159 1184 1083 1140 1085 1120 1129 1141 1118 1159 1101 1146 1134 1152 1108 1058 1051 1128 1054 1115 1110 1139 1122 1129 1120 1126 1105 1078 1167 1196 1105 1053 1100 1051 1133 1098 1005 1100 1088 1108 1144 1147 1123 1114 1192 1124 1094 1083 1107 1130 1102 1139 1086 1169 1095 1123 1135 1090 1156 1068 1046 1034 1048 1106 1036 1113 1080 1064 1102 1069 1051 1028 1074 1061 1039 1088 1044 1115 1037 989 1077 1055 984 1100 977 1074 1088 1026 1027 1069 1089 1004 1046 1030 1011 1029 1034 1007 1012 1028 1086 979 1061 1053 990 1051 1042 1034 1040 1088 1031 979 1054 1040 1038 1050 1034 1028 1016 1027 1043 982 1011 1065 985 1080 968 994 1007 1017 984 1053 1018 997 984 1008 925 1032 1041 995 997 1034 959 1064 999 979 1034 1012 992 971 1012 1047 954 920 1010 1006 1004 932 979 999 1009 999 1005 1038 1015 957 1014 1038 1012 943 986 1014 959 961 979 1004 945 1001 1037 1051 1017 1024 982 1021 1058 1076 1047 1036 1065 963 970 1028 1035 1031 975 1070 999 997 1016 985 971 1063 945 1011 989 984 967 1018 989 925 950 1022 995 953 961 971 987 951 987 972 952 1014 954 963 1001 901 946 1000 960 953 983 892 967 964 943 992 964 988 921 983 973 969 974 944 1001 988 961 978 987 932 920 868 972 976 931 944 937 951 955 938 950 973 950 945 944 953 936 940 950 975 937 927 966 950 983 995 919 984 981 1002 964 922 870 968 920 963 972 935 940 875 1008 1000 939 936 904 957 979 955 950 1021 958 927 922 972 937 945 941 916 880 947 942 924 978 938 1002 991 899 925 937 905 974 996 948 895 945 873 902 918 959 926 935 994 901 947 1005 905 958 937 962 892 925 946 925 970 959 953 918 956 917 906 907 967 887 911 939 942 948 940 929 926 939 931 958 990 966 990 996 996 1003 1032 1061 1014 1136 1119 1067 1181 1258 1203 1172 1175 1192 1239 1310 1430 1264 1331 1289 1239 1256 1272 1251 1344 1279 1169 1150 1116 1109 1129 1090 1061 1084 972 1055 1004 976 997 934 928 960 970 895 939 941 951 935 949 921 925 952 889 934 900 916 909 881 910 922 886 878 877 892 881 920 896 956 950 921 942 878 910 935 921 905 979 917 922 887 977 875 950 896 882 914 977 896 897 962 900 942 898 946 926 945 898 943 996 922 908 861 899 908 921 904 951 912 984 967 924 948 924 910 917 916 900 896 928 852 931 953 875 919 932 918 905 907 915 919 899 916 906 946 933 898 952 927 971 1036 990 968 1035 1055 1112 1127 1051 1129 1180 1204 1353 1235 1318 1285 1388 1244 1346 1383 1302 1383 1293 1380 1248 1254 1248 1348 1336 1279 1137 1163 1075 1077 1111 1075 1058 1027 1041 1016 988 1001 926 955 884 942 929 966 889 933 948 928 896 957 948 880 950 942 933 872 908 849 948 978 955 919 904 914 840 940 877 908 906 905 908 985 915 887 905 925 966 940 934 909 895 855 980 881 896 917 878 908 849 924 893 942 856 918 936 906 937 932 903 904 928 944 994 958 964 984 980 934 1017 970 1035 996 957 1018 1008 968 1015 1033 952 997 951 1037 1049 1011 959 973 996 996 1019 992 992 974 955 1034 981 910 943 911 924 919 939 984 959 925 959 910 940 878 892 917 878 927 930 930 869 890 927 951 908 1001 970 967 950 918 904 917 923 942 926 938 931 1004 925 894 908 892 966 910 990 935 922 964 876 943 894 944 877 903 913 842 903 923 912 899 965 941 940 870 903 949 878 935 1043 1025 907 923 940 918 932 898 960 919 883 937 867 932 932 955 916 954 969 864 956 943 948 922 906 922 928 882 935 915 908 946 995 934 899 998 942 900 933 861 1012 898 850 928 1012 964 910 897 897 912 920 986 989 942 954 1007 965 925 967 1011 953 971 978 940 952 980 962 871 886 965 990 980 930 891 872 1013 967 856 966 986 968 886 947 911 937 896 950 882 951 948 978 935 941 962 942 950 931 886 951 953 970 951 930 942 978 930 926 896 918 952 913 934 896 943 881 924 944 976 939 942 934 958 942 894 917 961 910 984 934 888 928 956 1040 929 956 1018 958 970 925 997 903 909 932 950 916 837 946 955 960 998 972 1006 962 969 912 940 958 925 920 951 972 935 963 910 967 921 935 947 916 925 885 1001 992 949 942 925 993 956 924 918 919 987 942 946 936 910 912 956 966 971 935 961 997 913 963 926 951 916 976 966 971 936 953 938 990 899 985 916 889 939 973 1025 915 981 951 925 977 968 988 949 960 1019 980 982 980 968 963 885 990 959 941 950 1007 973 923 873 985 949 984 985 1035 959 983 950 978 914 1023 982 945 991 977 985 981 970 933 915 957 967 967 960 959 941 1014 989 974 973 1052 991 969 970 941 964 1036 953 937 1010 884 940 967 967 1022 897 939 990 923 957 962 1002 967 991 935 927 937 1005 1073 1007 993 999 995 1043 982 1010 934 962 925 979 999 1014 1021 1008 976 981 970 982 922 1002 1003 1027 998 968 1011 925 981 947 961 972 999 996 944 986 1005 1036 1000 1017 1007 1005 979 936 1035 970 1021 1032 994 982 1051 1039 975 1004 953 988 1031 1029 1011 1012 1017 991 1017 1015 986 1011 965 965 1029 1038 991 953 1039 1085 1007 1032 1015 999 975 1030 1005 972 1071 986 1002 1012 985 986 953 1060 988 1014 1049 1062 1064 1007 966 1046 971 958 1000 1040 1023 1026 1013 1046 1022 1033 941 1054 973 995 1043 1016 1018 1034 1050 1012 989 983 999 1036 1029 1158 956 1046 997 994 1013 995 1045 1020 1043 1012 1041 1029 1005 1063 1025 1035 1037 1034 980 1026 1053 1033 1065 986 988 1007 1028 1026 1012 1027 1051 994 1074 1125 1058 972 1010 1059 1000 989 996 985 1055 1034 1027 1040 1102 1076 1065 1008 1080 1052 1041 1096 1048 1038 1049 1048 985 1077 1071 1047 1047 1030 1122 1051 1029 1042 983 1010 1017 1098 1085 1087 1025 1019 1068 1068 1051 1052 1021 1048 1047 966 1036 1061 1085 1109 1003 1075 1061 1037 1100 1104 1081 1038 1098 1062 1035 1057 1112 1078 996 1081 1039 1071 1070 1022 1110 1072 991 1055 1016 1048 1051 1097 982 1000 1104 1030 1123 1093 1058 1068 1057 1097 1116 1122 1058 1041 1073 1070 1041 1026 1012 1044 1080 1143 1086 1049 1080 1094 1136 1045 1144 1011 1076 1102 1117 1041 1159 1161 1124 1054 1090 1149 1030 1136 1111 1140 1146 1020 1083 1078 1111 1143 1093 1105 1182 1170 1127 1189 1093 1254 1158 1343 1234 1306 1571 1807 1899 2116 2403 2518 2617 2879 3195 3332 3650 3834 4147 4302 4570 4729 4844 5142 5133 5320 5395 5454 5715 5341 5403 5212 5091 5032 4858 4606 4318 4186 4021 3654 3500 3235 3056 2709 2533 2327 2238 1990 1795 1704 1516 1400 1359 1297 1243 1332 1223 1198 1125 1113 1248 1210 1102 1165 1174 1210 1121 1128 1170 1140 1146 1159 1103 1121 1163 1097 1110 1124 1139 1119 1082 1124 1183 1100 1151 1123 1096 1046 1086 1096 1093 1122 1132 1149 1141 1075 1154 1106 1229 1174 1195 1236 1139 1120 1081 1169 1138 1136 1177 1194 1117 1118 1127 1143 1119 1119 1078 1110 1106 1135 1144 1165 1123 1099 1148 1065 1175 1107 1098 1107 1236 1148 1159 1185 1109 1109 1168 1212 1137 1069 1175 1174 1165 1169 1123 1100 1068 1155 1153 1087 1041 1121 1169 1139 1125 1221 1082 1154 1111 1162 1133 1104 1139 1113 1150 1127 1102 1167 1105 1089 1259 1177 1114 1215 1129 1168 1151 1102 1130 1155 1166 1167 1143 1159 1153 1245 1196 1131 1101 1255 1106 1204 1149 1213 1122 1123 1132 1147 1171 1193 1135 1220 1148 1150 1149 1157 1134 1202 1143 1170 1161 1221 1175 1144 1184 1219 1087 1098 1184 1210 1197 1245 1218 1130 1187 1196 1228 1236 1248 1255 1152 1145 1148 1161 1246 1107 1211 1163 1122 1168 1161 1160 1222 1211 1141 1234 1242 1175 1245 1152 1261 1181 1187 1263 1151 1205 1178 1153 1270 1221 1181 1265 1195 1243 1195 1319 1212 1223 1253 1242 1235 1168 1190 1201 1209 1233 1191 1219 1256 1286 1288 1237 1190 1206 1195 1272 1258 1261 1257 1170 1202 1300 1284 1208 1162 1189 1295 1332 1243 1191 1266 1230 1243 1144 1245 1227 1221 1233 1257 1269 1261 1208 1211 1284 1327 1158 1208 1246 1271 1245 1292 1262 1263 1212 1306 1195 1361 1194 1202 1245 1180 1287 1207 1236 1296 1265 1202 1278 1215 1451 1334 1295 1182 1248 1214 1282 1265 1293 1299 1291 1264 1209 1246 1204 1244 1246 1241 1348 1264 1348 1329 1159 1285 1370 1256 1234 1210 1300 1318 1376 1208 1312 1288 1305 1248 1279 1239 1296 1429 1367 1278 1253 1262 1309 1312 1217 1290 1352 1415 1390 1352 1402 1273 1276 1424 1301 1239 1319 1450 1248 1327 1298 1395 1344 1405 1300 1243 1440 1406 1284 1369 1387 1390 1355 1396 1349 1363 1259 1318 1316 1365 1377 1291 1534 1321 1406 1383 1444 1381 1402 1469 1472 1468 1359 1330 1347 1297 1334 1362 1354 1390 1369 1315 1344 1366 1445 1367 1234 1369 1425 1343 1539 1334 1334 1304 1412 1539 1380 1367 1485 1456 1503 1440 1453 1473 1469 1430 1447 1492 1439 1556 1522 1598 1428 1509 1508 1474 1482 1415 1392 1577 1508 1539 1502 1439 1380 1592 1467 1444 1422 1571 1461 1424 1599 1496 1516 1459 1475 1604 1536 1438 1359 1488 1580 1631 1602 1437 1518 1507 1478 1494 1529 1519 1552 1509 1577 1520 1505 1660 1507 1565 1441 1606 1595 1552 1554 1635 1491 1624 1642 1629 1589 1475 1686 1738 1484</counts>
			</dataPoints>
		</scan>
	</xrdMeasurement>
</xrdMeasurements>