File: Data Files/Full/MSS dt (0-129, 3w, 0D).xrdml
<?xml version="1.0"?>
<xrdMeasurements xmlns="http://www.xrdml.com/XRDMeasurement/2.2" xmlns:xsi="http://www.w3.org/2001/XMLSchema-instance" xsi:schemaLocation="http://www.xrdml.com/XRDMeasurement/2.2 http://www.xrdml.com/XRDMeasurement/2.2/XRDMeasurement.xsd" status="Completed" recordIdentifier="{535CA254-12DE-4C66-8082-E706482D6684}">
	<comment>
		<entry/>
	</comment>
	<sample type="To be analyzed">
		<id>dt</id>
		<name></name>
		<preparedBy></preparedBy>
	</sample>
	<xrdMeasurement measurementType="Scan" status="Completed" sampleMode="Reflection">
		<usedWavelength intended="K-Alpha 1">
			<kAlpha1 unit="Angstrom">1.5405980</kAlpha1>
			<kAlpha2 unit="Angstrom">1.5444260</kAlpha2>
			<kBeta unit="Angstrom">1.3922500</kBeta>
			<ratioKAlpha2KAlpha1>0.5000</ratioKAlpha2KAlpha1>
		</usedWavelength>
		<incidentBeamPath>
			<radius unit="mm">145.00</radius>
			<xRayTube id="1010048" name="Empyrean Cu LFF HR (9430 033 7310x) DK437964">
				<tension unit="kV">40.0</tension>
				<current unit="mA">15.0</current>
				<anodeMaterial>Cu</anodeMaterial>
				<focus type="Line">
					<length unit="mm">12.0</length>
					<width unit="mm">0.4</width>
					<takeOffAngle unit="deg">6.0</takeOffAngle>
				</focus>
			</xRayTube>
			<filter id="20010004" name="Beta-filter Nickel">
				<material>Ni</material>
				<thickness unit="mm">0.020</thickness>
			</filter>
			<sollerSlit id="21010002" name="Soller slits 0.04 rad.">
				<opening unit="rad">0.0400</opening>
			</sollerSlit>
			<mask id="22031000" name="Fixed mask 13 mm">
				<width unit="mm">9.00</width>
			</mask>
			<divergenceSlit id="22120003" name="Divergence slit 1/4°" xsi:type="fixedDivergenceSlitType">
				<distanceToSample unit="mm">50.00</distanceToSample>
				<height unit="mm">0.38</height>
			</divergenceSlit>
		</incidentBeamPath>
		<diffractedBeamPath>
			<radius unit="mm">145.00</radius>
			<parallelPlateCollimator id="25020001" name="Parallel plate collimator 0.28°">
				<opening unit="deg">0.28</opening>
			</parallelPlateCollimator>
			<detector id="7010020" name="PIXcel3D-Medipix3 1x1 detector" xsi:type="areaDetectorType">
				<phd unit="keV">
					<lowerLevel>4.0</lowerLevel>
					<upperLevel>11.3</upperLevel>
				</phd>
				<mode>Receiving slit</mode>
				<activeChannelsEquatorial>255</activeChannelsEquatorial>
				<activeChannelsAxial>255</activeChannelsAxial>
				<pitchEquatorial unit="mm">0.05500</pitchEquatorial>
				<pitchAxial unit="mm">0.05500</pitchAxial>
				<readOutPeriod unit="seconds">0.050</readOutPeriod>
			</detector>
		</diffractedBeamPath>
		<scan appendNumber="0" mode="Continuous" scanAxis="2Theta" status="Completed">
			<header>
				<startTimeStamp>2025-05-14T14:03:53-08:00</startTimeStamp>
				<endTimeStamp>2025-05-15T04:23:42-08:00</endTimeStamp>
				<author>
					<name>Instrument</name>
				</author>
				<source>
					<applicationSoftware version="1.6 (94)">PANalytical Aeris Instrument Suite</applicationSoftware>
					<instrumentControlSoftware version="3.0.0 20211014">AERIS</instrumentControlSoftware>
					<instrumentID>2855484</instrumentID>
				</source>
			</header>
			<dataPoints>
				<positions axis="2Theta" unit="deg">
					<startPosition>0.005</startPosition>
					<endPosition>128.955</endPosition>
				</positions>
				<positions axis="Omega" unit="deg">
					<commonPosition>3.000</commonPosition>
				</positions>
				<commonCountingTime unit="seconds">3.520</commonCountingTime>
				<counts 12391 19131 27274 37959 60718 95628 145536 203095 266720 335757 401427 471245 522790 563926 587602 598707 598280 593735 583169 571703 557532 542624 536361 538055 538126 536499 530470 523014 516380 506587 497943 486904 476483 464054 456504 448431 441725 435151 429476 425382 422011 419143 416808 415991 414581 413776 414378 413713 413207 415151 414477 415782 416634 417280 417345 419932 420969 422117 424581 426858 428497 430734 432686 434840 436881 438770 442441 445298 446937 450018 452528 454593 456135 458988 461429 462442 462212 463139 464300 464190 467183 466917 467596 466370 465559 464838 465463 464464 462949 464469 462270 461624 460708 458154 454271 452057 447055 441421 435684 430358 423101 415083 406536 398104 387337 377275 363200 350688 336533 321052 305926 291904 275308 259947 244810 230063 214605 203184 188965 177612 165191 154911 144095 134355 126332 118470 111637 105441 100998 96404 92606 89912 86936 84630 82753 81627 80208 79382 77652 76692 75562 74087 73168 71876 71017 69448 69027 67877 67302 67147 66947 66620 66247 66371 65766 65283 65043 64651 64602 64223 64110 63671 63597 63487 63307 63120 62794 62806 62541 62735 62629 62323 61860 62010 62185 61696 61840 61184 61624 61867 61503 61525 62267 62010 62227 61671 62531 62535 62226 62744 62823 62794 63232 63126 62895 62909 63068 63768 62679 63834 63071 62441 62772 61282 61182 60661 59860 59298 58277 57389 57028 56204 54932 54437 53502 52747 51730 51479 50873 50292 49614 49254 49152 48342 47915 47358 46360 46451 45997 45792 44948 44243 43620 42899 42400 41745 40803 39776 39081 38147 37135 36586 36003 34670 33670 32781 31647 30398 29521 28443 27064 25787 24529 23260 21890 20969 19621 18360 16934 15710 14632 13349 12455 11071 10092 9225 8442 7515 6771 6193 5669 4954 4330 4105 3602 3269 3028 2890 2700 2665 2716 2658 2683 2733 2617 2721 2652 2589 2603 2570 2523 2587 2574 2675 2502 2682 2521 2500 2635 2478 2570 2517 2614 2510 2540 2514 2497 2556 2368 2484 2490 2436 2534 2469 2557 2399 2339 2371 2416 2467 2384 2417 2373 2426 2358 2424 2395 2416 2398 2346 2415 2290 2347 2249 2383 2375 2475 2353 2277 2321 2350 2393 2281 2364 2307 2343 2332 2377 2263 2289 2294 2301 2305 2324 2228 2230 2245 2279 2237 2173 2215 2225 2190 2178 2200 2227 2222 2238 2230 2271 2264 2286 2163 2199 2178 2139 2182 2295 2173 2109 2151 2181 2042 2160 2113 2081 2064 2200 2163 2076 2166 2159 2145 2049 2056 2113 2092 2035 2047 2157 2059 2068 2094 2081 2053 2074 2083 2040 2168 2027 2043 2028 2099 2097 2064 2044 2071 2009 2028 1996 2037 1936 1965 2006 1956 2032 1905 1984 2061 1987 2047 1889 2005 2014 1863 1977 1962 1996 1890 1943 1938 1998 1855 1922 1899 1955 1844 1843 1865 1866 1892 1949 1918 1876 1922 1873 1848 1897 1878 1938 1859 1855 1870 1969 1913 1862 1915 1849 1924 1856 1827 1818 1896 1828 1915 1859 1844 1735 1824 1838 1812 1896 1829 1772 1848 1855 1884 1825 1859 1850 1724 1862 1812 1807 1741 1822 1748 1728 1854 1796 1766 1780 1867 1593 1777 1782 1809 1786 1779 1600 1722 1754 1606 1724 1762 1619 1705 1683 1734 1763 1707 1592 1689 1500 1711 1679 1721 1591 1557 1642 1718 1584 1655 1650 1706 1656 1745 1570 1600 1667 1710 1505 1583 1449 1505 1765 1726 1498 1601 1590 1646 1559 1507 1567 1574 1591 1590 1572 1612 1604 1754 1537 1571 1556 1491 1554 1546 1651 1488 1525 1505 1593 1510 1417 1524 1478 1353 1586 1513 1381 1423 1556 1508 1521 1491 1427 1621 1620 1499 1464 1513 1406 1507 1567 1455 1487 1593 1418 1425 1417 1501 1552 1514 1527 1397 1543 1497 1604 1488 1391 1479 1407 1572 1532 1553 1452 1595 1479 1474 1576 1532 1451 1471 1452 1462 1459 1505 1585 1653 1492 1482 1494 1626 1515 1423 1559 1605 1527 1562 1462 1389 1364 1400 1428 1350 1464 1488 1620 1381 1528 1383 1702 1338 1486 1591 1475 1432 1458 1668 1399 1562 1402 1370 1471 1522 1432 1475 1409 1450 1566 1460 1489 1566 1576 1369 1551 1518 1391 1452 1448 1459 1462 1716 1492 1563 1506 1411 1523 1596 1537 1574 1420 1473 1433 1453 1438 1598 1520 1513 1525 1471 1510 1342 1490 1528 1579 1450 1527 1468 1497 1564 1600 1589 1554 1475 1553 1563 1685 1671 1446 1552 1446 1563 1632 1599 1708 1511 1674 1568 1668 1575 1489 1786 1641 1617 1631 1485 1713 1837 1445 1519 1636 1623 1507 1595 1612 1678 1535 1656 1580 1636 1646 1624 1689 1648 1628 1593 1636 1706 1695 1627 1689 1589 1639 1574 1638 1644 1656 1585 1712 1650 1601 1637 1621 1514 1756 1705 1664 1691 1695 1606 1690 1761 1671 1673 1720 1696 1751 1648 1759 1742 1549 1806 1632 1777 1681 1608 1737 1619 1788 1739 1813 1809 1863 1732 1711 1761 1672 1745 1752 1775 1767 1764 1756 1642 1638 1780 1793 1757 1711 1804 1661 1795 1695 1744 1817 1738 1746 1782 1797 1829 1739 1706 1793 1845 1740 1790 1877 1799 1789 1828 1774 1745 1735 1735 1851 1747 1908 1747 1870 1782 1705 1739 1838 1864 1807 1856 1817 1800 1849 1832 1790 1865 1922 1849 1864 1833 1883 1810 1847 1831 1835 1854 1914 1905 1915 1867 1841 1955 1901 1936 1838 1889 1844 1793 1888 1889 1921 1815 1865 1862 1894 1830 1874 1901 1880 1975 1913 1989 1912 1934 1915 1932 1877 1990 1944 1808 1995 1953 1913 1912 1796 1920 1996 2057 1974 1955 1968 1933 1981 1958 1975 2005 2030 1962 1884 1985 1905 1992 1961 2049 1954 1972 1977 1950 2047 1984 1993 2006 1958 2021 2087 2011 2011 2127 2126 2020 2035 1933 1957 1934 2034 2130 2088 1970 1995 2078 2033 2089 1970 2061 2035 2049 2046 2016 2018 2056 2134 2003 2133 2072 2109 2090 2047 2058 2058 2118 2047 2049 2065 2172 2059 2063 2020 2044 2163 2097 2141 2108 2053 2147 2079 2119 2058 2118 2123 2139 2144 2224 2176 2195 2103 2125 2191 2047 2094 2139 2158 2109 2135 2195 2103 2201 2160 2178 2162 2131 2135 2108 2129 2202 2277 2097 2213 2086 2273 2172 2103 2219 2185 2218 2239 2182 2197 2276 2148 2276 2280 2168 2186 2202 2197 2254 2291 2197 2188 2166 2186 2158 2170 2179 2226 2232 2225 2163 2121 2226 2210 2273 2285 2251 2303 2301 2289 2235 2107 2187 2224 2150 2207 2207 2214 2215 2156 2151 2275 2195 2259 2215 2216 2160 2251 2248 2248 2251 2176 2302 2246 2202 2186 2266 2193 2275 2205 2173 2176 2186 2163 2265 2221 2242 2189 2146 2221 2148 2199 2192 2236 2200 2203 2149 2144 2226 2280 2215 2170 2148 2231 2168 2198 2182 2244 2121 2144 2085 2112 2182 2212 2188 2171 2199 2193 2217 2097 2190 2140 2097 2250 2139 2102 2115 2166 2146 2188 2210 2129 2056 2077 2068 2218 2164 2140 2102 2213 2158 2112 2155 2157 2121 2119 2163 2117 1987 2129 2104 2107 2155 2150 2108 2035 2038 2113 2038 2105 2192 2084 2072 2015 2117 2041 2100 1970 2121 2074 2134 2112 2041 2101 2083 2030 2056 2070 2090 2035 2027 2073 1979 2096 2027 1960 1966 2018 2041 1998 2103 1948 2018 1941 1946 2039 2043 1962 1927 1925 1978 1948 1894 1963 1936 1950 1983 1975 1964 1921 1938 1993 2023 2038 1981 2003 1958 1954 1921 1922 1922 1864 1913 1882 1864 1941 1870 1898 1923 1835 1965 1992 1891 1846 1864 1813 1884 1901 1894 1867 1925 1886 1880 1855 1905 1925 1857 1708 1843 1895 1840 1732 1875 1870 1905 1709 1815 1812 1838 1748 1676 1773 1791 1765 1826 1824 1885 1808 1713 1696 1820 1716 1844 1683 1714 1857 1757 1693 1818 1661 1734 1864 1723 1713 1804 1781 1717 1724 1718 1698 1642 1777 1840 1652 1630 1778 1549 1681 1693 1621 1558 1732 1641 1693 1563 1637 1619 1705 1635 1548 1633 1661 1577 1544 1439 1466 1527 1549 1511 1687 1608 1506 1347 1533 1580 1496 1413 1531 1531 1655 1598 1476 1655 1523 1598 1427 1481 1528 1467 1408 1507 1504 1553 1605 1439 1506 1455 1454 1390 1459 1561 1494 1505 1392 1471 1498 1453 1390 1440 1498 1471 1350 1488 1577 1353 1373 1381 1404 1332 1510 1413 1400 1493 1338 1394 1314 1434 1745 1825 1940 1996 2213 2431 2728 2859 3169 3433 3671 3830 4095 4302 4488 4666 4781 4726 4715 4605 4445 4425 3941 3550 3413 3115 3014 2575 2515 2213 2027 1821 1749 1422 1304 1298 1284 1333 1247 1301 1451 1203 1402 1298 1321 1178 1291 1295 1300 1268 1296 1201 1253 1207 1139 1194 1206 1298 1117 1208 1189 1189 1149 1200 1182 1281 1183 1218 1207 1160 1242 1189 1230 1207 1194 1214 1261 1194 1213 1236 1289 1160 1307 1199 1194 1165 1149 1325 1310 1178 1162 1248 1197 1154 1170 1112 1212 1247 1153 1183 1129 1150 1114 1200 1164 1162 1138 1101 1122 1123 1198 1228 1099 1173 1152 1147 1153 1128 1187 1096 1158 1113 1124 1181 1109 1081 1147 1137 1127 1120 1127 1115 1092 1036 1130 1145 1098 1150 1169 1136 1117 1098 1212 1114 1169 1195 1123 1102 1127 1104 1135 1156 1123 1125 1110 1179 1104 1088 1253 1108 1056 1093 1132 1130 1057 1080 1085 1166 1081 1091 1115 1155 1077 1090 1131 1135 1074 1059 1069 1021 1125 1142 1030 1087 1088 1092 1110 1104 1024 1096 1095 1103 1080 1076 1074 1045 1061 1086 1018 1067 1018 1021 979 1096 1039 1053 1017 959 1048 1044 1025 1053 981 1065 1144 1003 1069 1065 1021 1055 1014 1069 971 991 970 1031 1002 1004 938 1029 979 1061 1016 964 1081 1021 1001 993 1004 987 963 1001 1004 948 1077 991 1015 1004 961 1016 1036 1017 1055 987 1010 967 1035 994 975 1105 999 1032 981 1018 988 934 943 984 1012 1016 1004 1059 953 1038 982 1079 943 1015 984 997 954 1041 966 929 1038 1038 993 992 955 963 976 925 987 1003 1005 970 1022 980 909 940 1003 987 918 1003 1010 1008 1055 1034 946 951 961 991 948 1014 976 931 937 912 920 958 958 939 958 990 929 972 914 953 942 931 980 992 958 950 942 936 965 926 944 933 967 993 970 961 979 957 959 935 952 913 932 917 901 1004 957 976 949 958 915 927 950 948 946 979 935 953 984 920 951 993 972 931 957 939 963 912 927 987 957 936 883 943 946 919 930 964 928 927 958 948 909 940 949 905 884 933 905 914 936 978 943 988 942 955 943 864 944 951 912 971 904 916 911 956 954 936 924 954 935 988 913 964 998 970 980 1037 960 996 961 1077 1038 1077 1069 1080 1070 1160 1480 1996 2539 3083 4000 4923 5802 7173 8491 9785 11256 12559 13932 14895 16109 16790 17336 17715 17201 17333 16338 15593 13920 12721 11830 10412 8958 7749 6434 5430 4375 3351 2739 2177 1636 1246 1171 1024 1029 1020 1008 1064 1025 963 1038 948 1000 1008 957 938 946 980 925 989 955 1004 900 908 889 862 893 900 927 869 846 862 921 890 869 886 868 927 882 869 928 899 842 910 852 867 853 880 945 924 841 840 837 833 879 948 900 859 845 852 833 907 885 887 906 851 840 901 867 876 832 880 787 835 848 881 869 856 853 957 839 843 807 865 850 857 865 825 840 867 829 884 811 849 825 919 906 854 849 826 848 841 873 852 815 820 847 904 807 871 875 873 801 855 854 891 825 844 803 793 886 850 836 843 917 851 814 893 875 823 870 845 837 846 898 804 965 901 885 896 924 846 906 868 856 834 881 873 804 866 811 832 841 843 829 813 896 803 830 860 846 837 845 845 872 850 796 804 884 798 850 762 870 821 811 824 843 854 806 870 808 798 804 788 828 823 823 805 819 811 870 792 854 795 796 796 837 833 866 802 819 861 811 846 855 856 825 851 842 818 778 864 783 880 838 811 842 825 868 818 866 860 813 799 820 829 827 819 793 781 863 793 871 843 860 797 860 876 822 863 874 830 850 809 802 752 820 846 780 836 822 808 866 814 795 850 815 866 799 805 832 814 819 855 882 819 795 853 851 817 854 814 846 841 857 862 795 883 850 803 823 812 820 831 840 823 873 816 820 870 833 808 849 848 911 847 789 791 815 806 859 815 807 872 834 860 876 816 891 845 794 812 870 821 856 817 836 879 868 853 839 856 883 820 862 861 862 879 823 846 884 877 856 903 1002 1004 1231 1344 1610 2023 2248 2680 2998 3241 3620 4044 4387 4646 4898 5057 5273 5293 5412 5227 4957 4831 4389 4229 3900 3569 3200 2826 2598 2226 1871 1604 1290 1076 998 954 901 835 803 853 856 888 803 904 882 806 863 862 837 847 886 872 840 815 770 871 764 835 849 852 762 856 779 769 761 837 791 818 839 792 800 866 800 805 866 819 807 824 773 830 774 813 804 808 781 811 775 775 843 850 874 763 797 792 813 809 852 776 819 815 788 795 774 759 821 751 794 820 808 768 791 769 827 819 784 831 818 771 768 834 807 838 741 772 797 800 772 753 806 753 760 778 768 759 764 776 785 850 773 831 826 820 752 873 750 802 849 821 847 824 819 743 781 866 760 791 801 785 773 801 748 847 805 813 749 808 761 872 872 867 875 922 889 843 864 888 921 904 898 918 930 906 923 871 874 869 814 800 894 854 830 898 801 809 803 772 811 754 765 706 780 789 788 859 788 775 765 766 776 808 821 810 777 779 800 780 754 799 769 755 773 795 799 833 785 759 771 829 763 781 819 795 807 822 755 794 807 786 763 796 765 761 776 785 754 813 753 724 798 728 775 781 809 848 822 852 782 818 770 766 791 855 765 816 794 832 753 772 772 782 814 755 790 793 771 774 814 782 797 799 842 789 765 767 818 772 794 796 799 803 774 831 770 766 830 731 803 760 740 796 824 794 748 805 777 807 745 758 830 798 824 775 793 779 792 803 762 763 788 851 822 837 802 809 875 812 878 804 806 843 770 816 796 836 845 805 814 896 816 829 821 805 865 828 720 824 806 805 808 831 871 868 823 809 849 785 810 801 813 852 872 852 812 842 801 827 860 879 824 817 846 846 897 852 889 943 829 822 842 870 812 795 898 880 791 876 829 859 825 886 852 874 834 873 780 865 816 854 825 844 891 871 835 903 892 929 846 864 814 927 859 875 868 891 918 923 903 923 884 838 987 951 912 945 936 912 895 894 928 952 908 889 913 939 964 932 1027 913 924 931 956 896 988 985 943 987 1055 966 971 993 953 948 959 978 998 1000 1039 1020 977 974 1006 984 1021 954 1005 997 1071 1082 1032 1030 1050 1106 1150 1114 1073 1046 996 1103 1071 1146 1106 1066 1146 1056 1074 1133 1132 1132 1209 1134 1176 1211 1156 1177 1251 1213 1263 1204 1247 1274 1229 1253 1395 1339 1366 1291 1363 1349 1391 1360 1502 1491 1479 1524 1431 1404 1583 1675 1688 1710 1703 1805 1720 1805 1771 1883 1933 1880 1936 1942 2013 2046 1968 1963 2064 2152 2109 2191 2169 2340 2330 2324 2417 2523 2565 2639 2592 2674 2810 2853 2948 3041 3302 3223 3396 3548 3623 3826 4042 4150 4520 4936 5299 5708 6305 6838 7645 8625 10206 12558 16935 27711 65852 210256 514435 909846 1499543 2273254 3382643 4520521 5771629 6977642 8216375 9451021 10659351 11874720 12994524 14063518 14852856 15397943 15627100 15532045 14945996 14038875 12895712 11738507 10477779 9289193 7995525 6796965 5500190 4284247 3181963 2209440 1386718 705904 330410 136888 67129 36072 21737 13266 8711 6200 5076 4364 4064 3753 3560 3422 3359 3043 2826 2819 2755 2574 2477 2483 2386 2355 2191 2205 2200 2109 2066 1969 1972 1967 1881 1971 1860 1867 1823 1858 1806 1716 1746 1620 1603 1514 1561 1592 1407 1580 1396 1456 1233 1230 1248 1319 1283 1250 1299 1194 1201 1130 1110 1174 1139 1195 1198 1102 1115 1074 1111 1150 1190 1036 1073 1047 1046 1076 1010 1120 1050 1000 1088 1010 982 1016 981 1024 993 978 950 921 975 976 960 1008 919 956 886 940 975 941 921 929 888 953 944 896 935 903 908 908 813 877 938 847 829 820 872 884 847 854 897 828 817 867 798 821 850 819 805 829 817 818 795 820 827 798 811 862 819 824 809 822 822 748 825 715 753 729 803 777 812 783 793 796 742 784 780 761 731 722 757 754 743 733 738 734 768 735 705 745 750 748 742 701 695 744 744 727 752 724 751 717 740 743 751 749 722 743 713 716 745 718 734 724 685 723 669 702 712 692 719 725 711 745 684 725 711 714 704 711 788 696 770 669 724 711 676 660 747 741 701 681 721 696 660 707 662 656 760 728 695 654 642 645 719 668 705 676 703 660 666 647 659 653 716 681 661 651 644 680 708 702 673 672 650 688 675 660 686 695 700 670 629 681 682 650 703 678 668 696 625 677 668 652 664 598 657 661 675 709 627 700 672 688 666 635 664 676 651 671 676 656 641 621 651 627 658 647 611 646 703 656 684 675 652 632 659 651 638 677 616 626 672 639 647 682 667 644 659 670 667 597 698 608 625 621 668 633 686 622 613 653 613 665 667 611 653 641 654 645 631 684 608 620 654 596 569 624 644 636 615 641 626 617 622 660 636 625 635 612 592 621 643 612 603 593 650 695 572 667 660 600 612 625 619 653 670 603 595 633 618 602 634 652 626 635 614 653 634 613 569 654 602 686 618 648 627 614 624 620 641 646 598 633 588 606 606 654 620 607 597 635 574 612 545 625 693 615 628 642 586 564 624 591 604 646 595 586 600 632 593 618 649 597 632 573 599 562 605 599 608 623 582 613 606 591 560 607 635 553 609 610 589 594 597 605 584 637 570 609 592 634 571 595 609 651 617 592 606 604 584 612 620 622 635 567 589 561 539 596 588 578 586 581 584 592 607 588 574 549 609 548 627 573 609 591 575 547 579 605 563 601 591 635 561 570 571 605 592 636 610 608 626 567 588 589 557 623 560 632 561 547 577 563 602 601 623 610 579 592 586 623 583 582 581 539 601 559 615 564 586 591 568 541 564 615 570 527 555 581 545 583 573 591 584 614 588 543 532 575 619 597 577 582 569 556 602 602 597 645 727 810 831 910 1022 1106 1231 1539 1663 1769 1914 2196 2132 2340 2364 2480 2364 2291 2256 2230 2093 1936 1844 1612 1304 1213 1113 992 928 868 727 698 661 587 563 556 604 592 551 564 579 605 590 583 587 553 599 563 554 596 542 579 540 586 564 542 539 568 579 563 618 581 546 581 558 565 585 591 593 576 549 531 565 568 592 546 584 589 589 525 555 616 567 508 560 529 539 512 571 599 567 512 541 537 560 583 527 523 511 594 531 561 550 537 529 522 553 540 529 564 568 563 547 566 573 550 591 554 540 561 568 570 572 547 567 540 554 561 557 566 527 529 503 550 536 511 543 574 554 532 551 590 553 594 539 517 550 524 543 553 584 552 547 571 593 620 558 557 576 586 607 603 603 601 588 620 625 627 613 654 630 607 618 640 550 594 536 572 605 574 588 577 558 569 561 547 556 560 561 548 569 563 580 538 550 573 522 554 537 544 534 543 580 534 538 536 591 577 532 530 534 550 564 538 555 560 467 565 564 539 525 545 575 545 555 588 552 549 528 490 537 563 557 529 533 556 558 513 482 635 557 540 569 562 556 593 520 593 594 552 540 574 494 541 544 591 546 499 544 515 546 548 531 550 497 539 573 528 522 539 573 559 544 540 477 564 514 556 510 495 528 516 496 529 515 527 576 540 542 502 619 534 516 539 564 553 538 499 560 568 542 495 516 575 539 582 502 507 519 515 545 506 531 484 544 536 494 566 533 525 526 561 520 541 531 551 543 567 531 585 545 497 476 535 536 561 526 561 529 533 521 578 512 552 578 550 539 524 499 527 517 523 519 520 534 532 534 559 565 545 527 537 502 530 534 537 563 555 523 530 566 497 546 530 560 522 556 554 516 498 576 587 509 544 524 541 586 574 574 546 573 549 512 577 551 559 544 553 539 566 561 574 594 642 646 639 751 826 857 966 1079 1196 1315 1677 1701 1756 1857 2085 2082 2094 2060 2168 2057 2056 1919 1805 1736 1312 1161 1126 1013 966 841 782 742 668 617 575 583 605 547 545 593 587 553 586 582 563 543 619 515 564 536 572 562 496 567 552 550 606 559 545 599 542 556 557 574 562 539 590 516 558 550 520 552 634 509 559 541 569 539 561 537 601 596 588 580 508 562 519 537 534 556 592 580 592 563 514 492 547 515 555 591 560 584 566 560 524 558 565 591 539 522 540 537 570 579 543 552 519 545 549 513 604 517 517 540 541 565 555 534 558 583 559 574 546 568 553 536 555 541 549 580 581 558 563 544 539 511 557 589 614 555 539 560 589 556 510 560 566 571 533 550 566 542 605 553 581 573 549 525 609 531 575 549 534 550 606 547 566 565 543 591 583 569 591 547 547 581 578 595 603 569 548 554 534 552 586 602 573 621 554 559 558 565 547 558 556 569 572 564 581 556 590 571 620 623 563 599 569 599 564 619 625 633 648 614 597 601 555 637 594 609 613 610 606 622 625 619 609 653 602 617 595 613 585 619 615 617 587 607 568 591 606 617 565 622 597 628 602 624 625 620 602 592 602 614 602 576 612 594 612 669 602 630 627 615 665 627 601 638 626 587 623 626 604 646 641 632 620 624 622 614 667 669 644 651 667 679 749 709 807 820 773 776 859 872 878 922 900 803 799 864 855 857 846 846 806 740 754 714 701 727 730 673 635 651 618 602 640 615 656 651 683 679 629 631 641 613 662 646 666 661 683 626 643 639 631 676 636 622 649 613 672 665 641 658 677 622 691 648 699 583 645 630 687 619 675 629 648 655 652 664 626 649 597 691 705 683 634 613 659 641 652 654 689 651 648 667 709 640 652 704 659 643 641 661 630 702 641 669 703 668 681 691 632 683 692 693 669 624 679 690 669 643 631 661 668 656 648 696 621 727 617 679 662 612 719 692 720 667 660 668 671 682 629 674 673 701 654 671 658 677 633 689 670 658 659 662 704 700 703 614 688 621 675 684 674 625 666 684 637 676 636 625 649 657 681 623 691 654 720 638 658 659 686 700 645 616 711 723 669 633 645 680 677 632 651 658 747 668 667 629 655 672 699 623 701 629 664 695 724 647 668 718 722 677 674 662 699 722 711 837 804 884 878 970 938 1068 1018 1070 1094 1087 1154 1089 1139 1095 1020 1037 1038 990 956 911 920 832 798 747 740 670 723 692 694 649 656 700 678 699 624 677 650 645 662 656 675 641 705 722 624 667 617 648 658 623 650 668 711 697 667 619 688 690 702 690 679 638 641 620 666 665 659 622 640 677 626 672 648 706 631 649 634 650 655 679 659 642 645 623 637 657 652 636 613 655 619 612 674 718 663 642 652 651 661 648 644 648 643 638 686 656 640 662 668 600 641 613 627 638 630 635 617 669 656 652 612 637 612 625 610 626 636 627 595 688 621 697 676 572 640 607 628 617 643 591 608 653 626 591 603 640 653 593 611 667 570 622 592 600 636 614 556 585 601 651 617 641 603 652 594 656 606 622 660 633 659 620 640 614 649 603 643 615 611 643 659 650 638 650 715 687 607 578 618 568 596 596 587 574 591 581 613 558 590 603 584 618 565 595 578 581 586 579 618 584 630 621 588 584 590 589 630 583 561 611 589 604 537 586 573 592 590 586 572 561 628 593 613 564 560 581 551 584 580 622 593 591 585 546 562 566 534 554 541 520 554 596 584 538 567 585 558 615 585 546 553 575 566 580 541 554 542 573 547 602 501 536 589 558 537 556 572 527 566 530 530 608 532 557 538 590 568 550 553 523 566 519 519 534 542 522 540 531 576 552 518 546 570 536 536 553 536 575 577 527 560 581 590 522 574 550 569 546 559 557 498 544 538 612 519 528 567 543 560 544 533 494 535 532 547 506 535 519 557 537 532 526 544 516 525 533 505 486 471 531 517 505 561 514 514 495 528 548 502 527 544 538 483 535 484 554 530 446 491 531 527 534 511 556 491 501 525 531 503 494 532 495 517 495 528 514 559 531 483 481 511 567 486 500 545 517 484 544 454 436 471 486 541 516 502 497 517 509 481 464 528 495 500 498 516 528 538 497 499 479 486 441 527 491 492 473 473 481 516 515 493 485 471 477 521 466 477 502 508 482 500 507 472 507 472 481 476 486 498 470 532 525 452 482 487 469 514 517 489 456 479 507 487 504 490 483 477 446 476 478 491 513 455 489 493 516 464 488 477 483 499 472 471 456 480 452 457 491 459 484 500 469 478 517 494 484 528 562 574 565 603 598 684 705 708 758 795 779 716 803 799 827 763 790 720 706 634 630 680 637 564 581 515 539 515 487 479 494 479 469 451 468 471 463 503 501 470 460 436 491 462 461 476 517 483 466 441 427 484 456 418 476 500 524 465 469 436 459 445 465 466 475 429 474 473 500 467 471 428 482 447 484 481 428 432 419 443 462 459 446 463 460 479 467 457 451 433 485 500 428 440 462 480 451 452 476 470 459 452 475 431 438 481 417 471 440 452 426 474 487 451 466 493 445 475 443 465 426 442 462 437 454 467 454 477 496 483 477 454 432 410 454 448 474 490 519 518 547 567 555 629 662 680 708 665 709 755 715 775 770 763 773 812 724 724 682 623 646 636 577 586 483 527 465 432 523 426 422 468 484 462 453 495 434 407 440 461 485 490 456 450 493 458 445 415 444 425 459 470 462 451 396 401 450 465 484 431 472 463 476 417 485 437 467 446 506 451 466 486 445 439 475 432 501 463 451 437 428 465 477 448 439 419 454 466 453 430 488 452 459 417 442 401 461 426 484 455 456 486 458 458 458 447 469 524 487 498 561 543 522 463 493 511 561 516 533 534 530 476 500 484 475 452 517 481 490 442 442 462 451 413 451 443 480 461 449 424 460 449 461 426 442 423 443 439 468 430 438 478 451 471 481 469 444 471 460 431 421 455 454 447 420 430 444 425 448 447 436 454 450 442 462 441 424 433 424 474 429 466 501 410 463 446 433 456 493 502 426 422 475 460 447 475 423 466 457 473 454 502 468 466 432 430 421 417 436 435 406 444 484 464 480 450 436 481 481 468 444 471 437 461 473 400 475 484 428 471 441 439 460 435 455 446 437 441 478 418 445 428 472 422 437 485 443 434 431 442 453 504 443 418 494 474 520 470 470 484 504 437 474 502 488 426 478 482 479 467 479 459 452 461 456 416 451 426 470 466 422 480 455 439 470 461 450 467 456 460 495 432 469 434 485 476 464 483 451 464 498 439 459 457 458 441 465 456 455 477 450 472 462 487 465 484 483 444 444 452 459 478 449 500 433 498 483 505 462 471 453 468 503 483 479 477 476 447 460 458 481 464 465 472 487 447 469 467 472 442 469 470 462 436 454 464 476 427 458 449 448 456 495 448 473 496 418 429 510 462 458 475 449 451 439 429 429 457 439 446 476 480 472 472 504 457 463 433 464 425 471 450 481 461 470 442 482 446 459 444 458 441 468 450 484 429 466 457 475 473 519 502 467 455 505 432 472 436 434 465 473 444 507 446 473 424 487 467 495 468 478 478 461 456 463 483 533 460 444 465 481 477 437 506 474 471 448 446 472 502 437 441 459 470 497 456 458 482 432 501 473 465 435 487 460 451 483 500 452 458 437 472 480 447 451 462 527 459 474 450 461 510 491 485 485 452 463 432 462 463 445 468 481 457 489 477 459 500 478 453 469 479 449 493 466 463 508 489 503 494 437 451 516 495 437 423 505 469 474 484 455 491 488 424 472 496 415 458 501 497 467 510 435 452 483 500 444 488 475 422 479 506 504 477 464 461 483 462 473 492 477 482 457 533 440 528 537 486 493 445 506 484 487 474 469 454 500 480 476 490 480 471 497 492 480 518 463 494 490 466 490 482 477 480 497 460 491 516 513 482 496 492 510 488 493 508 530 534 514 482 510 509 480 499 503 489 482 451 459 533 521 456 483 496 553 478 493 518 470 486 517 519 488 535 469 443 489 503 502 471 501 497 500 505 482 497 480 517 444 520 492 468 522 518 527 451 490 505 532 472 485 458 559 485 481 502 535 488 532 546 525 491 494 514 530 526 511 542 488 543 502 490 511 469 528 560 498 486 483 488 525 516 532 540 523 493 548 478 515 479 484 519 512 520 506 502 483 512 486 522 596 477 506 518 538 496 513 535 472 486 534 509 556 496 511 504 511 534 520 496 497 499 505 525 484 531 488 501 489 492 547 517 498 532 532 545 546 511 550 525 529 526 542 538 517 536 536 491 550 508 524 504 543 485 477 504 514 540 554 538 557 491 502 528 561 596 541 484 528 559 497 492 505 560 557 517 565 517 587 518 509 546 562 583 546 593 577 546 609 597 553 572 570 590 624 578 665 707 748 823 943 1121 1498 1827 2227 2767 3206 3636 4185 4528 5096 5305 5911 6471 6396 6742 6791 6883 6805 6430 5916 5718 5117 4687 4050 3793 3135 2666 2233 1823 1361 1143 914 754 665 604 593 579 561 572 580 586 581 576 553 568 509 545 562 546 549 566 578 540 495 530 570 571 582 536 558 548 556 554 512 511 534 509 566 542 564 560 529 562 569 560 527 525 548 569 550 565 574 551 545 557 623 530 592 506 536 509 506 580 528 527 593 557 568 527 511 521 554 525 539 595 574 537 581 544 600 510 537 569 515 528 537 556 579 564 552 549 537 545 528 561 489 566 545 571 570 585 570 506 592 527 557 564 542 573 547 571 514 576 556 595 557 582 562 538 555 588 555 575 564 537 514 557 551 577 541 520 542 559 567 571 574 548 587 575 510 561 598 558 544 603 581 521 564 576 552 538 570 558 569 629 608 560 547 584 582 565 614 530 553 561 586 568 570 556 511 563 543 570 583 571 512 524 555 552 536 617 635 530 549 588 592 541 592 545 583 551 583 582 556 597 612 569 547 582 622 556 564 582 550 585 541 634 570 546 580 616 533 560 576 624 570 605 566 606 563 587 561 570 630 572 614 588 544 576 605 562 563 635 567 545 590 621 547 649 602 608 569 589 593 563 552 611 604 622 621 551 554 575 566 520 621 551 630 583 634 608 579 553 574 590 610 606 597 587 596 579 586 672 565 570 615 585 578 563 597 585 607 563 603 566 615 598 658 598 641 587 561 561 615 589 646 587 593 600 651 615 590 584 597 560 612 578 623 583 610 634 599 591 601 619 578 634 618 616 621 601 598 620 627 637 656 607 621 601 622 576 607 605 639 599 616 664 668 623 610 631 646 616 635 587 623 613 646 648 638 593 629 616 624 588 654 637 608 618 646 593 588 637 551 583 589 656 604 638 627 670 644 626 635 648 614 638 663 674 654 657 648 598 636 645 630 598 605 634 635 654 614 599 617 611 637 619 660 661 594 624 640 622 649 599 619 616 598 623 626 643 614 635 623 636 626 659 639 604 640 664 659 670 635 607 576 676 628 658 653 654 617 677 673 647 674 662 631 649 635 674 616 661 648 640 648 670 620 667 703 638 686 635 643 641 655 652 677 671 663 665 627 676 655 677 642 659 697 639 682 653 666 691 643 639 639 723 629 695 620 624 613 707 661 683 675 656 649 689 636 671 633 700 662 724 689 613 736 690 693 689 676 687 708 714 644 711 673 663 684 694 682 689 701 729 631 682 641 706 712 733 686 671 673 717 728 657 686 724 682 649 734 675 721 667 676 705 704 686 674 714 714 725 688 710 724 679 692 715 667 703 717 694 713 716 699 724 753 727 736 748 736 754 740 755 767 755 755 759 712 744 691 743 670 706 778 725 677 727 734 717 722 693 743 780 728 710 662 754 718 726 726 711 745 715 758 781 711 752 758 751 721 711 702 713 716 727 700 772 734 766 731 744 753 718 746 777 748 761 758 800 729 790 792 755 806 764 764 768 789 806 804 762 783 813 845 807 749 759 717 775 787 799 748 761 800 781 700 714 773 759 780 811 741 738 720 758 795 758 713 792 742 780 790 778 740 742 755 743 748 776 726 739 801 768 732 766 736 772 748 751 739 723 770 819 758 774 761 766 784 808 797 697 757 726 802</counts>
			</dataPoints>
		</scan>
	</xrdMeasurement>
</xrdMeasurements>