File: Data Files/Full/MSS p (6-129, 5w)_01.xrdml
<?xml version="1.0"?>
<xrdMeasurements xmlns="http://www.xrdml.com/XRDMeasurement/2.2" xmlns:xsi="http://www.w3.org/2001/XMLSchema-instance" xsi:schemaLocation="http://www.xrdml.com/XRDMeasurement/2.2 http://www.xrdml.com/XRDMeasurement/2.2/XRDMeasurement.xsd" status="Completed" recordIdentifier="{5801F002-5C4C-4B60-B47D-E506E4F81D9E}">
	<comment>
		<entry/>
	</comment>
	<sample type="To be analyzed">
		<id>p</id>
		<name></name>
		<preparedBy></preparedBy>
	</sample>
	<xrdMeasurement measurementType="Scan" status="Completed" sampleMode="Reflection">
		<usedWavelength intended="K-Alpha 1">
			<kAlpha1 unit="Angstrom">1.5405980</kAlpha1>
			<kAlpha2 unit="Angstrom">1.5444260</kAlpha2>
			<kBeta unit="Angstrom">1.3922500</kBeta>
			<ratioKAlpha2KAlpha1>0.5000</ratioKAlpha2KAlpha1>
		</usedWavelength>
		<incidentBeamPath>
			<radius unit="mm">145.00</radius>
			<xRayTube id="1010048" name="Empyrean Cu LFF HR (9430 033 7310x) DK437964">
				<tension unit="kV">40.0</tension>
				<current unit="mA">15.0</current>
				<anodeMaterial>Cu</anodeMaterial>
				<focus type="Line">
					<length unit="mm">12.0</length>
					<width unit="mm">0.4</width>
					<takeOffAngle unit="deg">6.0</takeOffAngle>
				</focus>
			</xRayTube>
			<filter id="20010004" name="Beta-filter Nickel">
				<material>Ni</material>
				<thickness unit="mm">0.020</thickness>
			</filter>
			<sollerSlit id="21010002" name="Soller slits 0.04 rad.">
				<opening unit="rad">0.0400</opening>
			</sollerSlit>
			<mask id="22031000" name="Fixed mask 13 mm">
				<width unit="mm">9.00</width>
			</mask>
			<divergenceSlit id="22120002" name="Divergence slit 1/2°" xsi:type="fixedDivergenceSlitType">
				<distanceToSample unit="mm">50.00</distanceToSample>
				<height unit="mm">0.76</height>
			</divergenceSlit>
		</incidentBeamPath>
		<diffractedBeamPath>
			<radius unit="mm">145.00</radius>
			<parallelPlateCollimator id="25020001" name="Parallel plate collimator 0.28°">
				<opening unit="deg">0.28</opening>
			</parallelPlateCollimator>
			<detector id="7010020" name="PIXcel3D-Medipix3 1x1 detector" xsi:type="areaDetectorType">
				<phd unit="keV">
					<lowerLevel>4.0</lowerLevel>
					<upperLevel>11.3</upperLevel>
				</phd>
				<mode>Receiving slit</mode>
				<activeChannelsEquatorial>255</activeChannelsEquatorial>
				<activeChannelsAxial>255</activeChannelsAxial>
				<pitchEquatorial unit="mm">0.05500</pitchEquatorial>
				<pitchAxial unit="mm">0.05500</pitchAxial>
				<readOutPeriod unit="seconds">0.050</readOutPeriod>
			</detector>
		</diffractedBeamPath>
		<scan appendNumber="0" mode="Continuous" scanAxis="2Theta" status="Completed">
			<header>
				<startTimeStamp>2025-06-20T12:51:57-08:00</startTimeStamp>
				<endTimeStamp>2025-06-21T02:32:02-08:00</endTimeStamp>
				<author>
					<name>Instrument</name>
				</author>
				<source>
					<applicationSoftware version="1.6 (94)">PANalytical Aeris Instrument Suite</applicationSoftware>
					<instrumentControlSoftware version="3.0.0 20211014">AERIS</instrumentControlSoftware>
					<instrumentID>2855484</instrumentID>
				</source>
			</header>
			<dataPoints>
				<positions axis="2Theta" unit="deg">
					<startPosition>6.005</startPosition>
					<endPosition>128.995</endPosition>
				</positions>
				<positions axis="Omega" unit="deg">
					<commonPosition>5.000</commonPosition>
				</positions>
				<commonCountingTime unit="seconds">3.520</commonCountingTime>
				<counts 4768 4710 4742 4646 4666 4787 4734 4718 4633 4652 4720 4734 4665 4411 4612 4566 4535 4579 4561 4565 4418 4503 4430 4547 4468 4470 4478 4542 4468 4409 4429 4559 4287 4447 4515 4467 4386 4437 4406 4405 4265 4410 4504 4335 4500 4344 4416 4386 4401 4424 4380 4317 4309 4461 4339 4357 4396 4250 4331 4342 4391 4364 4373 4415 4376 4372 4390 4353 4328 4353 4299 4323 4269 4361 4280 4316 4286 4411 4315 4467 4327 4220 4251 4306 4229 4355 4316 4287 4303 4279 4214 4253 4262 4204 4164 4310 4236 4257 4314 4169 4251 4276 4253 4224 4166 4173 4123 4281 4166 4222 4223 4190 4341 4077 4166 4219 4179 4070 4096 4186 4099 4348 4213 4203 4101 3844 4082 4202 4089 4102 4071 4117 4115 4004 4066 4110 3985 4052 3976 4141 4121 4048 3973 3944 3937 3896 4057 4152 3964 4182 3947 4003 4038 3986 3999 3880 3965 3925 4072 3944 3966 4035 4042 4066 4123 4126 4066 4067 3878 4094 4075 4090 4169 4248 4217 4220 4181 4163 4178 4067 4321 4161 4173 4295 4196 4260 4274 4142 4199 4241 4149 4184 4299 4191 4100 4131 4187 4137 4137 4196 3976 4026 4072 4083 3930 4066 3929 4015 3923 3911 3790 3908 3742 3812 3805 3744 3783 3727 3633 3744 3682 3674 3860 3687 3658 3599 3586 3553 3541 3641 3671 3540 3551 3381 3397 3579 3559 3352 3452 3534 3481 3349 3474 3514 3487 3351 3405 3490 3424 3441 3426 3414 3422 3340 3361 3502 3370 3395 3389 3389 3516 3413 3334 3357 3443 3333 3437 3369 3292 3433 3419 3316 3319 3388 3467 3410 3313 3457 3360 3296 3366 3275 3391 3366 3406 3440 3334 3312 3342 3288 3340 3198 3436 3323 3429 3252 3340 3320 3437 3316 3479 3368 3419 3373 3457 3346 3328 3306 3301 3229 3276 3477 3340 3232 3314 3324 3358 3250 3267 3405 3364 3256 3309 3268 3294 3320 3331 3247 3329 3385 3360 3197 3285 3247 3304 3361 3341 3409 3280 3217 3323 3184 3355 3302 3308 3364 3310 3246 3280 3215 3318 3379 3437 3391 3416 3450 3395 3447 3369 3297 3223 3275 3442 3343 3333 3258 3327 3197 3323 3348 3288 3266 3375 3329 3448 3371 3331 3400 3317 3406 3303 3423 3345 3385 3456 3531 3372 3365 3424 3257 3368 3441 3439 3433 3328 3307 3446 3437 3450 3569 3398 3459 3555 3515 3441 3400 3481 3433 3342 3600 3467 3334 3582 3530 3497 3461 3450 3535 3404 3392 3527 3477 3408 3533 3540 3515 3577 3554 3496 3537 3556 3650 3484 3434 3485 3566 3568 3509 3508 3583 3532 3623 3604 3641 3659 3573 3545 3680 3593 3518 3582 3652 3584 3666 3637 3696 3593 3629 3673 3626 3579 3772 3700 3694 3621 3683 3703 3689 3756 3685 3558 3683 3621 3720 3656 3836 3841 3732 3787 3735 3762 3642 3671 3784 3741 3669 3750 3743 3760 3873 3851 3732 3785 3824 3834 3826 3916 3903 3879 3754 3806 3906 3723 3801 3835 3786 3902 3874 3833 3789 4025 3847 3862 3841 3907 3856 3966 3896 3928 3955 3823 3967 3885 3960 3867 3935 3848 4023 3936 4064 4048 4021 3995 3995 3993 4028 4095 4115 3950 4045 4130 4075 4042 4052 4023 3936 4080 4038 4117 4090 4066 4017 4050 4145 4113 4097 4300 4179 4073 4220 4232 4101 4114 4269 4197 4169 4139 4174 4213 4293 4381 4347 4245 4246 4226 4472 4255 4338 4356 4313 4341 4210 4349 4331 4310 4368 4361 4394 4371 4390 4319 4417 4276 4451 4422 4318 4364 4497 4444 4588 4510 4509 4344 4359 4460 4501 4526 4497 4531 4481 4609 4649 4530 4525 4632 4584 4704 4665 4595 4664 4600 4611 4666 4517 4646 4590 4637 4673 4613 4753 4733 4677 4704 4677 4691 4705 4844 4726 4786 4715 4656 4889 4898 4881 4846 4858 4960 4798 4776 4829 4845 4686 4979 4941 4950 4835 4867 5001 4897 4844 4906 4971 4790 4930 4985 4863 5009 4997 5010 5000 5021 5080 4991 5023 5140 5086 4957 5147 5153 5184 5173 5097 5093 5137 5298 5094 5212 5294 5181 5264 5128 5226 5201 5139 5213 5271 5151 5196 5235 5245 5287 5246 5283 5280 5286 5222 5380 5348 5240 5294 5310 5342 5446 5232 5439 5519 5243 5513 5409 5391 5532 5392 5432 5536 5368 5485 5421 5450 5472 5539 5422 5568 5477 5586 5393 5552 5519 5600 5606 5632 5489 5574 5622 5570 5535 5567 5584 5377 5587 5498 5682 5702 5663 5590 5504 5697 5535 5647 5614 5614 5711 5641 5724 5456 5725 5650 5633 5688 5724 5826 5650 5651 5625 5602 5649 5708 5604 5613 5775 5655 5620 5582 5745 5615 5657 5617 5663 5659 5578 5698 5697 5832 5631 5692 5721 5706 5646 5680 5713 5662 5688 5517 5717 5741 5663 5676 5707 5641 5682 5864 5667 5613 5939 5591 5578 5716 5677 5532 5595 5636 5511 5650 5600 5692 5705 5486 5685 5603 5583 5653 5698 5606 5585 5602 5564 5449 5553 5530 5521 5514 5647 5607 5499 5557 5528 5587 5563 5524 5478 5577 5393 5479 5387 5463 5421 5398 5429 5501 5336 5472 5346 5517 5467 5460 5398 5434 5479 5382 5292 5393 5213 5376 5423 5292 5208 5295 5390 5239 5402 5202 5183 5231 5247 5227 5235 5155 5394 5190 5121 5042 5074 5196 5231 5139 5101 5082 5011 5087 4894 5215 5150 5029 5081 4924 5056 4907 4965 4956 5041 4941 4981 5023 4828 4916 4888 4924 4911 4804 4785 4822 4814 4842 4840 4916 4705 4923 4873 4834 4732 4723 4724 4773 4859 4669 4688 4754 4746 4790 4735 4710 4641 4636 4779 4614 4517 4616 4537 4510 4741 4471 4551 4582 4463 4599 4583 4419 4521 4519 4461 4562 4455 4449 4356 4483 4571 4514 4362 4539 4484 4353 4491 4328 4446 4243 4381 4353 4255 4351 4292 4263 4453 4310 4271 4333 4344 4377 4232 4218 4162 4254 4166 4131 4174 4289 4095 4146 4132 4166 4200 4078 4168 4165 4117 4101 3980 4036 4002 3986 4072 4126 4114 3972 4107 3973 4124 3960 3995 3915 4001 3901 3964 3992 3944 4001 3893 3819 3812 3853 3798 3864 3885 3915 3767 3830 3948 3938 3884 3858 3761 3836 3817 3880 3835 3642 3806 3827 3660 3729 3681 3892 3653 3722 3741 3748 3646 3685 3716 3578 3617 3545 3599 3616 3491 3694 3635 3551 3609 3597 3544 3527 3598 3512 3515 3592 3471 3518 3642 3611 3597 3562 3520 3578 3604 3459 3564 3394 3569 3407 3545 3472 3480 3470 3447 3508 3502 3434 3443 3516 3371 3401 3381 3376 3419 3430 3508 3357 3393 3380 3382 3491 3316 3308 3442 3300 3326 3399 3416 3339 3384 3264 3236 3352 3368 3316 3266 3330 3238 3358 3238 3312 3347 3274 3150 3287 3100 3210 3141 3257 3193 3180 3181 3187 3317 3190 3188 3152 3290 3256 3139 3277 3150 3052 3190 3212 3156 3151 3134 3144 3188 3258 3099 3068 3079 3129 3124 3104 3026 3112 3220 3110 3145 3099 3038 3029 3035 3049 3132 3070 3091 3044 3143 3007 3041 2969 2955 3216 2900 3082 2885 3016 3015 2940 2989 2886 2989 2961 2968 3051 2971 2975 2856 2917 2923 2954 2878 2985 2959 3044 2908 2921 2879 3014 2873 2933 2899 2929 2972 2946 2996 2904 2903 3067 2828 2937 2834 2988 2903 2858 2867 2898 2824 2835 2860 2936 2873 2847 2917 2873 2782 2877 2810 2833 2872 2848 2830 2813 2958 2831 2855 2924 2733 2753 2910 2717 2790 2849 2779 2831 2851 2891 2863 2855 2834 2758 2814 2760 2727 2672 2851 2764 2758 2786 2810 2692 2692 2716 2830 2758 2893 2793 2739 2860 2774 2751 2787 2775 2803 2891 2884 2960 3100 3091 3299 3394 3658 3933 4062 4271 4497 4768 5027 5246 5345 5696 6021 6066 6425 6591 6571 6725 6929 7073 7253 7393 7296 7284 7520 7403 7488 7221 7182 7016 6809 6545 6002 5861 5610 5116 4720 4488 4316 3901 3656 3422 3262 3072 2893 2762 2689 2728 2619 2579 2660 2635 2598 2601 2621 2676 2630 2541 2469 2662 2545 2685 2582 2663 2571 2703 2709 2447 2565 2564 2560 2437 2595 2599 2616 2582 2560 2554 2544 2559 2504 2594 2628 2609 2549 2540 2522 2649 2605 2585 2532 2548 2539 2537 2564 2579 2530 2549 2447 2446 2542 2439 2552 2625 2457 2497 2543 2461 2402 2407 2548 2514 2582 2539 2483 2479 2527 2487 2482 2552 2491 2465 2548 2425 2425 2493 2451 2478 2488 2531 2516 2444 2483 2567 2406 2397 2447 2438 2430 2377 2456 2485 2426 2517 2352 2438 2496 2495 2478 2396 2381 2430 2423 2582 2528 2469 2487 2421 2405 2365 2441 2379 2366 2461 2457 2444 2438 2466 2438 2455 2291 2320 2428 2224 2579 2348 2403 2408 2487 2321 2418 2382 2353 2344 2381 2386 2382 2368 2301 2266 2284 2362 2410 2347 2352 2350 2430 2307 2348 2254 2299 2337 2302 2417 2291 2297 2317 2384 2352 2321 2369 2407 2280 2327 2235 2299 2358 2394 2276 2333 2272 2385 2272 2251 2340 2322 2257 2272 2309 2236 2308 2301 2260 2312 2364 2256 2352 2291 2276 2210 2344 2372 2261 2236 2264 2191 2240 2283 2265 2212 2338 2262 2200 2149 2211 2325 2274 2317 2253 2322 2214 2254 2244 2289 2347 2236 2225 2275 2283 2173 2267 2352 2226 2205 2224 2318 2276 2181 2250 2269 2344 2226 2186 2284 2191 2239 2174 2187 2250 2187 2268 2140 2257 2283 2191 2351 2210 2159 2194 2192 2150 2087 2340 2180 2251 2276 2188 2186 2219 2390 2209 2207 2101 2202 2191 2235 2160 2181 2244 2144 2109 2251 2228 2207 2264 2191 2239 2220 2141 2189 2107 2141 2208 2230 2200 2205 2136 2127 2096 2225 2181 2170 2164 2083 2148 2152 2176 2151 2212 2337 2086 2131 2110 2131 2167 2309 2205 2214 2216 2135 2230 2143 2213 2177 2257 2109 2272 2178 2081 2242 2158 2195 2230 2206 2165 2123 2054 2173 2193 2060 2072 2075 2113 2097 2169 2203 2154 2153 2131 2232 2158 2095 2159 2119 2145 2142 2067 2271 2311 2233 2135 2168 2140 2116 2218 2150 2174 2141 2218 2091 2103 2212 2193 2208 2134 2207 2197 2208 2185 2177 2150 2131 2220 2321 2230 2217 2214 2242 2357 2212 2342 2373 2388 2559 2697 2965 3179 3520 3875 4284 4670 5263 5810 6242 6872 7359 7930 8632 9025 9453 10253 10630 11236 11476 12014 12410 12885 13376 13712 14043 14556 14463 14397 14219 14438 13899 13663 13393 12414 11759 10926 9796 8903 8063 7118 6276 5537 5095 4096 3794 3230 2991 2661 2555 2424 2390 2259 2392 2414 2362 2223 2324 2229 2373 2169 2277 2166 2273 2225 2265 2207 2275 2060 2157 2111 2167 2208 2167 2146 2124 2123 2115 2089 2175 2206 2088 2046 2117 2168 2061 2066 2047 2070 2052 2085 2105 2101 2089 2088 2107 2053 2057 2130 2009 2085 2180 2068 2108 2013 2077 2093 2141 2018 2149 2112 2050 2074 2105 2171 2067 2149 2017 2001 2123 2052 2004 2149 2079 2053 2105 2155 1995 2123 2014 2056 2140 2113 2197 2163 2135 2048 2082 2197 1995 2043 2107 2128 2168 2088 2058 2096 2115 1981 2086 2058 2170 2052 2109 1954 2124 2111 2106 2068 2089 2059 1995 2127 2030 2073 2031 2039 2107 2051 2125 1998 2077 1989 2063 2093 2093 1979 2049 2051 2055 2113 2057 2037 2051 2043 2040 2058 2049 2053 2035 2063 2031 2054 2062 2046 2045 2019 2113 1997 2000 1980 2087 2106 1876 2022 2062 2076 2024 2075 1935 2040 2080 2057 1998 2073 2044 1986 2021 1969 1946 1902 2029 2041 1987 2107 2157 2016 1959 2015 1968 1999 2059 2019 2009 1927 1954 2011 1968 1982 2048 2054 1912 1923 1980 2045 2129 1993 2036 2038 2061 2093 2068 1970 2007 1986 2085 2042 1975 2030 1996 2055 1987 2053 2062 2025 2031 2011 2036 2022 2085 2040 2079 1942 2041 1992 2041 1948 1994 2031 2079 1995 1928 2089 2001 1954 1970 2091 2025 1995 2015 1993 1942 1972 1929 1927 2044 1990 1931 2045 1905 1986 1915 2035 2037 2028 2062 1998 2005 1953 1933 2019 1950 1893 2038 2124 1949 1940 1981 2066 1995 1976 2023 2086 1977 1954 2033 2018 1951 2092 2050 2044 2049 1935 2023 1980 1880 1996 1939 2062 1992 1899 2063 2003 2045 2008 2058 2022 1999 2039 1980 2016 2042 2059 2039 2033 2052 2093 2035 2007 2046 2042 2099 1931 2044 2091 2015 2087 2193 2269 2352 2508 2713 2905 2975 3225 3416 3855 3969 4246 4454 4782 4940 5143 5414 5480 5630 5972 6023 6286 6505 6657 6899 6935 7059 6964 7006 6869 6876 6829 6557 6650 6274 6141 5621 5393 5040 4601 4276 3950 3658 3278 3137 2709 2695 2444 2276 2199 2206 2099 2128 2084 2143 2066 2064 2013 2118 2049 2043 2026 2091 1986 2074 2065 2037 1900 2044 2003 2011 2071 1910 2004 1916 2005 1977 2105 2044 1986 1929 2024 2092 1993 1982 1966 2009 1985 1992 2089 1951 2020 2041 2023 1967 2003 2065 1930 1900 1958 2023 2012 2019 2034 1982 2079 2084 1954 1949 2079 2082 1902 1931 2015 1985 2011 1981 2064 1946 2060 2080 2094 1985 1991 2021 2031 2004 1960 1960 2017 2019 2015 1963 2065 1915 2014 2017 1958 2065 1982 2086 2045 2015 2074 2016 1937 1977 2068 2041 1970 2010 1956 2005 1995 2109 2006 1982 2035 1991 1999 2043 1970 2086 1920 1924 2024 2003 2149 2032 2113 2107 2049 2050 2133 2033 2074 2189 2252 2175 2163 2148 2211 2340 2220 2231 2213 2184 2149 2248 2298 2232 2224 2249 2221 2148 2163 2066 2164 2292 2135 2098 2106 2132 2023 2068 2129 2169 2038 2228 2103 2097 2063 2111 2059 2094 2095 2058 2011 1971 2121 2175 2106 2132 1992 2064 2056 2149 2131 2092 2077 2111 2160 2105 2048 2072 2112 2084 2194 2182 2030 2102 2169 2164 2066 2174 2143 2135 2195 2215 2150 2132 2181 2122 2114 2064 2019 2252 2140 2126 2103 2122 2225 2225 2217 2289 2139 2295 2256 2215 2172 2151 2144 2232 2269 2196 2250 2217 2218 2203 2159 2199 2174 2191 2189 2211 2208 2205 2341 2322 2212 2274 2308 2333 2288 2366 2203 2322 2258 2328 2387 2391 2300 2395 2315 2241 2319 2450 2465 2333 2512 2374 2330 2437 2448 2455 2405 2403 2433 2384 2454 2426 2521 2424 2487 2576 2462 2547 2417 2516 2431 2587 2533 2589 2551 2585 2629 2595 2567 2634 2601 2604 2584 2711 2648 2597 2685 2714 2768 2631 2643 2686 2784 2761 2715 2731 2807 2788 2776 2727 2883 2804 2772 2784 2863 2785 2896 2810 2940 3015 2939 2904 2991 2976 3011 3014 2980 3107 2977 3123 3046 2963 3054 3082 3043 3218 3105 3124 3151 3178 3181 3234 3265 3304 3238 3236 3256 3300 3309 3308 3277 3386 3300 3372 3323 3283 3258 3233 3436 3418 3435 3372 3499 3281 3362 3419 3410 3358 3451 3518 3482 3383 3399 3509 3552 3446 3325 3515 3407 3465 3471 3501 3388 3389 3421 3290 3462 3366 3266 3449 3349 3361 3243 3206 3180 3232 3374 3201 3255 3338 3149 3235 3230 3237 3123 3109 3072 3135 3060 3028 3032 2915 2948 3144 3009 3002 2965 2900 2854 3005 2879 2854 2903 2866 2803 2835 2928 2774 2735 2702 2748 2674 2714 2705 2622 2761 2728 2604 2636 2630 2605 2582 2578 2645 2560 2617 2668 2560 2644 2638 2572 2509 2551 2466 2610 2426 2560 2473 2512 2433 2410 2418 2332 2444 2416 2316 2346 2300 2309 2212 2279 2145 2229 2254 2275 2203 2151 2262 2231 2214 2155 2153 2114 2198 2165 2137 2175 2141 2096 2081 2094 2125 2084 2124 2073 2116 2116 2127 2101 2096 2105 2003 2042 2118 2139 2067 2037 2038 2076 2075 2208 2114 2076 2251 2260 2178 2260 2385 2295 2354 2439 2569 2564 2506 2645 2670 2933 3357 3897 4552 5373 6401 7466 8602 10103 11468 13420 15164 17479 19507 21693 23847 25459 27621 29364 30756 32842 34190 35721 36992 38366 39381 39518 40137 39634 39400 38514 37620 36942 35843 34390 32842 30481 28228 26219 23872 21688 19194 16719 14322 12311 10311 8580 6926 5653 4587 3774 3149 2725 2388 2400 2255 2234 2255 2116 2182 2058 2062 1997 1986 1965 1996 1915 1822 1838 1853 1848 1781 1786 1674 1724 1831 1828 1761 1749 1738 1717 1709 1717 1710 1643 1788 1781 1621 1705 1760 1785 1604 1795 1713 1775 1755 1737 1655 1638 1689 1844 1636 1653 1659 1613 1680 1706 1687 1707 1687 1786 1603 1755 1703 1690 1681 1596 1717 1631 1744 1473 1815 1610 1660 1734 1740 1679 1623 1579 1682 1680 1738 1588 1552 1571 1620 1587 1461 1629 1444 1691 1559 1526 1660 1682 1624 1648 1495 1510 1511 1511 1635 1615 1538 1685 1506 1487 1606 1606 1552 1575 1668 1518 1546 1523 1580 1602 1529 1668 1625 1575 1503 1552 1598 1595 1596 1413 1531 1527 1644 1423 1651 1530 1499 1543 1486 1594 1573 1415 1535 1468 1608 1477 1550 1610 1374 1526 1580 1725 1570 1434 1458 1441 1502 1508 1430 1538 1627 1558 1473 1463 1563 1662 1599 1494 1546 1411 1583 1563 1458 1501 1520 1567 1483 1401 1443 1466 1530 1589 1471 1452 1489 1570 1582 1337 1531 1511 1600 1527 1493 1529 1453 1448 1526 1518 1402 1528 1492 1425 1561 1600 1484 1415 1403 1643 1505 1537 1534 1521 1372 1423 1473 1361 1503 1441 1423 1420 1389 1407 1577 1250 1302 1431 1493 1492 1398 1351 1550 1520 1421 1376 1278 1390 1492 1486 1548 1423 1343 1367 1475 1509 1368 1412 1329 1287 1480 1482 1427 1501 1505 1437 1375 1463 1403 1426 1456 1360 1406 1479 1229 1376 1351 1454 1387 1262 1379 1390 1633 1366 1423 1369 1238 1515 1386 1228 1213 1314 1379 1257 1470 1449 1418 1320 1368 1402 1439 1397 1388 1237 1404 1427 1298 1296 1390 1464 1452 1368 1496 1345 1333 1428 1292 1381 1394 1361 1367 1398 1538 1366 1506 1291 1447 1543 1391 1348 1382 1318 1332 1519 1231 1423 1328 1387 1354 1346 1521 1356 1425 1346 1263 1359 1257 1371 1466 1273 1314 1392 1320 1300 1387 1288 1351 1378 1403 1361 1249 1395 1332 1304 1273 1381 1361 1315 1264 1292 1266 1190 1372 1401 1327 1352 1320 1430 1477 1330 1376 1419 1396 1236 1352 1349 1435 1451 1282 1345 1245 1378 1283 1457 1312 1327 1269 1299 1202 1233 1334 1237 1340 1361 1432 1256 1308 1248 1325 1185 1299 1187 1193 1246 1382 1279 1272 1256 1361 1288 1265 1295 1269 1255 1271 1276 1244 1230 1253 1344 1240 1201 1360 1312 1291 1264 1344 1314 1268 1297 1414 1251 1178 1274 1350 1462 1239 1174 1274 1202 1211 1212 1381 1290 1484 1264 1254 1242 1311 1290 1238 1321 1268 1211 1347 1403 1229 1352 1265 1287 1289 1346 1325 1242 1319 1244 1193 1276 1194 1161 1315 1275 1223 1260 1259 1310 1344 1252 1309 1262 1251 1287 1248 1255 1198 1333 1354 1237 1230 1211 1272 1212 1322 1336 1256 1324 1204 1292 1348 1327 1257 1235 1229 1153 1230 1375 1232 1221 1214 1331 1193 1200 1341 1191 1260 1220 1216 1188 1260 1182 1240 1348 1184 1255 1277 1376 1252 1287 1229 1370 1218 1250 1272 1189 1224 1241 1310 1278 1277 1233 1319 1300 1309 1256 1273 1283 1266 1270 1295 1210 1278 1272 1240 1282 1229 1329 1374 1453 1681 1651 1734 1883 1966 1896 1973 2190 2329 2217 2505 2436 2568 2573 2755 2683 2801 2840 3043 2958 3082 3142 3105 3066 3050 3113 3061 2876 2893 2898 2776 2733 2593 2523 2497 2343 2080 1983 2002 1907 1845 1754 1668 1528 1365 1372 1304 1170 1304 1150 1240 1275 1174 1170 1242 1249 1181 1260 1224 1260 1242 1210 1233 1211 1269 1222 1303 1188 1205 1183 1213 1255 1225 1174 1307 1283 1375 1250 1198 1206 1215 1198 1143 1289 1182 1355 1129 1318 1165 1180 1218 1176 1194 1220 1199 1170 1195 1250 1201 1200 1260 1165 1174 1221 1324 1244 1152 1239 1294 1167 1186 1196 1297 1234 1206 1258 1250 1198 1178 1213 1230 1298 1206 1187 1253 1304 1226 1218 1193 1224 1187 1204 1182 1199 1234 1178 1324 1153 1203 1255 1262 1188 1244 1132 1223 1185 1252 1202 1197 1241 1287 1187 1261 1218 1232 1217 1295 1304 1413 1245 1321 1297 1190 1339 1217 1311 1442 1330 1344 1418 1294 1416 1453 1369 1435 1468 1350 1467 1396 1285 1340 1297 1417 1387 1370 1245 1247 1280 1338 1204 1290 1302 1310 1233 1201 1185 1169 1280 1254 1233 1226 1262 1199 1115 1186 1185 1201 1261 1166 1159 1207 1325 1149 1206 1230 1217 1176 1296 1212 1210 1192 1313 1248 1149 1259 1198 1185 1270 1180 1273 1368 1206 1242 1247 1261 1208 1240 1230 1170 1236 1203 1273 1246 1206 1145 1287 1315 1225 1208 1172 1234 1271 1230 1215 1225 1190 1272 1216 1219 1224 1209 1252 1346 1236 1238 1289 1210 1222 1226 1222 1185 1274 1208 1216 1295 1176 1221 1294 1350 1225 1175 1293 1296 1381 1206 1171 1214 1202 1308 1243 1229 1202 1354 1342 1216 1244 1296 1328 1284 1299 1240 1236 1278 1247 1263 1254 1191 1262 1283 1518 1347 1250 1142 1357 1282 1282 1224 1367 1286 1330 1306 1209 1383 1251 1389 1304 1224 1331 1280 1392 1341 1240 1264 1243 1347 1227 1253 1258 1400 1293 1339 1248 1338 1231 1323 1266 1357 1248 1230 1193 1214 1254 1273 1329 1260 1192 1335 1367 1277 1287 1274 1323 1302 1411 1344 1375 1307 1376 1278 1241 1274 1450 1334 1258 1420 1317 1278 1281 1184 1388 1295 1318 1269 1216 1353 1293 1337 1408 1488 1307 1342 1385 1289 1210 1379 1454 1357 1378 1388 1334 1547 1480 1378 1459 1641 1744 1833 1780 1984 2034 2035 2090 2358 2448 2466 2467 2705 2681 2818 2874 2946 3060 3028 3030 3121 3121 3182 3095 3056 3083 3082 2981 3018 2998 2973 2701 2800 2612 2468 2335 2272 2192 2114 1955 1934 1828 1672 1558 1637 1554 1598 1462 1524 1546 1396 1479 1402 1478 1419 1454 1421 1252 1340 1380 1441 1312 1605 1428 1362 1426 1522 1576 1546 1496 1296 1422 1434 1520 1474 1397 1479 1474 1503 1484 1300 1447 1413 1478 1434 1594 1401 1389 1411 1529 1498 1486 1532 1535 1436 1415 1490 1478 1496 1536 1544 1621 1643 1559 1582 1437 1545 1539 1618 1534 1556 1582 1663 1665 1682 1567 1553 1532 1701 1748 1700 1634 1673 1731 1600 1641 1603 1655 1679 1726 1677 1547 1633 1636 1675 1739 1631 1642 1725 1703 1691 1682 1777 1658 1780 1762 1716 1779 1840 1782 1751 1773 1695 1824 1822 1823 1807 1803 1830 1852 1847 1828 1957 1850 1924 1920 1845 1868 1924 1967 1905 1827 1840 1935 1934 1894 1838 2003 1942 1984 1941 2006 1977 1989 1851 1989 1913 1987 1961 2016 1939 2006 2020 1945 2003 2097 2054 2049 1996 2010 2005 2120 2041 2050 2084 2122 2096 2099 1952 2114 2183 2087 2159 2081 2083 2063 2119 2199 2033 2164 2128 2120 2175 2131 2276 2098 2064 2150 2214 2213 2142 2213 2111 2154 2187 2158 2099 2142 2159 2091 2225 2164 2126 2177 2222 2260 2156 2255 2202 2110 2236 2181 2201 2124 2156 2277 2288 2227 2258 2280 2255 2284 2185 2204 2192 2179 2257 2104 2245 2229 2245 2186 2170 2230 2129 2250 2228 2324 2214 2214 2254 2308 2209 2217 2120 2171 2228 2319 2260 2239 2216 2238 2229 2260 2332 2350 2425 2334 2483 2439 2537 2447 2533 2472 2467 2453 2514 2578 2516 2508 2606 2531 2489 2538 2497 2538 2594 2445 2387 2513 2430 2410 2459 2301 2300 2425 2317 2243 2270 2285 2226 2254 2142 2100 2219 2073 2069 2208 2059 2111 2087 2148 2189 2206 2145 2075 2063 2118 2110 2089 2173 2118 2038 2071 2003 2169 2231 2012 2158 2078 2134 2170 2112 2029 2072 2031 2079 2123 2096 2084 2146 2080 2080 2023 2009 1971 2055 1993 2060 2088 2004 2039 2091 2077 1952 2046 1945 2057 2030 1917 2051 1931 1978 1981 1915 1941 2007 1883 2035 1974 1950 1948 1786 1981 1828 2000 1931 1947 1970 1918 1834 1975 1904 1884 1916 1872 1879 1914 1917 1911 1911 1867 1900 1863 1854 1792 1876 1880 1809 1879 1846 1806 1868 1816 1771 1848 1916 1786 1930 1769 1829 1795 1722 1738 1827 1816 1869 1818 1786 1765 1779 1738 1714 1836 1833 1820 1797 1766 1719 1707 1816 1741 1707 1721 1745 1816 1695 1746 1747 1761 1624 1760 1669 1698 1707 1740 1754 1665 1642 1536 1754 1607 1706 1700 1685 1620 1724 1591 1555 1561 1585 1607 1457 1526 1657 1619 1712 1618 1502 1565 1617 1535 1622 1571 1645 1677 1510 1564 1628 1546 1580 1646 1722 1655 1647 1804 1766 1680 1777 1751 1936 1813 1906 1891 1851 1865 1838 1845 1854 1881 1871 1888 1916 1825 1804 1825 1805 1742 1541 1675 1573 1586 1535 1529 1612 1404 1466 1417 1438 1317 1357 1314 1397 1355 1456 1267 1367 1446 1383 1364 1346 1332 1327 1350 1279 1336 1372 1274 1410 1389 1382 1316 1268 1308 1361 1180 1266 1201 1252 1224 1372 1220 1233 1341 1263 1232 1333 1341 1382 1254 1264 1241 1236 1297 1247 1233 1281 1140 1304 1307 1261 1188 1239 1264 1233 1184 1363 1204 1257 1241 1335 1166 1219 1193 1193 1216 1150 1159 1307 1182 1188 1265 1228 1238 1176 1129 1245 1230 1115 1204 1246 1234 1180 1226 1172 1233 1115 1178 1267 1155 1197 1144 1167 1118 1223 1162 1194 1211 1084 1153 1109 1212 1192 1152 1131 1109 1132 1111 1252 1202 1181 1162 1150 1177 1196 1162 1089 1155 1157 1053 1124 1171 1112 1119 1042 1178 1120 1165 1277 1070 1194 1187 1159 1109 1142 1143 1168 1125 1110 1118 1153 1060 1244 1132 1145 1146 1177 1122 1110 1131 1124 1132 1115 1147 1143 1195 1115 1138 1069 1152 1088 1147 1120 1109 1043 1150 1077 1203 1072 1068 1053 1066 1055 1126 1033 1123 1024 1030 1056 1088 1078 1141 1081 1012 1071 1142 1076 1098 1098 1073 1100 1030 1090 1020 1069 1057 1094 1054 1072 1087 999 1125 1038 1022 1103 1068 1065 1105 1060 1094 1058 997 1007 1092 996 1013 1025 1090 1025 1052 1075 1079 1022 992 1015 1045 1045 1045 987 1051 1005 995 1066 982 988 1055 1035 1044 1010 1009 1010 1033 1027 1014 1072 1084 1038 978 976 1019 956 1029 989 1042 1019 1031 967 973 1019 1040 975 1043 1037 1040 1053 1015 1002 1073 1042 1031 1035 996 1014 1035 1041 1023 1071 1069 1064 1023 1111 1021 1047 1065 1062 991 1004 1022 1043 1039 985 1046 1013 997 1064 1016 981 986 1045 986 1044 1066 943 1010 1000 1000 1081 1046 1013 972 1002 995 968 980 1060 989 1039 963 944 1025 995 1003 1044 993 970 967 1029 920 1012 984 969 975 1032 1016 991 975 984 967 1000 929 1002 982 988 962 1000 933 1025 1005 991 990 1009 989 1008 1076 974 925 1050 1012 978 966 981 937 942 998 993 1016 968 982 1008 986 940 1031 1002 958 923 923 982 983 975 996 995 1005 981 984 959 1041 1008 972 992 952 1070 1026 1011 936 993 968 1047 987 1010 918 1013 1011 1044 1015 998 1019 989 927 971 979 996 952 997 968 998 933 1028 989 962 970 958 980 931 993 940 969 924 951 882 968 957 956 973 1007 988 972 973 977 968 996 977 952 1010 954 959 988 1000 981 1049 929 991 956 1035 1012 1025 1013 1097 1165 1095 1190 1201 1221 1242 1240 1245 1351 1259 1325 1249 1341 1321 1359 1251 1553 1373 1447 1454 1360 1430 1398 1340 1494 1300 1301 1177 1148 1111 1171 1170 1029 1114 1059 1048 982 1062 956 964 1044 1024 891 939 1054 977 989 967 929 981 902 1020 942 971 996 959 944 981 975 979 1017 916 901 959 974 1010 865 980 980 950 900 963 989 968 880 954 982 975 919 1001 964 996 937 985 923 980 1008 961 966 952 952 959 992 928 935 930 997 963 928 985 962 929 981 995 983 906 957 988 925 926 962 941 957 936 947 974 964 991 933 959 967 982 1023 1015 983 912 956 952 976 927 996 1021 933 986 1004 1033 1017 1094 1096 1069 1056 1136 1187 1278 1156 1170 1258 1299 1323 1353 1357 1302 1349 1466 1590 1457 1312 1447 1506 1504 1439 1370 1594 1338 1307 1463 1241 1162 1256 1136 1182 1208 1132 1107 1063 1074 943 1064 1051 997 1020 1040 987 1015 918 981 955 1028 960 964 970 992 962 1000 928 933 922 988 946 907 964 949 940 961 951 932 954 930 957 1007 1002 969 940 971 939 995 990 934 968 1006 970 993 961 974 950 1009 954 1029 1007 902 951 1022 958 968 942 961 986 988 948 932 969 1051 1012 1037 944 967 1027 998 1005 1052 1008 1031 1038 1036 1158 1079 1059 1046 1106 1088 1092 1084 992 1077 986 1108 1081 1020 998 1112 1023 1002 1113 1002 1013 992 1017 1042 1026 996 966 1021 947 982 1014 955 977 1034 938 1051 924 964 936 978 962 962 983 946 936 1004 951 978 985 988 1010 977 939 1053 1006 958 937 960 1002 979 1017 974 975 997 930 1016 960 1081 951 952 1044 961 944 1005 1044 985 1014 942 976 971 957 943 991 966 985 947 996 986 1004 993 1009 991 1041 925 1029 991 975 961 990 1027 934 1005 965 948 956 978 957 1013 938 1011 989 942 1003 951 957 1006 1010 1014 944 901 989 962 953 1005 1033 965 985 1055 960 928 1012 975 966 928 975 950 977 1021 969 1049 997 963 1021 1057 994 1015 959 998 1039 992 988 965 1021 1060 1036 1044 1018 1031 1006 999 1039 1033 1020 981 938 1025 1004 925 1063 1004 969 955 1015 969 987 993 989 1001 996 1004 993 990 959 996 1017 982 962 1024 1000 941 1020 1015 1079 1065 914 963 971 1035 1047 1021 914 998 989 955 1049 1088 1008 1035 1022 933 1004 1005 950 1016 982 989 945 1000 1005 1053 1022 1007 947 975 1015 1066 1004 990 1015 977 988 961 993 961 1000 1017 1073 1040 1045 1025 1065 1016 1046 1009 990 1021 1003 1017 998 986 1009 1011 978 991 958 1014 1024 1041 1042 1034 1005 955 963 1067 964 1025 1010 1000 1063 997 999 1013 980 1036 978 1003 957 1074 1034 1032 998 1048 1042 1059 1036 1007 1012 1022 1028 1027 1003 1049 1009 977 1012 957 980 1039 1045 1067 1024 1138 1037 987 1046 1015 972 1069 1018 1049 1031 1006 1073 942 1058 1079 996 998 1009 1063 1040 1025 1053 1045 975 1036 1042 1041 1033 1033 1009 1013 993 1090 975 1047 1035 1003 1047 1060 1034 975 977 1075 1004 1022 1014 994 1044 1016 1025 995 1046 1081 1022 1023 996 1041 1018 1063 1072 991 1009 1068 1038 1040 988 1089 1043 1060 1034 1080 1002 1024 1034 1014 991 991 1034 1092 978 1041 1051 1019 1087 941 1045 1046 1050 1043 1088 1038 1077 1074 1064 1032 1030 1043 1095 1071 1015 1078 1070 1020 1097 1059 1076 1052 1068 1063 1028 1020 1047 993 1040 1108 1074 1081 1060 1059 1020 1079 1112 1054 1053 1100 985 1076 1042 1045 1046 1120 1031 1011 999 1126 1037 1092 1087 1020 1048 1014 1063 1005 1065 1075 985 1032 1077 1117 1174 1037 1141 1094 1062 1073 1113 1077 1049 1102 1082 1090 1139 1072 1118 1048 1030 1116 1109 1089 1073 1060 1071 1069 1079 1083 1051 1103 1055 1150 1064 1126 1085 1050 1108 1107 1091 1109 1032 1028 1028 1109 1117 1091 1105 1082 1086 1108 1036 1155 1112 1077 1084 1065 1022 1055 1140 1083 1094 1058 1111 1151 1172 1128 1138 1154 1185 1082 1100 1129 1098 1076 1132 1106 1121 1117 1060 1103 1142 1142 1101 1063 1052 1084 1045 1097 1137 1088 1103 1081 1108 1127 1114 1040 1085 1138 1030 1138 1148 1087 1152 1060 1121 1125 1085 1144 1121 1180 1107 1175 1106 1102 1170 1093 1164 1134 1115 1095 1123 1153 1077 1063 1145 1063 1126 1126 1092 1156 1155 1117 1126 1142 1076 1158 1087 1066 1157 1121 1173 1085 1096 1101 1107 1082 1135 1233 1051 1093 1122 1116 1117 1109 1153 1134 1134 1178 1157 1164 1096 1101 1124 1157 1098 1243 1124 1147 1159 1106 1104 1128 1164 1139 1210 1123 1121 1161 1150 1135 1177 1181 1158 1138 1182 1164 1218 1148 1127 1151 1152 1103 1222 1154 1158 1170 1137 1190 1133 1156 1167 1175 1184 1139 1114 1184 1140 1229 1187 1187 1084 1182 1211 1156 1180 1182 1231 1224 1147 1213 1189 1237 1254 1222 1164 1321 1203 1179 1222 1347 1332 1335 1314 1379 1359 1502 1716 1799 1938 2132 2404 2514 2643 2828 3206 3470 3670 4042 4189 4546 4884 4968 5168 5386 5711 5674 5980 6265 6115 6039 6045 5927 6021 5815 5609 5467 5350 4874 4786 4570 4299 3956 3682 3398 3121 2953 2637 2281 2239 2083 1922 1778 1592 1398 1480 1315 1359 1267 1215 1276 1326 1298 1366 1374 1214 1226 1295 1202 1279 1283 1260 1213 1258 1201 1253 1263 1202 1254 1351 1182 1324 1242 1168 1221 1218 1329 1208 1164 1233 1133 1190 1167 1324 1271 1249 1223 1207 1270 1320 1220 1198 1156 1216 1327 1244 1204 1254 1221 1120 1156 1272 1254 1259 1324 1301 1269 1164 1163 1252 1339 1199 1200 1349 1237 1228 1179 1241 1246 1284 1417 1323 1315 1434 1265 1234 1178 1170 1206 1271 1294 1219 1319 1325 1260 1237 1281 1302 1194 1259 1252 1343 1363 1232 1305 1367 1227 1310 1251 1258 1271 1376 1214 1221 1251 1207 1258 1242 1176 1393 1295 1334 1308 1306 1409 1280 1294 1258 1243 1321 1246 1406 1261 1365 1286 1258 1224 1233 1265 1224 1353 1302 1248 1253 1359 1195 1209 1158 1240 1297 1391 1436 1273 1307 1336 1323 1366 1246 1262 1263 1285 1451 1344 1309 1358 1245 1390 1432 1352 1288 1470 1267 1281 1282 1243 1247 1341 1311 1337 1294 1439 1338 1375 1231 1308 1295 1301 1424 1371 1329 1265 1319 1263 1353 1291 1287 1234 1462 1258 1389 1282 1297 1485 1237 1324 1248 1413 1323 1382 1316 1265 1322 1276 1385 1308 1502 1415 1204 1377 1399 1240 1431 1383 1441 1326 1445 1362 1384 1329 1428 1387 1509 1389 1526 1592 1325 1304 1318 1456 1357 1434 1489 1530 1367 1398 1264 1363 1456 1446 1334 1423 1484 1335 1446 1418 1484 1315 1343 1318 1547 1495 1312 1441 1560 1434 1281 1418 1455 1371 1411 1452 1412 1495 1554 1351 1305 1467 1483 1401 1398 1424 1517 1352 1392 1355 1328 1430 1436 1373 1449 1382 1373 1536 1471 1413 1406 1553 1499 1421 1490 1515 1469 1554 1487 1516 1546 1393 1455 1425 1441 1381 1506 1573 1516 1497 1397 1477 1446 1575 1399 1526 1509 1566 1544 1464 1321 1511 1549 1518 1394 1558 1510 1497 1564 1582 1578 1445 1512 1605 1589 1554 1476 1537 1558 1581 1460 1432 1512 1532 1656 1499 1411 1477 1595 1488 1616 1665 1522 1512 1595 1643 1505 1620 1689 1630 1515 1479 1678 1647 1469 1708 1548 1623 1583 1488 1608 1579 1612 1633 1669 1497 1637 1509 1557 1455 1633 1655 1623 1634 1677 1692 1559 1626 1570 1664 1469 1689 1540 1760 1601 1576 1706 1658 1572 1597 1564 1617 1568 1650 1662 1559 1643 1662 1667 1777 1694 1623 1576 1720 1602 1568 1704 1712 1537 1592 1620 1670 1618 1668 1583 1625 1644 1698 1555 1733 1646 1750 1663 1661 1718 1574 1776 1490 1672 1698 1633 1723 1694 1714 1747 1785 1746 1702 1718 1720 1654 1774 1605 1566 1731 1615 1813 1640 1758 1797 1858 1581 1704 1686 1642 1791 1707 1765 1702 1768 1823 1818 1743 1789 1812 1745 1776 1798 1802 1782 1746 1757</counts>
			</dataPoints>
		</scan>
	</xrdMeasurement>
</xrdMeasurements>