File: Data Files/Full/MSS p (6-129, 4w)_01_07.xrdml
<?xml version="1.0"?>
<xrdMeasurements xmlns="http://www.xrdml.com/XRDMeasurement/2.2" xmlns:xsi="http://www.w3.org/2001/XMLSchema-instance" xsi:schemaLocation="http://www.xrdml.com/XRDMeasurement/2.2 http://www.xrdml.com/XRDMeasurement/2.2/XRDMeasurement.xsd" status="Completed" recordIdentifier="{6EEA8E4E-14C8-4C12-A92C-C16197829D8E}">
	<comment>
		<entry/>
	</comment>
	<sample type="To be analyzed">
		<id>p</id>
		<name></name>
		<preparedBy></preparedBy>
	</sample>
	<xrdMeasurement measurementType="Scan" status="Completed" sampleMode="Reflection">
		<usedWavelength intended="K-Alpha 1">
			<kAlpha1 unit="Angstrom">1.5405980</kAlpha1>
			<kAlpha2 unit="Angstrom">1.5444260</kAlpha2>
			<kBeta unit="Angstrom">1.3922500</kBeta>
			<ratioKAlpha2KAlpha1>0.5000</ratioKAlpha2KAlpha1>
		</usedWavelength>
		<incidentBeamPath>
			<radius unit="mm">145.00</radius>
			<xRayTube id="1010048" name="Empyrean Cu LFF HR (9430 033 7310x) DK437964">
				<tension unit="kV">40.0</tension>
				<current unit="mA">15.0</current>
				<anodeMaterial>Cu</anodeMaterial>
				<focus type="Line">
					<length unit="mm">12.0</length>
					<width unit="mm">0.4</width>
					<takeOffAngle unit="deg">6.0</takeOffAngle>
				</focus>
			</xRayTube>
			<filter id="20010004" name="Beta-filter Nickel">
				<material>Ni</material>
				<thickness unit="mm">0.020</thickness>
			</filter>
			<sollerSlit id="21010002" name="Soller slits 0.04 rad.">
				<opening unit="rad">0.0400</opening>
			</sollerSlit>
			<mask id="22031000" name="Fixed mask 13 mm">
				<width unit="mm">9.00</width>
			</mask>
			<divergenceSlit id="22120003" name="Divergence slit 1/4°" xsi:type="fixedDivergenceSlitType">
				<distanceToSample unit="mm">50.00</distanceToSample>
				<height unit="mm">0.38</height>
			</divergenceSlit>
		</incidentBeamPath>
		<diffractedBeamPath>
			<radius unit="mm">145.00</radius>
			<parallelPlateCollimator id="25020001" name="Parallel plate collimator 0.28°">
				<opening unit="deg">0.28</opening>
			</parallelPlateCollimator>
			<detector id="7010020" name="PIXcel3D-Medipix3 1x1 detector" xsi:type="areaDetectorType">
				<phd unit="keV">
					<lowerLevel>4.0</lowerLevel>
					<upperLevel>11.3</upperLevel>
				</phd>
				<mode>Receiving slit</mode>
				<activeChannelsEquatorial>255</activeChannelsEquatorial>
				<activeChannelsAxial>255</activeChannelsAxial>
				<pitchEquatorial unit="mm">0.05500</pitchEquatorial>
				<pitchAxial unit="mm">0.05500</pitchAxial>
				<readOutPeriod unit="seconds">0.050</readOutPeriod>
			</detector>
		</diffractedBeamPath>
		<scan appendNumber="0" mode="Continuous" scanAxis="2Theta" status="Completed">
			<header>
				<startTimeStamp>2025-07-10T11:46:32-08:00</startTimeStamp>
				<endTimeStamp>2025-07-11T11:41:37-08:00</endTimeStamp>
				<author>
					<name>Instrument</name>
				</author>
				<source>
					<applicationSoftware version="1.6 (94)">PANalytical Aeris Instrument Suite</applicationSoftware>
					<instrumentControlSoftware version="3.0.0 20211014">AERIS</instrumentControlSoftware>
					<instrumentID>2855484</instrumentID>
				</source>
			</header>
			<dataPoints>
				<positions axis="2Theta" unit="deg">
					<startPosition>6.005</startPosition>
					<endPosition>128.995</endPosition>
				</positions>
				<positions axis="Omega" unit="deg">
					<commonPosition>4.000</commonPosition>
				</positions>
				<commonCountingTime unit="seconds">6.160</commonCountingTime>
				<counts 4548 4547 4467 4326 4354 4470 4430 4363 4456 4399 4291 4310 4396 4336 4354 4307 4314 4213 4407 4197 4537 4226 4260 4312 4319 4253 4344 4284 4200 4432 4312 4271 4359 4182 4207 4193 4232 4226 4279 4354 4260 4293 4304 4288 4393 4279 4237 4300 4212 4160 4326 4130 4216 4223 4103 4266 4263 4233 4304 4247 4298 4250 4276 4270 4368 4274 4241 4212 4184 4239 4294 4319 4247 4179 4309 4199 4296 4249 4205 4288 4229 4258 4173 4303 4162 4040 4283 4020 4136 4175 4094 4137 4114 4169 4102 4210 4108 4003 4088 4111 4075 4109 4067 4114 4181 4105 4183 4051 3949 3952 4147 3895 4066 4024 3962 4031 3822 4012 4066 3993 3942 4004 3888 3995 3951 3945 3914 3934 3892 4019 3873 3940 3840 3833 4003 3910 3767 3865 3810 3945 3778 3878 3772 3823 3878 3855 3954 3919 3899 3764 3793 3696 3855 3775 3812 3671 3804 3717 3744 3818 3719 3737 3699 3756 3804 3752 3751 3630 3708 3650 3672 3673 3567 3648 3667 3641 3493 3655 3592 3770 3584 3619 3584 3669 3656 3569 3571 3636 3679 3535 3549 3658 3520 3605 3653 3556 3499 3511 3484 3496 3473 3528 3575 3482 3404 3459 3424 3456 3424 3516 3302 3442 3438 3441 3535 3448 3567 3455 3420 3476 3531 3488 3484 3422 3413 3317 3394 3415 3310 3462 3343 3414 3259 3442 3387 3309 3241 3210 3383 3407 3355 3429 3339 3373 3287 3337 3269 3254 3219 3300 3308 3392 3221 3354 3202 3375 3251 3137 3070 3218 3294 3272 3237 3282 3134 3248 3107 3274 3291 3260 3153 3325 3219 3262 3184 3325 3158 3211 3259 3231 3344 3224 3097 3120 3082 3311 3163 3115 3176 3168 3302 3279 3243 3280 3175 3120 3263 3187 3182 3346 3120 3245 3235 3190 3258 3063 3144 3264 3093 3219 3173 3164 3237 3177 3272 3246 3238 3179 3089 3245 3165 3230 3165 3339 3256 3182 3139 3238 3166 3227 3256 3137 3225 3180 3150 3214 3138 3189 3205 3216 3210 3225 3242 3187 3294 3300 3245 3261 3273 3364 3354 3299 3275 3272 3202 3247 3310 3293 3294 3329 3272 3324 3259 3308 3253 3216 3280 3328 3349 3203 3194 3387 3249 3262 3324 3313 3347 3263 3340 3326 3275 3311 3412 3310 3398 3404 3303 3361 3375 3332 3517 3364 3245 3331 3413 3420 3404 3394 3362 3435 3418 3506 3389 3440 3476 3396 3382 3496 3372 3297 3435 3515 3467 3397 3379 3422 3440 3449 3406 3448 3507 3590 3386 3506 3606 3362 3444 3509 3517 3475 3525 3537 3522 3486 3561 3587 3484 3645 3516 3591 3642 3596 3473 3564 3512 3587 3464 3605 3610 3551 3620 3603 3710 3468 3664 3544 3587 3683 3456 3559 3617 3633 3663 3563 3703 3661 3577 3744 3677 3555 3698 3744 3648 3618 3686 3682 3667 3689 3750 3730 3726 3679 3823 3637 3769 3806 3898 3857 3785 3771 3758 3754 3694 3756 3918 3791 3649 3809 3753 3764 3783 3907 3827 3808 3891 3767 3865 3884 3852 3951 3753 3856 3977 3749 3891 3941 3833 3768 3908 3944 3943 3972 3930 3829 3902 3957 3884 4000 3999 3998 3845 3986 3943 4058 3931 3867 4144 4139 3894 4005 3974 3977 4048 4090 4002 4110 4065 4133 4122 4132 4153 4096 4073 4187 4115 4131 4033 4270 3961 4156 4165 4318 4302 4176 4138 4301 4198 4140 4182 4216 4183 4218 4224 4229 4223 4267 4326 4235 4207 4248 4328 4243 4251 4273 4251 4385 4389 4324 4349 4349 4293 4394 4450 4402 4301 4214 4463 4303 4361 4300 4394 4431 4438 4380 4434 4366 4546 4461 4395 4522 4391 4607 4417 4685 4472 4472 4622 4476 4536 4478 4487 4595 4703 4647 4574 4589 4573 4825 4724 4475 4678 4869 4642 4843 4638 4659 4710 4808 4702 4673 4652 4801 4844 4746 4745 4767 4827 4805 4717 4810 4871 4859 4878 4876 5093 4800 4988 4855 4848 4834 4913 5040 5059 5012 5016 4981 4850 4970 5053 4976 4897 5113 5156 5122 5004 5237 5048 5186 5202 4980 5122 5070 5035 5061 5234 5134 5158 5193 5161 5270 5119 5222 5208 5280 5186 5203 5219 5213 5297 5291 5271 5315 5204 5330 5447 5458 5445 5413 5321 5440 5273 5251 5423 5321 5548 5470 5513 5406 5354 5401 5502 5437 5504 5395 5533 5562 5491 5391 5571 5487 5530 5436 5502 5442 5508 5571 5570 5407 5634 5743 5660 5559 5656 5592 5655 5497 5595 5636 5619 5594 5761 5530 5549 5650 5642 5675 5650 5630 5600 5628 5698 5682 5697 5637 5709 5650 5775 5742 5722 5776 5664 5823 5675 5582 5753 5867 5713 5712 5663 5798 5880 5685 5788 5906 5763 5716 5691 5802 5913 5798 5781 5668 5795 5942 5826 5665 5817 5873 5765 5955 5924 5743 5830 5809 5699 5834 5854 5853 5734 5855 5872 5583 5729 5812 5922 5853 5793 5681 5802 5728 5795 5907 5834 5779 5707 5808 5651 5742 5765 5767 5812 5616 5739 5769 5901 5706 5664 5645 5581 5620 5697 5555 5747 5772 5698 5612 5632 5814 5597 5477 5619 5579 5693 5705 5647 5604 5690 5653 5475 5603 5611 5486 5519 5721 5469 5438 5570 5720 5595 5561 5528 5518 5452 5448 5388 5454 5366 5442 5538 5492 5544 5440 5432 5364 5413 5364 5272 5391 5380 5274 5263 5307 5462 5320 5184 5349 5273 5273 5332 5288 5173 5220 5272 5185 5219 5158 5116 5226 5252 5173 5147 5047 5161 5101 5032 5148 5103 4995 5102 4986 4984 5002 4854 5033 4956 5032 4948 4879 5020 4890 4957 4838 4823 4906 4943 4866 4931 4954 4791 4809 4796 4993 4872 4840 4693 4738 4804 4756 4671 4831 4734 4741 4712 4764 4635 4590 4674 4650 4626 4632 4598 4592 4619 4599 4528 4565 4694 4569 4493 4508 4542 4489 4478 4343 4326 4469 4597 4333 4515 4465 4458 4336 4473 4331 4342 4261 4293 4286 4278 4436 4288 4352 4253 4287 4374 4157 4214 4238 4286 4238 4224 4104 4198 4240 4128 4044 4195 4078 4143 4100 4160 4060 4082 4156 4150 4083 4067 4042 4012 3987 4085 4036 3977 3956 4070 4106 3901 3861 3981 4003 4043 3984 3845 3922 3979 3746 3954 3835 3997 3977 3865 3849 3792 3848 3858 3767 3862 3894 3826 3921 3792 3836 3692 3813 3879 3747 3757 3777 3709 3737 3709 3636 3741 3690 3756 3678 3627 3858 3705 3719 3705 3627 3655 3705 3692 3524 3664 3504 3697 3684 3541 3648 3572 3680 3587 3615 3519 3440 3574 3644 3627 3489 3540 3467 3520 3385 3529 3421 3462 3354 3488 3423 3447 3368 3507 3457 3431 3445 3413 3447 3350 3375 3466 3486 3426 3311 3354 3320 3306 3405 3382 3345 3291 3329 3224 3407 3309 3340 3136 3239 3362 3424 3299 3220 3405 3172 3339 3267 3350 3124 3176 3307 3293 3201 3237 3198 3282 3176 3300 3221 3259 3221 2978 3104 3245 3269 3155 3075 3237 3100 3092 3080 3056 3242 3073 3141 3105 3065 3084 3150 3141 3049 3153 2945 3123 3055 3182 3053 3010 3177 3091 3144 2999 2941 2955 3133 3014 3050 2880 2974 3192 2904 3027 3065 3202 3252 3271 3548 3845 3979 4214 4477 4711 5074 5535 5825 6372 6702 7018 7413 7674 7884 7966 7873 8072 7909 7881 7774 7337 6920 6392 6222 5758 5181 5004 4553 4408 4023 3752 3493 3306 3176 2928 3011 2844 2937 2540 2589 2877 2961 2774 2720 2690 2523 2791 2687 2532 2623 2630 2692 2675 2697 2704 2687 2626 2636 2444 2662 2630 2576 2789 2623 2638 2621 2640 2743 2564 2597 2601 2718 2688 2687 2487 2620 2570 2419 2492 2544 2443 2472 2646 2631 2523 2490 2447 2567 2531 2528 2374 2693 2672 2461 2420 2527 2549 2540 2547 2352 2291 2508 2404 2296 2404 2587 2397 2513 2245 2539 2348 2393 2289 2587 2324 2344 2407 2383 2420 2431 2431 2416 2446 2477 2305 2467 2419 2560 2449 2369 2323 2536 2430 2353 2306 2332 2311 2318 2386 2337 2372 2506 2335 2196 2236 2291 2250 2422 2251 2231 2162 2148 2245 2465 2304 2234 2232 2168 2327 2159 2297 2221 2174 2133 2258 2492 2267 2212 2375 2227 2205 2232 2158 2266 2248 2354 2292 2336 2192 2151 2148 2196 2216 2208 2195 2136 2103 2182 2183 2147 2221 2115 2149 2217 2126 2122 2150 2042 2128 2048 2064 2169 2085 2246 2164 2181 2215 2311 2123 2192 2141 2172 2077 2144 2084 2114 2152 2201 2126 2037 2214 2025 2063 2070 2156 2195 2076 2059 2123 2090 2068 2135 2058 2103 2171 2114 2030 2090 2008 2010 2142 2150 2044 2001 2041 2022 2128 2032 2159 2035 2037 1971 2072 2044 1958 1964 2017 2097 2132 2113 2148 2139 2010 2072 1999 2033 2074 1954 2076 1904 2011 2017 2030 2078 1960 2036 1995 1965 1990 1957 1929 2096 1959 2130 2025 2092 1975 1987 2053 2000 1986 1998 1929 1989 1929 1945 1940 2009 2005 2012 1962 1939 1948 1893 1936 2052 1904 1984 1973 1965 1968 1988 1913 1928 1894 1970 2047 1949 1979 1980 2083 1866 1918 1895 1962 2034 1924 1922 1922 1913 1773 1922 1846 1910 1925 1889 1935 1846 1918 1947 1853 1879 1899 1938 1922 1922 1912 1885 1945 1821 1845 1885 1836 1859 1978 1905 1826 1925 1896 2011 1866 1846 1944 1879 1912 1926 1865 1901 1970 1849 1887 1880 1901 1927 1899 1936 1891 1935 1940 1897 1871 1893 1827 1900 1873 1829 1858 1852 1901 1821 1875 1830 1910 1916 1867 1853 1870 1915 1863 1861 1860 1945 1941 1896 1952 1841 1830 1874 1880 1835 1942 1885 1954 1895 1883 1937 1890 1956 1933 1948 1991 1898 1985 1924 1973 1962 1941 1973 1928 1934 1964 2069 2140 2341 2595 3207 3492 3887 4331 4827 5669 6469 7241 8461 9656 10808 12015 13061 13964 15008 15165 15835 16313 16410 16298 16785 15772 15139 14146 13031 11868 10462 9379 8355 7636 6676 5589 4802 4042 3410 2893 2188 2158 2162 2021 2060 1955 2025 2131 1997 2002 1867 2124 1973 1920 1954 2011 1970 1922 2007 1878 1865 1814 1902 1835 1898 1808 1771 1880 1805 1820 1801 1792 1798 1795 1835 1710 1780 1846 1781 1809 1822 1915 1821 1829 1739 1823 1819 1741 1766 1844 1823 1740 1788 1836 1793 1770 1743 1782 1768 1772 1722 1765 1778 1848 1758 1792 1772 1779 1721 1795 1746 1688 1801 1733 1782 1738 1802 1755 1750 1785 1805 1825 1787 1723 1753 1701 1803 1711 1752 1691 1769 1748 1745 1774 1708 1792 1754 1776 1733 1776 1856 1842 1715 1789 1756 1760 1713 1757 1778 1769 1746 1778 1760 1741 1674 1713 1725 1786 1829 1694 1677 1708 1815 1743 1771 1709 1751 1692 1710 1666 1717 1641 1706 1703 1754 1668 1738 1664 1649 1698 1650 1692 1712 1673 1772 1744 1727 1715 1713 1814 1681 1773 1689 1706 1760 1722 1669 1726 1678 1773 1680 1746 1706 1723 1744 1681 1702 1685 1668 1626 1756 1765 1651 1785 1675 1731 1747 1613 1706 1689 1638 1708 1699 1701 1705 1679 1721 1673 1690 1728 1632 1679 1685 1604 1641 1670 1682 1657 1684 1639 1651 1640 1748 1619 1677 1649 1747 1705 1709 1667 1663 1732 1630 1680 1665 1717 1708 1682 1691 1680 1610 1718 1701 1725 1697 1709 1614 1753 1582 1679 1664 1644 1654 1705 1662 1718 1720 1677 1705 1689 1784 1722 1640 1739 1662 1725 1758 1624 1658 1731 1738 1679 1691 1658 1679 1650 1645 1627 1664 1689 1695 1624 1742 1786 1611 1680 1707 1734 1570 1635 1688 1687 1633 1659 1717 1691 1784 1688 1673 1728 1639 1628 1706 1663 1702 1733 1673 1580 1658 1668 1679 1686 1632 1708 1651 1629 1689 1712 1630 1725 1689 1667 1715 1693 1602 1731 1663 1707 1700 1703 1693 1737 1693 1703 1664 1645 1763 1655 1673 1725 1656 1739 1811 1763 1761 1694 1726 1648 1760 1771 1915 2005 2147 2375 2616 2966 3250 3484 3982 4279 4767 5141 5714 6143 6670 6795 6911 7251 7200 7647 7550 7423 7530 7200 6742 6418 5956 5438 5028 4633 4314 3753 3418 3019 2712 2338 2137 1874 1862 1815 1710 1716 1670 1756 1707 1656 1738 1672 1694 1762 1688 1724 1704 1715 1681 1643 1803 1645 1740 1804 1711 1744 1624 1712 1651 1667 1572 1660 1710 1732 1638 1663 1694 1680 1678 1635 1766 1677 1715 1595 1587 1672 1684 1671 1675 1618 1652 1684 1637 1597 1597 1673 1593 1661 1663 1654 1622 1695 1672 1635 1604 1604 1655 1659 1592 1646 1610 1591 1652 1632 1660 1617 1686 1720 1547 1600 1768 1602 1649 1654 1706 1660 1684 1713 1644 1712 1681 1696 1678 1562 1628 1674 1624 1623 1562 1662 1635 1662 1608 1709 1686 1619 1653 1659 1615 1601 1590 1597 1602 1645 1703 1714 1618 1643 1678 1627 1628 1660 1656 1549 1644 1650 1634 1636 1723 1670 1678 1707 1817 1714 1764 1671 1722 1831 1695 1711 1813 1783 1844 1752 1825 1802 1834 1791 1862 1733 1809 1889 1789 1688 1720 1668 1812 1627 1670 1682 1730 1686 1647 1591 1641 1585 1654 1635 1623 1633 1622 1641 1629 1726 1653 1539 1608 1595 1728 1564 1596 1625 1726 1667 1683 1699 1616 1623 1614 1666 1679 1666 1612 1589 1668 1655 1644 1663 1694 1617 1600 1657 1616 1637 1654 1646 1676 1647 1626 1642 1681 1654 1658 1661 1655 1597 1598 1709 1630 1708 1624 1660 1667 1585 1667 1665 1674 1697 1641 1611 1658 1675 1658 1630 1680 1660 1625 1639 1690 1676 1631 1708 1558 1702 1699 1651 1638 1685 1679 1735 1679 1752 1643 1634 1714 1704 1769 1762 1727 1685 1633 1656 1742 1652 1734 1719 1771 1752 1723 1708 1686 1678 1718 1777 1627 1643 1743 1635 1741 1683 1760 1794 1774 1773 1720 1716 1795 1702 1743 1769 1823 1730 1735 1809 1746 1801 1872 1816 1795 1698 1820 1826 1800 1762 1778 1856 1770 1806 1789 1725 1852 1905 1800 1769 1791 1824 1763 1833 1831 1892 1753 1905 1825 1857 1811 1980 1942 1988 1856 1974 1894 1846 1801 1924 1955 1928 1909 2019 1950 1944 1982 1978 1890 1961 1993 1970 1953 1894 2008 2019 1971 1996 2128 1961 2061 2028 2005 2090 2090 2139 2115 2125 2178 2061 2117 2302 2132 2144 2377 2144 2344 2223 2286 2203 2241 2210 2293 2236 2229 2338 2432 2279 2157 2469 2349 2425 2449 2395 2560 2569 2561 2577 2553 2481 2688 2555 2700 2925 2880 2662 2892 2953 2871 2956 2889 2916 3083 2926 2957 3082 3120 3178 3265 3217 3305 3233 3347 3422 3298 3477 3407 3389 3570 3504 3546 3522 3725 3519 3739 3730 3760 3736 3905 3768 3917 4025 4018 4075 4076 4044 4112 4245 4192 4276 4233 4352 4303 4454 4432 4560 4549 4713 4687 4479 4678 4738 4679 4632 4695 4752 4802 4951 4758 4757 4890 4901 4789 4906 4680 4816 4755 4758 4707 4675 4735 4551 4614 4539 4633 4528 4488 4439 4390 4368 4303 4204 4264 4083 4090 4097 3977 3984 4022 4083 4020 3902 4004 3970 3845 3910 4036 4025 3899 4077 3959 4013 3861 3805 3731 3700 3482 3590 3457 3472 3361 3187 3098 3267 3181 3017 2993 3160 2987 3067 3114 3152 3346 3343 3310 3398 3448 3417 3560 3544 3625 3748 3682 3738 3832 4052 4632 5548 6860 8546 10902 13318 16486 20178 24160 28650 33885 39205 44348 49769 53624 58679 62037 64485 66475 67430 67364 66463 64436 61477 57289 52598 47350 42294 36069 30852 26001 21253 17886 13921 11322 8630 6587 4845 3914 3204 2849 2617 2454 2354 2358 2301 2366 2139 2067 1995 2004 2039 1942 1983 1932 1810 1875 1888 1809 1797 1714 1819 1731 1777 1723 1702 1618 1758 1732 1666 1630 1587 1677 1677 1568 1618 1765 1645 1641 1604 1602 1608 1611 1641 1623 1560 1623 1635 1625 1613 1588 1576 1657 1617 1628 1565 1557 1559 1585 1566 1586 1577 1581 1587 1546 1535 1548 1553 1514 1542 1522 1532 1551 1531 1592 1485 1575 1528 1549 1479 1453 1502 1464 1430 1508 1487 1474 1506 1427 1544 1477 1479 1561 1584 1458 1463 1516 1489 1502 1452 1532 1555 1431 1438 1505 1552 1407 1498 1500 1416 1497 1544 1464 1379 1504 1440 1508 1450 1445 1428 1465 1504 1467 1463 1542 1478 1507 1385 1459 1442 1455 1425 1449 1461 1451 1423 1531 1399 1430 1521 1443 1474 1445 1439 1433 1485 1486 1437 1437 1420 1380 1430 1478 1451 1351 1462 1424 1409 1419 1429 1428 1363 1420 1382 1445 1357 1399 1395 1443 1409 1392 1405 1407 1385 1419 1396 1305 1395 1347 1432 1362 1426 1369 1292 1374 1375 1407 1418 1387 1448 1444 1352 1423 1393 1397 1436 1417 1438 1382 1376 1383 1481 1438 1432 1421 1407 1421 1404 1457 1418 1442 1357 1314 1389 1377 1328 1366 1385 1369 1389 1368 1378 1394 1365 1370 1431 1380 1384 1395 1327 1337 1396 1356 1412 1366 1351 1403 1395 1354 1440 1371 1372 1386 1445 1353 1404 1269 1327 1329 1384 1349 1412 1378 1286 1338 1435 1403 1394 1436 1347 1390 1388 1320 1351 1356 1366 1353 1291 1367 1347 1310 1363 1302 1316 1348 1362 1343 1387 1378 1318 1370 1403 1338 1360 1336 1277 1377 1309 1339 1378 1309 1334 1324 1319 1342 1339 1315 1348 1248 1355 1339 1359 1405 1325 1383 1384 1348 1273 1380 1345 1460 1402 1381 1393 1363 1387 1377 1297 1369 1357 1357 1431 1326 1333 1406 1322 1376 1308 1295 1309 1369 1346 1381 1263 1321 1307 1380 1403 1289 1298 1306 1326 1352 1305 1339 1341 1322 1414 1289 1285 1227 1355 1334 1393 1273 1335 1323 1324 1304 1309 1284 1311 1346 1365 1317 1291 1292 1308 1303 1337 1304 1330 1303 1313 1346 1311 1325 1320 1255 1258 1300 1290 1260 1288 1325 1279 1319 1293 1334 1313 1224 1356 1309 1347 1283 1333 1317 1340 1289 1321 1290 1329 1363 1343 1364 1284 1315 1259 1287 1248 1228 1291 1339 1278 1288 1283 1276 1277 1275 1281 1267 1309 1325 1308 1304 1321 1358 1265 1291 1332 1271 1318 1282 1282 1260 1317 1324 1295 1267 1300 1320 1299 1287 1277 1209 1312 1316 1290 1286 1254 1283 1297 1346 1278 1221 1265 1300 1265 1283 1290 1251 1366 1244 1353 1286 1278 1227 1330 1306 1323 1316 1288 1306 1371 1259 1211 1300 1236 1344 1247 1276 1294 1301 1257 1219 1287 1304 1288 1300 1274 1306 1253 1289 1281 1267 1234 1254 1307 1278 1237 1308 1315 1329 1283 1211 1226 1254 1341 1330 1252 1260 1224 1310 1213 1244 1204 1219 1273 1252 1222 1298 1271 1301 1290 1327 1271 1301 1270 1268 1335 1295 1321 1314 1210 1227 1282 1326 1270 1271 1263 1241 1243 1276 1295 1301 1267 1337 1270 1319 1302 1278 1305 1235 1282 1281 1230 1284 1301 1364 1327 1378 1400 1550 1588 1620 1657 1757 1806 2204 2215 2530 2938 3111 3232 3427 3566 3621 3695 3720 3751 3727 3622 3483 3299 3159 2866 2598 2115 2144 1880 1836 1746 1645 1531 1420 1439 1319 1305 1255 1281 1297 1308 1282 1255 1258 1310 1238 1207 1281 1280 1293 1257 1287 1222 1160 1244 1288 1234 1201 1225 1236 1255 1203 1256 1165 1224 1189 1232 1186 1187 1269 1248 1274 1189 1258 1172 1219 1174 1234 1183 1180 1224 1175 1244 1201 1306 1238 1230 1189 1180 1202 1227 1192 1211 1221 1184 1232 1232 1255 1239 1180 1214 1182 1200 1191 1285 1232 1267 1214 1209 1236 1213 1261 1201 1236 1211 1239 1209 1177 1284 1203 1298 1220 1263 1225 1180 1262 1173 1216 1181 1216 1276 1199 1191 1322 1251 1180 1217 1153 1215 1267 1207 1294 1197 1229 1161 1272 1201 1261 1172 1199 1225 1248 1225 1234 1215 1298 1252 1283 1295 1323 1300 1330 1345 1388 1336 1379 1424 1381 1401 1408 1377 1326 1380 1337 1326 1248 1271 1300 1323 1210 1263 1205 1209 1305 1215 1224 1267 1217 1231 1243 1217 1206 1229 1226 1205 1222 1195 1218 1208 1240 1163 1226 1173 1116 1169 1287 1242 1152 1248 1111 1249 1219 1231 1181 1230 1237 1228 1211 1250 1157 1251 1246 1165 1136 1231 1189 1166 1230 1251 1224 1271 1278 1220 1203 1195 1300 1245 1259 1172 1172 1196 1241 1219 1196 1262 1203 1209 1206 1267 1169 1220 1191 1190 1207 1242 1180 1222 1181 1179 1206 1301 1247 1217 1170 1234 1240 1248 1230 1221 1287 1173 1232 1242 1151 1223 1225 1254 1198 1157 1205 1165 1169 1196 1159 1221 1217 1218 1276 1259 1217 1273 1164 1260 1166 1154 1231 1165 1182 1173 1277 1260 1167 1242 1275 1272 1231 1223 1186 1199 1249 1211 1214 1196 1224 1297 1219 1271 1236 1215 1240 1207 1223 1234 1277 1256 1222 1212 1232 1220 1240 1237 1194 1219 1243 1221 1314 1230 1192 1228 1267 1193 1158 1273 1202 1239 1329 1251 1250 1254 1258 1198 1235 1229 1226 1251 1194 1248 1211 1292 1260 1231 1266 1249 1229 1278 1300 1194 1334 1218 1298 1202 1246 1248 1200 1279 1354 1192 1245 1251 1253 1289 1298 1180 1304 1287 1297 1324 1353 1234 1338 1304 1391 1385 1369 1440 1441 1440 1463 1441 1463 1533 1525 1633 1606 1697 1729 1776 1939 2025 2115 2411 2577 2819 3082 3367 3561 3830 3989 3819 4050 4047 4206 4173 4134 4077 3830 3651 3584 3345 3144 2467 2259 2196 1820 1870 1705 1577 1505 1491 1372 1385 1302 1347 1271 1248 1286 1272 1254 1279 1290 1230 1335 1246 1299 1291 1310 1326 1269 1323 1304 1256 1272 1300 1310 1275 1271 1247 1290 1294 1160 1322 1299 1318 1340 1316 1235 1329 1268 1280 1309 1292 1307 1272 1255 1291 1251 1208 1295 1237 1340 1346 1261 1270 1332 1385 1277 1247 1309 1320 1297 1289 1316 1309 1278 1332 1282 1318 1295 1304 1281 1261 1277 1285 1267 1340 1294 1289 1243 1350 1277 1287 1251 1283 1373 1316 1283 1344 1285 1222 1315 1301 1260 1290 1289 1330 1321 1335 1377 1302 1321 1446 1373 1354 1234 1320 1279 1382 1369 1290 1306 1385 1357 1282 1355 1236 1236 1302 1375 1312 1350 1338 1387 1335 1297 1471 1354 1420 1310 1378 1362 1361 1321 1407 1424 1398 1379 1359 1349 1388 1447 1408 1426 1384 1435 1446 1332 1339 1426 1381 1391 1404 1376 1406 1461 1358 1383 1378 1394 1470 1410 1433 1419 1424 1454 1402 1425 1438 1485 1502 1435 1408 1454 1508 1374 1487 1477 1444 1466 1454 1395 1426 1431 1481 1487 1476 1544 1544 1460 1504 1522 1479 1494 1438 1527 1569 1568 1550 1558 1458 1554 1509 1505 1431 1548 1495 1497 1469 1497 1525 1464 1558 1572 1499 1531 1533 1553 1573 1562 1595 1578 1456 1554 1540 1573 1572 1552 1564 1567 1509 1571 1544 1530 1561 1572 1582 1500 1566 1598 1584 1560 1577 1601 1552 1591 1608 1629 1592 1573 1604 1532 1542 1626 1561 1643 1573 1654 1693 1646 1734 1701 1678 1789 1835 1809 1885 1810 1957 1890 1934 1993 1909 1962 2107 1876 1943 1973 1920 1762 1852 1768 1753 1773 1734 1639 1744 1544 1648 1544 1722 1573 1552 1571 1685 1656 1638 1583 1641 1649 1648 1574 1679 1633 1608 1660 1544 1500 1664 1642 1541 1646 1629 1642 1618 1627 1513 1592 1596 1623 1640 1668 1645 1659 1591 1663 1581 1669 1648 1664 1582 1546 1546 1606 1514 1573 1622 1628 1609 1572 1638 1611 1629 1556 1618 1589 1573 1605 1612 1541 1600 1547 1619 1584 1619 1640 1548 1618 1599 1552 1500 1622 1579 1646 1538 1533 1605 1543 1677 1522 1612 1575 1632 1622 1544 1624 1617 1608 1553 1596 1608 1590 1555 1473 1541 1573 1561 1501 1535 1482 1544 1520 1567 1557 1614 1568 1516 1574 1647 1569 1495 1539 1590 1556 1539 1477 1533 1558 1498 1609 1557 1565 1506 1503 1546 1543 1569 1624 1554 1554 1501 1508 1561 1521 1607 1561 1557 1521 1607 1582 1502 1556 1486 1504 1510 1527 1556 1529 1546 1543 1499 1515 1566 1526 1439 1502 1474 1510 1424 1448 1465 1584 1493 1512 1464 1505 1477 1501 1484 1532 1582 1486 1512 1538 1456 1419 1570 1523 1513 1478 1450 1530 1562 1570 1545 1561 1546 1652 1677 1644 1736 1712 1750 1786 1775 1888 1827 1808 1927 1903 1820 1761 1735 1810 1778 1705 1673 1695 1583 1531 1510 1494 1526 1491 1460 1508 1458 1463 1351 1428 1426 1419 1434 1404 1415 1424 1429 1407 1351 1327 1389 1419 1403 1443 1405 1388 1340 1358 1333 1350 1263 1375 1364 1352 1367 1330 1369 1417 1397 1392 1400 1346 1467 1342 1303 1365 1284 1367 1350 1323 1307 1337 1379 1350 1360 1372 1278 1364 1314 1277 1357 1320 1281 1342 1317 1292 1340 1324 1314 1372 1256 1351 1248 1274 1253 1359 1306 1327 1259 1318 1342 1321 1296 1338 1251 1342 1273 1301 1253 1283 1323 1283 1305 1295 1298 1299 1280 1258 1307 1311 1285 1333 1273 1269 1298 1282 1234 1279 1311 1329 1225 1215 1238 1261 1271 1265 1240 1220 1255 1226 1172 1262 1226 1259 1283 1236 1232 1321 1308 1223 1255 1281 1208 1212 1206 1180 1145 1209 1168 1223 1270 1250 1166 1235 1207 1208 1178 1258 1227 1261 1265 1261 1281 1210 1287 1257 1278 1153 1237 1259 1287 1190 1214 1227 1265 1156 1267 1209 1203 1219 1191 1175 1160 1181 1146 1176 1211 1186 1189 1152 1137 1135 1181 1203 1200 1194 1150 1145 1144 1200 1172 1219 1217 1123 1120 1224 1145 1095 1184 1140 1201 1209 1128 1134 1098 1131 1175 1140 1104 1138 1078 1126 1115 1165 1181 1139 1107 1117 1177 1123 1144 1110 1108 1140 1047 1157 1089 1138 1154 1115 1113 1123 1177 1103 1175 1141 1137 1146 1051 1122 1157 1143 1132 1114 1080 1094 1132 1080 1152 1112 1106 1106 1139 1107 1070 1108 1080 1104 1080 1096 1111 1081 1155 1054 1106 1078 1114 1050 1136 1118 1092 1042 1088 1054 1013 1077 1108 1107 1147 1111 1172 1083 1097 1108 1203 1086 1173 1092 1094 1056 1173 1072 1075 1091 1130 1034 1113 1109 1104 1144 1066 1053 1049 1054 1036 1078 1157 1100 1033 1060 1025 1142 1068 1027 1021 1055 1024 1097 994 980 1109 993 974 1025 968 1039 1076 1003 1093 1106 1023 1010 1033 1005 988 1050 1006 1031 975 1057 1035 1036 1039 1044 976 1037 1063 1071 996 1119 986 1026 1045 1065 1001 1014 986 961 1056 1010 1042 1020 1027 1022 1027 1002 1033 1035 980 928 1036 984 1050 1032 1015 993 1011 1095 989 1009 991 1070 1046 976 1030 959 974 981 1055 954 1000 998 1033 1012 1099 1043 953 1001 990 1073 969 1066 915 1011 984 990 1001 1001 1029 976 1006 992 1029 1008 986 961 987 926 1017 996 1024 964 1030 1025 1084 961 1050 993 1003 1045 965 947 945 986 1002 964 947 969 952 1008 916 1009 996 979 974 984 1048 978 990 990 959 1049 980 1033 1012 982 960 985 990 950 998 1018 998 992 977 1045 1043 1024 991 1033 1029 1017 1136 1141 1151 1188 1233 1217 1260 1373 1358 1443 1398 1477 1464 1434 1505 1414 1428 1437 1294 1371 1330 1245 1219 1182 1187 1121 1058 1060 1050 1043 1002 1002 979 1041 1011 989 995 969 936 942 992 1005 983 971 954 966 993 987 923 982 986 1033 1037 1007 945 986 980 955 974 996 970 1004 1038 1000 999 1014 930 993 966 993 934 972 924 976 940 994 1034 957 994 943 992 930 941 1034 997 966 962 986 989 1001 977 962 997 916 921 965 987 964 962 884 1055 1019 964 1037 990 920 947 938 925 943 1004 953 894 996 941 972 984 994 960 930 989 997 979 983 998 978 1005 923 982 990 1001 973 965 948 1011 1044 1036 1064 1060 1097 1060 1095 1118 1190 1290 1299 1238 1288 1303 1452 1463 1495 1468 1410 1515 1503 1477 1353 1349 1344 1356 1322 1239 1179 1155 1122 1110 994 978 1033 994 991 952 1002 960 984 945 924 961 968 1023 979 964 941 984 978 916 950 982 982 959 963 1014 917 957 988 884 936 933 979 929 982 933 967 949 965 961 1009 1005 912 947 965 889 985 1001 938 958 939 956 972 967 1009 1053 984 947 907 962 968 937 900 973 961 941 1002 968 966 933 928 1004 953 968 991 991 988 997 1010 1003 1004 984 1057 1074 1063 1040 1108 1125 1122 1039 1096 1026 1080 1040 1058 1002 1057 979 1024 1007 1041 1030 954 1025 936 1006 986 941 919 961 966 975 1017 954 986 930 967 970 927 994 941 966 935 967 935 943 945 911 892 964 955 943 925 965 979 979 970 1011 928 968 985 987 978 1011 944 994 1002 941 912 930 938 1009 934 911 1014 946 957 960 976 962 913 1031 945 959 964 1010 942 935 950 948 941 969 923 991 961 987 971 997 949 969 975 1016 968 935 961 984 924 978 971 920 934 940 927 999 947 955 919 938 959 959 944 950 942 1014 981 963 998 985 986 966 919 962 938 995 973 964 1075 997 944 983 1021 961 1004 947 951 961 983 971 1039 959 992 913 1031 964 973 927 961 934 983 1021 1044 1010 938 902 993 950 979 973 971 1011 995 912 899 958 954 999 956 968 989 932 974 963 989 972 1005 952 987 983 950 970 953 939 988 921 973 956 996 970 957 1000 946 1053 967 964 944 980 1004 1012 1005 979 963 1009 1013 874 1006 929 934 1004 1010 963 882 962 988 1037 962 1024 988 958 915 921 970 1002 994 975 932 1014 1033 997 1009 936 976 985 999 978 1016 988 934 957 908 991 986 1033 964 927 1002 993 945 919 1007 992 1008 950 962 918 1016 998 943 950 962 946 954 945 973 995 951 1027 993 992 965 960 1023 953 957 1015 1042 1014 911 984 939 1036 990 954 942 968 926 959 962 955 948 968 984 978 950 1028 951 955 905 1020 988 984 990 942 909 949 998 977 956 997 1006 964 1036 975 1054 953 979 1001 989 1041 991 968 1000 961 966 1041 968 937 955 995 942 931 956 962 1002 984 890 977 974 999 953 936 949 965 945 1014 999 980 989 998 983 1025 982 940 1005 979 982 1024 1019 980 944 996 981 951 969 955 1005 1033 1009 993 1042 1047 945 948 935 997 943 1008 949 978 1068 982 991 1019 1041 1065 952 1020 1030 931 987 981 1029 982 984 974 985 975 976 1057 1001 911 949 973 993 907 1008 966 1012 1052 1081 1050 1011 971 991 1037 974 1030 1035 1041 1006 1007 995 1030 1014 934 997 1005 1026 979 1014 995 1017 1023 1016 996 1063 1011 949 1002 983 974 991 1010 953 994 1001 1017 923 984 1018 1072 996 973 972 1010 995 1051 1019 992 994 1036 1002 1015 1042 993 1062 1041 1028 1029 991 972 996 1023 1066 1003 1069 1055 1001 971 1072 984 1033 996 1039 1082 997 1026 1048 991 1002 1036 948 1025 1043 1044 1035 1012 1038 1015 1070 948 1031 1014 979 1007 1018 1053 1023 1040 1008 1003 1007 1091 1012 1082 1046 1028 1044 1029 1046 1060 1033 1096 1020 1016 1013 1037 979 1016 1060 1087 985 1049 1040 961 1054 1040 1005 1014 994 1048 1017 1056 1029 1020 1050 1046 1049 1056 1000 1039 1020 1066 1027 1050 991 1026 1056 1084 1034 1002 1056 1053 1009 1021 1081 1008 1072 1004 1014 1025 1060 1057 1050 1028 1040 1019 1019 1063 1080 1071 1089 1045 1058 989 1068 1033 1094 1010 1071 1104 995 1026 1067 1067 1028 1082 1065 1043 1015 1017 1028 1076 1035 1026 1061 1120 1022 1072 1033 1024 1105 1075 1055 1041 1042 1088 1059 998 1136 1084 1051 1055 1071 1102 1094 1005 1074 1094 1050 1098 1019 1064 1065 1089 1076 1038 1122 1063 1104 1085 1020 1073 1088 1099 1031 1136 1025 1091 1086 1018 1048 1119 1051 1069 1118 1143 1006 1059 1117 1162 1167 1063 1064 1149 1142 1170 1129 1108 1118 1108 1111 1176 1165 1138 1143 1228 1117 1189 1132 1207 1149 1273 1369 1502 1646 1846 2114 2513 3022 3490 4013 4533 5003 5480 5942 6496 6850 7169 7536 7481 7795 7700 7373 7251 7070 6522 6241 5709 5263 4749 4009 3565 3106 2746 2204 1930 1663 1490 1394 1277 1240 1249 1142 1176 1203 1133 1128 1076 1060 1192 1135 1154 1069 1149 1042 1133 1118 1115 1099 1116 1125 1073 1112 1095 1148 1165 1158 1135 1146 1153 1107 1223 1079 1131 1120 1118 1061 1166 1083 1152 1103 1141 1139 1135 1076 1091 1093 1099 1060 1144 1064 1155 1105 1052 1138 1106 1114 1080 1058 1144 1021 1052 1149 1171 1095 1116 1150 1021 1065 1065 1155 1112 1112 1099 1186 1154 1101 1161 1087 1072 1038 1126 1080 1093 1117 1078 1046 1102 1109 1143 1111 1110 1154 1089 1153 1125 1147 1164 1105 1127 1135 1112 1079 1067 1130 1128 1134 1078 1128 1160 1138 1175 1109 1087 1131 1133 1140 1156 1152 1142 1068 1122 1089 1129 1208 1144 1101 1200 1097 1134 1098 1135 1087 1097 1204 1151 1124 1061 1115 1101 1077 1086 1059 1158 1113 1126 1164 1145 1122 1038 1149 1138 1179 1210 1092 1111 1162 1124 1113 1095 1169 1148 1041 1061 1138 1099 1098 1133 1168 1158 1115 1148 1148 1060 1176 1146 1172 1136 1127 1085 1084 1135 1156 1094 1150 1043 1120 1217 1191 1094 1125 1135 1213 1042 1150 1113 1159 1125 1172 1128 1160 1161 1159 1124 1209 1135 1181 1188 1157 1124 1146 1177 1103 1130 1151 1157 1144 1204 1154 1161 1190 1147 1141 1098 1178 1131 1160 1160 1172 1162 1180 1067 1214 1122 1167 1153 1133 1143 1137 1170 1152 1181 1205 1231 1193 1134 1240 1164 1144 1160 1169 1087 1154 1137 1194 1100 1188 1086 1135 1174 1149 1143 1227 1198 1137 1171 1139 1193 1133 1228 1218 1201 1190 1223 1140 1181 1196 1165 1210 1092 1180 1088 1237 1168 1137 1165 1166 1246 1138 1159 1187 1123 1161 1137 1147 1213 1248 1196 1168 1143 1170 1201 1179 1232 1179 1176 1217 1182 1189 1206 1202 1142 1172 1213 1164 1185 1238 1175 1131 1183 1159 1249 1247 1212 1161 1232 1162 1172 1159 1142 1244 1221 1208 1222 1209 1186 1166 1174 1212 1202 1190 1214 1217 1215 1189 1184 1180 1224 1192 1181 1232 1234 1254 1221 1172 1253 1254 1182 1249 1196 1203 1218 1249 1282 1247 1237 1239 1212 1239 1230 1181 1218 1232 1221 1271 1249 1207 1277 1219 1218 1223 1193 1208 1247 1329 1233 1291 1283 1228 1288 1233 1180 1260 1288 1275 1228 1284 1269 1271 1203 1203 1211 1173 1197 1275 1280 1264 1229 1254 1242 1257 1227 1227 1274 1220 1253 1227 1201 1278 1219 1238 1250 1271 1311 1235 1271 1306 1225 1200 1255 1205 1278 1239 1269 1239 1248 1208 1267 1190 1318 1256 1311 1252 1292 1317 1277 1348 1286 1223 1289 1236 1326 1239 1320 1247 1289 1283 1321 1327 1271 1303 1275 1325 1261 1255 1273 1341 1321 1303 1333 1349 1326 1264 1305 1304 1294 1340 1311 1289 1221 1349 1280 1213 1198 1246 1345 1271 1255 1259 1312 1416 1293 1256 1367 1292 1386 1346 1291 1338 1291 1246 1267 1278 1335 1264 1283 1358 1302 1338 1329 1303 1294 1314 1377 1307 1294 1333 1280 1340 1322 1324 1376 1308 1344 1375 1318 1342 1309 1300 1284 1348 1369 1389 1328 1323 1334 1350 1313 1354 1405 1314 1366 1355 1329 1360 1320 1361 1385 1383 1403 1342 1388 1420 1477 1376 1433 1402 1499 1390 1370 1474 1437 1382 1461 1444 1416 1338 1414 1378 1399 1378 1364 1358 1379 1367 1347 1358 1384 1366 1329 1341 1412 1433 1274 1335 1424 1339</counts>
			</dataPoints>
		</scan>
	</xrdMeasurement>
</xrdMeasurements>