File: Data Files/Full/MSS p (13-129, 17w)_01.xrdml
<?xml version="1.0"?>
<xrdMeasurements xmlns="http://www.xrdml.com/XRDMeasurement/2.2" xmlns:xsi="http://www.w3.org/2001/XMLSchema-instance" xsi:schemaLocation="http://www.xrdml.com/XRDMeasurement/2.2 http://www.xrdml.com/XRDMeasurement/2.2/XRDMeasurement.xsd" status="Completed" recordIdentifier="{30193BAC-E403-40C9-9B73-D5CB78EAE58C}">
	<comment>
		<entry/>
	</comment>
	<sample type="To be analyzed">
		<id>p</id>
		<name></name>
		<preparedBy></preparedBy>
	</sample>
	<xrdMeasurement measurementType="Scan" status="Completed" sampleMode="Reflection">
		<usedWavelength intended="K-Alpha 1">
			<kAlpha1 unit="Angstrom">1.5405980</kAlpha1>
			<kAlpha2 unit="Angstrom">1.5444260</kAlpha2>
			<kBeta unit="Angstrom">1.3922500</kBeta>
			<ratioKAlpha2KAlpha1>0.5000</ratioKAlpha2KAlpha1>
		</usedWavelength>
		<incidentBeamPath>
			<radius unit="mm">145.00</radius>
			<xRayTube id="1010048" name="Empyrean Cu LFF HR (9430 033 7310x) DK437964">
				<tension unit="kV">40.0</tension>
				<current unit="mA">15.0</current>
				<anodeMaterial>Cu</anodeMaterial>
				<focus type="Line">
					<length unit="mm">12.0</length>
					<width unit="mm">0.4</width>
					<takeOffAngle unit="deg">6.0</takeOffAngle>
				</focus>
			</xRayTube>
			<filter id="20010004" name="Beta-filter Nickel">
				<material>Ni</material>
				<thickness unit="mm">0.020</thickness>
			</filter>
			<sollerSlit id="21010002" name="Soller slits 0.04 rad.">
				<opening unit="rad">0.0400</opening>
			</sollerSlit>
			<mask id="22031000" name="Fixed mask 13 mm">
				<width unit="mm">9.00</width>
			</mask>
			<divergenceSlit id="22120001" name="Divergence slit 1°" xsi:type="fixedDivergenceSlitType">
				<distanceToSample unit="mm">50.00</distanceToSample>
				<height unit="mm">1.52</height>
			</divergenceSlit>
		</incidentBeamPath>
		<diffractedBeamPath>
			<radius unit="mm">145.00</radius>
			<parallelPlateCollimator id="25020001" name="Parallel plate collimator 0.28°">
				<opening unit="deg">0.28</opening>
			</parallelPlateCollimator>
			<detector id="7010020" name="PIXcel3D-Medipix3 1x1 detector" xsi:type="areaDetectorType">
				<phd unit="keV">
					<lowerLevel>4.0</lowerLevel>
					<upperLevel>11.3</upperLevel>
				</phd>
				<mode>Receiving slit</mode>
				<activeChannelsEquatorial>255</activeChannelsEquatorial>
				<activeChannelsAxial>255</activeChannelsAxial>
				<pitchEquatorial unit="mm">0.05500</pitchEquatorial>
				<pitchAxial unit="mm">0.05500</pitchAxial>
				<readOutPeriod unit="seconds">0.050</readOutPeriod>
			</detector>
		</diffractedBeamPath>
		<scan appendNumber="0" mode="Continuous" scanAxis="2Theta" status="Completed">
			<header>
				<startTimeStamp>2025-07-03T14:24:40-08:00</startTimeStamp>
				<endTimeStamp>2025-07-04T03:18:04-08:00</endTimeStamp>
				<author>
					<name>Instrument</name>
				</author>
				<source>
					<applicationSoftware version="1.6 (94)">PANalytical Aeris Instrument Suite</applicationSoftware>
					<instrumentControlSoftware version="3.0.0 20211014">AERIS</instrumentControlSoftware>
					<instrumentID>2855484</instrumentID>
				</source>
			</header>
			<dataPoints>
				<positions axis="2Theta" unit="deg">
					<startPosition>13.005</startPosition>
					<endPosition>128.995</endPosition>
				</positions>
				<positions axis="Omega" unit="deg">
					<commonPosition>17.000</commonPosition>
				</positions>
				<commonCountingTime unit="seconds">3.520</commonCountingTime>
				<counts 2335 2304 2458 2445 2375 2356 2341 2368 2409 2299 2296 2413 2326 2249 2411 2359 2270 2374 2338 2362 2298 2310 2312 2333 2310 2319 2366 2331 2322 2330 2373 2399 2313 2279 2355 2323 2392 2415 2282 2482 2314 2322 2355 2430 2261 2378 2240 2398 2351 2307 2312 2301 2321 2457 2301 2408 2443 2390 2328 2278 2359 2291 2289 2327 2311 2323 2373 2494 2294 2375 2308 2402 2349 2404 2398 2440 2272 2401 2341 2265 2417 2333 2282 2347 2269 2439 2278 2382 2379 2396 2327 2309 2392 2433 2319 2363 2392 2366 2351 2381 2325 2359 2350 2299 2400 2326 2426 2439 2302 2435 2356 2307 2304 2337 2305 2393 2354 2345 2390 2259 2384 2355 2336 2380 2304 2341 2403 2307 2326 2312 2405 2369 2326 2313 2350 2245 2367 2255 2254 2351 2320 2334 2335 2311 2325 2438 2315 2305 2359 2369 2263 2329 2437 2243 2373 2239 2362 2258 2281 2231 2358 2225 2258 2336 2290 2311 2410 2394 2302 2350 2414 2331 2414 2486 2489 2498 2375 2599 2478 2499 2626 2563 2649 2718 2660 2792 2731 2824 2791 2788 2890 2807 2882 2841 2863 3039 2843 2922 2909 2990 3061 3045 3043 3118 3068 3103 3133 3074 3135 3157 3156 3234 3234 3181 3209 3290 3233 3170 3260 3322 3277 3269 3284 3290 3284 3425 3270 3388 3297 3351 3285 3271 3368 3315 3384 3461 3430 3435 3496 3482 3458 3485 3498 3439 3584 3396 3476 3440 3406 3481 3540 3484 3540 3391 3541 3431 3598 3473 3539 3547 3546 3614 3447 3478 3570 3575 3635 3609 3575 3645 3568 3519 3539 3491 3541 3669 3569 3668 3783 3632 3572 3555 3597 3632 3648 3561 3636 3628 3729 3702 3633 3684 3719 3618 3638 3735 3680 3563 3775 3755 3682 3705 3718 3735 3753 3848 3766 3765 3811 3795 3718 3689 3733 3654 3674 3873 3897 3860 3853 3736 3812 3850 3772 3796 3811 3674 3875 3834 3799 3850 3892 3921 3804 3963 3836 3905 3946 4050 3977 3934 3802 3884 3957 3990 3956 3868 3904 3937 3901 3967 4012 3931 3988 4106 4039 3960 4052 4016 3959 3943 4071 4094 4057 4148 4090 4157 4077 4125 4028 4102 4196 4061 4019 4134 4038 4062 4179 4158 4060 4105 4132 4309 4203 4250 4283 4171 4176 4220 4172 4338 4311 4097 4242 4266 4336 4220 4290 4169 4214 4256 4249 4237 4261 4195 4301 4220 4267 4234 4418 4363 4420 4304 4310 4368 4444 4378 4335 4382 4482 4352 4327 4495 4331 4455 4498 4496 4437 4503 4428 4356 4424 4472 4331 4445 4632 4540 4410 4421 4464 4457 4484 4528 4475 4534 4506 4519 4538 4506 4379 4468 4645 4715 4464 4491 4505 4509 4576 4559 4668 4463 4410 4557 4451 4521 4548 4473 4655 4460 4518 4458 4721 4508 4468 4502 4686 4581 4596 4467 4563 4600 4373 4702 4509 4496 4481 4481 4495 4623 4545 4639 4492 4628 4727 4569 4561 4538 4552 4425 4508 4580 4638 4473 4541 4507 4372 4620 4356 4550 4381 4474 4458 4567 4554 4450 4433 4475 4483 4422 4518 4491 4502 4360 4403 4518 4478 4590 4436 4339 4562 4374 4435 4410 4417 4439 4521 4375 4431 4342 4388 4391 4333 4362 4460 4322 4332 4349 4366 4464 4310 4252 4321 4226 4280 4391 4375 4371 4329 4372 4258 4328 4130 4178 4230 4277 4265 4255 4202 4192 4186 4239 4208 4207 4293 4267 4166 4239 4193 4230 4186 4131 4242 4162 4185 4177 4221 4111 4239 4198 4165 4062 4031 4046 4096 4120 4170 4167 4077 4116 4049 4084 4015 3982 4017 3977 4049 4053 4047 4001 4011 4034 3950 4045 4089 4066 4051 3976 4016 3816 3993 3925 3872 3924 3888 3815 3898 3989 3904 3907 3858 4049 3877 3859 4018 3981 3846 3834 3730 3877 4054 3822 3949 3903 3950 3719 3780 3788 3842 3799 3780 3784 3748 3832 3839 3833 3797 3742 3857 3870 3775 3717 3775 3797 3631 3695 3656 3776 3648 3741 3691 3702 3671 3602 3695 3645 3727 3805 3626 3626 3691 3796 3670 3692 3681 3603 3620 3621 3566 3637 3718 3757 3701 3709 3708 3556 3576 3554 3520 3582 3551 3562 3650 3527 3451 3397 3663 3575 3548 3672 3540 3616 3615 3460 3601 3535 3428 3537 3618 3569 3588 3497 3503 3420 3440 3425 3520 3342 3496 3656 3511 3530 3420 3496 3405 3482 3475 3548 3447 3428 3364 3356 3467 3460 3453 3603 3438 3460 3483 3514 3397 3308 3463 3474 3440 3305 3380 3373 3545 3408 3355 3498 3243 3374 3406 3408 3414 3439 3389 3400 3397 3376 3526 3386 3392 3281 3276 3361 3341 3457 3304 3448 3253 3250 3254 3417 3385 3191 3311 3360 3166 3338 3202 3286 3229 3245 3297 3300 3320 3295 3281 3237 3391 3293 3384 3275 3233 3176 3388 3272 3222 3112 3285 3268 3364 3178 3259 3239 3195 3262 3079 3233 3267 3241 3227 3131 3144 3158 3190 3227 3258 3196 3115 3161 3234 3147 3221 3173 3188 3187 3196 3263 3173 3179 3159 3235 3236 3130 3122 3061 3076 3202 3103 3052 3185 3285 3243 3162 3243 3165 3104 3119 3034 3145 3144 3169 3019 3146 3027 3163 3115 3000 3062 3041 3138 3015 3095 3120 3144 3234 3067 3141 3026 3120 3120 3022 3134 3012 3091 3024 3123 2930 2937 3103 3089 3091 3043 3071 3059 3061 3191 3148 3050 3048 3018 3030 3130 3119 3029 3178 3081 3088 2939 3130 3076 3039 3106 3056 3155 3116 3097 3028 2968 2987 3133 3101 3124 3110 3110 3045 3084 3042 2989 3025 3133 2971 3000 2925 3066 3110 3149 3112 3119 3094 3038 3165 3095 3166 3244 3053 3059 3135 3119 3161 3122 3083 3110 3005 3120 3117 3150 3056 3148 3057 3088 3088 3219 3227 3185 3021 3190 3198 3242 3248 3301 3088 3235 3203 3417 3245 3258 3344 3287 3373 3203 3340 3640 4404 4669 4802 4555 4849 5071 5246 5566 5929 6155 7290 8121 8808 9354 9711 10246 10372 10769 10514 10011 10041 10028 10319 10437 10047 10576 10326 10610 10878 11269 11581 12003 12231 12626 13133 13466 13929 14397 15045 15220 15953 16385 16501 16786 16971 17470 18038 17926 18422 18069 18062 18069 17704 17439 16896 16229 15332 14492 14008 13223 12446 11204 10463 9359 8650 7857 6929 6162 5520 4809 4283 3877 3571 3430 3337 3234 3230 3203 3213 3179 3219 3153 3027 3234 3046 3083 3032 3088 3037 3060 3086 3002 2976 3013 3018 3054 2967 2795 2965 2927 2961 2883 2868 2926 2876 2828 2972 2816 2721 2867 2873 2917 2810 2917 2955 2928 2899 2838 2740 2817 2881 2871 2870 2887 2799 2891 2856 2992 2937 2844 2815 2889 2731 2822 2855 2836 2821 2687 2778 2741 2840 2878 2724 2790 2792 2809 2726 2696 2861 2841 2864 2839 2753 2814 2683 2804 2748 2790 2673 2648 2671 2710 2762 2644 2746 2732 2678 2667 2710 2740 2750 2657 2621 2685 2631 2682 2666 2671 2664 2685 2691 2659 2658 2602 2559 2656 2715 2659 2649 2571 2628 2537 2605 2657 2644 2511 2547 2584 2606 2550 2593 2515 2617 2548 2555 2588 2620 2730 2543 2618 2620 2718 2589 2542 2544 2595 2501 2571 2598 2621 2549 2608 2449 2672 2617 2499 2544 2659 2580 2527 2489 2524 2562 2556 2477 2449 2548 2593 2566 2495 2618 2582 2500 2415 2578 2624 2488 2469 2481 2571 2489 2598 2587 2516 2450 2578 2446 2523 2621 2624 2420 2517 2467 2476 2618 2595 2480 2483 2505 2503 2529 2504 2577 2376 2552 2504 2497 2442 2438 2445 2434 2529 2497 2412 2458 2418 2480 2422 2505 2452 2417 2459 2487 2475 2562 2481 2483 2465 2345 2537 2425 2427 2561 2471 2410 2512 2531 2460 2332 2487 2492 2343 2472 2498 2373 2524 2506 2492 2530 2453 2402 2511 2477 2408 2359 2519 2415 2399 2391 2464 2480 2429 2470 2434 2404 2431 2365 2523 2555 2384 2344 2476 2427 2401 2367 2420 2401 2317 2412 2357 2494 2341 2393 2469 2413 2339 2347 2293 2307 2375 2350 2459 2520 2379 2341 2384 2368 2281 2304 2327 2432 2476 2330 2469 2442 2342 2342 2428 2284 2408 2393 2443 2312 2405 2318 2457 2433 2424 2361 2302 2369 2424 2376 2402 2339 2395 2309 2285 2345 2384 2416 2350 2474 2435 2430 2311 2319 2380 2395 2434 2348 2275 2357 2493 2403 2438 2390 2359 2430 2366 2407 2459 2364 2403 2223 2383 2347 2440 2398 2277 2270 2293 2356 2287 2263 2340 2323 2380 2421 2273 2352 2375 2353 2375 2355 2370 2369 2289 2408 2327 2300 2296 2346 2293 2368 2351 2421 2392 2398 2292 2406 2437 2301 2454 2269 2508 2381 2443 2337 2393 2258 2333 2243 2229 2431 2394 2315 2341 2235 2264 2391 2410 2341 2291 2326 2299 2333 2306 2377 2296 2288 2306 2333 2358 2341 2309 2354 2390 2353 2256 2347 2347 2291 2339 2354 2376 2391 2255 2326 2362 2356 2332 2327 2285 2351 2227 2408 2337 2273 2226 2363 2368 2333 2347 2304 2388 2319 2297 2268 2202 2363 2262 2230 2320 2350 2321 2308 2342 2396 2294 2354 2306 2301 2252 2393 2240 2259 2376 2316 2324 2376 2314 2260 2287 2365 2277 2257 2320 2280 2188 2257 2229 2320 2320 2323 2347 2225 2207 2391 2297 2288 2320 2285 2325 2297 2358 2376 2296 2302 2312 2310 2306 2302 2292 2342 2329 2272 2361 2315 2393 2304 2331 2238 2252 2307 2353 2262 2252 2293 2214 2327 2279 2387 2296 2271 2182 2301 2227 2238 2204 2202 2316 2348 2304 2308 2314 2339 2351 2159 2295 2290 2241 2302 2330 2235 2210 2312 2403 2262 2232 2225 2268 2245 2311 2368 2278 2324 2256 2313 2409 2244 2297 2315 2253 2264 2382 2294 2349 2300 2243 2213 2222 2268 2316 2258 2341 2378 2313 2245 2371 2330 2333 2248 2137 2273 2306 2247 2266 2204 2240 2311 2292 2274 2288 2250 2340 2225 2229 2242 2304 2263 2311 2219 2242 2258 2320 2288 2258 2210 2354 2249 2318 2196 2357 2233 2207 2248 2240 2329 2201 2294 2276 2260 2293 2254 2334 2361 2209 2310 2303 2305 2246 2310 2258 2264 2478 2225 2201 2205 2356 2150 2233 2278 2261 2310 2347 2242 2253 2286 2261 2278 2400 2168 2317 2310 2193 2190 2246 2229 2314 2303 2351 2277 2337 2365 2342 2376 2281 2299 2333 2318 2316 2420 2380 2303 2288 2432 2341 2423 2372 2320 2518 2351 2428 2352 2387 2459 2432 2255 2450 2454 2322 2391 2469 2399 2407 2377 2418 2378 2429 2420 2321 2431 2388 2399 2520 2351 2349 2302 2360 2400 2298 2319 2312 2369 2446 2323 2286 2392 2277 2237 2288 2327 2313 2236 2248 2309 2233 2215 2277 2250 2174 2246 2245 2241 2376 2331 2366 2357 2352 2289 2326 2244 2302 2275 2200 2226 2220 2271 2290 2211 2332 2213 2219 2205 2235 2232 2181 2178 2194 2300 2261 2237 2307 2178 2342 2217 2254 2338 2273 2273 2338 2296 2175 2223 2259 2338 2276 2322 2349 2288 2199 2260 2332 2223 2246 2262 2178 2214 2223 2313 2316 2276 2287 2307 2210 2179 2288 2194 2361 2363 2302 2245 2339 2272 2245 2175 2210 2195 2262 2254 2304 2290 2232 2310 2341 2352 2327 2492 2441 2515 2557 2613 2656 2693 2662 2771 2704 2766 2818 2917 3009 2985 2851 2920 3036 2961 2994 2944 3058 2971 3055 3059 3172 3158 3130 3071 3244 3283 3133 3282 3419 3265 3242 3307 3281 3302 3304 3423 3382 3385 3337 3348 3323 3314 3291 3196 3168 3233 3186 3121 3122 3023 2868 2736 2888 2722 2598 2521 2571 2471 2444 2390 2485 2299 2328 2268 2262 2380 2257 2340 2265 2262 2223 2274 2309 2274 2330 2253 2275 2237 2339 2225 2336 2249 2324 2186 2207 2401 2235 2327 2343 2242 2409 2356 2285 2317 2361 2313 2320 2253 2346 2268 2263 2264 2315 2211 2241 2311 2332 2359 2342 2323 2313 2316 2285 2280 2324 2272 2353 2321 2275 2329 2245 2309 2326 2398 2301 2244 2299 2397 2355 2290 2308 2359 2368 2361 2273 2252 2308 2402 2337 2278 2363 2317 2460 2196 2426 2302 2311 2272 2315 2324 2412 2330 2342 2398 2264 2325 2255 2361 2247 2319 2299 2390 2521 2341 2372 2396 2225 2292 2245 2444 2439 2298 2356 2321 2287 2342 2356 2358 2374 2279 2406 2350 2426 2409 2283 2330 2291 2313 2344 2369 2410 2275 2382 2415 2324 2314 2355 2204 2474 2399 2291 2465 2386 2332 2367 2319 2403 2448 2343 2380 2425 2388 2438 2482 2401 2401 2410 2460 2403 2364 2380 2485 2388 2480 2372 2390 2422 2422 2465 2476 2489 2468 2379 2400 2552 2433 2420 2430 2518 2445 2553 2611 2779 2886 2903 2983 3113 3191 3391 3495 3510 3656 3827 3949 3932 4002 4093 4112 4181 4252 4201 4431 4529 4533 4470 4560 4625 4667 4967 5094 5109 5169 5321 5482 5537 5628 5687 5731 5916 6003 6035 6137 6196 6527 6366 6292 6456 6567 6530 6514 6292 6316 6110 6177 5926 5809 5591 5537 5320 4809 4817 4445 4176 3894 3803 3527 3367 3175 2973 3021 2780 2784 2721 2696 2652 2637 2635 2634 2598 2610 2666 2624 2579 2671 2603 2540 2668 2634 2582 2721 2543 2585 2645 2600 2577 2666 2681 2610 2640 2498 2600 2654 2699 2555 2635 2758 2591 2702 2516 2641 2522 2663 2657 2717 2749 2570 2631 2647 2609 2669 2622 2624 2607 2657 2642 2547 2665 2602 2622 2747 2688 2610 2596 2584 2736 2772 2666 2628 2743 2754 2646 2599 2626 2743 2600 2641 2741 2527 2680 2730 2785 2613 2629 2615 2614 2634 2647 2675 2619 2662 2670 2585 2683 2607 2575 2683 2827 2679 2650 2584 2721 2618 2567 2666 2661 2619 2623 2634 2654 2690 2747 2681 2664 2740 2662 2578 2747 2682 2735 2611 2693 2599 2619 2781 2683 2649 2719 2774 2711 2718 2791 2711 2698 2777 2738 2725 2750 2827 2874 2779 2794 2710 2653 2723 2729 2691 2777 2667 2826 2809 2743 2826 2788 2774 2765 2767 2735 2715 2779 2813 2677 2868 2855 2715 2828 2815 2776 2731 2761 2669 2685 2646 2673 2716 2702 2655 2609 2649 2589 2546 2640 2615 2443 2522 2648 2650 2505 2562 2540 2581 2573 2516 2521 2459 2565 2517 2584 2555 2524 2551 2487 2463 2616 2457 2542 2510 2608 2409 2509 2552 2551 2544 2477 2536 2462 2487 2441 2496 2376 2437 2576 2500 2523 2477 2501 2431 2362 2454 2492 2472 2517 2441 2415 2431 2448 2540 2443 2511 2432 2440 2445 2431 2449 2431 2429 2456 2387 2322 2383 2405 2455 2351 2397 2495 2324 2393 2366 2382 2490 2447 2336 2316 2443 2354 2316 2442 2417 2336 2297 2324 2370 2355 2317 2398 2313 2338 2227 2284 2330 2291 2264 2401 2279 2326 2284 2320 2278 2353 2406 2231 2318 2357 2331 2328 2299 2323 2299 2317 2214 2285 2237 2317 2275 2316 2333 2314 2252 2368 2355 2235 2214 2206 2262 2213 2226 2196 2282 2209 2287 2356 2194 2230 2209 2200 2299 2274 2230 2241 2296 2256 2163 2267 2301 2197 2160 2170 2203 2265 2201 2188 2118 2157 2201 2177 2193 2278 2198 2255 2113 2261 2150 2218 2206 2155 2176 2115 2208 2256 2261 2180 2165 2081 2097 2128 2162 2265 2110 2250 2307 2236 2210 2266 2268 2451 2449 2332 2519 2408 2610 2694 2601 2795 2768 2698 2683 2795 2962 2830 2836 2925 2888 2976 2822 2909 3077 3012 2990 3075 2988 3012 3036 3117 3128 3093 3182 3142 3147 3033 3107 3069 3190 3142 3124 3189 3169 3109 3102 3135 3096 3056 3029 3037 2870 2883 2882 2710 2719 2650 2528 2486 2492 2416 2339 2258 2098 2199 2190 2131 2062 2104 2075 2092 2123 2036 2062 2108 2066 2140 2042 1990 2113 2013 2125 2075 1997 2064 1982 2081 1956 2063 2045 2137 1995 2010 2081 2000 2032 1985 2026 2013 2024 1917 2001 2112 2050 1908 1922 2056 2045 2025 2034 1972 1976 2022 2018 2003 2041 2027 1927 1981 2037 2018 2031 1960 1935 2005 1960 2078 1985 2009 1928 1994 2036 1980 1972 2045 1969 2085 1965 1999 1924 1852 1919 1953 2018 2012 2087 2029 1986 2030 1894 1895 2020 1992 1952 1960 1991 1957 2044 2003 1876 1945 1942 2000 1980 1927 1973 1958 1936 1910 1941 1943 1825 1969 1988 1972 1864 1927 1870 1973 1950 1881 2024 1933 1986 1937 1833 1905 1871 1930 1965 1933 1813 1882 1876 1927 1940 1908 1889 1984 1919 1986 2004 1844 1855 1938 1911 1969 1824 1829 1830 1985 1939 1810 1910 1951 1946 1882 1861 1903 1902 1880 1843 1857 1970 1910 1887 1871 1956 1861 1998 1896 1924 1979 1976 1951 1897 1876 1960 2022 1880 2046 1899 1845 1967 1931 1966 1835 1886 1878 2029 1991 1958 1885 1812 1949 1853 1975 1997 1890 1931 1895 1927 1883 1819 1956 2004 1946 1935 1915 2001 1935 1966 1888 1911 1935 2019 1816 1833 1841 1888 1804 1775 1815 1844 1931 1855 1895 1906 1957 1901 1881 1918 1935 1883 1907 1764 1849 1768 1875 1805 1842 1852 1949 1879 1941 1762 1898 1893 1845 1890 1876 1814 1917 1954 1850 1923 1903 2022 1843 1921 1902 1904 1881 1927 1985 1892 1929 1886 1832 1929 1877 1845 1860 1868 1873 1889 1850 1823 1855 1848 1871 1862 1876 1885 1844 1932 1786 1789 1892 1852 1941 1868 1889 1897 1952 1802 1899 1920 1964 1881 1950 1889 1888 1985 1954 1915 2054 2115 2133 2131 2337 2285 2369 2391 2475 2494 2634 2688 2709 2730 2867 2756 2922 2894 2883 2976 3055 3076 3089 3118 3406 3324 3418 3372 3557 3475 3821 3650 3822 3844 4057 3992 4026 4023 4131 4209 4060 4118 4272 4222 4230 4253 4253 4297 4226 4265 4294 4003 3970 3919 3792 3641 3290 3415 3109 3041 2806 2640 2505 2413 2399 2210 2085 2094 1930 1945 1840 1876 1880 1935 1924 1825 1930 1930 1944 1935 1903 1842 1835 1843 1848 1878 1913 1855 1862 1853 1870 1898 1812 1740 1811 1768 1859 1825 1767 1794 1879 1882 1827 1706 1871 1858 1871 1845 1793 1877 1853 1826 1794 1703 1866 1809 1766 1778 1854 1914 1678 1719 1837 1775 1791 1764 1856 1855 1836 1746 1769 1808 1937 1759 1924 1790 1852 1831 1861 1832 1845 1780 1809 1808 1802 1737 1724 1716 1758 1687 1833 1736 1776 1826 1830 1807 1883 1740 1880 1802 1805 1889 1784 1829 1676 1826 1892 1864 1861 1825 1884 1878 1890 1966 1865 1993 2049 1913 1931 1998 1854 1923 1904 1896 2003 2002 1920 1893 1969 2079 2001 2014 2030 2007 1999 2029 1965 1997 2031 2044 2025 1995 2074 1989 2004 1995 2115 1957 1977 2061 1942 1940 2053 2022 1965 1995 2040 1903 1834 1853 1958 1813 1905 1889 1864 1843 1784 1765 1781 1884 1821 1866 1743 1837 1880 1814 1784 1947 1698 1724 1844 1662 1689 1841 1764 1827 1779 1793 1857 1722 1819 1750 1736 1750 1690 1810 1823 1810 1738 1819 1791 1749 1881 1792 1856 1730 1673 1802 1713 1853 1715 1790 1821 1664 1826 1729 1785 1679 1696 1799 1915 1828 1819 1801 1719 1909 1664 1778 1896 1764 1738 1697 1700 1807 1792 1883 1877 1753 1830 1784 1625 1687 1843 1823 1736 1864 1805 1740 1726 1713 1824 1783 1774 1800 1745 1812 1775 1856 1817 1877 1773 1802 1721 1728 1804 1792 1795 1685 1749 1820 1873 1760 1753 1698 1665 1780 1853 1797 1849 1873 1870 1861 1897 1823 1888 1827 1786 1714 1853 1889 1760 1789 1792 1854 1792 1726 1866 1773 1852 1782 1820 1735 1714 1729 1845 1869 1751 1883 1893 1890 1883 1798 1788 1813 1847 1841 1779 1773 1737 1856 1675 1890 1746 1880 1809 1746 1835 1877 1715 1830 1806 1824 1838 1813 1823 1854 1854 1859 1838 1877 1864 1806 1784 1842 1823 1844 1819 1862 1821 1826 1792 1805 1801 1835 1810 1909 1882 1902 1854 1788 1909 1891 1900 1812 1891 1895 1865 1810 1777 1865 1911 1934 1846 1877 1889 1803 1828 1943 1732 1892 1888 1786 1735 1892 1891 1773 1890 1861 1859 1637 1850 1820 1794 1828 1912 1739 1840 1803 1890 1858 1905 1793 1832 1901 1819 1845 1796 1927 1904 1931 1868 1821 1745 1943 1874 1910 1843 1766 1903 1893 1853 1885 1879 1902 1874 1928 1811 1910 1889 1884 1883 1903 1967 1848 1840 1923 1923 1904 1884 1888 1947 1959 1875 1896 1850 1954 1845 1858 1993 1827 1918 1937 1983 1818 1841 1948 1957 1948 1975 2020 1907 1887 1887 1904 1927 1913 1973 1910 2021 1981 1886 1856 2049 1931 1914 1956 1950 1943 1959 1925 1993 1845 2038 1961 1951 1916 1914 1864 1980 1965 1894 1972 2012 2010 2059 2023 2015 2031 2020 1934 2022 2030 1992 2002 2011 1951 2008 1962 2115 2030 2018 2017 1992 2154 2196 2157 2268 2268 2400 2396 2489 2686 2518 2729 2763 2971 3087 3098 3218 3294 3291 3388 3507 3541 3550 3664 3806 3632 3766 3802 3771 3944 3865 3947 3975 3966 3792 4057 3845 4114 3985 4025 4099 3949 3972 4032 4028 4035 4132 3930 4041 4072 4017 3983 3955 3827 3812 3881 3744 3694 3590 3561 3441 3293 3213 3143 2873 2829 2717 2627 2574 2436 2455 2328 2298 2284 2318 2272 2214 2221 2198 2239 2392 2132 2131 2087 2130 2246 2101 2237 2233 2064 2171 2135 2200 2114 2123 2200 2206 2308 2183 2197 2188 2232 2215 2169 2197 2252 2285 2270 2200 2196 2256 2259 2198 2240 2200 2200 2241 2238 2267 2247 2243 2227 2194 2244 2298 2298 2276 2260 2243 2286 2200 2230 2248 2320 2318 2342 2236 2356 2243 2308 2222 2335 2241 2309 2200 2300 2280 2278 2401 2231 2369 2276 2208 2341 2362 2311 2404 2410 2302 2282 2426 2318 2336 2369 2379 2363 2413 2373 2403 2299 2384 2425 2352 2428 2473 2396 2393 2434 2351 2372 2408 2415 2419 2380 2271 2389 2407 2450 2398 2439 2339 2379 2478 2432 2378 2396 2490 2483 2484 2524 2449 2429 2435 2557 2416 2416 2405 2559 2401 2496 2459 2429 2499 2530 2483 2468 2462 2449 2528 2539 2446 2471 2470 2552 2515 2476 2461 2375 2537 2571 2530 2477 2593 2543 2553 2467 2524 2549 2525 2600 2550 2536 2551 2504 2579 2561 2562 2627 2626 2484 2641 2523 2495 2558 2533 2571 2573 2502 2643 2698 2603 2549 2521 2585 2575 2661 2473 2593 2518 2560 2596 2611 2604 2532 2498 2538 2581 2527 2498 2711 2550 2504 2600 2574 2612 2555 2732 2568 2647 2541 2505 2535 2573 2492 2656 2520 2662 2659 2666 2431 2491 2618 2587 2518 2526 2613 2638 2417 2458 2564 2556 2486 2533 2573 2600 2545 2651 2496 2512 2558 2553 2483 2526 2564 2547 2555 2583 2493 2451 2537 2434 2575 2505 2592 2544 2524 2699 2569 2565 2505 2581 2467 2483 2458 2570 2563 2684 2526 2581 2503 2461 2439 2504 2611 2569 2494 2576 2534 2544 2539 2510 2441 2551 2515 2558 2494 2555 2553 2536 2560 2564 2476 2423 2449 2516 2567 2503 2404 2485 2509 2359 2576 2440 2454 2463 2489 2505 2486 2515 2476 2473 2394 2424 2580 2377 2448 2417 2461 2406 2423 2359 2390 2335 2417 2434 2490 2400 2407 2390 2446 2410 2379 2435 2425 2456 2384 2395 2465 2360 2337 2503 2366 2445 2405 2401 2376 2332 2449 2298 2418 2382 2487 2449 2385 2338 2430 2352 2411 2329 2318 2373 2439 2370 2414 2311 2273 2291 2347 2326 2440 2328 2372 2310 2368 2332 2315 2307 2257 2279 2362 2296 2330 2360 2303 2197 2377 2220 2318 2321 2262 2352 2333 2219 2386 2203 2301 2264 2328 2319 2378 2287 2213 2258 2266 2273 2332 2224 2404 2290 2302 2262 2243 2215 2275 2249 2245 2287 2260 2178 2260 2156 2167 2225 2274 2194 2258 2336 2228 2258 2242 2152 2216 2301 2197 2231 2247 2247 2238 2234 2089 2273 2189 2197 2193 2211 2384 2268 2170 2177 2190 2202 2260 2252 2273 2237 2222 2281 2262 2204 2226 2276 2192 2260 2192 2290 2254 2176 2207 2273 2204 2264 2299 2163 2159 2156 2160 2159 2210 2241 2251 2193 2215 2241 2191 2161 2132 2261 2088 2195 2193 2171 2212 2170 2210 2140 2135 2241 2126 2157 2156 2148 2119 2110 2231 2161 2175 2108 2188 2152 2226 2170 2036 2172 2201 2157 2159 2179 2141 2164 2072 2201 2140 2199 2171 2257 2209 2263 2229 2254 2242 2330 2296 2385 2367 2406 2268 2347 2391 2506 2442 2345 2408 2454 2494 2422 2482 2498 2480 2495 2419 2608 2607 2439 2537 2573 2604 2518 2496 2699 2592 2682 2581 2533 2669 2684 2629 2653 2711 2580 2652 2693 2565 2607 2629 2594 2597 2584 2527 2462 2526 2414 2360 2388 2252 2343 2342 2269 2240 2233 2171 2168 2171 2088 2224 2062 2156 2085 2188 2179 2070 2146 1987 2107 2130 2123 2174 2115 2169 2158 2071 2018 2132 2081 2071 2116 2035 2139 2085 2112 1928 2110 2147 1976 2016 2189 2037 2126 2152 1981 2048 2073 2083 2003 2183 2142 2056 2096 2139 2022 2026 2047 2079 2118 2054 2128 2066 2048 2123 2083 2070 1978 2044 2076 2047 1975 2091 2116 2061 2037 1980 2058 1985 2088 2041 2069 1989 2049 2030 2080 2009 1960 2091 1942 1998 1991 2097 2027 1962 2015 2093 2029 2031 2028 2093 2063 1932 2100 2045 1979 2011 2143 2008 2035 2075 2059 2073 2037 2058 2158 2228 2071 2026 2045 2091 2076 2163 2100 2037 2088 2090 1962 2143 2075 2051 2021 2137 2155 2086 2173 2074 2104 1986 2076 2067 2031 2036 2011 1953 1997 2038 2062 2068 2014 2020 2000 1992 2012 2075 1994 1904 2002 1919 1880 1965 1957 1954 1928 1881 1965 1916 1915 2014 1981 1914 1936 1987 1890 1961 1941 1907 1936 1998 1944 1847 1960 1876 1931 1958 2017 2001 1934 1915 1841 1948 1924 1961 1886 1913 1893 1904 1909 1891 1987 1859 1987 1906 1932 1949 1888 1961 1826 1859 1884 1909 1925 1853 1923 1866 1883 2005 1871 1892 1938 1951 1725 1904 1887 1971 1892 1828 1860 2016 1881 1863 1969 1869 1807 1855 1905 1939 1906 1919 1863 1956 1828 1920 1853 1914 1826 1913 1846 1861 1866 1936 1900 1968 1895 1880 1880 1932 1927 1795 1899 1834 1860 1968 1895 1862 1852 1935 1920 1982 1865 1942 1916 1922 1916 1837 1769 1845 1935 1917 1856 1842 1909 1906 1885 1871 1889 1847 1907 1886 1956 1968 1895 1889 1929 1893 1868 1839 1829 1849 1876 1863 1871 1885 1852 1769 1926 1868 1928 1921 1864 1919 1948 1994 1880 1914 1829 2019 1978 2003 1977 1917 1959 1875 1962 1910 1928 2030 1918 1952 2039 1968 1991 2047 2079 2014 2123 2146 2145 2115 2297 2297 2589 2686 2966 2989 3327 3514 3970 4248 4742 5143 5464 6178 6381 6951 7362 7895 8254 8653 8727 9069 9285 9527 9481 9538 9699 9905 9913 9965 9813 10201 10219 10157 10269 10173 10209 10400 10352 10536 10516 10387 10769 10559 10469 10591 10870 10639 10856 10707 10527 10521 10633 10127 10236 9951 9628 9355 8834 8336 8035 7442 7054 6343 5680 5191 4750 4260 4094 3653 3256 2912 2906 2611 2446 2279 2227 2194 2099 2108 2164 2073 2171 1994 2089 2087 2074 2053 2123 1978 2084 2057 1980 2005 1971 1941 1921 1951 1887 1926 2028 1921 1840 1881 1925 1887 1867 1928 1943 1893 1868 1956 1923 1948 1848 1906 1854 1888 1933 1905 1908 1826 1869 1937 1837 1945 1944 1841 1885 1872 1831 1953 1909 1854 1845 1811 1942 1923 1946 1798 1796 1888 1861 1904 1895 1766 1855 1774 1771 1859 1919 1849 1861 1815 1953 1883 1897 1872 1862 1865 1880 1783 1876 1779 1824 1846 1887 1900 1852 1846 1915 1794 1915 1921 1869 1916 1844 1839 1874 1797 1773 1841 1822 1891 1915 1763 1936 1846 1875 1821 1876 1794 1751 1931 1870 1965 1938 1827 1902 1911 1867 1849 1733 1885 1942 1927 1917 1847 1798 1864 1915 1862 1875 1823 1905 1768 1897 1864 1911 1802 2004 1836 1876 1837 1959 1892 1889 1869 1976 1838 1847 1801 1812 1886 1832 1878 1872 1834 1885 1964 1905 1826 1921 1918 1856 1837 1927 1829 1900 1859 1885 1779 1916 1870 1902 1781 1772 1948 1917 1847 1765 1886 1863 1859 1872 1898 1841 1840 1846 1920 1810 1846 1847 1889 1806 1908 1814 1940 1939 1856 1866 1927 1893 1918 1765 1884 1927 1879 1733 1872 1782 1931 1825 1981 1812 1933 1865 1853 1929 1977 1925 2033 1959 1923 1990 2061 2027 2043 1968 2032 1993 2038 2086 2029 1934 2020 2107 1918 2094 2064 2057 2007 2043 2021 2109 2069 2085 2193 2056 2107 2144 2040 2169 2051 2155 2095 2096 2092 2132 2113 2111 2251 2115 2056 2082 2079 2113 2011 2047 2014 1991 2091 2042 1987 2086 2034 1925 1958 1944 1878 1923 1923 1888 1863 1900 1897 1775 1866 1925 1928 1867 1880 1944 1910 1814 1795 1841 1865 1814 1850 1852 1990 1953 1900 1884 1879 1921 1874 1789 1894 1839 1860 1945 1791 1954 1901 1922 1773 1930 1885 1748 1832 1813 1891 1881 1849 1864 1718 1809 1945 1919 1841 1816 1862 1911 1850 1875 1873 1848 1933 1821 1797 1788 1756 1827 1840 1905 1779 1929 1968 1820 1773 1887 1884 1867 1854 1760 1852 1825 1874 1886 1917 1741 1926 1890 1868 1908 1910 1874 1792 1863 1883 1849 1863 1797 1841 1857 1861 1896 1847 1885 1742 1791 1885 1831 1840 1903 1852 1897 1899 1902 1860 1952 1858 1880 1870 1938 1887 1988 1946 1881 1840 1804 1839 1855 1850 1812 1864 1858 1841 1895 1823 2015 1811 1829 1864 1930 1812 1924 1753 1964 1920 1987 1868 1889 1936 1930 1961 1927 1862 1898 1963 1936 1918 1971 1998 2046 2033 1998 2130 2207 2361 2476 2733 3155 3680 3990 4554 4872 5220 5870 6398 6628 7072 7407 7764 7941 7978 7622 7482 7191 6683 6563 6008 5653 5086 4792 4222 3892 3366 3111 2820 2585 2467 2400 2372 2369 2205 2238 2254 2094 2126 2198 2094 2002 2070 2074 2095 2004 2014 2085 2038 1990 1966 1913 1955 1831 1912 1878 1915 1898 1921 1951 1914 1967 1934 1946 1866 1932 1888 1903 1930 1919 1885 1881 1949 1883 1849 1914 1866 1870 1963 1945 1859 1824 1918 1857 1872 1866 1906 1741 1904 1858 1895 1921 1854 1872 1847 1916 1904 1853 1895 1967 1926 1951 1992 1899 1864 1957 1845 1820 1924 1932 1818 1872 1958 1913 1989 1908 1899 1906 1874 1920 1940 1887 1860 1940 2028 1867 1867 2057 1969 1944 1887 2001 1943 1884 1986 1909 1971 1960 1944 1954 2029 1926 1945 1950 1950 1930 1907 1921 1850 1900 1887 1972 1976 1957 1915 1918 1847 2033 2034 1906 1927 1929 1892 1954 1876 1952 1914 1912 1971 1862 2005 1974 1983 2017 2054 1973 1923 2018 1943 2017 1926 2053 2029 2013 2050 1921 1987 1865 2052 1960 1943 2020 1996 2026 1983 1916 1960 1949 1937 2073 2060 1996 2030 2025 2054 2039 2055 2124 2109 2053 2020 2002 2094 2050 1985 2039 2018 2042 2096 2075 1990 1942 1974 2003 2031 1973 1969 1939 2000 1957 2007 1979 1975 1944 2005 2011 1949 1986 1980 1999 1981 1990 1927 1870 2039 2023 2131 2015 2019 2009 1972 2059 1968 2054 2060 2084 2141 2063 1965 1972 2065 2089 1987 1982 1990 2033 2036 1997 2062 1999 2147 2116 2056 2013 2004 2104 1943 2166 2161 2039 1950 1973 1965 2069 1934 2149 2022 2042 2020 2070 1994 2143 2034 2021 2068 2141 2118 2052 2031 2151 2064 2088 2102 2174 2143 2103 2135 2016 2029 2156 2191 2109 2056 1954 2147 2130 2094 2170 2080 2030 2140 2088 2188 1996 2115 2085 2091 2134 2138 2129 2159 2117 2157 2021 2141 2206 2055 2116 2163 2099 2188 2055 2203 2116 2153 2131 2074 2071 2073 2148 2108 2035 2189 2093 2047 2120 2100 2058 2101 2175 2152 2103 2153 2135 2009 2012 2225 2306 2172 2116 2132 2017 2113 2089 2178 2164 2117 2045 2151 2001 2137 2114 2143 2159 2096 2149 2175 2176 2155 2161 2059 2110 2099 2125 2120 2040 2187 2208 2105 2179 2160 2204 2208 2112 2234 2176 2195 2225 2150 2134 2138 2192 2089 2218 2155 2211 2189 2191 2094 2179 2120 2238 2160 2205 2177 2142 2175 2115 2175 2167 2121 2157 2116 2217 2191 2179 2231 2221 2169 2252 2176 2192 2154 2227 2318 2174 2272 2238 2276 2293 2209 2175 2207 2132 2137 2117 2232 2255 2156 2227 2263 2231 2176 2181 2218 2330 2271 2204 2300 2204 2159 2173 2229 2284 2146 2233 2232 2240 2257 2302 2148 2239 2299 2378 2305 2272 2251 2224 2252 2213 2364 2295 2339 2276 2337 2348 2388 2267 2324 2479 2354 2471 2385 2372 2440 2506 2412 2352 2545 2506 2441 2505 2503 2504 2527 2346 2569 2542 2513 2583 2511 2660 2454 2495 2509 2568 2620 2574 2660 2605 2518 2626 2572 2563 2602 2535 2471 2513 2415 2485 2449 2471 2470 2485 2384 2385 2411 2376 2405 2319 2231 2238 2391 2341 2325 2205 2298 2291 2331 2344 2313 2257 2269 2364 2296 2326 2352 2326 2358 2233 2293 2344 2416 2295 2323 2255 2293 2296 2298 2288 2325 2316 2356 2255 2306 2292 2333 2337 2356 2272 2350 2388 2418 2364 2264 2347 2287 2408 2324 2338 2416 2322 2357 2358 2417 2413 2287 2273 2357 2412 2383 2465 2335 2353 2414 2377 2336 2351 2397 2464 2356 2386 2312 2369 2329 2469 2417 2422 2493 2422 2411 2525 2574 2515 2447 2542 2391 2502 2594 2711 2652 2680 2623 2629 2648 2665 2627 2651 2717 2747 2709 2709 2718 2722 2713 2723 2832 2771 2810 2808 2851 2907 2841 2797 2799 2747 2852 2874 2912 2790 2926 2884 2752 2829 2825 2712 2825 2780 2793 2768 2818 2707 2701 2557 2602 2510 2600 2565 2445 2529 2481 2459 2381 2529 2478 2483 2492 2396 2384 2577 2427 2483 2485 2488 2460 2451 2468 2494 2487 2443 2442 2540 2498 2504 2483 2460 2426 2502 2493 2443 2417 2506 2386 2492 2523 2494 2585 2477 2514 2585 2531 2551 2642 2610 2668 2516 2513 2506 2574 2526 2498 2610 2613 2697 2508 2637 2611 2624 2653 2635 2666 2606 2624 2623 2757 2633 2631 2576 2712 2615 2654 2639 2700 2627 2616 2701 2545 2717</counts>
			</dataPoints>
		</scan>
	</xrdMeasurement>
</xrdMeasurements>