File: Data Files/Full/MSS p (12-129, 16w)_01.xrdml
<?xml version="1.0"?>
<xrdMeasurements xmlns="http://www.xrdml.com/XRDMeasurement/2.2" xmlns:xsi="http://www.w3.org/2001/XMLSchema-instance" xsi:schemaLocation="http://www.xrdml.com/XRDMeasurement/2.2 http://www.xrdml.com/XRDMeasurement/2.2/XRDMeasurement.xsd" status="Completed" recordIdentifier="{CACB7DAF-E3F2-455F-AFA1-257B369B6CA5}">
	<comment>
		<entry/>
	</comment>
	<sample type="To be analyzed">
		<id>p</id>
		<name></name>
		<preparedBy></preparedBy>
	</sample>
	<xrdMeasurement measurementType="Scan" status="Completed" sampleMode="Reflection">
		<usedWavelength intended="K-Alpha 1">
			<kAlpha1 unit="Angstrom">1.5405980</kAlpha1>
			<kAlpha2 unit="Angstrom">1.5444260</kAlpha2>
			<kBeta unit="Angstrom">1.3922500</kBeta>
			<ratioKAlpha2KAlpha1>0.5000</ratioKAlpha2KAlpha1>
		</usedWavelength>
		<incidentBeamPath>
			<radius unit="mm">145.00</radius>
			<xRayTube id="1010048" name="Empyrean Cu LFF HR (9430 033 7310x) DK437964">
				<tension unit="kV">40.0</tension>
				<current unit="mA">15.0</current>
				<anodeMaterial>Cu</anodeMaterial>
				<focus type="Line">
					<length unit="mm">12.0</length>
					<width unit="mm">0.4</width>
					<takeOffAngle unit="deg">6.0</takeOffAngle>
				</focus>
			</xRayTube>
			<filter id="20010004" name="Beta-filter Nickel">
				<material>Ni</material>
				<thickness unit="mm">0.020</thickness>
			</filter>
			<sollerSlit id="21010002" name="Soller slits 0.04 rad.">
				<opening unit="rad">0.0400</opening>
			</sollerSlit>
			<mask id="22031000" name="Fixed mask 13 mm">
				<width unit="mm">9.00</width>
			</mask>
			<divergenceSlit id="22120001" name="Divergence slit 1°" xsi:type="fixedDivergenceSlitType">
				<distanceToSample unit="mm">50.00</distanceToSample>
				<height unit="mm">1.52</height>
			</divergenceSlit>
		</incidentBeamPath>
		<diffractedBeamPath>
			<radius unit="mm">145.00</radius>
			<parallelPlateCollimator id="25020001" name="Parallel plate collimator 0.28°">
				<opening unit="deg">0.28</opening>
			</parallelPlateCollimator>
			<detector id="7010020" name="PIXcel3D-Medipix3 1x1 detector" xsi:type="areaDetectorType">
				<phd unit="keV">
					<lowerLevel>4.0</lowerLevel>
					<upperLevel>11.3</upperLevel>
				</phd>
				<mode>Receiving slit</mode>
				<activeChannelsEquatorial>255</activeChannelsEquatorial>
				<activeChannelsAxial>255</activeChannelsAxial>
				<pitchEquatorial unit="mm">0.05500</pitchEquatorial>
				<pitchAxial unit="mm">0.05500</pitchAxial>
				<readOutPeriod unit="seconds">0.050</readOutPeriod>
			</detector>
		</diffractedBeamPath>
		<scan appendNumber="0" mode="Continuous" scanAxis="2Theta" status="Completed">
			<header>
				<startTimeStamp>2025-07-02T12:19:11-08:00</startTimeStamp>
				<endTimeStamp>2025-07-03T14:19:16-08:00</endTimeStamp>
				<author>
					<name>Instrument</name>
				</author>
				<source>
					<applicationSoftware version="1.6 (94)">PANalytical Aeris Instrument Suite</applicationSoftware>
					<instrumentControlSoftware version="3.0.0 20211014">AERIS</instrumentControlSoftware>
					<instrumentID>2855484</instrumentID>
				</source>
			</header>
			<dataPoints>
				<positions axis="2Theta" unit="deg">
					<startPosition>12.005</startPosition>
					<endPosition>128.995</endPosition>
				</positions>
				<positions axis="Omega" unit="deg">
					<commonPosition>16.000</commonPosition>
				</positions>
				<commonCountingTime unit="seconds">7.040</commonCountingTime>
				<counts 5323 5167 5211 5193 5270 5330 5181 5214 5233 5045 5040 5118 5153 5142 5080 5210 5138 5176 5161 5167 5179 5289 5132 5250 5234 5175 5246 5226 5191 5142 5151 5134 5178 5242 5207 5090 5235 5164 5155 5144 5397 5285 5214 5296 5195 5253 5248 5207 5167 5229 5204 5135 5161 5374 5200 5113 5058 5206 5255 5235 5138 5262 5201 5162 5155 5243 5187 5100 5186 5143 5159 5161 5131 5231 5247 5037 5123 5035 5050 5217 5045 5182 5174 5214 5183 5341 5133 5284 5162 5256 5170 5179 5225 5101 5099 5245 5178 5116 5093 5078 5147 5031 5156 5253 5148 5240 5131 5234 5172 5230 5279 5290 5242 5198 5012 5121 5256 5009 5202 5143 5203 5224 5245 5156 5064 5174 5195 5127 5202 5100 5228 5105 5182 4988 5044 5031 5157 5118 5041 5106 5080 5171 5124 5158 5173 5054 5209 5057 5073 5121 5178 5218 5163 5067 5120 5190 5114 5117 5101 5004 5192 5183 5104 5015 5046 5264 5152 5194 5270 5238 5320 5117 5315 5268 5342 5475 5479 5591 5470 5589 5762 5656 5640 5723 5753 5887 5716 5896 5966 5909 6188 6081 6021 6087 6037 6119 6232 6225 6241 6307 6466 6236 6318 6335 6248 6583 6546 6511 6609 6501 6596 6582 6561 6603 6695 6682 6802 6745 6774 6656 6648 6862 6804 6825 6606 6887 6957 6814 6825 6746 6878 6884 6979 6929 6672 7054 6809 6967 6920 6893 6954 6990 7008 6811 7104 6982 6890 7037 7117 7144 7054 7145 7167 7006 7035 7090 7039 7021 7094 7186 7124 6980 7250 7133 7295 7187 7087 7185 7292 7048 7194 7304 7276 7233 7172 7161 7061 7439 7272 7384 7144 7172 7446 7254 7418 7294 7221 7293 7203 7338 7346 7326 7402 7586 7387 7489 7299 7561 7502 7430 7426 7597 7506 7377 7599 7528 7624 7514 7585 7583 7352 7573 7545 7663 7565 7474 7698 7653 7776 7567 7568 7565 7606 7562 7753 7630 7747 7678 7814 7682 7721 7746 7630 7850 7763 7890 7801 7783 7779 7749 7859 7913 7880 7864 7891 7879 7915 7905 8130 8000 8055 8084 7893 8076 8032 8038 8071 7927 8097 8073 8038 8294 8234 8239 7968 7973 8236 8200 8384 8367 8250 8511 8426 8385 8316 8573 8427 8429 8382 8538 8194 8320 8518 8440 8533 8439 8493 8690 8448 8561 8686 8765 8624 8657 8633 8674 8823 8733 8890 8655 8825 9020 8843 8973 8852 8923 8928 9025 8982 8918 8985 9178 8941 8877 9079 9042 8913 9078 8958 8998 8978 9007 9186 9247 9083 9228 9257 9026 9252 9320 9302 9360 9239 9249 9291 9321 9338 9543 9326 9512 9438 9532 9490 9407 9637 9632 9421 9481 9555 9738 9468 9470 9788 9563 9477 9647 9413 9764 9584 9733 9649 9706 9577 9610 9541 9578 9747 9547 9701 9616 9648 9673 9909 9931 9667 9860 9853 9768 9756 9731 9715 9921 9702 9822 9824 9716 9658 9793 9917 9812 9916 9778 9897 9824 9881 9625 9747 10007 9864 9879 9750 9633 9881 9925 9747 9821 10071 9953 9861 9947 9922 9835 9835 9738 9730 9774 9979 9891 9665 9742 9961 9547 9879 9743 9726 9640 9745 9624 9705 9691 9615 9628 9951 9682 9765 9691 9699 9766 9649 9744 9640 9538 9712 9716 9752 9635 9666 9694 9671 9577 9598 9753 9615 9486 9499 9436 9486 9534 9679 9676 9419 9440 9495 9542 9701 9506 9465 9344 9415 9466 9559 9365 9290 9359 9458 9341 9445 9331 9435 9261 9183 9456 9162 9363 9394 9388 9345 9256 9072 9172 9275 9198 9127 9152 9272 9167 9182 9042 9333 9061 9009 8940 9175 9021 9053 9010 8936 9123 9136 9120 9254 9152 9000 9069 8831 9044 8890 8848 9003 8776 8811 8933 8868 8937 8927 8894 8698 8896 8647 8818 8740 8782 8732 8772 8949 8925 8767 8589 8766 8725 8731 8676 8639 8774 8769 8630 8759 8794 8469 8541 8593 8342 8575 8331 8606 8711 8439 8474 8410 8485 8362 8484 8431 8418 8484 8461 8438 8300 8452 8264 8357 8429 8183 8261 8337 8317 8145 8293 8341 8433 8318 8274 8178 8111 8208 8425 8242 8105 8108 8298 8009 8156 8048 8132 8143 7822 8176 8053 8172 8158 8118 8060 7931 8002 7914 8054 7893 8249 8108 7926 7888 7989 7986 8059 7938 7804 8065 7984 7843 7785 7782 7805 8057 7980 7952 7799 7911 7844 7906 7765 7525 7820 7866 7692 7911 7955 7801 7636 7792 7828 7537 7848 7670 7724 7599 7734 7669 7725 7547 7482 7592 7508 7699 7611 7455 7428 7589 7567 7446 7465 7658 7582 7652 7555 7620 7543 7495 7421 7567 7427 7328 7374 7416 7404 7428 7383 7334 7526 7341 7214 7253 7197 7579 7457 7251 7351 7203 7267 7296 7286 7263 7489 7422 7532 7660 7778 7861 7785 7701 7639 7486 7400 7540 7208 7220 7197 7088 7128 7007 7101 7055 7111 7195 7181 7193 7209 7073 6923 7012 7129 7125 6953 7097 7133 7059 6991 6968 7065 7108 7012 7110 7152 7014 6826 7149 6975 7105 7043 6902 7010 7109 6866 7016 7033 7043 6959 6896 6937 6848 7077 6897 6969 6801 6915 6995 6951 6894 6797 6799 6903 6964 6956 6879 6845 6753 6921 6888 6791 7050 6978 6837 6921 6909 7137 7029 6824 6908 6824 6879 6948 6830 6874 6838 6904 6676 6777 6926 6894 6949 6744 7131 6891 6820 6886 6895 6872 7011 7029 7001 6832 6783 6859 7033 6798 6777 6766 6935 7067 6896 6947 7054 6948 6997 6891 7130 7056 6828 6991 7178 7067 6997 7126 7230 6829 7138 7124 7101 7176 7362 7167 7253 7500 7538 7494 7590 7937 8666 9203 9710 10319 11022 11716 12534 13451 14148 15089 16195 17789 18858 20076 21190 21576 21936 22611 22344 22418 22578 22689 22425 22586 23189 23005 23304 23905 24767 25609 26360 27070 28045 29372 29916 31611 33175 34579 35678 36754 38259 38725 40042 40473 41767 42745 44945 49539 52064 51227 49192 46734 44453 43123 40728 39023 38365 39376 40591 39840 37692 36285 33746 32193 29845 24125 18124 14982 12979 10849 8711 7921 7434 7322 7236 7123 7080 7095 7029 6970 6819 6908 6914 6772 6924 6837 6669 6884 6789 6704 6737 6453 6608 6625 6622 6393 6541 6484 6466 6388 6415 6538 6290 6256 6312 6392 6239 6317 6432 6287 6413 6376 6402 6230 6283 6410 6181 6303 6248 6301 6429 6133 6245 6151 6183 6255 6396 6438 6228 6224 6302 6285 6256 6364 6247 6151 6261 6138 6361 6234 6028 6205 6185 6237 6186 6161 6101 6205 5989 6144 6119 6116 6216 6074 6135 6065 5972 6192 5963 6110 6077 5953 5886 6046 5862 5964 5834 5896 5930 5840 5802 5781 5839 5931 5783 5781 5774 5722 5773 5821 5730 5702 5780 5793 5807 5809 5835 5670 5708 5611 5663 5702 5759 5687 5684 5580 5667 5612 5460 5706 5742 5618 5820 5575 5528 5645 5593 5567 5625 5594 5625 5592 5616 5520 5577 5642 5749 5607 5709 5643 5600 5713 5606 5594 5572 5558 5480 5657 5549 5613 5530 5388 5484 5496 5484 5445 5460 5428 5424 5523 5449 5557 5484 5406 5495 5646 5449 5477 5345 5549 5450 5360 5494 5487 5506 5508 5432 5523 5636 5415 5350 5380 5440 5380 5265 5377 5383 5309 5456 5536 5282 5395 5222 5338 5520 5351 5412 5206 5404 5308 5332 5334 5207 5386 5301 5379 5335 5464 5241 5292 5344 5287 5313 5238 5255 5245 5260 5361 5322 5360 5239 5259 5292 5354 5314 5357 5229 5290 5220 5060 5335 5333 5254 5232 5115 5285 5217 5158 5314 5207 5176 5272 5477 5275 5223 5206 5315 5312 5210 5397 5163 5246 5248 5315 5149 5169 5162 5053 5304 5164 5253 5183 5277 5138 5039 5180 5099 5217 5192 5212 5162 5210 5196 5243 5297 5259 5093 5124 5078 5175 5092 5099 5133 5238 5318 5241 5230 5138 5145 5178 5196 5054 5145 5155 5142 5122 5126 5012 5029 5239 5132 5108 5066 5180 5092 5063 5154 5135 5214 5134 5040 5121 5021 5066 5135 5221 5078 4989 4928 4928 5033 5157 5032 5085 5020 5111 5022 5055 5027 4980 4930 5071 4950 4998 5144 5135 4980 5125 5030 5133 5159 5060 5075 4984 5071 5101 5002 4934 5039 5090 4917 4985 5022 5106 5000 5079 4959 4979 5029 5090 5102 5038 5104 5107 4982 5081 5137 4900 5053 5029 4909 4999 4796 5070 5034 5029 4965 4983 4974 4921 4886 4996 5101 5077 4944 4901 4879 5065 5101 4905 5017 4892 4905 5114 5055 4961 4992 4977 5084 4877 4954 5044 5030 5011 5022 4827 4772 4993 4945 4874 4833 4920 4987 4970 4859 4892 5005 4937 4898 4825 4906 4919 4976 4893 4758 4909 4784 4935 5006 4791 4870 4837 4919 5019 4977 4944 4915 4808 4914 4946 4884 4996 4953 5010 4860 4986 4753 4942 4946 4861 4908 5077 4870 4863 4913 4923 4843 4870 4941 4830 4933 4912 4956 4959 4920 4846 5068 5034 4913 4916 4884 4881 4872 4893 4875 4881 4898 4696 4784 4893 5039 4723 4855 4944 4828 4971 4837 4830 4916 4801 4756 4853 4907 4718 4955 4841 4807 4929 4706 4969 4855 4946 4762 4780 5026 4812 4841 4794 4783 4918 4757 4827 4796 4820 4807 4906 4971 4825 4793 4779 4743 4917 4839 4877 4821 4831 4791 4831 4887 4768 4715 4911 4854 4803 4888 4727 4917 4786 4847 4856 4828 4758 4816 4710 4778 4850 4765 4763 4771 4799 4954 4941 4776 4845 4873 4955 4948 4881 4713 5002 4878 4886 4758 4674 4795 4934 4899 4802 4951 4740 4698 4791 4860 4749 4723 4783 4915 4910 4817 4805 4909 4893 4717 4979 4817 4743 4776 4860 4767 4798 4847 4730 4871 4888 4785 4765 4774 4826 4881 4810 4773 4891 4768 4689 4819 4825 4764 4789 4726 4877 4773 4965 4733 4801 4887 4683 4752 4782 4806 4654 4658 4700 4753 4853 4772 4743 4685 4876 4888 4666 4824 4775 4905 4673 4628 4724 4864 4776 4644 4852 4774 4869 4682 4719 4730 4893 4926 4726 4642 4780 4780 4773 4849 4840 4735 4815 4821 4720 4817 4844 4821 4912 4838 4907 4873 4997 4905 4904 4822 4820 4908 4885 4886 4873 4840 4918 4936 4849 5025 4811 5023 4816 4905 4922 5004 5042 5102 5049 5029 4904 4873 5123 5017 4938 4874 5109 5021 4897 5128 4845 5038 5078 4888 4915 4950 4993 5122 5036 5040 4881 4837 5047 4990 4970 4862 5044 4951 4821 4966 4654 4849 4848 4916 4775 4867 4802 4735 4996 4881 4970 4937 4646 4777 4824 4877 4764 4875 4978 4804 4849 4792 4840 4802 4769 4814 4975 4714 4811 4595 4708 4775 4811 4772 4745 4790 4808 4757 4780 4605 4826 4770 4763 4719 4801 4715 4623 4683 4762 4758 4654 4766 4743 4595 4726 4762 4772 4835 4743 4780 4802 4760 4752 4624 4752 4827 4661 4893 4712 4779 4706 4733 4684 4698 4728 4732 4758 4684 4687 4718 4715 4659 4778 4807 4703 4836 4759 4709 4824 4594 4605 4849 4755 4801 4819 4815 5000 4909 4983 5207 5065 5252 5385 5527 5529 5760 5914 5935 5642 6093 6021 5855 5869 6082 6103 5994 5986 6073 6225 6181 5978 6296 6230 6403 6212 6328 6304 6365 6506 6571 6472 6712 6730 6579 6847 6700 6802 6617 6586 6765 6683 6844 6741 6840 6770 6545 6550 6460 6439 6443 6324 6132 6213 5984 5805 5678 5672 5255 5276 5176 5136 4902 4964 4952 4773 4750 4943 4779 4746 4847 4820 4702 4769 4697 4645 4719 4917 4758 4725 4679 4745 4670 4648 4697 4762 4791 4701 4788 4746 4699 4747 4609 4721 4694 4834 4726 4761 4806 4733 4734 4749 4755 4644 4768 4567 4681 4671 4801 4812 4815 4738 4704 4678 4781 4607 4677 4825 4786 4825 4805 4831 4795 4728 4832 4688 4832 4744 4815 4610 4658 4559 4722 4690 4733 4482 4597 4765 4770 4680 4752 4715 4711 4738 4615 4750 4765 4710 4641 4672 4651 4692 4810 4727 4596 4752 4705 4772 4703 4720 4780 4744 4796 4664 4645 4827 4693 4817 4748 4662 4620 4697 4791 4791 4705 4682 4913 4724 4764 4684 4685 4726 4703 4877 4728 4725 4742 4714 4734 4608 4741 4829 4801 4778 4749 4705 4856 4806 4697 4841 4927 4722 4879 4828 4720 4800 4846 4699 4650 4827 4797 4952 4698 4825 4758 4831 4799 4820 4786 4759 4904 4886 4877 4967 4870 4885 4825 4851 5016 4880 4816 4789 4768 4747 4992 4943 4977 5037 4763 4984 5035 4884 5088 5201 5261 5504 5575 5803 6002 6137 6565 6897 7234 7511 7698 7902 8387 8282 8493 8753 8766 8896 8905 9093 8965 8902 9119 9260 9332 9633 9678 10030 9917 10132 10683 10839 11369 11130 11745 11765 12056 12369 12935 12893 12917 13337 13448 13457 13794 13685 13927 13815 13775 13884 13665 13231 13477 12836 12820 12162 11793 11498 10972 10463 9806 9165 8547 8029 7682 7127 6728 6398 6234 5895 5722 5468 5392 5223 5331 5253 5087 5103 5147 5185 5115 5074 5080 5301 5111 5157 5027 5080 5106 5179 5125 5153 4921 5037 5187 5134 5165 5063 5054 5080 5066 5062 5159 5049 5109 4977 5083 5177 5143 5126 5062 5274 5304 5198 5028 5129 5241 5246 5092 5210 5093 5220 5354 5158 5197 5262 5163 5189 5310 5143 5258 5292 5207 5138 5118 5243 5294 5183 5086 5295 5347 5283 5242 5224 5084 5194 5238 5151 5207 5272 5265 5141 5090 5172 5145 5143 5141 5166 5206 5224 5336 5239 5160 5242 5368 5270 5174 5341 5443 5051 5362 5184 5169 5254 5302 5174 5268 5339 5195 5342 5152 5202 5343 5245 5309 5392 5281 5367 5382 5301 5445 5419 5362 5465 5388 5361 5630 5608 5546 5630 5578 5470 5440 5583 5562 5599 5570 5646 5584 5650 5569 5729 5578 5662 5595 5651 5592 5754 5882 5798 5675 5799 5849 5817 5675 5696 5748 5651 5673 5732 5841 5740 5805 5674 5456 5774 5542 5630 5813 5576 5578 5555 5719 5700 5637 5534 5514 5500 5613 5433 5464 5478 5537 5599 5566 5477 5474 5478 5525 5415 5671 5553 5574 5416 5442 5441 5439 5422 5437 5428 5549 5386 5463 5610 5451 5358 5233 5274 5489 5413 5476 5559 5476 5488 5609 5493 5376 5362 5468 5489 5337 5449 5364 5489 5370 5313 5540 5473 5323 5230 5384 5347 5432 5483 5452 5380 5408 5242 5290 5461 5341 5255 5107 5301 5369 5465 5498 5384 5325 5204 5189 5370 5305 5413 5248 5468 5208 5190 5152 5422 5301 5215 5227 5334 5292 5112 5265 5183 5253 5207 5140 5211 5270 5196 5138 5009 5023 5246 5221 5282 5089 5221 5112 5190 5240 5316 5318 5143 5228 5147 5074 5004 5085 5254 4966 4946 5254 4992 5135 5094 5078 5119 5161 5176 4965 4922 5001 5095 5071 4902 5019 4999 4992 4953 4876 4882 5045 5093 4862 4946 5005 4828 4937 4870 4930 4810 4869 4837 4968 4980 5084 4941 4900 4854 4876 4691 4758 4979 4875 4847 4908 4876 4847 4898 4788 4796 4734 4969 4808 4833 4963 4766 4832 4897 4868 4803 4860 4900 4883 4946 4813 4779 4784 4775 4841 4910 4913 4971 4833 5013 5144 5319 5257 5389 5540 5500 5710 5855 5717 6030 5988 6156 6213 6419 6504 6825 6823 6949 7113 7126 7238 7416 7384 7314 7674 7672 7604 7786 7837 8000 7751 7824 7822 7658 7865 7704 7656 7701 7493 7735 7567 7709 7743 7680 7500 7546 7660 7414 7479 7348 7116 7094 6820 6796 6574 6414 6288 5990 5892 5653 5607 5558 5230 5162 5048 4905 4819 4718 4654 4581 4537 4410 4547 4645 4594 4448 4471 4466 4476 4510 4529 4531 4458 4598 4459 4368 4487 4563 4297 4373 4565 4369 4352 4326 4399 4449 4365 4457 4388 4418 4363 4334 4406 4433 4470 4391 4398 4240 4319 4392 4332 4219 4307 4417 4464 4335 4415 4247 4284 4322 4366 4187 4410 4317 4321 4274 4258 4248 4311 4352 4282 4354 4346 4279 4437 4232 4115 4228 4249 4177 4272 4252 4179 4221 4173 4322 4164 4212 4152 4333 4320 4134 4137 4282 4228 4252 4197 4112 4140 4162 4181 4207 4191 4110 4244 4317 4213 4199 4137 4269 3985 4040 4088 4275 4140 4283 4178 4101 4138 4175 4164 4073 4103 4047 4211 4175 4121 4132 4208 4093 4137 4002 4045 4136 4154 4045 4089 3957 4079 4051 4100 4123 4080 4042 4067 4106 4162 4070 4103 4154 4130 4127 4112 4082 4178 4061 4106 4108 4084 4145 3995 3855 4023 4166 4075 4041 4060 4008 4080 4019 4018 4056 3970 4024 4140 4099 4072 3967 4065 4073 4113 4038 4165 4140 4138 4091 4084 4041 4060 4014 4064 4215 3999 4157 4121 3995 4164 3934 4113 4149 4030 4027 3903 3975 4013 3964 4077 3969 3953 4020 4036 3983 3890 4056 3979 4016 3979 4162 4067 3908 3987 4065 4064 3980 4153 4004 3921 3993 3989 3918 4071 4001 4057 3975 3927 4010 3942 3919 3925 3905 3901 4026 3908 3945 3927 3938 4001 3882 3937 4028 3964 3916 3912 3881 3938 4177 3905 3828 3875 4078 3968 4009 3936 4012 3980 3840 3880 4020 3871 3912 3971 3851 4094 3923 3969 3966 3924 3973 4071 3871 3917 3900 3945 3937 3918 3833 3870 3891 3997 3978 4016 3926 3792 3961 4034 3914 3967 3977 3793 3854 4011 3892 4026 4038 4085 4279 4160 4230 4562 4531 4707 4773 5049 5133 5239 5374 5434 5647 5857 5785 6003 6147 6141 6140 6103 6181 6407 6425 6479 6677 6820 6949 7221 6974 7420 7431 7713 7797 8159 8105 8375 8401 8486 8590 8874 8814 9007 9253 9015 9302 9147 9138 9028 9106 9197 9124 9169 8824 8774 8232 8237 7818 7527 7351 6937 6663 6216 6058 5720 5518 5235 5034 4790 4470 4388 4333 4325 4159 4097 3887 3946 3998 3951 3845 3913 3840 3900 3984 3982 3925 3914 3816 3841 3878 3899 3916 3994 3689 4000 3898 3837 3774 3781 3883 3854 3876 3790 3854 3774 3837 3785 3861 3781 3834 3802 3884 3791 3775 3783 3782 3836 3958 3704 3910 3847 3793 3734 3891 3884 3756 3816 3658 3968 3830 3803 3838 3792 3737 3628 3666 3821 3702 3805 3736 3850 3699 3695 3624 3768 3834 3861 3665 3728 3875 3675 3684 3853 3749 3814 3763 3896 3606 3700 3706 3662 3743 3800 3737 3840 3711 3788 3808 3791 3781 3796 3759 3802 3980 3900 3818 3968 4017 4004 3873 4042 4038 3990 3936 3899 3902 3992 4064 4128 4162 4081 3971 4004 4097 4126 4173 4109 4082 4021 4054 3981 4097 4062 3966 4017 4151 4170 4162 4220 4118 4013 4066 4091 4131 4174 4074 3951 3926 3953 3853 3871 3979 3946 4013 3838 3985 3979 3719 3737 3508 3585 3822 3718 3652 3902 3555 3697 3695 3571 3686 3706 3746 3628 3654 3718 3699 3520 3673 3635 3599 3633 3585 3583 3817 3455 3653 3683 3649 3778 3664 3616 3700 3760 3606 3626 3701 3713 3673 3640 3733 3712 3698 3571 3732 3636 3526 3706 3701 3680 3689 3744 3593 3641 3641 3686 3719 3720 3609 3571 3663 3853 3590 3813 3631 3759 3684 3642 3665 3549 3696 3700 3564 3700 3623 3702 3533 3670 3731 3733 3655 3656 3703 3536 3731 3600 3634 3594 3696 3814 3732 3705 3741 3604 3720 3709 3657 3649 3470 3694 3703 3616 3591 3773 3562 3738 3701 3571 3766 3609 3654 3552 3725 3790 3625 3832 3681 3709 3647 3568 3652 3677 3652 3786 3635 3821 3700 3645 3623 3657 3643 3691 3687 3558 3807 3688 3615 3647 3795 3670 3702 3715 3658 3796 3727 3747 3774 3709 3683 3856 3693 3788 3764 3788 3827 3785 3718 3677 3637 3697 3557 3778 3643 3631 3787 3687 3715 3663 3795 3778 3639 3692 3726 3604 3743 3610 3799 3602 3741 3585 3608 3706 3839 3605 3685 3582 3705 3746 3776 3715 3702 3631 3857 3661 3741 3645 3767 3842 3748 3816 3721 3677 3709 3828 3588 3811 3622 3642 3719 3732 3679 3701 3787 3859 3677 3809 3679 3741 3815 3806 3812 3744 3607 3766 3703 3696 3788 3808 3847 3882 3776 3699 3787 3831 3801 3720 3688 3854 3622 3790 3808 3716 3734 3822 3702 3734 3767 3668 3777 3821 3828 3780 3634 3879 3823 3732 3906 3798 3821 3917 3782 3782 3945 3721 3806 3832 3753 3757 3756 3781 3906 3850 3775 3766 3810 3806 3695 3809 3846 3741 3814 3810 3766 3698 3667 3927 3908 3740 3807 3818 3792 3887 3738 3917 3928 3879 3817 3932 3917 3843 3668 3894 4017 3930 3907 4012 3811 3830 3869 3886 3867 3924 3757 3879 3732 3966 3922 3868 3997 3969 3869 3931 3876 3791 3835 3826 3911 3918 4027 4019 3897 3852 3861 4092 3940 4101 3989 3968 3987 4048 3960 4156 4083 3978 3975 4065 4246 4264 4292 4326 4512 4739 4863 4892 5288 5324 5690 5925 6098 6353 6504 6782 7035 7333 7320 7605 7667 7768 7985 8216 8242 8247 8245 8445 8439 8348 8502 8804 8803 8572 8660 8749 8639 8682 8572 8786 8674 8678 8841 8784 8779 8746 8633 9108 9015 8817 8603 8780 8656 8639 8364 8410 8148 8018 7647 7408 7102 6837 6611 6385 6056 5858 5713 5404 5004 4995 4739 4545 4507 4386 4288 4331 4314 4357 4220 4236 4145 4297 4223 4160 4084 4211 4146 4131 4292 4238 4282 4289 4255 4212 4182 4092 4213 4236 4118 4189 4223 4127 4148 4186 4238 4171 4088 4198 4257 4280 4273 4105 4138 4179 4316 4251 4208 4135 4360 4184 4170 4191 4239 4253 4235 4300 4221 4394 4216 4302 4197 4187 4179 4224 4359 4303 4398 4366 4424 4262 4267 4301 4314 4400 4418 4399 4417 4380 4314 4297 4532 4476 4373 4432 4402 4402 4313 4368 4416 4434 4416 4450 4380 4401 4394 4259 4403 4490 4431 4451 4567 4534 4399 4426 4563 4466 4374 4396 4477 4511 4461 4502 4565 4457 4711 4503 4532 4391 4596 4562 4598 4619 4625 4584 4566 4546 4590 4555 4627 4437 4502 4586 4586 4681 4685 4870 4581 4741 4722 4696 4645 4564 4601 4584 4677 4573 4783 4572 4666 4763 4848 4641 4686 4677 4777 4715 4646 4695 4843 4730 4835 4780 4803 4734 4698 4820 4812 4711 4736 4857 5010 4841 4927 4808 4873 4915 4960 4864 4803 4984 4918 4897 5021 4835 4887 5021 4909 4957 4988 4855 4889 4897 4832 5151 4964 4958 4972 5029 4967 4990 5001 5062 4906 4997 4984 5056 5033 5047 4960 5053 5029 5190 5006 4982 5060 5134 5124 5140 5097 5035 5109 5108 4975 5272 5280 5192 5167 5197 5313 5185 5180 5260 5135 5177 5191 5231 5224 5330 5171 5345 5283 5311 5198 5301 5270 5273 5398 5283 5219 5353 5253 5247 5189 5372 5300 5219 5321 5374 5340 5405 5475 5399 5299 5212 5307 5318 5253 5391 5359 5226 5328 5375 5471 5536 5377 5480 5489 5332 5422 5417 5357 5425 5483 5451 5483 5494 5465 5473 5371 5324 5351 5440 5396 5272 5359 5457 5468 5457 5429 5314 5522 5534 5376 5414 5464 5459 5354 5477 5506 5451 5456 5341 5385 5503 5547 5559 5493 5577 5417 5591 5428 5410 5367 5392 5360 5461 5487 5441 5443 5409 5416 5378 5375 5435 5380 5294 5378 5359 5349 5293 5382 5195 5291 5273 5388 5395 5323 5284 5347 5396 5452 5333 5315 5244 5388 5331 5393 5327 5346 5249 5298 5434 5329 5376 5470 5314 5463 5311 5354 5203 5344 5376 5258 5174 5191 5326 5326 5163 5394 5279 5252 5386 5223 5403 5377 5340 5286 5263 5293 5092 5369 5233 5163 5250 5220 5279 5156 5348 5350 5175 5148 5282 5292 5135 5333 5148 5328 5132 5137 5174 5128 5130 5242 5160 5139 5228 5206 5092 5188 5079 5199 5095 5094 4986 5122 5205 5188 5062 5134 5121 5020 4989 5065 5157 5008 5020 5099 5057 5020 5273 4947 5104 5140 4829 5134 4970 5153 5157 4968 5128 5147 5138 5108 5049 5127 5057 5076 5068 5066 4906 4865 5009 5082 5014 4942 4937 4996 5097 4958 4877 4960 5100 5032 4935 5007 4908 4920 4948 4944 4963 5016 4944 4836 4939 4883 4960 5007 4998 4769 4955 4940 4885 5064 4876 4914 4772 4860 4824 4793 4822 4789 4889 4931 4939 4778 4851 5036 4773 4882 4999 4925 4737 4879 4803 5022 4815 4694 4969 4905 4983 4873 4708 4929 4849 4807 4829 4766 4789 4985 4875 4696 4917 4859 4834 5029 4927 5091 5019 4939 4963 5020 4989 5078 5161 5299 5261 5197 5189 5338 5300 5404 5340 5390 5319 5326 5483 5315 5416 5396 5560 5374 5505 5560 5725 5696 5655 5641 5645 5598 5597 5619 5939 5903 5845 5820 5814 5731 5815 5775 5860 5699 5847 5710 5677 5650 5644 5644 5500 5494 5356 5415 5180 5088 5097 4973 5021 4817 4962 4570 4740 4760 4617 4753 4636 4747 4585 4748 4602 4643 4785 4641 4640 4710 4686 4594 4630 4574 4724 4557 4581 4597 4699 4700 4678 4501 4470 4587 4532 4685 4663 4547 4606 4534 4475 4559 4670 4522 4596 4469 4691 4561 4657 4481 4502 4516 4652 4420 4376 4488 4647 4504 4358 4518 4493 4435 4439 4420 4430 4539 4414 4395 4470 4568 4450 4548 4459 4439 4413 4200 4383 4382 4569 4324 4493 4446 4488 4429 4547 4357 4481 4383 4410 4361 4371 4489 4329 4398 4449 4576 4382 4437 4477 4478 4473 4498 4531 4418 4496 4542 4461 4359 4474 4460 4501 4519 4593 4600 4502 4641 4385 4524 4516 4545 4576 4495 4353 4564 4457 4511 4488 4420 4520 4371 4537 4457 4461 4499 4559 4429 4578 4388 4415 4475 4446 4527 4383 4560 4405 4250 4398 4226 4496 4358 4156 4321 4273 4189 4278 4257 4267 4276 4100 4130 4198 4099 4072 4099 4062 4001 4246 4111 4254 4065 4235 4269 4158 4308 4072 4027 4189 4198 3946 4154 4046 4136 4142 4107 4214 4107 4204 4112 4130 4078 4059 4100 4205 4008 4062 4081 4126 4117 4061 3997 4018 4064 4156 3980 4081 4280 4089 4096 3973 4032 3983 3939 4170 3932 4069 4101 3970 3927 3978 4105 4085 4017 3967 3924 3984 3991 4053 3928 3936 3990 4006 3991 3983 3965 4071 3997 3936 4096 4048 4065 4018 4014 3986 3957 4033 3953 3993 3896 3946 4000 3869 3991 3966 3904 3852 3789 3759 3959 3890 4082 4044 3997 3944 4053 3944 3886 4105 3915 3845 3928 3976 3948 4006 3874 4053 3798 3980 3832 3971 4051 3734 3891 3952 3933 3907 3928 3914 4049 3998 3855 4011 4022 3834 3955 3846 3954 4014 3894 3937 4024 3923 4000 3819 3951 4009 4007 4077 3923 3949 3949 3899 4152 3889 4007 3874 3981 4011 4078 4040 4079 4096 3954 3994 4113 4224 4000 4123 4173 4128 4313 4061 4113 4202 4411 4304 4358 4334 4349 4336 4659 4728 5072 5550 6092 6621 7277 7847 8605 9325 10240 11240 12214 13163 14168 14849 15741 16685 17277 18008 18942 19689 19857 19937 20248 20818 20650 20785 21217 21431 21356 21590 21622 21506 21569 21679 21791 21834 22203 22163 22118 21791 22046 21908 22108 22250 22095 22588 22549 22667 22392 22254 22243 21499 21382 20408 19761 18713 18175 17069 16278 15021 14171 12805 11982 11167 10030 9128 8199 7270 6545 6049 5235 5153 4878 4600 4552 4368 4391 4228 4343 4351 4163 4328 4296 4121 4171 3964 4141 4085 4081 4145 4039 4067 3933 4019 3978 3957 3825 3980 4007 3793 4002 3866 4051 3935 3816 3957 3927 4082 3914 3912 3960 3809 3863 3811 3965 4015 3863 3845 3853 3809 3829 3901 3898 3880 3736 3878 3984 3855 3771 3982 3948 3855 3663 3922 3788 3778 3741 3875 3806 3823 3868 3757 3602 3756 3735 3798 3767 3930 3781 3825 3817 3877 3737 3770 3824 3805 3868 3790 3828 3817 3698 3838 3839 3807 3826 3868 3771 3864 3753 3735 3773 3831 3718 3819 3803 3935 3675 3874 3787 3727 3844 3807 3680 3814 3864 3796 3800 3753 3673 3726 3769 3807 3778 3801 3935 3802 3833 3718 3823 3832 3761 3866 3787 3721 3736 3702 3680 3621 3793 3820 3860 3811 3891 3754 3872 3900 3702 3831 3788 3909 3929 3736 3752 3729 3756 3907 3663 3803 3825 3752 3672 3652 3741 3781 3705 3736 3748 3843 3656 3745 3774 3746 3776 3768 3809 3714 3825 3856 3717 3671 3714 3819 3788 3795 3723 3790 3682 3729 3646 3875 3634 3731 3860 3893 3882 3839 3643 3732 3818 3713 3730 3709 3773 3846 3732 3715 3826 3794 3814 3765 3718 3889 3822 3818 3873 3929 3798 3858 3772 3729 3885 3801 3785 3887 3784 3876 3826 3832 3842 3944 4061 4028 4095 4068 4017 3961 4043 4042 4018 4078 4056 4278 4217 4152 4149 4123 4231 4202 4124 4173 4174 4256 4205 4423 4251 4304 4310 4378 4385 4428 4288 4288 4403 4281 4250 4351 4339 4338 4356 4169 4337 4224 4287 4189 4134 4153 4233 4113 4130 4061 4021 4062 3928 3935 3822 4020 3889 3829 3824 3674 3744 3776 3775 3713 3838 3729 3876 3724 3789 3730 3877 3769 3789 3652 3783 3698 3775 3733 3793 3651 3747 3762 3836 3907 3681 3706 3577 3669 3893 3830 3669 3759 3744 3704 3643 3788 3735 3772 3694 3754 3751 3704 3802 3817 3604 3797 3722 3713 3898 3576 3752 3595 3703 3607 3731 3680 3801 3733 3661 3799 3809 3680 3675 3660 3750 3568 3644 3605 3733 3669 3655 3809 3736 3851 3654 3655 3613 3732 3753 3638 3763 3770 3834 3598 3763 3611 3842 3786 3750 3799 3610 3663 3752 3745 3791 3661 3810 3851 3813 3621 3748 3735 3765 3693 3739 3688 3732 3727 3724 3612 3803 3694 3822 3754 3716 3645 3895 3591 3734 3745 3660 3707 3749 3704 3771 3724 3758 3644 3757 3739 3741 3642 3776 3536 3873 3709 3820 3723 3716 3641 3784 3780 3751 3627 3811 3690 3805 3736 3706 3671 3843 3766 3818 3756 3682 3696 3777 3831 3901 3829 3772 3887 3735 3813 3737 3870 3817 3610 3926 3757 3749 3972 3639 3878 3759 3875 3994 3869 4057 4098 3852 4001 4050 3948 3990 4150 4141 4256 4113 4206 4223 4341 4283 4220 4342 4199 4160 4125 4112 4125 4092 4194 4210 4067 4035 4042 4067 4085 3991 3801 3940 3946 3872 3858 3988 3869 3797 3910 3842 3963 3767 3919 3881 3913 4059 4068 3990 3892 4142 3931 4060 4096 3929 3926 3872 3796 3743 3797 3832 3756 3720 3841 3773 3807 3794 3726 3790 3747 3805 3682 3707 3801 3849 3850 3793 3783 3777 3777 3880 3862 3881 3816 3645 3793 3802 3793 3762 3788 3786 3696 3819 3923 3880 3708 3857 3912 3814 3764 3813 3770 3709 3789 3870 3771 3747 3890 3808 3787 3851 3812 3702 3926 3751 3892 3790 3854 3796 3806 3868 3663 3822 3868 3823 3855 3975 3677 3773 3657 3748 3905 3731 3925 3879 3828 3820 3738 3751 3737 3861 3852 3925 3821 3898 3830 3865 4040 3831 3666 3931 4003 3832 3872 3991 3912 3995 3783 3965 3871 3981 3943 3951 3938 3900 4051 3929 3974 3966 4028 4116 4060 3960 3874 3919 4038 4015 3965 3892 3929 4028 3968 3908 3981 3967 3884 3999 4113 3961 4120 3919 3938 3977 4023 3930 4033 3853 4040 3861 3914 3862 3811 3911 3880 3863 3970 3780 3979 3903 3951 3805 3887 3918 3960 3986 3913 3853 3923 3935 3890 4014 3843 3815 3821 4001 3851 3902 3962 3911 3915 3989 3983 3922 3959 4005 3849 4010 3842 3920 3926 3908 3929 3945 4046 3955 3878 3875 4038 4049 3993 3993 4102 4042 3942 4095 3903 3890 4033 3943 3929 4014 3898 4120 3900 3946 4103 4026 4043 4046 4087 3884 4094 3983 4059 3985 4021 3975 4064 4051 4106 4050 4070 4000 4033 4019 4071 4193 4124 4133 4032 4158 4024 3921 3917 4093 4152 4126 4119 4043 4058 4103 4006 4070 4145 4184 4193 4105 4085 4116 3924 4160 4086 4146 4150 4179 4096 4103 4174 3973 4125 4271 4139 4258 4110 4134 4178 4242 4228 4062 4094 4246 4249 4130 4062 4174 4067 4000 4197 4106 4181 4104 4067 3933 4053 4195 4059 4221 4082 4082 4124 4066 4028 3950 4051 4088 4154 4101 4152 4204 4147 4059 4164 4164 4159 4141 4173 4022 4257 4183 4019 4048 4268 4100 4144 4177 4287 4124 4246 4210 4181 4201 4344 4127 4119 4097 4115 4120 4243 4268 4297 4310 4276 4266 4236 4201 4258 4246 4235 4266 4328 4251 4194 4264 4140 4314 4209 4185 4270 4191 4157 4210 4251 4331 4328 4417 4209 4196 4206 4307 4289 4332 4277 4254 4308 4364 4245 4260 4346 4269 4216 4190 4289 4356 4339 4277 4244 4290 4244 4294 4349 4305 4348 4243 4335 4302 4237 4296 4276 4328 4263 4248 4186 4261 4335 4290 4250 4297 4266 4351 4263 4170 4207 4294 4386 4379 4387 4337 4527 4327 4376 4433 4514 4452 4472 4531 4648 4555 4506 4563 4700 4595 4636 4746 4700 4765 4720 4759 4696 4797 4800 4848 4739 4955 4957 4847 4908 4990 4962 4977 4916 5039 4950 4920 5058 4945 4939 5115 5064 5052 5086 5214 5015 5106 5125 4963 5003 4971 5093 4983 4789 4938 4940 4923 4712 4814 4895 4714 4631 4473 4552 4626 4476 4476 4535 4634 4401 4484 4581 4357 4476 4474 4469 4471 4462 4511 4519 4422 4612 4488 4441 4596 4480 4518 4425 4460 4459 4383 4487 4614 4503 4423 4623 4443 4395 4436 4468 4508 4624 4367 4560 4408 4552 4516 4556 4486 4483 4711 4497 4378 4546 4574 4418 4557 4471 4480 4592 4536 4500 4512 4518 4533 4526 4618 4403 4585 4579 4439 4501 4474 4609 4590 4672 4662 4503 4526 4507 4556 4631 4688 4880 4639 4682 4694 4664 4780 4912 5105 4904 5027 4966 5110 5134 5085 5114 5120 5146 5222 5138 5167 5264 5408 5281 5444 5289 5201 5284 5392 5316 5434 5263 5324 5411 5484 5371 5381 5430 5517 5708 5632 5443 5676 5626 5595 5594 5580 5597 5484 5436 5486 5559 5396 5355 5250 5273 5070 5172 5148 5058 4938 4915 4908 4783 4892 4794 4907 4644 4900 4903 4770 4862 4849 4757 4818 4619 4766 4889 4816 4720 4780 4679 4742 4800 4645 4782 4949 4669 4758 4763 4826 4784 4776 4728 4682 4813 4879 4894 4990 4787 4814 4867 4862 4905 4928 4704 4914 4911 4895 4819 4849 4865 4889 4864 4850 4938 5011 5110 5033 5044 5004 5010 5074 5010 5173 5172 5117 4946 5050 5162 4926 5097 5054 5199 5075 5003 5137 5035 5204 4943 5241 4959 5093 5239 5160 5207 5052 5186 4988 5140 5092 5216 4955 5141 5191 5069 5148 5144 5094 5053 5053 4974 5024 5096 4984 5133 4800 4948 4985 5024 5053 5032 4970 4964 4899 5050 5086 5024 5085 4953 4891 4960 4940 5042 4862 5039 4970 5002 4764 5107 5091 5043 4995 5135 4909 4921 5051 4931 5132 4924 5005 5177 5075 5049 5018 5025 4983 5191 4989 4973 5180 4932 5022 5056 4961 5122 4933 5172 5196 5097 5190 4971 5141 5068 4970 5087 5092 5250 5079 5073 5076 4999 5195 5071 5099 5217 5088 5258 5196 5140 5040 5062 5092</counts>
			</dataPoints>
		</scan>
	</xrdMeasurement>
</xrdMeasurements>