File: Data Files/Full/MSS p (24-136, 25w)_01_1D.xrdml
<?xml version="1.0"?>
<xrdMeasurements xmlns="http://www.xrdml.com/XRDMeasurement/2.2" xmlns:xsi="http://www.w3.org/2001/XMLSchema-instance" xsi:schemaLocation="http://www.xrdml.com/XRDMeasurement/2.2 http://www.xrdml.com/XRDMeasurement/2.2/XRDMeasurement.xsd" status="Completed" recordIdentifier="{B1AC4E91-1796-495A-8FDC-B416CFC29C16}">
	<comment>
		<entry/>
	</comment>
	<sample type="To be analyzed">
		<id>p</id>
		<name></name>
		<preparedBy></preparedBy>
	</sample>
	<xrdMeasurement measurementType="Scan" status="Completed" sampleMode="Reflection">
		<usedWavelength intended="K-Alpha 1">
			<kAlpha1 unit="Angstrom">1.5405980</kAlpha1>
			<kAlpha2 unit="Angstrom">1.5444260</kAlpha2>
			<kBeta unit="Angstrom">1.3922500</kBeta>
			<ratioKAlpha2KAlpha1>0.5000</ratioKAlpha2KAlpha1>
		</usedWavelength>
		<incidentBeamPath>
			<radius unit="mm">145.00</radius>
			<xRayTube id="1010048" name="Empyrean Cu LFF HR (9430 033 7310x) DK437964">
				<tension unit="kV">40.0</tension>
				<current unit="mA">15.0</current>
				<anodeMaterial>Cu</anodeMaterial>
				<focus type="Line">
					<length unit="mm">12.0</length>
					<width unit="mm">0.4</width>
					<takeOffAngle unit="deg">6.0</takeOffAngle>
				</focus>
			</xRayTube>
			<filter id="20010004" name="Beta-filter Nickel">
				<material>Ni</material>
				<thickness unit="mm">0.020</thickness>
			</filter>
			<sollerSlit id="21010002" name="Soller slits 0.04 rad.">
				<opening unit="rad">0.0400</opening>
			</sollerSlit>
			<mask id="22031000" name="Fixed mask 13 mm">
				<width unit="mm">9.00</width>
			</mask>
			<divergenceSlit id="22120001" name="Divergence slit 1°" xsi:type="fixedDivergenceSlitType">
				<distanceToSample unit="mm">50.00</distanceToSample>
				<height unit="mm">1.52</height>
			</divergenceSlit>
		</incidentBeamPath>
		<diffractedBeamPath>
			<radius unit="mm">145.00</radius>
			<antiScatterSlit id="22090040" name="AS slit 9 mm" xsi:type="fixedAntiScatterSlitType">
				<height unit="mm">9.00</height>
			</antiScatterSlit>
			<detector id="7010020" name="PIXcel3D-Medipix3 1x1 detector" xsi:type="areaDetectorType">
				<phd unit="keV">
					<lowerLevel>4.0</lowerLevel>
					<upperLevel>11.3</upperLevel>
				</phd>
				<mode>Scanning</mode>
				<activeChannelsEquatorial>255</activeChannelsEquatorial>
				<activeChannelsAxial>255</activeChannelsAxial>
				<pitchEquatorial unit="mm">0.05500</pitchEquatorial>
				<pitchAxial unit="mm">0.05500</pitchAxial>
				<readOutPeriod unit="seconds">0.015</readOutPeriod>
			</detector>
		</diffractedBeamPath>
		<scan appendNumber="0" mode="Continuous" scanAxis="2Theta" status="Completed">
			<header>
				<startTimeStamp>2025-07-01T08:39:37-08:00</startTimeStamp>
				<endTimeStamp>2025-07-01T08:50:30-08:00</endTimeStamp>
				<author>
					<name>Instrument</name>
				</author>
				<source>
					<applicationSoftware version="1.6 (94)">PANalytical Aeris Instrument Suite</applicationSoftware>
					<instrumentControlSoftware version="3.0.0 20211014">AERIS</instrumentControlSoftware>
					<instrumentID>2855484</instrumentID>
				</source>
			</header>
			<dataPoints>
				<positions axis="2Theta" unit="deg">
					<startPosition>23.77235831</startPosition>
					<endPosition>135.99823401</endPosition>
				</positions>
				<positions axis="Omega" unit="deg">
					<commonPosition>25.000</commonPosition>
				</positions>
				<commonCountingTime unit="seconds">2.295</commonCountingTime>
				<counts 72 77 75 83 85 65 95 71 68 92 101 85 94 90 63 84 96 76 89 76 85 79 85 89 79 83 68 82 73 88 87 76 70 68 93 77 80 72 68 86 78 69 83 63 71 71 77 79 86 65 86 68 78 72 56 90 71 72 78 67 78 83 86 81 76 73 79 77 92 70 59 85 80 71 81 77 88 68 81 71 60 76 93 78 83 83 66 62 58 65 70 70 80 76 63 91 86 81 76 82 74 73 56 57 74 88 75 76 84 72 84 92 86 94 66 81 81 99 84 80 85 81 81 82 93 79 108 98 95 85 112 86 93 97 108 95 117 86 119 122 115 100 115 99 99 108 91 109 114 122 114 113 99 93 96 118 108 144 128 99 124 109 116 131 103 129 115 111 125 89 123 114 126 126 145 108 130 112 123 131 128 122 135 131 114 112 123 126 118 147 122 116 120 112 104 132 111 115 131 128 114 124 114 132 137 124 127 121 126 130 131 113 154 137 116 126 128 141 131 135 147 129 147 115 151 141 125 132 137 129 136 141 121 125 133 134 136 132 124 133 117 145 133 134 141 131 129 138 122 142 129 122 151 127 143 155 139 144 135 137 144 174 116 153 147 148 139 125 155 154 156 154 141 127 155 113 153 150 138 137 132 127 142 135 140 130 142 148 148 124 154 147 138 156 142 136 138 154 146 153 144 143 145 155 153 147 150 151 166 135 141 159 145 170 139 132 153 160 155 134 144 180 146 140 167 160 147 155 145 161 154 174 173 168 157 151 150 169 156 161 180 172 142 179 173 149 154 159 153 174 137 183 158 191 174 159 159 122 174 154 183 139 144 134 123 141 179 129 155 169 137 127 137 144 128 153 114 132 121 125 148 150 128 138 138 135 133 151 132 130 117 101 122 141 137 146 146 143 145 130 143 140 122 123 123 130 137 129 138 142 134 122 118 133 147 141 132 132 140 134 134 125 116 136 131 165 162 150 128 124 112 128 157 132 151 120 147 134 108 136 141 136 149 139 128 110 120 137 117 147 135 143 110 136 124 116 114 123 136 137 127 129 101 125 113 129 141 123 139 143 110 124 135 135 109 117 131 126 117 108 137 127 136 141 130 116 142 111 124 129 134 125 117 137 138 141 143 134 139 128 148 122 129 125 144 130 139 117 136 118 141 125 115 121 143 137 122 144 121 158 125 118 103 117 134 146 109 107 110 125 128 131 109 123 168 117 122 106 137 119 141 130 96 112 114 123 133 115 152 123 128 109 120 117 111 109 111 127 131 128 132 118 115 115 104 123 116 131 120 133 134 118 126 118 147 111 134 131 149 121 119 131 125 149 126 120 138 118 120 102 118 124 106 126 120 111 141 141 127 132 124 124 124 156 117 127 115 122 120 112 117 116 89 114 109 120 134 140 132 118 108 123 138 128 121 134 117 118 110 116 136 121 125 137 108 133 115 113 113 122 124 105 125 130 120 115 119 111 119 115 148 119 133 116 119 113 120 137 120 125 129 129 126 124 118 109 130 129 134 118 124 122 106 123 125 110 143 131 143 112 112 119 109 111 128 125 108 120 110 112 128 122 124 134 121 102 105 122 124 109 105 117 140 116 137 116 140 139 128 124 134 126 104 114 132 111 125 113 150 108 104 115 115 117 104 132 130 114 119 124 132 99 148 110 144 121 118 110 143 120 113 132 121 127 121 116 129 125 124 108 139 118 121 96 118 138 116 103 105 124 124 114 134 130 99 136 132 145 111 120 125 140 128 132 118 119 119 119 128 123 123 126 128 123 133 130 109 116 128 121 120 112 116 115 124 134 117 141 122 110 122 106 137 127 133 115 126 114 134 111 114 119 113 123 107 136 126 117 125 97 118 122 119 109 123 137 114 129 107 152 143 110 122 129 124 116 125 110 111 104 121 107 121 121 130 132 125 124 130 116 115 113 112 110 117 123 121 117 120 115 124 119 107 109 128 112 104 89 138 99 115 119 106 102 113 124 126 129 118 120 113 127 128 112 104 122 116 122 129 138 133 116 103 115 112 127 95 133 127 116 106 132 108 112 122 119 99 118 116 93 103 113 127 115 120 108 115 107 106 98 106 99 132 123 106 103 109 125 144 111 122 122 104 115 128 106 109 120 117 132 123 130 110 118 139 116 106 106 118 121 120 114 112 113 118 115 114 89 118 118 96 124 120 114 108 90 116 102 102 124 95 132 116 131 99 108 122 113 125 122 109 129 117 101 118 100 103 123 125 105 120 116 115 105 106 106 101 94 131 116 105 108 132 113 107 135 121 120 117 102 109 111 108 106 97 117 89 124 107 135 105 108 120 109 110 131 112 107 114 115 122 113 97 106 92 102 109 123 100 131 93 109 142 106 118 126 106 113 133 112 101 148 114 110 121 127 127 125 106 116 118 134 112 115 122 144 112 106 123 116 114 114 95 115 127 107 99 105 114 126 108 124 121 126 111 118 113 111 159 103 116 122 113 109 106 134 118 127 103 119 113 112 121 121 102 117 111 117 119 116 126 133 100 115 127 98 120 118 108 137 101 120 98 113 112 118 122 112 106 101 127 126 118 126 114 101 119 137 122 115 113 110 111 130 110 104 106 100 108 117 121 108 89 113 111 122 102 92 116 117 98 123 115 111 95 124 106 123 99 118 99 139 124 130 125 128 111 107 118 107 104 126 109 99 96 104 107 110 114 108 109 106 115 114 128 115 120 111 112 109 121 115 122 113 111 112 100 107 93 117 129 124 118 123 118 116 86 123 94 104 110 123 118 119 105 110 113 125 119 120 113 103 111 123 125 125 130 118 120 113 110 116 131 109 105 106 98 137 93 130 142 131 109 115 105 125 109 107 109 108 124 116 112 130 120 119 110 123 105 121 120 131 119 123 101 120 112 95 115 113 124 123 114 94 106 108 98 102 93 104 110 105 125 104 107 124 138 118 108 128 105 121 104 123 95 109 113 111 139 111 102 108 117 92 106 113 113 122 106 110 84 117 106 127 117 110 108 103 98 108 108 103 111 107 107 99 132 113 119 112 109 98 121 95 111 111 111 98 116 115 114 111 128 123 128 114 97 106 100 113 87 113 106 95 105 108 107 110 113 94 105 105 102 99 115 125 110 119 102 114 125 131 146 107 115 106 117 113 103 96 93 98 104 102 120 106 118 110 91 95 115 116 102 102 107 113 121 120 106 112 116 96 117 103 107 116 98 117 109 115 128 103 107 126 121 124 116 112 122 139 113 104 112 89 134 86 122 112 117 111 126 125 113 117 92 90 117 109 126 120 114 114 104 100 121 130 118 117 106 104 102 115 98 87 127 118 120 124 107 113 107 110 92 113 117 110 110 123 92 105 95 112 105 115 128 116 107 107 118 101 111 121 107 101 112 122 111 117 131 110 104 102 123 105 107 120 115 110 97 108 104 109 91 97 120 102 98 94 110 127 104 99 114 117 92 108 101 116 100 97 113 106 116 99 121 106 99 104 102 104 109 126 97 104 117 96 101 116 107 103 109 108 119 97 98 96 98 114 119 99 101 106 107 118 115 109 118 105 107 98 95 99 129 119 122 112 113 109 88 99 139 109 115 104 110 119 114 89 119 103 92 108 109 113 110 99 102 127 118 107 95 106 95 111 125 121 121 91 119 101 111 92 109 109 103 120 115 117 100 104 97 109 110 111 105 116 95 103 96 121 113 112 104 95 119 118 135 111 106 112 109 92 99 115 119 116 100 103 110 117 106 118 119 117 90 112 120 111 111 108 115 113 118 110 102 94 114 101 94 107 114 110 120 106 102 113 106 107 122 113 109 90 97 116 103 115 127 106 104 97 117 104 111 112 114 104 116 101 123 99 101 107 107 114 99 107 109 120 108 116 109 121 109 116 109 116 118 107 132 112 110 119 109 96 113 102 123 113 99 103 105 101 118 114 128 94 107 123 92 115 102 118 98 109 112 128 126 104 123 86 108 122 110 118 114 98 113 101 122 129 102 110 105 124 118 112 111 107 111 118 88 120 112 121 100 125 119 117 117 129 131 99 104 108 111 121 113 116 118 119 100 100 96 99 116 99 116 108 97 104 104 110 103 93 101 101 133 116 119 99 98 107 104 110 111 117 98 127 131 123 113 106 92 95 107 126 103 105 94 92 111 105 109 109 95 110 117 102 109 109 100 128 105 117 129 91 109 113 117 96 116 100 99 109 134 111 115 106 134 97 110 109 113 112 114 144 107 109 105 111 108 107 100 86 89 115 95 106 108 104 111 90 127 125 107 102 98 112 88 109 115 135 111 106 121 114 97 101 139 128 114 127 124 115 111 97 89 101 101 119 112 101 95 108 108 122 118 93 110 101 108 122 109 107 114 100 107 103 108 104 97 127 101 114 95 112 100 104 115 99 96 115 98 136 106 120 98 112 131 99 105 112 115 101 119 110 94 105 99 113 107 110 108 98 114 105 110 108 131 106 94 112 107 109 118 123 114 113 94 99 107 102 128 106 92 98 106 106 105 94 121 111 109 102 108 107 109 109 113 112 118 105 95 120 94 100 127 111 124 100 107 112 114 108 112 106 94 121 106 111 106 101 135 104 105 108 118 101 112 123 107 107 102 91 114 108 88 130 110 99 99 117 115 105 110 127 128 87 108 111 137 113 103 105 116 139 111 122 120 118 99 122 117 125 101 96 110 101 115 115 105 139 104 100 103 103 120 108 107 117 112 115 120 115 102 145 113 89 114 145 124 105 109 105 119 121 132 133 92 105 109 95 105 116 116 103 134 119 111 122 111 100 134 91 131 106 115 117 110 135 112 108 99 106 121 103 112 133 107 111 115 106 92 100 130 124 111 102 119 103 94 128 116 103 115 112 110 99 111 101 141 89 106 112 119 107 103 108 109 105 105 88 113 89 104 108 113 94 108 102 107 100 127 120 108 96 107 97 102 97 107 123 111 112 102 125 108 112 121 119 116 114 104 109 111 116 108 107 107 121 87 91 109 112 124 106 112 133 124 110 112 109 94 112 120 110 109 113 122 123 125 125 126 107 92 114 108 116 115 113 113 100 94 106 124 124 104 114 124 116 115 114 117 108 113 98 100 107 110 104 117 112 124 134 116 126 109 114 112 101 114 103 110 109 110 105 112 113 106 96 111 92 124 106 102 132 115 144 112 126 107 104 125 121 113 125 114 108 119 112 127 106 118 119 127 111 121 121 122 130 92 111 128 119 117 104 122 132 135 111 113 115 127 130 128 145 126 122 142 147 141 149 171 149 182 172 172 165 186 187 164 182 186 186 184 174 144 169 164 190 183 192 189 210 204 180 202 190 191 210 208 218 197 233 214 221 224 257 187 159 230 199 217 196 274 206 212 230 213 206 219 211 246 220 262 240 239 245 232 231 263 266 248 227 240 227 266 238 244 283 245 263 262 258 248 261 286 247 239 261 257 245 225 264 246 240 222 247 263 243 265 235 272 263 249 248 241 251 286 242 267 290 257 250 262 300 236 294 290 273 248 256 271 267 302 267 292 262 277 303 269 286 241 287 261 282 291 296 296 277 279 272 275 294 289 289 280 239 307 277 291 245 281 278 273 291 272 256 260 286 241 296 291 297 280 276 257 248 276 266 287 269 282 298 285 229 279 262 262 263 300 291 261 240 244 233 229 204 230 212 249 228 206 188 183 159 168 171 135 130 119 134 97 118 125 124 111 128 107 103 110 121 129 129 106 123 132 121 90 110 108 118 127 121 102 101 94 106 107 114 105 110 96 125 104 116 101 92 116 98 114 103 140 109 120 114 127 117 100 115 118 106 97 112 105 105 120 112 113 119 97 96 117 129 100 108 107 121 103 99 114 120 116 97 112 100 104 121 107 118 109 97 99 119 111 82 115 107 108 119 124 101 107 100 105 109 101 110 106 103 101 93 92 123 98 118 108 112 120 123 98 117 108 108 134 105 111 112 104 135 109 105 104 110 115 90 100 93 99 107 117 106 119 125 100 129 121 117 108 114 101 112 118 120 102 109 122 116 122 100 110 106 111 112 110 94 131 118 118 132 120 113 109 117 111 111 92 120 91 98 133 104 121 85 125 111 118 106 91 110 128 118 116 90 115 97 99 112 94 94 111 125 100 111 117 95 113 104 89 121 117 108 118 102 92 106 104 113 100 115 122 90 119 117 104 93 96 104 94 99 114 83 115 114 111 92 100 107 121 99 116 102 110 122 98 104 120 106 111 98 132 110 109 138 90 113 109 116 107 110 104 117 122 93 118 107 107 83 95 97 106 106 93 90 108 105 114 92 90 114 119 117 105 114 103 111 107 104 110 106 90 110 102 105 104 104 113 108 88 102 81 81 95 89 117 111 115 97 118 95 98 98 91 83 93 108 104 122 107 106 110 111 117 106 109 116 105 121 119 105 103 108 101 118 126 102 116 103 107 115 106 121 101 116 111 108 112 99 108 102 104 105 106 91 132 100 95 105 103 112 119 117 106 111 93 123 122 128 98 108 116 108 122 102 93 89 118 123 105 113 122 99 104 101 109 96 99 112 104 128 98 106 96 106 98 105 106 120 96 132 94 110 93 102 119 107 118 100 97 114 111 124 91 116 98 102 104 104 111 96 111 107 99 107 115 114 118 104 114 95 111 100 106 107 115 109 99 100 98 102 96 103 107 106 116 109 88 120 117 109 101 108 105 103 122 112 106 110 124 105 127 127 106 112 124 104 96 107 117 116 110 95 101 91 104 118 111 131 112 119 94 97 104 121 106 124 126 115 96 105 102 107 122 108 108 113 120 122 132 86 100 90 105 101 116 131 125 107 108 85 104 92 115 113 102 93 107 103 117 97 122 95 101 105 106 114 107 113 107 116 116 122 108 123 106 120 114 140 112 122 119 102 107 95 115 109 103 123 95 109 104 89 99 115 125 124 129 102 102 111 108 99 104 107 122 109 106 119 107 122 99 103 123 106 116 117 104 118 123 122 96 108 108 110 112 111 136 117 99 114 139 99 116 114 99 114 117 114 96 102 107 94 121 113 120 118 97 104 106 92 105 129 103 85 90 121 115 119 85 113 129 104 130 106 95 108 116 113 116 109 123 117 100 100 116 112 111 131 122 97 119 100 99 130 97 95 96 102 143 94 131 129 99 115 122 114 122 101 119 131 115 101 113 96 117 111 118 118 126 107 94 107 108 117 109 118 117 107 102 118 114 118 128 112 139 113 115 99 108 143 123 120 118 114 104 93 115 102 126 112 110 113 109 117 100 103 105 110 103 124 115 110 117 86 106 120 126 126 102 124 120 118 94 120 94 132 128 119 115 128 124 106 111 140 125 109 104 114 124 123 106 109 115 126 112 112 100 123 114 111 127 110 106 117 138 110 99 96 113 109 114 97 109 121 133 123 94 119 104 117 110 125 115 123 132 126 115 105 133 128 107 121 119 133 105 121 115 119 116 104 119 123 119 123 117 116 119 105 124 99 126 143 115 122 124 118 122 120 110 110 100 127 115 103 132 110 132 101 136 99 126 108 126 129 144 108 122 114 125 126 111 112 114 132 116 119 133 117 133 82 124 112 121 117 121 102 117 109 131 111 115 107 121 126 124 112 120 122 128 105 135 144 124 114 144 97 116 122 105 125 115 118 119 132 130 121 120 117 105 127 109 136 101 90 108 112 114 148 129 135 123 115 116 122 117 127 138 142 114 133 112 125 107 116 107 128 116 114 100 118 130 124 114 145 133 124 127 125 111 141 127 124 111 111 154 125 136 108 122 135 140 137 136 123 134 139 127 114 115 142 112 136 120 125 112 148 135 126 110 123 110 108 138 134 130 110 120 146 129 138 122 128 127 140 125 127 146 134 139 152 143 128 126 133 134 137 129 125 136 130 122 139 139 138 146 137 123 131 144 117 148 131 144 119 171 138 136 138 133 127 138 127 114 124 135 134 125 123 146 138 137 142 130 116 131 136 125 119 137 130 131 122 133 126 138 151 125 131 134 135 147 126 161 128 166 136 155 132 145 156 158 143 153 151 160 128 147 138 135 140 140 135 152 144 130 152 161 133 124 118 136 155 158 154 129 137 140 166 148 111 141 133 145 146 136 138 135 146 156 154 139 156 140 137 152 148 166 153 163 151 143 139 134 153 141 150 136 157 151 134 129 142 101 146 148 143 146 140 133 113 120 150 119 138 124 133 126 150 166 125 134 144 146 138 162 142 156 150 173 146 158 138 111 143 135 162 148 151 125 141 135 165 146 143 169 149 153 166 145 155 161 146 158 142 156 158 139 136 159 150 150 145 125 155 164 151 139 148 130 129 153 160 160 144 149 135 152 139 162 154 171 144 146 150 143 173 151 145 138 167 166 153 152 142 135 142 147 144 120 137 151 155 131 151 149 129 169 130 144 143 163 129 152 152 156 151 146 144 159 122 155 182 142 168 157 131 130 147 137 146 155 151 143 148 143 151 134 142 134 150 139 143 149 150 157 154 173 153 154 132 161 131 138 143 146 145 149 133 163 147 141 139 144 151 153 127 151 145 155 141 129 148 132 146 140 152 140 165 129 122 143 141 143 141 170 153 135 135 138 149 120 134 152 136 125 151 157 149 161 135 127 149 141 158 140 154 152 160 152 159 150 149 146 128 125 135 151 132 131 150 146 139 133 150 144 108 164 133 155 138 153 143 154 141 122 166 141 148 123 144 127 140 139 132 148 131 134 155 123 153 151 142 137 130 144 117 142 146 141 131 145 144 149 124 141 149 134 155 133 118 128 165 136 128 144 154 149 120 130 143 142 128 142 144 127 138 115 144 156 112 144 127 141 140 113 115 131 123 149 136 146 142 131 161 138 140 138 129 132 109 124 128 132 117 152 121 129 150 109 134 114 131 130 130 124 133 128 125 135 150 130 128 158 133 132 120 125 138 125 139 140 120 129 160 116 132 127 135 133 145 150 137 133 135 139 125 116 150 153 155 129 141 141 129 135 144 150 142 132 131 145 124 176 126 127 156 136 139 131 140 145 149 136 137 141 135 161 134 136 129 153 131 156 139 144 145 141 145 138 145 132 141 150 141 134 159 142 141 118 134 140 139 133 144 155 132 145 138 137 118 135 145 125 159 141 151 140 133 126 150 139 132 150 146 134 144 148 160 135 157 160 156 158 147 142 149 161 153 179 140 140 120 139 135 145 148 164 148 127 139 161 109 132 130 135 148 121 134 134 120 160 139 123 150 134 155 145 145 119 139 137 142 131 128 126 140 132 115 138 148 117 122 111 142 141 138 153 132 140 136 149 142 142 143 139 158 132 140 126 148 136 160 139 134 151 152 145 143 150 145 142 152 141 155 120 141 141 136 119 151 133 135 150 141 115 140 133 140 130 160 137 133 131 114 157 142 163 137 140 116 136 136 142 114 163 148 137 132 155 138 147 149 120 117 121 136 133 141 136 132 112 134 113 122 107 130 108 109 122 113 126 124 98 103 136 100 109 106 122 129 109 130 121 115 117 111 94 98 110 100 112 112 122 107 112 120 120 110 114 101 112 110 109 124 99 104 117 127 111 131 107 115 104 108 102 102 124 125 124 94 127 124 108 88 108 108 101 119 118 108 117 110 116 115 122 96 106 116 87 110 116 110 88 127 96 98 117 109 137 131 118 101 115 91 118 111 106 101 93 95 103 118 92 111 114 84 123 108 118 130 96 111 119 124 110 91 114 100 124 103 124 106 115 127 109 93 103 103 109 104 119 119 103 98 111 125 114 101 107 116 110 116 126 122 112 98 93 108 121 118 86 115 97 104 109 103 103 100 112 120 118 116 120 104 124 116 93 103 108 114 103 115 97 86 99 105 108 105 121 105 103 95 101 104 127 133 110 97 77 91 131 132 102 111 104 101 106 104 107 113 111 105 105 121 135 117 110 86 112 128 109 110 92 110 112 91 115 112 119 107 104 114 104 125 112 124 117 125 128 118 102 125 137 125 119 151 108 124 117 106 142 123 119 105 110 135 106 100 115 93 128 159 120 121 139 158 140 125 129 127 127 103 113 125 114 133 129 125 116 122 129 107 116 149 138 124 134 135 129 134 117 135 132 146 122 113 125 143 127 142 121 108 143 126 141 142 113 115 121 120 131 129 132 159 126 130 127 126 137 137 132 122 136 157 140 161 130 139 154 120 125 133 126 143 125 139 143 131 135 120 130 114 120 130 134 141 136 130 120 143 110 112 128 131 122 144 142 130 116 119 140 142 173 138 141 126 128 119 126 131 138 141 99 122 111 135 134 127 137 129 146 130 137 139 138 119 137 116 117 120 128 146 139 130 155 137 129 126 129 153 120 139 128 116 131 130 140 135 126 142 111 159 124 136 132 141 118 133 133 138 135 142 140 135 140 106 130 126 113 143 134 120 116 134 141 114 128 135 136 141 125 142 141 151 137 128 120 124 125 122 147 111 129 140 146 133 148 131 150 160 138 137 136 139 150 135 138 139 125 123 128 134 111 132 128 122 125 114 122 119 97 120 101 113 95 107 97 98 102 100 104 88 87 106 94 104 87 92 91 99 121 101 83 85 109 85 90 109 99 97 80 106 97 107 104 104 102 91 107 113 93 110 106 93 110 100 97 127 90 86 83 83 104 109 102 98 94 110 108 94 120 127 94 110 95 89 103 97 97 88 101 74 97 88 94 103 95 114 93 131 105 106 94 95 110 102 102 109 125 118 106 101 86 88 105 120 106 102 114 109 103 99 96 110 125 95 105 85 100 93 107 89 126 116 103 123 115 100 92 104 100 100 83 93 116 97 102 109 104 103 104 105 104 84 97 99 100 100 103 94 112 84 110 102 97 88 113 98 110 104 84 116 102 108 84 119 74 109 100 86 98 92 121 105 103 88 99 100 100 105 103 99 104 109 114 99 122 119 100 92 102 102 109 99 98 97 108 94 93 106 102 110 97 87 80 94 82 112 96 108 93 118 111 100 109 115 106 96 104 111 107 103 102 113 93 105 81 98 130 91 102 99 74 97 87 108 104 96 93 98 88 123 101 104 100 107 120 95 85 108 90 97 88 107 95 104 119 112 123 128 103 100 114 101 96 104 103 108 108 103 90 101 121 96 105 83 105 89 100 113 85 104 99 112 86 98 107 86 105 104 106 108 90 101 104 95 108 112 101 103 105 128 82 106 104 94 127 110 111 110 108 90 91 99 106 107 101 108 110 101 117 114 131 106 104 105 115 105 110 95 112 88 100 99 117 95 109 82 87 103 101 113 94 107 103 97 95 86 88 105 87 88 91 82 97 99 98 105 103 101 87 87 100 91 97 93 80 98 98 99 92 100 88 93 100 93 89 101 84 107 84 94 86 116 95 88 109 97 102 100 100 97 110 85 83 77 75 85 97 100 73 105 97 99 73 123 96 93 97 87 102 101 91 71 117 94 125 88 93 97 96 78 111 81 89 89 76 84 71 95 97 95 115 101 106 101 80 113 105 100 85 107 94 76 106 90 84 82 79 90 80 79 99 95 84 98 96 61 96 93 92 103 79 101 105 106 96 92 81 95 90 99 90 102 119 97 94 105 96 100 86 99 76 112 95 86 95 83 86 102 91 101 94 96 88 95 83 86 82 111 84 97 90 120 87 94 90 91 95 98 102 76 90 85 97 109 100 87 103 97 94 103 83 78 88 98 87 87 84 92 86 82 95 94 109 91 100 78 96 90 85 92 87 87 107 78 101 113 90 88 86 80 106 85 107 101 88 89 108 91 98 91 102 90 98 100 96 82 102 101 107 91 107 96 96 102 90 94 105 115 109 93 92 81 98 91 104 81 94 92 99 95 97 92 97 108 92 84 93 110 93 103 98 102 100 79 99 111 91 120 104 97 99 82 104 79 84 82 101 96 91 96 94 90 96 76 115 87 105 98 96 88 104 85 76 100 96 117 105 102 97 83 87 98 91 107 65 98 96 87 101 100 91 98 86 95 79 73 87 103 103 73 89 93 77 93 96 108 115 104 105 88 68 71 106 106 106 82 101 107 100 92 112 99 77 82 92 86 99 83 90 88 91 83 117 72 94 83 88 90 96 81 89 94 87 90 94 83 85 81 82 102 79 87 88 101 96 93 88 87 95 90 84 98 112 104 85 98 87 97 80 96 79 82 102 95 110 102 93 71 101 78 110 85 102 78 80 94 96 93 86 118 105 93 88 102 83 100 78 87 93 100 116 96 103 95 96 90 69 106 92 92 110 85 93 84 83 109 96 101 88 100 105 96 90 93 90 97 99 96 98 85 82 74 80 103 101 85 112 96 97 110 101 103 104 99 101 93 89 111 82 109 73 80 94 99 84 111 97 111 94 89 87 77 102 95 94 101 94 95 105 108 89 116 84 80 79 93 83 81 88 88 90 92 78 110 103 116 78 86 85 94 87 98 96 106 79 118 111 107 92 97 96 97 90 87 104 83 85 73 90 91 82 80 96 91 104 76 94 89 84 88 99 108 102 101 102 90 88 87 103 110 115 85 84 88 111 103 111 98 102 90 98 89 87 92 106 116 81 112 93 107 88 74 103 84 105 95 92 80 121 108 85 85 84 96 87 98 85 95 79 91 78 81 69 110 93 96 100 95 100 84 95 110 93 93 85 100 103 99 104 85 81 105 81 90 84 101 127 99 92 93 102 91 114 104 94 95 78 86 94 92 112 89 90 93 105 80 103 110 94 80 110 79 104 101 90 94 111 99 90 89 91 95 85 90 93 72 97 105 104 106 87 113 101 108 90 86 84 83 103 90 81 86 113 87 94 91 88 92 99 90 94 102 94 104 119 97 112 100 96 104 91 107 90 87 98 97 122 91 97 117 106 93 108 103 95 93 79 78 110 111 112 111 85 88 83 109 98 88 107 77 91 101 90 81 106 107 99 121 117 104 92 93 92 103 76 105 106 89 115 96 113 93 101 108 125 85 92 92 108 102 103 104 99 104 88 113 100 69 100 108 118 114 107 86 98 84 106 93 103 104 104 89 71 108 97 109 100 103 111 90 121 96 95 82 83 105 100 113 98 115 110 93 109 90 89 100 94 111 83 113 84 113 123 104 86 100 102 90 121 94 98 96 106 94 110 93 108 108 105 112 88 101 122 105 102 107 116 89 95 90 111 122 96 105 101 93 102 107 111 100 93 92 100 111 97 105 111 97 110 112 112 98 114 92 99 95 111 98 111 108 97 105 105 108 99 95 94 103 102 102 104 89 100 99 102 116 102 102 113 117 123 128 125 102 103 130 120 130 114 118 124 108 101 126 103 125 110 97 127 107 128 117 121 106 118 125 118 116 131 134 101 127 111 110 106 132 123 133 115 122 125 108 134 134 133 103 137 132 113 129 129 118 119 128 149 130 108 130 105 128 105 133 113 122 144 130 145 107 111 114 112 113 106 109 118 121 126 141 133 118 129 132 120 138 142 126 137 137 131 127 138 114 125 136 154 148 150 136 139 130 133 138 136 142 127 137 124 129 135 111 152 136 152 144 129 114 144 120 130 138 141 137 149 130 131 145 119 130 134 125 158 125 139 147 131 135 116 148 128 123 107 162 138 124 157 146 138 139 149 162 170 129 142 139 157 140 147 137 148 143 148 152 155 156 127 131 137 123 147 153 124 141 158 139 146 157 127 160 137 143 126 164 141 146 150 150 127 124 151 112 140 134 162 126 137 135 144 148 119 145 146 147 150 133 145 142 156 114 136 134 152 157 128 133 151 132 135 159 133 132 129 150 134 126 149 132 154 141 149 155 147 155 131 142 131 149 122 138 161 152 138 143 150 129 131 146 156 153 147 158 147 132 139 139 143 132 134 145 138 156 154 147 127 125 139 156 147 148 135 178 140 144 157 160 151 144 147 144 136 157 137 115 156 152 126 124 128 168 149 135 147 111 126 144 123 137 131 121 145 139 136 134 148 143 124 147 149 142 137 139 139 120 143 136 121 129 131 132 133 122 139 139 120 119 141 149 129 135 148 121 140 136 132 108 139 125 141 134 138 143 138 138 130 128 137 134 141 121 125 125 147 140 138 139 111 128 128 137 126 165 126 145 130 117 129 142 119 131 137 145 125 119 157 107 123 114 144 124 116 143 136 137 161 149 137 134 134 143 156 128 125 119 146 129 123 139 123 131 139 126 136 131 123 139 114 128 130 171 135 136 130 149 143 120 159 137 130 139 145 137 127 135 154 116 123 117 119 138 138 133 119 128 151 122 129 123 133 121 139 124 126 148 149 140 139 119 143 138 137 142 137 126 122 120 131 114 136 134 114 145 144 126 139 122 126 140 141 152 139 134 128 116 129 131 133 127 123 143 136 144 132 133 136 133 106 153 133 132 125 130 128 149 140 157 140 119 132 144 139 122 149 149 105 150 146 142 125 121 132 130 132 118 139 133 138 158 136 152 144 150 138 153 141 143 149 149 154 121 133 144 143 135 147 138 148 134 140 150 149 126 129 135 146 118 138 120 123 133 117 129 132 137 123 138 128 136 127 116 148 144 149 147 136 138 159 139 130 148 132 151 130 126 142 142 117 109 115 125 147 135 126 134 136 127 122 105 120 128 137 125 118 139 138 118 126 133 119 131 128 145 130 113 103 135 124 109 118 129 140 131 128 127 146 103 126 118 130 113 125 148 132 118 119 120 126 137 124 138 116 145 136 130 116 134 115 121 128 147 105 135 127 118 123 131 115 123 121 109 134 144 129 126 116 105 132 116 125 125 128 151 137 140 118 116 113 104 116 124 131 181 129 124 123 113 131 126 109 118 113 115 137 135 116 128 124 102 121 149 136 138 128 95 133 126 104 128 115 116 117 130 126 122 105 118 113 129 117 127 103 127 91 111 122 120 107 121 115 121 134 126 138 143 99 113 110 118 118 106 125 113 103 131 111 118 115 116 110 100 115 140 115 132 122 110 95 113 106 118 121 117 118 109 113 109 108 99 115 130 118 119 110 124 108 120 110 112 101 113 121 90 136 124 128 106 86 108 110 126 117 122 105 137 109 118 107 128 114 130 127 99 103 118 90 118 119 132 99 115 115 120 108 106 115 124 96 117 109 137 122 98 110 105 126 116 103 109 126 130 109 122 100 115 115 112 108 115 112 111 125 105 119 105 118 107 104 103 106 84 108 116 115 104 103 107 78 92 132 89 96 92 108 103 143 91 89 105 124 131 128 116 103 101 90 96 105 84 115 100 99 106 115 113 108 97 108 110 110 99 117 117 108 116 109 107 95 115 113 134 108 84 99 113 118 104 129 114 102 104 109 100 125 128 102 111 98 102 107 101 110 128 121 104 111 116 95 106 98 107 101 91 100 91 105 111 102 129 98 108 103 127 104 108 99 97 101 118 99 108 85 92 92 102 114 122 104 100 117 110 113 139 103 116 116 111 108 99 104 99 104 99 98 106 99 92 101 121 86 104 114 101 108 92 112 95 102 98 89 123 112 130 102 123 102 119 123 112 107 97 119 90 101 109 108 108 126 108 114 112 105 105 120 85 95 99 111 103 101 98 105 117 105 107 108 103 99 110 91 98 99 119 96 94 84 120 103 113 103 126 121 105 107 96 107 95 93 111 109 112 98 106 93 120 100 103 107 87 109 107 104 112 104 105 128 111 112 122 124 121 106 113 104 112 117 132 104 113 111 129 124 124 113 148 108 107 122 123 121 129 104 120 120 109 138 104 113 99 112 123 121 127 111 110 102 110 112 127 125 142 94 107 102 102 129 128 106 134 106 133 116 105 113 130 92 114 104 115 107 123 138 121 112 119 111 120 128 123 109 101 115 115 131 127 112 116 96 119 147 141 97 128 113 133 98 97 117 90 120 114 116 114 95 119 132 110 123 113 111 109 106 96 105 96 107 114 108 121 120 126 96 107 110 101 120 104 99 104 108 108 106 102 104 142 103 97 105 109 128 118 142 99 110 107 118 125 108 124 114 113 127 105 128 120 124 128 101 118 105 121 108 109 112 122 128 130 107 107 118 128 100 125 112 135 123 124 113 111 145 125 95 97 112 102 104 128 110 99 111 119 119 118 135 134 115 117 116 121 119 109 123 113 101 116 96 123 109 109 109 100 120 128 150 100 127 118 137 114 113 98 121 94 117 120 125 112 117 110 112 116 113 139 113 103 111 111 109 102 109 91 113 97 119 136 104 116 109 101 112 100 107 102 102 100 125 102 119 115 119 107 103 109 105 132 105 130 136 125 102 100 136 130 122 120 118 107 102 115 118 117 117 127 113 110 126 109 123 122 122 119 119 105 123 110 117 97 104 118 126 117 112 107 129 111 97 99 110 107 107 91 102 91 98 107 91 107 93 92 93 109 113 105 97 94 101 102 96 92 112 91 93 109 97 96 97 88 107 77 106 98 99 97 115 108 106 99 109 100 79 102 95 101 114 99 89 96 81 107 102 81 89 99 85 114 113 101 102 102 82 98 94 92 92 114 110 106 107 96 81 117 90 94 99 106 122 97 98 107 96 107 101 87 110 92 121 97 96 83 98 71 89 94 101 111 112 101 105 108 101 112 98 90 96 110 110 106 85 107 97 88 99 90 110 96 88 124 101 88 109 97 109 107 93 104 89 87 93 85 100 108 87 112 114 117 100 124 83 100 100 107 112 104 112 106 101 94 105 76 101 95 93 89 90 105 82 94 110 94 101 110 98 92 116 93 102 102 106 106 86 88 101 114 88 111 99 93 103 92 97 106 84 106 90 101 101 101 88 111 103 80 120 88 89 86 92 89 90 93 89 113 94 95 104 101 95 107 106 103 98 106 101 95 90 91 100 101 111 83 102 90 81 94 103 93 108 87 77 78 105 89 95 96 99 93 95 83 108 113 116 95 108 101 100 97 104 95 96 89 111 94 99 120 106 104 85 88 85 77 91 87 88 95 102 107 96 105 102 90 101 91 93 113 81 97 110 90 109 100 117 78 94 110 101 102 109 81 98 101 113 99 88 92 121 93 110 106 93 105 94 101 89 107 88 104 102 90 102 97 89 99 81 109 89 98 104 99 89 98 127 92 91 77 96 99 109 84 108 102 112 79 91 81 102 94 116 88 109 90 114 84 115 116 108 95 97 106 94 95 103 100 99 117 103 94 99 92 88 101 97 91 100 95 102 113 103 121 87 94 100 84 79 111 92 94 107 98 96 100 95 108 103 108 100 88 96 105 89 79 98 102 97 106 92 95 99 103 104 85 100 101 112 95 104 98 107 94 92 91 106 91 115 109 101 130 98 109 89 113 105 100 102 110 100 100 114 99 124 91 103 96 104 95 112 96 99 96 90 93 99 82 93 109 102 110 106 106 114 120 96 99 94 100 96 93 107 112 106 95 81 101 116 101 110 102 81 88 105 93 120 77 92 100 103 103 87 97 109 118 108 91 78 87 91 93 97 96 113 94 103 100 113 88 82 99 95 108 101 93 93 119 92 104 98 102 107 101 116 104 112 111 110 90 88 110 91 112 100 91 85 98 125 107 119 108 90 100 104 95 125 101 99 89 95 90 105 101 81 93 92 101 113 99 109 92 104 93 92 94 101 111 91 119 112 106 98 105 106 108 104 109 118 104 88 105 101 92 114 100 96 102 105 120 98 113 101 112 97 103 105 100 103 90 107 118 89 112 100 107 91 104 103 99 116 107 92 101 99 87 101 103 107 103 96 107 87 104 93 101 99 112 113 96 92 106 92 109 101 116 107 101 91 101 105 89 102 104 93 93 120 96 84 87 98 96 104 103 106 95 96 83 81 97 101 93 118 103 108 91 95 101 102 91 111 105 116 96 112 97 84 82 79 94 106 91 97 116 107 87 86 91 109 88 110 121 112 98 103 101 92 107 90 113 99 91 114 88 99 93 115 112 108 107 101 117 94 77 97 99 117 90 99 101 94 89 109 103 92 102 98 99 97 102 94 93 88 103 96 78 105 86 107 81 91 103 83 95 88 94 106 106 96 105 103 97 107 106 98 95 108 86 122 103 110 106 111 108 99 89 88 98 94 121 94 120 90 97 100 98 94 96 96 106 98 95 104 101 93 101 99 79 113 115 95 100 98 84 101 90 95 96 113 94 96 94 109 105 91 98 98 105 96 102 96 101 92 88 115 110 115 126 96 90 104 122 112 116 119 100 118 112 93 116 131 94 104 96 119 111 108 92 99 101 119 109 119 118 119 123 98 101 105 128 108 127 119 116 127 113 117 115 94 113 122 113 104 89 124 111 107 124 110 98 97 92 128 104 103 100 111 102 120 113 129 114 122 100 102 100 96 117 101 104 95 110 101 114 107 123 99 96 96 114 117 131 112 116 98 118 96 104 113 116 137 113 118 101 104 107 109 96 125 103 114 108 95 95 115 103 104 114 98 93 102 87 95 91 105 88 98 91 94 103 121 108 91 121 103 109 85 94 120 98 84 97 92 137 106 97 95 129 92 104 130 101 103 109 104 106 107 113 94 104 108 127 130 105 124 105 106 111 117 89 109 95 120 93 106 105 103 99 109 106 95 110 97 129 96 126 114 111 110 87 123 101 115 120 115 102 101 83 111 118 118 112 102 91 117 94 93 105 103 123 96 111 92 111 107 113 102 116 101 106 100 116 118 106 115 108 107 112 100 115 99 94 108 119 127 118 111 109 114 112 107 115 122 118 114 125 116 98 105 102 87 98 125 110 112 117 114 95 99 111 123 100 100 113 107 117 113 104 113 105 100 121 115 119 109 93 103 89 105 98 109 108 122 115 118 128 135 95 91 94 106 97 101 127 108 123 114 131 96 96 105 123 103 99 96 108 115 119 113 94 100 101 119 116 111 119 122 100 103 127 107 112 112 100 118 119 116 107 106 111 96 93 92 115 98 113 98 98 102 107 118 93 119 115 98 111 120 99 110 105 98 71 99 86 124 94 109 99 118 98 125 121 107 99 103 110 124 112 106 101 102 119 106 102 96 90 102 97 114 117 103 113 96 92 102 100 105 111 95 116 107 98 94 102 127 101 92 96 107 99 103 84 96 113 84 97 116 99 135 115 122 122 104 113 101 109 92 89 94 103 92 127 115 90 101 96 102 117 105 100 116 104 118 102 125 113 96 111 95 87 103 106 121 102 99 111 86 120 101 100 123 117 123 114 101 92 106 111 99 113 101 103 109 116 104 110 90 110 104 96 98 89 121 104 102 115 85 121 108 113 129 101 117 87 99 94 105 91 95 96 104 105 112 98 107 100 130 107 97 122 97 110 121 81 114 116 108 112 100 108 108 117 106 115 123 110 115 96 126 114 115 96 113 104 100 121 105 115 94 113 106 106 85 95 104 88 102 85 100 99 123 114 86 111 96 108 111 121 113 126 92 107 112 114 114 96 106 85 98 95 118 94 125 116 130 115 116 109 118 104 122 97 119 105 96 92 103 106 98 102 89 108 95 103 95 92 124 76 122 112 105 117 102 103 99 111 99 106 96 118 86 111 105 119 108 123 104 124 119 112 97 109 91 107 119 107 110 93 100 114 104 129 112 107 120 106 99 123 130 117 110 128 107 101 108 122 98 98 92 113 99 114 101 121 103 98 135 117 100 106 108 99 124 115 126 130 97 107 112 106 112 106 112 100 104 110 116 93 92 111 101 101 91 106 108 97 115 111 105 117 110 107 109 112 108 104 137 98 115 128 112 114 112 108 116 139 131 102 115 115 134 112 92 115 105 117 92 108 98 109 119 124 96 111 104 98 106 108 101 125 103 121 101 128 114 114 117 95 104 100 146 129 132 120 130 112 112 99 131 117 131 114 126 127 146 138 174 154 178 187 194 172 171 198 157 196 199 204 165 181 182 206 193 169 191 170 180 173 206 211 230 201 190 166 191 197 201 216 189 186 216 192 178 195 186 195 167 209 191 217 194 213 190 221 176 209 165 201 186 199 187 170 235 184 199 188 166 171 182 200 192 206 190 185 193 198 187 211 203 182 174 182 193 167 216 183 206 170 190 195 173 179 184 180 173 199 169 175 219 190 201 222 237 176 199 205 211 177 191 176 191 192 197 217 177 192 198 214 179 203 219 194 185 221 178 199 215 216 214 197 196 185 204 198 213 174 198 186 212 198 209 180 177 171 193 197 175 200 247 192 215 214 196 205 215 196 212 187 204 185 219 205 197 176 208 215 193 202 180 217 199 175 178 193 199 200 193 182 189 204 191 185 222 186 192 186 192 182 215 190 184 189 181 182 189 194 201 209 199 228 179 184 219 219 204 192 207 222 180 181 245 175 205 215 195 222 188 195 194 181 187 212 207 210 183 206 206 190 194 215 198 241 192 197 189 197 193 190 203 209 200 192 209 203 201 210 209 190 202 215 181 223 204 205 206 175 191 183 218 188 196 197 207 215 213 195 179 222 202 204 231 149 200 209 200 182 189 225 191 182 213 187 197 193 196 186 216 188 178 218 209 204 207 190 197 193 211 205 171 188 187 219 176 242 197 202 194 201 187 205 195 192 189 159 155 136 163 114 142 117 144 137 132 129 101 105 111 102 116 125 123 122 118 127 130 123 119 116 106 122 132 124 124 131 92 114 102 128 131 116 115 123 132 128 130 130 144 122 109 120 137 122 118 130 112 134 141 119 132 118 124 124 129 134 146 127 99 113 113 112 128 113 119 125 136 126 150 101 130 119 121 130 116 116 124 138 135 133 153 128 132 150 127 134 117 120 129 105 115 123 116 121 127 122 118 128 127 103 106 135 112 125 123 117 113 134 120 120 113 122 109 89 124 97 125 126 120 120 140 130 129 119 125 109 119 92 135 108 129 129 133 112 120 115 117 123 127 107 124 136 109 113 101 134 126 130 133 146 98 130 125 116 124 113 108 132 136 136 122 123 112 115 148 108 112 107 116 112 110 114 132 125 116 147 139 125 128 111 114 125 128 121 108 110 124 115 135 118 123 101 116 121 116 122 119 135 125 121 120 117 131 135 115 161 117 133 132 108 126 123 108 132 143 125 136 124 124 118 123 112 148 124 130 137 123 122 115 148 144 130 143 116 133 140 140 136 152 124 146 126 119 124 107 109 118 130 121 128 130 122 146 116 137 151 138 140 110 139 127 114 141 139 139 120 126 123 117 131 143 148 139 133 125 136 133 132 140 120 124 143 149 128 132 117 118 132 109 113 154 131 156 114 135 121 134 129 133 157 134 133 115 127 131 132 139 146 143 136 138 134 136 140 137 121 111 125 136 129 118 122 137 130 139 136 119 153 154 148 145 132 140 138 142 132 125 109 128 132 130 131 144 127 134 126 141 136 127 121 137 140 117 137 150 122 154 142 128 131 133 145 136 156 132 134 127 132 145 143 123 145 133 133 149 139 131 131 139 153 143 123 136 150 156 131 158 138 160 130 135 143 137 142 135 126 130 153 126 136 157 158 134 137 121 149 120 143 146 135 149 130 150 135 119 123 139 127 142 150 136 117 144 137 144 164 147 146 173 141 162 154 125 159 144 119 165 123 131 150 139 144 137 133 126 144 125 147 166 138 161 137 149 169 161 158 153 162 159 157 139 140 144 134 152 165 152 149 162 126 143 149 147 126 150 160 154 153 140 162 134 157 147 154 163 133 154 137 153 159 139 152 147 159 131 159 136 141 138 124 160 135 129 167 146 162 166 138 153 146 153 134 157 154 149 155 146 164 145 149 158 155 156 128 154 129 141 140 136 158 136 159 135 182 165 148 157 152 148 141 150 160 137 163 151 142 137 154 151 142 142 148 138 138 164 156 168 129 142 141 142 141 141 150 155 162 144 145 156 160 150 158 162 152 164 170 172 165 159 166 165 135 158 154 154 157 166 143 155 148 158 152 150 141 171 146 137 185 166 146 180 188 162 166 168 160 174 163 165 152 173 151 178 141 174 170 164 180 211 217 232 249 287 290 265 300 290 286 274 301 281 294 265 297 296 299 308 267 299 308 337 278 323 301 334 317 316 323 300 330 297 316 328 306 304 332 298 303 327 307 297 324 326 297 304 290 310 307 317 291 302 307 326 283 326 312 319 304 331 320 346 307 300 312 294 340 350 320 323 309 317 338 305 321 320 336 292 333 338 319 326 313 293 302 338 329 334 294 350 309 325 342 365 332 336 323 348 331 331 340 348 337 346 290 313 336 337 372 311 341 345 332 360 349 324 370 336 339 366 372 386 387 343 393 379 370 422 368 396 331 384 371 426 349 413 361 403 352 392 388 395 391 366 380 381 385 374 354 365 350 378 357 350 354 367 369 355 372 323 398 342 356 336 332 335 352 363 337 364 336 394 354 354 365 352 352 375 372 370 360 398 392 343 363 354 348 361 360 358 360 383 385 390 333 363 371 409 400 387 386 372 364 353 387 343 384 373 410 393 388 348 385 373 395 375 380 385 413 381 366 384 381 364 401 385 384 362 392 365 399 376 381 387 387 386 373 373 365 400 363 430 369 394 354 418 378 370 416 380 416 400 409 386 403 380 404 372 419 418 405 393 391 392 416 350 370 443 374 425 414 372 391 378 390 411 395 414 403 392 425 403 396 423 421 455 424 406 436 413 439 402 398 374 423 412 415 420 381 406 378 359 364 315 288 293 245 240 234 272 250 274 273 236 265 263 243 276 264 282 266 290 233 261 240 312 244 280 265 233 244 271 280 271 265 271 236 271 276 227 273 265 261 298 272 268 265 274 278 287 271 262 268 259 270 274 279 310 269 260 307 305 239 288 247 258 240 258 274 276 277 268 278 262 243 229 227 310 257 274 286 231 242 244 262 262 281 263 292 263 285 286 264 261 259 241 301 264 270 273 276 263 263 266 303 267 271 265 251 257 243 267 240 280 276 272 233 269 244 241 266 260 230 239 270 274 264 273 300 280 229 264 263 267 275 275 233 276 295 250 286 275 262 250 279 272 282 279 267 283 258 260 281 295 261 260 248 237 289 293 263 261 261 261 282 273 263 286 277 275 244 245 245 261 237 265 262 245 238 270 273 232 314 260 262 291 259 285 249 266 266 270 272 241 211 243 274 258 263 238 272 245 246 297 242 244 251 227 288 235 243 276 258 261 232 263 262 257 247 281 247 270 225 267 215 250 256 246 262 268 243 262 259 242 210 218 256 269 244 248 260 261 240 263 234 226 249 233 273 230 286 242 274 256 223 270 243 273 226 233 233 261 214 211 222 249 235 209 218 217 258 246 223 225 235 230 248 218 276 285 222 244 238 235 257 270 266 226 251 245 223 234 204 240 243 220 231 227 238 245 267 244 272 247 213 272 231 240 217 209 202 204 210 234 257 215 210 228 245 238 210 246 242 232 231 231 222 234 228 227 236 234 215 181 232 232 237 220 213 218 236 231 199 218 239 234 224 257 244</counts>
			</dataPoints>
		</scan>
	</xrdMeasurement>
</xrdMeasurements>