File: Data Files/Full/MSS p (6-129, 2w)_01_1.xrdml
<?xml version="1.0"?>
<xrdMeasurements xmlns="http://www.xrdml.com/XRDMeasurement/2.2" xmlns:xsi="http://www.w3.org/2001/XMLSchema-instance" xsi:schemaLocation="http://www.xrdml.com/XRDMeasurement/2.2 http://www.xrdml.com/XRDMeasurement/2.2/XRDMeasurement.xsd" status="Completed" recordIdentifier="{2A6F97AB-0FBB-42D7-A6E2-57BFD4B4A225}">
	<comment>
		<entry/>
	</comment>
	<sample type="To be analyzed">
		<id>p</id>
		<name></name>
		<preparedBy></preparedBy>
	</sample>
	<xrdMeasurement measurementType="Scan" status="Completed" sampleMode="Reflection">
		<usedWavelength intended="K-Alpha 1">
			<kAlpha1 unit="Angstrom">1.5405980</kAlpha1>
			<kAlpha2 unit="Angstrom">1.5444260</kAlpha2>
			<kBeta unit="Angstrom">1.3922500</kBeta>
			<ratioKAlpha2KAlpha1>0.5000</ratioKAlpha2KAlpha1>
		</usedWavelength>
		<incidentBeamPath>
			<radius unit="mm">145.00</radius>
			<xRayTube id="1010048" name="Empyrean Cu LFF HR (9430 033 7310x) DK437964">
				<tension unit="kV">40.0</tension>
				<current unit="mA">15.0</current>
				<anodeMaterial>Cu</anodeMaterial>
				<focus type="Line">
					<length unit="mm">12.0</length>
					<width unit="mm">0.4</width>
					<takeOffAngle unit="deg">6.0</takeOffAngle>
				</focus>
			</xRayTube>
			<filter id="20010004" name="Beta-filter Nickel">
				<material>Ni</material>
				<thickness unit="mm">0.020</thickness>
			</filter>
			<sollerSlit id="21010002" name="Soller slits 0.04 rad.">
				<opening unit="rad">0.0400</opening>
			</sollerSlit>
			<mask id="22031000" name="Fixed mask 13 mm">
				<width unit="mm">9.00</width>
			</mask>
			<divergenceSlit id="22120004" name="Divergence slit 1/8°" xsi:type="fixedDivergenceSlitType">
				<distanceToSample unit="mm">50.00</distanceToSample>
				<height unit="mm">0.19</height>
			</divergenceSlit>
		</incidentBeamPath>
		<diffractedBeamPath>
			<radius unit="mm">145.00</radius>
			<parallelPlateCollimator id="25020001" name="Parallel plate collimator 0.28°">
				<opening unit="deg">0.28</opening>
			</parallelPlateCollimator>
			<detector id="7010020" name="PIXcel3D-Medipix3 1x1 detector" xsi:type="areaDetectorType">
				<phd unit="keV">
					<lowerLevel>4.0</lowerLevel>
					<upperLevel>11.3</upperLevel>
				</phd>
				<mode>Receiving slit</mode>
				<activeChannelsEquatorial>255</activeChannelsEquatorial>
				<activeChannelsAxial>255</activeChannelsAxial>
				<pitchEquatorial unit="mm">0.05500</pitchEquatorial>
				<pitchAxial unit="mm">0.05500</pitchAxial>
				<readOutPeriod unit="seconds">0.050</readOutPeriod>
			</detector>
		</diffractedBeamPath>
		<scan appendNumber="0" mode="Continuous" scanAxis="2Theta" status="Completed">
			<header>
				<startTimeStamp>2025-06-18T12:44:54-08:00</startTimeStamp>
				<endTimeStamp>2025-06-19T02:25:03-08:00</endTimeStamp>
				<author>
					<name>Instrument</name>
				</author>
				<source>
					<applicationSoftware version="1.6 (94)">PANalytical Aeris Instrument Suite</applicationSoftware>
					<instrumentControlSoftware version="3.0.0 20211014">AERIS</instrumentControlSoftware>
					<instrumentID>2855484</instrumentID>
				</source>
			</header>
			<dataPoints>
				<positions axis="2Theta" unit="deg">
					<startPosition>6.005</startPosition>
					<endPosition>128.995</endPosition>
				</positions>
				<positions axis="Omega" unit="deg">
					<commonPosition>2.000</commonPosition>
				</positions>
				<commonCountingTime unit="seconds">3.520</commonCountingTime>
				<counts 1386 1287 1220 1214 1259 1322 1206 1255 1365 1211 1349 1193 1224 1265 1334 1228 1241 1274 1176 1257 1205 1220 1214 1159 1203 1304 1273 1248 1346 1236 1183 1216 1277 1232 1330 1199 1209 1241 1326 1248 1208 1180 1219 1200 1197 1221 1341 1297 1219 1201 1258 1255 1244 1173 1149 1206 1280 1282 1248 1202 1160 1119 1201 1162 1267 1231 1214 1194 1204 1245 1150 1168 1127 1202 1182 1237 1177 1198 1145 1146 1126 1208 1158 1148 1152 1185 1143 1128 1193 1132 1141 1108 1137 1188 1104 1151 1138 1081 1175 1122 1136 1187 1093 1132 1042 1191 1115 1123 1089 1109 1098 1075 1129 1127 1108 1129 1100 1106 1076 1089 1080 1025 1098 1027 1118 1057 1078 1078 1100 1128 1043 1052 1134 1067 1066 1090 1088 1103 1076 1104 1172 1065 1046 1014 1020 1141 1065 1050 1094 1060 1030 1087 1104 953 1024 1074 1033 1050 1029 1096 1068 1058 1015 1038 1069 1026 1039 1034 1046 1062 1010 1052 1111 1010 1080 1022 1032 1061 1037 1040 1037 1022 1031 1006 958 1044 1024 934 976 956 1046 1006 993 1025 982 1006 1039 949 1010 1018 996 1035 1024 1010 1039 1043 978 1033 1042 989 1010 1008 1005 967 1000 907 998 1002 1000 1002 976 995 993 1041 1073 1035 992 994 1009 1015 967 981 991 955 1031 971 947 980 1023 1022 984 1017 961 1002 996 936 967 997 990 1005 935 962 1016 1019 1016 970 1031 892 1063 978 980 943 970 928 1043 996 931 911 991 1000 968 978 963 1026 981 978 996 985 1049 996 967 936 940 1004 980 956 1048 1034 957 990 958 976 978 901 948 938 962 950 965 905 994 956 985 1117 1034 991 976 923 997 1049 993 1032 988 1012 969 961 1027 927 1051 995 1029 941 1042 1014 937 937 900 929 974 984 1006 982 952 949 1018 968 1003 1025 970 1026 965 990 1012 1018 986 967 984 1000 995 1027 1013 990 1025 1001 1021 971 1025 971 1011 939 1022 979 999 1054 1010 1051 1067 1022 988 980 1051 909 1028 956 1029 1025 1006 1045 1037 1019 986 957 1097 1034 981 1011 962 1069 1015 1038 964 1014 1040 1085 1098 991 1049 1036 1053 981 1022 1045 1087 990 1106 1064 1079 1045 1045 1045 1007 1076 1052 1058 1067 999 1039 1125 986 1078 1070 1079 1073 1114 1051 1096 1050 1078 1103 1066 1062 1074 1061 1097 1107 1173 1136 1076 1129 1093 1098 1137 1143 1085 1100 1059 1141 1106 1068 1077 1095 1091 1105 1110 1140 1097 1118 1086 1174 1142 1080 1136 1060 1124 1138 1195 1154 1154 1132 1136 1154 1136 1186 1208 1141 1154 1133 1093 1169 1245 1173 1199 1237 1149 1164 1154 1224 1147 1144 1204 1235 1244 1212 1239 1247 1266 1207 1203 1195 1120 1200 1239 1241 1182 1196 1176 1217 1202 1249 1209 1230 1172 1264 1178 1297 1180 1234 1218 1280 1197 1397 1361 1270 1277 1283 1224 1275 1390 1327 1235 1347 1219 1333 1284 1245 1336 1268 1475 1381 1409 1241 1381 1386 1433 1397 1359 1410 1430 1480 1452 1466 1354 1483 1419 1472 1526 1494 1515 1513 1362 1459 1491 1554 1515 1438 1426 1549 1543 1592 1569 1556 1587 1497 1732 1732 1553 1545 1481 1510 1603 1634 1566 1633 1553 1660 1556 1688 1737 1668 1669 1477 1623 1728 1722 1673 1737 1788 1683 1789 1731 1729 1626 1864 1744 1748 1794 1697 1715 1749 1792 1857 1781 1757 1798 1779 1759 1875 1813 1755 1788 1847 1830 1907 1865 1851 1829 1854 2006 1842 1924 1818 1879 1905 1842 1934 1891 1858 1917 1878 1920 1806 1929 1969 1954 1949 1874 1994 1996 1968 1845 1965 2000 2014 1931 1982 1873 1944 2003 1929 2049 1982 2024 1996 2034 1946 2027 2026 2043 2032 2035 2035 2187 2003 2067 2093 2028 2062 2072 2152 2092 2155 2158 2144 2084 2123 2167 2137 2125 2188 2129 2153 2074 2115 2198 2193 2172 2217 2235 2123 2283 2313 2318 2218 2161 2208 2182 2233 2235 2128 2172 2221 2256 2120 2252 2330 2273 2221 2356 2253 2230 2250 2264 2344 2249 2285 2197 2301 2307 2223 2363 2292 2380 2291 2294 2339 2311 2328 2297 2369 2349 2429 2303 2381 2385 2426 2307 2324 2306 2418 2360 2461 2399 2388 2516 2494 2374 2285 2395 2266 2459 2358 2423 2345 2348 2421 2435 2417 2452 2481 2468 2497 2386 2527 2422 2370 2432 2373 2355 2419 2433 2433 2453 2370 2303 2412 2361 2451 2431 2475 2433 2502 2465 2413 2490 2377 2515 2486 2432 2400 2408 2424 2490 2344 2467 2350 2416 2419 2417 2381 2427 2362 2477 2494 2488 2518 2368 2461 2428 2398 2416 2388 2453 2379 2418 2348 2397 2495 2374 2353 2394 2390 2347 2380 2448 2436 2386 2352 2499 2341 2447 2435 2330 2384 2361 2342 2395 2394 2370 2290 2342 2296 2302 2315 2352 2285 2346 2301 2268 2395 2282 2338 2323 2307 2282 2390 2273 2342 2216 2395 2315 2247 2197 2299 2280 2223 2173 2289 2192 2203 2167 2218 2267 2192 2198 2212 2240 2195 2184 2210 2239 2274 2119 2208 2162 2156 2167 2096 2146 2173 2201 2167 2153 2107 2107 2089 2092 2123 2166 2030 2111 2102 2107 2068 2093 2144 2104 2077 2082 2082 2044 2035 2011 2069 2005 2040 2045 2002 2069 1971 2002 2017 1893 1991 1996 1986 2022 1960 1979 1922 1941 1975 1945 1974 1961 1987 1849 1909 1953 1920 2015 1807 1849 1912 1964 1955 1927 1893 1902 1920 1828 1745 1859 1820 1776 1845 1763 1801 1883 1862 1848 1875 1880 1759 1773 1812 1739 1713 1761 1858 1838 1768 1663 1770 1804 1712 1742 1739 1706 1559 1755 1747 1687 1718 1590 1660 1861 1749 1747 1752 1662 1885 1850 1895 1985 2055 2234 2283 2276 2371 2470 2546 2613 2703 2704 2782 2826 2802 2761 2615 2557 2397 2289 2230 2195 2074 1987 1879 1717 1663 1637 1438 1522 1566 1312 1324 1451 1543 1410 1541 1389 1426 1427 1272 1397 1292 1405 1272 1529 1259 1556 1511 1311 1272 1284 1382 1385 1328 1402 1325 1378 1326 1385 1358 1331 1290 1323 1213 1317 1253 1307 1369 1290 1355 1268 1327 1247 1206 1348 1216 1174 1367 1199 1299 1252 1287 1210 1352 1301 1246 1189 1162 1196 1201 1232 1249 1200 1257 1178 1257 1228 1167 1211 1188 1186 1305 1232 1364 1209 1198 1219 1288 1216 1229 1252 1258 1181 1204 1192 1217 1213 1163 1162 1226 1218 1132 1125 1128 1169 1161 1134 1218 1117 1137 1093 1058 1053 1112 1124 1100 1087 1121 1104 1096 1048 1025 1040 1059 1089 1058 1086 1069 1086 1086 1031 1077 1091 1057 1028 1055 1019 1005 1063 1075 1099 1092 1024 1127 1022 1019 953 979 995 1053 1090 992 1036 1092 1052 1043 1019 981 1033 980 1025 1050 1047 1032 1008 1081 1058 1048 1098 1039 1003 998 1001 961 1046 958 963 1028 1014 953 1032 1033 1028 964 997 1055 979 965 1009 1022 1015 1027 958 1055 933 1005 958 1012 1007 994 971 1006 951 993 957 1008 990 936 973 958 951 955 889 914 901 900 914 964 932 942 885 926 852 946 927 959 941 936 917 971 884 925 963 905 939 859 954 909 933 931 904 856 863 928 903 844 884 866 872 902 878 937 889 899 890 937 883 908 896 820 859 866 885 895 932 882 908 841 885 890 896 875 887 895 939 940 880 838 876 935 783 844 913 880 874 847 871 877 870 901 872 868 838 851 854 813 869 862 873 943 811 821 905 830 820 881 856 859 853 842 845 833 844 848 796 916 796 847 849 854 833 842 885 817 822 847 911 839 778 875 837 817 841 863 865 859 845 861 805 852 907 837 847 842 844 831 786 809 808 856 879 811 839 821 803 810 863 798 823 827 831 851 851 799 822 826 797 821 801 742 858 867 845 759 814 773 832 829 846 822 797 803 800 838 841 772 857 819 829 767 776 762 791 819 821 787 756 798 824 826 806 858 817 861 791 785 819 831 862 846 833 842 987 983 1193 1744 2146 2646 3118 3759 4267 5027 5295 5816 6406 6868 7328 7588 7793 7774 7661 7408 6892 6371 5949 5486 4934 4287 3661 3188 2757 2170 1786 1080 1008 838 812 823 834 782 763 797 788 727 816 745 795 768 754 793 780 754 738 810 778 751 765 780 800 786 729 731 748 794 722 718 778 858 753 755 782 715 709 763 726 702 722 764 739 734 755 796 738 736 724 780 683 747 683 715 715 693 724 806 704 710 720 743 748 719 673 710 700 729 711 695 741 752 748 708 671 697 709 746 695 733 727 719 668 732 765 739 745 688 692 803 718 715 689 691 722 690 725 748 686 767 690 692 704 705 782 750 728 699 744 691 749 667 694 688 700 721 731 700 676 715 699 659 678 640 685 696 682 690 708 681 661 627 699 698 703 675 628 692 707 706 736 677 667 690 692 710 723 713 733 697 692 722 712 694 683 702 712 721 695 686 689 617 683 691 706 689 748 656 680 709 686 704 704 686 700 667 710 664 686 635 673 675 649 719 648 664 678 665 683 677 670 715 655 714 703 673 679 700 644 662 640 679 582 653 667 705 659 661 666 657 615 666 692 660 706 684 609 658 655 645 606 646 705 665 604 686 628 679 653 670 642 656 656 658 640 682 654 663 673 672 700 613 673 647 672 682 667 654 600 687 641 669 638 638 677 706 651 613 659 649 632 639 672 622 674 663 667 651 651 672 682 641 730 650 618 642 608 626 634 688 614 626 654 640 623 677 645 632 667 663 638 641 664 630 679 651 631 710 645 637 675 656 636 609 666 643 673 682 659 641 657 693 583 658 632 640 664 609 653 714 643 657 613 637 691 698 625 661 614 610 695 676 665 712 722 792 831 951 1023 1129 1440 1576 1856 1936 2165 2407 2451 2655 2773 2790 2823 2700 2687 2681 2357 2331 2011 2010 1875 1627 1396 1213 1018 913 779 720 702 681 633 637 620 651 627 630 689 690 626 645 629 628 631 599 622 650 660 672 645 618 633 654 653 636 605 619 670 630 645 642 658 633 644 688 659 649 648 663 662 643 641 598 619 670 593 593 624 627 624 606 642 655 651 632 637 632 639 680 650 662 663 623 609 556 648 624 627 616 631 670 649 636 641 589 625 652 627 667 645 639 669 610 621 616 628 607 597 597 627 665 621 601 611 613 631 633 611 640 672 617 643 621 616 605 615 631 616 609 642 626 600 660 579 604 608 558 630 585 609 640 615 609 605 596 591 631 588 641 614 654 611 647 646 649 644 620 630 620 711 633 686 715 677 719 707 672 689 684 642 632 671 661 643 641 617 649 631 639 631 570 609 649 577 586 627 661 634 632 604 621 675 607 577 578 628 618 605 595 620 696 624 634 618 660 605 631 623 611 586 645 653 614 659 606 621 681 669 633 615 657 608 642 609 695 587 577 595 633 599 585 595 598 616 615 639 623 615 632 566 602 620 601 652 583 584 584 607 641 613 637 597 634 631 653 648 607 631 600 615 613 614 672 627 600 565 639 604 593 664 582 607 610 622 646 572 573 640 583 620 593 569 567 592 571 581 599 629 578 572 641 603 635 568 638 586 561 587 585 631 573 602 611 579 579 627 647 622 653 607 593 610 588 583 653 606 623 608 641 608 598 620 608 594 610 568 600 616 578 590 609 620 569 603 579 649 601 605 591 583 636 578 600 601 573 604 602 636 567 607 645 582 580 631 583 626 567 596 590 639 605 628 614 616 639 591 622 584 586 632 637 603 605 576 559 595 598 602 614 607 659 592 629 562 597 640 558 584 570 604 606 624 597 618 587 617 604 579 612 564 622 582 636 625 563 652 620 568 596 616 597 570 613 633 583 589 628 603 621 597 576 568 582 597 653 604 579 614 595 574 615 613 620 577 593 612 581 612 647 624 637 606 599 594 620 595 589 612 614 580 669 577 620 584 621 622 593 665 612 590 559 631 572 610 617 577 595 616 628 621 632 632 651 645 619 627 592 610 676 636 614 632 613 694 605 615 644 615 670 668 645 677 678 644 615 665 627 602 645 663 613 594 663 617 636 666 620 612 621 634 632 632 603 597 614 632 672 620 650 628 676 707 647 646 673 645 688 704 631 718 667 694 639 696 679 713 667 666 675 676 669 723 683 680 662 707 704 732 717 747 742 707 752 768 760 757 755 778 801 790 958 1007 1563 2210 3295 4608 6451 8703 11106 13824 15824 18535 21160 23408 25861 28173 30184 31257 32540 32285 31420 29958 27909 26008 23691 21022 18606 16129 13648 11124 8925 6532 4697 3294 2179 1657 1108 1007 972 983 930 957 920 988 981 988 1120 1068 1179 1252 1408 1471 1432 1487 1594 1747 1751 1777 1840 1777 1751 1705 1730 1635 1715 1647 1699 1648 1473 1545 1523 1505 1436 1517 1421 1671 1529 1526 1653 1481 1670 1502 1570 1630 1654 1711 1540 1480 1562 1609 1631 1606 1448 1549 1479 1493 1306 1472 1352 1268 1276 1165 1342 1337 1169 1233 1208 1104 1177 1144 1103 1089 1061 1038 1000 1022 1032 1029 993 1014 907 996 922 945 926 972 881 910 897 892 878 844 881 900 855 837 838 823 811 797 780 845 739 791 754 720 764 792 785 774 808 754 678 750 766 781 691 701 757 737 681 693 664 660 660 739 716 741 717 709 722 642 695 678 683 682 668 695 681 653 661 606 658 640 644 664 681 657 640 642 634 702 673 619 624 621 605 605 615 601 591 591 603 624 662 638 631 596 644 628 561 604 602 596 592 558 636 578 606 581 563 595 553 559 598 586 589 595 568 553 604 594 593 611 613 622 609 556 586 597 559 589 556 573 585 527 587 565 563 565 562 589 536 586 512 561 566 532 589 543 577 537 578 591 530 531 618 553 615 573 577 550 535 556 539 592 554 564 538 517 522 540 556 610 557 587 533 563 589 537 558 550 583 546 532 514 578 574 503 553 519 579 569 538 573 555 535 529 541 536 501 568 518 538 523 537 584 543 517 563 532 569 544 501 557 508 572 515 530 514 503 531 522 608 534 512 546 560 585 540 532 524 525 536 506 566 505 567 549 551 522 585 547 513 542 561 530 553 539 553 557 528 502 524 528 509 526 560 509 541 550 512 545 522 541 546 523 583 519 480 522 558 510 496 500 505 567 510 528 569 471 535 499 490 581 464 532 536 597 524 487 560 519 537 523 524 529 505 519 480 569 560 529 553 481 487 546 562 566 498 480 490 513 567 486 526 509 504 538 506 492 581 522 576 493 504 572 514 505 525 493 561 534 500 517 510 508 553 473 506 561 496 538 489 521 563 518 498 538 546 514 549 561 496 512 514 557 510 499 501 521 510 535 529 492 479 494 524 465 506 523 519 520 473 516 539 514 528 532 521 524 523 530 525 476 473 502 500 521 531 477 525 523 550 521 534 519 491 474 540 515 509 484 548 518 485 500 528 476 492 555 496 512 507 526 487 538 548 524 550 535 554 505 510 523 519 486 519 487 534 515 504 505 465 512 527 485 493 497 471 492 528 501 511 520 512 544 509 514 478 519 543 506 508 516 518 508 506 536 549 502 481 512 512 508 504 471 514 495 485 539 505 501 522 515 472 516 489 475 523 529 506 514 513 512 517 513 526 528 516 516 527 529 591 656 648 728 845 809 859 936 976 1090 1115 1288 1167 1204 1290 1237 1225 1143 1062 1047 953 905 848 763 747 723 635 589 499 567 546 483 481 492 506 547 536 508 495 519 496 494 489 492 467 485 469 515 504 509 460 490 492 515 513 489 505 505 502 512 531 512 497 492 489 474 489 532 494 483 488 495 493 480 509 499 508 501 469 503 474 507 508 446 504 486 474 466 459 512 466 465 533 453 528 518 474 495 461 503 492 486 507 498 464 482 527 509 464 494 491 484 427 470 491 482 448 476 500 468 507 475 531 543 497 463 474 514 472 442 478 463 468 498 476 456 492 475 490 495 471 477 502 496 475 467 478 469 464 477 455 482 503 483 499 523 479 512 475 520 510 490 472 553 486 506 529 533 517 514 506 517 501 523 490 475 487 444 475 472 468 482 470 487 491 425 484 499 451 477 471 458 473 438 445 454 472 451 476 490 371 451 477 476 484 499 456 437 451 464 445 440 461 474 442 482 433 481 436 402 482 468 469 472 460 467 416 487 452 472 459 473 475 443 424 503 474 486 447 460 522 448 417 449 421 457 493 461 420 469 465 432 432 490 464 484 510 455 474 497 459 471 435 488 445 464 471 441 459 429 479 468 474 486 459 467 474 471 421 437 471 459 427 481 476 417 458 469 492 457 495 452 446 465 446 454 461 460 473 465 499 403 443 446 480 462 491 465 428 443 481 449 442 446 438 450 470 457 464 437 481 492 437 461 453 421 459 491 444 469 485 432 449 455 446 444 435 431 489 503 406 429 437 442 474 471 458 489 442 476 416 440 410 481 411 459 502 409 463 408 496 451 424 426 441 474 442 410 475 437 456 471 464 492 472 436 465 446 463 433 480 440 475 448 459 435 479 416 501 432 460 429 452 457 463 439 480 457 474 480 444 467 476 503 540 562 587 691 668 768 847 803 920 896 996 1031 1041 995 1105 978 1091 900 903 936 893 861 768 730 671 570 598 574 539 487 523 462 474 458 479 512 453 454 463 492 439 447 447 447 468 459 443 447 435 432 464 417 441 493 427 427 420 443 462 438 495 462 527 448 406 440 436 461 426 455 440 481 464 417 459 400 455 434 468 452 457 445 459 429 453 468 488 456 430 448 460 402 449 446 449 488 462 447 429 462 456 473 452 466 473 452 443 468 449 462 455 470 506 507 457 463 474 465 424 435 478 480 468 457 507 461 427 453 473 436 437 492 422 453 475 495 470 435 444 430 475 468 458 456 451 421 468 482 471 448 507 458 451 436 411 453 481 424 432 468 436 475 427 455 468 479 459 448 431 408 477 432 470 471 467 455 412 457 465 461 434 474 499 469 448 509 458 445 449 454 435 486 478 447 464 435 480 464 467 452 443 418 488 424 493 486 450 459 469 445 477 472 452 448 434 417 462 468 481 463 463 469 498 433 458 450 477 456 477 458 432 484 430 432 459 489 472 455 484 450 455 441 450 472 457 469 488 440 461 469 467 448 459 489 472 422 432 485 498 479 481 514 472 459 470 462 488 493 469 452 453 479 436 430 481 500 438 467 489 435 472 481 474 447 452 527 496 431 503 473 483 485 513 489 562 517 564 576 562 573 559 622 613 576 601 578 542 577 591 528 554 502 498 510 494 484 456 508 468 453 469 486 487 452 474 440 473 481 511 465 440 470 422 413 449 485 475 508 513 448 497 485 476 499 481 459 472 473 508 441 504 488 427 501 496 449 496 494 461 542 486 494 462 497 468 506 446 454 462 451 515 535 450 512 470 474 489 501 472 426 447 438 501 459 466 517 481 503 445 446 454 465 439 460 431 467 474 497 476 449 468 489 448 459 474 491 459 470 463 498 425 467 519 463 459 471 509 467 497 469 482 433 479 434 482 513 482 436 438 560 445 483 506 437 492 491 475 507 499 492 470 506 466 449 438 456 499 487 468 468 515 441 463 466 454 471 459 465 458 476 486 468 491 437 494 455 460 472 478 474 436 435 456 500 460 460 470 451 488 442 441 472 460 455 488 449 461 450 477 506 487 458 474 433 450 492 529 450 451 453 470 477 470 453 443 478 459 526 550 555 532 584 623 598 599 627 614 619 607 616 633 610 615 585 535 626 575 488 501 493 497 471 491 490 462 472 474 447 454 448 453 448 434 431 454 426 444 462 480 450 435 479 441 442 437 437 452 452 468 474 458 446 454 471 463 452 427 435 436 441 459 461 444 467 420 459 487 469 438 430 453 474 471 456 480 482 470 443 478 488 467 473 492 467 445 447 434 472 453 452 426 408 478 454 459 437 503 453 439 437 482 484 467 409 479 437 416 424 426 410 423 416 478 460 440 454 483 455 462 431 428 446 457 467 457 420 424 447 482 448 477 422 451 458 440 428 431 448 400 450 479 454 406 432 469 416 451 456 442 439 459 447 462 422 458 470 423 471 450 449 422 433 455 437 456 450 428 452 421 444 469 408 437 456 434 464 476 452 432 451 422 452 471 444 453 422 408 443 476 452 423 449 447 441 422 484 422 477 472 455 426 434 393 415 446 442 449 436 399 423 428 435 422 418 417 421 414 408 433 431 420 401 451 423 400 439 464 400 413 386 485 421 411 446 438 449 423 438 443 414 440 443 426 455 435 419 417 444 410 425 420 436 436 374 416 431 420 402 436 439 440 450 423 435 447 442 437 390 468 443 415 425 425 418 440 397 417 422 411 440 447 380 416 419 370 412 380 445 432 430 438 402 416 394 426 445 446 421 449 440 394 392 451 427 419 399 426 434 423 450 396 423 386 459 413 415 379 412 409 462 404 373 401 410 442 443 415 388 387 405 432 403 436 365 425 395 396 391 418 382 414 375 401 412 375 389 427 394 414 378 418 396 426 395 399 403 386 421 400 442 394 413 368 388 392 366 362 402 439 398 403 405 382 468 410 399 421 335 394 405 428 408 410 378 397 384 416 397 393 380 405 397 365 362 412 384 331 367 373 405 379 382 425 396 402 391 407 343 364 391 383 393 378 409 381 391 403 392 365 387 430 446 386 354 380 388 395 392 394 363 334 356 393 390 441 372 389 387 382 371 375 377 427 384 398 382 392 388 379 356 398 353 394 376 399 363 380 368 375 391 366 359 397 411 355 405 352 371 420 366 400 364 348 348 364 373 376 392 385 345 362 368 378 394 401 371 400 379 395 353 395 380 391 408 420 421 439 466 466 474 465 492 547 477 466 511 520 513 531 501 448 492 438 440 442 435 393 430 400 420 371 385 382 370 415 376 370 354 374 363 392 338 334 396 411 354 372 335 378 354 345 381 365 363 368 377 368 366 366 345 353 347 342 364 358 374 338 354 353 379 367 376 353 355 387 374 383 405 395 396 373 324 357 365 366 334 369 357 333 372 382 361 397 349 359 359 387 360 370 390 334 355 371 368 409 384 346 367 413 366 336 378 366 396 382 383 383 360 363 362 362 401 380 343 345 325 404 348 368 363 384 365 373 379 350 357 368 325 342 380 353 415 397 370 456 391 435 418 410 468 443 465 506 497 491 505 477 481 509 477 470 440 456 430 431 411 415 367 379 405 345 364 342 345 362 368 345 387 363 375 324 359 377 371 351 356 352 367 351 399 375 339 406 364 379 376 375 347 411 416 363 389 388 361 359 364 346 371 352 333 356 375 341 382 330 389 347 340 357 352 395 345 372 427 367 340 367 367 367 387 356 377 347 351 352 322 343 354 341 358 351 383 351 364 357 369 333 371 377 357 396 375 384 373 411 387 372 399 403 361 364 375 408 377 348 369 381 366 374 349 325 376 364 370 361 375 356 347 361 309 376 382 351 357 332 385 353 338 373 363 325 354 351 359 365 367 366 367 349 381 353 347 377 337 367 395 327 351 367 369 357 363 380 343 376 355 370 362 342 367 358 357 344 389 366 365 344 366 365 346 370 362 352 354 341 394 344 361 369 340 341 351 376 334 357 409 355 376 321 357 400 326 382 357 361 364 342 366 331 365 363 393 375 379 344 344 359 364 328 377 367 342 348 346 346 339 329 379 351 334 368 361 334 410 366 330 354 370 351 356 377 327 418 394 397 359 375 352 371 401 345 352 350 348 346 360 379 351 365 347 357 394 373 367 371 388 392 361 362 348 367 339 369 376 311 363 382 317 368 344 384 363 359 362 319 364 375 338 330 397 381 403 376 364 353 372 327 365 354 355 363 371 361 370 349 363 361 381 368 350 341 378 357 369 363 374 383 387 374 399 343 375 355 351 400 365 373 361 353 375 386 364 383 373 392 412 371 366 349 382 375 359 389 398 365 323 361 372 318 354 375 374 337 380 394 371 405 405 371 348 358 368 356 330 391 330 355 354 393 346 349 375 352 395 356 378 340 374 370 378 386 371 419 340 362 343 365 394 358 346 360 342 374 367 381 356 345 381 365 361 366 377 359 387 379 374 367 393 385 357 366 365 342 383 387 382 373 384 391 372 364 386 368 409 356 371 408 377 357 359 366 387 359 359 409 397 358 376 392 365 383 356 375 418 343 373 386 350 416 368 415 396 382 364 353 389 369 394 357 338 372 318 379 364 420 363 346 374 352 419 329 410 378 349 362 346 365 367 405 383 394 399 407 407 366 392 365 375 374 350 388 369 346 358 372 431 350 388 381 404 385 360 373 418 394 393 371 357 380 346 398 393 421 354 363 401 380 393 359 382 422 413 383 391 385 375 411 392 366 380 424 403 376 390 357 362 352 387 397 398 374 372 361 380 374 387 390 338 372 388 416 382 386 429 402 353 361 368 387 377 348 380 400 410 379 381 408 401 369 395 410 375 418 389 408 407 379 404 413 394 377 409 400 404 348 371 396 385 404 386 382 412 364 402 409 366 353 403 411 391 363 407 391 359 404 397 383 361 372 398 383 410 402 358 376 365 390 370 452 416 383 370 392 418 382 394 400 368 410 408 416 349 428 416 379 417 411 380 402 409 394 392 377 379 432 392 400 358 364 393 407 390 394 378 371 383 392 394 437 405 362 375 426 397 355 397 373 392 397 398 443 416 406 391 385 380 394 389 388 386 423 417 441 407 361 425 395 399 395 398 408 387 393 417 407 410 436 415 432 396 386 432 365 383 397 385 403 413 383 431 402 398 413 379 373 416 410 402 390 399 428 419 409 387 422 389 416 431 411 430 405 427 445 393 407 451 411 408 417 389 436 388 373 395 441 403 447 395 399 414 430 411 409 431 417 428 398 410 379 425 478 410 412 432 379 432 437 397 466 423 419 456 446 412 431 405 446 429 417 414 409 414 440 418 439 406 427 398 445 446 431 424 477 461 534 514 607 660 758 867 943 1014 1135 1240 1197 1486 1518 1774 1784 1790 1713 1705 1665 1550 1286 1267 1150 958 924 855 773 701 590 509 514 464 445 453 411 450 458 415 471 467 441 412 469 435 418 416 456 441 404 404 413 437 389 423 433 426 407 408 462 435 459 433 424 453 435 451 440 423 399 396 413 406 451 451 448 453 430 439 450 426 455 430 408 414 412 465 431 433 451 408 421 455 442 394 451 393 491 415 439 409 462 416 437 447 460 429 433 430 429 441 424 442 421 437 464 422 442 425 455 438 456 437 409 430 431 453 447 438 435 430 436 436 424 406 398 430 403 442 454 432 445 462 407 437 425 476 456 446 465 446 421 473 459 403 445 467 437 427 436 386 426 426 421 457 407 465 439 384 458 427 438 432 435 436 455 473 444 465 453 416 457 440 427 445 386 454 454 405 482 456 415 458 422 480 469 468 446 442 458 467 409 432 461 420 479 440 441 467 450 445 433 483 438 450 458 475 497 470 440 456 462 467 465 454 439 448 412 438 431 431 440 429 449 470 449 469 433 473 426 444 447 473 462 484 473 422 438 466 442 456 474 452 454 451 444 434 436 450 443 491 454 476 433 481 466 423 492 419 468 476 456 463 458 471 427 491 420 483 487 476 483 472 476 449 431 522 475 460 477 454 485 524 480 418 452 487 476 463 447 487 496 431 489 468 454 476 460 481 494 457 465 487 454 463 464 452 462 485 461 445 462 475 469 430 529 454 504 437 449 444 471 466 431 465 442 478 500 439 479 482 498 485 482 459 479 457 449 448 466 460 493 523 463 476 473 455 466 463 479 494 458 494 465 481 458 442 477 494 519 503 468 508 453 472 498 454 472 460 462 495 470 444 484 483 469 488 476 519 466 505 472 460 473 456 461 505 485 484 501 489 505 481 468 529 494 477 459 470 537 491 478 486 472 483 461 508 463 502 479 469 479 456 514 474 466 477 475 470 476 543 497 482 462 474 494 483 458 499 454 461 494 491 425 466 467 542 489 501 532 508 512 463 502 510 497 521 528 466 508 512 488 502 524 488 481 480 476 467 491 502 490 477 482 490 494 481 471 488 503 493 501 501 474 482 502 474 530 524 537 544 477 501 530 506 525 515 478 467 481 514 487 474 501 466 508 490 498 531 504 498 494 525 504 519 503 552 476 521 483 510 519 508 492 514 515 491 548 503 486 494 526 522 494 507 485 510 505 529 511 509 504 486 496 534 515 545 557 482 502 512 528 546 510 519 480 476 541 563 506 491 535 523 538 539 522 512 542 559 540 538 489 531 533 522 488 504 484 534 459 501 540 502 554 537 572 520 551 551 550 542 529 564 555 560 550 566 515 545 571 523 543 516 536 577 516 554 554 522 551 496 543 533 510 525 534 577 516 543 521 534 546 490 523 520 521 526 515 529 565 529 512 524 503 523 535 497 549 565 512 512 509 515 541 544 525 571 525 530 547 563 573 542 511 542 555 550 530 577 605 568 520 555 573 556 522 546 519 558 576 533 523 539 550 520 552 543 536 597 544 572 569 537 547 528 515 576 551 527 554 517 561 532 534 531 552 602 556 541 579 526 605 591 548 514 549 560 565 583 552 545 575 543 572 593 536 559 544 540 554 608 571 515 600 581 574 581 544 549 540 567 552 549 509 579 582 555 556 550 564 587 533 541 585 569 586 538 561 563 584 570 560 614 558 572 571 584 570 580 563 535 602 550 583 542 564 562 566 553 579 591 535 563 569 573 561 580 526 547 550 580 563 539 582 600 603 579 554 528 552 591 643 574 547 607 636 609 542 592 528 581 613 534 601 543 554 582 554 566 549 557 576 514 563 582 574 539 581 599 583 537 588 568 620</counts>
			</dataPoints>
		</scan>
	</xrdMeasurement>
</xrdMeasurements>