File: Data Files/Full/MSS p (6-129, 6w)_01.xrdml
<?xml version="1.0"?>
<xrdMeasurements xmlns="http://www.xrdml.com/XRDMeasurement/2.2" xmlns:xsi="http://www.w3.org/2001/XMLSchema-instance" xsi:schemaLocation="http://www.xrdml.com/XRDMeasurement/2.2 http://www.xrdml.com/XRDMeasurement/2.2/XRDMeasurement.xsd" status="Completed" recordIdentifier="{89BF6481-23E0-4AEF-90E3-097DD33773AD}">
	<comment>
		<entry/>
	</comment>
	<sample type="To be analyzed">
		<id>p</id>
		<name></name>
		<preparedBy></preparedBy>
	</sample>
	<xrdMeasurement measurementType="Scan" status="Completed" sampleMode="Reflection">
		<usedWavelength intended="K-Alpha 1">
			<kAlpha1 unit="Angstrom">1.5405980</kAlpha1>
			<kAlpha2 unit="Angstrom">1.5444260</kAlpha2>
			<kBeta unit="Angstrom">1.3922500</kBeta>
			<ratioKAlpha2KAlpha1>0.5000</ratioKAlpha2KAlpha1>
		</usedWavelength>
		<incidentBeamPath>
			<radius unit="mm">145.00</radius>
			<xRayTube id="1010048" name="Empyrean Cu LFF HR (9430 033 7310x) DK437964">
				<tension unit="kV">40.0</tension>
				<current unit="mA">15.0</current>
				<anodeMaterial>Cu</anodeMaterial>
				<focus type="Line">
					<length unit="mm">12.0</length>
					<width unit="mm">0.4</width>
					<takeOffAngle unit="deg">6.0</takeOffAngle>
				</focus>
			</xRayTube>
			<filter id="20010004" name="Beta-filter Nickel">
				<material>Ni</material>
				<thickness unit="mm">0.020</thickness>
			</filter>
			<sollerSlit id="21010002" name="Soller slits 0.04 rad.">
				<opening unit="rad">0.0400</opening>
			</sollerSlit>
			<mask id="22031000" name="Fixed mask 13 mm">
				<width unit="mm">9.00</width>
			</mask>
			<divergenceSlit id="22120002" name="Divergence slit 1/2°" xsi:type="fixedDivergenceSlitType">
				<distanceToSample unit="mm">50.00</distanceToSample>
				<height unit="mm">0.76</height>
			</divergenceSlit>
		</incidentBeamPath>
		<diffractedBeamPath>
			<radius unit="mm">145.00</radius>
			<parallelPlateCollimator id="25020001" name="Parallel plate collimator 0.28°">
				<opening unit="deg">0.28</opening>
			</parallelPlateCollimator>
			<detector id="7010020" name="PIXcel3D-Medipix3 1x1 detector" xsi:type="areaDetectorType">
				<phd unit="keV">
					<lowerLevel>4.0</lowerLevel>
					<upperLevel>11.3</upperLevel>
				</phd>
				<mode>Receiving slit</mode>
				<activeChannelsEquatorial>255</activeChannelsEquatorial>
				<activeChannelsAxial>255</activeChannelsAxial>
				<pitchEquatorial unit="mm">0.05500</pitchEquatorial>
				<pitchAxial unit="mm">0.05500</pitchAxial>
				<readOutPeriod unit="seconds">0.050</readOutPeriod>
			</detector>
		</diffractedBeamPath>
		<scan appendNumber="0" mode="Continuous" scanAxis="2Theta" status="Completed">
			<header>
				<startTimeStamp>2025-06-21T06:50:27-08:00</startTimeStamp>
				<endTimeStamp>2025-06-21T20:30:31-08:00</endTimeStamp>
				<author>
					<name>Instrument</name>
				</author>
				<source>
					<applicationSoftware version="1.6 (94)">PANalytical Aeris Instrument Suite</applicationSoftware>
					<instrumentControlSoftware version="3.0.0 20211014">AERIS</instrumentControlSoftware>
					<instrumentID>2855484</instrumentID>
				</source>
			</header>
			<dataPoints>
				<positions axis="2Theta" unit="deg">
					<startPosition>6.005</startPosition>
					<endPosition>128.995</endPosition>
				</positions>
				<positions axis="Omega" unit="deg">
					<commonPosition>6.000</commonPosition>
				</positions>
				<commonCountingTime unit="seconds">3.520</commonCountingTime>
				<counts 4496 4314 4434 4307 4411 4330 4357 4362 4361 4389 4264 4413 4309 4213 4202 4252 4234 4220 4082 4257 4263 4332 4267 4179 4271 4311 4235 4237 4155 4209 4275 4236 4041 4225 4130 4272 4216 4149 4040 4103 4232 4206 4114 4231 4008 4177 4050 4041 4082 4042 4068 4060 4001 4023 4160 4028 4121 4086 4072 4116 4122 4091 4026 4033 4000 4027 4053 3955 3996 4022 4035 3904 3995 4013 3869 4052 3938 3818 3914 3887 3980 3813 3919 3915 3924 3876 3936 3905 3906 3943 3979 3865 3894 3868 3845 3878 4002 3941 3919 3757 3823 3909 3868 3834 3857 3830 3808 3736 3794 3692 3816 3835 3883 3804 3783 3842 3822 3773 3729 3891 3657 3800 3700 3710 3595 3755 3712 3781 3738 3686 3633 3806 3806 3697 3776 3717 3776 3717 3694 3721 3663 3724 3674 3694 3664 3742 3663 3574 3632 3652 3792 3661 3726 3616 3624 3653 3692 3690 3702 3577 3719 3580 3676 3724 3756 3726 3721 3778 3690 3734 3703 3559 3753 3770 3763 3690 3656 3762 3770 3776 3744 3734 3620 3707 3634 3621 3726 3660 3779 3778 3694 3814 3753 3584 3705 3718 3601 3729 3691 3639 3670 3570 3509 3595 3532 3583 3540 3436 3428 3424 3540 3453 3484 3448 3406 3506 3514 3385 3370 3451 3456 3332 3418 3376 3387 3371 3307 3385 3347 3300 3439 3390 3376 3422 3266 3297 3408 3416 3247 3438 3201 3458 3357 3437 3450 3347 3399 3511 3464 3534 3531 3606 3484 3461 3470 3510 3517 3615 3508 3555 3626 3588 3633 3673 3766 3709 3639 3656 3696 3742 3662 3755 3749 3755 3692 3729 3787 3893 3697 3627 3640 3759 3603 3638 3553 3569 3421 3533 3614 3417 3564 3480 3482 3494 3416 3439 3454 3417 3472 3351 3354 3236 3311 3070 3213 3187 3237 3161 3202 3301 3072 3120 3043 3138 3083 2978 3107 3103 2995 3086 3105 3162 3032 3037 3024 3113 3030 3049 3074 3066 3094 3100 3087 3167 3192 3072 3106 3160 3164 3127 3214 3070 3198 3132 3130 3110 3190 3227 3071 3043 3013 3082 3084 2948 3108 3040 3179 3171 3048 3144 3132 3211 3118 3216 3115 3173 3158 3162 3111 3127 3089 3179 3124 3100 3070 3088 3309 3213 3128 3079 3137 3163 3180 3090 3210 3175 3119 3277 3111 3187 3193 3146 3335 3127 3186 3169 3242 3090 3200 3182 3154 3149 3159 3220 3165 3208 3171 3278 3105 3202 3267 3373 3180 3225 3300 3233 3267 3227 3321 3227 3323 3310 3241 3332 3278 3231 3237 3330 3402 3231 3121 3236 3309 3294 3246 3302 3190 3274 3289 3279 3360 3351 3316 3217 3201 3341 3385 3240 3228 3404 3313 3445 3290 3395 3347 3423 3289 3346 3312 3389 3367 3427 3411 3457 3359 3417 3451 3312 3368 3441 3383 3453 3344 3410 3438 3357 3430 3362 3408 3417 3502 3462 3468 3497 3413 3502 3412 3485 3568 3469 3521 3441 3477 3498 3598 3545 3486 3508 3493 3488 3467 3523 3580 3610 3516 3655 3533 3680 3527 3596 3553 3544 3485 3591 3506 3585 3527 3480 3522 3653 3505 3465 3581 3551 3703 3668 3698 3604 3560 3613 3631 3606 3697 3651 3630 3583 3621 3716 3750 3730 3730 3812 3727 3662 3789 3631 3782 3680 3658 3793 3770 3718 3835 3763 3864 3809 3849 3850 3816 3804 3817 3796 3816 3822 3796 3862 3786 4108 3943 3857 3991 3954 3867 3838 3807 3961 3855 4045 3856 3960 3856 3905 3891 3940 3930 4043 3953 3975 3940 3974 3937 4016 4088 3904 4017 4048 3984 4066 4145 3989 4172 4101 4238 4029 4188 4102 4216 4234 4123 4143 4208 4239 4162 4187 4114 4370 4160 4127 4361 4103 4377 4258 4250 4322 4282 4211 4266 4238 4310 4249 4464 4447 4324 4296 4412 4206 4541 4399 4412 4377 4422 4422 4422 4257 4486 4477 4429 4449 4418 4385 4466 4419 4439 4469 4649 4359 4303 4494 4532 4505 4538 4557 4531 4407 4504 4579 4641 4568 4645 4627 4644 4710 4678 4618 4583 4718 4740 4556 4604 4632 4604 4750 4575 4664 4540 4535 4706 4674 4733 4690 4822 4730 4806 4786 4814 4791 4812 4791 4728 4793 4892 4943 4922 5034 4946 5002 5024 5052 4924 4882 4991 4848 4932 4889 5086 4981 5008 4973 4831 4980 4896 4846 4983 4998 4894 5031 4907 5020 4887 4956 4961 5074 5018 5060 4993 4851 5088 5092 5170 5202 4902 4996 5080 5109 5021 5133 4945 4992 5066 5116 5208 5195 5175 5126 5118 4949 5259 5161 5064 5099 5222 5253 5207 5151 5158 5089 5126 5141 5028 5169 5235 5173 5091 5119 5106 5127 5204 5086 5363 5196 5174 5290 5201 5151 5321 5088 5259 5361 5089 5049 5271 5312 5192 5043 5311 5223 5199 5118 5130 5204 5088 5190 5211 5252 5293 5157 5266 5322 5172 5204 5321 5224 5236 5147 5124 5242 5221 5118 5254 5277 5225 5191 5109 5137 5092 5151 5159 5301 5039 5155 5018 5146 5122 5056 5172 5029 5030 5116 5105 5228 5104 5135 5066 4923 5006 5043 4980 4964 4966 4780 5091 5039 4978 4957 4976 4981 4885 4801 4854 5005 4915 4848 4829 4904 4781 4930 4921 4799 4836 4926 4806 4869 4902 4834 4830 4764 4826 4790 4785 4715 4739 4713 4739 4797 4775 4640 4744 4726 4660 4599 4627 4587 4603 4677 4632 4630 4682 4678 4672 4745 4612 4542 4528 4544 4420 4602 4632 4532 4453 4415 4501 4557 4321 4441 4473 4369 4430 4445 4432 4486 4469 4515 4464 4362 4487 4373 4390 4389 4389 4376 4316 4280 4249 4286 4267 4224 4123 4194 4223 4212 4176 4202 4320 4241 4298 4232 4236 4210 4110 4127 4192 4147 4118 4202 4043 4151 4184 4097 4054 4089 4049 3952 4158 3956 4001 4039 4093 3983 3938 3993 3961 4046 3949 4026 4013 4018 4025 3979 4115 3866 3787 3913 3882 3828 3926 3948 3850 3904 3821 3921 3789 3741 3803 3810 3896 3810 3752 3711 3735 3731 3696 3710 3633 3581 3730 3626 3748 3586 3828 3697 3711 3763 3629 3697 3716 3628 3570 3570 3614 3577 3489 3591 3635 3591 3549 3549 3516 3565 3540 3489 3568 3558 3450 3460 3513 3618 3522 3492 3463 3548 3425 3407 3485 3406 3468 3462 3381 3370 3270 3405 3375 3449 3341 3376 3429 3308 3372 3217 3269 3272 3359 3276 3375 3330 3184 3342 3319 3328 3260 3397 3229 3285 3353 3678 3979 4011 4036 4122 4401 4413 4271 3882 3616 3594 3493 3329 3169 3186 3152 3156 3265 3272 3349 3176 3263 3250 3226 3094 3214 3039 2906 3181 3060 3039 3144 3165 3145 3050 3100 3054 3133 3080 3089 3019 3079 3016 3062 3126 2980 3147 3019 3020 3046 3005 3055 2970 2968 2993 3017 3034 3006 2915 2880 3034 2905 2955 2986 2987 2967 2884 2912 2821 3042 2911 2955 3004 3020 2924 2837 2774 2897 2906 2831 2867 2892 2844 2896 2926 2775 2878 2829 2889 2880 2892 2847 2732 2867 2765 2796 2859 2761 2829 2775 2810 2803 2766 2874 2791 2801 2789 2742 2764 2708 2868 2813 2831 2802 2741 2827 2835 2799 2630 2689 2728 2746 2750 2691 2816 2716 2640 2753 2841 2723 2796 2763 2632 2711 2690 2671 2739 2697 2683 2681 2659 2701 2671 2632 2663 2591 2701 2683 2659 2567 2627 2693 2550 2707 2592 2705 2691 2622 2677 2717 2562 2661 2664 2725 2652 2587 2642 2567 2677 2638 2625 2657 2514 2559 2542 2612 2537 2529 2584 2613 2692 2583 2543 2559 2544 2534 2507 2551 2581 2570 2532 2527 2567 2556 2562 2507 2523 2471 2551 2468 2665 2533 2591 2512 2500 2484 2633 2566 2483 2448 2522 2570 2503 2429 2512 2597 2460 2522 2536 2498 2479 2551 2445 2544 2518 2500 2537 2441 2391 2394 2516 2466 2474 2466 2529 2479 2469 2503 2592 2517 2440 2437 2494 2518 2440 2482 2505 2356 2378 2352 2485 2428 2432 2396 2531 2453 2465 2447 2375 2438 2422 2423 2371 2334 2470 2431 2332 2449 2412 2405 2449 2434 2429 2436 2426 2522 2365 2418 2376 2429 2487 2330 2350 2356 2311 2299 2332 2446 2386 2313 2417 2318 2458 2385 2344 2365 2338 2395 2448 2297 2239 2373 2349 2340 2423 2496 2314 2398 2411 2441 2281 2286 2413 2365 2404 2505 2621 2635 2705 2930 3148 3370 3512 3691 3846 4215 4437 4609 4987 5176 5351 5703 5723 5913 6262 6374 6681 6734 6626 7265 7197 7103 7276 7439 7216 7352 6908 6818 6814 6356 6249 6048 5741 5249 5105 4569 4304 4022 3684 3306 3195 3021 2640 2696 2411 2340 2318 2270 2330 2369 2342 2261 2308 2284 2415 2318 2330 2284 2209 2356 2312 2245 2343 2255 2284 2212 2319 2248 2280 2285 2323 2259 2217 2204 2297 2177 2168 2281 2157 2254 2275 2217 2218 2279 2115 2140 2241 2233 2224 2168 2178 2184 2288 2235 2240 2166 2223 2147 2154 2209 2185 2255 2229 2257 2202 2172 2176 2258 2294 2315 2216 2212 2179 2235 2149 2209 2136 2155 2239 2108 2229 2205 2144 2173 2188 2178 2236 2157 2177 2116 2191 2209 2172 2150 2085 2214 2142 2097 2231 2151 2091 2186 2167 2150 2108 2101 2196 2068 2058 2175 2099 2161 2130 2298 2153 2093 2119 2189 2068 2146 2135 2057 2063 2180 2094 2229 2082 2012 2121 2001 2038 2082 2119 2212 2118 2104 2151 2114 2082 2070 2117 2098 2125 1989 2094 2103 2025 2058 2131 2013 2029 2158 2084 2073 2018 2058 2002 2042 2059 2071 2041 2054 1975 2135 2065 2114 2027 2044 2010 2141 2092 1951 2096 2101 2048 1991 2078 2085 2035 1952 2108 2043 2113 2019 1992 2067 2066 2083 2047 2129 2020 2044 1954 2107 1931 2082 2025 1954 2065 2002 1951 2022 2056 2040 1986 2076 2012 1950 2064 1987 2035 1977 2049 2068 2057 2038 2006 2053 2011 2041 2000 1979 1963 1918 1929 2037 1905 1949 1966 1960 1998 1942 1931 1897 1957 2102 1974 2033 2041 1977 1939 1960 2006 1942 2150 2009 1952 1970 2001 1964 2027 2126 1911 2030 2012 2029 2033 2006 2056 1990 1965 1986 1988 2019 2055 1976 2007 2055 1839 1995 1989 1955 2026 2031 2033 1923 2003 1947 1901 1994 1966 2040 2001 2013 2046 1961 1924 1988 1945 2009 1980 2079 1919 1938 2122 1849 1954 1936 1903 1983 2051 1941 1937 1909 2023 1963 1954 2049 2071 1951 1967 1947 2036 1987 1981 1874 2060 1992 1923 2009 2008 1964 2005 1937 1987 1966 2039 1986 1959 2067 2002 1987 1997 1948 1887 1893 1945 1949 1964 1982 1945 1963 1875 1943 1986 1996 1996 1977 1883 1884 2076 1983 2044 1966 2015 1958 1951 1894 1967 1927 2028 1915 1983 1921 1993 1985 1996 1937 1957 1958 2010 2008 2003 2038 2019 2057 2160 1979 1989 2030 2034 2072 2106 1941 2037 2012 2088 2157 2123 2096 2078 2218 2251 2385 2590 2827 3001 3380 3616 4092 4471 5071 5289 5729 6238 6661 7161 7624 8029 8332 8758 8993 9668 10075 10265 10877 11210 11594 11606 11843 11957 11855 12145 11993 11633 11203 10954 10473 9813 9005 8377 7595 6793 6043 5613 4785 4087 3603 3310 2850 2626 2406 2362 2250 2222 2186 2124 2104 2157 2136 2098 2099 2201 2059 2126 2052 2018 2050 2087 2030 1931 1975 1860 1976 1913 2001 1975 1912 1965 1907 1902 1934 1915 1948 1913 1949 1865 1935 1924 1933 1985 1911 1974 1944 1849 1914 1880 1866 1875 1949 1924 1993 1904 1861 1944 1922 1893 1879 1874 1850 1866 1890 1969 1908 1920 1837 1828 1893 1834 1904 1815 1854 1948 1823 1939 1788 2044 1989 1904 1953 1900 1952 1949 1965 1977 1946 1937 1805 1854 1803 1840 1924 1895 1908 1939 1894 1837 1880 1874 1854 1878 1889 1886 1895 1902 1930 1909 1875 1845 1808 1882 1831 1849 1950 2010 1861 1864 1853 1909 1862 1727 1857 1957 1866 1915 1854 1886 1918 1880 1836 1906 1818 1885 1921 1898 1863 1842 1817 1879 1844 1816 1895 1939 1854 1885 1854 1914 1980 1787 1781 1782 1834 1938 1887 1877 1872 1924 1877 1903 1843 1835 1988 1832 1851 1861 1804 1847 1791 1919 1766 1852 1862 1928 1779 1865 1876 1866 1804 1845 1869 1862 1901 1879 1879 1838 1909 1852 1956 1930 1867 1855 1843 1898 1832 1860 1844 1811 1915 1891 1922 1894 1923 1726 1826 1928 1850 1798 1848 1816 1786 1827 1935 1885 1853 1835 1852 1878 1826 1804 1857 1886 1867 1988 1816 1899 1875 1813 1864 1876 1871 1881 1957 1772 1936 1901 1722 1883 1871 1929 1836 1786 1880 1893 1840 1836 1867 1953 1821 1835 1811 1901 1808 1839 1882 1793 1897 1833 1909 1857 1906 2012 1825 1921 1942 1988 1795 1852 1928 1834 1881 1751 1901 1873 1893 1899 1806 1865 1885 1806 1851 1746 1853 1859 1825 1906 1865 1781 1806 1876 1884 1863 1846 1864 1949 1879 1873 1977 1961 1961 1837 1817 2016 1908 1811 1957 1905 1965 1921 1884 1960 1891 1822 1961 1944 1900 1976 1919 1914 2008 2010 2110 2249 2215 2358 2433 2692 2891 2966 3431 3376 3681 3831 4096 4302 4643 4802 4996 5314 5494 5457 5868 5861 6220 6160 6270 6593 6456 6591 6578 6595 6420 6504 6283 5919 6036 5809 5206 5026 4709 4464 4094 3862 3333 2998 2813 2576 2477 2211 2169 1969 1959 1996 1932 2047 1954 1987 2004 1963 1936 1947 1972 2099 1909 2052 1950 1934 1884 1929 1914 1990 2004 1898 1916 1986 1896 1933 1946 1957 1946 1956 1939 1780 1849 1958 1887 1790 1967 1941 2018 2006 1977 1901 1966 1926 1925 1933 1883 1994 1844 1854 1942 1962 1932 1957 1935 1955 1943 1932 1902 1983 1943 1910 2008 1964 1916 1902 1919 1988 1929 1942 1933 1894 1948 2044 1999 1924 1886 1900 1976 1950 1943 1957 1988 1954 1939 1909 1932 1998 1967 1910 2004 1918 1982 1957 1923 1967 2026 1981 1896 2020 2030 1969 2021 1940 1990 2015 2008 1992 1977 1963 2026 1933 1980 2011 2060 2004 2044 1866 1962 2073 2093 2112 2104 2188 2064 2165 2160 2085 2181 2177 2204 2240 2281 2163 2245 2260 2239 2167 2315 2266 2251 2301 2163 2239 2199 2299 2237 2302 2344 2257 2103 2167 2183 2248 2169 2091 2058 2079 2102 2169 1990 2160 2162 2120 2231 2188 2081 2223 2165 2127 2137 2186 2232 2182 2155 2227 2180 2208 2165 2293 2248 2137 2144 2208 2248 2211 2225 2207 2229 2241 2223 2216 2305 2383 2338 2226 2236 2262 2308 2353 2200 2348 2282 2246 2362 2360 2364 2353 2328 2278 2392 2329 2520 2362 2426 2470 2593 2612 2640 2721 2599 2617 2447 2624 2666 2509 2615 2599 2712 2676 2639 2729 2685 2696 2655 2750 2622 2625 2624 2475 2580 2607 2500 2425 2479 2490 2555 2594 2631 2594 2608 2743 2484 2539 2609 2700 2529 2625 2493 2536 2586 2614 2632 2571 2520 2610 2564 2631 2603 2623 2630 2547 2727 2618 2629 2580 2730 2633 2596 2643 2599 2672 2711 2694 2721 2685 2710 2663 2602 2671 2564 2711 2758 2574 2734 2669 2500 2650 2589 2692 2679 2725 2638 2665 2637 2570 2573 2645 2617 2519 2553 2625 2624 2511 2553 2527 2516 2588 2419 2557 2617 2560 2595 2550 2483 2536 2406 2418 2445 2438 2463 2399 2449 2425 2414 2358 2473 2431 2460 2334 2365 2307 2404 2362 2405 2410 2283 2402 2400 2279 2365 2267 2278 2307 2252 2218 2218 2364 2196 2282 2312 2235 2095 2134 2250 2128 2114 2108 2229 2061 2152 2170 2237 2124 2156 2178 2046 2094 2054 2128 2041 2084 1974 2041 2075 2093 1993 2062 2067 2050 1954 2017 2094 2115 1900 2028 2016 1963 1976 1889 1972 1961 1984 1997 1962 1984 2023 1997 1935 1971 1903 1970 1907 1940 1894 2017 1876 1893 1903 1893 1950 1950 1890 1878 1783 1853 1889 1751 1888 1882 1875 1863 1752 1807 1924 1785 1880 1864 1760 1811 1638 1793 1756 1888 1863 1856 1797 1716 1686 1752 1642 1699 1816 1805 1754 1777 1783 1746 1716 1836 1797 1707 1649 1790 1643 1727 1850 1699 1797 1672 1565 1673 1712 1734 1676 1686 1612 1781 1712 1772 1725 1686 1721 1634 1669 1732 1626 1810 1668 1729 1693 1748 1751 1801 1769 1971 2138 2573 2939 3580 4048 4664 5131 5886 6194 6856 7117 7524 7822 8175 8412 8122 8052 7862 7475 7102 6689 6382 5841 5347 4943 4421 3937 3539 3414 3249 3193 3371 3757 4276 5087 5850 6814 7709 8926 10165 11781 13023 14541 16380 17716 19153 20760 22064 23170 24498 25847 27056 27384 28370 29370 29083 29487 29269 28851 28129 27415 26434 25334 23866 22925 21254 19381 17640 15827 14078 12611 10952 9155 7807 6656 5561 4744 3911 3328 2777 2559 2332 2135 2118 2106 1978 2032 1948 1932 1932 1777 1900 1782 1692 1841 1737 1651 1666 1605 1672 1655 1635 1526 1478 1390 1501 1604 1392 1405 1463 1496 1571 1645 1590 1412 1476 1547 1450 1453 1526 1320 1516 1418 1507 1528 1418 1442 1589 1557 1556 1440 1516 1454 1403 1392 1411 1443 1499 1487 1562 1325 1468 1447 1369 1392 1499 1562 1380 1356 1441 1549 1345 1527 1458 1525 1379 1333 1402 1381 1418 1574 1428 1292 1458 1369 1339 1420 1417 1437 1432 1420 1334 1471 1509 1326 1392 1467 1376 1373 1489 1608 1370 1459 1553 1443 1378 1401 1338 1434 1457 1399 1365 1478 1260 1512 1382 1283 1386 1388 1234 1318 1261 1493 1478 1429 1437 1309 1323 1277 1255 1350 1319 1419 1369 1308 1440 1388 1266 1329 1329 1221 1407 1351 1400 1263 1295 1391 1347 1317 1414 1326 1359 1363 1365 1341 1248 1413 1499 1293 1335 1315 1384 1351 1376 1357 1286 1364 1378 1378 1316 1335 1364 1304 1272 1234 1363 1304 1335 1393 1259 1364 1405 1366 1205 1291 1304 1321 1347 1434 1317 1207 1242 1356 1333 1257 1285 1243 1233 1297 1385 1377 1297 1283 1217 1323 1442 1218 1388 1399 1269 1232 1335 1232 1375 1195 1307 1408 1329 1288 1214 1261 1405 1290 1180 1232 1313 1360 1278 1270 1251 1193 1292 1270 1283 1320 1241 1220 1362 1240 1267 1292 1287 1205 1305 1211 1243 1224 1271 1217 1318 1218 1299 1211 1321 1249 1190 1205 1236 1259 1267 1185 1322 1296 1396 1318 1236 1256 1291 1243 1170 1353 1238 1229 1349 1245 1221 1246 1197 1252 1189 1193 1223 1178 1267 1258 1324 1348 1390 1247 1319 1159 1220 1211 1268 1213 1215 1257 1345 1319 1272 1200 1278 1346 1252 1297 1335 1241 1291 1259 1256 1232 1328 1298 1237 1190 1172 1267 1288 1260 1274 1165 1240 1304 1228 1253 1214 1330 1249 1132 1212 1321 1178 1233 1305 1160 1168 1179 1233 1216 1227 1161 1335 1157 1236 1261 1239 1164 1164 1184 1248 1219 1206 1232 1186 1295 1211 1221 1225 1208 1196 1266 1274 1225 1236 1201 1230 1280 1299 1167 1165 1260 1346 1204 1228 1193 1135 1234 1269 1153 1307 1236 1303 1200 1242 1204 1155 1184 1255 1172 1164 1193 1206 1172 1186 1314 1258 1167 1193 1183 1201 1223 1210 1251 1191 1253 1173 1217 1238 1223 1219 1320 1318 1161 1234 1216 1218 1286 1290 1202 1303 1192 1110 1214 1162 1200 1193 1167 1181 1295 1224 1231 1197 1194 1219 1216 1165 1211 1163 1190 1199 1156 1172 1256 1231 1163 1250 1195 1185 1242 1175 1170 1221 1283 1256 1259 1162 1344 1184 1145 1147 1219 1256 1297 1224 1239 1189 1260 1252 1211 1185 1238 1242 1256 1225 1200 1276 1198 1213 1172 1284 1150 1163 1229 1178 1193 1250 1233 1243 1197 1148 1190 1237 1324 1228 1213 1250 1127 1184 1163 1356 1253 1218 1144 1176 1269 1200 1267 1220 1225 1229 1240 1205 1135 1273 1197 1201 1186 1319 1106 1251 1227 1219 1213 1232 1238 1221 1181 1323 1157 1216 1272 1155 1294 1318 1143 1212 1310 1214 1316 1294 1187 1155 1381 1257 1207 1271 1243 1253 1268 1295 1359 1283 1412 1497 1587 1700 1672 1808 1794 2043 2011 2061 2110 2204 2334 2529 2508 2568 2556 2745 2670 2864 2916 2908 2943 3044 3020 2915 3026 2789 2876 2843 2671 2596 2614 2539 2407 2299 2147 2052 1913 1789 1752 1652 1721 1486 1513 1296 1236 1195 1292 1319 1190 1248 1226 1223 1262 1283 1276 1165 1269 1285 1250 1212 1199 1207 1289 1151 1180 1212 1320 1273 1156 1186 1217 1152 1192 1258 1183 1263 1222 1193 1202 1263 1248 1174 1262 1243 1277 1269 1148 1259 1171 1189 1208 1293 1216 1324 1283 1288 1172 1196 1202 1242 1265 1179 1221 1213 1180 1217 1346 1325 1190 1289 1197 1260 1285 1308 1211 1227 1246 1314 1234 1221 1269 1294 1261 1179 1243 1284 1296 1181 1188 1341 1198 1353 1157 1271 1205 1298 1312 1215 1257 1235 1249 1229 1293 1265 1338 1573 1235 1239 1196 1305 1202 1189 1232 1266 1283 1278 1291 1219 1278 1338 1329 1482 1343 1365 1441 1327 1421 1463 1390 1423 1468 1393 1490 1308 1425 1421 1463 1389 1325 1294 1372 1291 1271 1441 1457 1243 1216 1193 1255 1278 1284 1311 1234 1301 1336 1346 1333 1210 1459 1227 1432 1328 1262 1343 1257 1321 1225 1299 1242 1304 1284 1222 1243 1361 1305 1315 1459 1346 1330 1293 1356 1201 1285 1216 1190 1201 1350 1244 1267 1245 1381 1247 1185 1195 1272 1304 1254 1399 1382 1284 1319 1302 1241 1237 1299 1249 1354 1242 1373 1297 1254 1255 1482 1296 1332 1386 1309 1369 1301 1319 1229 1227 1305 1186 1438 1313 1318 1312 1334 1236 1202 1353 1348 1259 1252 1345 1323 1338 1271 1267 1258 1398 1325 1231 1361 1252 1317 1249 1316 1328 1367 1323 1252 1435 1301 1220 1409 1363 1487 1352 1276 1508 1358 1489 1361 1272 1481 1344 1311 1401 1430 1397 1590 1407 1407 1287 1445 1444 1342 1324 1431 1300 1330 1485 1443 1440 1305 1309 1415 1502 1398 1280 1369 1417 1472 1377 1301 1384 1398 1624 1356 1357 1431 1511 1432 1360 1573 1593 1306 1537 1443 1466 1393 1545 1563 1484 1479 1483 1461 1499 1404 1426 1327 1382 1458 1426 1437 1502 1511 1550 1454 1440 1595 1509 1555 1652 1535 1585 1481 1590 1421 1549 1701 1616 1576 1663 1641 1764 1595 1585 1626 1563 1496 1684 1727 1691 1656 1731 1490 1533 1718 1747 1792 1942 1937 1975 2073 2048 2127 2341 2312 2409 2401 2479 2537 2747 2704 2782 2893 2947 3083 3180 3126 3117 3079 3164 3261 3219 3222 3153 3244 3146 3139 2964 3019 2906 2622 2811 2547 2406 2362 2344 2153 2110 2042 1918 1867 1897 1915 1893 1819 1870 1811 1878 1868 1958 1921 1911 1855 1932 1903 1885 1943 1881 1959 1914 1981 1979 1920 1967 1939 1934 1971 2089 1954 1966 1970 1983 1979 2044 1998 2010 2008 1947 2001 2082 1956 1998 2081 2113 2008 2077 2184 2066 2169 2115 2021 2233 2162 2092 2181 2180 2110 2185 2129 2169 2316 2194 2210 2124 2237 2317 2279 2241 2299 2227 2270 2352 2363 2373 2300 2315 2375 2362 2433 2353 2361 2440 2342 2382 2383 2556 2499 2465 2472 2524 2488 2589 2559 2622 2512 2644 2657 2529 2686 2656 2654 2676 2657 2800 2660 2673 2717 2768 2875 2681 2834 2706 2794 2859 2791 2759 2749 2827 2742 2790 2819 2832 2853 2918 2744 2814 2832 2844 2829 2896 2869 2858 2943 3053 2891 2872 2911 3022 2981 2881 2941 3005 3000 2928 2961 3003 3012 2936 3007 3026 3054 3039 3050 2940 3082 3049 3100 2932 2934 3108 3012 2973 2964 3074 3049 3067 2951 3021 3069 2988 3001 3084 2975 2979 3054 2972 2989 3010 2960 3063 3033 2977 2991 3164 3072 2972 3080 2977 3005 2935 3112 2980 3030 3103 2970 2811 2941 2997 2896 3043 2954 2942 2900 2928 2811 2958 2875 2906 2962 2862 2802 2781 2758 2788 2804 2936 2864 2870 2857 2789 2800 2814 2788 2724 2923 2859 2802 2765 2744 2693 2627 2762 2783 2686 2707 2707 2600 2715 2665 2592 2650 2613 2584 2631 2576 2663 2639 2693 2636 2655 2648 2607 2659 2616 2672 2711 2685 2742 2729 2820 2734 2818 2765 2717 2687 2717 2725 2673 2724 2703 2798 2783 2782 2689 2705 2673 2574 2585 2502 2405 2495 2376 2392 2459 2322 2332 2253 2275 2385 2169 2265 2150 2224 2203 2188 2217 2225 2114 2200 2137 2095 2176 2200 2177 2206 2154 2202 2078 2230 2139 2116 2051 2149 2125 2012 2192 2067 2112 2023 2033 1996 1992 1991 2074 1931 1931 2092 2013 2034 2026 1916 2010 1930 1969 1973 1992 1929 1941 1830 1937 1846 1961 1919 1889 1896 1928 1864 1970 1916 1837 1822 1863 1882 1850 1835 1770 1806 1916 1844 1755 1874 1730 1836 1823 1904 1889 1879 1829 1801 1908 1835 1844 1812 1815 1663 1769 1701 1738 1739 1628 1719 1653 1820 1829 1689 1670 1600 1679 1747 1728 1704 1817 1738 1683 1582 1648 1659 1663 1694 1688 1447 1690 1663 1582 1585 1371 1559 1613 1488 1554 1529 1541 1547 1578 1489 1564 1564 1619 1560 1533 1526 1616 1459 1436 1448 1406 1518 1489 1491 1469 1475 1589 1418 1335 1476 1403 1472 1354 1371 1479 1463 1360 1432 1377 1296 1373 1385 1385 1376 1480 1464 1237 1429 1434 1283 1374 1421 1313 1406 1474 1369 1428 1482 1382 1455 1404 1386 1306 1489 1412 1506 1628 1653 1564 1639 1600 1614 1486 1660 1672 1571 1684 1682 1595 1707 1687 1526 1550 1675 1649 1584 1498 1457 1411 1490 1458 1367 1418 1456 1397 1398 1432 1346 1234 1317 1210 1293 1268 1252 1313 1234 1278 1175 1154 1241 1189 1116 1169 1252 1164 1179 1210 1187 1180 1203 1191 1270 1131 1255 1240 1157 1143 1139 1232 1232 1106 1217 1196 1135 1143 1158 1162 1158 1195 1112 1139 1169 1123 1127 1181 1108 1156 1103 1166 1164 1129 1152 1193 1141 1183 1190 1123 1171 1147 1203 1142 1110 1115 1079 1145 1187 1117 1162 1140 1115 1098 1089 1117 1159 1095 1136 1137 1176 1151 1154 1069 1162 1139 1113 1142 1127 1144 1073 1054 1089 1142 1125 1138 1108 1134 1132 1126 1116 1135 1059 1126 1068 1097 1123 1123 1120 1109 1077 1034 1058 1097 1072 1041 1123 1117 1065 1059 1141 1033 1006 1037 1077 1083 1198 1025 1048 1105 1127 1126 1056 1162 1114 1153 1118 1084 1073 1140 1031 1081 1100 1102 1081 1108 1108 1132 1120 1133 1052 1118 1073 1236 1075 1137 1133 1082 1132 1165 1028 1003 1076 1112 1094 1073 979 1060 1071 1074 1050 1030 1025 1069 1068 1040 1022 1041 1007 982 1046 1055 1072 1099 1072 1081 1017 1025 1112 1048 1040 1035 1121 1003 1055 1012 1052 977 1058 1038 925 1041 1037 1068 1015 1120 1022 1062 983 1007 1064 1085 1003 1086 987 1003 1058 1018 1115 1032 950 983 1043 1030 1028 985 1092 1020 1058 1125 1017 1034 1045 1057 1004 969 986 918 985 970 1070 1015 1022 986 1011 1062 1032 996 1011 1022 977 1049 1024 1094 1022 1043 1058 1026 1009 1052 1041 970 1024 1040 1079 1056 998 986 1042 1094 1035 1077 1047 1101 1069 1134 1033 1091 1058 979 1006 1059 1026 1055 1015 1004 990 1078 988 967 1062 1067 1001 1025 1031 1023 991 1002 1051 1011 1000 1062 1052 997 1015 974 992 985 971 1011 955 935 955 1080 1029 953 1025 985 993 985 1011 1031 1030 955 1013 961 982 983 963 1005 986 993 985 975 992 1008 1001 986 1047 958 1048 1033 960 996 1031 967 1012 985 1068 965 1018 1032 1014 1004 957 1062 952 985 929 1033 999 981 969 971 1013 930 945 961 971 928 1005 972 1025 954 1062 980 1056 956 1015 966 1003 1013 945 969 961 1028 913 1007 1047 994 1007 1018 1067 951 988 976 962 1028 995 996 980 1026 970 963 972 999 1013 1006 986 1026 981 997 967 989 950 984 1049 1012 981 977 1001 985 939 1038 1018 952 973 926 1009 949 968 991 1023 981 905 957 946 985 1042 1017 927 974 968 969 994 915 949 955 953 910 1035 991 1066 923 986 1043 1040 989 1033 1069 1079 1096 1173 1160 1122 1142 1084 1201 1236 1195 1294 1252 1277 1335 1385 1565 1410 1340 1455 1357 1475 1457 1349 1337 1310 1299 1360 1438 1321 1332 1239 1256 1168 1164 1131 1089 1085 1062 997 1043 1004 982 1013 1054 961 1000 994 1007 1012 1024 986 991 985 986 983 933 963 1043 1045 986 1068 944 1014 985 956 993 968 972 1007 952 956 983 942 952 938 1035 976 1018 952 990 994 996 999 992 988 1035 954 973 975 1024 1096 1003 956 1037 996 992 986 972 990 1038 997 1013 964 993 975 969 889 983 1025 1023 964 956 966 938 980 1013 957 948 1028 1006 953 1028 944 1026 933 1010 1006 974 925 1003 1017 944 998 1060 1013 1016 1012 1022 1058 994 1116 1147 1079 1190 1141 1174 1169 1307 1353 1271 1379 1386 1480 1309 1573 1552 1433 1433 1554 1558 1599 1539 1459 1580 1445 1617 1563 1317 1277 1309 1301 1184 1129 1128 1120 1125 1063 1123 998 1116 1017 1028 1038 982 1020 998 993 1011 1011 1019 972 945 982 941 1027 968 990 965 962 986 970 997 1047 992 978 958 982 987 989 998 927 960 1007 919 1000 956 935 1022 1028 968 974 991 1037 1006 1021 1010 1033 950 971 1040 992 1028 950 1002 955 922 1007 1037 1036 1016 1005 993 1025 1074 987 1027 1085 1052 1051 1098 1054 1021 1086 1078 1037 1105 1050 1113 1061 1083 1131 1117 1063 1129 1073 1086 1063 1116 1108 1117 1154 1058 1163 1056 1003 994 1037 990 1046 1005 1056 1045 1020 991 1023 1005 974 1030 1029 994 1074 1034 1041 1065 972 974 1040 1023 1029 1072 1012 1021 984 1022 931 1017 1016 1014 1036 1007 1000 1018 993 1008 1015 1031 975 1035 990 1016 989 943 996 1022 951 1020 1019 992 995 1024 982 1014 939 957 1026 1030 943 962 969 1016 980 982 999 1069 965 1019 993 997 991 1038 1071 1025 1039 980 1020 1005 941 1020 1058 1031 1017 995 1025 943 961 1009 998 976 1005 991 1003 993 1066 1029 1033 1027 965 1005 1030 984 1006 1045 1040 1041 1024 1020 1044 1003 1021 1018 1005 1065 969 1052 1075 992 1010 997 1016 1043 968 1039 1083 1079 1041 1063 1055 1019 1073 1045 1074 1026 1098 1000 1048 1027 978 1008 1051 1042 1024 1069 1054 984 1021 992 1024 1003 1049 1034 1020 1064 945 1053 960 1081 992 965 1011 1040 1001 1061 993 1082 999 1027 997 1007 1080 1088 1030 1010 1098 1054 1079 1023 1052 1027 1118 1086 1010 1044 1058 1066 1101 1090 1023 1073 1034 1047 1090 966 1047 1015 992 1096 1048 1077 1040 1026 1015 1008 1051 1001 991 1036 1062 1056 1041 1035 1098 989 1017 1034 1030 1000 1081 1067 1053 1064 1018 1072 994 1040 1073 1039 1103 1034 1050 1003 1079 984 1042 1084 1044 1024 1057 1082 1078 1093 1057 1085 1062 1027 1005 1096 1057 1049 1031 1013 1049 1059 1063 1059 1056 1060 1061 1047 1102 1070 1092 1048 1030 1054 1014 1035 996 995 1071 1111 1020 1052 1113 1054 1071 1080 1068 1050 1089 1054 1072 1090 1068 1068 1022 1056 1037 1012 1106 1019 1088 1082 1063 1082 1044 1103 1032 1063 1032 1082 1033 1059 1027 1102 1081 1073 1135 1022 1105 1020 1082 1068 1052 1050 1086 1079 1101 1085 1024 1062 1031 1053 1084 1088 1130 1023 1041 1094 1048 1101 1098 1157 1065 1124 1078 1091 1052 1157 1066 1107 1087 1066 1097 1095 1040 1113 1066 989 1068 1039 1147 1060 1120 1140 1095 1124 1057 1036 1057 1050 1124 1044 1035 1193 1071 1098 1095 1149 1079 1174 1072 1150 1115 1155 1093 1103 1088 1100 1080 1156 1080 1150 1113 1091 1098 1118 1087 1105 1098 1149 1071 1116 1115 1147 1112 1054 1107 1148 1181 1120 1125 1097 1175 1102 1104 1068 1101 1133 1157 1101 1030 1114 1024 1107 1107 1101 1130 1143 1105 1087 1104 1140 1087 1113 1125 1101 1067 1187 1149 1155 1096 1090 1161 1128 1114 1077 1135 1113 1080 1144 1068 1165 1173 1158 1096 1156 1098 1059 1175 1168 1112 1147 1116 1192 1056 1196 1084 1212 1106 1136 1116 1208 1231 1131 1097 1104 1188 1123 1168 1159 1160 1126 1099 1115 1118 1076 1208 1147 1089 1109 1089 1180 1100 1146 1122 1135 1123 1100 1149 1169 1123 1104 1211 1100 1117 1151 1142 1124 1124 1135 1133 1131 1108 1176 1185 1107 1141 1151 1207 1104 1129 1134 1169 1183 1133 1151 1142 1229 1122 1170 1151 1183 1125 1128 1110 1158 1108 1167 1068 1190 1111 1141 1175 1277 1144 1129 1124 1197 1077 1210 1157 1246 1163 1182 1140 1228 1168 1174 1120 1146 1245 1141 1194 1198 1150 1200 1210 1192 1132 1271 1098 1208 1137 1237 1152 1106 1181 1169 1162 1198 1197 1201 1218 1123 1235 1161 1269 1174 1156 1225 1136 1253 1169 1129 1152 1136 1144 1224 1159 1188 1205 1131 1173 1149 1185 1327 1225 1155 1204 1210 1156 1235 1230 1197 1171 1130 1206 1227 1188 1195 1148 1240 1263 1181 1225 1238 1179 1184 1234 1270 1204 1187 1238 1212 1178 1198 1131 1287 1204 1213 1278 1327 1232 1221 1233 1339 1278 1189 1273 1276 1232 1386 1242 1228 1295 1185 1346 1281 1291 1342 1226 1212 1303 1350 1324 1403 1588 1437 1625 1674 1766 2046 2140 2310 2396 2625 2733 3007 3193 3526 3731 4083 4322 4607 4771 4979 5162 5378 5554 5541 5785 5897 5823 6016 5860 5790 5682 5664 5430 5457 5111 4951 4715 4354 4193 3805 3615 3267 3046 2831 2553 2248 2196 2025 1852 1594 1576 1571 1504 1465 1502 1400 1369 1366 1290 1403 1357 1354 1393 1364 1265 1260 1340 1236 1339 1294 1326 1255 1283 1277 1259 1262 1276 1228 1296 1305 1221 1260 1314 1226 1395 1202 1409 1349 1246 1242 1260 1304 1354 1346 1272 1306 1281 1260 1271 1302 1351 1302 1295 1330 1326 1326 1316 1311 1431 1358 1321 1345 1198 1262 1321 1361 1298 1329 1277 1317 1301 1347 1310 1384 1292 1364 1277 1389 1492 1336 1343 1311 1349 1418 1268 1276 1330 1348 1282 1472 1472 1368 1450 1212 1346 1371 1353 1297 1360 1372 1388 1342 1290 1418 1331 1317 1378 1532 1277 1225 1362 1297 1378 1289 1439 1475 1387 1375 1392 1423 1325 1414 1323 1417 1453 1337 1436 1261 1345 1411 1310 1303 1381 1199 1281 1475 1242 1268 1351 1351 1408 1348 1303 1458 1278 1240 1386 1366 1469 1289 1365 1294 1321 1436 1457 1444 1361 1288 1457 1403 1383 1466 1402 1438 1338 1520 1482 1408 1425 1371 1510 1478 1474 1313 1375 1380 1383 1203 1466 1361 1474 1453 1439 1331 1406 1428 1532 1330 1467 1490 1434 1385 1411 1496 1428 1453 1519 1415 1463 1393 1412 1414 1316 1465 1356 1463 1439 1472 1358 1330 1360 1413 1360 1479 1286 1526 1469 1506 1537 1427 1434 1366 1326 1412 1421 1561 1396 1547 1317 1527 1491 1559 1559 1412 1518 1500 1388 1412 1544 1454 1484 1386 1476 1459 1415 1388 1531 1527 1636 1343 1380 1444 1530 1525 1334 1281 1435 1572 1467 1512 1492 1453 1609 1485 1520 1526 1410 1554 1566 1384 1544 1465 1527 1372 1383 1555 1506 1551 1520 1546 1448 1419 1623 1510 1467 1532 1604 1495 1480 1492 1599 1581 1529 1638 1396 1460 1467 1458 1586 1552 1444 1514 1595 1536 1502 1432 1635 1471 1626 1551 1591 1463 1501 1547 1446 1643 1524 1678 1704 1641 1608 1576 1523 1613 1645 1515 1516 1653 1632 1603 1605 1557 1614 1564 1649 1534 1595 1627 1462 1587 1646 1632 1609 1638 1586 1568 1662 1656 1674 1709 1692 1702 1605 1627 1732 1722 1700 1453 1662 1728 1579 1579 1721 1651 1608 1588 1642 1624 1604 1691 1543 1543 1605 1505 1707 1696 1568 1630 1653 1630 1754 1633 1711</counts>
			</dataPoints>
		</scan>
	</xrdMeasurement>
</xrdMeasurements>